Workbook
Name Common_Equations.Common_ConvertCH4ToCO2e: _xlfn.LAMBDA(_xlpm.E_CH4,_xlpm.GWP_CH4, _xlpm.E_CH4 * _xlpm.GWP_CH4)
Name Common_Equations.Common_ConvertCH4ToCO2e: _xlfn.LAMBDA(_xlpm.E_CH4,_xlpm.GWP_CH4, _xlpm.E_CH4 * _xlpm.GWP_CH4)
Name Common_Equations.Common_ConvertCH4ToCO2e: _xlfn.LAMBDA(_xlpm.E_CH4,_xlpm.GWP_CH4, _xlpm.E_CH4 * _xlpm.GWP_CH4)
Name Common_Equations.Common_ConvertCH4ToCO2e_Arguments: _xlfn.LAMBDA(_xlfn.MAKEARRAY(2, 2, _xlfn.LAMBDA(_xlpm.r,_xlpm.c, INDEX({"ECH4","Methane emissions (t CH4)";"GWPCH4","Global warming potential for methane (t CO2-e / t CH4)"}, _xlpm.r, _xlpm.c))))
Name Common_Equations.Common_ConvertCH4ToCO2e_Arguments: _xlfn.LAMBDA(_xlfn.MAKEARRAY(2, 2, _xlfn.LAMBDA(_xlpm.r,_xlpm.c, INDEX({"ECH4","Methane emissions (t CH4)";"GWPCH4","Global warming potential for methane (t CO2-e / t CH4)"}, _xlpm.r, _xlpm.c))))
Name Common_Equations.Common_ConvertCH4ToCO2e_Arguments: _xlfn.LAMBDA(_xlfn.MAKEARRAY(2, 2, _xlfn.LAMBDA(_xlpm.r,_xlpm.c, INDEX({"ECH4","Methane emissions (t CH4)";"GWPCH4","Global warming potential for methane (t CO2-e / t CH4)"}, _xlpm.r, _xlpm.c))))
Name Common_Equations.Common_ConvertCH4ToCO2e_LatexEquation: _xlfn.LAMBDA("CO2_e = E_{CH4} \times GWP_{CH4}")
Name Common_Equations.Common_ConvertCH4ToCO2e_NIRReference: _xlfn.LAMBDA("")
Name Common_Equations.Common_ConvertCH4ToCO2e_Title: _xlfn.LAMBDA("Convert methane emissions to carbon dioxide equivalent emissions")
Name Common_Equations.Common_ConvertCH4ToCO2e_Unit: _xlfn.LAMBDA("t CO2e")
Name Common_Equations.Common_ConvertCH4ToCO2e_Variable: _xlfn.LAMBDA("ECH4 CO2e")
Name Common_Equations.Common_ConvertN2OToCO2e: _xlfn.LAMBDA(_xlpm.E_N2O,_xlpm.GWP_N2O, _xlpm.E_N2O * _xlpm.GWP_N2O)
Name Common_Equations.Common_ConvertN2OToCO2e: _xlfn.LAMBDA(_xlpm.E_N2O,_xlpm.GWP_N2O, _xlpm.E_N2O * _xlpm.GWP_N2O)
Name Common_Equations.Common_ConvertN2OToCO2e: _xlfn.LAMBDA(_xlpm.E_N2O,_xlpm.GWP_N2O, _xlpm.E_N2O * _xlpm.GWP_N2O)
Name Common_Equations.Common_ConvertN2OToCO2e_LatexEquation: _xlfn.LAMBDA("CO2_e = E_{N2O} \times GWP_{N2O}")
Name Common_Equations.Common_ConvertN2OToCO2e_NIRReference: _xlfn.LAMBDA("")
Name Common_Equations.Common_ConvertN2OToCO2e_Title: _xlfn.LAMBDA("Convert nitrous oxide emissions to carbon dioxide equivalent emissions")
Name Common_Equations.Common_ConvertN2OToCO2e_Unit: _xlfn.LAMBDA("t CO2e")
Name Common_Equations.Common_ConvertN2OToCO2e_Variable: _xlfn.LAMBDA("EN2O CO2e")
Name Common_InputFunctions.Utility_ConvertStateCommonNameToAbbreviation: _xlfn.LAMBDA(_xlpm.StateCommonName,_xlpm.StateCommonNameArray,_xlpm.StateAbbreviationArray, _xlfn.XLOOKUP(_xlpm.StateCommonName, _xlpm.StateCommonNameArray, _xlpm.StateAbbreviationArray, ""))
Name Common_InputFunctions.Utility_ConvertStateCommonNameToAbbreviation: _xlfn.LAMBDA(_xlpm.StateCommonName,_xlpm.StateCommonNameArray,_xlpm.StateAbbreviationArray, _xlfn.XLOOKUP(_xlpm.StateCommonName, _xlpm.StateCommonNameArray, _xlpm.StateAbbreviationArray, ""))
Name Common_InputFunctions.Utility_ConvertStateCommonNameToAbbreviation: _xlfn.LAMBDA(_xlpm.StateCommonName,_xlpm.StateCommonNameArray,_xlpm.StateAbbreviationArray, _xlfn.XLOOKUP(_xlpm.StateCommonName, _xlpm.StateCommonNameArray, _xlpm.StateAbbreviationArray, ""))
Name Common_InputFunctions.Utility_DisplayArguments_1_2: _xlfn.LAMBDA(_xlpm.ArgumentsArray, _xlfn.CHOOSECOLS(_xlpm.ArgumentsArray, 1, 2))
Name Common_InputFunctions.Utility_DisplayArguments_1_2: _xlfn.LAMBDA(_xlpm.ArgumentsArray, _xlfn.CHOOSECOLS(_xlpm.ArgumentsArray, 1, 2))
Name Common_InputFunctions.Utility_DisplayArguments_1_2: _xlfn.LAMBDA(_xlpm.ArgumentsArray, _xlfn.CHOOSECOLS(_xlpm.ArgumentsArray, 1, 2))
Name Common_InputFunctions.Utility_DisplayArguments_3_4: _xlfn.LAMBDA(_xlpm.ArgumentsArray, _xlfn.CHOOSECOLS(_xlpm.ArgumentsArray, 3, 4))
Name Common_InputFunctions.Utility_DisplayArguments_3_4: _xlfn.LAMBDA(_xlpm.ArgumentsArray, _xlfn.CHOOSECOLS(_xlpm.ArgumentsArray, 3, 4))
Name Common_InputFunctions.Utility_DisplayArguments_3_4: _xlfn.LAMBDA(_xlpm.ArgumentsArray, _xlfn.CHOOSECOLS(_xlpm.ArgumentsArray, 3, 4))
Name Common_InputFunctions.Utility_DisplayFunctionName: _xlfn.LAMBDA(_xlpm.Function, _xlfn.TEXTBEFORE(_xlfn.FORMULATEXT(_xlpm.Function), "("))
Name Common_InputFunctions.Utility_DisplayFunctionName: _xlfn.LAMBDA(_xlpm.Function, _xlfn.TEXTBEFORE(_xlfn.FORMULATEXT(_xlpm.Function), "("))
Name Common_InputFunctions.Utility_DisplayFunctionName: _xlfn.LAMBDA(_xlpm.Function, _xlfn.TEXTBEFORE(_xlfn.FORMULATEXT(_xlpm.Function), "("))
Name Common_InputFunctions.Utility_GetArrayTableColumnStartNumber: _xlfn.LAMBDA(_xlpm.TableHeaderCell, COLUMN(_xlpm.TableHeaderCell))
Name Common_InputFunctions.Utility_GetArrayTableColumnStartNumber: _xlfn.LAMBDA(_xlpm.TableHeaderCell, COLUMN(_xlpm.TableHeaderCell))
Name Common_InputFunctions.Utility_GetArrayTableColumnStartNumber: _xlfn.LAMBDA(_xlpm.TableHeaderCell, COLUMN(_xlpm.TableHeaderCell))
Name Common_InputFunctions.Utility_GetArrayTableRowStartNumber: _xlfn.LAMBDA(_xlpm.TableheaderCell,_xlpm.RowsBetweenHeaderandArray, ROW(_xlpm.TableheaderCell) + _xlpm.RowsBetweenHeaderandArray - 1)
Name Common_InputFunctions.Utility_GetArrayTableRowStartNumber: _xlfn.LAMBDA(_xlpm.TableheaderCell,_xlpm.RowsBetweenHeaderandArray, ROW(_xlpm.TableheaderCell) + _xlpm.RowsBetweenHeaderandArray - 1)
Name Common_InputFunctions.Utility_GetArrayTableRowStartNumber: _xlfn.LAMBDA(_xlpm.TableheaderCell,_xlpm.RowsBetweenHeaderandArray, ROW(_xlpm.TableheaderCell) + _xlpm.RowsBetweenHeaderandArray - 1)
Name Common_InputFunctions.Utility_LookupValueInTable: _xlfn.LAMBDA(_xlpm.LookupValue,_xlpm.LookupArray,_xlpm.ReturnArray, _xlfn.XLOOKUP(_xlpm.LookupValue, _xlpm.LookupArray, _xlpm.ReturnArray, ""))
Name Common_InputFunctions.Utility_LookupValueInTable: _xlfn.LAMBDA(_xlpm.LookupValue,_xlpm.LookupArray,_xlpm.ReturnArray, _xlfn.XLOOKUP(_xlpm.LookupValue, _xlpm.LookupArray, _xlpm.ReturnArray, ""))
Name Common_InputFunctions.Utility_LookupValueInTable: _xlfn.LAMBDA(_xlpm.LookupValue,_xlpm.LookupArray,_xlpm.ReturnArray, _xlfn.XLOOKUP(_xlpm.LookupValue, _xlpm.LookupArray, _xlpm.ReturnArray, ""))
Name Common_InputFunctions.Utility_ResultsItemFromEquationTitleAndSource: _xlfn.LAMBDA(_xlpm.TitleCell,_xlpm.SourceCell, SUBSTITUTE(LEFT(_xlpm.SourceCell, FIND(",", _xlpm.SourceCell) - 1), "VEERG 2026: ", "") & " " & _xlpm.TitleCell)
Name Common_InputFunctions.Utility_ResultsItemFromEquationTitleAndSource: _xlfn.LAMBDA(_xlpm.TitleCell,_xlpm.SourceCell, SUBSTITUTE(LEFT(_xlpm.SourceCell, FIND(",", _xlpm.SourceCell) - 1), "VEERG 2026: ", "") & " " & _xlpm.TitleCell)
Name Common_InputFunctions.Utility_ResultsItemFromEquationTitleAndSource: _xlfn.LAMBDA(_xlpm.TitleCell,_xlpm.SourceCell, SUBSTITUTE(LEFT(_xlpm.SourceCell, FIND(",", _xlpm.SourceCell) - 1), "VEERG 2026: ", "") & " " & _xlpm.TitleCell)
Name Common_InputFunctions.Utility_SourceHyperlink: _xlfn.LAMBDA(_xlpm.TargetCell, _xlfn.LET(_xlpm.sh, _xlfn.TEXTAFTER(CELL("filename", _xlpm.TargetCell), "]"), _xlpm.addr, CELL("address", _xlpm.TargetCell), "#'" & _xlpm.sh & "'!" & _xlpm.addr))
Name Common_InputFunctions.Utility_SourceHyperlink: _xlfn.LAMBDA(_xlpm.TargetCell, _xlfn.LET(_xlpm.sh, _xlfn.TEXTAFTER(CELL("filename", _xlpm.TargetCell), "]"), _xlpm.addr, CELL("address", _xlpm.TargetCell), "#'" & _xlpm.sh & "'!" & _xlpm.addr))
Name Common_InputFunctions.Utility_SourceHyperlink: _xlfn.LAMBDA(_xlpm.TargetCell, _xlfn.LET(_xlpm.sh, _xlfn.TEXTAFTER(CELL("filename", _xlpm.TargetCell), "]"), _xlpm.addr, CELL("address", _xlpm.TargetCell), "#'" & _xlpm.sh & "'!" & _xlpm.addr))
Name Common_InputFunctions.Utility_SourceHyperlinkDifferentSheet: _xlfn.LAMBDA(_xlpm.TargetCell, _xlfn.LET(_xlpm.sh, _xlfn.TEXTAFTER(CELL("filename", _xlpm.TargetCell), "]"), _xlpm.addr, CELL("address", _xlpm.TargetCell), "#" & _xlpm.addr))
Name Common_InputFunctions.Utility_SourceHyperlinkDifferentSheet: _xlfn.LAMBDA(_xlpm.TargetCell, _xlfn.LET(_xlpm.sh, _xlfn.TEXTAFTER(CELL("filename", _xlpm.TargetCell), "]"), _xlpm.addr, CELL("address", _xlpm.TargetCell), "#" & _xlpm.addr))
Name Common_InputFunctions.Utility_SourceHyperlinkDifferentSheet: _xlfn.LAMBDA(_xlpm.TargetCell, _xlfn.LET(_xlpm.sh, _xlfn.TEXTAFTER(CELL("filename", _xlpm.TargetCell), "]"), _xlpm.addr, CELL("address", _xlpm.TargetCell), "#" & _xlpm.addr))
Name Common_SourceData.Common_SourceData_AustralianStatesTerritories_Source: _xlfn.LAMBDA("")
Name Common_SourceData.Common_SourceData_AustralianStatesTerritories_Title: _xlfn.LAMBDA("Australian states and territories")
Name Common_SourceData.Common_SourceData_AustralianStatesTerritories_Unit: _xlfn.LAMBDA("")
Name Common_SourceData.Common_SourceData_AustralianStatesTerritories_Variable: _xlfn.LAMBDA("")
Name Common_SourceData.Common_SourceData_ClimateZones_Source: _xlfn.LAMBDA("VEERG 2026: Table 1.3: Climate and Rainfall zone classifications and definitions")
Name Common_SourceData.Common_SourceData_ClimateZones_Title: _xlfn.LAMBDA("VEERG Australian climate zones")
Name Common_SourceData.Common_SourceData_ClimateZones_Unit: _xlfn.LAMBDA("")
Name Common_SourceData.Common_SourceData_ClimateZones_Variable: _xlfn.LAMBDA("")
Name Common_SourceData.Common_SourceData_ConvertGasElementalToMolecular_Source: _xlfn.LAMBDA("XXXXXXX")
Name Common_SourceData.Common_SourceData_ConvertGasElementalToMolecular_Title: _xlfn.LAMBDA("Factor to convert elemental mass of gas to molecular mass")
Name Common_SourceData.Common_SourceData_ConvertGasElementalToMolecular_Unit: _xlfn.LAMBDA("factor")

Sheet Home
A1: Home

Sheet Results
A1: #VALUE! | C1: Enterprise: Dairy: Results
A3: =HYPERLINK("#'Home'!A1", "Home") -> Home
A4: =HYPERLINK("#'Results'!A1", "Results") -> Results | D4: ="Emissions breakdown for activities running between " & TEXT(X_Cell_Site_StartDate, "dd mmmm yyyy") & " and " & TEXT('Input - Enterprise'!E13, "dd mmmm yyyy") -> Emissions breakdown for activities running between 01 January 2024 and 31 December 2024
A6: INPUTS | D6: Scope 1 source | E6: GHG emissions method 1 | F6: GHG emissions method 2 | G6: GHG Unit | H6: CO2-e emissions method 1 | I6: CO2-e emissions method 2
A7: =HYPERLINK("#'Input - Site'!A1", "Site") -> Site | D7: 3.3.1.1-2 Enteric methane | E7: {=VEERG_3_3_1_1__1_TotalAnnualMethaneFromEntericFermentationVariation_Result_Method1} -> #NAME? | F7: {=VEERG_3_3_1_1__1_TotalAnnualMethaneFromEntericFermentationVariation_Result_Method2} -> #NAME? | G7: t CH4 | H7: {=Common_Equations.Common_ConvertCH4ToCO2e(E7,_xlfn.XLOOKUP("CH4", Table_GWPData[Gas],Table_GWPData[CO2-e factor]))} -> #NAME? | I7: {=Common_Equations.Common_ConvertCH4ToCO2e(F7,_xlfn.XLOOKUP("CH4", Table_GWPData[Gas],Table_GWPData[CO2-e factor]))} -> #NAME? | J7: t CO2e
A8: =HYPERLINK("#'Input - Pasture Beef'!A1", "Pasture Beef") -> Pasture Beef | D8: 4.3.1.1-2 Manure methane | E8: {=VEERG_4_3_1_1__1_TotalAnnualMethaneFromManureManagement_Result_Method1} -> #NAME? | F8: {=VEERG_4_3_1_1__1_TotalAnnualMethaneFromManureManagement_Result_Method2} -> #NAME? | G8: t CH4 | H8: {=Common_Equations.Common_ConvertCH4ToCO2e(E8,_xlfn.XLOOKUP("CH4", Table_GWPData[Gas],Table_GWPData[CO2-e factor]))} -> #NAME? | I8: {=Common_Equations.Common_ConvertCH4ToCO2e(F8,_xlfn.XLOOKUP("CH4", Table_GWPData[Gas],Table_GWPData[CO2-e factor]))} -> #NAME? | J8: t CO2e
D9: 4.3.1.3-4 Manure direct N2O | E9: {=VEERG_4_3_1_3__1_TotalAnnualDirectNitrousOxideEmissionsFromMMS_Result_Method1} -> #NAME? | F9: {=VEERG_4_3_1_3__1_TotalAnnualDirectNitrousOxideEmissionsFromMMS_Result_Method2} -> #NAME? | G9: t N2O | H9: {=Common_Equations.Common_ConvertN2OToCO2e(E9,_xlfn.XLOOKUP("N2O", Table_GWPData[Gas],Table_GWPData[CO2-e factor]))} -> #NAME? | I9: {=Common_Equations.Common_ConvertN2OToCO2e(F9,_xlfn.XLOOKUP("N2O", Table_GWPData[Gas],Table_GWPData[CO2-e factor]))} -> #NAME? | J9: t CO2e
A10: CALCULATIONS | D10: 4.3.1.5 Manure atmospheric deposition | E10: {=VEERG_4_3_1_5__1_AnnualAtmosphericDepositionEmissionsFromMMS_Result_Method1} -> #NAME? | F10: {=VEERG_4_3_1_5__1_AnnualAtmosphericDepositionEmissionsFromMMS_Result_Method2} -> #NAME? | G10: t N2O | H10: {=Common_Equations.Common_ConvertN2OToCO2e(E10,_xlfn.XLOOKUP("N2O", Table_GWPData[Gas],Table_GWPData[CO2-e factor]))} -> #NAME? | I10: {=Common_Equations.Common_ConvertN2OToCO2e(F10,_xlfn.XLOOKUP("N2O", Table_GWPData[Gas],Table_GWPData[CO2-e factor]))} -> #NAME? | J10: t CO2e
A11: =HYPERLINK("#'4.2.1.1-2 Methane'!A1", "4.2.1.1-2 Methane") -> 4.2.1.1-2 Methane | D11: 4.3.1.6-7 Manure leaching and runoff | E11: {=VEERG_4_3_1_6__1_AnnualEmissionsFromLeachingAndRunoffFromMMS_Result_Method1} -> #NAME? | F11: {=VEERG_4_3_1_6__1_AnnualEmissionsFromLeachingAndRunoffFromMMS_Result_Method2} -> #NAME? | G11: t N2O | H11: {=Common_Equations.Common_ConvertN2OToCO2e(E11,_xlfn.XLOOKUP("N2O", Table_GWPData[Gas],Table_GWPData[CO2-e factor]))} -> #NAME? | I11: {=Common_Equations.Common_ConvertN2OToCO2e(F11,_xlfn.XLOOKUP("N2O", Table_GWPData[Gas],Table_GWPData[CO2-e factor]))} -> #NAME? | J11: t CO2e
A12: =HYPERLINK("#'4.2.1.3-4 Soil direct N2O'!A1", "4.2.1.3-4 Soil direct N2O") -> 4.2.1.3-4 Soil direct N2O | D12: 4.3.1.9 Soil direct N2O | E12: {=VEERG_4_3_1_9__1_DirectNitrousOxideEmissionsOnPasture_Result_Method1} -> #NAME? | F12: {=VEERG_4_3_1_9__1_DirectNitrousOxideEmissionsOnPasture_Result_Method2} -> #NAME? | G12: t N2O | H12: {=Common_Equations.Common_ConvertN2OToCO2e(E12,_xlfn.XLOOKUP("N2O", Table_GWPData[Gas],Table_GWPData[CO2-e factor]))} -> #NAME? | I12: {=Common_Equations.Common_ConvertN2OToCO2e(F12,_xlfn.XLOOKUP("N2O", Table_GWPData[Gas],Table_GWPData[CO2-e factor]))} -> #NAME? | J12: t CO2e
A13: =HYPERLINK("#'4.2.1.5-6 Soil Atmos Dep'!A1", "4.2.1.5-6 Soil atm. deposition") -> 4.2.1.5-6 Soil atm. deposition | D13: 4.3.1.10-11 Soil atmospheric deposition | E13: {=VEERG_4_3_1_10__1_AtmosphericDepositionEmissionsFromUrineAndDungOnPasture_Result_Method1} -> #NAME? | F13: {=VEERG_4_3_1_10__1_AtmosphericDepositionEmissionsFromUrineAndDungOnPasture_Result_Method2} -> #NAME? | G13: t N2O | H13: {=Common_Equations.Common_ConvertN2OToCO2e(E13,_xlfn.XLOOKUP("N2O", Table_GWPData[Gas],Table_GWPData[CO2-e factor]))} -> #NAME? | I13: {=Common_Equations.Common_ConvertN2OToCO2e(F13,_xlfn.XLOOKUP("N2O", Table_GWPData[Gas],Table_GWPData[CO2-e factor]))} -> #NAME? | J13: t CO2e
A14: =HYPERLINK("#'4.2.1.7-8 Soil leach runoff'!A1", "4.2.1.7-8 Soil leach & runoff") -> 4.2.1.7-8 Soil leach & runoff | D14: 4.3.1.12-13 Soil leaching and runoff | E14: {=VEERG_4_3_1_12__1_LeachingAndRunoffEmissionsFromUrineAndDungOnPasture_Result_Method1} -> #NAME? | F14: {=VEERG_4_3_1_12__1_LeachingAndRunoffEmissionsFromUrineAndDungOnPasture_Result_Method2} -> #NAME? | G14: t N2O | H14: {=Common_Equations.Common_ConvertN2OToCO2e(E14,_xlfn.XLOOKUP("N2O", Table_GWPData[Gas],Table_GWPData[CO2-e factor]))} -> #NAME? | I14: {=Common_Equations.Common_ConvertN2OToCO2e(F14,_xlfn.XLOOKUP("N2O", Table_GWPData[Gas],Table_GWPData[CO2-e factor]))} -> #NAME? | J14: t CO2e
D15: 5.1.1.1-2 Inorganic fert N2O | E15: {=VEERG_5_1_1_1__1_InorganicFertiliserApplicationN2OEmissions_Result_Method1} -> #NAME? | F15: {=VEERG_5_1_1_1__1_InorganicFertiliserApplicationN2OEmissions_Result_Method2} -> #NAME? | G15: t N2O | H15: {=Common_Equations.Common_ConvertN2OToCO2e(E15,_xlfn.XLOOKUP("N2O", Table_GWPData[Gas],Table_GWPData[CO2-e factor]))} -> #NAME? | I15: {=Common_Equations.Common_ConvertN2OToCO2e(F15,_xlfn.XLOOKUP("N2O", Table_GWPData[Gas],Table_GWPData[CO2-e factor]))} -> #NAME? | J15: t CO2e
A16: APPENDICES | D16: 5.1.1.3-4 Inorganic fert CO2 | E16: {=VEERG_5_1_1_3__1_InorganicFertiliserApplicationCO2Emissions_Result_Method1} -> #NAME? | F16: =E16 -> #NAME? | G16: t CO2 | H16: =E16 -> #NAME? | I16: =F16 -> #NAME? | J16: t CO2e
A17: =HYPERLINK("#'Constants - Pasture Beef'!A1", "Constants - Pasture Beef") -> Constants - Pasture Beef | D17: 5.2.1.1-2 Organic fert N2O | E17: {=VEERG_5_2_1_1__2_MassOfNitrogenInOrganicFertiliser_Result_Method1} -> #NAME? | F17: =E17 -> #NAME? | G17: t N2O | H17: {=Common_Equations.Common_ConvertN2OToCO2e(E17,_xlfn.XLOOKUP("N2O", Table_GWPData[Gas],Table_GWPData[CO2-e factor]))} -> #NAME? | I17: {=Common_Equations.Common_ConvertN2OToCO2e(F17,_xlfn.XLOOKUP("N2O", Table_GWPData[Gas],Table_GWPData[CO2-e factor]))} -> #NAME? | J17: t CO2e
A18: =HYPERLINK("#'Constants - Livestock'!A1", "Constants - Livestock") -> Constants - Livestock | D18: 5.3.1.1-2 Lime CO2 | E18: {=VEERG_5_3_1_1__1_LimeApplicationCO2Emissions_Result_Method1} -> #NAME? | F18: =E18 -> #NAME? | G18: t CO2 | H18: =E18 -> #NAME? | I18: =F18 -> #NAME? | J18: t CO2e
A19: =HYPERLINK("#'Constants - Common'!A1", "Constants - Common") -> Constants - Common | D19: 5.4.1.1-4 Atmos. deposition | E19: {=VEERG_5_4_1_3__1_OrganicFertiliserAtmosphericDepositionN2OEmissions_Result_Method1} -> #NAME? | F19: =E19 -> #NAME? | G19: t N2O | H19: {=Common_Equations.Common_ConvertN2OToCO2e(E19,_xlfn.XLOOKUP("N2O", Table_GWPData[Gas],Table_GWPData[CO2-e factor]))} -> #NAME? | I19: {=Common_Equations.Common_ConvertN2OToCO2e(F19,_xlfn.XLOOKUP("N2O", Table_GWPData[Gas],Table_GWPData[CO2-e factor]))} -> #NAME? | J19: t CO2e
A20: =HYPERLINK("#'Acknowledgements'!A1", "Acknowledgements") -> Acknowledgements | D20: 5.5.1.1-2 Leaching & runoff | E20: {=VEERG_5_5_1_1__1_FertiliserLeachingAndRunoffN2OEmissions_result_Method1} -> #NAME? | F20: =E20 -> #NAME? | G20: t N2O | H20: {=Common_Equations.Common_ConvertN2OToCO2e(E20,_xlfn.XLOOKUP("N2O", Table_GWPData[Gas],Table_GWPData[CO2-e factor]))} -> #NAME? | I20: {=Common_Equations.Common_ConvertN2OToCO2e(F20,_xlfn.XLOOKUP("N2O", Table_GWPData[Gas],Table_GWPData[CO2-e factor]))} -> #NAME? | J20: t CO2e
D21: 6.2.1.1-2 Pasture residue N2O | E21: {=VEERG_6_2_1_1__1__NitrousOxideEmissionsFromPastureResidues_Result_Method1} -> #NAME? | F21: {=VEERG_6_2_1_1__1__NitrousOxideEmissionsFromPastureResidues_Result_Method2} -> #NAME? | G21: t N2O | H21: {=Common_Equations.Common_ConvertN2OToCO2e(E21,_xlfn.XLOOKUP("N2O", Table_GWPData[Gas],Table_GWPData[CO2-e factor]))} -> #NAME? | I21: {=Common_Equations.Common_ConvertN2OToCO2e(F21,_xlfn.XLOOKUP("N2O", Table_GWPData[Gas],Table_GWPData[CO2-e factor]))} -> #NAME? | J21: t CO2e
D22: 6.3.1.1-2 Leach & runoff (pasture) | E22: {=VEERG_6_3_1_1__1__LeachingAndRunoffEmissionsCropAndPastureResidue_PastureOnly_Result_Method1} -> #NAME? | F22: {=VEERG_6_3_1_1__1__LeachingAndRunoffEmissionsCropAndPastureResidue_PastureOnly_Result_Method2} -> #NAME? | G22: t N2O | H22: {=Common_Equations.Common_ConvertN2OToCO2e(E22,_xlfn.XLOOKUP("N2O", Table_GWPData[Gas],Table_GWPData[CO2-e factor]))} -> #NAME? | I22: {=Common_Equations.Common_ConvertN2OToCO2e(F22,_xlfn.XLOOKUP("N2O", Table_GWPData[Gas],Table_GWPData[CO2-e factor]))} -> #NAME? | J22: t CO2e
D23: 8.1.1.1-2 Transport fuel CO2 | E23: {=VEERG_8_1_1_1__1_FuelCombustionTransport_Result_CO2} -> #NAME? | F23: =E23 -> #NAME? | G23: t CO2 | H23: =E23 -> #NAME? | I23: =F23 -> #NAME? | J23: t CO2e
D24: 8.1.1.1-2 Transport fuel CH4 | E24: {=VEERG_8_1_1_1__1_FuelCombustionTransport_Result_CH4} -> #NAME? | F24: =E24 -> #NAME? | G24: t CH4 | H24: {=Common_Equations.Common_ConvertCH4ToCO2e(E24,_xlfn.XLOOKUP("CH4", Table_GWPData[Gas],Table_GWPData[CO2-e factor]))} -> #NAME? | I24: {=Common_Equations.Common_ConvertCH4ToCO2e(F24,_xlfn.XLOOKUP("CH4", Table_GWPData[Gas],Table_GWPData[CO2-e factor]))} -> #NAME? | J24: t CO2e
D25: 8.1.1.1-2 Transport fuel N2O | E25: {=VEERG_8_1_1_1__1_FuelCombustionTransport_Result_N2O} -> #NAME? | F25: =E25 -> #NAME? | G25: t N2O | H25: {=Common_Equations.Common_ConvertN2OToCO2e(E25,_xlfn.XLOOKUP("N2O", Table_GWPData[Gas],Table_GWPData[CO2-e factor]))} -> #NAME? | I25: {=Common_Equations.Common_ConvertN2OToCO2e(F25,_xlfn.XLOOKUP("N2O", Table_GWPData[Gas],Table_GWPData[CO2-e factor]))} -> #NAME? | J25: t CO2e
D26: 8.2.1.1-2 Stationary fuel CO2 | E26: {=VEERG_8_2_1_1__1_FuelCombustionStationary_Result_CO2} -> #NAME? | F26: =E26 -> #NAME? | G26: t CO2 | H26: =E26 -> #NAME? | I26: =F26 -> #NAME? | J26: t CO2e
D27: 8.2.1.1-2 Stationary fuel CH4 | E27: {=VEERG_8_2_1_1__1_FuelCombustionStationary_Result_CH4} -> #NAME? | F27: =E27 -> #NAME? | G27: t CH4 | H27: {=Common_Equations.Common_ConvertCH4ToCO2e(E27,_xlfn.XLOOKUP("CH4", Table_GWPData[Gas],Table_GWPData[CO2-e factor]))} -> #NAME? | I27: {=Common_Equations.Common_ConvertCH4ToCO2e(F27,_xlfn.XLOOKUP("CH4", Table_GWPData[Gas],Table_GWPData[CO2-e factor]))} -> #NAME? | J27: t CO2e
D28: 8.2.1.1-2 Stationary fuel N2O | E28: {=VEERG_8_2_1_1__1_FuelCombustionStationary_Result_N2O} -> #NAME? | F28: =E28 -> #NAME? | G28: t N2O | H28: {=Common_Equations.Common_ConvertN2OToCO2e(E28,_xlfn.XLOOKUP("N2O", Table_GWPData[Gas],Table_GWPData[CO2-e factor]))} -> #NAME? | I28: {=Common_Equations.Common_ConvertN2OToCO2e(F28,_xlfn.XLOOKUP("N2O", Table_GWPData[Gas],Table_GWPData[CO2-e factor]))} -> #NAME? | J28: t CO2e
D29: 14.1.1-2 Purchased electricity (Location-based) | E29: {=VEERG_14_1_1__1_LocationBasedScopeElectricityEmissions_Result_Method1} -> #NAME? | F29: =E29 -> #NAME? | G29: t CO2e | H29: =E29 -> #NAME? | I29: =F29 -> #NAME? | J29: t CO2e
D30: 14.1.1-2 Purchased electricity (Market-based) | E30: {=VEERG_14_1_2__1_MarketBasedScopeElectricityEmissionsVariation_Result_Method1} -> #NAME? | F30: =E30 -> #NAME? | G30: t CO2e | H30: =E30 -> #NAME? | I30: =F30 -> #NAME? | J30: t CO2e
D31: Total | H31: =SUM(H7:H30) -> #NAME? | I31: =SUM(I7:I30) -> #NAME? | J31: t CO2e
D35: Emissions for whole production cycle
D36: {="There are " & Common_InputFunctions.getOverlappingReportingCycles(X_Cell_Enterprise_ProductionTimeframeStart,X_Cell_Enterprise_ProductionTimeframeEnd,X_Cell_Site_StartDate) & " emissions calculation periods that need to be completed before total product emissions can be determined."} -> There are 3 emissions calculation periods that need to be completed before total product emissions can be determined.
D37: Enter the method 1 and 2 CO2e emissions from prevoius emissions calculation periods if applicable.
D39: Emissions calculation cycle | E39: CO2-e emissions method 1 | F39: CO2-e emissions method 2
D40: {=Common_InputFunctions.getOverlappingReportingPeriods(X_Cell_Enterprise_ProductionTimeframeStart,X_Cell_Enterprise_ProductionTimeframeEnd,X_Cell_Site_StartDate)} -> 01 Jan 2023 to 31 Dec 2023 | E40: =IF(ISBLANK($D40), 0, IF(ISNUMBER(SEARCH("reporting", $D40)), Result_Enterprise_Method1, "Enter value")) -> Enter value | F40: =IF(ISBLANK($D40), 0, IF(ISNUMBER(SEARCH("reporting", $D40)), Result_Enterprise_Method2, "Enter value")) -> Enter value | G40: t CO2e
D41: 01 Jan 2024 to 31 Dec 2024 (This reporting cycle) | E41: =IF(ISBLANK($D41), 0, IF(ISNUMBER(SEARCH("reporting", $D41)), Result_Enterprise_Method1, "Enter value")) -> #NAME? | F41: =IF(ISBLANK($D41), 0, IF(ISNUMBER(SEARCH("reporting", $D41)), Result_Enterprise_Method2, "Enter value")) -> #NAME? | G41: t CO2e
D42: 01 Jan 2025 to 31 Dec 2025 | E42: =IF(ISBLANK($D42), 0, IF(ISNUMBER(SEARCH("reporting", $D42)), Result_Enterprise_Method1, "Enter value")) -> Enter value | F42: =IF(ISBLANK($D42), 0, IF(ISNUMBER(SEARCH("reporting", $D42)), Result_Enterprise_Method2, "Enter value")) -> Enter value | G42: t CO2e
E43: =IF(ISBLANK($D43), 0, IF(ISNUMBER(SEARCH("reporting", $D43)), Result_Enterprise_Method1, "Enter value")) -> 0 | F43: =IF(ISBLANK($D43), 0, IF(ISNUMBER(SEARCH("reporting", $D43)), Result_Enterprise_Method2, "Enter value")) -> 0 | G43: t CO2e
E44: =IF(ISBLANK($D44), 0, IF(ISNUMBER(SEARCH("reporting", $D44)), Result_Enterprise_Method1, "Enter value")) -> 0 | F44: =IF(ISBLANK($D44), 0, IF(ISNUMBER(SEARCH("reporting", $D44)), Result_Enterprise_Method2, "Enter value")) -> 0 | G44: t CO2e
D45: Total emissions for production cycle | E45: =SUM(E40:E44) -> #NAME? | F45: =SUM(F40:F44) -> #NAME?
D48: Carbon removals from plantings
...

Sheet Input - Site
A1: #VALUE! | C1: Input - Site
A3: =HYPERLINK("#'Home'!A1", "Home") -> Home
A4: =HYPERLINK("#'Results'!A1", "Results") -> Results
D5: Location and climate
A6: INPUTS
A7: =HYPERLINK("#'Input - Site'!A1", "Site") -> Site | D7: Location information is used to reference some region and climate-specific emission factors
A8: =HYPERLINK("#'Input - Pasture Beef'!A1", "Pasture Beef") -> Pasture Beef | D8: Tip: Use the web-based GAF Location Helper tool to easily get region and climate information. You will need an internet connection to use the GAF Location Helper.
A10: CALCULATIONS | D10: State | E10: Western Australia | F10: ← Please select
A11: =HYPERLINK("#'4.2.1.1-2 Methane'!A1", "4.2.1.1-2 Methane") -> 4.2.1.1-2 Methane | D11: Region (ABS Statistical area level 4) if state is WA | E11: Western Australia - Outback (South) | F11: ← Please select
A12: =HYPERLINK("#'4.2.1.3-4 Soil direct N2O'!A1", "4.2.1.3-4 Soil direct N2O") -> 4.2.1.3-4 Soil direct N2O | D12: Leaching zone | E12: NO - Not in leaching zone | F12: ← Please select
A13: =HYPERLINK("#'4.2.1.5-6 Soil Atmos Dep'!A1", "4.2.1.5-6 Soil atm. deposition") -> 4.2.1.5-6 Soil atm. deposition | D13: Elevation | E13: 307.7 | F13: Meters
A14: =HYPERLINK("#'4.2.1.7-8 Soil leach runoff'!A1", "4.2.1.7-8 Soil leach & runoff") -> 4.2.1.7-8 Soil leach & runoff | D14: Average temperature for reporting period | E14: 18 | F14: Degrees celsius
D15: Total rainfall for reporting period | E15: 601 | F15: Millimetres
A16: APPENDICES | D16: Potential evapotranspiration for reporting period | E16: 1326 | F16: Millimetres
A17: =HYPERLINK("#'Constants - Pasture Beef'!A1", "Constants - Pasture Beef") -> Constants - Pasture Beef | D17: Number of frost days for reporting period | E17: 7 | F17: Days
A18: =HYPERLINK("#'Constants - Livestock'!A1", "Constants - Livestock") -> Constants - Livestock | D18: MAP:PET ratio | E18: =E15/E16 -> 0.45324284
A19: =HYPERLINK("#'Constants - Common'!A1", "Constants - Common") -> Constants - Common | D19: Rainfall zone | E19: =Common_InputFunctions.Utility_LookupItemFromMinMax(E15,Table_SourceData_RainfallZones[Min rainfall],Table_SourceData_RainfallZones[Max rainfall],Table_SourceData_RainfallZones[Rainfall Zone]) -> High rainfall
A20: =HYPERLINK("#'Acknowledgements'!A1", "Acknowledgements") -> Acknowledgements | D20: Climate zone | E20: =Common_InputFunctions.Utility_GetClimateZone(E14,E15,E17,E13,E18,Table_SourceData_ClimateZones[Min temp],Table_SourceData_ClimateZones[Max temp],Table_SourceData_ClimateZones[Min rainfall],Table_SourceData_ClimateZones[Max rainfall],Table_SourceData_ClimateZones[Min frost days],Table_SourceData_ClimateZones[Max frost days],Table_SourceData_ClimateZones[Min elevation],Table_SourceData_ClimateZones[Max elevation],Table_SourceData_ClimateZones[Min MAP:PET],Table_SourceData_ClimateZones[Max MAP:PET],Table_SourceData_ClimateZones[Climate zone]) -> Warm temperate dry
D21: Wet or dry climate zone | E21: =Common_InputFunctions.Utility_LookupValueInTable($E$20,Table_SourceData_WetDryZones[Climate zone],Table_SourceData_WetDryZones[Wet or Dry Zone]) -> Dry climate zone
D22: Temperature zone | E22: =Common_InputFunctions.Utility_LookupItemFromMinMax(E14,Table_SourceData_TemperatureZones[Min MAT],Table_SourceData_TemperatureZones[Max MAT],Table_SourceData_TemperatureZones[Temperature Zone]) -> Temperate

Sheet Input - Enterprise
C1: Input - Enterprise
D5: Your business
D7: Farm name | E7: Test Farms
D8: Reporting entity name | E8: Test Farms Pty Ltd
D10: 💡An 'Emissions accounting period' is a 12 month period where the business can report on the emissions, and is typically the same as the business' financial accounting period.
D12: Emissions calculation period start date | E12: 45292 | F12: ← DD/MM/YYYY or DD Month YYYY
D13: Emissions calculation period end date | E13: =DATE(YEAR(E12)+1,MONTH(E12),DAY(E12))-1 -> 45657 | F13: ← Automatically calculated, 12 months after start date
D16: Production
D18: Production timeframe start | E18: 45231 | F18: ← DD/MM/YYYY or DD Month YYYY
D19: Production timeframe end | E19: 45747 | F19: ← DD/MM/YYYY or DD Month YYYY
D20: Production timeframe length | E20: =DATEDIF(E18,E19+1,"m") -> 17 | F20: Months
D22: Liveweight sold | E22: =SUM(Table_Input_LivestockSales[Total liveweight sold])*10^-3 -> 5 | G22: tonnes
D23: Milk produced unit | E23: {=X_Cell_Dairy_MilkProductionUnit} -> #NAME?
D24: Milk produced | E24: {=X_Cell_Dairy_MilkProductionAmount*365*IF(E23="Milk solds", 1, 1.03)} -> #NAME? | G24: tonnes
D25: Manure sold | E25: 1 | G25: tonnes
D27: Percentage of income from liveweight sold | E27: 0.15 | G27: percent
D28: Percentage of income from manure sold | E28: 0.05 | G28: percent
D29: Percentage of income from milk sold | E29: 0.8 | G29: percent

Sheet Input - Livestock sales
A1: #VALUE! | C1: Input - Livestock sales
D5: ⚠️ Livestock sales are not automatically reflected in the duration and head tables - you will need to manually adjust head count and average liveweight
D6: Transaction name | E6: Class (select) | F6: Sale date | G6: Head sold | H6: Average weight per head (kg) | I6: Total liveweight sold
F7: 45566 | G7: 10 | H7: 500 | I7: =G7*H7 -> 5000
I8: =G8*H8 -> 0
I9: =G9*H9 -> 0
I10: =G10*H10 -> 0
I11: =G11*H11 -> 0
I12: =G12*H12 -> 0
I13: =G13*H13 -> 0
I14: =G14*H14 -> 0
I15: =G15*H15 -> 0
I16: =G16*H16 -> 0

Sheet Input - Fert Prod System
A1: #VALUE! | C1: Input - Fertiliser Production System
D5: These inputs are used for fertiliser calculations, and they take their values from the "Input - Pasture" sheet. Do not edit these cells.
D7: Production system | E7: Pasture
D8: Crop type | E8: Pasture
D9: Irrigation method | E9: {=X_Cell_Pasture_IrrigationMethod} -> #NAME?
D10: Area under cropping | E10: {=X_Cell_Pasture_AreaUnderPasture} -> #NAME?

Sheet Input - Data quality
C1: Input - Data quality
D6: Input | E6: Temporal representativeness | F6: Spatial resolution | G6: Sample size | H6: Notes | I6: Evidence files | J6: Score
D7: Input name | E7: TR4 | F7: SR5 | G7: SS3 | J7: =_xlfn.XLOOKUP(Table_Input_DataQuality[[#This Row],[Temporal representativeness]],[3]!Table_SourceData_DataQuality_TemporalRepresentativeness[ID],[3]!Table_SourceData_DataQuality_TemporalRepresentativeness[Score])+_xlfn.XLOOKUP(Table_Input_DataQuality[[#This Row],[Spatial resolution]],[3]!Table_SourceData_DataQuality_SpatialRepresentativeness[ID],[3]!Table_SourceData_DataQuality_SpatialRepresentativeness[Score])+_xlfn.XLOOKUP(Table_Input_DataQuality[[#This Row],[Sample size]],[3]!Table_SourceData_DataQuality_SampleSize[ID],[3]!Table_SourceData_DataQuality_SampleSize[Score]) -> 12

Sheet Constants - Common
A1: #VALUE! | C1: Constants - Common
D5: {=Common_SourceData.Common_SourceData_AustralianStatesTerritories_Title()} -> Australian states and territories
D6: State/Territory | E6: Common Name | F6: Abbreviation
D7: {=Common_InputFunctions.Utility_DisplayArrayInTable(Common_SourceData.Common_SourceData_AustralianStatesTerritories_Data(),Table_AustralianStates[[#Headers],[State/Territory]],0)} -> New South Wales | E7: {=Common_InputFunctions.Utility_DisplayArrayInTable(Common_SourceData.Common_SourceData_AustralianStatesTerritories_Data(),Table_AustralianStates[[#Headers],[State/Territory]],0)} -> New South Wales | F7: {=Common_InputFunctions.Utility_DisplayArrayInTable(Common_SourceData.Common_SourceData_AustralianStatesTerritories_Data(),Table_AustralianStates[[#Headers],[State/Territory]],0)} -> NSW
D8: {=Common_InputFunctions.Utility_DisplayArrayInTable(Common_SourceData.Common_SourceData_AustralianStatesTerritories_Data(),Table_AustralianStates[[#Headers],[State/Territory]],0)} -> Australian Capital Territory | E8: {=Common_InputFunctions.Utility_DisplayArrayInTable(Common_SourceData.Common_SourceData_AustralianStatesTerritories_Data(),Table_AustralianStates[[#Headers],[State/Territory]],0)} -> ACT | F8: {=Common_InputFunctions.Utility_DisplayArrayInTable(Common_SourceData.Common_SourceData_AustralianStatesTerritories_Data(),Table_AustralianStates[[#Headers],[State/Territory]],0)} -> ACT
D9: {=Common_InputFunctions.Utility_DisplayArrayInTable(Common_SourceData.Common_SourceData_AustralianStatesTerritories_Data(),Table_AustralianStates[[#Headers],[State/Territory]],0)} -> Victoria | E9: {=Common_InputFunctions.Utility_DisplayArrayInTable(Common_SourceData.Common_SourceData_AustralianStatesTerritories_Data(),Table_AustralianStates[[#Headers],[State/Territory]],0)} -> Victoria | F9: {=Common_InputFunctions.Utility_DisplayArrayInTable(Common_SourceData.Common_SourceData_AustralianStatesTerritories_Data(),Table_AustralianStates[[#Headers],[State/Territory]],0)} -> VIC
D10: {=Common_InputFunctions.Utility_DisplayArrayInTable(Common_SourceData.Common_SourceData_AustralianStatesTerritories_Data(),Table_AustralianStates[[#Headers],[State/Territory]],0)} -> Queensland | E10: {=Common_InputFunctions.Utility_DisplayArrayInTable(Common_SourceData.Common_SourceData_AustralianStatesTerritories_Data(),Table_AustralianStates[[#Headers],[State/Territory]],0)} -> Queensland | F10: {=Common_InputFunctions.Utility_DisplayArrayInTable(Common_SourceData.Common_SourceData_AustralianStatesTerritories_Data(),Table_AustralianStates[[#Headers],[State/Territory]],0)} -> QLD
D11: {=Common_InputFunctions.Utility_DisplayArrayInTable(Common_SourceData.Common_SourceData_AustralianStatesTerritories_Data(),Table_AustralianStates[[#Headers],[State/Territory]],0)} -> South Australia | E11: {=Common_InputFunctions.Utility_DisplayArrayInTable(Common_SourceData.Common_SourceData_AustralianStatesTerritories_Data(),Table_AustralianStates[[#Headers],[State/Territory]],0)} -> South Australia | F11: {=Common_InputFunctions.Utility_DisplayArrayInTable(Common_SourceData.Common_SourceData_AustralianStatesTerritories_Data(),Table_AustralianStates[[#Headers],[State/Territory]],0)} -> SA
D12: {=Common_InputFunctions.Utility_DisplayArrayInTable(Common_SourceData.Common_SourceData_AustralianStatesTerritories_Data(),Table_AustralianStates[[#Headers],[State/Territory]],0)} -> Western Australia | E12: {=Common_InputFunctions.Utility_DisplayArrayInTable(Common_SourceData.Common_SourceData_AustralianStatesTerritories_Data(),Table_AustralianStates[[#Headers],[State/Territory]],0)} -> Western Australia | F12: {=Common_InputFunctions.Utility_DisplayArrayInTable(Common_SourceData.Common_SourceData_AustralianStatesTerritories_Data(),Table_AustralianStates[[#Headers],[State/Territory]],0)} -> WA
D13: {=Common_InputFunctions.Utility_DisplayArrayInTable(Common_SourceData.Common_SourceData_AustralianStatesTerritories_Data(),Table_AustralianStates[[#Headers],[State/Territory]],0)} -> Tasmania | E13: {=Common_InputFunctions.Utility_DisplayArrayInTable(Common_SourceData.Common_SourceData_AustralianStatesTerritories_Data(),Table_AustralianStates[[#Headers],[State/Territory]],0)} -> Tasmania | F13: {=Common_InputFunctions.Utility_DisplayArrayInTable(Common_SourceData.Common_SourceData_AustralianStatesTerritories_Data(),Table_AustralianStates[[#Headers],[State/Territory]],0)} -> TAS
D14: {=Common_InputFunctions.Utility_DisplayArrayInTable(Common_SourceData.Common_SourceData_AustralianStatesTerritories_Data(),Table_AustralianStates[[#Headers],[State/Territory]],0)} -> Northern Territory | E14: {=Common_InputFunctions.Utility_DisplayArrayInTable(Common_SourceData.Common_SourceData_AustralianStatesTerritories_Data(),Table_AustralianStates[[#Headers],[State/Territory]],0)} -> Northern Territory | F14: {=Common_InputFunctions.Utility_DisplayArrayInTable(Common_SourceData.Common_SourceData_AustralianStatesTerritories_Data(),Table_AustralianStates[[#Headers],[State/Territory]],0)} -> NT
D18: {=Common_SourceData.Common_SourceData_WASA4Areas_Title()} -> ABS Statistcal Areas Level 4 - Western Australia
D19: {=Common_SourceData.Common_SourceData_WASA4Areas_Source()} -> Australian Bureau of Statistics (ABS) - Statistical Areas Level 2 - 2021 - Shapefile
D20: SA 4 Name
D21: {=Common_InputFunctions.Utility_DisplayArrayInTable(Common_SourceData.Common_SourceData_WASA4Areas_Data(), Table_WASA4Areas[[#Headers],[SA 4 Name]], 0)} -> Bunbury
D22: {=Common_InputFunctions.Utility_DisplayArrayInTable(Common_SourceData.Common_SourceData_WASA4Areas_Data(), Table_WASA4Areas[[#Headers],[SA 4 Name]], 0)} -> Mandurah
D23: {=Common_InputFunctions.Utility_DisplayArrayInTable(Common_SourceData.Common_SourceData_WASA4Areas_Data(), Table_WASA4Areas[[#Headers],[SA 4 Name]], 0)} -> Perth - Inner
D24: {=Common_InputFunctions.Utility_DisplayArrayInTable(Common_SourceData.Common_SourceData_WASA4Areas_Data(), Table_WASA4Areas[[#Headers],[SA 4 Name]], 0)} -> Perth - North East
D25: {=Common_InputFunctions.Utility_DisplayArrayInTable(Common_SourceData.Common_SourceData_WASA4Areas_Data(), Table_WASA4Areas[[#Headers],[SA 4 Name]], 0)} -> Perth - North West
D26: {=Common_InputFunctions.Utility_DisplayArrayInTable(Common_SourceData.Common_SourceData_WASA4Areas_Data(), Table_WASA4Areas[[#Headers],[SA 4 Name]], 0)} -> Perth - South East
D27: {=Common_InputFunctions.Utility_DisplayArrayInTable(Common_SourceData.Common_SourceData_WASA4Areas_Data(), Table_WASA4Areas[[#Headers],[SA 4 Name]], 0)} -> Perth - South West
D28: {=Common_InputFunctions.Utility_DisplayArrayInTable(Common_SourceData.Common_SourceData_WASA4Areas_Data(), Table_WASA4Areas[[#Headers],[SA 4 Name]], 0)} -> Western Australia - Wheat Belt
D29: {=Common_InputFunctions.Utility_DisplayArrayInTable(Common_SourceData.Common_SourceData_WASA4Areas_Data(), Table_WASA4Areas[[#Headers],[SA 4 Name]], 0)} -> Western Australia - Outback (North)
D30: {=Common_InputFunctions.Utility_DisplayArrayInTable(Common_SourceData.Common_SourceData_WASA4Areas_Data(), Table_WASA4Areas[[#Headers],[SA 4 Name]], 0)} -> Western Australia - Outback (South)
D34: {=Common_SourceData.Common_SourceData_GWP_Title()} -> Global warming potential for greenhouse gases
D35: {=Common_SourceData.Common_SourceData_GWP_Source()} -> XXXXXXX
D36: Gas | E36: CO2-e factor
D37: {=Common_InputFunctions.Utility_DisplayArrayInTable(Common_SourceData.Common_SourceData_GWP_Data(), Table_GWPData[[#Headers],[Gas]], 0)} -> CO2 | E37: {=Common_InputFunctions.Utility_DisplayArrayInTable(Common_SourceData.Common_SourceData_GWP_Data(), Table_GWPData[[#Headers],[Gas]], 0)} -> 1
D38: {=Common_InputFunctions.Utility_DisplayArrayInTable(Common_SourceData.Common_SourceData_GWP_Data(), Table_GWPData[[#Headers],[Gas]], 0)} -> CH4 | E38: {=Common_InputFunctions.Utility_DisplayArrayInTable(Common_SourceData.Common_SourceData_GWP_Data(), Table_GWPData[[#Headers],[Gas]], 0)} -> 28
D39: {=Common_InputFunctions.Utility_DisplayArrayInTable(Common_SourceData.Common_SourceData_GWP_Data(), Table_GWPData[[#Headers],[Gas]], 0)} -> N2O | E39: {=Common_InputFunctions.Utility_DisplayArrayInTable(Common_SourceData.Common_SourceData_GWP_Data(), Table_GWPData[[#Headers],[Gas]], 0)} -> 265
D40: {=Common_InputFunctions.Utility_DisplayArrayInTable(Common_SourceData.Common_SourceData_GWP_Data(), Table_GWPData[[#Headers],[Gas]], 0)} -> CF4 | E40: {=Common_InputFunctions.Utility_DisplayArrayInTable(Common_SourceData.Common_SourceData_GWP_Data(), Table_GWPData[[#Headers],[Gas]], 0)} -> 6630
D41: {=Common_InputFunctions.Utility_DisplayArrayInTable(Common_SourceData.Common_SourceData_GWP_Data(), Table_GWPData[[#Headers],[Gas]], 0)} -> C2F6 | E41: {=Common_InputFunctions.Utility_DisplayArrayInTable(Common_SourceData.Common_SourceData_GWP_Data(), Table_GWPData[[#Headers],[Gas]], 0)} -> 12200
D42: {=Common_InputFunctions.Utility_DisplayArrayInTable(Common_SourceData.Common_SourceData_GWP_Data(), Table_GWPData[[#Headers],[Gas]], 0)} -> SF6 | E42: {=Common_InputFunctions.Utility_DisplayArrayInTable(Common_SourceData.Common_SourceData_GWP_Data(), Table_GWPData[[#Headers],[Gas]], 0)} -> 22800
D43: {=Common_InputFunctions.Utility_DisplayArrayInTable(Common_SourceData.Common_SourceData_GWP_Data(), Table_GWPData[[#Headers],[Gas]], 0)} -> NF3 | E43: {=Common_InputFunctions.Utility_DisplayArrayInTable(Common_SourceData.Common_SourceData_GWP_Data(), Table_GWPData[[#Headers],[Gas]], 0)} -> 17200
D45: {=Common_SourceData.Common_SourceData_ConvertGasElementalToMolecular_Title()} -> Factor to convert elemental mass of gas to molecular mass
D46: {=Common_SourceData.Common_SourceData_ConvertGasElementalToMolecular_Source()} -> XXXXXXX
D47: Gas | E47: Conversion factor | F47: Conversion factor 1 | G47: Conversion factor 2 | H47: Conversion factor combined
D48: {=Common_InputFunctions.Utility_DisplayArrayInTable(Common_SourceData.Common_SourceData_ConvertGasElementalToMolecular_Data(),Table_GasToMolecularConversionFactor[[#Headers],[Gas]], 0)} -> CO2 | E48: {=Common_InputFunctions.Utility_DisplayArrayInTable(Common_SourceData.Common_SourceData_ConvertGasElementalToMolecular_Data(),Table_GasToMolecularConversionFactor[[#Headers],[Gas]], 0)} -> 44/12 | F48: {=Common_InputFunctions.Utility_DisplayArrayInTable(Common_SourceData.Common_SourceData_ConvertGasElementalToMolecular_Data(),Table_GasToMolecularConversionFactor[[#Headers],[Gas]], 0)} -> 44 | G48: {=Common_InputFunctions.Utility_DisplayArrayInTable(Common_SourceData.Common_SourceData_ConvertGasElementalToMolecular_Data(),Table_GasToMolecularConversionFactor[[#Headers],[Gas]], 0)} -> 12 | H48: =Table_GasToMolecularConversionFactor[[#This Row],[Conversion factor 1]]/Table_GasToMolecularConversionFactor[[#This Row],[Conversion factor 2]] -> 3.6666667
D49: {=Common_InputFunctions.Utility_DisplayArrayInTable(Common_SourceData.Common_SourceData_ConvertGasElementalToMolecular_Data(),Table_GasToMolecularConversionFactor[[#Headers],[Gas]], 0)} -> CH4 | E49: {=Common_InputFunctions.Utility_DisplayArrayInTable(Common_SourceData.Common_SourceData_ConvertGasElementalToMolecular_Data(),Table_GasToMolecularConversionFactor[[#Headers],[Gas]], 0)} -> 16/12 | F49: {=Common_InputFunctions.Utility_DisplayArrayInTable(Common_SourceData.Common_SourceData_ConvertGasElementalToMolecular_Data(),Table_GasToMolecularConversionFactor[[#Headers],[Gas]], 0)} -> 16 | G49: {=Common_InputFunctions.Utility_DisplayArrayInTable(Common_SourceData.Common_SourceData_ConvertGasElementalToMolecular_Data(),Table_GasToMolecularConversionFactor[[#Headers],[Gas]], 0)} -> 12 | H49: =Table_GasToMolecularConversionFactor[[#This Row],[Conversion factor 1]]/Table_GasToMolecularConversionFactor[[#This Row],[Conversion factor 2]] -> 1.3333333
D50: {=Common_InputFunctions.Utility_DisplayArrayInTable(Common_SourceData.Common_SourceData_ConvertGasElementalToMolecular_Data(),Table_GasToMolecularConversionFactor[[#Headers],[Gas]], 0)} -> N2O | E50: {=Common_InputFunctions.Utility_DisplayArrayInTable(Common_SourceData.Common_SourceData_ConvertGasElementalToMolecular_Data(),Table_GasToMolecularConversionFactor[[#Headers],[Gas]], 0)} -> 44/28 | F50: {=Common_InputFunctions.Utility_DisplayArrayInTable(Common_SourceData.Common_SourceData_ConvertGasElementalToMolecular_Data(),Table_GasToMolecularConversionFactor[[#Headers],[Gas]], 0)} -> 44 | G50: {=Common_InputFunctions.Utility_DisplayArrayInTable(Common_SourceData.Common_SourceData_ConvertGasElementalToMolecular_Data(),Table_GasToMolecularConversionFactor[[#Headers],[Gas]], 0)} -> 28 | H50: =Table_GasToMolecularConversionFactor[[#This Row],[Conversion factor 1]]/Table_GasToMolecularConversionFactor[[#This Row],[Conversion factor 2]] -> 1.5714286
...
