Workbook
Name AgResidue_Equations_FieldBurning.VEERG_6_4_1_1__1__MethaneEmissionsFromBurningOfCropResidues: _xlfn.LAMBDA(_xlpm.Mburnc,_xlpm.CCc,_xlpm.EFCH4,_xlpm.C_CH4, _xlpm.Mburnc * _xlpm.CCc * _xlpm.EFCH4 * _xlpm.C_CH4 * 10 ^ (-3))
Name AgResidue_Equations_FieldBurning.VEERG_6_4_1_1__1__MethaneEmissionsFromBurningOfCropResidues_FunctionName: _xlfn.LAMBDA("VEERG_6_4_1_1__1__MethaneEmissionsFromBurningOfCropResidues")
Name AgResidue_Equations_FieldBurning.VEERG_6_4_1_1__1__MethaneEmissionsFromBurningOfCropResidues_LatexEquation: _xlfn.LAMBDA("E_{CH4}=\sum_{c}(M_{burn,c}\times CC_{c}\times EF_{CH4}\times C_{CH4}\times 10^{-3})")
Name AgResidue_Equations_FieldBurning.VEERG_6_4_1_1__1__MethaneEmissionsFromBurningOfCropResidues_NIRReference: _xlfn.LAMBDA("")
Name AgResidue_Equations_FieldBurning.VEERG_6_4_1_1__1__MethaneEmissionsFromBurningOfCropResidues_Source: _xlfn.LAMBDA("VEERG 2026: 6.4.1.1, Equation (1)")
Name AgResidue_Equations_FieldBurning.VEERG_6_4_1_1__1__MethaneEmissionsFromBurningOfCropResidues_Title: _xlfn.LAMBDA("Methane emissions from the burning of crop residues")
Name AgResidue_Equations_FieldBurning.VEERG_6_4_1_1__1__MethaneEmissionsFromBurningOfCropResidues_Unit: _xlfn.LAMBDA("t CH4")
Name AgResidue_Equations_FieldBurning.VEERG_6_4_1_1__1__MethaneEmissionsFromBurningOfCropResidues_Variable: _xlfn.LAMBDA("ECH4")
Name AgResidue_Equations_FieldBurning.VEERG_6_4_1_1__2__NitrousOxideEmissionsFromBurningOfCropResidues: _xlfn.LAMBDA(_xlpm.Mburnc,_xlpm.NCAGc,_xlpm.EFN2O,_xlpm.CN2O, _xlpm.Mburnc * _xlpm.NCAGc * _xlpm.EFN2O * _xlpm.CN2O * 10 ^ (-3))
Name AgResidue_Equations_FieldBurning.VEERG_6_4_1_1__2__NitrousOxideEmissionsFromBurningOfCropResidues_FunctionName: _xlfn.LAMBDA("VEERG_6_4_1_1__2__NitrousOxideEmissionsFromBurningOfCropResidues")
Name AgResidue_Equations_FieldBurning.VEERG_6_4_1_1__2__NitrousOxideEmissionsFromBurningOfCropResidues_LatexEquation: _xlfn.LAMBDA("E_{N2O}=\sum_{c}(M_{burn,c}\times NC_{AGc}\times EF_{N2O}\times C_{N2O}\times 10^{-3})")
Name AgResidue_Equations_FieldBurning.VEERG_6_4_1_1__2__NitrousOxideEmissionsFromBurningOfCropResidues_NIRReference: _xlfn.LAMBDA("")
Name AgResidue_Equations_FieldBurning.VEERG_6_4_1_1__2__NitrousOxideEmissionsFromBurningOfCropResidues_Source: _xlfn.LAMBDA("VEERG 2026: 6.4.1.1, Equation (2)")
Name AgResidue_Equations_FieldBurning.VEERG_6_4_1_1__2__NitrousOxideEmissionsFromBurningOfCropResidues_Title: _xlfn.LAMBDA("Nitrous oxide emissions from the burning of crop residues")
Name AgResidue_Equations_FieldBurning.VEERG_6_4_1_1__2__NitrousOxideEmissionsFromBurningOfCropResidues_Unit: _xlfn.LAMBDA("t N2O")
Name AgResidue_Equations_FieldBurning.VEERG_6_4_1_1__2__NitrousOxideEmissionsFromBurningOfCropResidues_Variable: _xlfn.LAMBDA("EN2O")
Name AgResidue_Equations_FieldBurning.VEERG_6_4_1_1__3__MassOfCropResidueBurnt: _xlfn.LAMBDA(_xlpm.Pc,_xlpm.RAGc,_xlpm.Sc,_xlpm.DMc,_xlpm.Zc,_xlpm.Fc, _xlpm.Pc * _xlpm.RAGc * _xlpm.Sc * _xlpm.DMc * _xlpm.Zc * _xlpm.Fc)
Name AgResidue_Equations_FieldBurning.VEERG_6_4_1_1__3__MassOfCropResidueBurnt_FunctionName: _xlfn.LAMBDA("VEERG_6_4_1_1__3__MassOfCropResidueBurnt")
Name AgResidue_Equations_FieldBurning.VEERG_6_4_1_1__3__MassOfCropResidueBurnt_LatexEquation: _xlfn.LAMBDA("M_{burn,c}=P_{c}\times R_{AGc}\times S_{c}\times DM_{c}\times Z_{c}\times F_{c}")
Name AgResidue_Equations_FieldBurning.VEERG_6_4_1_1__3__MassOfCropResidueBurnt_NIRReference: _xlfn.LAMBDA("")
Name AgResidue_Equations_FieldBurning.VEERG_6_4_1_1__3__MassOfCropResidueBurnt_Source: _xlfn.LAMBDA("VEERG 2026: 6.4.1.1, Equation (3)")
Name AgResidue_Equations_FieldBurning.VEERG_6_4_1_1__3__MassOfCropResidueBurnt_Title: _xlfn.LAMBDA("Mass of residue of crop c burnt")
Name AgResidue_Equations_FieldBurning.VEERG_6_4_1_1__3__MassOfCropResidueBurnt_Unit: _xlfn.LAMBDA("kg")
Name AgResidue_Equations_FieldBurning.VEERG_6_4_1_1__3__MassOfCropResidueBurnt_Variable: _xlfn.LAMBDA("Mburnc")
Name AgResidues_Equations_CropResidues.VEERG_6_1_1_1__1__NitrousOxideEmissionsFromCropResidues: _xlfn.LAMBDA(_xlpm.Mc,_xlpm.EFNi,_xlpm.CgN2O, _xlpm.Mc * _xlpm.EFNi * _xlpm.CgN2O * 10 ^ (-3))
Name AgResidues_Equations_CropResidues.VEERG_6_1_1_1__1__NitrousOxideEmissionsFromCropResidues_FunctionName: _xlfn.LAMBDA("VEERG_6_1_1_1__1__NitrousOxideEmissionsFromCropResidues")
Name AgResidues_Equations_CropResidues.VEERG_6_1_1_1__1__NitrousOxideEmissionsFromCropResidues_LatexEquation: _xlfn.LAMBDA("E=\sum_{c}{M_{c}\times EF_{N}\times C_{g,N2O}\times 10^{-3}}")
Name AgResidues_Equations_CropResidues.VEERG_6_1_1_1__1__NitrousOxideEmissionsFromCropResidues_NIRReference: _xlfn.LAMBDA("")
Name AgResidues_Equations_CropResidues.VEERG_6_1_1_1__1__NitrousOxideEmissionsFromCropResidues_Source: _xlfn.LAMBDA("VEERG 2026: 6.1.1.1, Equation (1)")
Name AgResidues_Equations_CropResidues.VEERG_6_1_1_1__1__NitrousOxideEmissionsFromCropResidues_Title: _xlfn.LAMBDA("Nitrous oxide emissions from the return of crop residues across all crops c to the soil")
Name AgResidues_Equations_CropResidues.VEERG_6_1_1_1__1__NitrousOxideEmissionsFromCropResidues_Unit: _xlfn.LAMBDA("t N2O")
Name AgResidues_Equations_CropResidues.VEERG_6_1_1_1__1__NitrousOxideEmissionsFromCropResidues_Variable: _xlfn.LAMBDA("E")
Name AgResidues_Equations_CropResidues.VEERG_6_1_1_1__2__MassOfNitrogenInCropResidues_LatexEquation: _xlfn.LAMBDA("M_{c}=(P_{c}\times R_{AGc}\times(1-F_{c}-FFOD_{c})\times DM_{c}\times NC_{AGc})+(P_{c}\times R_{AGc}\times R_{BGc}\times DM_{c}\times NC_{BGc})")
Name AgResidues_Equations_CropResidues.VEERG_6_1_1_1__2__MassOfNitrogenInCropResidues_NIRReference: _xlfn.LAMBDA("")
Name AgResidues_Equations_CropResidues.VEERG_6_1_1_1__2__MassOfNitrogenInCropResidues_Source: _xlfn.LAMBDA("VEERG 2026: 6.1.1.1, Equation (2)")
Name AgResidues_Equations_CropResidues.VEERG_6_1_1_1__2__MassOfNitrogenInCropResidues_Title: _xlfn.LAMBDA("Mass of nitrogen in crop residues returned to the soil")
Name AgResidues_Equations_CropResidues.VEERG_6_1_1_1__2__MassOfNitrogenInCropResidues_Unit: _xlfn.LAMBDA("kg N")
Name AgResidues_Equations_CropResidues.VEERG_6_1_1_1__2__MassOfNitrogenInCropResidues_Variable: _xlfn.LAMBDA("Mc")
Name AgResidues_Equations_CropResidues.VEERG_6_1_1_2__1__FractionOfCropResidueRemovedBaled: _xlfn.LAMBDA(_xlpm.B,_xlpm.MB,_xlpm.Pc,_xlpm.RAGc, IFERROR((_xlpm.B * _xlpm.MB) / (_xlpm.Pc * _xlpm.RAGc), 0))
Name AgResidues_Equations_CropResidues.VEERG_6_1_1_2__1__FractionOfCropResidueRemovedBaled_LatexEquation: _xlfn.LAMBDA("FFOD_{c,baled}=\frac{B\times M_{B}}{P_{c}\times R_{AG,c}}")
Name AgResidues_Equations_CropResidues.VEERG_6_1_1_2__1__FractionOfCropResidueRemovedBaled_NIRReference: _xlfn.LAMBDA("")
Name AgResidues_Equations_CropResidues.VEERG_6_1_1_2__1__FractionOfCropResidueRemovedBaled_Source: _xlfn.LAMBDA("VEERG 2026: 6.1.1.2, Equation (1)")
Name AgResidues_Equations_CropResidues.VEERG_6_1_1_2__1__FractionOfCropResidueRemovedBaled_Title: _xlfn.LAMBDA("Fraction of crop residue that is removed for crop c, calculated where residues are baled")
Name AgResidues_Equations_CropResidues.VEERG_6_1_1_2__1__FractionOfCropResidueRemovedBaled_Unit: _xlfn.LAMBDA("dimensionless")
Name AgResidues_Equations_CropResidues.VEERG_6_1_1_2__1__FractionOfCropResidueRemovedBaled_Variable: _xlfn.LAMBDA("FFODcbaled")
Name AgResidues_Equations_CropResidues.VEERG_6_1_1_2__1__FractionOfCropResidueRemovedBaled_Variation: _xlfn.LAMBDA("VARIATION FROM SOURCE: Added 'baled' to variable subscript")
Name AgResidues_Equations_CropResidues.VEERG_6_1_1_2__1a__FractionOfCropResidueRemoved: _xlfn.LAMBDA(_xlpm.FFODcbaled,_xlpm.FFODcother, _xlpm.FFODcbaled + _xlpm.FFODcother)
Name AgResidues_Equations_CropResidues.VEERG_6_1_1_2__1a__FractionOfCropResidueRemoved_LatexEquation: _xlfn.LAMBDA("FFOD_{c} = FFOD_{c,baled} + FFOD_{c,other}")
Name AgResidues_Equations_CropResidues.VEERG_6_1_1_2__1a__FractionOfCropResidueRemoved_NIRReference: _xlfn.LAMBDA("")
Name AgResidues_Equations_CropResidues.VEERG_6_1_1_2__1a__FractionOfCropResidueRemoved_Source: _xlfn.LAMBDA("")
Name AgResidues_Equations_CropResidues.VEERG_6_1_1_2__1a__FractionOfCropResidueRemoved_Title: _xlfn.LAMBDA("Fraction of crop residue that is removed for crop c")
Name AgResidues_Equations_CropResidues.VEERG_6_1_1_2__1a__FractionOfCropResidueRemoved_Unit: _xlfn.LAMBDA("dimensionless")
Name AgResidues_Equations_CropResidues.VEERG_6_1_1_2__1a__FractionOfCropResidueRemoved_Variable: _xlfn.LAMBDA("FFODc")
Name AgResidues_Equations_CropResidues.VEERG_6_1_1_2__1a__FractionOfCropResidueRemoved_Variation: _xlfn.LAMBDA("VARIATION FROM SOURCE: Added this equation to accommodate user-defined residue removal other than baling.")
Name AgResidues_Equations_Leaching.VEERG_6_3_1_1__1__LeachingAndRunoffEmissionsCropAndPastureResidue: _xlfn.LAMBDA(_xlpm.Mleachcp,_xlpm.EFleach,_xlpm.CgN2O, _xlpm.Mleachcp * _xlpm.EFleach * _xlpm.CgN2O * 10 ^ (-3))
Name AgResidues_Equations_Leaching.VEERG_6_3_1_1__1__LeachingAndRunoffEmissionsCropAndPastureResidue_LatexEquation: _xlfn.LAMBDA("E_{N2O}=\sum_{c}\sum_{p}(M_{leach,cp}\times EF_{leach}\times Cg_{N2O}\times 10^{-3})")
Name AgResidues_Equations_Leaching.VEERG_6_3_1_1__1__LeachingAndRunoffEmissionsCropAndPastureResidue_NIRReference: _xlfn.LAMBDA("")
Name AgResidues_Equations_Leaching.VEERG_6_3_1_1__1__LeachingAndRunoffEmissionsCropAndPastureResidue_Source: _xlfn.LAMBDA("VEERG 2026: 6.3.1.1, Equation (1)")
Name AgResidues_Equations_Leaching.VEERG_6_3_1_1__1__LeachingAndRunoffEmissionsCropAndPastureResidue_Title: _xlfn.LAMBDA("Nitrous oxide leaching and runoff emissions from crop and pasture residues returned to the soil")
Name AgResidues_Equations_Leaching.VEERG_6_3_1_1__1__LeachingAndRunoffEmissionsCropAndPastureResidue_Unit: _xlfn.LAMBDA("t N2O")

Sheet Input - Site
A1: #VALUE! | C1: Input - Site
A3: =HYPERLINK("#'Home'!A1", "Home") -> Home
A4: =HYPERLINK("#'Overview'!A1", "Overview") -> Overview
A5: =HYPERLINK("#'Results'!A1", "Results") -> Results | D5: Your business
A7: INPUTS | D7: Farm name | E7: Test Farms
A8: =HYPERLINK("#'Input - Electricity'!A1", "Electricity") -> Electricity | D8: Reporting entity name | E8: Test Farms Pty Ltd
A10: CALCULATIONS | D10: 💡An 'Emissions accounting period' is a 12 month period where the business can report on the emissions, and is typically the same as the business' financial accounting period.
A11: =HYPERLINK("#'14.1.1-2 Purchased electricity'!A1", "14.1.1-2 Purchased electricity") -> 14.1.1-2 Purchased electricity
D12: Emissions calculation period start date | E12: 45292 | F12: ← DD/MM/YYYY or DD Month YYYY
A13: APPENDICES | D13: Emissions calculation period end date | E13: =DATE(YEAR(E12)+1,MONTH(E12),DAY(E12))-1 -> 45657 | F13: ← Automatically calculated, 12 months after start date
A14: =HYPERLINK("#'Constants - Electricity'!A1", "Constants - Electricity") -> Constants - Electricity
A15: =HYPERLINK("#'Constants - Common'!A1", "Constants - Common") -> Constants - Common
D16: Location and climate
D18: Location information is used to reference some region and climate-specific emission factors
D19: Tip: Use the web-based GAF Location Helper tool to easily get region and climate information. You will need an internet connection to use the GAF Location Helper.
D21: State | E21: ACT | F21: ← Please select
D22: Region (ABS Statistical area level 4) if state is WA | E22: Western Australia - Outback (South) | F22: ← Please select

Sheet Input - Fertiliser
A1: #VALUE! | C1: Input - Fertiliser
A3: =HYPERLINK("#'Home'!A1", "Home") -> Home
A4: =HYPERLINK("#'Overview'!A1", "Overview") -> Overview
A5: =HYPERLINK("#'Results'!A1", "Results") -> Results
D6: Production system | E6: Crop | F6: ← Please select
A7: INPUTS | D7: Crop type | E7: Grains | F7: ← Please select
A8: =HYPERLINK("#'Input - Site'!A1", "Site") -> Site | D8: Irrigation method | E8: Drip irrigation | F8: ← Please select
A9: =HYPERLINK("#'Input - Fertiliser'!A1", "Fertiliser") -> Fertiliser | D9: Area under cropping | E9: 100 | F9: hectares
A11: CALCULATIONS | D11: Inorganic fertiliser applied
A12: =HYPERLINK("#'5.1.1.1-2 Inorganic Fert N2O'!A1", "5.1.1.1-2 Inorganic Fert N2O") -> 5.1.1.1-2 Inorganic Fert N2O
A13: =HYPERLINK("#'5.1.1.3-4 Inorganic fert CO2'!A1", "5.1.1.3-4 Inorganic fert CO2") -> 5.1.1.3-4 Inorganic fert CO2 | D13: 💡You can add more rows to tables by right-clicking on the table and selecting "Insert > Table rows above/below".
A14: =HYPERLINK("#'5.2.1.1-2 Organic Fert N2O'!A1", "5.2.1.1-2 Organic Fert N2O") -> 5.2.1.1-2 Organic Fert N2O | D14: 💡The application area is the same as the area under pasture / cropping by default. You can edit it if the application area is different.
A15: =HYPERLINK("#'5.3.1.1-2 Lime CO2'!A1", "5.3.1.1-2 Lime CO2") -> 5.3.1.1-2 Lime CO2
A16: =HYPERLINK("#'5.4.1.1-4 Atmos deposition'!A1", "5.4.1.1-4 Atmos deposition") -> 5.4.1.1-4 Atmos deposition | D16: Branded fertiliser products
A17: =HYPERLINK("#'5.5.1.1-2 Leaching and runoff'!A1", "5.5.1.1-2 Leaching and runoff") -> 5.5.1.1-2 Leaching and runoff | D17: Product (select) | E17: Amount applied per hectare | F17: Application unit | G17: Density | H17: Application area (ha) | I17: Total applied (kg) | J17: Ingredient 1 | K17: Ingredient 1 percent | L17: Ingredient 2 | M17: Ingredient 2 percent | N17: Ingredient 3 | O17: Ingredient 3 percent | P17: Ingredient 4 | Q17: Ingredient 4 percent | R17: Ingredient 5 | S17: Ingredient 5 percent | T17: Ingredient 6 | U17: Ingredient 6 percent | V17: N application rate (kg/ha) | W17: Urea source | X17: Ammonia source
D18: CoRoN 12-0-10 | E18: 100 | F18: =_xlfn.XLOOKUP(Table_Input_InorganicFertiliser_Brands[[#This Row],[Product (select)]],FertiliserProducts[Product name],FertiliserProducts[Unit]) -> L | G18: =_xlfn.XLOOKUP(Table_Input_InorganicFertiliser_Brands[[#This Row],[Product (select)]],FertiliserProducts[Product name],FertiliserProducts[Density / gravity]) -> 1.215 | H18: =$E$9 -> 100 | I18: =(Table_Input_InorganicFertiliser_Brands[[#This Row],[Amount applied per hectare]]*Table_Input_InorganicFertiliser_Brands[[#This Row],[Density]])*Table_Input_InorganicFertiliser_Brands[[#This Row],[Application area (ha)]] -> 12150 | J18: {=Fertiliser_InputFunctions.Fertiliser_FertiliserProductLookup(Table_Input_InorganicFertiliser_Brands[[#This Row],[Product (select)]], Table_Input_InorganicFertiliser_Brands[[#Headers],[Ingredient 1]], FertiliserProducts[#Data], FertiliserProducts[Product name], FertiliserProducts[#Headers])} -> Urea | K18: {=Fertiliser_InputFunctions.Fertiliser_FertiliserProductLookup(Table_Input_InorganicFertiliser_Brands[[#This Row],[Product (select)]], Table_Input_InorganicFertiliser_Brands[[#Headers],[Ingredient 1 percent]], FertiliserProducts[#Data], FertiliserProducts[Product name], FertiliserProducts[#Headers])} -> 0.19565217 | L18: {=Fertiliser_InputFunctions.Fertiliser_FertiliserProductLookup(Table_Input_InorganicFertiliser_Brands[[#This Row],[Product (select)]], Table_Input_InorganicFertiliser_Brands[[#Headers],[Ingredient 2]], FertiliserProducts[#Data], FertiliserProducts[Product name], FertiliserProducts[#Headers])} -> Potassium - Generic | M18: {=Fertiliser_InputFunctions.Fertiliser_FertiliserProductLookup(Table_Input_InorganicFertiliser_Brands[[#This Row],[Product (select)]], Table_Input_InorganicFertiliser_Brands[[#Headers],[Ingredient 2 percent]], FertiliserProducts[#Data], FertiliserProducts[Product name], FertiliserProducts[#Headers])} -> 0.1 | N18: {=Fertiliser_InputFunctions.Fertiliser_FertiliserProductLookup(Table_Input_InorganicFertiliser_Brands[[#This Row],[Product (select)]], Table_Input_InorganicFertiliser_Brands[[#Headers],[Ingredient 3]], FertiliserProducts[#Data], FertiliserProducts[Product name], FertiliserProducts[#Headers])} -> Nitrogen - Generic | O18: {=Fertiliser_InputFunctions.Fertiliser_FertiliserProductLookup(Table_Input_InorganicFertiliser_Brands[[#This Row],[Product (select)]], Table_Input_InorganicFertiliser_Brands[[#Headers],[Ingredient 3 percent]], FertiliserProducts[#Data], FertiliserProducts[Product name], FertiliserProducts[#Headers])} -> 0.03 | P18: {=Fertiliser_InputFunctions.Fertiliser_FertiliserProductLookup(Table_Input_InorganicFertiliser_Brands[[#This Row],[Product (select)]], Table_Input_InorganicFertiliser_Brands[[#Headers],[Ingredient 4]], FertiliserProducts[#Data], FertiliserProducts[Product name], FertiliserProducts[#Headers])} -> Boron | Q18: {=Fertiliser_InputFunctions.Fertiliser_FertiliserProductLookup(Table_Input_InorganicFertiliser_Brands[[#This Row],[Product (select)]], Table_Input_InorganicFertiliser_Brands[[#Headers],[Ingredient 4 percent]], FertiliserProducts[#Data], FertiliserProducts[Product name], FertiliserProducts[#Headers])} -> 0.005 | R18: {=Fertiliser_InputFunctions.Fertiliser_FertiliserProductLookup(Table_Input_InorganicFertiliser_Brands[[#This Row],[Product (select)]], Table_Input_InorganicFertiliser_Brands[[#Headers],[Ingredient 5]], FertiliserProducts[#Data], FertiliserProducts[Product name], FertiliserProducts[#Headers])} | S18: {=Fertiliser_InputFunctions.Fertiliser_FertiliserProductLookup(Table_Input_InorganicFertiliser_Brands[[#This Row],[Product (select)]], Table_Input_InorganicFertiliser_Brands[[#Headers],[Ingredient 5 percent]], FertiliserProducts[#Data], FertiliserProducts[Product name], FertiliserProducts[#Headers])} | T18: {=Fertiliser_InputFunctions.Fertiliser_FertiliserProductLookup(Table_Input_InorganicFertiliser_Brands[[#This Row],[Product (select)]], Table_Input_InorganicFertiliser_Brands[[#Headers],[Ingredient 6]], FertiliserProducts[#Data], FertiliserProducts[Product name], FertiliserProducts[#Headers])} | U18: {=Fertiliser_InputFunctions.Fertiliser_FertiliserProductLookup(Table_Input_InorganicFertiliser_Brands[[#This Row],[Product (select)]], Table_Input_InorganicFertiliser_Brands[[#Headers],[Ingredient 6 percent]], FertiliserProducts[#Data], FertiliserProducts[Product name], FertiliserProducts[#Headers])} | V18: =(Table_Input_InorganicFertiliser_Brands[[#This Row],[Amount applied per hectare]]*Table_Input_InorganicFertiliser_Brands[[#This Row],[Density]])*(IFERROR((_xlfn.XLOOKUP(Table_Input_InorganicFertiliser_Brands[[#This Row],[Ingredient 1]], Table_Fertiliser_ChemicalCompounds[Fertiliser type f],Table_Fertiliser_ChemicalCompounds[FNinorganic f])*Table_Input_InorganicFertiliser_Brands[[#This Row],[Ingredient 1 percent]]), 0)+ IFERROR((_xlfn.XLOOKUP(Table_Input_InorganicFertiliser_Brands[[#This Row],[Ingredient 2]],Table_Fertiliser_ChemicalCompounds[Fertiliser type f],Table_Fertiliser_ChemicalCompounds[FNinorganic f])*Table_Input_InorganicFertiliser_Brands[[#This Row],[Ingredient 2 percent]]), 0)+ IFERROR((_xlfn.XLOOKUP(Table_Input_InorganicFertiliser_Brands[[#This Row],[Ingredient 3]],Table_Fertiliser_ChemicalCompounds[Fertiliser type f],Table_Fertiliser_ChemicalCompounds[FNinorganic f])*Table_Input_InorganicFertiliser_Brands[[#This Row],[Ingredient 3 percent]]), 0)+ IFERROR((_xlfn.XLOOKUP(Table_Input_InorganicFertiliser_Brands[[#This Row],[Ingredient 4]],Table_Fertiliser_ChemicalCompounds[Fertiliser type f],Table_Fertiliser_ChemicalCompounds[FNinorganic f])*Table_Input_InorganicFertiliser_Brands[[#This Row],[Ingredient 4 percent]]), 0)+ IFERROR((_xlfn.XLOOKUP(Table_Input_InorganicFertiliser_Brands[[#This Row],[Ingredient 5]],Table_Fertiliser_ChemicalCompounds[Fertiliser type f],Table_Fertiliser_ChemicalCompounds[FNinorganic f])*Table_Input_InorganicFertiliser_Brands[[#This Row],[Ingredient 5 percent]]), 0)+ IFERROR((_xlfn.XLOOKUP(Table_Input_InorganicFertiliser_Brands[[#This Row],[Ingredient 6]],Table_Fertiliser_ChemicalCompounds[Fertiliser type f],Table_Fertiliser_ChemicalCompounds[FNinorganic f])*Table_Input_InorganicFertiliser_Brands[[#This Row],[Ingredient 6 percent]]), 0)) -> 14.58 | W18: =_xlfn.XLOOKUP(Table_Input_InorganicFertiliser_Brands[[#This Row],[Product (select)]],FertiliserProducts[Product name],FertiliserProducts[Urea source]) | X18: =_xlfn.XLOOKUP(Table_Input_InorganicFertiliser_Brands[[#This Row],[Product (select)]],FertiliserProducts[Product name],FertiliserProducts[Ammonia source])
A19: APPENDICES | D19: CoRoN 12-0-10 | E19: 200 | F19: =_xlfn.XLOOKUP(Table_Input_InorganicFertiliser_Brands[[#This Row],[Product (select)]],FertiliserProducts[Product name],FertiliserProducts[Unit]) -> L | G19: =_xlfn.XLOOKUP(Table_Input_InorganicFertiliser_Brands[[#This Row],[Product (select)]],FertiliserProducts[Product name],FertiliserProducts[Density / gravity]) -> 1.215 | H19: 0 | I19: =(Table_Input_InorganicFertiliser_Brands[[#This Row],[Amount applied per hectare]]*Table_Input_InorganicFertiliser_Brands[[#This Row],[Density]])*Table_Input_InorganicFertiliser_Brands[[#This Row],[Application area (ha)]] -> 0 | J19: {=Fertiliser_InputFunctions.Fertiliser_FertiliserProductLookup(Table_Input_InorganicFertiliser_Brands[[#This Row],[Product (select)]], Table_Input_InorganicFertiliser_Brands[[#Headers],[Ingredient 1]], FertiliserProducts[#Data], FertiliserProducts[Product name], FertiliserProducts[#Headers])} -> Urea | K19: {=Fertiliser_InputFunctions.Fertiliser_FertiliserProductLookup(Table_Input_InorganicFertiliser_Brands[[#This Row],[Product (select)]], Table_Input_InorganicFertiliser_Brands[[#Headers],[Ingredient 1 percent]], FertiliserProducts[#Data], FertiliserProducts[Product name], FertiliserProducts[#Headers])} -> 0.19565217 | L19: {=Fertiliser_InputFunctions.Fertiliser_FertiliserProductLookup(Table_Input_InorganicFertiliser_Brands[[#This Row],[Product (select)]], Table_Input_InorganicFertiliser_Brands[[#Headers],[Ingredient 2]], FertiliserProducts[#Data], FertiliserProducts[Product name], FertiliserProducts[#Headers])} -> Potassium - Generic | M19: {=Fertiliser_InputFunctions.Fertiliser_FertiliserProductLookup(Table_Input_InorganicFertiliser_Brands[[#This Row],[Product (select)]], Table_Input_InorganicFertiliser_Brands[[#Headers],[Ingredient 2 percent]], FertiliserProducts[#Data], FertiliserProducts[Product name], FertiliserProducts[#Headers])} -> 0.1 | N19: {=Fertiliser_InputFunctions.Fertiliser_FertiliserProductLookup(Table_Input_InorganicFertiliser_Brands[[#This Row],[Product (select)]], Table_Input_InorganicFertiliser_Brands[[#Headers],[Ingredient 3]], FertiliserProducts[#Data], FertiliserProducts[Product name], FertiliserProducts[#Headers])} -> Nitrogen - Generic | O19: {=Fertiliser_InputFunctions.Fertiliser_FertiliserProductLookup(Table_Input_InorganicFertiliser_Brands[[#This Row],[Product (select)]], Table_Input_InorganicFertiliser_Brands[[#Headers],[Ingredient 3 percent]], FertiliserProducts[#Data], FertiliserProducts[Product name], FertiliserProducts[#Headers])} -> 0.03 | P19: {=Fertiliser_InputFunctions.Fertiliser_FertiliserProductLookup(Table_Input_InorganicFertiliser_Brands[[#This Row],[Product (select)]], Table_Input_InorganicFertiliser_Brands[[#Headers],[Ingredient 4]], FertiliserProducts[#Data], FertiliserProducts[Product name], FertiliserProducts[#Headers])} -> Boron | Q19: {=Fertiliser_InputFunctions.Fertiliser_FertiliserProductLookup(Table_Input_InorganicFertiliser_Brands[[#This Row],[Product (select)]], Table_Input_InorganicFertiliser_Brands[[#Headers],[Ingredient 4 percent]], FertiliserProducts[#Data], FertiliserProducts[Product name], FertiliserProducts[#Headers])} -> 0.005 | R19: {=Fertiliser_InputFunctions.Fertiliser_FertiliserProductLookup(Table_Input_InorganicFertiliser_Brands[[#This Row],[Product (select)]], Table_Input_InorganicFertiliser_Brands[[#Headers],[Ingredient 5]], FertiliserProducts[#Data], FertiliserProducts[Product name], FertiliserProducts[#Headers])} | S19: {=Fertiliser_InputFunctions.Fertiliser_FertiliserProductLookup(Table_Input_InorganicFertiliser_Brands[[#This Row],[Product (select)]], Table_Input_InorganicFertiliser_Brands[[#Headers],[Ingredient 5 percent]], FertiliserProducts[#Data], FertiliserProducts[Product name], FertiliserProducts[#Headers])} | T19: {=Fertiliser_InputFunctions.Fertiliser_FertiliserProductLookup(Table_Input_InorganicFertiliser_Brands[[#This Row],[Product (select)]], Table_Input_InorganicFertiliser_Brands[[#Headers],[Ingredient 6]], FertiliserProducts[#Data], FertiliserProducts[Product name], FertiliserProducts[#Headers])} | U19: {=Fertiliser_InputFunctions.Fertiliser_FertiliserProductLookup(Table_Input_InorganicFertiliser_Brands[[#This Row],[Product (select)]], Table_Input_InorganicFertiliser_Brands[[#Headers],[Ingredient 6 percent]], FertiliserProducts[#Data], FertiliserProducts[Product name], FertiliserProducts[#Headers])} | V19: =(Table_Input_InorganicFertiliser_Brands[[#This Row],[Amount applied per hectare]]*Table_Input_InorganicFertiliser_Brands[[#This Row],[Density]])*(IFERROR((_xlfn.XLOOKUP(Table_Input_InorganicFertiliser_Brands[[#This Row],[Ingredient 1]], Table_Fertiliser_ChemicalCompounds[Fertiliser type f],Table_Fertiliser_ChemicalCompounds[FNinorganic f])*Table_Input_InorganicFertiliser_Brands[[#This Row],[Ingredient 1 percent]]), 0)+ IFERROR((_xlfn.XLOOKUP(Table_Input_InorganicFertiliser_Brands[[#This Row],[Ingredient 2]],Table_Fertiliser_ChemicalCompounds[Fertiliser type f],Table_Fertiliser_ChemicalCompounds[FNinorganic f])*Table_Input_InorganicFertiliser_Brands[[#This Row],[Ingredient 2 percent]]), 0)+ IFERROR((_xlfn.XLOOKUP(Table_Input_InorganicFertiliser_Brands[[#This Row],[Ingredient 3]],Table_Fertiliser_ChemicalCompounds[Fertiliser type f],Table_Fertiliser_ChemicalCompounds[FNinorganic f])*Table_Input_InorganicFertiliser_Brands[[#This Row],[Ingredient 3 percent]]), 0)+ IFERROR((_xlfn.XLOOKUP(Table_Input_InorganicFertiliser_Brands[[#This Row],[Ingredient 4]],Table_Fertiliser_ChemicalCompounds[Fertiliser type f],Table_Fertiliser_ChemicalCompounds[FNinorganic f])*Table_Input_InorganicFertiliser_Brands[[#This Row],[Ingredient 4 percent]]), 0)+ IFERROR((_xlfn.XLOOKUP(Table_Input_InorganicFertiliser_Brands[[#This Row],[Ingredient 5]],Table_Fertiliser_ChemicalCompounds[Fertiliser type f],Table_Fertiliser_ChemicalCompounds[FNinorganic f])*Table_Input_InorganicFertiliser_Brands[[#This Row],[Ingredient 5 percent]]), 0)+ IFERROR((_xlfn.XLOOKUP(Table_Input_InorganicFertiliser_Brands[[#This Row],[Ingredient 6]],Table_Fertiliser_ChemicalCompounds[Fertiliser type f],Table_Fertiliser_ChemicalCompounds[FNinorganic f])*Table_Input_InorganicFertiliser_Brands[[#This Row],[Ingredient 6 percent]]), 0)) -> 29.16 | W19: =_xlfn.XLOOKUP(Table_Input_InorganicFertiliser_Brands[[#This Row],[Product (select)]],FertiliserProducts[Product name],FertiliserProducts[Urea source]) | X19: =_xlfn.XLOOKUP(Table_Input_InorganicFertiliser_Brands[[#This Row],[Product (select)]],FertiliserProducts[Product name],FertiliserProducts[Ammonia source])
A20: =HYPERLINK("#'Constants - Fertiliser'!A1", "Constants - Fertiliser") -> Constants - Fertiliser
A21: =HYPERLINK("#'Constants - Common'!A1", "Constants - Common") -> Constants - Common | D21: Custom fertiliser blends
D22: Custom blend name | E22: Amount applied (kg / ha) | F22: Application area (ha) | G22: Total applied (kg) | H22: Ingredient 1 (select) | I22: Ingredient 1 percent | J22: Ingredient 2 | K22: Ingredient 2 percent | L22: Ingredient 3 | M22: Ingredient 3 percent | N22: Ingredient 4 | O22: Ingredient 4 percent | P22: N application rate (kg/ha) | Q22: Urea source | R22: Ammonia source
D23: My first custom blend | E23: 0 | F23: =$E$9 -> 100 | G23: =Table_Input_InorganicFertiliser_Custom[[#This Row],[Amount applied (kg / ha)]]*Table_Input_InorganicFertiliser_Custom[[#This Row],[Application area (ha)]] -> 0 | H23: Ammonia | I23: 0.45 | J23: Calcium nitrate | K23: 0.3 | L23: Potassium - Generic | M23: 0.1 | N23: Sulfur - Generic | O23: 0.1 | P23: =Table_Input_InorganicFertiliser_Custom[[#This Row],[Amount applied (kg / ha)]]* (IFERROR((_xlfn.XLOOKUP(Table_Input_InorganicFertiliser_Custom[[#This Row],[Ingredient 1 (select)]], Table_Fertiliser_ChemicalCompounds[Fertiliser type f],Table_Fertiliser_ChemicalCompounds[FNinorganic f])*Table_Input_InorganicFertiliser_Custom[[#This Row],[Ingredient 1 percent]]), 0) + IFERROR((_xlfn.XLOOKUP(Table_Input_InorganicFertiliser_Custom[[#This Row],[Ingredient 2]], Table_Fertiliser_ChemicalCompounds[Fertiliser type f],Table_Fertiliser_ChemicalCompounds[FNinorganic f])*Table_Input_InorganicFertiliser_Custom[[#This Row],[Ingredient 2 percent]]), 0) + IFERROR((_xlfn.XLOOKUP(Table_Input_InorganicFertiliser_Custom[[#This Row],[Ingredient 3]], Table_Fertiliser_ChemicalCompounds[Fertiliser type f],Table_Fertiliser_ChemicalCompounds[FNinorganic f])*Table_Input_InorganicFertiliser_Custom[[#This Row],[Ingredient 3 percent]]), 0) + IFERROR((_xlfn.XLOOKUP(Table_Input_InorganicFertiliser_Custom[[#This Row],[Ingredient 4]], Table_Fertiliser_ChemicalCompounds[Fertiliser type f],Table_Fertiliser_ChemicalCompounds[FNinorganic f])*Table_Input_InorganicFertiliser_Custom[[#This Row],[Ingredient 4 percent]]), 0) ) -> 0 | Q23: Canada | R23: Canada
E24: 0 | F24: =$E$9 -> 100 | G24: =Table_Input_InorganicFertiliser_Custom[[#This Row],[Amount applied (kg / ha)]]*Table_Input_InorganicFertiliser_Custom[[#This Row],[Application area (ha)]] -> 0 | H24: Urea | I24: 0.9 | J24: Ammonia | K24: 0.1 | P24: =Table_Input_InorganicFertiliser_Custom[[#This Row],[Amount applied (kg / ha)]]* (IFERROR((_xlfn.XLOOKUP(Table_Input_InorganicFertiliser_Custom[[#This Row],[Ingredient 1 (select)]], Table_Fertiliser_ChemicalCompounds[Fertiliser type f],Table_Fertiliser_ChemicalCompounds[FNinorganic f])*Table_Input_InorganicFertiliser_Custom[[#This Row],[Ingredient 1 percent]]), 0) + IFERROR((_xlfn.XLOOKUP(Table_Input_InorganicFertiliser_Custom[[#This Row],[Ingredient 2]], Table_Fertiliser_ChemicalCompounds[Fertiliser type f],Table_Fertiliser_ChemicalCompounds[FNinorganic f])*Table_Input_InorganicFertiliser_Custom[[#This Row],[Ingredient 2 percent]]), 0) + IFERROR((_xlfn.XLOOKUP(Table_Input_InorganicFertiliser_Custom[[#This Row],[Ingredient 3]], Table_Fertiliser_ChemicalCompounds[Fertiliser type f],Table_Fertiliser_ChemicalCompounds[FNinorganic f])*Table_Input_InorganicFertiliser_Custom[[#This Row],[Ingredient 3 percent]]), 0) + IFERROR((_xlfn.XLOOKUP(Table_Input_InorganicFertiliser_Custom[[#This Row],[Ingredient 4]], Table_Fertiliser_ChemicalCompounds[Fertiliser type f],Table_Fertiliser_ChemicalCompounds[FNinorganic f])*Table_Input_InorganicFertiliser_Custom[[#This Row],[Ingredient 4 percent]]), 0) ) -> 0 | Q24: Canada | R24: Canada
D26: Soil amendments
D28: 💡 You can add more rows to the table by right-clicking on the table and selecting "Insert > Table rows above/below".
D29: 💡 'Lime' refers to calcium carbonate - CaCO3. 'Dolomite' refers to calcium magnesium carbonate - CaMg(CO3)2
D30: 💡The application area is the same as the area under pasture / cropping by default. You can edit it if the application area is different.
D31: =IF(MAX(Table_Input_Lime[Total]) > 1, "There can not be more than 100% ingredients in a product. Check the table below.", "")
D32: Product | E32: Amount applied (t/hectare) | F32: Application area (ha) | G32: Total amount applied (t) | H32: Percent Lime CaCO3 | I32: Percent Dolomite CaMg(CO3)2 | J32: Percent Gypsum | K32: Percent Potash | L32: Total
D33: Lime product 1 | E33: 100 | F33: =$E$9 -> 100 | G33: =IFERROR(Table_Input_Lime[[#This Row],[Amount applied (t/hectare)]]*Table_Input_Lime[[#This Row],[Application area (ha)]], 0) -> 10000 | H33: 0.4 | I33: 0.3 | J33: 0.25 | K33: 0.05 | L33: =SUM(Table_Input_Lime[[#This Row],[Percent Lime CaCO3]:[Percent Potash]]) -> 1
D34: Lime product 2 | E34: 100 | F34: =$E$9 -> 100 | G34: =IFERROR(Table_Input_Lime[[#This Row],[Amount applied (t/hectare)]]*Table_Input_Lime[[#This Row],[Application area (ha)]], 0) -> 10000 | I34: 1 | L34: =SUM(Table_Input_Lime[[#This Row],[Percent Lime CaCO3]:[Percent Potash]]) -> 1
D37: Organic fertiliser applied
D39: 💡 You can add more rows to the table by right-clicking on the table and selecting "Insert > Table rows above/below".
D40: 💡The application area is the same as the area under pasture / cropping by default. You can edit it if the application area is different.
D42: Organic fertiliser type (select) | E42: Percentage of N in fertiliser | F42: Amount applied (kg/hectare) | G42: Amount N applied (kg/hectare) | H42: Application area (ha) | I42: Total organic fertliser applied | J42: Total nitrogen applied (kg)
D43: Manure - Other | E43: 0.3 | F43: 10 | G43: =Table_Input_OrganicFertiliser[[#This Row],[Amount applied (kg/hectare)]]*Table_Input_OrganicFertiliser[[#This Row],[Percentage of N in fertiliser]] -> 3 | H43: =$E$9 -> 100 | I43: =Table_Input_OrganicFertiliser[[#This Row],[Amount applied (kg/hectare)]]*Table_Input_OrganicFertiliser[[#This Row],[Application area (ha)]] -> 1000 | J43: =IFERROR(Table_Input_OrganicFertiliser[[#This Row],[Amount N applied (kg/hectare)]]*Table_Input_OrganicFertiliser[[#This Row],[Application area (ha)]], 0) -> 300
A44: =HYPERLINK("#A1", "▲ Back to top") -> ▲ Back to top | D44: Manure - Poultry | E44: 0.25 | F44: 10 | G44: =Table_Input_OrganicFertiliser[[#This Row],[Amount applied (kg/hectare)]]*Table_Input_OrganicFertiliser[[#This Row],[Percentage of N in fertiliser]] -> 2.5 | H44: =$E$9 -> 100 | I44: =Table_Input_OrganicFertiliser[[#This Row],[Amount applied (kg/hectare)]]*Table_Input_OrganicFertiliser[[#This Row],[Application area (ha)]] -> 1000 | J44: =IFERROR(Table_Input_OrganicFertiliser[[#This Row],[Amount N applied (kg/hectare)]]*Table_Input_OrganicFertiliser[[#This Row],[Application area (ha)]], 0) -> 250

Sheet Input - Feed - Dairy
A1: #VALUE! | C1: Input - Purchased feed - Livestock
A3: Home
A4: =HYPERLINK("#'Results'!A1", "Results") -> Results
D5: Supplemental feed
A6: INPUTS
A7: =HYPERLINK("#'Input - Site'!A1", "Site") -> Site | D7: Lick blocks
A8: =HYPERLINK("#'Input - Production'!A1", "Production and outputs") -> Production and outputs | D8: Product | E8: Amount (t)
A9: =HYPERLINK("#'Input - Herd - Dairy'!A1", "Herd - Dairy") -> Herd - Dairy | D9: ='Calcs - Scope 3'!D106 -> Mineral block | E9: 10
A10: =HYPERLINK("#'Input - Feed - Dairy'!A1", "Purchased feed - Livestock") -> Purchased feed - Livestock | D10: ='Calcs - Scope 3'!D107 -> Weaner block | E10: 20
A11: =HYPERLINK("#'Input - Herd - Feedlot'!A1", "Herd - Feedlot") -> Herd - Feedlot | D11: ='Calcs - Scope 3'!D108 -> Dry season mix | E11: 30
A12: =HYPERLINK("#'Input - Pasture'!A1", "Pasture") -> Pasture
A13: =HYPERLINK("#'Input - Grains'!A1", "Crop - Grains") -> Crop - Grains | D13: Feed blends
A14: =HYPERLINK("#'Input - Fert Lime Chem'!A1", "Fertiliser, Lime & Chemicals") -> Fertiliser, Lime & Chemicals | D14: Tip: You can add more rows to the table by right-clicking on the table and selecting "Insert > Table rows above/below".
A15: =HYPERLINK("#'Input - Fuel & Energy'!A1", "Electricity and fuel") -> Electricity and fuel
A16: Waste | D16: Feed blend name | E16: Amount fed (kg) | F16: Ingredient 1 (select) | G16: Ingredient 1 percent | H16: Ingredient 2 (select) | I16: Ingredient 2 percent | J16: Ingredient 3 (select) | K16: Ingredient 3 percent | L16: Ingredient 4 (select) | M16: Ingredient 4 percent | N16: Ingredient 5 (select) | O16: Ingredient 5 percent
A17: Freight and transport | E17: 1200 | F17: Beet pulp | G17: 0.35 | H17: Wheat | I17: 0.22 | J17: Canola oil | K17: 0.12 | L17: Bentonite | M17: 0.05 | N17: Meat meal | O17: 0.02
A18: =HYPERLINK("#'Input - Other Farm Inputs'!A1", "Other farm inputs") -> Other farm inputs | E18: 3456 | F18: Cotton seed | G18: 0.2 | H18: Wheat Bran | I18: 0.2
A19: =HYPERLINK("#'Input - Data quality'!A1", "Data quality") -> Data quality | D19: Hay bales in paddock | E19: 300 | F19: Hay | G19: 1 | H19: Hay | I19: 0.2
A21: CALCULATIONS
A22: N2O MMS
A23: Enteric methane | D23: Feed blends Aquaculture and fishery
A24: =HYPERLINK("#'Calcs - Fert Lime'!A1", "Fertiliser & soil amendments") -> Fertiliser & soil amendments | D24: Tip: You can add more rows to the table by right-clicking on the table and selecting "Insert > Table rows above/below".
A25: =HYPERLINK("#'Calcs - Residue mgmt - Crop'!A1", "Residue management - Crop") -> Residue management - Crop | D25: Feed blend name | E25: Amount fed (kg) | F25: Ingredient 1 (select) | G25: Ingredient 1 percent | H25: Ingredient 2 (select) | I25: Ingredient 2 percent | J25: Ingredient 3 (select) | K25: Ingredient 3 percent | L25: Ingredient 4 (select) | M25: Ingredient 4 percent | N25: Ingredient 5 (select) | O25: Ingredient 5 percent
A26: =HYPERLINK("#'Calcs - Residue mgmt - Pasture'!A1", "Residue management - Pasture") -> Residue management - Pasture | E26: 1200 | F26: Whole Fish | G26: 0.35 | H26: High Animal Protein Formulated Feed | I26: 0.22 | J26: Cereal grain | K26: 0.12 | L26: Squid | M26: 0.05 | N26: Whole Sardines | O26: 0.02
A27: =HYPERLINK("#'Calcs - Field burning'!A1", "Field burning - Crop") -> Field burning - Crop | E27: 1200 | F27: Squid | G27: 1
A28: =HYPERLINK("#'Calcs - Fuel'!A1", "Fuel") -> Fuel
A29: =HYPERLINK("#'Calcs - Electricity'!A1", "Electricity") -> Electricity
A30: =HYPERLINK("#'Calcs - Refrigerants'!A1", "Refrigerants") -> Refrigerants
A31: Waste
A32: Freight and transport
A33: =HYPERLINK("#'Calcs - Scope 3'!A1", "Purchased goods scope 3") -> Purchased goods scope 3
A35: APPENDICES
A36: =HYPERLINK("#'Constants - Common'!A1", "Constants - Common") -> Constants - Common
A37: =HYPERLINK("#'Constants - Cropping'!A1", "Constants - Cropping") -> Constants - Cropping
A38: =HYPERLINK("#'Constants - Livestock'!A1", "Constants - Livestock") -> Constants - Livestock
A39: =HYPERLINK("#'Constants - Dairy'!A1", "Constants - Dairy") -> Constants - Dairy
A40: Sources & acknowledgements

Sheet Input - Other Farm Inputs
A1: #VALUE! | C1: Input - Other farm inputs
A3: Home
A4: =HYPERLINK("#'Results'!A1", "Results") -> Results
A6: INPUTS | D6: ='Calcs - Scope 3'!D198 -> CO2 for carbonation | E6: 100 | F6: ='Calcs - Scope 3'!F198 -> t
A7: =HYPERLINK("#'Input - Site'!A1", "Site") -> Site | D7: ='Calcs - Scope 3'!D199 -> Livestock antibiotics | E7: 200 | F7: ='Calcs - Scope 3'!F199 -> t
A8: =HYPERLINK("#'Input - Production'!A1", "Production and outputs") -> Production and outputs | D8: ='Calcs - Scope 3'!D200 -> Nylon netting for horticulture | E8: 300 | F8: ='Calcs - Scope 3'!F200 -> t
A9: =HYPERLINK("#'Input - Herd - Dairy'!A1", "Herd - Dairy") -> Herd - Dairy | D9: ='Calcs - Scope 3'!D201 -> Pallets - Wood | E9: 400 | F9: ='Calcs - Scope 3'!F201 -> t
A10: =HYPERLINK("#'Input - Feed - Dairy'!A1", "Purchased feed - Livestock") -> Purchased feed - Livestock | D10: ='Calcs - Scope 3'!D202 -> Pallets - Plastic | E10: 500 | F10: ='Calcs - Scope 3'!F202 -> t
A11: =HYPERLINK("#'Input - Herd - Feedlot'!A1", "Herd - Feedlot") -> Herd - Feedlot | D11: ='Calcs - Scope 3'!D203 -> Livestock tags | E11: 600 | F11: ='Calcs - Scope 3'!F203 -> t
A12: =HYPERLINK("#'Input - Pasture'!A1", "Pasture") -> Pasture | D12: Seed (general crop and pasture) | E12: 700 | F12: ='Calcs - Scope 3'!F187 -> t
A13: =HYPERLINK("#'Input - Grains'!A1", "Crop - Grains") -> Crop - Grains | D13: Seedlings (forestry, horticulture, environmental) | E13: 800 | F13: ='Calcs - Scope 3'!F188 -> Seedling
A14: =HYPERLINK("#'Input - Fert Lime Chem'!A1", "Fertiliser, Lime & Chemicals") -> Fertiliser, Lime & Chemicals
A15: =HYPERLINK("#'Input - Fuel & Energy'!A1", "Electricity and fuel") -> Electricity and fuel
A16: Waste
A17: Freight and transport | D17: Agrochemicals applied
A18: =HYPERLINK("#'Input - Other Farm Inputs'!A1", "Other farm inputs") -> Other farm inputs
A19: =HYPERLINK("#'Input - Data quality'!A1", "Data quality") -> Data quality | D19: 💡You can add more rows to the table by right-clicking on the table and selecting "Insert > Table rows above/below".
D20: 💡You can find specific product information in the Australian Government's 'PubCRIS' database search. | H20: Application area | I20: 100
A21: CALCULATIONS | D21: Click here to find instructions on how to use the PubCRIS database
A22: N2O MMS
A23: Enteric methane | D23: Product | E23: Amount applied per ha | F23: Application unit (select) | G23: Application area (ha) | H23: Total applied | I23: Active ingredient 1 (select) | J23: Active ingredient 1 unit (select) | K23: Active ingredient 1 amount | L23: Active ingredient 2 (select) | M23: Active ingredient 2 unit (select) | N23: Active ingredient 2 amount | O23: Active ingredient 3 (select) | P23: Active ingredient 3 unit (select) | Q23: Active ingredient 3 amount
A24: =HYPERLINK("#'Calcs - Fert Lime'!A1", "Fertiliser & soil amendments") -> Fertiliser & soil amendments | D24: RELYON DI-PAR 250 SC HERBICIDE | E24: 10 | F24: litre / hectare | G24: =I20 -> 100 | H24: =Table_Input_Agrochemicals[[#This Row],[Amount applied per ha]]*Table_Input_Agrochemicals[[#This Row],[Application area (ha)]] -> 1000 | I24: Generic Insecticide | J24: Grams / kg | K24: 115 | L24: Generic Insecticide | M24: Grams / litre | N24: 135 | O24: Paraquat, diquat | P24: Grams / litre | Q24: 200
A25: =HYPERLINK("#'Calcs - Residue mgmt - Crop'!A1", "Residue management - Crop") -> Residue management - Crop
A26: =HYPERLINK("#'Calcs - Residue mgmt - Pasture'!A1", "Residue management - Pasture") -> Residue management - Pasture | D26: Tip: You can add more rows to the table by right-clicking on the table and selecting "Insert > Table rows above/below".
A27: =HYPERLINK("#'Calcs - Field burning'!A1", "Field burning - Crop") -> Field burning - Crop
A28: =HYPERLINK("#'Calcs - Fuel'!A1", "Fuel") -> Fuel | D28: Packaging name | E28: Packaging component (select) | F28: Quantity purchased | G28: Quantity unit
A29: =HYPERLINK("#'Calcs - Electricity'!A1", "Electricity") -> Electricity | D29: Reisling bottle | E29: Polypropylene (PP) | F29: 100 | G29: {=Common_InputFunctions.Utility_LookupValueInTable(Table_Input_Packaging[[#This Row],[Packaging component (select)]], Table_Scope3_Packaging[Packaging component],Table_Scope3_Packaging[Quantity Unit])} -> kg
A30: =HYPERLINK("#'Calcs - Refrigerants'!A1", "Refrigerants") -> Refrigerants | E30: Polypropylene (PP) | F30: 1000 | G30: {=Common_InputFunctions.Utility_LookupValueInTable(Table_Input_Packaging[[#This Row],[Packaging component (select)]], Table_Scope3_Packaging[Packaging component],Table_Scope3_Packaging[Quantity Unit])} -> kg
A31: Waste | E31: Plastic packaging | F31: 456 | G31: {=Common_InputFunctions.Utility_LookupValueInTable(Table_Input_Packaging[[#This Row],[Packaging component (select)]], Table_Scope3_Packaging[Packaging component],Table_Scope3_Packaging[Quantity Unit])} -> kg
A32: Freight and transport | E32: Cardboard | F32: 1234 | G32: {=Common_InputFunctions.Utility_LookupValueInTable(Table_Input_Packaging[[#This Row],[Packaging component (select)]], Table_Scope3_Packaging[Packaging component],Table_Scope3_Packaging[Quantity Unit])} -> kg
A33: =HYPERLINK("#'Calcs - Scope 3'!A1", "Purchased goods scope 3") -> Purchased goods scope 3
A35: APPENDICES | D35: Cleaning chemicals
A36: =HYPERLINK("#'Constants - Common'!A1", "Constants - Common") -> Constants - Common
A37: =HYPERLINK("#'Constants - Cropping'!A1", "Constants - Cropping") -> Constants - Cropping | D37: Tip: You can add more rows to the table by right-clicking on the table and selecting "Insert > Table rows above/below".
A38: =HYPERLINK("#'Constants - Livestock'!A1", "Constants - Livestock") -> Constants - Livestock
A39: =HYPERLINK("#'Constants - Dairy'!A1", "Constants - Dairy") -> Constants - Dairy | D39: Chemical name | E39: Type | F39: Quantity purchased (L)
A40: Sources & acknowledgements | E40: Detergent | F40: 145
E41: Detergent | F41: 3456
E42: Acid | F42: 333
D43: White king | E43: Bleach | F43: 12
...

Sheet Input - Fuel
A1: #VALUE! | C1: Input - Fuel
A3: =HYPERLINK("#'Home'!A1", "Home") -> Home
A4: =HYPERLINK("#'Overview'!A1", "Overview") -> Overview
A5: =HYPERLINK("#'Results'!A1", "Results") -> Results | D5: Fuel purchases and consumption
A7: INPUTS | D7: 💡 You can add more rows to the table by right-clicking on the table and selecting "Insert > Table rows above/below"
A8: =HYPERLINK("#'Input - Fuel'!A1", "Fuel") -> Fuel | D8: 💡 'Percent consumed" is 100% by default. If you purchased more fuel than was consumed you can edit this field.
A10: CALCULATIONS | D10: Fuel use (select) | E10: Fuel type (select) | F10: Amount purchased | G10: Amount unit | H10: Percent consumed | I10: Amount consumed
A11: =HYPERLINK("#'8.1.1.1-2 Transport fuel'!A1", "8.1.1.1-2 Transport fuel") -> 8.1.1.1-2 Transport fuel | D11: Cars and light commercial vehicles | E11: Petrol | F11: 1000 | G11: {=Common_InputFunctions.Utility_LookupValueInTable(Table_Input_Fuel[[#This Row],[Fuel type (select)]],Table_FuelTypes_Units[Fuel type], Table_FuelTypes_Units[Unit])} -> kL | H11: =1 -> 1 | I11: =Table_Input_Fuel[[#This Row],[Amount purchased]]*Table_Input_Fuel[[#This Row],[Percent consumed]]*10^-3 -> 1
A12: =HYPERLINK("#'8.2.1.1-2 Stationary fuel'!A1", "8.2.1.1-2 Stationary fuel") -> 8.2.1.1-2 Stationary fuel | D12: Cars and light commercial vehicles | E12: Petrol | F12: 1000 | G12: {=Common_InputFunctions.Utility_LookupValueInTable(Table_Input_Fuel[[#This Row],[Fuel type (select)]],Table_FuelTypes_Units[Fuel type], Table_FuelTypes_Units[Unit])} -> kL | H12: =1 -> 1 | I12: =Table_Input_Fuel[[#This Row],[Amount purchased]]*Table_Input_Fuel[[#This Row],[Percent consumed]]*10^-3 -> 1
A13: =HYPERLINK("#'8.X.1.1-2 General use fuel'!A1", "8.X.1.1-2 General use fuel") -> 8.X.1.1-2 General use fuel
A15: APPENDICES
A16: =HYPERLINK("#'Constants - Fuel'!A1", "Constants - Fuel") -> Constants - Fuel
A17: =HYPERLINK("#'Constants - Common'!A1", "Constants - Common") -> Constants - Common

Sheet Input - Electricity
A1: #VALUE! | C1: Input - Electricity
A3: =HYPERLINK("#'Home'!A1", "Home") -> Home
A4: =HYPERLINK("#'Overview'!A1", "Overview") -> Overview
A5: =HYPERLINK("#'Results'!A1", "Results") -> Results | D5: Option 1: Location-based electricity
A7: INPUTS | D7: State grid electricity purchases
A8: =HYPERLINK("#'Input - Electricity'!A1", "Electricity") -> Electricity
D9: 💡The grid you purchase electricity from is typically the same as the state and region the farm is in.
A10: CALCULATIONS
A11: =HYPERLINK("#'14.1.1-2 Purchased electricity'!A1", "14.1.1-2 Purchased electricity") -> 14.1.1-2 Purchased electricity | D11: Amount purchased in kWh | E11: 500 | F11: kWh
D12: State and region your farm is in | E12: =IF('Input - Site'!E21="Western Australia", 'Input - Site'!E22, 'Input - Site'!E21) -> ACT
A13: APPENDICES | D13: Grid where electricity purchased from | E13: Western Australia - South West Interconnected System (SWIS) | F13: ← Please select
A14: =HYPERLINK("#'Constants - Electricity'!A1", "Constants - Electricity") -> Constants - Electricity
A15: =HYPERLINK("#'Constants - Common'!A1", "Constants - Common") -> Constants - Common
D17: Option 2: Market-based electricity
E18: =IF(E12="ACT", "", "ALERT: Your farm is not in the ACT, so the JRPP is not applicable")
D19: Electricity purchased in kWh (excluding GreenPower providers) | E19: 30000 | F19: kWh
D20: Renewable Power Percentage | E20: 0.1 | F20: percent
D21: Jurisdictional renewable power percentage (ACT only) | E21: 0.1 | F21: percent
D23: Electricity purchased from an accredited GreenPower provider | E23: 10000 | F23: kWh
D25: Start of reporting year | E25: =TEXT('Input - Site'!$E$12, "dd mmm yyyy") -> 01 Jan 2024
D26: End of reporting year | E26: =TEXT('Input - Site'!$E$13, "dd mmm yyyy") -> 31 Dec 2024
D28: Voluntarily surrendered Renewable Energy Certificates (RECs)
D30: 💡 You can add more rows to the table by right-clicking on the table and selecting "Insert > Table rows above/below"
D32: Description | E32: Source (select) | F32: Generation date | G32: Number of certificates | H32: MWh | I32: Elegibility
D33: Dec 2023 certs | E33: Purchased certificate | F33: 44185 | G33: 12 | H33: =Table_Input_RECSurrendered[[#This Row],[Number of certificates]] -> 12 | I33: =IF(DATEDIF(Table_Input_RECSurrendered[[#This Row],[Generation date]],DATEVALUE($E$26),"M")>36,"Ineligible - older than 36 months","Elegible") -> Ineligible - older than 36 months
E34: Issued for generated electricity | F34: 44575 | G34: 5 | H34: =Table_Input_RECSurrendered[[#This Row],[Number of certificates]] -> 5 | I34: =IF(DATEDIF(Table_Input_RECSurrendered[[#This Row],[Generation date]],DATEVALUE($E$26),"M")>36,"Ineligible - older than 36 months","Elegible") -> Elegible
E35: Purchased certificate | F35: 45438 | G35: 5 | H35: =Table_Input_RECSurrendered[[#This Row],[Number of certificates]] -> 5 | I35: =IF(DATEDIF(Table_Input_RECSurrendered[[#This Row],[Generation date]],DATEVALUE($E$26),"M")>36,"Ineligible - older than 36 months","Elegible") -> Elegible
D37: Total elegible voluntarily surrendered RECs | E37: =SUMIF(Table_Input_RECSurrendered[Elegibility], "Elegible", Table_Input_RECSurrendered[MWh]) -> 10 | F37: MWh
D39: Renewable Energy Certificates (RECs) for electricity produced on-site and consumed by the entity
D41: Description | E41: Source | F41: Generation date | G41: Number of certificates | H41: MWh | I41: Elegibility
D42: May 2022 generated | E42: ="Issued for generated electricity" -> Issued for generated electricity | F42: 44697 | G42: 10 | H42: =Table_Input_RECConsumedByEntity[[#This Row],[Number of certificates]] -> 10 | I42: =IF(AND(Table_Input_RECConsumedByEntity[[#This Row],[Generation date]]>=DATEVALUE($E$25), Table_Input_RECConsumedByEntity[[#This Row],[Generation date]]<= DATEVALUE($E$26)), "Elegible", "Ineligible - outside reporting year") -> Ineligible - outside reporting year
E43: ="Issued for generated electricity" -> Issued for generated electricity | F43: 45483 | G43: 4 | H43: =Table_Input_RECConsumedByEntity[[#This Row],[Number of certificates]] -> 4 | I43: =IF(AND(Table_Input_RECConsumedByEntity[[#This Row],[Generation date]]>=DATEVALUE($E$25), Table_Input_RECConsumedByEntity[[#This Row],[Generation date]]<= DATEVALUE($E$26)), "Elegible", "Ineligible - outside reporting year") -> Elegible
E44: ="Issued for generated electricity" -> Issued for generated electricity | F44: 45607 | G44: 7 | H44: =Table_Input_RECConsumedByEntity[[#This Row],[Number of certificates]] -> 7 | I44: =IF(AND(Table_Input_RECConsumedByEntity[[#This Row],[Generation date]]>=DATEVALUE($E$25), Table_Input_RECConsumedByEntity[[#This Row],[Generation date]]<= DATEVALUE($E$26)), "Elegible", "Ineligible - outside reporting year") -> Elegible
D46: Total elegible RECs for electricity produced on-site and consumed by entity | E46: =SUMIF(Table_Input_RECConsumedByEntity[Elegibility], "Elegible", Table_Input_RECConsumedByEntity[Number of certificates]) -> 11 | F46: MWh

Sheet Calcs - Scope 3
A1: #VALUE! | C1: Calculations - Purchased goods scope 3
A3: Home
A4: =HYPERLINK("#'Results'!A1", "Results") -> Results
D5: {=Scope3_SourceData.Scope3_InorganicFertilisers_Title()} -> Inorganic fertiliser chemical compound scope 3
A6: INPUTS | D6: {=Scope3_SourceData.Scope3_InorganicFertilisers_Source()} -> Scope 3 GHG Emission Factors for Australian Agriculture, Fisheries and Forestry 2026
A7: =HYPERLINK("#'Input - Site'!A1", "Site") -> Site
A8: =HYPERLINK("#'Input - Production'!A1", "Production and outputs") -> Production and outputs | D8: Category | E8: Product | F8: Region of origin | G8: Chemical compound | H8: Urea source | I8: Ammonia source | J8: Quantity | K8: Quantity Unit | L8: AusLCI Emissions intensity | M8: Custom emissions intensity | N8: Emissions intensity unit | O8: Scope 3 emissions exc. cusotm (t CO2-e) | P8: Scope 3 emissions inc. custom (t CO2-e)2 | Q8: Custom emissions intensity source | R8: Custom emissions intensity source type (Select) | S8: Custom emissions intensity credential / certification link | T8: Scope 3 data score
A9: =HYPERLINK("#'Input - Herd - Dairy'!A1", "Herd - Dairy") -> Herd - Dairy | D9: {=Common_InputFunctions.Utility_DisplayArrayInTable(Scope3_SourceData.Scope3_InorganicFertilisers_Data(), Table_Scope3_InorganicFertiliser[[#Headers],[Category]], 0, 2)} -> Inorganic fertilisers | E9: {=Common_InputFunctions.Utility_DisplayArrayInTable(Scope3_SourceData.Scope3_InorganicFertilisers_Data(), Table_Scope3_InorganicFertiliser[[#Headers],[Category]], 0, 2)} -> Ammonia, AU market mix | F9: {=Common_InputFunctions.Utility_DisplayArrayInTable(Scope3_SourceData.Scope3_InorganicFertilisers_Data(), Table_Scope3_InorganicFertiliser[[#Headers],[Category]], 0, 2)} -> Global | G9: ='Constants - Fertiliser'!$D$37 -> Ammonia | I9: ='Constants - Fertiliser'!$V$20 -> Global | J9: {=Fertiliser_InputFunctions.Fertiliser_TotalChemicalCompoundtAppliedBySourceAllIngredients(Table_Scope3_InorganicFertiliser[[#This Row],[Chemical compound]],Table_Scope3_InorganicFertiliser[[#This Row],[Ammonia source]],(Table_Input_InorganicFertiliser_Brands[Amount applied per hectare]*Table_Input_InorganicFertiliser_Brands[Density]),Table_Input_InorganicFertiliser_Brands[Ingredient 1],Table_Input_InorganicFertiliser_Brands[Ingredient 1 percent],Table_Input_InorganicFertiliser_Brands[Ammonia source],Table_Input_InorganicFertiliser_Brands[Ingredient 2],Table_Input_InorganicFertiliser_Brands[Ingredient 2 percent],Table_Input_InorganicFertiliser_Brands[Ingredient 3],Table_Input_InorganicFertiliser_Brands[Ingredient 3 percent],Table_Input_InorganicFertiliser_Brands[Ingredient 4],Table_Input_InorganicFertiliser_Brands[Ingredient 4 percent],Table_Input_InorganicFertiliser_Brands[Ingredient 5],Table_Input_InorganicFertiliser_Brands[Ingredient 5 percent],Table_Input_InorganicFertiliser_Brands[Ingredient 6],Table_Input_InorganicFertiliser_Brands[Ingredient 6 percent])+ Fertiliser_InputFunctions.Fertiliser_TotalChemicalCompoundtAppliedBySourceAllIngredients(Table_Scope3_InorganicFertiliser[[#This Row],[Chemical compound]],Table_Scope3_InorganicFertiliser[[#This Row],[Ammonia source]],Table_Input_InorganicFertiliser_Custom[Amount applied (kg / ha)],Table_Input_InorganicFertiliser_Custom[Ingredient 1 (select)],Table_Input_InorganicFertiliser_Custom[Ingredient 1 percent],Table_Input_InorganicFertiliser_Custom[Ammonia source],Table_Input_InorganicFertiliser_Custom[Ingredient 2],Table_Input_InorganicFertiliser_Custom[Ingredient 2 percent],Table_Input_InorganicFertiliser_Custom[Ingredient 3],Table_Input_InorganicFertiliser_Custom[Ingredient 3 percent],Table_Input_InorganicFertiliser_Custom[Ingredient 4],Table_Input_InorganicFertiliser_Custom[Ingredient 4 percent])} -> 0 | K9: {=Common_InputFunctions.Utility_DisplayArrayInTable(Scope3_SourceData.Scope3_InorganicFertilisers_Data(), Table_Scope3_InorganicFertiliser[[#Headers],[Category]], 0, -2)} -> kg | L9: {=Common_InputFunctions.Utility_DisplayArrayInTable(Scope3_SourceData.Scope3_InorganicFertilisers_Data(), Table_Scope3_InorganicFertiliser[[#Headers],[Category]], 0, -2)} -> 2.32 | M9: 3 | N9: {=Common_InputFunctions.Utility_DisplayArrayInTable(Scope3_SourceData.Scope3_InorganicFertilisers_Data(), Table_Scope3_InorganicFertiliser[[#Headers],[Category]], 0, 1)} | O9: =Table_Scope3_InorganicFertiliser[[#This Row],[Quantity]]*Table_Scope3_InorganicFertiliser[[#This Row],[AusLCI Emissions intensity]] -> 0 | P9: =Table_Scope3_InorganicFertiliser[[#This Row],[Quantity]]*IF(Table_Scope3_InorganicFertiliser[[#This Row],[Custom emissions intensity]], Table_Scope3_InorganicFertiliser[[#This Row],[Custom emissions intensity]], Table_Scope3_InorganicFertiliser[[#This Row],[AusLCI Emissions intensity]]) -> 0 | R9: Emissions intensity calculated from approved method | T9: {=Common_InputFunctions.Utility_LookupValueInTableNumber(Table_Scope3_InorganicFertiliser[[#This Row],[Custom emissions intensity source type (Select)]],#REF!,#REF!)} -> 0
A10: =HYPERLINK("#'Input - Feed - Dairy'!A1", "Purchased feed - Livestock") -> Purchased feed - Livestock | D10: {=Common_InputFunctions.Utility_DisplayArrayInTable(Scope3_SourceData.Scope3_InorganicFertilisers_Data(), Table_Scope3_InorganicFertiliser[[#Headers],[Category]], 0, 2)} -> Inorganic fertilisers | E10: {=Common_InputFunctions.Utility_DisplayArrayInTable(Scope3_SourceData.Scope3_InorganicFertilisers_Data(), Table_Scope3_InorganicFertiliser[[#Headers],[Category]], 0, 2)} -> Ammonia, Canada | F10: {=Common_InputFunctions.Utility_DisplayArrayInTable(Scope3_SourceData.Scope3_InorganicFertilisers_Data(), Table_Scope3_InorganicFertiliser[[#Headers],[Category]], 0, 2)} -> Canada | G10: ='Constants - Fertiliser'!$D$37 -> Ammonia | I10: ='Constants - Fertiliser'!$V$21 -> Canada | J10: {=Fertiliser_InputFunctions.Fertiliser_TotalChemicalCompoundtAppliedBySourceAllIngredients(Table_Scope3_InorganicFertiliser[[#This Row],[Chemical compound]],Table_Scope3_InorganicFertiliser[[#This Row],[Ammonia source]],(Table_Input_InorganicFertiliser_Brands[Amount applied per hectare]*Table_Input_InorganicFertiliser_Brands[Density]),Table_Input_InorganicFertiliser_Brands[Ingredient 1],Table_Input_InorganicFertiliser_Brands[Ingredient 1 percent],Table_Input_InorganicFertiliser_Brands[Ammonia source],Table_Input_InorganicFertiliser_Brands[Ingredient 2],Table_Input_InorganicFertiliser_Brands[Ingredient 2 percent],Table_Input_InorganicFertiliser_Brands[Ingredient 3],Table_Input_InorganicFertiliser_Brands[Ingredient 3 percent],Table_Input_InorganicFertiliser_Brands[Ingredient 4],Table_Input_InorganicFertiliser_Brands[Ingredient 4 percent],Table_Input_InorganicFertiliser_Brands[Ingredient 5],Table_Input_InorganicFertiliser_Brands[Ingredient 5 percent],Table_Input_InorganicFertiliser_Brands[Ingredient 6],Table_Input_InorganicFertiliser_Brands[Ingredient 6 percent])+ Fertiliser_InputFunctions.Fertiliser_TotalChemicalCompoundtAppliedBySourceAllIngredients(Table_Scope3_InorganicFertiliser[[#This Row],[Chemical compound]],Table_Scope3_InorganicFertiliser[[#This Row],[Ammonia source]],Table_Input_InorganicFertiliser_Custom[Amount applied (kg / ha)],Table_Input_InorganicFertiliser_Custom[Ingredient 1 (select)],Table_Input_InorganicFertiliser_Custom[Ingredient 1 percent],Table_Input_InorganicFertiliser_Custom[Ammonia source],Table_Input_InorganicFertiliser_Custom[Ingredient 2],Table_Input_InorganicFertiliser_Custom[Ingredient 2 percent],Table_Input_InorganicFertiliser_Custom[Ingredient 3],Table_Input_InorganicFertiliser_Custom[Ingredient 3 percent],Table_Input_InorganicFertiliser_Custom[Ingredient 4],Table_Input_InorganicFertiliser_Custom[Ingredient 4 percent])} -> 0 | K10: {=Common_InputFunctions.Utility_DisplayArrayInTable(Scope3_SourceData.Scope3_InorganicFertilisers_Data(), Table_Scope3_InorganicFertiliser[[#Headers],[Category]], 0, -2)} -> kg | L10: {=Common_InputFunctions.Utility_DisplayArrayInTable(Scope3_SourceData.Scope3_InorganicFertilisers_Data(), Table_Scope3_InorganicFertiliser[[#Headers],[Category]], 0, -2)} -> 2.12 | N10: {=Common_InputFunctions.Utility_DisplayArrayInTable(Scope3_SourceData.Scope3_InorganicFertilisers_Data(), Table_Scope3_InorganicFertiliser[[#Headers],[Category]], 0, 1)} | O10: =Table_Scope3_InorganicFertiliser[[#This Row],[Quantity]]*Table_Scope3_InorganicFertiliser[[#This Row],[AusLCI Emissions intensity]] -> 0 | P10: =Table_Scope3_InorganicFertiliser[[#This Row],[Quantity]]*IF(Table_Scope3_InorganicFertiliser[[#This Row],[Custom emissions intensity]], Table_Scope3_InorganicFertiliser[[#This Row],[Custom emissions intensity]], Table_Scope3_InorganicFertiliser[[#This Row],[AusLCI Emissions intensity]]) -> 0 | T10: {=Common_InputFunctions.Utility_LookupValueInTableNumber(Table_Scope3_InorganicFertiliser[[#This Row],[Custom emissions intensity source type (Select)]],#REF!,#REF!)} -> 0
