Workbook
Name Common_Equations.Common_ConvertCH4ToCO2e: _xlfn.LAMBDA(_xlpm.E_CH4,_xlpm.GWP_CH4, _xlpm.E_CH4 * _xlpm.GWP_CH4)
Name Common_Equations.Common_ConvertCH4ToCO2e_Arguments: _xlfn.LAMBDA(_xlfn.MAKEARRAY(2, 2, _xlfn.LAMBDA(_xlpm.r,_xlpm.c, INDEX({"ECH4","Methane emissions (t CH4)";"GWPCH4","Global warming potential for methane (t CO2-e / t CH4)"}, _xlpm.r, _xlpm.c))))
Name Common_Equations.Common_ConvertCH4ToCO2e_LatexEquation: _xlfn.LAMBDA("CO2_e = E_{CH4} \times GWP_{CH4}")
Name Common_Equations.Common_ConvertCH4ToCO2e_NIRReference: _xlfn.LAMBDA("")
Name Common_Equations.Common_ConvertCH4ToCO2e_Title: _xlfn.LAMBDA("Convert methane emissions to carbon dioxide equivalent emissions")
Name Common_Equations.Common_ConvertCH4ToCO2e_Unit: _xlfn.LAMBDA("t CO2e")
Name Common_Equations.Common_ConvertCH4ToCO2e_Variable: _xlfn.LAMBDA("ECH4 CO2e")
Name Common_Equations.Common_ConvertN2OToCO2e: _xlfn.LAMBDA(_xlpm.E_N2O,_xlpm.GWP_N2O, _xlpm.E_N2O * _xlpm.GWP_N2O)
Name Common_Equations.Common_ConvertN2OToCO2e_LatexEquation: _xlfn.LAMBDA("CO2_e = E_{N2O} \times GWP_{N2O}")
Name Common_Equations.Common_ConvertN2OToCO2e_NIRReference: _xlfn.LAMBDA("")
Name Common_Equations.Common_ConvertN2OToCO2e_Title: _xlfn.LAMBDA("Convert nitrous oxide emissions to carbon dioxide equivalent emissions")
Name Common_Equations.Common_ConvertN2OToCO2e_Unit: _xlfn.LAMBDA("t CO2e")
Name Common_Equations.Common_ConvertN2OToCO2e_Variable: _xlfn.LAMBDA("EN2O CO2e")
Name Common_InputFunctions.Utility_ConvertStateCommonNameToAbbreviation: _xlfn.LAMBDA(_xlpm.StateCommonName,_xlpm.StateCommonNameArray,_xlpm.StateAbbreviationArray, _xlfn.XLOOKUP(_xlpm.StateCommonName, _xlpm.StateCommonNameArray, _xlpm.StateAbbreviationArray, ""))
Name Common_InputFunctions.Utility_DisplayArguments_1_2: _xlfn.LAMBDA(_xlpm.ArgumentsArray, _xlfn.CHOOSECOLS(_xlpm.ArgumentsArray, 1, 2))
Name Common_InputFunctions.Utility_DisplayArguments_3_4: _xlfn.LAMBDA(_xlpm.ArgumentsArray, _xlfn.CHOOSECOLS(_xlpm.ArgumentsArray, 3, 4))
Name Common_InputFunctions.Utility_DisplayFunctionName: _xlfn.LAMBDA(_xlpm.Function, _xlfn.TEXTBEFORE(_xlfn.FORMULATEXT(_xlpm.Function), "("))
Name Common_InputFunctions.Utility_GetArrayTableColumnStartNumber: _xlfn.LAMBDA(_xlpm.TableHeaderCell, COLUMN(_xlpm.TableHeaderCell))
Name Common_InputFunctions.Utility_GetArrayTableRowStartNumber: _xlfn.LAMBDA(_xlpm.TableheaderCell,_xlpm.RowsBetweenHeaderandArray, ROW(_xlpm.TableheaderCell) + _xlpm.RowsBetweenHeaderandArray - 1)
Name Common_InputFunctions.Utility_LookupValueInTable: _xlfn.LAMBDA(_xlpm.LookupValue,_xlpm.LookupArray,_xlpm.ReturnArray, _xlfn.XLOOKUP(_xlpm.LookupValue, _xlpm.LookupArray, _xlpm.ReturnArray, ""))
Name Common_InputFunctions.Utility_SourceHyperlink: _xlfn.LAMBDA(_xlpm.TargetCell, _xlfn.LET(_xlpm.sh, _xlfn.TEXTAFTER(CELL("filename", _xlpm.TargetCell), "]"), _xlpm.addr, CELL("address", _xlpm.TargetCell), "#'" & _xlpm.sh & "'!" & _xlpm.addr))
Name Common_SourceData.Common_SourceData_AustralianStatesTerritories_Source: _xlfn.LAMBDA("")
Name Common_SourceData.Common_SourceData_AustralianStatesTerritories_Title: _xlfn.LAMBDA("Australian states and territories")
Name Common_SourceData.Common_SourceData_AustralianStatesTerritories_Unit: _xlfn.LAMBDA("")
Name Common_SourceData.Common_SourceData_AustralianStatesTerritories_Variable: _xlfn.LAMBDA("")
Name Common_SourceData.Common_SourceData_ClimateZones_Source: _xlfn.LAMBDA("VEERG 2026: Table 1.3: Climate and Rainfall zone classifications and definitions")
Name Common_SourceData.Common_SourceData_ClimateZones_Title: _xlfn.LAMBDA("VEERG Australian climate zones")
Name Common_SourceData.Common_SourceData_ClimateZones_Unit: _xlfn.LAMBDA("")
Name Common_SourceData.Common_SourceData_ClimateZones_Variable: _xlfn.LAMBDA("")
Name Common_SourceData.Common_SourceData_ConvertGasElementalToMolecular_Source: _xlfn.LAMBDA("XXXXXXX")
Name Common_SourceData.Common_SourceData_ConvertGasElementalToMolecular_Title: _xlfn.LAMBDA("Factor to convert elemental mass of gas to molecular mass")
Name Common_SourceData.Common_SourceData_ConvertGasElementalToMolecular_Unit: _xlfn.LAMBDA("factor")
Name Common_SourceData.Common_SourceData_ConvertGasElementalToMolecular_Variable: _xlfn.LAMBDA("Cg")
Name Common_SourceData.Common_SourceData_ConvertN2oElementalToMolecularCg_Data: _xlfn.LAMBDA(44 / 28)
Name Common_SourceData.Common_SourceData_ConvertN2oElementalToMolecularCg_Source: _xlfn.LAMBDA("National Inventory Report 2023 Volume 1")
Name Common_SourceData.Common_SourceData_ConvertN2oElementalToMolecularCg_Title: _xlfn.LAMBDA("Factor to convert elemental mass of N2O to molecular mass")
Name Common_SourceData.Common_SourceData_ConvertN2oElementalToMolecularCg_Unit: _xlfn.LAMBDA("factor")
Name Common_SourceData.Common_SourceData_ConvertN2oElementalToMolecularCg_Variable: _xlfn.LAMBDA("CgN2O")
Name Common_SourceData.Common_SourceData_DataScores_Scope3_Source: _xlfn.LAMBDA("VEERG 2026: XXXXXXXX")
Name Common_SourceData.Common_SourceData_DataScores_Scope3_Title: _xlfn.LAMBDA("Australian data scores for scope 3")
Name Common_SourceData.Common_SourceData_DataScores_Scope3_Unit: _xlfn.LAMBDA("")
Name Common_SourceData.Common_SourceData_DataScores_Scope3_Variable: _xlfn.LAMBDA("")
Name Common_SourceData.Common_SourceData_DataScores_Scope3_Variation: _xlfn.LAMBDA("")
Name Common_SourceData.Common_SourceData_DensityOfMethane_Data: _xlfn.LAMBDA(0.6784)
Name Common_SourceData.Common_SourceData_DensityOfMethane_Source: _xlfn.LAMBDA("National Inventory Report 2023 Volume 1: Equations 3.B.1a_2, 3.B.1c_2, 3.B.3_1, 3.B.4g_2")
Name Common_SourceData.Common_SourceData_DensityOfMethane_Title: _xlfn.LAMBDA("p = density of methane")
Name Common_SourceData.Common_SourceData_DensityOfMethane_Unit: _xlfn.LAMBDA("kg/m3")
Name Common_SourceData.Common_SourceData_EFleach_Data: _xlfn.LAMBDA(_xlfn.MAKEARRAY(1, 2, _xlfn.LAMBDA(_xlpm.r,_xlpm.c, INDEX({"EFleach",0.011}, _xlpm.r, _xlpm.c))))
Name Common_SourceData.Common_SourceData_EFleach_NIRReference: _xlfn.LAMBDA("National Inventory Report Volume 1: Equation 3.D.B_10")
Name Common_SourceData.Common_SourceData_EFleach_Source: _xlfn.LAMBDA("VEERG 2026:5.5.2.3 Constant Parameters")
Name Common_SourceData.Common_SourceData_EFleach_Title: _xlfn.LAMBDA("Emission factor for nitrogen leaching and runoff")
Name Common_SourceData.Common_SourceData_EFleach_Unit: _xlfn.LAMBDA("(kg N2O-N / kg N")
Name Common_SourceData.Common_SourceData_EFleach_Variation: _xlfn.LAMBDA((""))
Name Common_SourceData.Common_SourceData_EFN2O_NIRReference: _xlfn.LAMBDA("")
Name Common_SourceData.Common_SourceData_EFN2O_Source: _xlfn.LAMBDA("VEERG 2026: Table A.2.2.1")
Name Common_SourceData.Common_SourceData_EFN2O_Title: _xlfn.LAMBDA("Nitrous oxide emission factors for inorganic fertiliser application")
Name Common_SourceData.Common_SourceData_EFN2O_Unit: _xlfn.LAMBDA("(kg N2O-N / kg N")
Name Common_SourceData.Common_SourceData_EFOrganicFertiliserAndCropResidues_Data: _xlfn.LAMBDA(_xlfn.MAKEARRAY(3, 2, _xlfn.LAMBDA(_xlpm.r,_xlpm.c, INDEX({"Climate zone","EFNi & EFN2O";"Wet climate zone",0.006;"Dry climate zone",0.005}, _xlpm.r, _xlpm.c))))
Name Common_SourceData.Common_SourceData_EFOrganicFertiliserAndCropResidues_NIRReference: _xlfn.LAMBDA("")
Name Common_SourceData.Common_SourceData_EFOrganicFertiliserAndCropResidues_Source: _xlfn.LAMBDA("VEERG 2026: Table A.2.1.4")

Sheet Home
A1: Home

Sheet Overview
A1: #VALUE! | C1: 14: Electricity use scope 2: Overview
A3: =HYPERLINK("#'Home'!A1", "Home") -> Home
A4: =HYPERLINK("#'Overview'!A1", "Overview") -> Overview
A5: =HYPERLINK("#'Results'!A1", "Results") -> Results | D5: 💡 Below is a diagram that maps the equations used to calculate emissions, and how they interact with each other.
D6: Click on a box to go to the corresponding calculation.
A7: INPUTS
A8: =HYPERLINK("#'Input - Electricity'!A1", "Electricity") -> Electricity
A10: CALCULATIONS
A11: =HYPERLINK("#'14.1.1-2 Purchased electricity'!A1", "14.1.1-2 Purchased electricity") -> 14.1.1-2 Purchased electricity
A13: APPENDICES
A14: =HYPERLINK("#'Constants - Electricity'!A1", "Constants - Electricity") -> Constants - Electricity
A15: =HYPERLINK("#'Constants - Common'!A1", "Constants - Common") -> Constants - Common
L37: `

Sheet Results
A1: #VALUE! | C1: 14: Electricity use scope 2: Results
A3: =HYPERLINK("#'Home'!A1", "Home") -> Home
A4: =HYPERLINK("#'Overview'!A1", "Overview") -> Overview | D4: Emissions breakdown
A5: =HYPERLINK("#'Results'!A1", "Results") -> Results
D6: 💡 NOTE: When there is no Method 2, the Method 2 result are the same as Method 1
A7: INPUTS
A8: =HYPERLINK("#'Input - Electricity'!A1", "Electricity") -> Electricity | D8: Scope 1 source | E8: GHG emissions method 1 | F8: GHG emissions method 2 | G8: GHG Unit
D9: 14:1.1 Purchased electricity - Location-based | E9: ='14.1.1-2 Purchased electricity'!E18 -> 16.8 | F9: =E9 -> 16.8 | G9: t CO2e
A10: CALCULATIONS | D10: 14:1.2 Purchased electricity - Market-based | E10: ='14.1.1-2 Purchased electricity'!E39 -> 14.58 | F10: =E10 -> 14.58 | G10: t CO2e
A11: =HYPERLINK("#'14.1.1-2 Purchased electricity'!A1", "14.1.1-2 Purchased electricity") -> 14.1.1-2 Purchased electricity
A13: APPENDICES
A14: =HYPERLINK("#'Constants - Electricity'!A1", "Constants - Electricity") -> Constants - Electricity
A15: =HYPERLINK("#'Constants - Common'!A1", "Constants - Common") -> Constants - Common

Sheet Input - Site
A1: #VALUE! | C1: Input - Site
A3: =HYPERLINK("#'Home'!A1", "Home") -> Home
A4: =HYPERLINK("#'Overview'!A1", "Overview") -> Overview
A5: =HYPERLINK("#'Results'!A1", "Results") -> Results | D5: Your business
A7: INPUTS | D7: Farm name | E7: Test Farms
A8: =HYPERLINK("#'Input - Electricity'!A1", "Electricity") -> Electricity | D8: Reporting entity name | E8: Test Farms Pty Ltd
A10: CALCULATIONS | D10: 💡An 'Emissions accounting period' is a 12 month period where the business can report on the emissions, and is typically the same as the business' financial accounting period.
A11: =HYPERLINK("#'14.1.1-2 Purchased electricity'!A1", "14.1.1-2 Purchased electricity") -> 14.1.1-2 Purchased electricity
D12: Emissions calculation period start date | E12: 45292 | F12: ← DD/MM/YYYY or DD Month YYYY
A13: APPENDICES | D13: Emissions calculation period end date | E13: =DATE(YEAR(E12)+1,MONTH(E12),DAY(E12))-1 -> 45657 | F13: ← Automatically calculated, 12 months after start date
A14: =HYPERLINK("#'Constants - Electricity'!A1", "Constants - Electricity") -> Constants - Electricity
A15: =HYPERLINK("#'Constants - Common'!A1", "Constants - Common") -> Constants - Common
D16: Location and climate
D18: Location information is used to reference some region and climate-specific emission factors
D19: Tip: Use the web-based GAF Location Helper tool to easily get region and climate information. You will need an internet connection to use the GAF Location Helper.
D21: State | E21: Western Australia | F21: ← Please select
D22: Region (ABS Statistical area level 4) if state is WA | E22: Western Australia - Outback (South) | F22: ← Please select

Sheet Input - Electricity
A1: #VALUE! | C1: Input - Electricity
A3: =HYPERLINK("#'Home'!A1", "Home") -> Home
A4: =HYPERLINK("#'Overview'!A1", "Overview") -> Overview
A5: =HYPERLINK("#'Results'!A1", "Results") -> Results | D5: Option 1: Location-based electricity
A7: INPUTS | D7: State grid electricity purchases
A8: =HYPERLINK("#'Input - Electricity'!A1", "Electricity") -> Electricity
D9: 💡The grid you purchase electricity from is typically the same as the state and region the farm is in.
A10: CALCULATIONS
A11: =HYPERLINK("#'14.1.1-2 Purchased electricity'!A1", "14.1.1-2 Purchased electricity") -> 14.1.1-2 Purchased electricity | D11: Amount purchased in kWh | E11: 30000 | F11: kWh
D12: State and region your farm is in | E12: =IF('Input - Site'!E21="Western Australia", 'Input - Site'!E22, 'Input - Site'!E21) -> Western Australia - Outback (South)
A13: APPENDICES | D13: Grid where electricity purchased from | E13: Western Australia - North Western Interconnected System (NWIS) | F13: ← Please select
A14: =HYPERLINK("#'Constants - Electricity'!A1", "Constants - Electricity") -> Constants - Electricity
A15: =HYPERLINK("#'Constants - Common'!A1", "Constants - Common") -> Constants - Common
D17: Option 2: Market-based electricity
E18: =IF(E12="ACT", "", "ALERT: Your farm is not in the ACT, so the JRPP is not applicable") -> ALERT: Your farm is not in the ACT, so the JRPP is not applicable
D19: Electricity purchased in kWh (excluding GreenPower providers) | E19: 30000 | F19: kWh
D20: Renewable Power Percentage | E20: 0.1 | F20: percent
D21: Jurisdictional renewable power percentage (ACT only) | E21: 0.1 | F21: percent
D23: Electricity purchased from an accredited GreenPower provider | E23: 10000 | F23: kWh
D25: Start of reporting year | E25: =TEXT('Input - Site'!$E$12, "dd mmm yyyy") -> 01 Jan 2024
D26: End of reporting year | E26: =TEXT('Input - Site'!$E$13, "dd mmm yyyy") -> 31 Dec 2024
D28: Voluntarily surrendered Renewable Energy Certificates (RECs)
D30: 💡 You can add more rows to the table by right-clicking on the table and selecting "Insert > Table rows above/below"
D32: Description | E32: Source (select) | F32: Generation date | G32: Number of certificates | H32: MWh | I32: Elegibility
D33: Dec 2020 certs | E33: Purchased certificate | F33: 44185 | G33: 12 | H33: =Table_Input_RECSurrendered[[#This Row],[Number of certificates]] -> 12 | I33: =IF(DATEDIF(Table_Input_RECSurrendered[[#This Row],[Generation date]],DATEVALUE($E$26),"M")>36,"Ineligible - older than 36 months","Elegible") -> Ineligible - older than 36 months
D34: Jan 2022 certs | E34: Issued for generated electricity | F34: 44575 | G34: 5 | H34: =Table_Input_RECSurrendered[[#This Row],[Number of certificates]] -> 5 | I34: =IF(DATEDIF(Table_Input_RECSurrendered[[#This Row],[Generation date]],DATEVALUE($E$26),"M")>36,"Ineligible - older than 36 months","Elegible") -> Elegible
D35: 2024 certs | E35: Purchased certificate | F35: 45438 | G35: 5 | H35: =Table_Input_RECSurrendered[[#This Row],[Number of certificates]] -> 5 | I35: =IF(DATEDIF(Table_Input_RECSurrendered[[#This Row],[Generation date]],DATEVALUE($E$26),"M")>36,"Ineligible - older than 36 months","Elegible") -> Elegible
D37: Total elegible voluntarily surrendered RECs | E37: =SUMIF(Table_Input_RECSurrendered[Elegibility], "Elegible", Table_Input_RECSurrendered[MWh]) -> 10 | F37: MWh
D39: Renewable Energy Certificates (RECs) for electricity produced on-site and consumed by the entity
D41: Description | E41: Source | F41: Generation date | G41: Number of certificates | H41: MWh | I41: Elegibility
D42: May 2022 generated | E42: ="Issued for generated electricity" -> Issued for generated electricity | F42: 44697 | G42: 10 | H42: =Table_Input_RECConsumedByEntity[[#This Row],[Number of certificates]] -> 10 | I42: =IF(AND(Table_Input_RECConsumedByEntity[[#This Row],[Generation date]]>=DATEVALUE($E$25), Table_Input_RECConsumedByEntity[[#This Row],[Generation date]]<= DATEVALUE($E$26)), "Elegible", "Ineligible - outside reporting year") -> Ineligible - outside reporting year
D43: Jul 24 certs generated | E43: ="Issued for generated electricity" -> Issued for generated electricity | F43: 45483 | G43: 4 | H43: =Table_Input_RECConsumedByEntity[[#This Row],[Number of certificates]] -> 4 | I43: =IF(AND(Table_Input_RECConsumedByEntity[[#This Row],[Generation date]]>=DATEVALUE($E$25), Table_Input_RECConsumedByEntity[[#This Row],[Generation date]]<= DATEVALUE($E$26)), "Elegible", "Ineligible - outside reporting year") -> Elegible
D44: 45597 | E44: ="Issued for generated electricity" -> Issued for generated electricity | F44: 45607 | G44: 7 | H44: =Table_Input_RECConsumedByEntity[[#This Row],[Number of certificates]] -> 7 | I44: =IF(AND(Table_Input_RECConsumedByEntity[[#This Row],[Generation date]]>=DATEVALUE($E$25), Table_Input_RECConsumedByEntity[[#This Row],[Generation date]]<= DATEVALUE($E$26)), "Elegible", "Ineligible - outside reporting year") -> Elegible
D46: Total elegible RECs for electricity produced on-site and consumed by entity | E46: =SUMIF(Table_Input_RECConsumedByEntity[Elegibility], "Elegible", Table_Input_RECConsumedByEntity[Number of certificates]) -> 11 | F46: MWh

Sheet 14.1.1-2 Purchased electricity
A1: #VALUE! | C1: 14.1.1-2 Purchased Electricity
A3: =HYPERLINK("#'Home'!A1", "Home") -> Home | D3: Method 1
A4: =HYPERLINK("#'Overview'!A1", "Overview") -> Overview
A5: =HYPERLINK("#'Results'!A1", "Results") -> Results | D5: {=Electricity_Equations.VEERG_14_1_1__1_LocationBasedScopeElectricityEmissions_Title()} -> Location-based Scope 2 emissions from purchased electricity
D6: {=Electricity_Equations.VEERG_14_1_1__1_LocationBasedScopeElectricityEmissions_Source()} -> VEERG 2026: 14.1.1, Equation (1)
A7: INPUTS | D7: {=Electricity_Equations.VEERG_14_1_1__1_LocationBasedScopeElectricityEmissions_Variation()} -> Added g variable to capture which grid electricity was purchased from
A8: =HYPERLINK("#'Input - Electricity'!A1", "Electricity") -> Electricity | D8: Function name | E8: {=Common_InputFunctions.Utility_DisplayFunctionName(E18)} -> =Electricity_Equations.VEERG_14_1_1__1_LocationBasedScopeElectricityEmissions
A10: CALCULATIONS
A11: =HYPERLINK("#'14.1.1-2 Purchased electricity'!A1", "14.1.1-2 Purchased electricity") -> 14.1.1-2 Purchased electricity | D11: Variable | E11: {=Electricity_Equations.VEERG_14_1_1__1_LocationBasedScopeElectricityEmissions_Variable()} -> E_2elec
D12: Unit | E12: {=Electricity_Equations.VEERG_14_1_1__1_LocationBasedScopeElectricityEmissions_Unit()} -> t CO2e
A13: APPENDICES
A14: =HYPERLINK("#'Constants - Electricity'!A1", "Constants - Electricity") -> Constants - Electricity | D14: {=_xlfn.CHOOSECOLS(Electricity_Equations.VEERG_14_1_1__1_LocationBasedScopeElectricityEmissions_Arguments(),1,2)} -> Q_elec | E14: amount of electricity purchased from the grid | G14: {=_xlfn.CHOOSECOLS(Electricity_Equations.VEERG_14_1_1__1_LocationBasedScopeElectricityEmissions_Arguments(),3,4)} -> kWh | H14: Input | I14: ='Input - Electricity'!$E$11 -> 30000
A15: =HYPERLINK("#'Constants - Common'!A1", "Constants - Common") -> Constants - Common | D15: EF_2elec | E15: location-based Scope 2 emission factor for electricity | G15: kg CO2e/kWh | H15: Constant | I15: {=Common_InputFunctions.Utility_LookupValueInTableNumber(I16,Table_SourceData_ElectricityEFs[State, Territory or grid description],Table_SourceData_ElectricityEFs[Scope 2 Emission Factors (kg CO2-e/kWh)])} -> 0.56
D16: g | E16: Grid electricity was purchased from | H16: Input | I16: ='Input - Electricity'!$E$13 -> Western Australia - North Western Interconnected System (NWIS)
D18: E2,elec | E18: {=Electricity_Equations.VEERG_14_1_1__1_LocationBasedScopeElectricityEmissions(I14,I15)} -> 16.8 | F18: =$E$12 -> t CO2e
D22: {=Electricity_Equations.VEERG_14_1_2__1_MarketBasedScopeElectricityEmissions_Title()} -> Market-based Scope 2 emissions from purchased electricity
D23: {=Electricity_Equations.VEERG_14_1_2__1_MarketBasedScopeElectricityEmissions_Source()} -> VEERG 2026: 14.1.2, Equation (1)
D24: {=Electricity_Equations.VEERG_14_1_2__1_MarketBasedScopeElectricityEmissions_Variation()} -> VARIATION ON SOURCE: In order to convert megawatt hours to kilowatt hours, the REC_surrendered and REC_onsite variables are multiplied by 10^3 instead of 10^-3.
D25: Function name | E25: {=Common_InputFunctions.Utility_DisplayFunctionName(E39)} -> =Electricity_Equations.VEERG_14_1_2__1_MarketBasedScopeElectricityEmissionsVariation
D28: Variable | E28: {=Electricity_Equations.VEERG_14_1_2__1_MarketBasedScopeElectricityEmissions_Variable()} -> E_2elec
D29: Unit | E29: {=Electricity_Equations.VEERG_14_1_2__1_MarketBasedScopeElectricityEmissions_Unit()} -> t CO2e
D31: {=_xlfn.CHOOSECOLS(Electricity_Equations.VEERG_14_1_2__1_MarketBasedScopeElectricityEmissions_Arguments(),1,2)} -> Q_elec | E31: amount of electricity purchased from the grid | H31: {=_xlfn.CHOOSECOLS(Electricity_Equations.VEERG_14_1_2__1_MarketBasedScopeElectricityEmissions_Arguments(),3,4)} -> kWh | I31: Input | J31: ='Input - Electricity'!E19 -> 30000
D32: RPP | E32: Renewable Power Percentage under the Large-scale Renewable Energy Target (LRET) | H32: per cent | I32: Input | J32: ='Input - Electricity'!E20 -> 0.1
D33: JRPP | E33: jurisdictional renewable power percentage for the applicable period (ACT only) | H33: per cent | I33: Input | J33: =IF(J37="ACT", 'Input - Electricity'!E21, "N/A") -> N/A
D34: REC_surrendered | E34: Renewable Energy Certificates voluntarily surrendered in the reporting year | H34: MWh | I34: Input | J34: =('Input - Electricity'!E23*10^-3)+'Input - Electricity'!$E$37 -> 20
D35: REC_onsite | E35: Renewable Energy Certificates issued for electricity produced on-site during the year and consumed by the entity | H35: MWh | I35: Input | J35: ='Input - Electricity'!$E$46 -> 11
D36: EF_RMF2elec | E36: Scope 2 residual mix emission factor for electricity | H36: kg CO2e/kWh | I36: Constant | J36: {=Table_SourceData_ElectricityEFsMarketBased[Scope 2 EF (kg CO2-e/kWh)]} -> 0.81
D37: i | E37: state | I37: Input | J37: ='Input - Site'!E21 -> Western Australia
D39: E2,elec | E39: {=Electricity_Equations.VEERG_14_1_2__1_MarketBasedScopeElectricityEmissionsVariation(J31,J32,IF(ISNUMBER(J33), J33, 0),J34,J35,J36)} -> 14.58 | F39: =E29 -> t CO2e

Sheet Constants - Electricity
A1: #VALUE! | C1: Constants - Electricity
A3: =HYPERLINK("#'Home'!A1", "Home") -> Home
A4: =HYPERLINK("#'Overview'!A1", "Overview") -> Overview
A5: =HYPERLINK("#'Results'!A1", "Results") -> Results | D5: {=Electricity_SourceData.Electricity_Scope2Scope3LocationBased_Title()} -> Electricity scope 2 and scope 3 location-based emission factors
D6: {=Electricity_SourceData.Electricity_Scope2Scope3LocationBased_Source()} -> Australian National Greenhouse Accounts Factors 2025 - Table 1
A7: INPUTS | D7: {="⚠️" & Electricity_SourceData.Electricity_Scope2Scope3LocationBased_Variation()} -> ⚠️VARIATION OF SOURCE DATA: NSW and ACT split into separate rows.
A8: =HYPERLINK("#'Input - Electricity'!A1", "Electricity") -> Electricity
D9: State, Territory or grid description | E9: Scope 2 Emission Factors (kg CO2-e/kWh) | F9: Scope 3 Emission Factors (kg CO2-e/kWh)
A10: CALCULATIONS | D10: {=Common_InputFunctions.Utility_DisplayArrayInTable(Electricity_SourceData.Electricity_Scope2Scope3LocationBased_Data(), Table_SourceData_ElectricityEFs[[#Headers],[State, Territory or grid description]], 0)} -> New South Wales | E10: {=Common_InputFunctions.Utility_DisplayArrayInTable(Electricity_SourceData.Electricity_Scope2Scope3LocationBased_Data(), Table_SourceData_ElectricityEFs[[#Headers],[State, Territory or grid description]], 0)} -> 0.64 | F10: {=Common_InputFunctions.Utility_DisplayArrayInTable(Electricity_SourceData.Electricity_Scope2Scope3LocationBased_Data(), Table_SourceData_ElectricityEFs[[#Headers],[State, Territory or grid description]], 0)} -> 0.03
A11: =HYPERLINK("#'14.1.1-2 Purchased electricity'!A1", "14.1.1-2 Purchased electricity") -> 14.1.1-2 Purchased electricity | D11: {=Common_InputFunctions.Utility_DisplayArrayInTable(Electricity_SourceData.Electricity_Scope2Scope3LocationBased_Data(), Table_SourceData_ElectricityEFs[[#Headers],[State, Territory or grid description]], 0)} -> ACT | E11: {=Common_InputFunctions.Utility_DisplayArrayInTable(Electricity_SourceData.Electricity_Scope2Scope3LocationBased_Data(), Table_SourceData_ElectricityEFs[[#Headers],[State, Territory or grid description]], 0)} -> 0.64 | F11: {=Common_InputFunctions.Utility_DisplayArrayInTable(Electricity_SourceData.Electricity_Scope2Scope3LocationBased_Data(), Table_SourceData_ElectricityEFs[[#Headers],[State, Territory or grid description]], 0)} -> 0.03
D12: {=Common_InputFunctions.Utility_DisplayArrayInTable(Electricity_SourceData.Electricity_Scope2Scope3LocationBased_Data(), Table_SourceData_ElectricityEFs[[#Headers],[State, Territory or grid description]], 0)} -> Victoria | E12: {=Common_InputFunctions.Utility_DisplayArrayInTable(Electricity_SourceData.Electricity_Scope2Scope3LocationBased_Data(), Table_SourceData_ElectricityEFs[[#Headers],[State, Territory or grid description]], 0)} -> 0.78 | F12: {=Common_InputFunctions.Utility_DisplayArrayInTable(Electricity_SourceData.Electricity_Scope2Scope3LocationBased_Data(), Table_SourceData_ElectricityEFs[[#Headers],[State, Territory or grid description]], 0)} -> 0.09
A13: APPENDICES | D13: {=Common_InputFunctions.Utility_DisplayArrayInTable(Electricity_SourceData.Electricity_Scope2Scope3LocationBased_Data(), Table_SourceData_ElectricityEFs[[#Headers],[State, Territory or grid description]], 0)} -> Queensland | E13: {=Common_InputFunctions.Utility_DisplayArrayInTable(Electricity_SourceData.Electricity_Scope2Scope3LocationBased_Data(), Table_SourceData_ElectricityEFs[[#Headers],[State, Territory or grid description]], 0)} -> 0.67 | F13: {=Common_InputFunctions.Utility_DisplayArrayInTable(Electricity_SourceData.Electricity_Scope2Scope3LocationBased_Data(), Table_SourceData_ElectricityEFs[[#Headers],[State, Territory or grid description]], 0)} -> 0.09
A14: =HYPERLINK("#'Constants - Electricity'!A1", "Constants - Electricity") -> Constants - Electricity | D14: {=Common_InputFunctions.Utility_DisplayArrayInTable(Electricity_SourceData.Electricity_Scope2Scope3LocationBased_Data(), Table_SourceData_ElectricityEFs[[#Headers],[State, Territory or grid description]], 0)} -> South Australia | E14: {=Common_InputFunctions.Utility_DisplayArrayInTable(Electricity_SourceData.Electricity_Scope2Scope3LocationBased_Data(), Table_SourceData_ElectricityEFs[[#Headers],[State, Territory or grid description]], 0)} -> 0.22 | F14: {=Common_InputFunctions.Utility_DisplayArrayInTable(Electricity_SourceData.Electricity_Scope2Scope3LocationBased_Data(), Table_SourceData_ElectricityEFs[[#Headers],[State, Territory or grid description]], 0)} -> 0.04
A15: =HYPERLINK("#'Constants - Common'!A1", "Constants - Common") -> Constants - Common | D15: {=Common_InputFunctions.Utility_DisplayArrayInTable(Electricity_SourceData.Electricity_Scope2Scope3LocationBased_Data(), Table_SourceData_ElectricityEFs[[#Headers],[State, Territory or grid description]], 0)} -> Western Australia - South West Interconnected System (SWIS) | E15: {=Common_InputFunctions.Utility_DisplayArrayInTable(Electricity_SourceData.Electricity_Scope2Scope3LocationBased_Data(), Table_SourceData_ElectricityEFs[[#Headers],[State, Territory or grid description]], 0)} -> 0.5 | F15: {=Common_InputFunctions.Utility_DisplayArrayInTable(Electricity_SourceData.Electricity_Scope2Scope3LocationBased_Data(), Table_SourceData_ElectricityEFs[[#Headers],[State, Territory or grid description]], 0)} -> 0.06
D16: {=Common_InputFunctions.Utility_DisplayArrayInTable(Electricity_SourceData.Electricity_Scope2Scope3LocationBased_Data(), Table_SourceData_ElectricityEFs[[#Headers],[State, Territory or grid description]], 0)} -> Western Australia - North Western Interconnected System (NWIS) | E16: {=Common_InputFunctions.Utility_DisplayArrayInTable(Electricity_SourceData.Electricity_Scope2Scope3LocationBased_Data(), Table_SourceData_ElectricityEFs[[#Headers],[State, Territory or grid description]], 0)} -> 0.56 | F16: {=Common_InputFunctions.Utility_DisplayArrayInTable(Electricity_SourceData.Electricity_Scope2Scope3LocationBased_Data(), Table_SourceData_ElectricityEFs[[#Headers],[State, Territory or grid description]], 0)} -> 0.09
D17: {=Common_InputFunctions.Utility_DisplayArrayInTable(Electricity_SourceData.Electricity_Scope2Scope3LocationBased_Data(), Table_SourceData_ElectricityEFs[[#Headers],[State, Territory or grid description]], 0)} -> Tasmania | E17: {=Common_InputFunctions.Utility_DisplayArrayInTable(Electricity_SourceData.Electricity_Scope2Scope3LocationBased_Data(), Table_SourceData_ElectricityEFs[[#Headers],[State, Territory or grid description]], 0)} -> 0.2 | F17: {=Common_InputFunctions.Utility_DisplayArrayInTable(Electricity_SourceData.Electricity_Scope2Scope3LocationBased_Data(), Table_SourceData_ElectricityEFs[[#Headers],[State, Territory or grid description]], 0)} -> 0.03
D18: {=Common_InputFunctions.Utility_DisplayArrayInTable(Electricity_SourceData.Electricity_Scope2Scope3LocationBased_Data(), Table_SourceData_ElectricityEFs[[#Headers],[State, Territory or grid description]], 0)} -> Northern Territory - Darwin Katherine Interconnected System (DKIS) | E18: {=Common_InputFunctions.Utility_DisplayArrayInTable(Electricity_SourceData.Electricity_Scope2Scope3LocationBased_Data(), Table_SourceData_ElectricityEFs[[#Headers],[State, Territory or grid description]], 0)} -> 0.56 | F18: {=Common_InputFunctions.Utility_DisplayArrayInTable(Electricity_SourceData.Electricity_Scope2Scope3LocationBased_Data(), Table_SourceData_ElectricityEFs[[#Headers],[State, Territory or grid description]], 0)} -> 0.09
D19: {=Common_InputFunctions.Utility_DisplayArrayInTable(Electricity_SourceData.Electricity_Scope2Scope3LocationBased_Data(), Table_SourceData_ElectricityEFs[[#Headers],[State, Territory or grid description]], 0)} -> National | E19: {=Common_InputFunctions.Utility_DisplayArrayInTable(Electricity_SourceData.Electricity_Scope2Scope3LocationBased_Data(), Table_SourceData_ElectricityEFs[[#Headers],[State, Territory or grid description]], 0)} -> 0.62 | F19: {=Common_InputFunctions.Utility_DisplayArrayInTable(Electricity_SourceData.Electricity_Scope2Scope3LocationBased_Data(), Table_SourceData_ElectricityEFs[[#Headers],[State, Territory or grid description]], 0)} -> 0.07
D21: {=Electricity_SourceData.Electricity_Scope2Scope3MarketBased_Title()} -> Electricity scope 2 and scope 3 market-based emission factors
D22: {=Electricity_SourceData.Electricity_Scope2Scope3MarketBased_Source()} -> Australian National Greenhouse Accounts Factors 2025 - Table 2a
D24: State, Territory or grid description | E24: Scope 2 EF (kg CO2-e/kWh) | F24: Scope 2 EF (kg CO2-e/GJ) | G24: Scope 3 EF (kg CO2-e/kWh) | H24: Scope 3 EF (kg CO2-e/GJ)
D25: {=Common_InputFunctions.Utility_DisplayArrayInTable(Electricity_SourceData.Electricity_Scope2Scope3MarketBased_Data(), Table_SourceData_ElectricityEFsMarketBased[[#Headers],[State, Territory or grid description]], 0)} -> National | E25: {=Common_InputFunctions.Utility_DisplayArrayInTable(Electricity_SourceData.Electricity_Scope2Scope3MarketBased_Data(), Table_SourceData_ElectricityEFsMarketBased[[#Headers],[State, Territory or grid description]], 0)} -> 0.81 | F25: {=Common_InputFunctions.Utility_DisplayArrayInTable(Electricity_SourceData.Electricity_Scope2Scope3MarketBased_Data(), Table_SourceData_ElectricityEFsMarketBased[[#Headers],[State, Territory or grid description]], 0)} -> 226 | G25: {=Common_InputFunctions.Utility_DisplayArrayInTable(Electricity_SourceData.Electricity_Scope2Scope3MarketBased_Data(), Table_SourceData_ElectricityEFsMarketBased[[#Headers],[State, Territory or grid description]], 0)} -> 0.1 | H25: {=Common_InputFunctions.Utility_DisplayArrayInTable(Electricity_SourceData.Electricity_Scope2Scope3MarketBased_Data(), Table_SourceData_ElectricityEFsMarketBased[[#Headers],[State, Territory or grid description]], 0)} -> 29

Sheet Constants - Common
A1: #VALUE! | C1: Constants - Common
D5: {=Common_SourceData.Common_SourceData_AustralianStatesTerritories_Title()} -> Australian states and territories
D6: State/Territory | E6: Common Name | F6: Abbreviation
D7: {=Common_InputFunctions.Utility_DisplayArrayInTable(Common_SourceData.Common_SourceData_AustralianStatesTerritories_Data(),Table_AustralianStates[[#Headers],[State/Territory]],0)} -> New South Wales | E7: {=Common_InputFunctions.Utility_DisplayArrayInTable(Common_SourceData.Common_SourceData_AustralianStatesTerritories_Data(),Table_AustralianStates[[#Headers],[State/Territory]],0)} -> New South Wales | F7: {=Common_InputFunctions.Utility_DisplayArrayInTable(Common_SourceData.Common_SourceData_AustralianStatesTerritories_Data(),Table_AustralianStates[[#Headers],[State/Territory]],0)} -> NSW
D8: {=Common_InputFunctions.Utility_DisplayArrayInTable(Common_SourceData.Common_SourceData_AustralianStatesTerritories_Data(),Table_AustralianStates[[#Headers],[State/Territory]],0)} -> Australian Capital Territory | E8: {=Common_InputFunctions.Utility_DisplayArrayInTable(Common_SourceData.Common_SourceData_AustralianStatesTerritories_Data(),Table_AustralianStates[[#Headers],[State/Territory]],0)} -> ACT | F8: {=Common_InputFunctions.Utility_DisplayArrayInTable(Common_SourceData.Common_SourceData_AustralianStatesTerritories_Data(),Table_AustralianStates[[#Headers],[State/Territory]],0)} -> ACT
D9: {=Common_InputFunctions.Utility_DisplayArrayInTable(Common_SourceData.Common_SourceData_AustralianStatesTerritories_Data(),Table_AustralianStates[[#Headers],[State/Territory]],0)} -> Victoria | E9: {=Common_InputFunctions.Utility_DisplayArrayInTable(Common_SourceData.Common_SourceData_AustralianStatesTerritories_Data(),Table_AustralianStates[[#Headers],[State/Territory]],0)} -> Victoria | F9: {=Common_InputFunctions.Utility_DisplayArrayInTable(Common_SourceData.Common_SourceData_AustralianStatesTerritories_Data(),Table_AustralianStates[[#Headers],[State/Territory]],0)} -> VIC
D10: {=Common_InputFunctions.Utility_DisplayArrayInTable(Common_SourceData.Common_SourceData_AustralianStatesTerritories_Data(),Table_AustralianStates[[#Headers],[State/Territory]],0)} -> Queensland | E10: {=Common_InputFunctions.Utility_DisplayArrayInTable(Common_SourceData.Common_SourceData_AustralianStatesTerritories_Data(),Table_AustralianStates[[#Headers],[State/Territory]],0)} -> Queensland | F10: {=Common_InputFunctions.Utility_DisplayArrayInTable(Common_SourceData.Common_SourceData_AustralianStatesTerritories_Data(),Table_AustralianStates[[#Headers],[State/Territory]],0)} -> QLD
D11: {=Common_InputFunctions.Utility_DisplayArrayInTable(Common_SourceData.Common_SourceData_AustralianStatesTerritories_Data(),Table_AustralianStates[[#Headers],[State/Territory]],0)} -> South Australia | E11: {=Common_InputFunctions.Utility_DisplayArrayInTable(Common_SourceData.Common_SourceData_AustralianStatesTerritories_Data(),Table_AustralianStates[[#Headers],[State/Territory]],0)} -> South Australia | F11: {=Common_InputFunctions.Utility_DisplayArrayInTable(Common_SourceData.Common_SourceData_AustralianStatesTerritories_Data(),Table_AustralianStates[[#Headers],[State/Territory]],0)} -> SA
D12: {=Common_InputFunctions.Utility_DisplayArrayInTable(Common_SourceData.Common_SourceData_AustralianStatesTerritories_Data(),Table_AustralianStates[[#Headers],[State/Territory]],0)} -> Western Australia | E12: {=Common_InputFunctions.Utility_DisplayArrayInTable(Common_SourceData.Common_SourceData_AustralianStatesTerritories_Data(),Table_AustralianStates[[#Headers],[State/Territory]],0)} -> Western Australia | F12: {=Common_InputFunctions.Utility_DisplayArrayInTable(Common_SourceData.Common_SourceData_AustralianStatesTerritories_Data(),Table_AustralianStates[[#Headers],[State/Territory]],0)} -> WA
D13: {=Common_InputFunctions.Utility_DisplayArrayInTable(Common_SourceData.Common_SourceData_AustralianStatesTerritories_Data(),Table_AustralianStates[[#Headers],[State/Territory]],0)} -> Tasmania | E13: {=Common_InputFunctions.Utility_DisplayArrayInTable(Common_SourceData.Common_SourceData_AustralianStatesTerritories_Data(),Table_AustralianStates[[#Headers],[State/Territory]],0)} -> Tasmania | F13: {=Common_InputFunctions.Utility_DisplayArrayInTable(Common_SourceData.Common_SourceData_AustralianStatesTerritories_Data(),Table_AustralianStates[[#Headers],[State/Territory]],0)} -> TAS
D14: {=Common_InputFunctions.Utility_DisplayArrayInTable(Common_SourceData.Common_SourceData_AustralianStatesTerritories_Data(),Table_AustralianStates[[#Headers],[State/Territory]],0)} -> Northern Territory | E14: {=Common_InputFunctions.Utility_DisplayArrayInTable(Common_SourceData.Common_SourceData_AustralianStatesTerritories_Data(),Table_AustralianStates[[#Headers],[State/Territory]],0)} -> Northern Territory | F14: {=Common_InputFunctions.Utility_DisplayArrayInTable(Common_SourceData.Common_SourceData_AustralianStatesTerritories_Data(),Table_AustralianStates[[#Headers],[State/Territory]],0)} -> NT
D18: {=Common_SourceData.Common_SourceData_WASA4Areas_Title()} -> ABS Statistcal Areas Level 4 - Western Australia
D19: {=Common_SourceData.Common_SourceData_WASA4Areas_Source()} -> Australian Bureau of Statistics (ABS) - Statistical Areas Level 2 - 2021 - Shapefile
D20: SA 4 Name
D21: {=Common_InputFunctions.Utility_DisplayArrayInTable(Common_SourceData.Common_SourceData_WASA4Areas_Data(), Table_WASA4Areas[[#Headers],[SA 4 Name]], 0)} -> Bunbury
D22: {=Common_InputFunctions.Utility_DisplayArrayInTable(Common_SourceData.Common_SourceData_WASA4Areas_Data(), Table_WASA4Areas[[#Headers],[SA 4 Name]], 0)} -> Mandurah
D23: {=Common_InputFunctions.Utility_DisplayArrayInTable(Common_SourceData.Common_SourceData_WASA4Areas_Data(), Table_WASA4Areas[[#Headers],[SA 4 Name]], 0)} -> Perth - Inner
D24: {=Common_InputFunctions.Utility_DisplayArrayInTable(Common_SourceData.Common_SourceData_WASA4Areas_Data(), Table_WASA4Areas[[#Headers],[SA 4 Name]], 0)} -> Perth - North East
D25: {=Common_InputFunctions.Utility_DisplayArrayInTable(Common_SourceData.Common_SourceData_WASA4Areas_Data(), Table_WASA4Areas[[#Headers],[SA 4 Name]], 0)} -> Perth - North West
D26: {=Common_InputFunctions.Utility_DisplayArrayInTable(Common_SourceData.Common_SourceData_WASA4Areas_Data(), Table_WASA4Areas[[#Headers],[SA 4 Name]], 0)} -> Perth - South East
D27: {=Common_InputFunctions.Utility_DisplayArrayInTable(Common_SourceData.Common_SourceData_WASA4Areas_Data(), Table_WASA4Areas[[#Headers],[SA 4 Name]], 0)} -> Perth - South West
D28: {=Common_InputFunctions.Utility_DisplayArrayInTable(Common_SourceData.Common_SourceData_WASA4Areas_Data(), Table_WASA4Areas[[#Headers],[SA 4 Name]], 0)} -> Western Australia - Wheat Belt
D29: {=Common_InputFunctions.Utility_DisplayArrayInTable(Common_SourceData.Common_SourceData_WASA4Areas_Data(), Table_WASA4Areas[[#Headers],[SA 4 Name]], 0)} -> Western Australia - Outback (North)
D30: {=Common_InputFunctions.Utility_DisplayArrayInTable(Common_SourceData.Common_SourceData_WASA4Areas_Data(), Table_WASA4Areas[[#Headers],[SA 4 Name]], 0)} -> Western Australia - Outback (South)
D34: {=Common_SourceData.Common_SourceData_GWP_Title()} -> Global warming potential for greenhouse gases
D35: {=Common_SourceData.Common_SourceData_GWP_Source()} -> XXXXXXX
D36: Gas | E36: CO2-e factor
D37: {=Common_InputFunctions.Utility_DisplayArrayInTable(Common_SourceData.Common_SourceData_GWP_Data(), Table_GWPData[[#Headers],[Gas]], 0)} -> CO2 | E37: {=Common_InputFunctions.Utility_DisplayArrayInTable(Common_SourceData.Common_SourceData_GWP_Data(), Table_GWPData[[#Headers],[Gas]], 0)} -> 1
D38: {=Common_InputFunctions.Utility_DisplayArrayInTable(Common_SourceData.Common_SourceData_GWP_Data(), Table_GWPData[[#Headers],[Gas]], 0)} -> CH4 | E38: {=Common_InputFunctions.Utility_DisplayArrayInTable(Common_SourceData.Common_SourceData_GWP_Data(), Table_GWPData[[#Headers],[Gas]], 0)} -> 28
D39: {=Common_InputFunctions.Utility_DisplayArrayInTable(Common_SourceData.Common_SourceData_GWP_Data(), Table_GWPData[[#Headers],[Gas]], 0)} -> N2O | E39: {=Common_InputFunctions.Utility_DisplayArrayInTable(Common_SourceData.Common_SourceData_GWP_Data(), Table_GWPData[[#Headers],[Gas]], 0)} -> 265
D40: {=Common_InputFunctions.Utility_DisplayArrayInTable(Common_SourceData.Common_SourceData_GWP_Data(), Table_GWPData[[#Headers],[Gas]], 0)} -> CF4 | E40: {=Common_InputFunctions.Utility_DisplayArrayInTable(Common_SourceData.Common_SourceData_GWP_Data(), Table_GWPData[[#Headers],[Gas]], 0)} -> 6630
D41: {=Common_InputFunctions.Utility_DisplayArrayInTable(Common_SourceData.Common_SourceData_GWP_Data(), Table_GWPData[[#Headers],[Gas]], 0)} -> C2F6 | E41: {=Common_InputFunctions.Utility_DisplayArrayInTable(Common_SourceData.Common_SourceData_GWP_Data(), Table_GWPData[[#Headers],[Gas]], 0)} -> 12200
D42: {=Common_InputFunctions.Utility_DisplayArrayInTable(Common_SourceData.Common_SourceData_GWP_Data(), Table_GWPData[[#Headers],[Gas]], 0)} -> SF6 | E42: {=Common_InputFunctions.Utility_DisplayArrayInTable(Common_SourceData.Common_SourceData_GWP_Data(), Table_GWPData[[#Headers],[Gas]], 0)} -> 22800
D43: {=Common_InputFunctions.Utility_DisplayArrayInTable(Common_SourceData.Common_SourceData_GWP_Data(), Table_GWPData[[#Headers],[Gas]], 0)} -> NF3 | E43: {=Common_InputFunctions.Utility_DisplayArrayInTable(Common_SourceData.Common_SourceData_GWP_Data(), Table_GWPData[[#Headers],[Gas]], 0)} -> 17200
D45: {=Common_SourceData.Common_SourceData_ConvertGasElementalToMolecular_Title()} -> Factor to convert elemental mass of gas to molecular mass
D46: {=Common_SourceData.Common_SourceData_ConvertGasElementalToMolecular_Source()} -> XXXXXXX
D47: Gas | E47: Conversion factor | F47: Conversion factor 1 | G47: Conversion factor 2 | H47: Conversion factor combined
D48: {=Common_InputFunctions.Utility_DisplayArrayInTable(Common_SourceData.Common_SourceData_ConvertGasElementalToMolecular_Data(),Table_GasToMolecularConversionFactor[[#Headers],[Gas]], 0)} -> CO2 | E48: {=Common_InputFunctions.Utility_DisplayArrayInTable(Common_SourceData.Common_SourceData_ConvertGasElementalToMolecular_Data(),Table_GasToMolecularConversionFactor[[#Headers],[Gas]], 0)} -> 44/12 | F48: {=Common_InputFunctions.Utility_DisplayArrayInTable(Common_SourceData.Common_SourceData_ConvertGasElementalToMolecular_Data(),Table_GasToMolecularConversionFactor[[#Headers],[Gas]], 0)} -> 44 | G48: {=Common_InputFunctions.Utility_DisplayArrayInTable(Common_SourceData.Common_SourceData_ConvertGasElementalToMolecular_Data(),Table_GasToMolecularConversionFactor[[#Headers],[Gas]], 0)} -> 12 | H48: =Table_GasToMolecularConversionFactor[[#This Row],[Conversion factor 1]]/Table_GasToMolecularConversionFactor[[#This Row],[Conversion factor 2]] -> 3.6666667
D49: {=Common_InputFunctions.Utility_DisplayArrayInTable(Common_SourceData.Common_SourceData_ConvertGasElementalToMolecular_Data(),Table_GasToMolecularConversionFactor[[#Headers],[Gas]], 0)} -> CH4 | E49: {=Common_InputFunctions.Utility_DisplayArrayInTable(Common_SourceData.Common_SourceData_ConvertGasElementalToMolecular_Data(),Table_GasToMolecularConversionFactor[[#Headers],[Gas]], 0)} -> 16/12 | F49: {=Common_InputFunctions.Utility_DisplayArrayInTable(Common_SourceData.Common_SourceData_ConvertGasElementalToMolecular_Data(),Table_GasToMolecularConversionFactor[[#Headers],[Gas]], 0)} -> 16 | G49: {=Common_InputFunctions.Utility_DisplayArrayInTable(Common_SourceData.Common_SourceData_ConvertGasElementalToMolecular_Data(),Table_GasToMolecularConversionFactor[[#Headers],[Gas]], 0)} -> 12 | H49: =Table_GasToMolecularConversionFactor[[#This Row],[Conversion factor 1]]/Table_GasToMolecularConversionFactor[[#This Row],[Conversion factor 2]] -> 1.3333333
D50: {=Common_InputFunctions.Utility_DisplayArrayInTable(Common_SourceData.Common_SourceData_ConvertGasElementalToMolecular_Data(),Table_GasToMolecularConversionFactor[[#Headers],[Gas]], 0)} -> N2O | E50: {=Common_InputFunctions.Utility_DisplayArrayInTable(Common_SourceData.Common_SourceData_ConvertGasElementalToMolecular_Data(),Table_GasToMolecularConversionFactor[[#Headers],[Gas]], 0)} -> 44/28 | F50: {=Common_InputFunctions.Utility_DisplayArrayInTable(Common_SourceData.Common_SourceData_ConvertGasElementalToMolecular_Data(),Table_GasToMolecularConversionFactor[[#Headers],[Gas]], 0)} -> 44 | G50: {=Common_InputFunctions.Utility_DisplayArrayInTable(Common_SourceData.Common_SourceData_ConvertGasElementalToMolecular_Data(),Table_GasToMolecularConversionFactor[[#Headers],[Gas]], 0)} -> 28 | H50: =Table_GasToMolecularConversionFactor[[#This Row],[Conversion factor 1]]/Table_GasToMolecularConversionFactor[[#This Row],[Conversion factor 2]] -> 1.5714286
...
