Workbook
Name Common_Equations.Common_ConvertCH4ToCO2e: _xlfn.LAMBDA(_xlpm.E_CH4,_xlpm.GWP_CH4, _xlpm.E_CH4 * _xlpm.GWP_CH4)
Name Common_Equations.Common_ConvertCH4ToCO2e_Arguments: _xlfn.LAMBDA(_xlfn.MAKEARRAY(2, 2, _xlfn.LAMBDA(_xlpm.r,_xlpm.c, INDEX({"ECH4","Methane emissions (t CH4)";"GWPCH4","Global warming potential for methane (t CO2-e / t CH4)"}, _xlpm.r, _xlpm.c))))
Name Common_Equations.Common_ConvertCH4ToCO2e_LatexEquation: _xlfn.LAMBDA("CO2_e = E_{CH4} \times GWP_{CH4}")
Name Common_Equations.Common_ConvertCH4ToCO2e_NIRReference: _xlfn.LAMBDA("")
Name Common_Equations.Common_ConvertCH4ToCO2e_Title: _xlfn.LAMBDA("Convert methane emissions to carbon dioxide equivalent emissions")
Name Common_Equations.Common_ConvertCH4ToCO2e_Unit: _xlfn.LAMBDA("t CO2e")
Name Common_Equations.Common_ConvertCH4ToCO2e_Variable: _xlfn.LAMBDA("ECH4 CO2e")
Name Common_Equations.Common_ConvertN2OToCO2e: _xlfn.LAMBDA(_xlpm.E_N2O,_xlpm.GWP_N2O, _xlpm.E_N2O * _xlpm.GWP_N2O)
Name Common_Equations.Common_ConvertN2OToCO2e_LatexEquation: _xlfn.LAMBDA("CO2_e = E_{N2O} \times GWP_{N2O}")
Name Common_Equations.Common_ConvertN2OToCO2e_NIRReference: _xlfn.LAMBDA("")
Name Common_Equations.Common_ConvertN2OToCO2e_Title: _xlfn.LAMBDA("Convert nitrous oxide emissions to carbon dioxide equivalent emissions")
Name Common_Equations.Common_ConvertN2OToCO2e_Unit: _xlfn.LAMBDA("t CO2e")
Name Common_Equations.Common_ConvertN2OToCO2e_Variable: _xlfn.LAMBDA("EN2O CO2e")
Name Common_InputFunctions.Utility_ConvertStateCommonNameToAbbreviation: _xlfn.LAMBDA(_xlpm.StateCommonName,_xlpm.StateCommonNameArray,_xlpm.StateAbbreviationArray, _xlfn.XLOOKUP(_xlpm.StateCommonName, _xlpm.StateCommonNameArray, _xlpm.StateAbbreviationArray, ""))
Name Common_InputFunctions.Utility_DisplayArguments_1_2: _xlfn.LAMBDA(_xlpm.ArgumentsArray, _xlfn.CHOOSECOLS(_xlpm.ArgumentsArray, 1, 2))
Name Common_InputFunctions.Utility_DisplayArguments_3_4: _xlfn.LAMBDA(_xlpm.ArgumentsArray, _xlfn.CHOOSECOLS(_xlpm.ArgumentsArray, 3, 4))
Name Common_InputFunctions.Utility_DisplayFunctionName: _xlfn.LAMBDA(_xlpm.Function, _xlfn.TEXTBEFORE(_xlfn.FORMULATEXT(_xlpm.Function), "("))
Name Common_InputFunctions.Utility_GetArrayTableColumnStartNumber: _xlfn.LAMBDA(_xlpm.TableHeaderCell, COLUMN(_xlpm.TableHeaderCell))
Name Common_InputFunctions.Utility_GetArrayTableRowStartNumber: _xlfn.LAMBDA(_xlpm.TableheaderCell,_xlpm.RowsBetweenHeaderandArray, ROW(_xlpm.TableheaderCell) + _xlpm.RowsBetweenHeaderandArray - 1)
Name Common_InputFunctions.Utility_LookupValueInTable: _xlfn.LAMBDA(_xlpm.LookupValue,_xlpm.LookupArray,_xlpm.ReturnArray, _xlfn.XLOOKUP(_xlpm.LookupValue, _xlpm.LookupArray, _xlpm.ReturnArray, ""))
Name Common_InputFunctions.Utility_SourceHyperlink: _xlfn.LAMBDA(_xlpm.TargetCell, _xlfn.LET(_xlpm.sh, _xlfn.TEXTAFTER(CELL("filename", _xlpm.TargetCell), "]"), _xlpm.addr, CELL("address", _xlpm.TargetCell), "#'" & _xlpm.sh & "'!" & _xlpm.addr))
Name Common_SourceData.Common_SourceData_AustralianStatesTerritories_Source: _xlfn.LAMBDA("")
Name Common_SourceData.Common_SourceData_AustralianStatesTerritories_Title: _xlfn.LAMBDA("Australian states and territories")
Name Common_SourceData.Common_SourceData_AustralianStatesTerritories_Unit: _xlfn.LAMBDA("")
Name Common_SourceData.Common_SourceData_AustralianStatesTerritories_Variable: _xlfn.LAMBDA("")
Name Common_SourceData.Common_SourceData_ClimateZones_Source: _xlfn.LAMBDA("VEERG 2026: Table 1.3: Climate and Rainfall zone classifications and definitions")
Name Common_SourceData.Common_SourceData_ClimateZones_Title: _xlfn.LAMBDA("VEERG Australian climate zones")
Name Common_SourceData.Common_SourceData_ClimateZones_Unit: _xlfn.LAMBDA("")
Name Common_SourceData.Common_SourceData_ClimateZones_Variable: _xlfn.LAMBDA("")
Name Common_SourceData.Common_SourceData_ConvertGasElementalToMolecular_Source: _xlfn.LAMBDA("XXXXXXX")
Name Common_SourceData.Common_SourceData_ConvertGasElementalToMolecular_Title: _xlfn.LAMBDA("Factor to convert elemental mass of gas to molecular mass")
Name Common_SourceData.Common_SourceData_ConvertGasElementalToMolecular_Unit: _xlfn.LAMBDA("factor")
Name Common_SourceData.Common_SourceData_ConvertGasElementalToMolecular_Variable: _xlfn.LAMBDA("Cg")
Name Common_SourceData.Common_SourceData_ConvertN2oElementalToMolecularCg_Data: _xlfn.LAMBDA(44 / 28)
Name Common_SourceData.Common_SourceData_ConvertN2oElementalToMolecularCg_Source: _xlfn.LAMBDA("National Inventory Report 2023 Volume 1")
Name Common_SourceData.Common_SourceData_ConvertN2oElementalToMolecularCg_Title: _xlfn.LAMBDA("Factor to convert elemental mass of N2O to molecular mass")
Name Common_SourceData.Common_SourceData_ConvertN2oElementalToMolecularCg_Unit: _xlfn.LAMBDA("factor")
Name Common_SourceData.Common_SourceData_ConvertN2oElementalToMolecularCg_Variable: _xlfn.LAMBDA("CgN2O")
Name Common_SourceData.Common_SourceData_DataScores_Scope3_Source: _xlfn.LAMBDA("VEERG 2026: XXXXXXXX")
Name Common_SourceData.Common_SourceData_DataScores_Scope3_Title: _xlfn.LAMBDA("Australian data scores for scope 3")
Name Common_SourceData.Common_SourceData_DataScores_Scope3_Unit: _xlfn.LAMBDA("")
Name Common_SourceData.Common_SourceData_DataScores_Scope3_Variable: _xlfn.LAMBDA("")
Name Common_SourceData.Common_SourceData_DataScores_Scope3_Variation: _xlfn.LAMBDA("")
Name Common_SourceData.Common_SourceData_DensityOfMethane_Data: _xlfn.LAMBDA(0.6784)
Name Common_SourceData.Common_SourceData_DensityOfMethane_Source: _xlfn.LAMBDA("National Inventory Report 2023 Volume 1: Equations 3.B.1a_2, 3.B.1c_2, 3.B.3_1, 3.B.4g_2")
Name Common_SourceData.Common_SourceData_DensityOfMethane_Title: _xlfn.LAMBDA("p = density of methane")
Name Common_SourceData.Common_SourceData_DensityOfMethane_Unit: _xlfn.LAMBDA("kg/m3")
Name Common_SourceData.Common_SourceData_EFleach_Data: _xlfn.LAMBDA(_xlfn.MAKEARRAY(1, 2, _xlfn.LAMBDA(_xlpm.r,_xlpm.c, INDEX({"EFleach",0.011}, _xlpm.r, _xlpm.c))))
Name Common_SourceData.Common_SourceData_EFleach_NIRReference: _xlfn.LAMBDA("National Inventory Report Volume 1: Equation 3.D.B_10")
Name Common_SourceData.Common_SourceData_EFleach_Source: _xlfn.LAMBDA("VEERG 2026:5.5.2.3 Constant Parameters")
Name Common_SourceData.Common_SourceData_EFleach_Title: _xlfn.LAMBDA("Emission factor for nitrogen leaching and runoff")
Name Common_SourceData.Common_SourceData_EFleach_Unit: _xlfn.LAMBDA("(kg N2O-N / kg N")
Name Common_SourceData.Common_SourceData_EFleach_Variation: _xlfn.LAMBDA((""))
Name Common_SourceData.Common_SourceData_EFN2O_NIRReference: _xlfn.LAMBDA("")
Name Common_SourceData.Common_SourceData_EFN2O_Source: _xlfn.LAMBDA("VEERG 2026: Table A.2.2.1")
Name Common_SourceData.Common_SourceData_EFN2O_Title: _xlfn.LAMBDA("Nitrous oxide emission factors for inorganic fertiliser application")
Name Common_SourceData.Common_SourceData_EFN2O_Unit: _xlfn.LAMBDA("(kg N2O-N / kg N")
Name Common_SourceData.Common_SourceData_EFOrganicFertiliserAndCropResidues_Data: _xlfn.LAMBDA(_xlfn.MAKEARRAY(3, 2, _xlfn.LAMBDA(_xlpm.r,_xlpm.c, INDEX({"Climate zone","EFNi & EFN2O";"Wet climate zone",0.006;"Dry climate zone",0.005}, _xlpm.r, _xlpm.c))))
Name Common_SourceData.Common_SourceData_EFOrganicFertiliserAndCropResidues_NIRReference: _xlfn.LAMBDA("")
Name Common_SourceData.Common_SourceData_EFOrganicFertiliserAndCropResidues_Source: _xlfn.LAMBDA("VEERG 2026: Table A.2.1.4")

Sheet Home
A1: Home

Sheet Overview
A1: #VALUE! | C1: 3.1: Enteric Methane: Beef feedlot: Overview
A3: =HYPERLINK("#'Home'!A1", "Home") -> Home
A4: =HYPERLINK("#'Overview'!A1", "Overview") -> Overview
A5: =HYPERLINK("#'Results'!A1", "Results") -> Results | D5: 💡 Below is a diagram that maps the equations used to calculate emissions and how they interact with each other.
D6: Click on a box to go to the corresponding calculation.
A7: INPUTS
A8: =HYPERLINK("#'Input - Site'!A1", "Site") -> Site
A9: =HYPERLINK("#'Input - Feedlot'!A1", "Feedlot") -> Feedlot
A11: CALCULATIONS
A12: =HYPERLINK("#'3.1.1.1-2 Enteric Methane'!A1", "3.1.1.1-2 Enteric Methane") -> 3.1.1.1-2 Enteric Methane
A14: APPENDICES
A15: =HYPERLINK("#'Constants - Feedlot'!A1", "Constants - Feedlot") -> Constants - Feedlot
A16: =HYPERLINK("#'Constants - Livestock'!A1", "Constants - Livestock") -> Constants - Livestock
A17: =HYPERLINK("#'Constants - Common'!A1", "Constants - Common") -> Constants - Common
A18: =HYPERLINK("#'Acknowledgements'!A1", "Acknowledgements") -> Acknowledgements

Sheet Results
A1: #VALUE! | C1: 3.1 Enteric Methane: Beef Feedlot: Results
A3: =HYPERLINK("#'Home'!A1", "Home") -> Home
A4: =HYPERLINK("#'Overview'!A1", "Overview") -> Overview | D4: Emissions breakdown
A5: =HYPERLINK("#'Results'!A1", "Results") -> Results
D6: Scope 1 source | E6: GHG emissions method 1 | F6: GHG emissions method 2 | G6: GHG Unit | H6: CO2-e emissions method 1 | I6: CO2-e emissions method 2 | J6: CO2-e unit
A7: INPUTS | D7: 3.1.1.1-2 Enteric Methane | E7: =VEERG_3_1_1_1__1_TotalAnnualMethaneFromEntericFermentation_Result -> 35.42023 | F7: ='3.1.1.1-2 Enteric Methane'!N67 -> 35.42023 | G7: ='3.1.1.1-2 Enteric Methane'!F67 -> t CH4 | H7: ='3.1.1.1-2 Enteric Methane'!E72 -> 991.76644 | I7: ='3.1.1.1-2 Enteric Methane'!N72 -> 991.76644 | J7: t CO2e
A8: =HYPERLINK("#'Input - Site'!A1", "Site") -> Site | D8: Total | H8: =SUM(H7:H7) -> 991.76644 | I8: =SUM(I7:I7) -> 991.76644 | J8: t CO2e
A9: =HYPERLINK("#'Input - Feedlot'!A1", "Feedlot") -> Feedlot
A11: CALCULATIONS
A12: =HYPERLINK("#'3.1.1.1-2 Enteric Methane'!A1", "3.1.1.1-2 Enteric Methane") -> 3.1.1.1-2 Enteric Methane
A14: APPENDICES
A15: =HYPERLINK("#'Constants - Feedlot'!A1", "Constants - Feedlot") -> Constants - Feedlot
A16: =HYPERLINK("#'Constants - Livestock'!A1", "Constants - Livestock") -> Constants - Livestock
A17: =HYPERLINK("#'Constants - Common'!A1", "Constants - Common") -> Constants - Common
A18: =HYPERLINK("#'Acknowledgements'!A1", "Acknowledgements") -> Acknowledgements

Sheet Input - Site
A1: #VALUE! | C1: Input - Site
A3: =HYPERLINK("#'Home'!A1", "Home") -> Home
A4: =HYPERLINK("#'Overview'!A1", "Overview") -> Overview
A5: =HYPERLINK("#'Results'!A1", "Results") -> Results | D5: Your business
A7: INPUTS | D7: Farm name | E7: Test Farms
A8: =HYPERLINK("#'Input - Site'!A1", "Site") -> Site | D8: Reporting entity name | E8: Test Farms Pty Ltd
A9: =HYPERLINK("#'Input - Feedlot'!A1", "Feedlot") -> Feedlot
D10: 💡An 'Emissions accounting period' is a 12 month period where the business can report on the emissions, and is typically the same as the business' financial accounting period.
A11: CALCULATIONS
A12: =HYPERLINK("#'3.1.1.1-2 Enteric Methane'!A1", "3.1.1.1-2 Enteric Methane") -> 3.1.1.1-2 Enteric Methane | D12: Emissions calculation period start date | E12: 45292 | F12: ← DD/MM/YYYY or DD Month YYYY
D13: Emissions calculation period end date | E13: =DATE(YEAR(E12)+1,MONTH(E12),DAY(E12))-1 -> 45657 | F13: ← Automatically calculated, 12 months after start date
A14: APPENDICES
A15: =HYPERLINK("#'Constants - Feedlot'!A1", "Constants - Feedlot") -> Constants - Feedlot
A16: =HYPERLINK("#'Constants - Livestock'!A1", "Constants - Livestock") -> Constants - Livestock
A17: =HYPERLINK("#'Constants - Common'!A1", "Constants - Common") -> Constants - Common
A18: =HYPERLINK("#'Acknowledgements'!A1", "Acknowledgements") -> Acknowledgements

Sheet Input - Feedlot
A1: #VALUE! | C1: Input - Feedlot
A3: =HYPERLINK("#'Home'!A1", "Home") -> Home
A4: =HYPERLINK("#'Overview'!A1", "Overview") -> Overview
A5: =HYPERLINK("#'Results'!A1", "Results") -> Results | D5: Herd movement
A7: INPUTS | E7: Domestic | F7: Mid-fed | G7: Long-fed
A8: =HYPERLINK("#'Input - Site'!A1", "Site") -> Site | D8: ="Average number of head between " & TEXT('Input - Site'!$E$12, "dd mmm yy") & " and " & TEXT('Input - Site'!$E$13, "dd mmm yy") -> Average number of head between 01 Jan 24 and 31 Dec 24 | E8: 4300 | F8: 100 | G8: 100 | H8: head
A9: =HYPERLINK("#'Input - Feedlot'!A1", "Feedlot") -> Feedlot | D9: ="Average duration of stay between " & TEXT('Input - Site'!$E$12, "dd mmm yy") & " and " & TEXT('Input - Site'!$E$13, "dd mmm yy") -> Average duration of stay between 01 Jan 24 and 31 Dec 24 | E9: 90 | F9: 140 | G9: 250 | H9: days
A11: CALCULATIONS | D11: Intake
A12: =HYPERLINK("#'3.1.1.1-2 Enteric Methane'!A1", "3.1.1.1-2 Enteric Methane") -> 3.1.1.1-2 Enteric Methane
D13: Method 1 default values (Do not edit) | E13: Domestic | F13: Mid-fed | G13: Long-fed
A14: APPENDICES | D14: Feed intake | E14: {=_xlfn.XLOOKUP(1, (Table_SourceData_Feedlot_AnimalCharacteristics[Feedlot type] = E$13) * (Table_SourceData_Feedlot_AnimalCharacteristics[Characteristic] = $D$14), Table_SourceData_Feedlot_AnimalCharacteristics[2020-2023], "Not Found")} -> 10.4 | F14: {=_xlfn.XLOOKUP(1, (Table_SourceData_Feedlot_AnimalCharacteristics[Feedlot type] = F$13) * (Table_SourceData_Feedlot_AnimalCharacteristics[Characteristic] = $D$14), Table_SourceData_Feedlot_AnimalCharacteristics[2020-2023], "Not Found")} -> 10.8 | G14: {=_xlfn.XLOOKUP(1, (Table_SourceData_Feedlot_AnimalCharacteristics[Feedlot type] = G$13) * (Table_SourceData_Feedlot_AnimalCharacteristics[Characteristic] = $D$14), Table_SourceData_Feedlot_AnimalCharacteristics[2020-2023], "Not Found")} -> 8.2 | H14: kg dry matter / head day
A15: =HYPERLINK("#'Constants - Feedlot'!A1", "Constants - Feedlot") -> Constants - Feedlot | D15: Ether extract | E15: {=_xlfn.XLOOKUP(1, (Table_SourceData_Feedlot_DietProperties[Feedlot type] = E$13) * (Table_SourceData_Feedlot_DietProperties[Nutrient analysis] = $D$15), Table_SourceData_Feedlot_DietProperties[2020-2023 Converted to fraction], "Not Found")} -> 4.8 | F15: {=_xlfn.XLOOKUP(1, (Table_SourceData_Feedlot_DietProperties[Feedlot type] = F$13) * (Table_SourceData_Feedlot_DietProperties[Nutrient analysis] = $D$15), Table_SourceData_Feedlot_DietProperties[2020-2023 Converted to fraction], "Not Found")} -> 5 | G15: {=_xlfn.XLOOKUP(1, (Table_SourceData_Feedlot_DietProperties[Feedlot type] = G$13) * (Table_SourceData_Feedlot_DietProperties[Nutrient analysis] = $D$15), Table_SourceData_Feedlot_DietProperties[2020-2023 Converted to fraction], "Not Found")} -> 5.5 | H15: fraction
A16: =HYPERLINK("#'Constants - Livestock'!A1", "Constants - Livestock") -> Constants - Livestock | D16: NDF | E16: {=_xlfn.XLOOKUP(1, (Table_SourceData_Feedlot_DietProperties[Feedlot type] = E$13) * (Table_SourceData_Feedlot_DietProperties[Nutrient analysis] = $D$16), Table_SourceData_Feedlot_DietProperties[2020-2023 Converted to fraction], "Not Found")} -> 22 | F16: {=_xlfn.XLOOKUP(1, (Table_SourceData_Feedlot_DietProperties[Feedlot type] = F$13) * (Table_SourceData_Feedlot_DietProperties[Nutrient analysis] = $D$16), Table_SourceData_Feedlot_DietProperties[2020-2023 Converted to fraction], "Not Found")} -> 22 | G16: {=_xlfn.XLOOKUP(1, (Table_SourceData_Feedlot_DietProperties[Feedlot type] = G$13) * (Table_SourceData_Feedlot_DietProperties[Nutrient analysis] = $D$16), Table_SourceData_Feedlot_DietProperties[2020-2023 Converted to fraction], "Not Found")} -> 24 | H16: fraction
A17: =HYPERLINK("#'Constants - Common'!A1", "Constants - Common") -> Constants - Common
A18: =HYPERLINK("#'Acknowledgements'!A1", "Acknowledgements") -> Acknowledgements | D18: Method 2 custom values (Edit if known) | E18: Domestic | F18: Mid-fed | G18: Long-fed
D19: Feed intake | E19: {=_xlfn.XLOOKUP(1, (Table_SourceData_Feedlot_AnimalCharacteristics[Feedlot type] = E$18) * (Table_SourceData_Feedlot_AnimalCharacteristics[Characteristic] = $D$19), Table_SourceData_Feedlot_AnimalCharacteristics[2020-2023], "Not Found")} -> 10.4 | F19: {=_xlfn.XLOOKUP(1, (Table_SourceData_Feedlot_AnimalCharacteristics[Feedlot type] = F$18) * (Table_SourceData_Feedlot_AnimalCharacteristics[Characteristic] = $D$19), Table_SourceData_Feedlot_AnimalCharacteristics[2020-2023], "Not Found")} -> 10.8 | G19: {=_xlfn.XLOOKUP(1, (Table_SourceData_Feedlot_AnimalCharacteristics[Feedlot type] = G$18) * (Table_SourceData_Feedlot_AnimalCharacteristics[Characteristic] = $D$19), Table_SourceData_Feedlot_AnimalCharacteristics[2020-2023], "Not Found")} -> 8.2 | H19: kg dry matter / head day
D20: Ether extract | E20: {=_xlfn.XLOOKUP(1, (Table_SourceData_Feedlot_DietProperties[Feedlot type] = E$18) * (Table_SourceData_Feedlot_DietProperties[Nutrient analysis] = $D$20), Table_SourceData_Feedlot_DietProperties[2020-2023 Converted to fraction], "Not Found")} -> 4.8 | F20: {=_xlfn.XLOOKUP(1, (Table_SourceData_Feedlot_DietProperties[Feedlot type] = F$18) * (Table_SourceData_Feedlot_DietProperties[Nutrient analysis] = $D$20), Table_SourceData_Feedlot_DietProperties[2020-2023 Converted to fraction], "Not Found")} -> 5 | G20: {=_xlfn.XLOOKUP(1, (Table_SourceData_Feedlot_DietProperties[Feedlot type] = G$18) * (Table_SourceData_Feedlot_DietProperties[Nutrient analysis] = $D$20), Table_SourceData_Feedlot_DietProperties[2020-2023 Converted to fraction], "Not Found")} -> 5.5 | H20: fraction
D21: NDF | E21: {=_xlfn.XLOOKUP(1, (Table_SourceData_Feedlot_DietProperties[Feedlot type] = E$18) * (Table_SourceData_Feedlot_DietProperties[Nutrient analysis] = $D$21), Table_SourceData_Feedlot_DietProperties[2020-2023 Converted to fraction], "Not Found")} -> 22 | F21: {=_xlfn.XLOOKUP(1, (Table_SourceData_Feedlot_DietProperties[Feedlot type] = F$18) * (Table_SourceData_Feedlot_DietProperties[Nutrient analysis] = $D$21), Table_SourceData_Feedlot_DietProperties[2020-2023 Converted to fraction], "Not Found")} -> 22 | G21: {=_xlfn.XLOOKUP(1, (Table_SourceData_Feedlot_DietProperties[Feedlot type] = G$18) * (Table_SourceData_Feedlot_DietProperties[Nutrient analysis] = $D$21), Table_SourceData_Feedlot_DietProperties[2020-2023 Converted to fraction], "Not Found")} -> 24 | H21: fraction

Sheet 3.1.1.1-2 Enteric Methane
A1: #VALUE! | C1: 3.1.1.1-2 Enteric Methane Beef Feedlot
A3: =HYPERLINK("#'Home'!A1", "Home") -> Home | D3: Method 1 | M3: Method 2
A4: =HYPERLINK("#'Overview'!A1", "Overview") -> Overview
A5: =HYPERLINK("#'Results'!A1", "Results") -> Results | D5: {=EntericMethane_Feedlot_Equations.VEERG_3_1_1_1__2_DailyEntericMethaneProduction_Title()} -> Daily production of enteric methane
D6: {=EntericMethane_Feedlot_Equations.VEERG_3_1_1_1__2_DailyEntericMethaneProduction_Source()} -> VEERG 2026: 3.1.1.1, Equation (2)
A7: INPUTS | D7: Function name | E7: {=Common_InputFunctions.Utility_DisplayFunctionName(D35)} -> =EntericMethane_Feedlot_Equations.VEERG_3_1_1_1__2_DailyEntericMethaneProduction
A8: =HYPERLINK("#'Input - Site'!A1", "Site") -> Site
A9: =HYPERLINK("#'Input - Feedlot'!A1", "Feedlot") -> Feedlot
D10: Variable | E10: {=EntericMethane_Feedlot_Equations.VEERG_3_1_1_1__2_DailyEntericMethaneProduction_Variable()} -> M_j
A11: CALCULATIONS | D11: Unit | E11: {=EntericMethane_Feedlot_Equations.VEERG_3_1_1_1__2_DailyEntericMethaneProduction_Unit()} -> kg CH4/head/day
A12: =HYPERLINK("#'3.1.1.1-2 Enteric Methane'!A1", "3.1.1.1-2 Enteric Methane") -> 3.1.1.1-2 Enteric Methane
D13: {=_xlfn.CHOOSECOLS(EntericMethane_Feedlot_Equations.VEERG_3_1_1_1__2_DailyEntericMethaneProduction_Arguments(),1,2)} -> I_j | E13: dry matter intake | G13: {=_xlfn.CHOOSECOLS(EntericMethane_Feedlot_Equations.VEERG_3_1_1_1__2_DailyEntericMethaneProduction_Arguments(),3,4)} -> kg DM/head/day | H13: Input | I13: {=HYPERLINK(Common_InputFunctions.Utility_SourceHyperlink($D$17),$D$17)} -> M1_Table_I_j
A14: APPENDICES | D14: EE_j | E14: ether extract as a percentage of I_j | G14: per cent | H14: Input | I14: {=HYPERLINK(Common_InputFunctions.Utility_SourceHyperlink($D$22),$D$22)} -> M1_Table_EE_j
A15: =HYPERLINK("#'Constants - Feedlot'!A1", "Constants - Feedlot") -> Constants - Feedlot | D15: NDF_j | E15: neutral detergent fibre as a percentage of I_j | G15: per cent | H15: Input | I15: {=HYPERLINK(Common_InputFunctions.Utility_SourceHyperlink($D$27),$D$27)} -> M1_Table_NDF_j
A16: =HYPERLINK("#'Constants - Livestock'!A1", "Constants - Livestock") -> Constants - Livestock
A17: =HYPERLINK("#'Constants - Common'!A1", "Constants - Common") -> Constants - Common | D17: M1_Table_I_j | M17: M2_Table_I_j
A18: =HYPERLINK("#'Acknowledgements'!A1", "Acknowledgements") -> Acknowledgements | D18: Dry matter intake (Method 1) | M18: Dry matter intake (Method 2)
D19: Domestic | E19: Mid-fed | F19: Long-fed | M19: Domestic | N19: Mid-fed | O19: Long-fed
D20: ='Input - Feedlot'!$E$14 -> 10.4 | E20: ='Input - Feedlot'!$F$14 -> 10.8 | F20: ='Input - Feedlot'!$G$14 -> 8.2 | G20: =$G$13 -> kg DM/head/day | M20: =Input_Feedlot_FeedIntake_Domestic -> 10.4 | N20: =Input_Feedlot_FeedIntake_MidFed -> 10.8 | O20: =Input_Feedlot_FeedIntake_LongFed -> 8.2 | P20: =$G$13 -> kg DM/head/day
D22: M1_Table_EE_j | M22: M2_Table_EE_j
D23: Ether extract (Method 1) | M23: Ether extract (Method 2)
D24: Domestic | E24: Mid-fed | F24: Long-fed | M24: Domestic | N24: Mid-fed | O24: Long-fed
D25: ='Input - Feedlot'!$E$15 -> 4.8 | E25: ='Input - Feedlot'!$F$15 -> 5 | F25: ='Input - Feedlot'!$G$15 -> 5.5 | G25: =$G$14 -> per cent | M25: =Input_Feedlot_EtherExtract_Domestic -> 4.8 | N25: =Input_Feedlot_EtherExtract_MidFed -> 5 | O25: =Input_Feedlot_EtherExtract_LongFed -> 5.5 | P25: =$G$14 -> per cent
D27: M1_Table_NDF_j | M27: M2_Table_NDF_j
D28: Neutral detergent fibre (Method 1) | M28: Neutral detergent fibre (Method 2)
D29: Domestic | E29: Mid-fed | F29: Long-fed | M29: Domestic | N29: Mid-fed | O29: Long-fed
D30: ='Input - Feedlot'!$E$16 -> 22 | E30: ='Input - Feedlot'!$F$16 -> 22 | F30: ='Input - Feedlot'!$G$16 -> 24 | G30: =$G$15 -> per cent | M30: =Input_Feedlot_NDF_Domestic -> 22 | N30: =Input_Feedlot_NDF_MidFed -> 22 | O30: =Input_Feedlot_NDF_LongFed -> 24 | P30: =$G$15 -> per cent
D32: M1_Table_M_j | M32: M2_Table_M_j
D33: Daily production of enteric methane (Method 1) | M33: Daily production of enteric methane (Method 2)
D34: Domestic | E34: Mid-fed | F34: Long-fed | M34: Domestic | N34: Mid-fed | O34: Long-fed
D35: {=EntericMethane_Feedlot_Equations.VEERG_3_1_1_1__2_DailyEntericMethaneProduction(D20,D25,D30)} -> 0.083664 | E35: {=EntericMethane_Feedlot_Equations.VEERG_3_1_1_1__2_DailyEntericMethaneProduction(E20,E25,E30)} -> 0.084908 | F35: {=EntericMethane_Feedlot_Equations.VEERG_3_1_1_1__2_DailyEntericMethaneProduction(F20,F25,F30)} -> 0.074142 | G35: =$E$11 -> kg CH4/head/day | M35: {=EntericMethane_Feedlot_Equations.VEERG_3_1_1_1__2_DailyEntericMethaneProduction(M20,M25,M30)} -> 0.083664 | N35: {=EntericMethane_Feedlot_Equations.VEERG_3_1_1_1__2_DailyEntericMethaneProduction(N20,N25,N30)} -> 0.084908 | O35: {=EntericMethane_Feedlot_Equations.VEERG_3_1_1_1__2_DailyEntericMethaneProduction(O20,O25,O30)} -> 0.074142 | P35: =$E$11 -> kg CH4/head/day
D39: {=EntericMethane_Feedlot_Equations.VEERG_3_1_1_1__1_TotalAnnualMethaneFromEntericFermentation_Title()} -> Total annual methane production from enteric fermentation in feedlot beef cattle
D40: {=EntericMethane_Feedlot_Equations.VEERG_3_1_1_1__1_TotalAnnualMethaneFromEntericFermentation_Source()} -> VEERG 2026: 3.1.1.1, Equation (1)
D41: Function name | E41: {=Common_InputFunctions.Utility_DisplayFunctionName(D65)} -> =EntericMethane_Feedlot_Equations.VEERG_3_1_1_1__1_TotalAnnualMethaneFromEntericFermentation
D45: Variable | E45: {=EntericMethane_Feedlot_Equations.VEERG_3_1_1_1__1_TotalAnnualMethaneFromEntericFermentation_Variable()} -> E_enteric
D46: Unit | E46: {=EntericMethane_Feedlot_Equations.VEERG_3_1_1_1__1_TotalAnnualMethaneFromEntericFermentation_Unit()} -> t CH4
D48: {=_xlfn.CHOOSECOLS(EntericMethane_Feedlot_Equations.VEERG_3_1_1_1__1_TotalAnnualMethaneFromEntericFermentation_Arguments(),1,2)} -> D_j | E48: duration of stay of each cattle lot | G48: {=_xlfn.CHOOSECOLS(EntericMethane_Feedlot_Equations.VEERG_3_1_1_1__1_TotalAnnualMethaneFromEntericFermentation_Arguments(),3,4)} -> days | H48: Input | I48: {=HYPERLINK(Common_InputFunctions.Utility_SourceHyperlink($D$52),$D$52)} -> Table_D_j
D49: M_j | E49: daily methane production | G49: kg CH4/head/day | H49: Calculated from 3.1.1.1, (2) | I49: {=HYPERLINK(Common_InputFunctions.Utility_SourceHyperlink($D$32),$D$32)} -> M1_Table_M_j
D50: N_j | E50: numbers of feedlot cattle in each cattle lot | G50: head | H50: Input | I50: {=HYPERLINK(Common_InputFunctions.Utility_SourceHyperlink($D$57),$D$57)} -> Table_N_j
D52: Table_D_j
...

Sheet Constants - Feedlot
A1: #VALUE! | C1: Source Data - Feedlot
A3: =HYPERLINK("#'Home'!A1", "Home") -> Home
A4: =HYPERLINK("#'Overview'!A1", "Overview") -> Overview
A5: =HYPERLINK("#'Results'!A1", "Results") -> Results | D5: {=SourceData_Feedlot.SourceData_Feedlot_VSL_Title()} -> Feedlot - Fraction of volatile solids lost during storage in the primary system
D6: {=SourceData_Feedlot.SourceData_Feedlot_VSL_Source()} -> VEERG 2026: 4.1.2.3 CONSTANTS
A7: INPUTS | D7: {=SourceData_Feedlot.SourceData_Feedlot_VSL_Variable()} -> VSL | E7: {=SourceData_Feedlot.SourceData_Feedlot_VSL_Data()} -> 0.5 | F7: {=SourceData_Feedlot.SourceData_Feedlot_VSL_Unit()} -> Fraction
A8: =HYPERLINK("#'Input - Site'!A1", "Site") -> Site
A9: =HYPERLINK("#'Input - Feedlot'!A1", "Feedlot") -> Feedlot
D10: {=SourceData_Feedlot.SourceData_Feedlot_MMSm1T3_Title()} -> Fraction of volatile solids to each tertiary system assumed that 2 per cent is run - off from the feed pad.
A11: CALCULATIONS | D11: {=SourceData_Feedlot.SourceData_Feedlot_MMSm1T3_Source()} -> VEERG 2026: 4.1.2.3 CONSTANTS
A12: =HYPERLINK("#'3.1.1.1-2 Enteric Methane'!A1", "3.1.1.1-2 Enteric Methane") -> 3.1.1.1-2 Enteric Methane | D12: {=SourceData_Feedlot.SourceData_Feedlot_MMSm1T3_Variable()} -> MMSm1T3 | E12: {=SourceData_Feedlot.SourceData_Feedlot_MMSm1T3_Data()} -> 0.02 | F12: {=SourceData_Feedlot.SourceData_Feedlot_MMSm1T3_Unit()} -> Fraction
A14: APPENDICES
A15: =HYPERLINK("#'Constants - Feedlot'!A1", "Constants - Feedlot") -> Constants - Feedlot | D15: {=SourceData_Feedlot.SourceData_Feedlot_AshContent_Title()} -> Ash content of manure.
A16: =HYPERLINK("#'Constants - Livestock'!A1", "Constants - Livestock") -> Constants - Livestock | D16: {=SourceData_Feedlot.SourceData_Feedlot_AshContent_Source()} -> VEERG 2026: 4.1.2.3 CONSTANTS
A17: =HYPERLINK("#'Constants - Common'!A1", "Constants - Common") -> Constants - Common | D17: {=SourceData_Feedlot.SourceData_Feedlot_AshContent_Variable()} -> A | E17: {=SourceData_Feedlot.SourceData_Feedlot_AshContent_Data()} -> 0.16 | F17: {=SourceData_Feedlot.SourceData_Feedlot_AshContent_Unit()} -> Fraction
A18: =HYPERLINK("#'Acknowledgements'!A1", "Acknowledgements") -> Acknowledgements
D20: {=SourceData_Feedlot.SourceData_Feedlot_MethaneEmissionsPotential_Title()} -> Methane emissions potential.
D21: {=SourceData_Feedlot.SourceData_Feedlot_MethaneEmissionsPotential_Source()} -> VEERG 2026: 4.1.2.3 CONSTANTS
D22: {=SourceData_Feedlot.SourceData_Feedlot_MethaneEmissionsPotential_Variable()} -> B0 | E22: {=SourceData_Feedlot.SourceData_Feedlot_MethaneEmissionsPotential_Data()} -> 0.19 | F22: {=SourceData_Feedlot.SourceData_Feedlot_MethaneEmissionsPotential_Unit()} -> m3 CH4 / kg VS
D25: Feedlot manure management systems | G25: Feedlot crop or pasture production systems | J25: Irrigation methods
D27: MMS | E27: Symbol and MMS | G27: Production system | J27: Irrigation method
D28: ='Constants - Livestock'!$E$16 -> Drylot (feed pad) | E28: ='Constants - Livestock'!$F$16 -> Drylot (feed pad) (m=5) | G28: ='Constants - Common'!$F$188 -> Crop | J28: Not irrigated
D29: ='Constants - Livestock'!$E$15 -> Solid storage | E29: ='Constants - Livestock'!$F$15 -> Solid storage (m=4) | G29: ='Constants - Common'!$F$187 -> Pasture | J29: Drip irrigation
D30: ='Constants - Livestock'!$E$17 -> Composting (passive windrow) | E30: ='Constants - Livestock'!$F$17 -> Composting (passive windrow) (m=6) | J30: Sprinkler irrigation
D31: ='Constants - Livestock'!$E$26 -> Direct application | E31: ='Constants - Livestock'!$F$26 -> Direct application (m=13) | J31: Surface irrigation
D32: ='Constants - Livestock'!$E$10 -> Anaerobic lagoon | E32: ='Constants - Livestock'!$F$10 -> Anaerobic lagoon (m=1) | J32: Other irrigation
D36: {=SourceData_Feedlot.SourceData_Feedlot_DurationOfStay_Title()} -> Beef feedlot cattle - Duration of stay (days)
D37: {=SourceData_Feedlot.SourceData_Feedlot_DurationOfStay_Source()} -> VEERG 2026: Table A.1.1.1: Beef feedlot cattle - Duration of stay (days)
D38: Feedlot type | E38: Length of stay
D39: {=Common_InputFunctions.Utility_DisplayArrayInTable(SourceData_Feedlot.SourceData_Feedlot_DurationOfStay_Data(), Table_SourceData_Feedlot_LengthOfStay[[#Headers],[Feedlot type]], 0)} -> Domestic | E39: {=Common_InputFunctions.Utility_DisplayArrayInTable(SourceData_Feedlot.SourceData_Feedlot_DurationOfStay_Data(), Table_SourceData_Feedlot_LengthOfStay[[#Headers],[Feedlot type]], 0)} -> 1-80 days
D40: {=Common_InputFunctions.Utility_DisplayArrayInTable(SourceData_Feedlot.SourceData_Feedlot_DurationOfStay_Data(), Table_SourceData_Feedlot_LengthOfStay[[#Headers],[Feedlot type]], 0)} -> Mid-fed | E40: {=Common_InputFunctions.Utility_DisplayArrayInTable(SourceData_Feedlot.SourceData_Feedlot_DurationOfStay_Data(), Table_SourceData_Feedlot_LengthOfStay[[#Headers],[Feedlot type]], 0)} -> 81-200 days
D41: {=Common_InputFunctions.Utility_DisplayArrayInTable(SourceData_Feedlot.SourceData_Feedlot_DurationOfStay_Data(), Table_SourceData_Feedlot_LengthOfStay[[#Headers],[Feedlot type]], 0)} -> Long-fed | E41: {=Common_InputFunctions.Utility_DisplayArrayInTable(SourceData_Feedlot.SourceData_Feedlot_DurationOfStay_Data(), Table_SourceData_Feedlot_LengthOfStay[[#Headers],[Feedlot type]], 0)} -> 201+ days
D44: {=SourceData_Feedlot.SourceData_Feedlot_AnimalCharacteristics_Title()} -> Beef feedlot cattle - Animal characteristics
D45: {=SourceData_Feedlot.SourceData_Feedlot_AnimalCharacteristics_Source()} -> VEERG 2026: Table A.1.1.2: Beef feedlot cattle - Animal characteristics
D46: {=SourceData_Feedlot.SourceData_Feedlot_AnimalCharacteristics_Variation()} -> VARIATION ON SOURCE:
D47: Moved feedlot types to a separate column to aid lookup.
D48: Named 'characteristic' column - original has header 'Unit' which covers two columns)
D49: Feedlot type | E49: Characteristic | F49: Unit | G49: 2005-2009 | H49: 2010-2014 | I49: 2015-2019 | J49: 2020-2023
D50: {=Common_InputFunctions.Utility_DisplayArrayInTable(SourceData_Feedlot.SourceData_Feedlot_AnimalCharacteristics_Data(), Table_SourceData_Feedlot_AnimalCharacteristics[[#Headers],[Feedlot type]], 0)} -> Domestic | E50: {=Common_InputFunctions.Utility_DisplayArrayInTable(SourceData_Feedlot.SourceData_Feedlot_AnimalCharacteristics_Data(), Table_SourceData_Feedlot_AnimalCharacteristics[[#Headers],[Feedlot type]], 0)} -> Days on feed | F50: {=Common_InputFunctions.Utility_DisplayArrayInTable(SourceData_Feedlot.SourceData_Feedlot_AnimalCharacteristics_Data(), Table_SourceData_Feedlot_AnimalCharacteristics[[#Headers],[Feedlot type]], 0)} -> days | G50: {=Common_InputFunctions.Utility_DisplayArrayInTable(SourceData_Feedlot.SourceData_Feedlot_AnimalCharacteristics_Data(), Table_SourceData_Feedlot_AnimalCharacteristics[[#Headers],[Feedlot type]], 0)} -> 70 | H50: {=Common_InputFunctions.Utility_DisplayArrayInTable(SourceData_Feedlot.SourceData_Feedlot_AnimalCharacteristics_Data(), Table_SourceData_Feedlot_AnimalCharacteristics[[#Headers],[Feedlot type]], 0)} -> 70 | I50: {=Common_InputFunctions.Utility_DisplayArrayInTable(SourceData_Feedlot.SourceData_Feedlot_AnimalCharacteristics_Data(), Table_SourceData_Feedlot_AnimalCharacteristics[[#Headers],[Feedlot type]], 0)} -> 70 | J50: {=Common_InputFunctions.Utility_DisplayArrayInTable(SourceData_Feedlot.SourceData_Feedlot_AnimalCharacteristics_Data(), Table_SourceData_Feedlot_AnimalCharacteristics[[#Headers],[Feedlot type]], 0)} -> 75
D51: {=Common_InputFunctions.Utility_DisplayArrayInTable(SourceData_Feedlot.SourceData_Feedlot_AnimalCharacteristics_Data(), Table_SourceData_Feedlot_AnimalCharacteristics[[#Headers],[Feedlot type]], 0)} -> Domestic | E51: {=Common_InputFunctions.Utility_DisplayArrayInTable(SourceData_Feedlot.SourceData_Feedlot_AnimalCharacteristics_Data(), Table_SourceData_Feedlot_AnimalCharacteristics[[#Headers],[Feedlot type]], 0)} -> Feed intake | F51: {=Common_InputFunctions.Utility_DisplayArrayInTable(SourceData_Feedlot.SourceData_Feedlot_AnimalCharacteristics_Data(), Table_SourceData_Feedlot_AnimalCharacteristics[[#Headers],[Feedlot type]], 0)} -> kg DM/day | G51: {=Common_InputFunctions.Utility_DisplayArrayInTable(SourceData_Feedlot.SourceData_Feedlot_AnimalCharacteristics_Data(), Table_SourceData_Feedlot_AnimalCharacteristics[[#Headers],[Feedlot type]], 0)} -> 10 | H51: {=Common_InputFunctions.Utility_DisplayArrayInTable(SourceData_Feedlot.SourceData_Feedlot_AnimalCharacteristics_Data(), Table_SourceData_Feedlot_AnimalCharacteristics[[#Headers],[Feedlot type]], 0)} -> 10 | I51: {=Common_InputFunctions.Utility_DisplayArrayInTable(SourceData_Feedlot.SourceData_Feedlot_AnimalCharacteristics_Data(), Table_SourceData_Feedlot_AnimalCharacteristics[[#Headers],[Feedlot type]], 0)} -> 10.4 | J51: {=Common_InputFunctions.Utility_DisplayArrayInTable(SourceData_Feedlot.SourceData_Feedlot_AnimalCharacteristics_Data(), Table_SourceData_Feedlot_AnimalCharacteristics[[#Headers],[Feedlot type]], 0)} -> 10.4
...

Sheet Constants - Common
A1: #VALUE! | C1: Constants - Common
D5: {=Common_SourceData.Common_SourceData_AustralianStatesTerritories_Title()} -> Australian states and territories
D6: State/Territory | E6: Common Name | F6: Abbreviation
D7: {=Common_InputFunctions.Utility_DisplayArrayInTable(Common_SourceData.Common_SourceData_AustralianStatesTerritories_Data(),Table_AustralianStates[[#Headers],[State/Territory]],0)} -> New South Wales | E7: {=Common_InputFunctions.Utility_DisplayArrayInTable(Common_SourceData.Common_SourceData_AustralianStatesTerritories_Data(),Table_AustralianStates[[#Headers],[State/Territory]],0)} -> New South Wales | F7: {=Common_InputFunctions.Utility_DisplayArrayInTable(Common_SourceData.Common_SourceData_AustralianStatesTerritories_Data(),Table_AustralianStates[[#Headers],[State/Territory]],0)} -> NSW
D8: {=Common_InputFunctions.Utility_DisplayArrayInTable(Common_SourceData.Common_SourceData_AustralianStatesTerritories_Data(),Table_AustralianStates[[#Headers],[State/Territory]],0)} -> Australian Capital Territory | E8: {=Common_InputFunctions.Utility_DisplayArrayInTable(Common_SourceData.Common_SourceData_AustralianStatesTerritories_Data(),Table_AustralianStates[[#Headers],[State/Territory]],0)} -> ACT | F8: {=Common_InputFunctions.Utility_DisplayArrayInTable(Common_SourceData.Common_SourceData_AustralianStatesTerritories_Data(),Table_AustralianStates[[#Headers],[State/Territory]],0)} -> ACT
D9: {=Common_InputFunctions.Utility_DisplayArrayInTable(Common_SourceData.Common_SourceData_AustralianStatesTerritories_Data(),Table_AustralianStates[[#Headers],[State/Territory]],0)} -> Victoria | E9: {=Common_InputFunctions.Utility_DisplayArrayInTable(Common_SourceData.Common_SourceData_AustralianStatesTerritories_Data(),Table_AustralianStates[[#Headers],[State/Territory]],0)} -> Victoria | F9: {=Common_InputFunctions.Utility_DisplayArrayInTable(Common_SourceData.Common_SourceData_AustralianStatesTerritories_Data(),Table_AustralianStates[[#Headers],[State/Territory]],0)} -> VIC
D10: {=Common_InputFunctions.Utility_DisplayArrayInTable(Common_SourceData.Common_SourceData_AustralianStatesTerritories_Data(),Table_AustralianStates[[#Headers],[State/Territory]],0)} -> Queensland | E10: {=Common_InputFunctions.Utility_DisplayArrayInTable(Common_SourceData.Common_SourceData_AustralianStatesTerritories_Data(),Table_AustralianStates[[#Headers],[State/Territory]],0)} -> Queensland | F10: {=Common_InputFunctions.Utility_DisplayArrayInTable(Common_SourceData.Common_SourceData_AustralianStatesTerritories_Data(),Table_AustralianStates[[#Headers],[State/Territory]],0)} -> QLD
D11: {=Common_InputFunctions.Utility_DisplayArrayInTable(Common_SourceData.Common_SourceData_AustralianStatesTerritories_Data(),Table_AustralianStates[[#Headers],[State/Territory]],0)} -> South Australia | E11: {=Common_InputFunctions.Utility_DisplayArrayInTable(Common_SourceData.Common_SourceData_AustralianStatesTerritories_Data(),Table_AustralianStates[[#Headers],[State/Territory]],0)} -> South Australia | F11: {=Common_InputFunctions.Utility_DisplayArrayInTable(Common_SourceData.Common_SourceData_AustralianStatesTerritories_Data(),Table_AustralianStates[[#Headers],[State/Territory]],0)} -> SA
D12: {=Common_InputFunctions.Utility_DisplayArrayInTable(Common_SourceData.Common_SourceData_AustralianStatesTerritories_Data(),Table_AustralianStates[[#Headers],[State/Territory]],0)} -> Western Australia | E12: {=Common_InputFunctions.Utility_DisplayArrayInTable(Common_SourceData.Common_SourceData_AustralianStatesTerritories_Data(),Table_AustralianStates[[#Headers],[State/Territory]],0)} -> Western Australia | F12: {=Common_InputFunctions.Utility_DisplayArrayInTable(Common_SourceData.Common_SourceData_AustralianStatesTerritories_Data(),Table_AustralianStates[[#Headers],[State/Territory]],0)} -> WA
D13: {=Common_InputFunctions.Utility_DisplayArrayInTable(Common_SourceData.Common_SourceData_AustralianStatesTerritories_Data(),Table_AustralianStates[[#Headers],[State/Territory]],0)} -> Tasmania | E13: {=Common_InputFunctions.Utility_DisplayArrayInTable(Common_SourceData.Common_SourceData_AustralianStatesTerritories_Data(),Table_AustralianStates[[#Headers],[State/Territory]],0)} -> Tasmania | F13: {=Common_InputFunctions.Utility_DisplayArrayInTable(Common_SourceData.Common_SourceData_AustralianStatesTerritories_Data(),Table_AustralianStates[[#Headers],[State/Territory]],0)} -> TAS
D14: {=Common_InputFunctions.Utility_DisplayArrayInTable(Common_SourceData.Common_SourceData_AustralianStatesTerritories_Data(),Table_AustralianStates[[#Headers],[State/Territory]],0)} -> Northern Territory | E14: {=Common_InputFunctions.Utility_DisplayArrayInTable(Common_SourceData.Common_SourceData_AustralianStatesTerritories_Data(),Table_AustralianStates[[#Headers],[State/Territory]],0)} -> Northern Territory | F14: {=Common_InputFunctions.Utility_DisplayArrayInTable(Common_SourceData.Common_SourceData_AustralianStatesTerritories_Data(),Table_AustralianStates[[#Headers],[State/Territory]],0)} -> NT
D18: {=Common_SourceData.Common_SourceData_WASA4Areas_Title()} -> ABS Statistcal Areas Level 4 - Western Australia
D19: {=Common_SourceData.Common_SourceData_WASA4Areas_Source()} -> Australian Bureau of Statistics (ABS) - Statistical Areas Level 2 - 2021 - Shapefile
D20: SA 4 Name
D21: {=Common_InputFunctions.Utility_DisplayArrayInTable(Common_SourceData.Common_SourceData_WASA4Areas_Data(), Table_WASA4Areas[[#Headers],[SA 4 Name]], 0)} -> Bunbury
D22: {=Common_InputFunctions.Utility_DisplayArrayInTable(Common_SourceData.Common_SourceData_WASA4Areas_Data(), Table_WASA4Areas[[#Headers],[SA 4 Name]], 0)} -> Mandurah
D23: {=Common_InputFunctions.Utility_DisplayArrayInTable(Common_SourceData.Common_SourceData_WASA4Areas_Data(), Table_WASA4Areas[[#Headers],[SA 4 Name]], 0)} -> Perth - Inner
D24: {=Common_InputFunctions.Utility_DisplayArrayInTable(Common_SourceData.Common_SourceData_WASA4Areas_Data(), Table_WASA4Areas[[#Headers],[SA 4 Name]], 0)} -> Perth - North East
D25: {=Common_InputFunctions.Utility_DisplayArrayInTable(Common_SourceData.Common_SourceData_WASA4Areas_Data(), Table_WASA4Areas[[#Headers],[SA 4 Name]], 0)} -> Perth - North West
D26: {=Common_InputFunctions.Utility_DisplayArrayInTable(Common_SourceData.Common_SourceData_WASA4Areas_Data(), Table_WASA4Areas[[#Headers],[SA 4 Name]], 0)} -> Perth - South East
D27: {=Common_InputFunctions.Utility_DisplayArrayInTable(Common_SourceData.Common_SourceData_WASA4Areas_Data(), Table_WASA4Areas[[#Headers],[SA 4 Name]], 0)} -> Perth - South West
D28: {=Common_InputFunctions.Utility_DisplayArrayInTable(Common_SourceData.Common_SourceData_WASA4Areas_Data(), Table_WASA4Areas[[#Headers],[SA 4 Name]], 0)} -> Western Australia - Wheat Belt
D29: {=Common_InputFunctions.Utility_DisplayArrayInTable(Common_SourceData.Common_SourceData_WASA4Areas_Data(), Table_WASA4Areas[[#Headers],[SA 4 Name]], 0)} -> Western Australia - Outback (North)
D30: {=Common_InputFunctions.Utility_DisplayArrayInTable(Common_SourceData.Common_SourceData_WASA4Areas_Data(), Table_WASA4Areas[[#Headers],[SA 4 Name]], 0)} -> Western Australia - Outback (South)
D34: {=Common_SourceData.Common_SourceData_GWP_Title()} -> Global warming potential for greenhouse gases
D35: {=Common_SourceData.Common_SourceData_GWP_Source()} -> XXXXXXX
D36: Gas | E36: CO2-e factor
D37: {=Common_InputFunctions.Utility_DisplayArrayInTable(Common_SourceData.Common_SourceData_GWP_Data(), Table_GWPData[[#Headers],[Gas]], 0)} -> CO2 | E37: {=Common_InputFunctions.Utility_DisplayArrayInTable(Common_SourceData.Common_SourceData_GWP_Data(), Table_GWPData[[#Headers],[Gas]], 0)} -> 1
D38: {=Common_InputFunctions.Utility_DisplayArrayInTable(Common_SourceData.Common_SourceData_GWP_Data(), Table_GWPData[[#Headers],[Gas]], 0)} -> CH4 | E38: {=Common_InputFunctions.Utility_DisplayArrayInTable(Common_SourceData.Common_SourceData_GWP_Data(), Table_GWPData[[#Headers],[Gas]], 0)} -> 28
D39: {=Common_InputFunctions.Utility_DisplayArrayInTable(Common_SourceData.Common_SourceData_GWP_Data(), Table_GWPData[[#Headers],[Gas]], 0)} -> N2O | E39: {=Common_InputFunctions.Utility_DisplayArrayInTable(Common_SourceData.Common_SourceData_GWP_Data(), Table_GWPData[[#Headers],[Gas]], 0)} -> 265
D40: {=Common_InputFunctions.Utility_DisplayArrayInTable(Common_SourceData.Common_SourceData_GWP_Data(), Table_GWPData[[#Headers],[Gas]], 0)} -> CF4 | E40: {=Common_InputFunctions.Utility_DisplayArrayInTable(Common_SourceData.Common_SourceData_GWP_Data(), Table_GWPData[[#Headers],[Gas]], 0)} -> 6630
D41: {=Common_InputFunctions.Utility_DisplayArrayInTable(Common_SourceData.Common_SourceData_GWP_Data(), Table_GWPData[[#Headers],[Gas]], 0)} -> C2F6 | E41: {=Common_InputFunctions.Utility_DisplayArrayInTable(Common_SourceData.Common_SourceData_GWP_Data(), Table_GWPData[[#Headers],[Gas]], 0)} -> 12200
D42: {=Common_InputFunctions.Utility_DisplayArrayInTable(Common_SourceData.Common_SourceData_GWP_Data(), Table_GWPData[[#Headers],[Gas]], 0)} -> SF6 | E42: {=Common_InputFunctions.Utility_DisplayArrayInTable(Common_SourceData.Common_SourceData_GWP_Data(), Table_GWPData[[#Headers],[Gas]], 0)} -> 22800
D43: {=Common_InputFunctions.Utility_DisplayArrayInTable(Common_SourceData.Common_SourceData_GWP_Data(), Table_GWPData[[#Headers],[Gas]], 0)} -> NF3 | E43: {=Common_InputFunctions.Utility_DisplayArrayInTable(Common_SourceData.Common_SourceData_GWP_Data(), Table_GWPData[[#Headers],[Gas]], 0)} -> 17200
D45: {=Common_SourceData.Common_SourceData_ConvertGasElementalToMolecular_Title()} -> Factor to convert elemental mass of gas to molecular mass
D46: {=Common_SourceData.Common_SourceData_ConvertGasElementalToMolecular_Source()} -> XXXXXXX
D47: Gas | E47: Conversion factor | F47: Conversion factor 1 | G47: Conversion factor 2 | H47: Conversion factor combined
D48: {=Common_InputFunctions.Utility_DisplayArrayInTable(Common_SourceData.Common_SourceData_ConvertGasElementalToMolecular_Data(),Table_GasToMolecularConversionFactor[[#Headers],[Gas]], 0)} -> CO2 | E48: {=Common_InputFunctions.Utility_DisplayArrayInTable(Common_SourceData.Common_SourceData_ConvertGasElementalToMolecular_Data(),Table_GasToMolecularConversionFactor[[#Headers],[Gas]], 0)} -> 44/12 | F48: {=Common_InputFunctions.Utility_DisplayArrayInTable(Common_SourceData.Common_SourceData_ConvertGasElementalToMolecular_Data(),Table_GasToMolecularConversionFactor[[#Headers],[Gas]], 0)} -> 44 | G48: {=Common_InputFunctions.Utility_DisplayArrayInTable(Common_SourceData.Common_SourceData_ConvertGasElementalToMolecular_Data(),Table_GasToMolecularConversionFactor[[#Headers],[Gas]], 0)} -> 12 | H48: =Table_GasToMolecularConversionFactor[[#This Row],[Conversion factor 1]]/Table_GasToMolecularConversionFactor[[#This Row],[Conversion factor 2]] -> 3.6666667
D49: {=Common_InputFunctions.Utility_DisplayArrayInTable(Common_SourceData.Common_SourceData_ConvertGasElementalToMolecular_Data(),Table_GasToMolecularConversionFactor[[#Headers],[Gas]], 0)} -> CH4 | E49: {=Common_InputFunctions.Utility_DisplayArrayInTable(Common_SourceData.Common_SourceData_ConvertGasElementalToMolecular_Data(),Table_GasToMolecularConversionFactor[[#Headers],[Gas]], 0)} -> 16/12 | F49: {=Common_InputFunctions.Utility_DisplayArrayInTable(Common_SourceData.Common_SourceData_ConvertGasElementalToMolecular_Data(),Table_GasToMolecularConversionFactor[[#Headers],[Gas]], 0)} -> 16 | G49: {=Common_InputFunctions.Utility_DisplayArrayInTable(Common_SourceData.Common_SourceData_ConvertGasElementalToMolecular_Data(),Table_GasToMolecularConversionFactor[[#Headers],[Gas]], 0)} -> 12 | H49: =Table_GasToMolecularConversionFactor[[#This Row],[Conversion factor 1]]/Table_GasToMolecularConversionFactor[[#This Row],[Conversion factor 2]] -> 1.3333333
D50: {=Common_InputFunctions.Utility_DisplayArrayInTable(Common_SourceData.Common_SourceData_ConvertGasElementalToMolecular_Data(),Table_GasToMolecularConversionFactor[[#Headers],[Gas]], 0)} -> N2O | E50: {=Common_InputFunctions.Utility_DisplayArrayInTable(Common_SourceData.Common_SourceData_ConvertGasElementalToMolecular_Data(),Table_GasToMolecularConversionFactor[[#Headers],[Gas]], 0)} -> 44/28 | F50: {=Common_InputFunctions.Utility_DisplayArrayInTable(Common_SourceData.Common_SourceData_ConvertGasElementalToMolecular_Data(),Table_GasToMolecularConversionFactor[[#Headers],[Gas]], 0)} -> 44 | G50: {=Common_InputFunctions.Utility_DisplayArrayInTable(Common_SourceData.Common_SourceData_ConvertGasElementalToMolecular_Data(),Table_GasToMolecularConversionFactor[[#Headers],[Gas]], 0)} -> 28 | H50: =Table_GasToMolecularConversionFactor[[#This Row],[Conversion factor 1]]/Table_GasToMolecularConversionFactor[[#This Row],[Conversion factor 2]] -> 1.5714286
...

Sheet Constants - Livestock
A1: #VALUE! | C1: Constants - Livestock
A3: =HYPERLINK("#'Home'!A1", "Home") -> Home
A4: =HYPERLINK("#'Overview'!A1", "Overview") -> Overview
A5: =HYPERLINK("#'Results'!A1", "Results") -> Results
D6: {=CommonLivestock_SourceData.SourceData_Livestock_Common_SymbolsMMS_Title()} -> Table 5.12 Additional symbols used in algorithms for manure related emissions
A7: INPUTS | D7: {=CommonLivestock_SourceData.SourceData_Livestock_Common_SymbolsMMS_Vairable()} -> MMS
A8: =HYPERLINK("#'Input - Site'!A1", "Site") -> Site | D8: {=CommonLivestock_SourceData.SourceData_Livestock_Common_SymbolsMMS_Source()} -> National Inventory Report 2023 Volume 1: Table 5.12
A9: =HYPERLINK("#'Input - Feedlot'!A1", "Feedlot") -> Feedlot | D9: Symbol | E9: Manure management system | F9: Symbol and MMS
D10: {=Common_InputFunctions.Utility_DisplayArrayInTable(CommonLivestock_SourceData.SourceData_Livestock_Common_SymbolsMMS_Data(), Table_Data_MMSSymbols[[#Headers],[Symbol]], 0)} -> 1 | E10: {=Common_InputFunctions.Utility_DisplayArrayInTable(CommonLivestock_SourceData.SourceData_Livestock_Common_SymbolsMMS_Data(), Table_Data_MMSSymbols[[#Headers],[Symbol]], 0)} -> Anaerobic lagoon | F10: {=Common_InputFunctions.Utility_DisplayArrayInTable(CommonLivestock_SourceData.SourceData_Livestock_Common_SymbolsMMS_Data(), Table_Data_MMSSymbols[[#Headers],[Symbol]], 0)} -> Anaerobic lagoon (m=1)
A11: CALCULATIONS | D11: {=Common_InputFunctions.Utility_DisplayArrayInTable(CommonLivestock_SourceData.SourceData_Livestock_Common_SymbolsMMS_Data(), Table_Data_MMSSymbols[[#Headers],[Symbol]], 0)} -> 2 | E11: {=Common_InputFunctions.Utility_DisplayArrayInTable(CommonLivestock_SourceData.SourceData_Livestock_Common_SymbolsMMS_Data(), Table_Data_MMSSymbols[[#Headers],[Symbol]], 0)} -> Liquid systems | F11: {=Common_InputFunctions.Utility_DisplayArrayInTable(CommonLivestock_SourceData.SourceData_Livestock_Common_SymbolsMMS_Data(), Table_Data_MMSSymbols[[#Headers],[Symbol]], 0)} -> Liquid systems (m=2)
A12: =HYPERLINK("#'3.1.1.1-2 Enteric Methane'!A1", "3.1.1.1-2 Enteric Methane") -> 3.1.1.1-2 Enteric Methane | D12: {=Common_InputFunctions.Utility_DisplayArrayInTable(CommonLivestock_SourceData.SourceData_Livestock_Common_SymbolsMMS_Data(), Table_Data_MMSSymbols[[#Headers],[Symbol]], 0)} -> 3 | E12: {=Common_InputFunctions.Utility_DisplayArrayInTable(CommonLivestock_SourceData.SourceData_Livestock_Common_SymbolsMMS_Data(), Table_Data_MMSSymbols[[#Headers],[Symbol]], 0)} -> Daily spread | F12: {=Common_InputFunctions.Utility_DisplayArrayInTable(CommonLivestock_SourceData.SourceData_Livestock_Common_SymbolsMMS_Data(), Table_Data_MMSSymbols[[#Headers],[Symbol]], 0)} -> Daily spread (m=3)
D13: {=Common_InputFunctions.Utility_DisplayArrayInTable(CommonLivestock_SourceData.SourceData_Livestock_Common_SymbolsMMS_Data(), Table_Data_MMSSymbols[[#Headers],[Symbol]], 0)} -> 3a | E13: {=Common_InputFunctions.Utility_DisplayArrayInTable(CommonLivestock_SourceData.SourceData_Livestock_Common_SymbolsMMS_Data(), Table_Data_MMSSymbols[[#Headers],[Symbol]], 0)} -> Sump and dispersal system | F13: {=Common_InputFunctions.Utility_DisplayArrayInTable(CommonLivestock_SourceData.SourceData_Livestock_Common_SymbolsMMS_Data(), Table_Data_MMSSymbols[[#Headers],[Symbol]], 0)} -> Sump and dispersal system (m=3a)
A14: APPENDICES | D14: {=Common_InputFunctions.Utility_DisplayArrayInTable(CommonLivestock_SourceData.SourceData_Livestock_Common_SymbolsMMS_Data(), Table_Data_MMSSymbols[[#Headers],[Symbol]], 0)} -> 3b | E14: {=Common_InputFunctions.Utility_DisplayArrayInTable(CommonLivestock_SourceData.SourceData_Livestock_Common_SymbolsMMS_Data(), Table_Data_MMSSymbols[[#Headers],[Symbol]], 0)} -> Drains to paddock | F14: {=Common_InputFunctions.Utility_DisplayArrayInTable(CommonLivestock_SourceData.SourceData_Livestock_Common_SymbolsMMS_Data(), Table_Data_MMSSymbols[[#Headers],[Symbol]], 0)} -> Drains to paddock (m=3b)
A15: =HYPERLINK("#'Constants - Feedlot'!A1", "Constants - Feedlot") -> Constants - Feedlot | D15: {=Common_InputFunctions.Utility_DisplayArrayInTable(CommonLivestock_SourceData.SourceData_Livestock_Common_SymbolsMMS_Data(), Table_Data_MMSSymbols[[#Headers],[Symbol]], 0)} -> 4 | E15: {=Common_InputFunctions.Utility_DisplayArrayInTable(CommonLivestock_SourceData.SourceData_Livestock_Common_SymbolsMMS_Data(), Table_Data_MMSSymbols[[#Headers],[Symbol]], 0)} -> Solid storage | F15: {=Common_InputFunctions.Utility_DisplayArrayInTable(CommonLivestock_SourceData.SourceData_Livestock_Common_SymbolsMMS_Data(), Table_Data_MMSSymbols[[#Headers],[Symbol]], 0)} -> Solid storage (m=4)
A16: =HYPERLINK("#'Constants - Livestock'!A1", "Constants - Livestock") -> Constants - Livestock | D16: {=Common_InputFunctions.Utility_DisplayArrayInTable(CommonLivestock_SourceData.SourceData_Livestock_Common_SymbolsMMS_Data(), Table_Data_MMSSymbols[[#Headers],[Symbol]], 0)} -> 5 | E16: {=Common_InputFunctions.Utility_DisplayArrayInTable(CommonLivestock_SourceData.SourceData_Livestock_Common_SymbolsMMS_Data(), Table_Data_MMSSymbols[[#Headers],[Symbol]], 0)} -> Drylot (feed pad) | F16: {=Common_InputFunctions.Utility_DisplayArrayInTable(CommonLivestock_SourceData.SourceData_Livestock_Common_SymbolsMMS_Data(), Table_Data_MMSSymbols[[#Headers],[Symbol]], 0)} -> Drylot (feed pad) (m=5)
A17: =HYPERLINK("#'Constants - Common'!A1", "Constants - Common") -> Constants - Common | D17: {=Common_InputFunctions.Utility_DisplayArrayInTable(CommonLivestock_SourceData.SourceData_Livestock_Common_SymbolsMMS_Data(), Table_Data_MMSSymbols[[#Headers],[Symbol]], 0)} -> 6 | E17: {=Common_InputFunctions.Utility_DisplayArrayInTable(CommonLivestock_SourceData.SourceData_Livestock_Common_SymbolsMMS_Data(), Table_Data_MMSSymbols[[#Headers],[Symbol]], 0)} -> Composting (passive windrow) | F17: {=Common_InputFunctions.Utility_DisplayArrayInTable(CommonLivestock_SourceData.SourceData_Livestock_Common_SymbolsMMS_Data(), Table_Data_MMSSymbols[[#Headers],[Symbol]], 0)} -> Composting (passive windrow) (m=6)
A18: =HYPERLINK("#'Acknowledgements'!A1", "Acknowledgements") -> Acknowledgements | D18: {=Common_InputFunctions.Utility_DisplayArrayInTable(CommonLivestock_SourceData.SourceData_Livestock_Common_SymbolsMMS_Data(), Table_Data_MMSSymbols[[#Headers],[Symbol]], 0)} -> 7 | E18: {=Common_InputFunctions.Utility_DisplayArrayInTable(CommonLivestock_SourceData.SourceData_Livestock_Common_SymbolsMMS_Data(), Table_Data_MMSSymbols[[#Headers],[Symbol]], 0)} -> Digester / covered lagoons | F18: {=Common_InputFunctions.Utility_DisplayArrayInTable(CommonLivestock_SourceData.SourceData_Livestock_Common_SymbolsMMS_Data(), Table_Data_MMSSymbols[[#Headers],[Symbol]], 0)} -> Digester / covered lagoons (m=7)
D19: {=Common_InputFunctions.Utility_DisplayArrayInTable(CommonLivestock_SourceData.SourceData_Livestock_Common_SymbolsMMS_Data(), Table_Data_MMSSymbols[[#Headers],[Symbol]], 0)} -> 8 | E19: {=Common_InputFunctions.Utility_DisplayArrayInTable(CommonLivestock_SourceData.SourceData_Livestock_Common_SymbolsMMS_Data(), Table_Data_MMSSymbols[[#Headers],[Symbol]], 0)} -> Deep litter | F19: {=Common_InputFunctions.Utility_DisplayArrayInTable(CommonLivestock_SourceData.SourceData_Livestock_Common_SymbolsMMS_Data(), Table_Data_MMSSymbols[[#Headers],[Symbol]], 0)} -> Deep litter (m=8)
D20: {=Common_InputFunctions.Utility_DisplayArrayInTable(CommonLivestock_SourceData.SourceData_Livestock_Common_SymbolsMMS_Data(), Table_Data_MMSSymbols[[#Headers],[Symbol]], 0)} -> 9 | E20: {=Common_InputFunctions.Utility_DisplayArrayInTable(CommonLivestock_SourceData.SourceData_Livestock_Common_SymbolsMMS_Data(), Table_Data_MMSSymbols[[#Headers],[Symbol]], 0)} -> Pit storage | F20: {=Common_InputFunctions.Utility_DisplayArrayInTable(CommonLivestock_SourceData.SourceData_Livestock_Common_SymbolsMMS_Data(), Table_Data_MMSSymbols[[#Headers],[Symbol]], 0)} -> Pit storage (m=9)
D21: {=Common_InputFunctions.Utility_DisplayArrayInTable(CommonLivestock_SourceData.SourceData_Livestock_Common_SymbolsMMS_Data(), Table_Data_MMSSymbols[[#Headers],[Symbol]], 0)} -> 10 | E21: {=Common_InputFunctions.Utility_DisplayArrayInTable(CommonLivestock_SourceData.SourceData_Livestock_Common_SymbolsMMS_Data(), Table_Data_MMSSymbols[[#Headers],[Symbol]], 0)} -> Poultry manure with bedding | F21: {=Common_InputFunctions.Utility_DisplayArrayInTable(CommonLivestock_SourceData.SourceData_Livestock_Common_SymbolsMMS_Data(), Table_Data_MMSSymbols[[#Headers],[Symbol]], 0)} -> Poultry manure with bedding (m=10)
D22: {=Common_InputFunctions.Utility_DisplayArrayInTable(CommonLivestock_SourceData.SourceData_Livestock_Common_SymbolsMMS_Data(), Table_Data_MMSSymbols[[#Headers],[Symbol]], 0)} -> 11 | E22: {=Common_InputFunctions.Utility_DisplayArrayInTable(CommonLivestock_SourceData.SourceData_Livestock_Common_SymbolsMMS_Data(), Table_Data_MMSSymbols[[#Headers],[Symbol]], 0)} -> Poultry manure without bedding | F22: {=Common_InputFunctions.Utility_DisplayArrayInTable(CommonLivestock_SourceData.SourceData_Livestock_Common_SymbolsMMS_Data(), Table_Data_MMSSymbols[[#Headers],[Symbol]], 0)} -> Poultry manure without bedding (m=11)
D23: {=Common_InputFunctions.Utility_DisplayArrayInTable(CommonLivestock_SourceData.SourceData_Livestock_Common_SymbolsMMS_Data(), Table_Data_MMSSymbols[[#Headers],[Symbol]], 0)} -> 11a | E23: {=Common_InputFunctions.Utility_DisplayArrayInTable(CommonLivestock_SourceData.SourceData_Livestock_Common_SymbolsMMS_Data(), Table_Data_MMSSymbols[[#Headers],[Symbol]], 0)} -> Belt manure removal | F23: {=Common_InputFunctions.Utility_DisplayArrayInTable(CommonLivestock_SourceData.SourceData_Livestock_Common_SymbolsMMS_Data(), Table_Data_MMSSymbols[[#Headers],[Symbol]], 0)} -> Belt manure removal (m=11a)
D24: {=Common_InputFunctions.Utility_DisplayArrayInTable(CommonLivestock_SourceData.SourceData_Livestock_Common_SymbolsMMS_Data(), Table_Data_MMSSymbols[[#Headers],[Symbol]], 0)} -> 11b | E24: {=Common_InputFunctions.Utility_DisplayArrayInTable(CommonLivestock_SourceData.SourceData_Livestock_Common_SymbolsMMS_Data(), Table_Data_MMSSymbols[[#Headers],[Symbol]], 0)} -> Manure stored in house | F24: {=Common_InputFunctions.Utility_DisplayArrayInTable(CommonLivestock_SourceData.SourceData_Livestock_Common_SymbolsMMS_Data(), Table_Data_MMSSymbols[[#Headers],[Symbol]], 0)} -> Manure stored in house (m=11b)
D25: {=Common_InputFunctions.Utility_DisplayArrayInTable(CommonLivestock_SourceData.SourceData_Livestock_Common_SymbolsMMS_Data(), Table_Data_MMSSymbols[[#Headers],[Symbol]], 0)} -> 12 | E25: {=Common_InputFunctions.Utility_DisplayArrayInTable(CommonLivestock_SourceData.SourceData_Livestock_Common_SymbolsMMS_Data(), Table_Data_MMSSymbols[[#Headers],[Symbol]], 0)} -> Direct processing | F25: {=Common_InputFunctions.Utility_DisplayArrayInTable(CommonLivestock_SourceData.SourceData_Livestock_Common_SymbolsMMS_Data(), Table_Data_MMSSymbols[[#Headers],[Symbol]], 0)} -> Direct processing (m=12)
D26: {=Common_InputFunctions.Utility_DisplayArrayInTable(CommonLivestock_SourceData.SourceData_Livestock_Common_SymbolsMMS_Data(), Table_Data_MMSSymbols[[#Headers],[Symbol]], 0)} -> 13 | E26: {=Common_InputFunctions.Utility_DisplayArrayInTable(CommonLivestock_SourceData.SourceData_Livestock_Common_SymbolsMMS_Data(), Table_Data_MMSSymbols[[#Headers],[Symbol]], 0)} -> Direct application | F26: {=Common_InputFunctions.Utility_DisplayArrayInTable(CommonLivestock_SourceData.SourceData_Livestock_Common_SymbolsMMS_Data(), Table_Data_MMSSymbols[[#Headers],[Symbol]], 0)} -> Direct application (m=13)
D27: {=Common_InputFunctions.Utility_DisplayArrayInTable(CommonLivestock_SourceData.SourceData_Livestock_Common_SymbolsMMS_Data(), Table_Data_MMSSymbols[[#Headers],[Symbol]], 0)} -> 14 | E27: {=Common_InputFunctions.Utility_DisplayArrayInTable(CommonLivestock_SourceData.SourceData_Livestock_Common_SymbolsMMS_Data(), Table_Data_MMSSymbols[[#Headers],[Symbol]], 0)} -> Pasture range and paddock | F27: {=Common_InputFunctions.Utility_DisplayArrayInTable(CommonLivestock_SourceData.SourceData_Livestock_Common_SymbolsMMS_Data(), Table_Data_MMSSymbols[[#Headers],[Symbol]], 0)} -> Pasture range and paddock (m=14)

Sheet Acknowledgements
A1: Acknowledgements

Sheet Tab template
A1: #VALUE!
A3: Home
A4: =HYPERLINK("#'Results'!A1", "Results") -> Results
A6: INPUTS
A7: =HYPERLINK("#'Input - Site'!A1", "Site") -> Site
A8: =HYPERLINK("#'Input - Production'!A1", "Production and outputs") -> Production and outputs
A9: =HYPERLINK("#'Input - Herd - Dairy'!A1", "Herd - Dairy") -> Herd - Dairy
A10: =HYPERLINK("#'Input - Feed - Dairy'!A1", "Purchased feed - Livestock") -> Purchased feed - Livestock
A11: =HYPERLINK("#'Input - Herd - Feedlot'!A1", "Herd - Feedlot") -> Herd - Feedlot
A12: =HYPERLINK("#'Input - Pasture'!A1", "Pasture") -> Pasture
A13: =HYPERLINK("#'Input - Grains'!A1", "Crop - Grains") -> Crop - Grains
A14: =HYPERLINK("#'Input - Fert Lime Chem'!A1", "Fertiliser, Lime & Chemicals") -> Fertiliser, Lime & Chemicals
A15: =HYPERLINK("#'Input - Fuel & Energy'!A1", "Electricity and fuel") -> Electricity and fuel
A16: Waste
A17: Freight and transport
A18: =HYPERLINK("#'Input - Other Farm Inputs'!A1", "Other farm inputs") -> Other farm inputs
A19: =HYPERLINK("#'Input - Data quality'!A1", "Data quality") -> Data quality
A21: CALCULATIONS
A22: N2O MMS
A23: Enteric methane
A24: =HYPERLINK("#'Calcs - Fert Lime'!A1", "Fertiliser & soil amendments") -> Fertiliser & soil amendments
A25: =HYPERLINK("#'Calcs - Residue mgmt - Crop'!A1", "Residue management - Crop") -> Residue management - Crop
A26: =HYPERLINK("#'Calcs - Residue mgmt - Pasture'!A1", "Residue management - Pasture") -> Residue management - Pasture
A27: =HYPERLINK("#'Calcs - Field burning'!A1", "Field burning - Crop") -> Field burning - Crop
A28: =HYPERLINK("#'Calcs - Fuel'!A1", "Fuel") -> Fuel
A29: =HYPERLINK("#'Calcs - Electricity'!A1", "Electricity") -> Electricity
A30: =HYPERLINK("#'Calcs - Refrigerants'!A1", "Refrigerants") -> Refrigerants
A31: Waste
A32: Freight and transport
A33: =HYPERLINK("#'Calcs - Scope 3'!A1", "Purchased goods scope 3") -> Purchased goods scope 3
A35: APPENDICES
A36: =HYPERLINK("#'Constants - Common'!A1", "Constants - Common") -> Constants - Common
A37: =HYPERLINK("#'Constants - Cropping'!A1", "Constants - Cropping") -> Constants - Cropping
