Workbook
Name Common_Equations.Common_ConvertCH4ToCO2e: _xlfn.LAMBDA(_xlpm.E_CH4,_xlpm.GWP_CH4, _xlpm.E_CH4 * _xlpm.GWP_CH4)
Name Common_Equations.Common_ConvertCH4ToCO2e_Arguments: _xlfn.LAMBDA(_xlfn.MAKEARRAY(2, 2, _xlfn.LAMBDA(_xlpm.r,_xlpm.c, INDEX({"ECH4","Methane emissions (t CH4)";"GWPCH4","Global warming potential for methane (t CO2-e / t CH4)"}, _xlpm.r, _xlpm.c))))
Name Common_Equations.Common_ConvertCH4ToCO2e_LatexEquation: _xlfn.LAMBDA("CO2_e = E_{CH4} \times GWP_{CH4}")
Name Common_Equations.Common_ConvertCH4ToCO2e_NIRReference: _xlfn.LAMBDA("")
Name Common_Equations.Common_ConvertCH4ToCO2e_Title: _xlfn.LAMBDA("Convert methane emissions to carbon dioxide equivalent emissions")
Name Common_Equations.Common_ConvertCH4ToCO2e_Unit: _xlfn.LAMBDA("t CO2e")
Name Common_Equations.Common_ConvertCH4ToCO2e_Variable: _xlfn.LAMBDA("ECH4 CO2e")
Name Common_Equations.Common_ConvertN2OToCO2e: _xlfn.LAMBDA(_xlpm.E_N2O,_xlpm.GWP_N2O, _xlpm.E_N2O * _xlpm.GWP_N2O)
Name Common_Equations.Common_ConvertN2OToCO2e_LatexEquation: _xlfn.LAMBDA("CO2_e = E_{N2O} \times GWP_{N2O}")
Name Common_Equations.Common_ConvertN2OToCO2e_NIRReference: _xlfn.LAMBDA("")
Name Common_Equations.Common_ConvertN2OToCO2e_Title: _xlfn.LAMBDA("Convert nitrous oxide emissions to carbon dioxide equivalent emissions")
Name Common_Equations.Common_ConvertN2OToCO2e_Unit: _xlfn.LAMBDA("t CO2e")
Name Common_Equations.Common_ConvertN2OToCO2e_Variable: _xlfn.LAMBDA("EN2O CO2e")
Name Common_InputFunctions.Utility_ConvertStateCommonNameToAbbreviation: _xlfn.LAMBDA(_xlpm.StateCommonName,_xlpm.StateCommonNameArray,_xlpm.StateAbbreviationArray, _xlfn.XLOOKUP(_xlpm.StateCommonName, _xlpm.StateCommonNameArray, _xlpm.StateAbbreviationArray, ""))
Name Common_InputFunctions.Utility_DisplayArguments_1_2: _xlfn.LAMBDA(_xlpm.ArgumentsArray, _xlfn.CHOOSECOLS(_xlpm.ArgumentsArray, 1, 2))
Name Common_InputFunctions.Utility_DisplayArguments_3_4: _xlfn.LAMBDA(_xlpm.ArgumentsArray, _xlfn.CHOOSECOLS(_xlpm.ArgumentsArray, 3, 4))
Name Common_InputFunctions.Utility_DisplayFunctionName: _xlfn.LAMBDA(_xlpm.Function, _xlfn.TEXTBEFORE(_xlfn.FORMULATEXT(_xlpm.Function), "("))
Name Common_InputFunctions.Utility_GetArrayTableColumnStartNumber: _xlfn.LAMBDA(_xlpm.TableHeaderCell, COLUMN(_xlpm.TableHeaderCell))
Name Common_InputFunctions.Utility_GetArrayTableRowStartNumber: _xlfn.LAMBDA(_xlpm.TableheaderCell,_xlpm.RowsBetweenHeaderandArray, ROW(_xlpm.TableheaderCell) + _xlpm.RowsBetweenHeaderandArray - 1)
Name Common_InputFunctions.Utility_LookupValueInTable: _xlfn.LAMBDA(_xlpm.LookupValue,_xlpm.LookupArray,_xlpm.ReturnArray, _xlfn.XLOOKUP(_xlpm.LookupValue, _xlpm.LookupArray, _xlpm.ReturnArray, ""))
Name Common_InputFunctions.Utility_ResultsItemFromEquationTitleAndSource: _xlfn.LAMBDA(_xlpm.TitleCell,_xlpm.SourceCell, SUBSTITUTE(LEFT(_xlpm.SourceCell, FIND(",", _xlpm.SourceCell) - 1), "VEERG 2026: ", "") & " " & _xlpm.TitleCell)
Name Common_InputFunctions.Utility_SourceHyperlink: _xlfn.LAMBDA(_xlpm.TargetCell, _xlfn.LET(_xlpm.sh, _xlfn.TEXTAFTER(CELL("filename", _xlpm.TargetCell), "]"), _xlpm.addr, CELL("address", _xlpm.TargetCell), "#'" & _xlpm.sh & "'!" & _xlpm.addr))
Name Common_InputFunctions.Utility_SourceHyperlinkDifferentSheet: _xlfn.LAMBDA(_xlpm.TargetCell, _xlfn.LET(_xlpm.sh, _xlfn.TEXTAFTER(CELL("filename", _xlpm.TargetCell), "]"), _xlpm.addr, CELL("address", _xlpm.TargetCell), "#" & _xlpm.addr))
Name Common_SourceData.Common_SourceData_AustralianStatesTerritories_Source: _xlfn.LAMBDA("")
Name Common_SourceData.Common_SourceData_AustralianStatesTerritories_Title: _xlfn.LAMBDA("Australian states and territories")
Name Common_SourceData.Common_SourceData_AustralianStatesTerritories_Unit: _xlfn.LAMBDA("")
Name Common_SourceData.Common_SourceData_AustralianStatesTerritories_Variable: _xlfn.LAMBDA("")
Name Common_SourceData.Common_SourceData_ClimateZones_Source: _xlfn.LAMBDA("VEERG 2026: Table 1.3: Climate and Rainfall zone classifications and definitions")
Name Common_SourceData.Common_SourceData_ClimateZones_Title: _xlfn.LAMBDA("VEERG Australian climate zones")
Name Common_SourceData.Common_SourceData_ClimateZones_Unit: _xlfn.LAMBDA("")
Name Common_SourceData.Common_SourceData_ClimateZones_Variable: _xlfn.LAMBDA("")
Name Common_SourceData.Common_SourceData_ConvertGasElementalToMolecular_Source: _xlfn.LAMBDA("XXXXXXX")
Name Common_SourceData.Common_SourceData_ConvertGasElementalToMolecular_Title: _xlfn.LAMBDA("Factor to convert elemental mass of gas to molecular mass")
Name Common_SourceData.Common_SourceData_ConvertGasElementalToMolecular_Unit: _xlfn.LAMBDA("factor")
Name Common_SourceData.Common_SourceData_ConvertGasElementalToMolecular_Variable: _xlfn.LAMBDA("Cg")
Name Common_SourceData.Common_SourceData_ConvertN2oElementalToMolecularCg_Data: _xlfn.LAMBDA(44 / 28)
Name Common_SourceData.Common_SourceData_ConvertN2oElementalToMolecularCg_Source: _xlfn.LAMBDA("National Inventory Report 2023 Volume 1")
Name Common_SourceData.Common_SourceData_ConvertN2oElementalToMolecularCg_Title: _xlfn.LAMBDA("Factor to convert elemental mass of N2O to molecular mass")
Name Common_SourceData.Common_SourceData_ConvertN2oElementalToMolecularCg_Unit: _xlfn.LAMBDA("factor")
Name Common_SourceData.Common_SourceData_ConvertN2oElementalToMolecularCg_Variable: _xlfn.LAMBDA("CgN2O")
Name Common_SourceData.Common_SourceData_DataScores_Scope3_Source: _xlfn.LAMBDA("VEERG 2026: XXXXXXXX")
Name Common_SourceData.Common_SourceData_DataScores_Scope3_Title: _xlfn.LAMBDA("Australian data scores for scope 3")
Name Common_SourceData.Common_SourceData_DataScores_Scope3_Unit: _xlfn.LAMBDA("")
Name Common_SourceData.Common_SourceData_DataScores_Scope3_Variable: _xlfn.LAMBDA("")
Name Common_SourceData.Common_SourceData_DataScores_Scope3_Variation: _xlfn.LAMBDA("")
Name Common_SourceData.Common_SourceData_DensityOfMethane_Data: _xlfn.LAMBDA(0.6784)
Name Common_SourceData.Common_SourceData_DensityOfMethane_Source: _xlfn.LAMBDA("National Inventory Report 2023 Volume 1: Equations 3.B.1a_2, 3.B.1c_2, 3.B.3_1, 3.B.4g_2")
Name Common_SourceData.Common_SourceData_DensityOfMethane_Title: _xlfn.LAMBDA("p = density of methane")
Name Common_SourceData.Common_SourceData_DensityOfMethane_Unit: _xlfn.LAMBDA("kg/m3")
Name Common_SourceData.Common_SourceData_EFleach_Data: _xlfn.LAMBDA(_xlfn.MAKEARRAY(1, 2, _xlfn.LAMBDA(_xlpm.r,_xlpm.c, INDEX({"EFleach",0.011}, _xlpm.r, _xlpm.c))))
Name Common_SourceData.Common_SourceData_EFleach_NIRReference: _xlfn.LAMBDA("National Inventory Report Volume 1: Equation 3.D.B_10")
Name Common_SourceData.Common_SourceData_EFleach_Source: _xlfn.LAMBDA("VEERG 2026:5.5.2.3 Constant Parameters")
Name Common_SourceData.Common_SourceData_EFleach_Title: _xlfn.LAMBDA("Emission factor for nitrogen leaching and runoff")
Name Common_SourceData.Common_SourceData_EFleach_Unit: _xlfn.LAMBDA("(kg N2O-N / kg N")
Name Common_SourceData.Common_SourceData_EFleach_Variation: _xlfn.LAMBDA((""))
Name Common_SourceData.Common_SourceData_EFN2O_NIRReference: _xlfn.LAMBDA("")
Name Common_SourceData.Common_SourceData_EFN2O_Source: _xlfn.LAMBDA("VEERG 2026: Table A.2.2.1")
Name Common_SourceData.Common_SourceData_EFN2O_Title: _xlfn.LAMBDA("Nitrous oxide emission factors for inorganic fertiliser application")
Name Common_SourceData.Common_SourceData_EFN2O_Unit: _xlfn.LAMBDA("(kg N2O-N / kg N")
Name Common_SourceData.Common_SourceData_EFOrganicFertiliserAndCropResidues_Data: _xlfn.LAMBDA(_xlfn.MAKEARRAY(3, 2, _xlfn.LAMBDA(_xlpm.r,_xlpm.c, INDEX({"Climate zone","EFNi & EFN2O";"Wet climate zone",0.006;"Dry climate zone",0.005}, _xlpm.r, _xlpm.c))))

Sheet Home
A1: Home

Sheet Results
A1: #VALUE! | C1: 3.2 Enteric Methane: Pasture Beef: Results
A3: =HYPERLINK("#'Home'!A1", "Home") -> Home
A4: =HYPERLINK("#'Results'!A1", "Results") -> Results | D4: Emissions breakdown
A6: INPUTS | D6: Scope 1 source | E6: GHG emissions method 1 | F6: GHG emissions method 2 | G6: GHG Unit | H6: CO2-e emissions method 1 | I6: CO2-e emissions method 2 | J6: CO2-e unit
A7: =HYPERLINK("#'Input - Site'!A1", "Site") -> Site | D7: 4.3.1.1-2 Enteric Methane | E7: =VEERG_3_2_1_1__1_TotalAnnualMethaneFromEntericFermentation_Result -> #NAME? | F7: =VEERG_3_2_1_1__1_TotalAnnualMethaneFromEntericFermentation_Result_Method2 -> 56.163953 | G7: t CH4 | H7: ='3.2.1.1-2 Enteric Methane'!E133 -> 1558.9857 | I7: ='3.2.1.1-2 Enteric Methane'!V166 -> 1572.5907 | J7: t CO2e
A8: =HYPERLINK("#'Input - Pasture Beef'!A1", "Pasture Beef") -> Pasture Beef | D8: Total | H8: =SUM(H7:H7) -> 1558.9857 | I8: =SUM(I7:I7) -> 1572.5907 | J8: t CO2e
A10: CALCULATIONS
A11: =HYPERLINK("#'3.2.1.1-2 Enteric Methane'!A1", "3.2.1.1-2 Enteric Methane") -> 3.2.1.1-2 Enteric Methane
A13: APPENDICES
A14: =HYPERLINK("#'Constants - Pasture Beef'!A1", "Constants - Pasture Beef") -> Constants - Pasture Beef
A15: =HYPERLINK("#'Constants - Livestock'!A1", "Constants - Livestock") -> Constants - Livestock
A16: =HYPERLINK("#'Constants - Common'!A1", "Constants - Common") -> Constants - Common
A17: =HYPERLINK("#'Acknowledgements'!A1", "Acknowledgements") -> Acknowledgements

Sheet Input - Site
A1: #VALUE! | C1: Input - Site
A3: =HYPERLINK("#'Home'!A1", "Home") -> Home
A4: =HYPERLINK("#'Results'!A1", "Results") -> Results
D5: Your business
A6: INPUTS
A7: =HYPERLINK("#'Input - Site'!A1", "Site") -> Site | D7: Farm name | E7: Test Farms
A8: =HYPERLINK("#'Input - Pasture Beef'!A1", "Pasture Beef") -> Pasture Beef | D8: Reporting entity name | E8: Test Farms Pty Ltd
A10: CALCULATIONS | D10: 💡An 'Emissions accounting period' is a 12 month period where the business can report on the emissions, and is typically the same as the business' financial accounting period.
A11: =HYPERLINK("#'3.2.1.1-2 Enteric Methane'!A1", "3.2.1.1-2 Enteric Methane") -> 3.2.1.1-2 Enteric Methane
D12: Emissions calculation period start date | E12: 45292 | F12: ← DD/MM/YYYY or DD Month YYYY
A13: APPENDICES | D13: Emissions calculation period end date | E13: =DATE(YEAR(E12)+1,MONTH(E12),DAY(E12))-1 -> 45657 | F13: ← Automatically calculated, 12 months after start date
A14: =HYPERLINK("#'Constants - Pasture Beef'!A1", "Constants - Pasture Beef") -> Constants - Pasture Beef
A15: =HYPERLINK("#'Constants - Livestock'!A1", "Constants - Livestock") -> Constants - Livestock
A16: =HYPERLINK("#'Constants - Common'!A1", "Constants - Common") -> Constants - Common | D16: Location and climate
A17: =HYPERLINK("#'Acknowledgements'!A1", "Acknowledgements") -> Acknowledgements
D18: Location information is used to reference some region and climate-specific emission factors
D19: Tip: Use the web-based GAF Location Helper tool to easily get region and climate information. You will need an internet connection to use the GAF Location Helper.
D21: State | E21: Western Australia | F21: ← Please select

Sheet Input - Pasture Beef
A1: #VALUE! | C1: Input -Pasture Beef
A3: =HYPERLINK("#'Home'!A1", "Home") -> Home
A4: =HYPERLINK("#'Results'!A1", "Results") -> Results
D5: Herd movement
A6: INPUTS
A7: =HYPERLINK("#'Input - Site'!A1", "Site") -> Site | D7: State | E7: =X_Cell_Site_State -> Western Australia
A8: =HYPERLINK("#'Input - Pasture Beef'!A1", "Pasture Beef") -> Pasture Beef | D8: Livestock production region | E8: South West | F8: ← Please select
D9: Cattle breed | E9: Hereford or Shorthorn breeds | F9: ← Please select
A10: CALCULATIONS
A11: =HYPERLINK("#'3.2.1.1-2 Enteric Methane'!A1", "3.2.1.1-2 Enteric Methane") -> 3.2.1.1-2 Enteric Methane
D12: NOTE: VEERG states that under method 2, time periods may be seasons, months or a custom time period. In this example, method 2 time periods are months.
A13: APPENDICES
A14: =HYPERLINK("#'Constants - Pasture Beef'!A1", "Constants - Pasture Beef") -> Constants - Pasture Beef | D14: Duration on farm
A15: =HYPERLINK("#'Constants - Livestock'!A1", "Constants - Livestock") -> Constants - Livestock | D15: Method 1 default values (do not edit) | E15: Bulls < 1 year | F15: Bulls > 1 year | G15: Cows < 1 year | H15: Cows 1-2 years | I15: Cows 2-3 years | J15: Cows > 3 years | K15: Steers < 1 year | L15: Steers 1-2 years | M15: Steers 2-3 years | N15: Steers >3 years
A16: =HYPERLINK("#'Constants - Common'!A1", "Constants - Common") -> Constants - Common | D16: Spring | E16: 91.25 | F16: 91.25 | G16: 91.25 | H16: 91.25 | I16: 91.25 | J16: 91.25 | K16: 91.25 | L16: 91.25 | M16: 91.25 | N16: 91.25 | O16: Days
A17: =HYPERLINK("#'Acknowledgements'!A1", "Acknowledgements") -> Acknowledgements | D17: Summer | E17: 91.25 | F17: 91.25 | G17: 91.25 | H17: 91.25 | I17: 91.25 | J17: 91.25 | K17: 91.25 | L17: 91.25 | M17: 91.25 | N17: 91.25 | O17: Days
D18: Autumn | E18: 91.25 | F18: 91.25 | G18: 91.25 | H18: 91.25 | I18: 91.25 | J18: 91.25 | K18: 91.25 | L18: 91.25 | M18: 91.25 | N18: 91.25 | O18: Days
D19: Winter | E19: 91.25 | F19: 91.25 | G19: 91.25 | H19: 91.25 | I19: 91.25 | J19: 91.25 | K19: 91.25 | L19: 91.25 | M19: 91.25 | N19: 91.25 | O19: Days
D21: Method 2 custom values (edit if known) | E21: Bulls < 1 year | F21: Bulls > 1 year | G21: Cows < 1 year | H21: Cows 1-2 years | I21: Cows 2-3 years | J21: Cows > 3 years | K21: Steers < 1 year | L21: Steers 1-2 years | M21: Steers 2-3 years | N21: Steers >3 years
D22: =TEXT(X_Cell_Site_StartDate, "mmmm yyyy") -> January 2024 | E22: =DAY(EOMONTH($D22,0)) -> 31 | F22: =DAY(EOMONTH($D22,0)) -> 31 | G22: =DAY(EOMONTH($D22,0)) -> 31 | H22: =DAY(EOMONTH($D22,0)) -> 31 | I22: =DAY(EOMONTH($D22,0)) -> 31 | J22: =DAY(EOMONTH($D22,0)) -> 31 | K22: =DAY(EOMONTH($D22,0)) -> 31 | L22: =DAY(EOMONTH($D22,0)) -> 31 | ... N22: =DAY(EOMONTH($D22,0)) -> 31 | O22: Days
D23: =TEXT(EDATE(X_Cell_Site_StartDate,1), "mmmm yyyy") -> February 2024 | E23: =DAY(EOMONTH($D23,0)) -> 29 | F23: =DAY(EOMONTH($D23,0)) -> 29 | G23: =DAY(EOMONTH($D23,0)) -> 29 | H23: =DAY(EOMONTH($D23,0)) -> 29 | I23: =DAY(EOMONTH($D23,0)) -> 29 | J23: =DAY(EOMONTH($D23,0)) -> 29 | K23: =DAY(EOMONTH($D23,0)) -> 29 | L23: =DAY(EOMONTH($D23,0)) -> 29 | ... N23: =DAY(EOMONTH($D23,0)) -> 29 | O23: Days
D24: =TEXT(EDATE(X_Cell_Site_StartDate,2), "mmmm yyyy") -> March 2024 | E24: =DAY(EOMONTH($D24,0)) -> 31 | F24: =DAY(EOMONTH($D24,0)) -> 31 | G24: =DAY(EOMONTH($D24,0)) -> 31 | H24: =DAY(EOMONTH($D24,0)) -> 31 | I24: =DAY(EOMONTH($D24,0)) -> 31 | J24: =DAY(EOMONTH($D24,0)) -> 31 | K24: =DAY(EOMONTH($D24,0)) -> 31 | L24: =DAY(EOMONTH($D24,0)) -> 31 | ... N24: =DAY(EOMONTH($D24,0)) -> 31 | O24: Days
D25: =TEXT(EDATE(X_Cell_Site_StartDate,3), "mmmm yyyy") -> April 2024 | E25: =DAY(EOMONTH($D25,0)) -> 30 | F25: =DAY(EOMONTH($D25,0)) -> 30 | G25: =DAY(EOMONTH($D25,0)) -> 30 | H25: =DAY(EOMONTH($D25,0)) -> 30 | I25: =DAY(EOMONTH($D25,0)) -> 30 | J25: =DAY(EOMONTH($D25,0)) -> 30 | K25: =DAY(EOMONTH($D25,0)) -> 30 | L25: =DAY(EOMONTH($D25,0)) -> 30 | ... N25: =DAY(EOMONTH($D25,0)) -> 30 | O25: Days
D26: =TEXT(EDATE(X_Cell_Site_StartDate,4), "mmmm yyyy") -> May 2024 | E26: =DAY(EOMONTH($D26,0)) -> 31 | F26: =DAY(EOMONTH($D26,0)) -> 31 | G26: =DAY(EOMONTH($D26,0)) -> 31 | H26: =DAY(EOMONTH($D26,0)) -> 31 | I26: =DAY(EOMONTH($D26,0)) -> 31 | J26: =DAY(EOMONTH($D26,0)) -> 31 | K26: =DAY(EOMONTH($D26,0)) -> 31 | L26: =DAY(EOMONTH($D26,0)) -> 31 | ... N26: =DAY(EOMONTH($D26,0)) -> 31 | O26: Days
D27: =TEXT(EDATE(X_Cell_Site_StartDate,5), "mmmm yyyy") -> June 2024 | E27: =DAY(EOMONTH($D27,0)) -> 30 | F27: =DAY(EOMONTH($D27,0)) -> 30 | G27: =DAY(EOMONTH($D27,0)) -> 30 | H27: =DAY(EOMONTH($D27,0)) -> 30 | I27: =DAY(EOMONTH($D27,0)) -> 30 | J27: =DAY(EOMONTH($D27,0)) -> 30 | K27: =DAY(EOMONTH($D27,0)) -> 30 | L27: =DAY(EOMONTH($D27,0)) -> 30 | ... N27: =DAY(EOMONTH($D27,0)) -> 30 | O27: Days
D28: =TEXT(EDATE(X_Cell_Site_StartDate,6), "mmmm yyyy") -> July 2024 | E28: =DAY(EOMONTH($D28,0)) -> 31 | F28: =DAY(EOMONTH($D28,0)) -> 31 | G28: =DAY(EOMONTH($D28,0)) -> 31 | H28: =DAY(EOMONTH($D28,0)) -> 31 | I28: =DAY(EOMONTH($D28,0)) -> 31 | J28: =DAY(EOMONTH($D28,0)) -> 31 | K28: =DAY(EOMONTH($D28,0)) -> 31 | L28: =DAY(EOMONTH($D28,0)) -> 31 | ... N28: =DAY(EOMONTH($D28,0)) -> 31 | O28: Days | U28: =TEXT(X_Cell_Site_StartDate,"mmmm") -> January
D29: =TEXT(EDATE(X_Cell_Site_StartDate,7), "mmmm yyyy") -> August 2024 | E29: =DAY(EOMONTH($D29,0)) -> 31 | F29: =DAY(EOMONTH($D29,0)) -> 31 | G29: =DAY(EOMONTH($D29,0)) -> 31 | H29: =DAY(EOMONTH($D29,0)) -> 31 | I29: =DAY(EOMONTH($D29,0)) -> 31 | J29: =DAY(EOMONTH($D29,0)) -> 31 | K29: =DAY(EOMONTH($D29,0)) -> 31 | L29: =DAY(EOMONTH($D29,0)) -> 31 | ... N29: =DAY(EOMONTH($D29,0)) -> 31 | O29: Days | U29: =TEXT(EDATE(X_Cell_Site_StartDate,1), "mmmm") -> February
D30: =TEXT(EDATE(X_Cell_Site_StartDate,8), "mmmm yyyy") -> September 2024 | E30: =DAY(EOMONTH($D30,0)) -> 30 | F30: =DAY(EOMONTH($D30,0)) -> 30 | G30: =DAY(EOMONTH($D30,0)) -> 30 | H30: =DAY(EOMONTH($D30,0)) -> 30 | I30: =DAY(EOMONTH($D30,0)) -> 30 | J30: =DAY(EOMONTH($D30,0)) -> 30 | K30: =DAY(EOMONTH($D30,0)) -> 30 | L30: =DAY(EOMONTH($D30,0)) -> 30 | ... N30: =DAY(EOMONTH($D30,0)) -> 30 | O30: Days | U30: =TEXT(EDATE(X_Cell_Site_StartDate,2), "mmmm") -> March
D31: =TEXT(EDATE(X_Cell_Site_StartDate,9), "mmmm yyyy") -> October 2024 | E31: =DAY(EOMONTH($D31,0)) -> 31 | F31: =DAY(EOMONTH($D31,0)) -> 31 | G31: =DAY(EOMONTH($D31,0)) -> 31 | H31: =DAY(EOMONTH($D31,0)) -> 31 | I31: =DAY(EOMONTH($D31,0)) -> 31 | J31: =DAY(EOMONTH($D31,0)) -> 31 | K31: =DAY(EOMONTH($D31,0)) -> 31 | L31: =DAY(EOMONTH($D31,0)) -> 31 | ... N31: =DAY(EOMONTH($D31,0)) -> 31 | O31: Days | U31: =TEXT(EDATE(X_Cell_Site_StartDate,3), "mmmm") -> April
D32: =TEXT(EDATE(X_Cell_Site_StartDate,10), "mmmm yyyy") -> November 2024 | E32: =DAY(EOMONTH($D32,0)) -> 30 | F32: =DAY(EOMONTH($D32,0)) -> 30 | G32: =DAY(EOMONTH($D32,0)) -> 30 | H32: =DAY(EOMONTH($D32,0)) -> 30 | I32: =DAY(EOMONTH($D32,0)) -> 30 | J32: =DAY(EOMONTH($D32,0)) -> 30 | K32: =DAY(EOMONTH($D32,0)) -> 30 | L32: =DAY(EOMONTH($D32,0)) -> 30 | ... N32: =DAY(EOMONTH($D32,0)) -> 30 | O32: Days | U32: =TEXT(EDATE(X_Cell_Site_StartDate,4), "mmmm") -> May
D33: =TEXT(EDATE(X_Cell_Site_StartDate,11), "mmmm yyyy") -> December 2024 | E33: =DAY(EOMONTH($D33,0)) -> 31 | F33: =DAY(EOMONTH($D33,0)) -> 31 | G33: =DAY(EOMONTH($D33,0)) -> 31 | H33: =DAY(EOMONTH($D33,0)) -> 31 | I33: =DAY(EOMONTH($D33,0)) -> 31 | J33: =DAY(EOMONTH($D33,0)) -> 31 | K33: =DAY(EOMONTH($D33,0)) -> 31 | L33: =DAY(EOMONTH($D33,0)) -> 31 | ... N33: =DAY(EOMONTH($D33,0)) -> 31 | O33: Days | U33: =TEXT(EDATE(X_Cell_Site_StartDate,5), "mmmm") -> June
U34: =TEXT(EDATE(X_Cell_Site_StartDate,6), "mmmm") -> July
U35: =TEXT(EDATE(X_Cell_Site_StartDate,7), "mmmm") -> August
D36: Head | U36: =TEXT(EDATE(X_Cell_Site_StartDate,8), "mmmm") -> September
D37: Method 1 values | E37: Bulls < 1 year | F37: Bulls > 1 year | G37: Cows < 1 year | H37: Cows 1-2 years | I37: Cows 2-3 years | J37: Cows > 3 years | K37: Steers < 1 year | L37: Steers 1-2 years | M37: Steers 2-3 years | N37: Steers >3 years | U37: =TEXT(EDATE(X_Cell_Site_StartDate,9), "mmmm") -> October
D38: Spring | E38: 100 | F38: 100 | G38: 100 | H38: 100 | I38: 100 | J38: 100 | K38: 100 | L38: 100 | M38: 100 | N38: 100 | O38: Head | U38: =TEXT(EDATE(X_Cell_Site_StartDate,10), "mmmm") -> November
D39: Summer | E39: 100 | F39: 100 | G39: 100 | H39: 100 | I39: 100 | J39: 100 | K39: 100 | L39: 100 | M39: 100 | N39: 100 | O39: Head | U39: =TEXT(EDATE(X_Cell_Site_StartDate,11), "mmmm") -> December
D40: Autumn | E40: 100 | F40: 100 | G40: 100 | H40: 100 | I40: 100 | J40: 100 | K40: 100 | L40: 100 | M40: 100 | N40: 100 | O40: Head
D41: Winter | E41: 100 | F41: 100 | G41: 100 | H41: 100 | I41: 100 | J41: 100 | K41: 100 | L41: 100 | M41: 100 | N41: 100 | O41: Head
D43: Method 2 values | E43: Bulls < 1 year | F43: Bulls > 1 year | G43: Cows < 1 year | H43: Cows 1-2 years | I43: Cows 2-3 years | J43: Cows > 3 years | K43: Steers < 1 year | L43: Steers 1-2 years | M43: Steers 2-3 years | N43: Steers >3 years
...

Sheet 3.2.1.1-2 Enteric Methane
A1: #VALUE! | C1: 3.2.1.1-2 Enteric Beef Grazing
A3: =HYPERLINK("#'Home'!A1", "Home") -> Home | D3: Method 1 | U3: Method 2
A4: =HYPERLINK("#'Results'!A1", "Results") -> Results
D5: {=EntericMethane_PastureBeef_Equations.VEERG_3_2_1_1__4_AdditionalIntakeForMilkProduction_Title()} -> Additional intake for milk production in the season of calving and the season after calving
A6: INPUTS | D6: {=EntericMethane_PastureBeef_Equations.VEERG_3_2_1_1__4_AdditionalIntakeForMilkProduction_Source()} -> VEERG 2026: 3.2.1.1, Equation (4)
A7: =HYPERLINK("#'Input - Site'!A1", "Site") -> Site | D7: Function name | E7: EntericMethane_PastureBeef_Equations.VEERG_3_2_1_1__4_AdditionalIntakeForMilkProduction
A8: =HYPERLINK("#'Input - Pasture Beef'!A1", "Pasture Beef") -> Pasture Beef
A10: CALCULATIONS | D10: Variable | E10: {=EntericMethane_PastureBeef_Equations.VEERG_3_2_1_1__4_AdditionalIntakeForMilkProduction_Variable()} -> MA_jk45
A11: =HYPERLINK("#'3.2.1.1-2 Enteric Methane'!A1", "3.2.1.1-2 Enteric Methane") -> 3.2.1.1-2 Enteric Methane | D11: Unit | E11: {=EntericMethane_PastureBeef_Equations.VEERG_3_2_1_1__4_AdditionalIntakeForMilkProduction_Unit()} -> fraction
A13: APPENDICES | D13: {=_xlfn.CHOOSECOLS(EntericMethane_PastureBeef_Equations.VEERG_3_2_1_1__4_AdditionalIntakeForMilkProduction_ArgumentsVariation(), 1, 2)} -> LC_jk45 | E13: proportion of cows greater than 1 year in calf in the season of calving expressed as a fraction | H13: {=_xlfn.CHOOSECOLS(EntericMethane_PastureBeef_Equations.VEERG_3_2_1_1__4_AdditionalIntakeForMilkProduction_ArgumentsVariation(), 3,4)} -> fraction | I13: Input | J13: {=HYPERLINK(Common_InputFunctions.Utility_SourceHyperlink($D$18), $D$18)} -> M1_Table_LC_j_k-4-5
A14: =HYPERLINK("#'Constants - Pasture Beef'!A1", "Constants - Pasture Beef") -> Constants - Pasture Beef | D14: FA_jk45calv | E14: feed adjustment value for lactating cows in the season of calving expressed as a fraction | H14: fraction | I14: Constant | J14: {=_xlfn.XLOOKUP(1, (Table_SourceData_PastureBeef_FeedIntakeAdjustment_Variation[Breed]=$J$16)*(Table_SourceData_PastureBeef_FeedIntakeAdjustment_Variation[Season]=+"Calving season"),Table_SourceData_PastureBeef_FeedIntakeAdjustment_Variation[Feed adjustment])} -> 1.3
A15: =HYPERLINK("#'Constants - Livestock'!A1", "Constants - Livestock") -> Constants - Livestock | D15: FA_jk45after | E15: feed adjustment value for lactating cows in the season immediately after calving expressed as a fraction | H15: fraction | I15: Constant | J15: {=_xlfn.XLOOKUP(1, (Table_SourceData_PastureBeef_FeedIntakeAdjustment_Variation[Breed]=$J$16)*(Table_SourceData_PastureBeef_FeedIntakeAdjustment_Variation[Season]=+"Season after calving"),Table_SourceData_PastureBeef_FeedIntakeAdjustment_Variation[Feed adjustment])} -> 1.1
A16: =HYPERLINK("#'Constants - Common'!A1", "Constants - Common") -> Constants - Common | D16: b | E16: breed of cattle | I16: Input | J16: =X_Cell_PastureBeef_Breed -> Hereford or Shorthorn breeds
A17: =HYPERLINK("#'Acknowledgements'!A1", "Acknowledgements") -> Acknowledgements
D18: M1_Table_LC_j_k-4-5
D19: Proportion of cows in calf during season (Method 1) | U19: M2_Table_LC_j_k-4-5
D20: Season | E20: Cows 1-2 years | F20: Cows 2-3 years | G20: Cows > 3 years | U20: Proportion of cows in calf during season (Method 2)
D21: ='Input - Pasture Beef'!$E$104 -> Winter | E21: ='Input - Pasture Beef'!$E$107 -> 0.9 | F21: ='Input - Pasture Beef'!$F$107 -> 0.5 | G21: ='Input - Pasture Beef'!$G$107 -> 0.5 | H21: Fraction | U21: Month | V21: Cows 1-2 years | W21: Cows 2-3 years | X21: Cows > 3 years
U22: =TEXT(EDATE('Input - Pasture Beef'!$D$117,0), "mmmm") & ", " & TEXT(EDATE('Input - Pasture Beef'!$D$118,0), "mmmm") & ", " & TEXT(EDATE('Input - Pasture Beef'!$D$119,0), "mmmm") -> August, September, October | V22: ='Input - Pasture Beef'!$E$120 -> 0.75 | W22: ='Input - Pasture Beef'!$F$120 -> 0.75 | X22: ='Input - Pasture Beef'!$G$120 -> 0.75 | Y22: Fraction
D23: M1_Table_MA_j_k-4-5 | U23: =TEXT(EDATE('Input - Pasture Beef'!$D$119,1), "mmmm") & ", " & TEXT(EDATE('Input - Pasture Beef'!$D$119,2), "mmmm") & ", " & TEXT(EDATE('Input - Pasture Beef'!$D$119,3), "mmmm") -> November, December, January
D24: Additional intake for milk production in calving and post-calving seasons (Method 1)
D25: Season | E25: Calving season | F25: FAjk=4,5 | G25: Bulls < 1 year | H25: Bulls > 1 year | I25: Cows < 1 year | J25: Cows 1-2 years | K25: Cows 2-3 years | L25: Cows > 3 years | M25: Steers < 1 year | N25: Steers 1-2 years | O25: Steers 2-3 years | P25: Steers >3 years | U25: M2_Table_MA_j_k-4-5
D26: Spring | E26: {=_xlfn.IFS(D21=D26, "Calving season", D21=D29, "Season after calving", D21=D27, "", D21=D28, "")} -> Season after calving | F26: {=_xlfn.IFS(E26="Calving season", $J$14, E26="Season after calving", $J$15, E26="", "")} -> 1.1 | G26: 1 | H26: 1 | I26: 1 | J26: {=IFERROR(EntericMethane_PastureBeef_Equations.VEERG_3_2_1_1__4_AdditionalIntakeForMilkProduction(E$21,$F26), 1)} -> 1.09 | K26: {=IFERROR(EntericMethane_PastureBeef_Equations.VEERG_3_2_1_1__4_AdditionalIntakeForMilkProduction(F$21,$F26), 1)} -> 1.05 | L26: {=IFERROR(EntericMethane_PastureBeef_Equations.VEERG_3_2_1_1__4_AdditionalIntakeForMilkProduction(G$21,$F26), 1)} -> 1.05 | M26: 1 | N26: 1 | O26: 1 | P26: 1 | Q26: =$E$11 -> fraction | U26: Additional intake for milk production in calving and post-calving seasons (Method 2)
D27: Summer | E27: {=_xlfn.IFS(D21=D27, "Calving season", D21=D26, "Season after calving", D21=D28, "", D21=D29, "")} | F27: {=_xlfn.IFS(E27="Calving season", $J$14, E27="Season after calving", $J$15, E27="", "")} | G27: 1 | H27: 1 | I27: 1 | J27: {=IFERROR(EntericMethane_PastureBeef_Equations.VEERG_3_2_1_1__4_AdditionalIntakeForMilkProduction(E$21,$F27), 1)} -> 1 | K27: {=IFERROR(EntericMethane_PastureBeef_Equations.VEERG_3_2_1_1__4_AdditionalIntakeForMilkProduction(F$21,$F27), 1)} -> 1 | L27: {=IFERROR(EntericMethane_PastureBeef_Equations.VEERG_3_2_1_1__4_AdditionalIntakeForMilkProduction(G$21,$F27), 1)} -> 1 | M27: 1 | N27: 1 | O27: 1 | P27: 1 | Q27: =$E$11 -> fraction | U27: Month | V27: Calving season | W27: FAjk=4,5 | X27: Bulls < 1 year | Y27: Bulls > 1 year | Z27: Cows < 1 year | AA27: Cows 1-2 years | AB27: Cows 2-3 years | AC27: Cows > 3 years | AD27: Steers < 1 year | AE27: Steers 1-2 years | AF27: Steers 2-3 years | AG27: Steers >3 years
D28: Autumn | E28: {=_xlfn.IFS(D21=D28, "Calving season", D21=D27, "Season after calving", D21=D29, "", D21=D26, "")} | F28: {=_xlfn.IFS(E28="Calving season", $J$14, E28="Season after calving", $J$15, E28="", "")} | G28: 1 | H28: 1 | I28: 1 | J28: {=IFERROR(EntericMethane_PastureBeef_Equations.VEERG_3_2_1_1__4_AdditionalIntakeForMilkProduction(E$21,$F28), 1)} -> 1 | K28: {=IFERROR(EntericMethane_PastureBeef_Equations.VEERG_3_2_1_1__4_AdditionalIntakeForMilkProduction(F$21,$F28), 1)} -> 1 | L28: {=IFERROR(EntericMethane_PastureBeef_Equations.VEERG_3_2_1_1__4_AdditionalIntakeForMilkProduction(G$21,$F28), 1)} -> 1 | M28: 1 | N28: 1 | O28: 1 | P28: 1 | Q28: =$E$11 -> fraction | U28: =TEXT('Input - Site'!$E$12,"mmmm") -> January | V28: {=IFERROR(_xlfn.IFS(SUMPRODUCT(ISNUMBER(SEARCH(TRIM(_xlfn.TEXTSPLIT($U$22,",")),U28))*1)>0,"Calving season",SUMPRODUCT(ISNUMBER(SEARCH(TRIM(_xlfn.TEXTSPLIT($U$23,",")),U28))*1)>0,"Season after calving"), "")} -> Season after calving | W28: {=_xlfn.IFS(V28="Calving season", $J$14, V28="Season after calving", $J$15, V28="", "")} -> 1.1 | X28: 1 | Y28: 1 | Z28: 1 | AA28: {=IFERROR(EntericMethane_PastureBeef_Equations.VEERG_3_2_1_1__4_AdditionalIntakeForMilkProduction(V$22,$W28), 1)} -> 1.075 | AB28: {=IFERROR(EntericMethane_PastureBeef_Equations.VEERG_3_2_1_1__4_AdditionalIntakeForMilkProduction(W$22,$W28), 1)} -> 1.075 | AC28: {=IFERROR(EntericMethane_PastureBeef_Equations.VEERG_3_2_1_1__4_AdditionalIntakeForMilkProduction(X$22,$W28), 1)} -> 1.075 | AD28: 1 | AE28: 1 | AF28: 1 | AG28: 1 | AH28: =$E$11 -> fraction
D29: Winter | E29: {=_xlfn.IFS(D21=D29, "Calving season", D21=D28, "Season after calving", D21=D26, "", D21=D27, "")} -> Calving season | F29: {=_xlfn.IFS(E29="Calving season", $J$14, E29="Season after calving", $J$15, E29="", "")} -> 1.3 | G29: 1 | H29: 1 | I29: 1 | J29: {=IFERROR(EntericMethane_PastureBeef_Equations.VEERG_3_2_1_1__4_AdditionalIntakeForMilkProduction(E$21,$F29), 1)} -> 1.27 | K29: {=IFERROR(EntericMethane_PastureBeef_Equations.VEERG_3_2_1_1__4_AdditionalIntakeForMilkProduction(F$21,$F29), 1)} -> 1.15 | L29: {=IFERROR(EntericMethane_PastureBeef_Equations.VEERG_3_2_1_1__4_AdditionalIntakeForMilkProduction(G$21,$F29), 1)} -> 1.15 | M29: 1 | N29: 1 | O29: 1 | P29: 1 | Q29: =$E$11 -> fraction | U29: =TEXT(EDATE('Input - Site'!$E$12,1), "mmmm") -> February | V29: {=IFERROR(_xlfn.IFS(SUMPRODUCT(ISNUMBER(SEARCH(TRIM(_xlfn.TEXTSPLIT($U$22,",")),U29))*1)>0,"Calving season",SUMPRODUCT(ISNUMBER(SEARCH(TRIM(_xlfn.TEXTSPLIT($U$23,",")),U29))*1)>0,"Season after calving"), "")} | W29: {=_xlfn.IFS(V29="Calving season", $J$14, V29="Season after calving", $J$15, V29="", "")} | X29: 1 | Y29: 1 | Z29: 1 | AA29: {=IFERROR(EntericMethane_PastureBeef_Equations.VEERG_3_2_1_1__4_AdditionalIntakeForMilkProduction(V$22,$W29), 1)} -> 1 | AB29: {=IFERROR(EntericMethane_PastureBeef_Equations.VEERG_3_2_1_1__4_AdditionalIntakeForMilkProduction(W$22,$W29), 1)} -> 1 | AC29: {=IFERROR(EntericMethane_PastureBeef_Equations.VEERG_3_2_1_1__4_AdditionalIntakeForMilkProduction(X$22,$W29), 1)} -> 1 | AD29: 1 | AE29: 1 | AF29: 1 | AG29: 1 | AH29: =$E$11 -> fraction
U30: =TEXT(EDATE('Input - Site'!$E$12,2), "mmmm") -> March | V30: {=IFERROR(_xlfn.IFS(SUMPRODUCT(ISNUMBER(SEARCH(TRIM(_xlfn.TEXTSPLIT($U$22,",")),U30))*1)>0,"Calving season",SUMPRODUCT(ISNUMBER(SEARCH(TRIM(_xlfn.TEXTSPLIT($U$23,",")),U30))*1)>0,"Season after calving"), "")} | W30: {=_xlfn.IFS(V30="Calving season", $J$14, V30="Season after calving", $J$15, V30="", "")} | X30: 1 | Y30: 1 | Z30: 1 | AA30: {=IFERROR(EntericMethane_PastureBeef_Equations.VEERG_3_2_1_1__4_AdditionalIntakeForMilkProduction(V$22,$W30), 1)} -> 1 | AB30: {=IFERROR(EntericMethane_PastureBeef_Equations.VEERG_3_2_1_1__4_AdditionalIntakeForMilkProduction(W$22,$W30), 1)} -> 1 | AC30: {=IFERROR(EntericMethane_PastureBeef_Equations.VEERG_3_2_1_1__4_AdditionalIntakeForMilkProduction(X$22,$W30), 1)} -> 1 | AD30: 1 | AE30: 1 | AF30: 1 | AG30: 1 | AH30: =$E$11 -> fraction
U31: =TEXT(EDATE('Input - Site'!$E$12,3), "mmmm") -> April | V31: {=IFERROR(_xlfn.IFS(SUMPRODUCT(ISNUMBER(SEARCH(TRIM(_xlfn.TEXTSPLIT($U$22,",")),U31))*1)>0,"Calving season",SUMPRODUCT(ISNUMBER(SEARCH(TRIM(_xlfn.TEXTSPLIT($U$23,",")),U31))*1)>0,"Season after calving"), "")} | W31: {=_xlfn.IFS(V31="Calving season", $J$14, V31="Season after calving", $J$15, V31="", "")} | X31: 1 | Y31: 1 | Z31: 1 | AA31: {=IFERROR(EntericMethane_PastureBeef_Equations.VEERG_3_2_1_1__4_AdditionalIntakeForMilkProduction(V$22,$W31), 1)} -> 1 | AB31: {=IFERROR(EntericMethane_PastureBeef_Equations.VEERG_3_2_1_1__4_AdditionalIntakeForMilkProduction(W$22,$W31), 1)} -> 1 | AC31: {=IFERROR(EntericMethane_PastureBeef_Equations.VEERG_3_2_1_1__4_AdditionalIntakeForMilkProduction(X$22,$W31), 1)} -> 1 | AD31: 1 | AE31: 1 | AF31: 1 | AG31: 1 | AH31: =$E$11 -> fraction
U32: =TEXT(EDATE('Input - Site'!$E$12,4), "mmmm") -> May | V32: {=IFERROR(_xlfn.IFS(SUMPRODUCT(ISNUMBER(SEARCH(TRIM(_xlfn.TEXTSPLIT($U$22,",")),U32))*1)>0,"Calving season",SUMPRODUCT(ISNUMBER(SEARCH(TRIM(_xlfn.TEXTSPLIT($U$23,",")),U32))*1)>0,"Season after calving"), "")} | W32: {=_xlfn.IFS(V32="Calving season", $J$14, V32="Season after calving", $J$15, V32="", "")} | X32: 1 | Y32: 1 | Z32: 1 | AA32: {=IFERROR(EntericMethane_PastureBeef_Equations.VEERG_3_2_1_1__4_AdditionalIntakeForMilkProduction(V$22,$W32), 1)} -> 1 | AB32: {=IFERROR(EntericMethane_PastureBeef_Equations.VEERG_3_2_1_1__4_AdditionalIntakeForMilkProduction(W$22,$W32), 1)} -> 1 | AC32: {=IFERROR(EntericMethane_PastureBeef_Equations.VEERG_3_2_1_1__4_AdditionalIntakeForMilkProduction(X$22,$W32), 1)} -> 1 | AD32: 1 | AE32: 1 | AF32: 1 | AG32: 1 | AH32: =$E$11 -> fraction
D33: {=EntericMethane_PastureBeef_Equations.VEERG_3_2_1_1__3_FeedIntakeForGrazingBeef_Title()} -> Feed intake for grazing beef cattle | U33: =TEXT(EDATE('Input - Site'!$E$12,5), "mmmm") -> June | V33: {=IFERROR(_xlfn.IFS(SUMPRODUCT(ISNUMBER(SEARCH(TRIM(_xlfn.TEXTSPLIT($U$22,",")),U33))*1)>0,"Calving season",SUMPRODUCT(ISNUMBER(SEARCH(TRIM(_xlfn.TEXTSPLIT($U$23,",")),U33))*1)>0,"Season after calving"), "")} | W33: {=_xlfn.IFS(V33="Calving season", $J$14, V33="Season after calving", $J$15, V33="", "")} | X33: 1 | Y33: 1 | Z33: 1 | AA33: {=IFERROR(EntericMethane_PastureBeef_Equations.VEERG_3_2_1_1__4_AdditionalIntakeForMilkProduction(V$22,$W33), 1)} -> 1 | AB33: {=IFERROR(EntericMethane_PastureBeef_Equations.VEERG_3_2_1_1__4_AdditionalIntakeForMilkProduction(W$22,$W33), 1)} -> 1 | AC33: {=IFERROR(EntericMethane_PastureBeef_Equations.VEERG_3_2_1_1__4_AdditionalIntakeForMilkProduction(X$22,$W33), 1)} -> 1 | AD33: 1 | AE33: 1 | AF33: 1 | AG33: 1 | AH33: =$E$11 -> fraction
D34: {=EntericMethane_PastureBeef_Equations.VEERG_3_2_1_1__3_FeedIntakeForGrazingBeef_Source()} -> VEERG 2026: 3.2.1.1, Equation (3) | U34: =TEXT(EDATE('Input - Site'!$E$12,6), "mmmm") -> July | V34: {=IFERROR(_xlfn.IFS(SUMPRODUCT(ISNUMBER(SEARCH(TRIM(_xlfn.TEXTSPLIT($U$22,",")),U34))*1)>0,"Calving season",SUMPRODUCT(ISNUMBER(SEARCH(TRIM(_xlfn.TEXTSPLIT($U$23,",")),U34))*1)>0,"Season after calving"), "")} | W34: {=_xlfn.IFS(V34="Calving season", $J$14, V34="Season after calving", $J$15, V34="", "")} | X34: 1 | Y34: 1 | Z34: 1 | AA34: {=IFERROR(EntericMethane_PastureBeef_Equations.VEERG_3_2_1_1__4_AdditionalIntakeForMilkProduction(V$22,$W34), 1)} -> 1 | AB34: {=IFERROR(EntericMethane_PastureBeef_Equations.VEERG_3_2_1_1__4_AdditionalIntakeForMilkProduction(W$22,$W34), 1)} -> 1 | AC34: {=IFERROR(EntericMethane_PastureBeef_Equations.VEERG_3_2_1_1__4_AdditionalIntakeForMilkProduction(X$22,$W34), 1)} -> 1 | AD34: 1 | AE34: 1 | AF34: 1 | AG34: 1 | AH34: =$E$11 -> fraction
D35: Function name | E35: {=Common_InputFunctions.Utility_DisplayFunctionName($E$64)} -> =EntericMethane_PastureBeef_Equations.VEERG_3_2_1_1__3_FeedIntakeForGrazingBeef | U35: =TEXT(EDATE('Input - Site'!$E$12,7), "mmmm") -> August | V35: {=IFERROR(_xlfn.IFS(SUMPRODUCT(ISNUMBER(SEARCH(TRIM(_xlfn.TEXTSPLIT($U$22,",")),U35))*1)>0,"Calving season",SUMPRODUCT(ISNUMBER(SEARCH(TRIM(_xlfn.TEXTSPLIT($U$23,",")),U35))*1)>0,"Season after calving"), "")} -> Calving season | W35: {=_xlfn.IFS(V35="Calving season", $J$14, V35="Season after calving", $J$15, V35="", "")} -> 1.3 | X35: 1 | Y35: 1 | Z35: 1 | AA35: {=IFERROR(EntericMethane_PastureBeef_Equations.VEERG_3_2_1_1__4_AdditionalIntakeForMilkProduction(V$22,$W35), 1)} -> 1.225 | AB35: {=IFERROR(EntericMethane_PastureBeef_Equations.VEERG_3_2_1_1__4_AdditionalIntakeForMilkProduction(W$22,$W35), 1)} -> 1.225 | AC35: {=IFERROR(EntericMethane_PastureBeef_Equations.VEERG_3_2_1_1__4_AdditionalIntakeForMilkProduction(X$22,$W35), 1)} -> 1.225 | AD35: 1 | AE35: 1 | AF35: 1 | AG35: 1 | AH35: =$E$11 -> fraction
U36: =TEXT(EDATE('Input - Site'!$E$12,8), "mmmm") -> September | V36: {=IFERROR(_xlfn.IFS(SUMPRODUCT(ISNUMBER(SEARCH(TRIM(_xlfn.TEXTSPLIT($U$22,",")),U36))*1)>0,"Calving season",SUMPRODUCT(ISNUMBER(SEARCH(TRIM(_xlfn.TEXTSPLIT($U$23,",")),U36))*1)>0,"Season after calving"), "")} -> Calving season | W36: {=_xlfn.IFS(V36="Calving season", $J$14, V36="Season after calving", $J$15, V36="", "")} -> 1.3 | X36: 1 | Y36: 1 | Z36: 1 | AA36: {=IFERROR(EntericMethane_PastureBeef_Equations.VEERG_3_2_1_1__4_AdditionalIntakeForMilkProduction(V$22,$W36), 1)} -> 1.225 | AB36: {=IFERROR(EntericMethane_PastureBeef_Equations.VEERG_3_2_1_1__4_AdditionalIntakeForMilkProduction(W$22,$W36), 1)} -> 1.225 | AC36: {=IFERROR(EntericMethane_PastureBeef_Equations.VEERG_3_2_1_1__4_AdditionalIntakeForMilkProduction(X$22,$W36), 1)} -> 1.225 | AD36: 1 | AE36: 1 | AF36: 1 | AG36: 1 | AH36: =$E$11 -> fraction
G37: {=EntericMethane_PastureBeef_Equations.VEERG_3_2_1_1__3_FeedIntakeForGrazingBeef_LatexEquation()} -> I_{jkl}=(1.185+0.00454\times W_{jkl}-0.0000026\times W_{jkl}^{2}+0.315\times LWG_{jkl})^2\times MA_{jk=4,5} | U37: =TEXT(EDATE('Input - Site'!$E$12,9), "mmmm") -> October | V37: {=IFERROR(_xlfn.IFS(SUMPRODUCT(ISNUMBER(SEARCH(TRIM(_xlfn.TEXTSPLIT($U$22,",")),U37))*1)>0,"Calving season",SUMPRODUCT(ISNUMBER(SEARCH(TRIM(_xlfn.TEXTSPLIT($U$23,",")),U37))*1)>0,"Season after calving"), "")} -> Calving season | W37: {=_xlfn.IFS(V37="Calving season", $J$14, V37="Season after calving", $J$15, V37="", "")} -> 1.3 | X37: 1 | Y37: 1 | Z37: 1 | AA37: {=IFERROR(EntericMethane_PastureBeef_Equations.VEERG_3_2_1_1__4_AdditionalIntakeForMilkProduction(V$22,$W37), 1)} -> 1.225 | AB37: {=IFERROR(EntericMethane_PastureBeef_Equations.VEERG_3_2_1_1__4_AdditionalIntakeForMilkProduction(W$22,$W37), 1)} -> 1.225 | AC37: {=IFERROR(EntericMethane_PastureBeef_Equations.VEERG_3_2_1_1__4_AdditionalIntakeForMilkProduction(X$22,$W37), 1)} -> 1.225 | AD37: 1 | AE37: 1 | AF37: 1 | AG37: 1 | AH37: =$E$11 -> fraction
D38: Variable | E38: {=EntericMethane_PastureBeef_Equations.VEERG_3_2_1_1__3_FeedIntakeForGrazingBeef_Variable()} -> I_jkl | U38: =TEXT(EDATE('Input - Site'!$E$12,10), "mmmm") -> November | V38: {=IFERROR(_xlfn.IFS(SUMPRODUCT(ISNUMBER(SEARCH(TRIM(_xlfn.TEXTSPLIT($U$22,",")),U38))*1)>0,"Calving season",SUMPRODUCT(ISNUMBER(SEARCH(TRIM(_xlfn.TEXTSPLIT($U$23,",")),U38))*1)>0,"Season after calving"), "")} -> Season after calving | W38: {=_xlfn.IFS(V38="Calving season", $J$14, V38="Season after calving", $J$15, V38="", "")} -> 1.1 | X38: 1 | Y38: 1 | Z38: 1 | AA38: {=IFERROR(EntericMethane_PastureBeef_Equations.VEERG_3_2_1_1__4_AdditionalIntakeForMilkProduction(V$22,$W38), 1)} -> 1.075 | AB38: {=IFERROR(EntericMethane_PastureBeef_Equations.VEERG_3_2_1_1__4_AdditionalIntakeForMilkProduction(W$22,$W38), 1)} -> 1.075 | AC38: {=IFERROR(EntericMethane_PastureBeef_Equations.VEERG_3_2_1_1__4_AdditionalIntakeForMilkProduction(X$22,$W38), 1)} -> 1.075 | AD38: 1 | AE38: 1 | AF38: 1 | AG38: 1 | AH38: =$E$11 -> fraction
D39: Unit | E39: {=EntericMethane_PastureBeef_Equations.VEERG_3_2_1_1__3_FeedIntakeForGrazingBeef_Unit()} -> kg DM/head/day | U39: =TEXT(EDATE('Input - Site'!$E$12,11), "mmmm") -> December | V39: {=IFERROR(_xlfn.IFS(SUMPRODUCT(ISNUMBER(SEARCH(TRIM(_xlfn.TEXTSPLIT($U$22,",")),U39))*1)>0,"Calving season",SUMPRODUCT(ISNUMBER(SEARCH(TRIM(_xlfn.TEXTSPLIT($U$23,",")),U39))*1)>0,"Season after calving"), "")} -> Season after calving | W39: {=_xlfn.IFS(V39="Calving season", $J$14, V39="Season after calving", $J$15, V39="", "")} -> 1.1 | X39: 1 | Y39: 1 | Z39: 1 | AA39: {=IFERROR(EntericMethane_PastureBeef_Equations.VEERG_3_2_1_1__4_AdditionalIntakeForMilkProduction(V$22,$W39), 1)} -> 1.075 | AB39: {=IFERROR(EntericMethane_PastureBeef_Equations.VEERG_3_2_1_1__4_AdditionalIntakeForMilkProduction(W$22,$W39), 1)} -> 1.075 | AC39: {=IFERROR(EntericMethane_PastureBeef_Equations.VEERG_3_2_1_1__4_AdditionalIntakeForMilkProduction(X$22,$W39), 1)} -> 1.075 | AD39: 1 | AE39: 1 | AF39: 1 | AG39: 1 | AH39: =$E$11 -> fraction
D41: {=_xlfn.CHOOSECOLS(EntericMethane_PastureBeef_Equations.VEERG_3_2_1_1__3_FeedIntakeForGrazingBeef_Arguments(), 1, 2)} -> W_jkl | E41: liveweight (kg) | G41: {=_xlfn.CHOOSECOLS(EntericMethane_PastureBeef_Equations.VEERG_3_2_1_1__3_FeedIntakeForGrazingBeef_Arguments(), 3,4)} -> kg | H41: Input | I41: {=HYPERLINK(Common_InputFunctions.Utility_SourceHyperlink($D$45), $D$45)} -> M1_Table_W_j_k_l | U41: M2_Table_W_j_k_l
D42: LWG_jkl | E42: live weight gain (kg/head/day) | G42: kg/head/day | H42: Input | I42: {=HYPERLINK(Common_InputFunctions.Utility_SourceHyperlink($D$53), $D$53)} -> M1_Table_LWG_j_k_l | U42: Liveweight (Method 2)
D43: MA_jk45 | E43: additional intake for milk production in cows greater than 2 years | G43: kg/head/day | H43: Calculated from 3.2.1.1, (4) | I43: {=HYPERLINK(Common_InputFunctions.Utility_SourceHyperlink($D$23), $D$23)} -> M1_Table_MA_j_k-4-5 | U43: Month | V43: Bulls < 1 year | W43: Bulls > 1 year | X43: Cows < 1 year | Y43: Cows 1-2 years | Z43: Cows 2-3 years | AA43: Cows > 3 years | AB43: Steers < 1 year | AC43: Steers 1-2 years | AD43: Steers 2-3 years | AE43: Steers >3 years
U44: =TEXT('Input - Site'!$E$12,"mmmm") -> January | V44: {=OFFSET(X_Table_PastureBeef_Liveweight_Method2,1,1,12,10)} -> 380 | W44: 780 | X44: 300 | Y44: 450 | Z44: 530 | AA44: 530 | AB44: 340 | AC44: 470 | AD44: 470 | AE44: 470 | AF44: kg/head
...

Sheet Constants - Pasture Beef
A1: #VALUE! | C1: Constants - Pasture Beef
A3: =HYPERLINK("#'Home'!A1", "Home") -> Home
A4: =HYPERLINK("#'Results'!A1", "Results") -> Results
D5: Pasture beefcrop or pasture production systems | G5: Irrigation methods | M5: Table_SourceData_PastureBeef_Region_WesternAustralia | O5: Table_SourceData_PastureBeef_Region_Queensland | Q5: Table_SourceData_PastureBeef_Region_NorthernTerritory | S5: Table_SourceData_PastureBeef_Region_Victoria
A6: INPUTS
A7: =HYPERLINK("#'Input - Site'!A1", "Site") -> Site | D7: Production system | G7: Irrigation method | M7: Region | O7: Region | Q7: Region | S7: Region
A8: =HYPERLINK("#'Input - Pasture Beef'!A1", "Pasture Beef") -> Pasture Beef | D8: ='Constants - Common'!$F$187 -> Pasture | G8: Not irrigated | M8: South West | O8: Alice Springs | Q8: High | S8: n/a
D9: ='Constants - Common'!$F$188 -> Crop | G9: Drip irrigation | M9: Pilbara | O9: Barkly | Q9: Moderate/High
A10: CALCULATIONS | G10: Sprinkler irrigation | M10: Kimberley | O10: Northern | Q10: Moderate/Low | S10: Table_SourceData_PastureBeef_Region_NewSouthWales
A11: =HYPERLINK("#'3.2.1.1-2 Enteric Methane'!A1", "3.2.1.1-2 Enteric Methane") -> 3.2.1.1-2 Enteric Methane | G11: Surface irrigation | Q11: Low
G12: Other irrigation | S12: Region
A13: APPENDICES | S13: n/a
A14: =HYPERLINK("#'Constants - Pasture Beef'!A1", "Constants - Pasture Beef") -> Constants - Pasture Beef | D14: {=SourceData_PastureBeef.SourceData_PastureBeef_Liveweight_Title()} -> Beef pasture cattle - Liveweight (kg) (Wjkl)
A15: =HYPERLINK("#'Constants - Livestock'!A1", "Constants - Livestock") -> Constants - Livestock | D15: {=SourceData_PastureBeef.SourceData_PastureBeef_Liveweight_Source()} -> VEERG 2026: Table A.1.2.1 | S15: Table_SourceData_PastureBeef_Region_SouthAustralia
A16: =HYPERLINK("#'Constants - Common'!A1", "Constants - Common") -> Constants - Common | D16: {=SourceData_PastureBeef.SourceData_PastureBeef_Liveweight_Variable()} -> Wjkl
A17: =HYPERLINK("#'Acknowledgements'!A1", "Acknowledgements") -> Acknowledgements | D17: {=SourceData_PastureBeef.SourceData_PastureBeef_Liveweight_Unit()} -> kg | S17: Region
D18: State | E18: Region | F18: Season | G18: Bull < 1 | H18: Bull > 1 | I18: Cow < 1 | J18: Cow 1-2 | K18: Cow > 2 | L18: Steer < 1 | M18: Steer > 1 | S18: n/a
D19: {=Common_InputFunctions.Utility_DisplayArrayInTable(SourceData_PastureBeef.SourceData_PastureBeef_Liveweight_Data(), Table_SourceData_PastureBeef_Liveweight[[#Headers],[State]], 0)} -> ACT/NSW | E19: {=Common_InputFunctions.Utility_DisplayArrayInTable(SourceData_PastureBeef.SourceData_PastureBeef_Liveweight_Data(), Table_SourceData_PastureBeef_Liveweight[[#Headers],[State]], 0)} -> n/a | F19: {=Common_InputFunctions.Utility_DisplayArrayInTable(SourceData_PastureBeef.SourceData_PastureBeef_Liveweight_Data(), Table_SourceData_PastureBeef_Liveweight[[#Headers],[State]], 0)} -> Spring | G19: {=Common_InputFunctions.Utility_DisplayArrayInTable(SourceData_PastureBeef.SourceData_PastureBeef_Liveweight_Data(), Table_SourceData_PastureBeef_Liveweight[[#Headers],[State]], 0)} -> 80 | H19: {=Common_InputFunctions.Utility_DisplayArrayInTable(SourceData_PastureBeef.SourceData_PastureBeef_Liveweight_Data(), Table_SourceData_PastureBeef_Liveweight[[#Headers],[State]], 0)} -> 480 | I19: {=Common_InputFunctions.Utility_DisplayArrayInTable(SourceData_PastureBeef.SourceData_PastureBeef_Liveweight_Data(), Table_SourceData_PastureBeef_Liveweight[[#Headers],[State]], 0)} -> 75 | J19: {=Common_InputFunctions.Utility_DisplayArrayInTable(SourceData_PastureBeef.SourceData_PastureBeef_Liveweight_Data(), Table_SourceData_PastureBeef_Liveweight[[#Headers],[State]], 0)} -> 300 | K19: {=Common_InputFunctions.Utility_DisplayArrayInTable(SourceData_PastureBeef.SourceData_PastureBeef_Liveweight_Data(), Table_SourceData_PastureBeef_Liveweight[[#Headers],[State]], 0)} -> 440 | ... M19: {=Common_InputFunctions.Utility_DisplayArrayInTable(SourceData_PastureBeef.SourceData_PastureBeef_Liveweight_Data(), Table_SourceData_PastureBeef_Liveweight[[#Headers],[State]], 0)} -> 380
D20: {=Common_InputFunctions.Utility_DisplayArrayInTable(SourceData_PastureBeef.SourceData_PastureBeef_Liveweight_Data(), Table_SourceData_PastureBeef_Liveweight[[#Headers],[State]], 0)} -> ACT/NSW | E20: {=Common_InputFunctions.Utility_DisplayArrayInTable(SourceData_PastureBeef.SourceData_PastureBeef_Liveweight_Data(), Table_SourceData_PastureBeef_Liveweight[[#Headers],[State]], 0)} -> n/a | F20: {=Common_InputFunctions.Utility_DisplayArrayInTable(SourceData_PastureBeef.SourceData_PastureBeef_Liveweight_Data(), Table_SourceData_PastureBeef_Liveweight[[#Headers],[State]], 0)} -> Summer | G20: {=Common_InputFunctions.Utility_DisplayArrayInTable(SourceData_PastureBeef.SourceData_PastureBeef_Liveweight_Data(), Table_SourceData_PastureBeef_Liveweight[[#Headers],[State]], 0)} -> 170 | H20: {=Common_InputFunctions.Utility_DisplayArrayInTable(SourceData_PastureBeef.SourceData_PastureBeef_Liveweight_Data(), Table_SourceData_PastureBeef_Liveweight[[#Headers],[State]], 0)} -> 520 | I20: {=Common_InputFunctions.Utility_DisplayArrayInTable(SourceData_PastureBeef.SourceData_PastureBeef_Liveweight_Data(), Table_SourceData_PastureBeef_Liveweight[[#Headers],[State]], 0)} -> 160 | J20: {=Common_InputFunctions.Utility_DisplayArrayInTable(SourceData_PastureBeef.SourceData_PastureBeef_Liveweight_Data(), Table_SourceData_PastureBeef_Liveweight[[#Headers],[State]], 0)} -> 360 | K20: {=Common_InputFunctions.Utility_DisplayArrayInTable(SourceData_PastureBeef.SourceData_PastureBeef_Liveweight_Data(), Table_SourceData_PastureBeef_Liveweight[[#Headers],[State]], 0)} -> 470 | ... M20: {=Common_InputFunctions.Utility_DisplayArrayInTable(SourceData_PastureBeef.SourceData_PastureBeef_Liveweight_Data(), Table_SourceData_PastureBeef_Liveweight[[#Headers],[State]], 0)} -> 420 | S20: Table_SourceData_PastureBeef_Region_Tasmania
D21: {=Common_InputFunctions.Utility_DisplayArrayInTable(SourceData_PastureBeef.SourceData_PastureBeef_Liveweight_Data(), Table_SourceData_PastureBeef_Liveweight[[#Headers],[State]], 0)} -> ACT/NSW | E21: {=Common_InputFunctions.Utility_DisplayArrayInTable(SourceData_PastureBeef.SourceData_PastureBeef_Liveweight_Data(), Table_SourceData_PastureBeef_Liveweight[[#Headers],[State]], 0)} -> n/a | F21: {=Common_InputFunctions.Utility_DisplayArrayInTable(SourceData_PastureBeef.SourceData_PastureBeef_Liveweight_Data(), Table_SourceData_PastureBeef_Liveweight[[#Headers],[State]], 0)} -> Autumn | G21: {=Common_InputFunctions.Utility_DisplayArrayInTable(SourceData_PastureBeef.SourceData_PastureBeef_Liveweight_Data(), Table_SourceData_PastureBeef_Liveweight[[#Headers],[State]], 0)} -> 240 | H21: {=Common_InputFunctions.Utility_DisplayArrayInTable(SourceData_PastureBeef.SourceData_PastureBeef_Liveweight_Data(), Table_SourceData_PastureBeef_Liveweight[[#Headers],[State]], 0)} -> 550 | I21: {=Common_InputFunctions.Utility_DisplayArrayInTable(SourceData_PastureBeef.SourceData_PastureBeef_Liveweight_Data(), Table_SourceData_PastureBeef_Liveweight[[#Headers],[State]], 0)} -> 220 | J21: {=Common_InputFunctions.Utility_DisplayArrayInTable(SourceData_PastureBeef.SourceData_PastureBeef_Liveweight_Data(), Table_SourceData_PastureBeef_Liveweight[[#Headers],[State]], 0)} -> 390 | K21: {=Common_InputFunctions.Utility_DisplayArrayInTable(SourceData_PastureBeef.SourceData_PastureBeef_Liveweight_Data(), Table_SourceData_PastureBeef_Liveweight[[#Headers],[State]], 0)} -> 490 | ... M21: {=Common_InputFunctions.Utility_DisplayArrayInTable(SourceData_PastureBeef.SourceData_PastureBeef_Liveweight_Data(), Table_SourceData_PastureBeef_Liveweight[[#Headers],[State]], 0)} -> 450
D22: {=Common_InputFunctions.Utility_DisplayArrayInTable(SourceData_PastureBeef.SourceData_PastureBeef_Liveweight_Data(), Table_SourceData_PastureBeef_Liveweight[[#Headers],[State]], 0)} -> ACT/NSW | E22: {=Common_InputFunctions.Utility_DisplayArrayInTable(SourceData_PastureBeef.SourceData_PastureBeef_Liveweight_Data(), Table_SourceData_PastureBeef_Liveweight[[#Headers],[State]], 0)} -> n/a | F22: {=Common_InputFunctions.Utility_DisplayArrayInTable(SourceData_PastureBeef.SourceData_PastureBeef_Liveweight_Data(), Table_SourceData_PastureBeef_Liveweight[[#Headers],[State]], 0)} -> Winter | G22: {=Common_InputFunctions.Utility_DisplayArrayInTable(SourceData_PastureBeef.SourceData_PastureBeef_Liveweight_Data(), Table_SourceData_PastureBeef_Liveweight[[#Headers],[State]], 0)} -> 280 | H22: {=Common_InputFunctions.Utility_DisplayArrayInTable(SourceData_PastureBeef.SourceData_PastureBeef_Liveweight_Data(), Table_SourceData_PastureBeef_Liveweight[[#Headers],[State]], 0)} -> 560 | I22: {=Common_InputFunctions.Utility_DisplayArrayInTable(SourceData_PastureBeef.SourceData_PastureBeef_Liveweight_Data(), Table_SourceData_PastureBeef_Liveweight[[#Headers],[State]], 0)} -> 260 | J22: {=Common_InputFunctions.Utility_DisplayArrayInTable(SourceData_PastureBeef.SourceData_PastureBeef_Liveweight_Data(), Table_SourceData_PastureBeef_Liveweight[[#Headers],[State]], 0)} -> 410 | K22: {=Common_InputFunctions.Utility_DisplayArrayInTable(SourceData_PastureBeef.SourceData_PastureBeef_Liveweight_Data(), Table_SourceData_PastureBeef_Liveweight[[#Headers],[State]], 0)} -> 500 | ... M22: {=Common_InputFunctions.Utility_DisplayArrayInTable(SourceData_PastureBeef.SourceData_PastureBeef_Liveweight_Data(), Table_SourceData_PastureBeef_Liveweight[[#Headers],[State]], 0)} -> 460 | S22: Region
D23: {=Common_InputFunctions.Utility_DisplayArrayInTable(SourceData_PastureBeef.SourceData_PastureBeef_Liveweight_Data(), Table_SourceData_PastureBeef_Liveweight[[#Headers],[State]], 0)} -> South Australia | E23: {=Common_InputFunctions.Utility_DisplayArrayInTable(SourceData_PastureBeef.SourceData_PastureBeef_Liveweight_Data(), Table_SourceData_PastureBeef_Liveweight[[#Headers],[State]], 0)} -> n/a | F23: {=Common_InputFunctions.Utility_DisplayArrayInTable(SourceData_PastureBeef.SourceData_PastureBeef_Liveweight_Data(), Table_SourceData_PastureBeef_Liveweight[[#Headers],[State]], 0)} -> Spring | G23: {=Common_InputFunctions.Utility_DisplayArrayInTable(SourceData_PastureBeef.SourceData_PastureBeef_Liveweight_Data(), Table_SourceData_PastureBeef_Liveweight[[#Headers],[State]], 0)} -> 250 | H23: {=Common_InputFunctions.Utility_DisplayArrayInTable(SourceData_PastureBeef.SourceData_PastureBeef_Liveweight_Data(), Table_SourceData_PastureBeef_Liveweight[[#Headers],[State]], 0)} -> 800 | I23: {=Common_InputFunctions.Utility_DisplayArrayInTable(SourceData_PastureBeef.SourceData_PastureBeef_Liveweight_Data(), Table_SourceData_PastureBeef_Liveweight[[#Headers],[State]], 0)} -> 220 | J23: {=Common_InputFunctions.Utility_DisplayArrayInTable(SourceData_PastureBeef.SourceData_PastureBeef_Liveweight_Data(), Table_SourceData_PastureBeef_Liveweight[[#Headers],[State]], 0)} -> 400 | K23: {=Common_InputFunctions.Utility_DisplayArrayInTable(SourceData_PastureBeef.SourceData_PastureBeef_Liveweight_Data(), Table_SourceData_PastureBeef_Liveweight[[#Headers],[State]], 0)} -> 500 | ... M23: {=Common_InputFunctions.Utility_DisplayArrayInTable(SourceData_PastureBeef.SourceData_PastureBeef_Liveweight_Data(), Table_SourceData_PastureBeef_Liveweight[[#Headers],[State]], 0)} -> 420 | S23: n/a
D24: {=Common_InputFunctions.Utility_DisplayArrayInTable(SourceData_PastureBeef.SourceData_PastureBeef_Liveweight_Data(), Table_SourceData_PastureBeef_Liveweight[[#Headers],[State]], 0)} -> South Australia | E24: {=Common_InputFunctions.Utility_DisplayArrayInTable(SourceData_PastureBeef.SourceData_PastureBeef_Liveweight_Data(), Table_SourceData_PastureBeef_Liveweight[[#Headers],[State]], 0)} -> n/a | F24: {=Common_InputFunctions.Utility_DisplayArrayInTable(SourceData_PastureBeef.SourceData_PastureBeef_Liveweight_Data(), Table_SourceData_PastureBeef_Liveweight[[#Headers],[State]], 0)} -> Summer | G24: {=Common_InputFunctions.Utility_DisplayArrayInTable(SourceData_PastureBeef.SourceData_PastureBeef_Liveweight_Data(), Table_SourceData_PastureBeef_Liveweight[[#Headers],[State]], 0)} -> 320 | H24: {=Common_InputFunctions.Utility_DisplayArrayInTable(SourceData_PastureBeef.SourceData_PastureBeef_Liveweight_Data(), Table_SourceData_PastureBeef_Liveweight[[#Headers],[State]], 0)} -> 800 | I24: {=Common_InputFunctions.Utility_DisplayArrayInTable(SourceData_PastureBeef.SourceData_PastureBeef_Liveweight_Data(), Table_SourceData_PastureBeef_Liveweight[[#Headers],[State]], 0)} -> 280 | J24: {=Common_InputFunctions.Utility_DisplayArrayInTable(SourceData_PastureBeef.SourceData_PastureBeef_Liveweight_Data(), Table_SourceData_PastureBeef_Liveweight[[#Headers],[State]], 0)} -> 420 | K24: {=Common_InputFunctions.Utility_DisplayArrayInTable(SourceData_PastureBeef.SourceData_PastureBeef_Liveweight_Data(), Table_SourceData_PastureBeef_Liveweight[[#Headers],[State]], 0)} -> 500 | ... M24: {=Common_InputFunctions.Utility_DisplayArrayInTable(SourceData_PastureBeef.SourceData_PastureBeef_Liveweight_Data(), Table_SourceData_PastureBeef_Liveweight[[#Headers],[State]], 0)} -> 420
D25: {=Common_InputFunctions.Utility_DisplayArrayInTable(SourceData_PastureBeef.SourceData_PastureBeef_Liveweight_Data(), Table_SourceData_PastureBeef_Liveweight[[#Headers],[State]], 0)} -> South Australia | E25: {=Common_InputFunctions.Utility_DisplayArrayInTable(SourceData_PastureBeef.SourceData_PastureBeef_Liveweight_Data(), Table_SourceData_PastureBeef_Liveweight[[#Headers],[State]], 0)} -> n/a | F25: {=Common_InputFunctions.Utility_DisplayArrayInTable(SourceData_PastureBeef.SourceData_PastureBeef_Liveweight_Data(), Table_SourceData_PastureBeef_Liveweight[[#Headers],[State]], 0)} -> Autumn | G25: {=Common_InputFunctions.Utility_DisplayArrayInTable(SourceData_PastureBeef.SourceData_PastureBeef_Liveweight_Data(), Table_SourceData_PastureBeef_Liveweight[[#Headers],[State]], 0)} -> 80 | H25: {=Common_InputFunctions.Utility_DisplayArrayInTable(SourceData_PastureBeef.SourceData_PastureBeef_Liveweight_Data(), Table_SourceData_PastureBeef_Liveweight[[#Headers],[State]], 0)} -> 700 | I25: {=Common_InputFunctions.Utility_DisplayArrayInTable(SourceData_PastureBeef.SourceData_PastureBeef_Liveweight_Data(), Table_SourceData_PastureBeef_Liveweight[[#Headers],[State]], 0)} -> 70 | J25: {=Common_InputFunctions.Utility_DisplayArrayInTable(SourceData_PastureBeef.SourceData_PastureBeef_Liveweight_Data(), Table_SourceData_PastureBeef_Liveweight[[#Headers],[State]], 0)} -> 300 | K25: {=Common_InputFunctions.Utility_DisplayArrayInTable(SourceData_PastureBeef.SourceData_PastureBeef_Liveweight_Data(), Table_SourceData_PastureBeef_Liveweight[[#Headers],[State]], 0)} -> 450 | ... M25: {=Common_InputFunctions.Utility_DisplayArrayInTable(SourceData_PastureBeef.SourceData_PastureBeef_Liveweight_Data(), Table_SourceData_PastureBeef_Liveweight[[#Headers],[State]], 0)} -> 400 | S25: Table_SourceData_PastureBeef_Region_ACT
D26: {=Common_InputFunctions.Utility_DisplayArrayInTable(SourceData_PastureBeef.SourceData_PastureBeef_Liveweight_Data(), Table_SourceData_PastureBeef_Liveweight[[#Headers],[State]], 0)} -> South Australia | E26: {=Common_InputFunctions.Utility_DisplayArrayInTable(SourceData_PastureBeef.SourceData_PastureBeef_Liveweight_Data(), Table_SourceData_PastureBeef_Liveweight[[#Headers],[State]], 0)} -> n/a | F26: {=Common_InputFunctions.Utility_DisplayArrayInTable(SourceData_PastureBeef.SourceData_PastureBeef_Liveweight_Data(), Table_SourceData_PastureBeef_Liveweight[[#Headers],[State]], 0)} -> Winter | G26: {=Common_InputFunctions.Utility_DisplayArrayInTable(SourceData_PastureBeef.SourceData_PastureBeef_Liveweight_Data(), Table_SourceData_PastureBeef_Liveweight[[#Headers],[State]], 0)} -> 160 | H26: {=Common_InputFunctions.Utility_DisplayArrayInTable(SourceData_PastureBeef.SourceData_PastureBeef_Liveweight_Data(), Table_SourceData_PastureBeef_Liveweight[[#Headers],[State]], 0)} -> 700 | I26: {=Common_InputFunctions.Utility_DisplayArrayInTable(SourceData_PastureBeef.SourceData_PastureBeef_Liveweight_Data(), Table_SourceData_PastureBeef_Liveweight[[#Headers],[State]], 0)} -> 140 | J26: {=Common_InputFunctions.Utility_DisplayArrayInTable(SourceData_PastureBeef.SourceData_PastureBeef_Liveweight_Data(), Table_SourceData_PastureBeef_Liveweight[[#Headers],[State]], 0)} -> 350 | K26: {=Common_InputFunctions.Utility_DisplayArrayInTable(SourceData_PastureBeef.SourceData_PastureBeef_Liveweight_Data(), Table_SourceData_PastureBeef_Liveweight[[#Headers],[State]], 0)} -> 450 | ... M26: {=Common_InputFunctions.Utility_DisplayArrayInTable(SourceData_PastureBeef.SourceData_PastureBeef_Liveweight_Data(), Table_SourceData_PastureBeef_Liveweight[[#Headers],[State]], 0)} -> 400
D27: {=Common_InputFunctions.Utility_DisplayArrayInTable(SourceData_PastureBeef.SourceData_PastureBeef_Liveweight_Data(), Table_SourceData_PastureBeef_Liveweight[[#Headers],[State]], 0)} -> Tasmania | E27: {=Common_InputFunctions.Utility_DisplayArrayInTable(SourceData_PastureBeef.SourceData_PastureBeef_Liveweight_Data(), Table_SourceData_PastureBeef_Liveweight[[#Headers],[State]], 0)} -> n/a | F27: {=Common_InputFunctions.Utility_DisplayArrayInTable(SourceData_PastureBeef.SourceData_PastureBeef_Liveweight_Data(), Table_SourceData_PastureBeef_Liveweight[[#Headers],[State]], 0)} -> Spring | G27: {=Common_InputFunctions.Utility_DisplayArrayInTable(SourceData_PastureBeef.SourceData_PastureBeef_Liveweight_Data(), Table_SourceData_PastureBeef_Liveweight[[#Headers],[State]], 0)} -> 105 | H27: {=Common_InputFunctions.Utility_DisplayArrayInTable(SourceData_PastureBeef.SourceData_PastureBeef_Liveweight_Data(), Table_SourceData_PastureBeef_Liveweight[[#Headers],[State]], 0)} -> 700 | I27: {=Common_InputFunctions.Utility_DisplayArrayInTable(SourceData_PastureBeef.SourceData_PastureBeef_Liveweight_Data(), Table_SourceData_PastureBeef_Liveweight[[#Headers],[State]], 0)} -> 85 | J27: {=Common_InputFunctions.Utility_DisplayArrayInTable(SourceData_PastureBeef.SourceData_PastureBeef_Liveweight_Data(), Table_SourceData_PastureBeef_Liveweight[[#Headers],[State]], 0)} -> 300 | K27: {=Common_InputFunctions.Utility_DisplayArrayInTable(SourceData_PastureBeef.SourceData_PastureBeef_Liveweight_Data(), Table_SourceData_PastureBeef_Liveweight[[#Headers],[State]], 0)} -> 490 | ... M27: {=Common_InputFunctions.Utility_DisplayArrayInTable(SourceData_PastureBeef.SourceData_PastureBeef_Liveweight_Data(), Table_SourceData_PastureBeef_Liveweight[[#Headers],[State]], 0)} -> 480 | S27: Region
