Workbook
Name Common_Equations.Common_ConvertCH4ToCO2e: _xlfn.LAMBDA(_xlpm.E_CH4,_xlpm.GWP_CH4, _xlpm.E_CH4 * _xlpm.GWP_CH4)
Name Common_Equations.Common_ConvertCH4ToCO2e_Arguments: _xlfn.LAMBDA(_xlfn.MAKEARRAY(2, 2, _xlfn.LAMBDA(_xlpm.r,_xlpm.c, INDEX({"ECH4","Methane emissions (t CH4)";"GWPCH4","Global warming potential for methane (t CO2-e / t CH4)"}, _xlpm.r, _xlpm.c))))
Name Common_Equations.Common_ConvertCH4ToCO2e_LatexEquation: _xlfn.LAMBDA("CO2_e = E_{CH4} \times GWP_{CH4}")
Name Common_Equations.Common_ConvertCH4ToCO2e_NIRReference: _xlfn.LAMBDA("")
Name Common_Equations.Common_ConvertCH4ToCO2e_Title: _xlfn.LAMBDA("Convert methane emissions to carbon dioxide equivalent emissions")
Name Common_Equations.Common_ConvertCH4ToCO2e_Unit: _xlfn.LAMBDA("t CO2e")
Name Common_Equations.Common_ConvertCH4ToCO2e_Variable: _xlfn.LAMBDA("ECH4 CO2e")
Name Common_Equations.Common_ConvertN2OToCO2e: _xlfn.LAMBDA(_xlpm.E_N2O,_xlpm.GWP_N2O, _xlpm.E_N2O * _xlpm.GWP_N2O)
Name Common_Equations.Common_ConvertN2OToCO2e_LatexEquation: _xlfn.LAMBDA("CO2_e = E_{N2O} \times GWP_{N2O}")
Name Common_Equations.Common_ConvertN2OToCO2e_NIRReference: _xlfn.LAMBDA("")
Name Common_Equations.Common_ConvertN2OToCO2e_Title: _xlfn.LAMBDA("Convert nitrous oxide emissions to carbon dioxide equivalent emissions")
Name Common_Equations.Common_ConvertN2OToCO2e_Unit: _xlfn.LAMBDA("t CO2e")
Name Common_Equations.Common_ConvertN2OToCO2e_Variable: _xlfn.LAMBDA("EN2O CO2e")
Name Common_InputFunctions.Utility_ConvertStateCommonNameToAbbreviation: _xlfn.LAMBDA(_xlpm.StateCommonName,_xlpm.StateCommonNameArray,_xlpm.StateAbbreviationArray, _xlfn.XLOOKUP(_xlpm.StateCommonName, _xlpm.StateCommonNameArray, _xlpm.StateAbbreviationArray, ""))
Name Common_InputFunctions.Utility_DisplayArguments_1_2: _xlfn.LAMBDA(_xlpm.ArgumentsArray, _xlfn.CHOOSECOLS(_xlpm.ArgumentsArray, 1, 2))
Name Common_InputFunctions.Utility_DisplayArguments_3_4: _xlfn.LAMBDA(_xlpm.ArgumentsArray, _xlfn.CHOOSECOLS(_xlpm.ArgumentsArray, 3, 4))
Name Common_InputFunctions.Utility_DisplayFunctionName: _xlfn.LAMBDA(_xlpm.Function, _xlfn.TEXTBEFORE(_xlfn.FORMULATEXT(_xlpm.Function), "("))
Name Common_InputFunctions.Utility_GetArrayTableColumnStartNumber: _xlfn.LAMBDA(_xlpm.TableHeaderCell, COLUMN(_xlpm.TableHeaderCell))
Name Common_InputFunctions.Utility_GetArrayTableRowStartNumber: _xlfn.LAMBDA(_xlpm.TableheaderCell,_xlpm.RowsBetweenHeaderandArray, ROW(_xlpm.TableheaderCell) + _xlpm.RowsBetweenHeaderandArray - 1)
Name Common_InputFunctions.Utility_LookupValueInTable: _xlfn.LAMBDA(_xlpm.LookupValue,_xlpm.LookupArray,_xlpm.ReturnArray, _xlfn.XLOOKUP(_xlpm.LookupValue, _xlpm.LookupArray, _xlpm.ReturnArray, ""))
Name Common_InputFunctions.Utility_SourceHyperlink: _xlfn.LAMBDA(_xlpm.TargetCell, _xlfn.LET(_xlpm.sh, _xlfn.TEXTAFTER(CELL("filename", _xlpm.TargetCell), "]"), _xlpm.addr, CELL("address", _xlpm.TargetCell), "#'" & _xlpm.sh & "'!" & _xlpm.addr))
Name Common_SourceData.Common_SourceData_AustralianStatesTerritories_Source: _xlfn.LAMBDA("")
Name Common_SourceData.Common_SourceData_AustralianStatesTerritories_Title: _xlfn.LAMBDA("Australian states and territories")
Name Common_SourceData.Common_SourceData_AustralianStatesTerritories_Unit: _xlfn.LAMBDA("")
Name Common_SourceData.Common_SourceData_AustralianStatesTerritories_Variable: _xlfn.LAMBDA("")
Name Common_SourceData.Common_SourceData_ClimateZones_Source: _xlfn.LAMBDA("VEERG 2026: Table 1.3: Climate and Rainfall zone classifications and definitions")
Name Common_SourceData.Common_SourceData_ClimateZones_Title: _xlfn.LAMBDA("VEERG Australian climate zones")
Name Common_SourceData.Common_SourceData_ClimateZones_Unit: _xlfn.LAMBDA("")
Name Common_SourceData.Common_SourceData_ClimateZones_Variable: _xlfn.LAMBDA("")
Name Common_SourceData.Common_SourceData_ConvertGasElementalToMolecular_Source: _xlfn.LAMBDA("XXXXXXX")
Name Common_SourceData.Common_SourceData_ConvertGasElementalToMolecular_Title: _xlfn.LAMBDA("Factor to convert elemental mass of gas to molecular mass")
Name Common_SourceData.Common_SourceData_ConvertGasElementalToMolecular_Unit: _xlfn.LAMBDA("factor")
Name Common_SourceData.Common_SourceData_ConvertGasElementalToMolecular_Variable: _xlfn.LAMBDA("Cg")
Name Common_SourceData.Common_SourceData_ConvertN2oElementalToMolecularCg_Data: _xlfn.LAMBDA(44 / 28)
Name Common_SourceData.Common_SourceData_ConvertN2oElementalToMolecularCg_Source: _xlfn.LAMBDA("National Inventory Report 2023 Volume 1")
Name Common_SourceData.Common_SourceData_ConvertN2oElementalToMolecularCg_Title: _xlfn.LAMBDA("Factor to convert elemental mass of N2O to molecular mass")
Name Common_SourceData.Common_SourceData_ConvertN2oElementalToMolecularCg_Unit: _xlfn.LAMBDA("factor")
Name Common_SourceData.Common_SourceData_ConvertN2oElementalToMolecularCg_Variable: _xlfn.LAMBDA("CgN2O")
Name Common_SourceData.Common_SourceData_DataScores_Scope3_Source: _xlfn.LAMBDA("VEERG 2026: XXXXXXXX")
Name Common_SourceData.Common_SourceData_DataScores_Scope3_Title: _xlfn.LAMBDA("Australian data scores for scope 3")
Name Common_SourceData.Common_SourceData_DataScores_Scope3_Unit: _xlfn.LAMBDA("")
Name Common_SourceData.Common_SourceData_DataScores_Scope3_Variable: _xlfn.LAMBDA("")
Name Common_SourceData.Common_SourceData_DataScores_Scope3_Variation: _xlfn.LAMBDA("")
Name Common_SourceData.Common_SourceData_DensityOfMethane_Data: _xlfn.LAMBDA(0.6784)
Name Common_SourceData.Common_SourceData_DensityOfMethane_Source: _xlfn.LAMBDA("National Inventory Report 2023 Volume 1: Equations 3.B.1a_2, 3.B.1c_2, 3.B.3_1, 3.B.4g_2")
Name Common_SourceData.Common_SourceData_DensityOfMethane_Title: _xlfn.LAMBDA("p = density of methane")
Name Common_SourceData.Common_SourceData_DensityOfMethane_Unit: _xlfn.LAMBDA("kg/m3")
Name Common_SourceData.Common_SourceData_EFleach_Data: _xlfn.LAMBDA(_xlfn.MAKEARRAY(1, 2, _xlfn.LAMBDA(_xlpm.r,_xlpm.c, INDEX({"EFleach",0.011}, _xlpm.r, _xlpm.c))))
Name Common_SourceData.Common_SourceData_EFleach_NIRReference: _xlfn.LAMBDA("National Inventory Report Volume 1: Equation 3.D.B_10")
Name Common_SourceData.Common_SourceData_EFleach_Source: _xlfn.LAMBDA("VEERG 2026:5.5.2.3 Constant Parameters")
Name Common_SourceData.Common_SourceData_EFleach_Title: _xlfn.LAMBDA("Emission factor for nitrogen leaching and runoff")
Name Common_SourceData.Common_SourceData_EFleach_Unit: _xlfn.LAMBDA("(kg N2O-N / kg N")
Name Common_SourceData.Common_SourceData_EFleach_Variation: _xlfn.LAMBDA((""))
Name Common_SourceData.Common_SourceData_EFN2O_NIRReference: _xlfn.LAMBDA("")
Name Common_SourceData.Common_SourceData_EFN2O_Source: _xlfn.LAMBDA("VEERG 2026: Table A.2.2.1")
Name Common_SourceData.Common_SourceData_EFN2O_Title: _xlfn.LAMBDA("Nitrous oxide emission factors for inorganic fertiliser application")
Name Common_SourceData.Common_SourceData_EFN2O_Unit: _xlfn.LAMBDA("(kg N2O-N / kg N")
Name Common_SourceData.Common_SourceData_EFOrganicFertiliserAndCropResidues_Data: _xlfn.LAMBDA(_xlfn.MAKEARRAY(3, 2, _xlfn.LAMBDA(_xlpm.r,_xlpm.c, INDEX({"Climate zone","EFNi & EFN2O";"Wet climate zone",0.006;"Dry climate zone",0.005}, _xlpm.r, _xlpm.c))))
Name Common_SourceData.Common_SourceData_EFOrganicFertiliserAndCropResidues_NIRReference: _xlfn.LAMBDA("")
Name Common_SourceData.Common_SourceData_EFOrganicFertiliserAndCropResidues_Source: _xlfn.LAMBDA("VEERG 2026: Table A.2.1.4")

Sheet Home
A1: Home

Sheet Overview
A1: #VALUE! | C1: 3.5 Enteric Methane: Swine: Overview
A3: =HYPERLINK("#'Home'!A1", "Home") -> Home
A4: =HYPERLINK("#'Overview'!A1", "Overview") -> Overview
A5: =HYPERLINK("#'Results'!A1", "Results") -> Results | D5: 💡 Below is a diagram that maps the equations used to calculate emissions, and how they interact with each other.
D6: Click on a box to go to the corresponding calculation.
A7: INPUTS
A8: =HYPERLINK("#'Input - Site'!A1", "Site") -> Site
A9: =HYPERLINK("#'Input - Swine'!A1", "Swine") -> Swine
A11: CALCULATIONS
A12: =HYPERLINK("#'3.5.1.1-2 Enteric Methane'!A1", "3.5.1.1-2 Enteric Methane") -> 3.5.1.1-2 Enteric Methane
A14: APPENDICES
A15: =HYPERLINK("#'Constants - Swine'!A1", "Constants - Swine") -> Constants - Swine
A16: =HYPERLINK("#'Constants - Livestock'!A1", "Constants - Livestock") -> Constants - Livestock
A17: =HYPERLINK("#'Constants - Common'!A1", "Constants - Common") -> Constants - Common
A18: =HYPERLINK("#'Acknowledgements'!A1", "Acknowledgements") -> Acknowledgements

Sheet Results
A1: #VALUE! | C1: 3.5 Enteric Methane: Swine: Results
A3: =HYPERLINK("#'Home'!A1", "Home") -> Home
A4: =HYPERLINK("#'Overview'!A1", "Overview") -> Overview | D4: Emissions breakdown
A5: =HYPERLINK("#'Results'!A1", "Results") -> Results
D6: Scope 1 source | E6: GHG emissions method 1 | F6: GHG emissions method 2 | G6: GHG Unit | H6: CO2-e emissions method 1 | I6: CO2-e emissions method 2 | J6: CO2-e unit
A7: INPUTS | D7: 3.5.1.1-2 Enteric methane | E7: ='3.5.1.1-2 Enteric Methane'!E58 -> 0.78573884 | F7: ='3.5.1.1-2 Enteric Methane'!N58 -> 0.78573884 | G7: t CH4 | H7: ='3.5.1.1-2 Enteric Methane'!E63 -> 22.000688 | I7: ='3.5.1.1-2 Enteric Methane'!N63 -> 22.000688 | J7: t CO2e
A8: =HYPERLINK("#'Input - Site'!A1", "Site") -> Site | D8: Total | H8: =SUM(H7:H7) -> 22.000688 | I8: =SUM(I7:I7) -> 22.000688 | J8: t CO2e
A9: =HYPERLINK("#'Input - Swine'!A1", "Swine") -> Swine
A11: CALCULATIONS
A12: =HYPERLINK("#'3.5.1.1-2 Enteric Methane'!A1", "3.5.1.1-2 Enteric Methane") -> 3.5.1.1-2 Enteric Methane
A14: APPENDICES
A15: =HYPERLINK("#'Constants - Swine'!A1", "Constants - Swine") -> Constants - Swine
A16: =HYPERLINK("#'Constants - Livestock'!A1", "Constants - Livestock") -> Constants - Livestock
A17: =HYPERLINK("#'Constants - Common'!A1", "Constants - Common") -> Constants - Common
A18: =HYPERLINK("#'Acknowledgements'!A1", "Acknowledgements") -> Acknowledgements

Sheet Input - Site
A1: #VALUE! | C1: Input - Site
A3: =HYPERLINK("#'Home'!A1", "Home") -> Home
A4: =HYPERLINK("#'Overview'!A1", "Overview") -> Overview
A5: =HYPERLINK("#'Results'!A1", "Results") -> Results | D5: Your business
A7: INPUTS | D7: Farm name | E7: Test Farms
A8: =HYPERLINK("#'Input - Site'!A1", "Site") -> Site | D8: Reporting entity name | E8: Test Farms Pty Ltd
A9: =HYPERLINK("#'Input - Swine'!A1", "Swine") -> Swine
D10: 💡An 'Emissions accounting period' is a 12 month period where the business can report on the emissions, and is typically the same as the business' financial accounting period.
A11: CALCULATIONS
A12: =HYPERLINK("#'3.5.1.1-2 Enteric Methane'!A1", "3.5.1.1-2 Enteric Methane") -> 3.5.1.1-2 Enteric Methane | D12: Emissions calculation period start date | E12: 45292 | F12: ← DD/MM/YYYY or DD Month YYYY
D13: Emissions calculation period end date | E13: =DATE(YEAR(E12)+1,MONTH(E12),DAY(E12))-1 -> 45657 | F13: ← Automatically calculated, 12 months after start date
A14: APPENDICES
A15: =HYPERLINK("#'Constants - Swine'!A1", "Constants - Swine") -> Constants - Swine
A16: =HYPERLINK("#'Constants - Livestock'!A1", "Constants - Livestock") -> Constants - Livestock
A17: =HYPERLINK("#'Constants - Common'!A1", "Constants - Common") -> Constants - Common
A18: =HYPERLINK("#'Acknowledgements'!A1", "Acknowledgements") -> Acknowledgements

Sheet Input - Swine
A1: #VALUE! | C1: Input -Swine
A3: =HYPERLINK("#'Home'!A1", "Home") -> Home
A4: =HYPERLINK("#'Overview'!A1", "Overview") -> Overview
A5: =HYPERLINK("#'Results'!A1", "Results") -> Results | E5: Boars | F5: Sows | G5: Gilts | H5: Others
D6: ="Average duration of stay between " & TEXT('Input - Site'!$E$12, "dd mmm yy") & " and " & TEXT('Input - Site'!$E$13, "dd mmm yy") -> Average duration of stay between 01 Jan 24 and 31 Dec 24 | E6: 365 | F6: 365 | G6: 365 | H6: 365 | I6: Days
A7: INPUTS | D7: ="Average number of head between " & TEXT('Input - Site'!$E$12, "dd mmm yy") & " and " & TEXT('Input - Site'!$E$13, "dd mmm yy") -> Average number of head between 01 Jan 24 and 31 Dec 24 | E7: 100 | F7: 100 | G7: 100 | H7: 100 | I7: Head
A8: =HYPERLINK("#'Input - Site'!A1", "Site") -> Site
A9: =HYPERLINK("#'Input - Swine'!A1", "Swine") -> Swine | D9: Feed intake
A11: CALCULATIONS | D11: Method 1 default values (Do not edit) | E11: Boars | F11: Sows | G11: Gilts | H11: Others
A12: =HYPERLINK("#'3.5.1.1-2 Enteric Methane'!A1", "3.5.1.1-2 Enteric Methane") -> 3.5.1.1-2 Enteric Methane | D12: Volatile solids produced per head per day | E12: {=Common_InputFunctions.Utility_LookupValueInTableNumber(E11, Table_SourceData_Swine_FeedIntake[Class],Table_SourceData_Swine_FeedIntake[Ij])} -> 2.62 | F12: {=Common_InputFunctions.Utility_LookupValueInTableNumber(F11, Table_SourceData_Swine_FeedIntake[Class],Table_SourceData_Swine_FeedIntake[Ij])} -> 2.3 | G12: {=Common_InputFunctions.Utility_LookupValueInTableNumber(G11, Table_SourceData_Swine_FeedIntake[Class],Table_SourceData_Swine_FeedIntake[Ij])} -> 2.5 | H12: {=Common_InputFunctions.Utility_LookupValueInTableNumber(H11, Table_SourceData_Swine_FeedIntake[Class],Table_SourceData_Swine_FeedIntake[Ij])} -> 1.71 | I12: kg/head/day
A14: APPENDICES | D14: Method 2 custom values (Edit if known) | E14: Boars | F14: Sows | G14: Gilts | H14: Others
A15: =HYPERLINK("#'Constants - Swine'!A1", "Constants - Swine") -> Constants - Swine | D15: Volatile solids produced per head per day | E15: {=Common_InputFunctions.Utility_LookupValueInTableNumber(E14, Table_SourceData_Swine_FeedIntake[Class],Table_SourceData_Swine_FeedIntake[Ij])} -> 2.62 | F15: {=Common_InputFunctions.Utility_LookupValueInTableNumber(F14, Table_SourceData_Swine_FeedIntake[Class],Table_SourceData_Swine_FeedIntake[Ij])} -> 2.3 | G15: {=Common_InputFunctions.Utility_LookupValueInTableNumber(G14, Table_SourceData_Swine_FeedIntake[Class],Table_SourceData_Swine_FeedIntake[Ij])} -> 2.5 | H15: {=Common_InputFunctions.Utility_LookupValueInTableNumber(H14, Table_SourceData_Swine_FeedIntake[Class],Table_SourceData_Swine_FeedIntake[Ij])} -> 1.71 | I15: kg/head/day
A16: =HYPERLINK("#'Constants - Livestock'!A1", "Constants - Livestock") -> Constants - Livestock
A17: =HYPERLINK("#'Constants - Common'!A1", "Constants - Common") -> Constants - Common
A18: =HYPERLINK("#'Acknowledgements'!A1", "Acknowledgements") -> Acknowledgements
A46: =HYPERLINK("#A1", "▲ Back to top") -> ▲ Back to top
A92: =HYPERLINK("#A1", "▲ Back to top") -> ▲ Back to top

Sheet 3.5.1.1-2 Enteric Methane
A1: #VALUE! | C1: 3.5.1.1-2 Enteric methane
A3: =HYPERLINK("#'Home'!A1", "Home") -> Home | D3: Method 1 | M3: Method 2
A4: =HYPERLINK("#'Overview'!A1", "Overview") -> Overview
A5: =HYPERLINK("#'Results'!A1", "Results") -> Results | D5: {=EntericMethane_Swine_Equations.VEERG_3_5_1_1__2_DailyEntericMethaneProduction_Title()} -> Total daily production of enteric methane of swine
D6: {=EntericMethane_Swine_Equations.VEERG_3_5_1_1__2_DailyEntericMethaneProduction_Source()} -> VEERG 2026: 3.5.1.1, Equation (2)
A7: INPUTS | D7: Function name | E7: {=Common_InputFunctions.Utility_DisplayFunctionName(D26)} -> =EntericMethane_Swine_Equations.VEERG_3_5_1_1__2_DailyEntericMethaneProduction
A8: =HYPERLINK("#'Input - Site'!A1", "Site") -> Site
A9: =HYPERLINK("#'Input - Swine'!A1", "Swine") -> Swine
D10: Variable | E10: {=EntericMethane_Swine_Equations.VEERG_3_5_1_1__2_DailyEntericMethaneProduction_Variable()} -> M_j
A11: CALCULATIONS | D11: Unit | E11: {=EntericMethane_Swine_Equations.VEERG_3_5_1_1__2_DailyEntericMethaneProduction_Unit()} -> kg CH4/head/day
A12: =HYPERLINK("#'3.5.1.1-2 Enteric Methane'!A1", "3.5.1.1-2 Enteric Methane") -> 3.5.1.1-2 Enteric Methane
D13: {=_xlfn.CHOOSECOLS(EntericMethane_Swine_Equations.VEERG_3_5_1_1__2_DailyEntericMethaneProduction_Arguments(),1,2)} -> I_j | E13: daily feed ingested by each swine class | G13: {=_xlfn.CHOOSECOLS(EntericMethane_Swine_Equations.VEERG_3_5_1_1__2_DailyEntericMethaneProduction_Arguments(),3,4)} -> kg/head/day | H13: Input | I13: {=HYPERLINK(Common_InputFunctions.Utility_SourceHyperlink($D$18), $D$18)} -> M1_Table_I_j
A14: APPENDICES | D14: 18.6 | E14: gross energy (GE) content of feed | G14: MJ GE/kg feed | H14: Constant | I14: =D14 -> 18.6
A15: =HYPERLINK("#'Constants - Swine'!A1", "Constants - Swine") -> Constants - Swine | D15: 0.007 | E15: fraction of GE intake converted to methane by swine | G15: fraction | H15: Constant | I15: =D15 -> 0.007
A16: =HYPERLINK("#'Constants - Livestock'!A1", "Constants - Livestock") -> Constants - Livestock | D16: F | E16: megajoules per kilogram of methane | G16: MJ/kg CH4 | H16: Constant | I16: ='Constants - Swine'!$E$122 -> 55.22
A17: =HYPERLINK("#'Constants - Common'!A1", "Constants - Common") -> Constants - Common
A18: =HYPERLINK("#'Acknowledgements'!A1", "Acknowledgements") -> Acknowledgements | D18: M1_Table_I_j | M18: M1_Table_I_j
D19: Feed intake (Method 1) | M19: Feed intake (Method 1)
D20: Boars | E20: Sows | F20: Gilts | G20: Others | M20: Boars | N20: Sows | O20: Gilts | P20: Others
D21: ='Input - Swine'!E12 -> 2.62 | E21: ='Input - Swine'!F12 -> 2.3 | F21: ='Input - Swine'!G12 -> 2.5 | G21: ='Input - Swine'!H12 -> 1.71 | H21: =G13 -> kg/head/day | M21: ='Input - Swine'!E15 -> 2.62 | N21: ='Input - Swine'!F15 -> 2.3 | O21: ='Input - Swine'!G15 -> 2.5 | P21: ='Input - Swine'!H15 -> 1.71 | Q21: =G13 -> kg/head/day
D23: M1_Table_M_j | M23: M1_Table_M_j
D24: Daily enteric methane production (Method 1) | M24: Daily enteric methane production (Method 1)
D25: Boars | E25: Sows | F25: Gilts | G25: Others | M25: Boars | N25: Sows | O25: Gilts | P25: Others
D26: {=EntericMethane_Swine_Equations.VEERG_3_5_1_1__2_DailyEntericMethaneProduction(D21,$I$16)} -> 0.0061775444 | E26: {=EntericMethane_Swine_Equations.VEERG_3_5_1_1__2_DailyEntericMethaneProduction(E21,$I$16)} -> 0.0054230351 | F26: {=EntericMethane_Swine_Equations.VEERG_3_5_1_1__2_DailyEntericMethaneProduction(F21,$I$16)} -> 0.0058946034 | G26: {=EntericMethane_Swine_Equations.VEERG_3_5_1_1__2_DailyEntericMethaneProduction(G21,$I$16)} -> 0.0040319087 | H26: =$E$11 -> kg CH4/head/day | M26: {=EntericMethane_Swine_Equations.VEERG_3_5_1_1__2_DailyEntericMethaneProduction(M21,$I$16)} -> 0.0061775444 | N26: {=EntericMethane_Swine_Equations.VEERG_3_5_1_1__2_DailyEntericMethaneProduction(N21,$I$16)} -> 0.0054230351 | O26: {=EntericMethane_Swine_Equations.VEERG_3_5_1_1__2_DailyEntericMethaneProduction(O21,$I$16)} -> 0.0058946034 | P26: {=EntericMethane_Swine_Equations.VEERG_3_5_1_1__2_DailyEntericMethaneProduction(P21,$I$16)} -> 0.0040319087 | Q26: =$E$11 -> kg CH4/head/day
D30: {=EntericMethane_Swine_Equations.VEERG_3_5_1_1__1_TotalAnnualMethaneFromEntericFermentation_Title()} -> Total annual methane production from enteric fermentation in swine
D31: {=EntericMethane_Swine_Equations.VEERG_3_5_1_1__1_TotalAnnualMethaneFromEntericFermentation_Source()} -> VEERG 2026: 3.5.1.1, Equation (1)
D32: Function name | E32: {=Common_InputFunctions.Utility_DisplayFunctionName(D56)} -> =EntericMethane_Swine_Equations.VEERG_3_5_1_1__1_TotalAnnualMethaneFromEntericFermentation
D36: Variable | E36: {=EntericMethane_Swine_Equations.VEERG_3_5_1_1__1_TotalAnnualMethaneFromEntericFermentation_Variable()} -> E_enteric
D37: Unit | E37: {=EntericMethane_Swine_Equations.VEERG_3_5_1_1__1_TotalAnnualMethaneFromEntericFermentation_Unit()} -> t CH4
D39: {=_xlfn.CHOOSECOLS(EntericMethane_Swine_Equations.VEERG_3_5_1_1__1_TotalAnnualMethaneFromEntericFermentation_Arguments(), 1, 2)} -> N_j | E39: numbers of swine of each class | G39: {=_xlfn.CHOOSECOLS(EntericMethane_Swine_Equations.VEERG_3_5_1_1__1_TotalAnnualMethaneFromEntericFermentation_Arguments(), 3,4)} -> head | H39: Input | I39: {=HYPERLINK(Common_InputFunctions.Utility_SourceHyperlink($D$48), $D$48)} -> Table_N_j
D40: M_j | E40: methane production | G40: kg CH4/head/day | H40: Calculated from 3.5.1.1, (2) | I40: {=HYPERLINK(Common_InputFunctions.Utility_SourceHyperlink($D$23), $D$23)} -> M1_Table_M_j
D41: D_j | E41: the average number of days on farm for each swine class | G41: days | H41: Input | I41: {=HYPERLINK(Common_InputFunctions.Utility_SourceHyperlink($D$43), $D$43)} -> Table_D_j
D43: Table_D_j
D44: Duration of stay of each class of swine
D45: Boars | E45: Sows | F45: Gilts | G45: Others
D46: ='Input - Swine'!E6 -> 365 | E46: ='Input - Swine'!F6 -> 365 | F46: ='Input - Swine'!G6 -> 365 | G46: ='Input - Swine'!H6 -> 365 | H46: =G39 -> head
D48: Table_N_j
D49: Number of head for each swine class
D50: Boars | E50: Sows | F50: Gilts | G50: Others
D51: ='Input - Swine'!$E$7 -> 100 | E51: ='Input - Swine'!$F$7 -> 100 | F51: ='Input - Swine'!$G$7 -> 100 | G51: ='Input - Swine'!$H$7 -> 100 | H51: =G41 -> days
...

Sheet Constants - Swine
A1: #VALUE! | C1: Constants - Swine
A3: =HYPERLINK("#'Home'!A1", "Home") -> Home
A4: =HYPERLINK("#'Overview'!A1", "Overview") -> Overview
A5: =HYPERLINK("#'Results'!A1", "Results") -> Results
D6: Swine crop or pasture production systems | G6: Irrigation methods
A7: INPUTS
A8: =HYPERLINK("#'Input - Site'!A1", "Site") -> Site | D8: Production system | G8: Irrigation method
A9: =HYPERLINK("#'Input - Swine'!A1", "Swine") -> Swine | D9: Pasture | G9: Not irrigated
D10: Crop | G10: Drip irrigation
A11: CALCULATIONS | G11: Sprinkler irrigation
A12: =HYPERLINK("#'3.5.1.1-2 Enteric Methane'!A1", "3.5.1.1-2 Enteric Methane") -> 3.5.1.1-2 Enteric Methane | G12: Surface irrigation
G13: Other irrigation
A14: APPENDICES | D14: {=SourceData_Swine.SourceData_Swine_FracLEACH_DrylotMMS_Title()} -> Fraction of nitrogen lost through leaching and runoff for drylot MMS
A15: =HYPERLINK("#'Constants - Swine'!A1", "Constants - Swine") -> Constants - Swine | D15: {=SourceData_Swine.SourceData_Swine_FracLEACH_DrylotMMS_Source()} -> VEERG 2026: 4.5.2.3 CONSTANT
A16: =HYPERLINK("#'Constants - Livestock'!A1", "Constants - Livestock") -> Constants - Livestock | D16: {=SourceData_Swine.SourceData_Swine_FracLEACH_DrylotMMS_Variation()} -> VARIATION ON SOURCE: Text refers to 'solid storage' MMS, but equation refers to 'drylot' MMS.
A17: =HYPERLINK("#'Constants - Common'!A1", "Constants - Common") -> Constants - Common | D17: {=SourceData_Swine.SourceData_Swine_FracLEACH_DrylotMMS_Variable()} -> FracLEACH_MS | E17: {=SourceData_Swine.SourceData_Swine_FracLEACH_DrylotMMS_Data()} -> 0.02 | F17: {=SourceData_Swine.SourceData_Swine_FracLEACH_DrylotMMS_Unit()} -> fraction
A18: =HYPERLINK("#'Acknowledgements'!A1", "Acknowledgements") -> Acknowledgements
D19: {=SourceData_Swine.SourceData_Swine_MethaneVolatileSolidsEmissionsPotential_Title()} -> Emissions potential of methane per kilogram of volatile solids
D20: {=SourceData_Swine.SourceData_Swine_MethaneVolatileSolidsEmissionsPotential_Source()} -> IPCC (2019), Chapter 10 [4]
D21: {=SourceData_Swine.SourceData_Swine_MethaneVolatileSolidsEmissionsPotential_Variable()} -> B0 | E21: {=SourceData_Swine.SourceData_Swine_MethaneVolatileSolidsEmissionsPotential_Data()} -> 0.19 | F21: {=SourceData_Swine.SourceData_Swine_MethaneVolatileSolidsEmissionsPotential_Unit()} -> m3 CH4 / kg VS
D24: {=SourceData_Swine.SourceData_Swine_MMS_MCFs_Title()} -> Methane conversion factor for temperature zone and manure management system. | H24: CHange title to match source
D25: {=SourceData_Swine.SourceData_Swine_MMS_MCFs_Source()} -> VEERG 2026: Table A.1.6.4: Swine - MCFs (MCFim) | H25: CHange source
D26: {=SourceData_Swine.SourceData_Swine_MMS_MCFs_Variation()} -> VARIATION ON SOURCE DATA: Added columns for ACT, split QLD and NT. Added extra column with MMS names that match NIR definitions
D28: MMS | E28: NSW | F28: ACT | G28: QLD | H28: NT | I28: SA | J28: TAS | K28: VIC | L28: WA | M28: NIR definition
D29: {=Common_InputFunctions.Utility_DisplayArrayInTable(SourceData_Swine.SourceData_Swine_MMS_MCFs_Data(),Table_SourceData_Swine_MMSMCF[[#Headers],[MMS]],0)} -> Outdoor (Dry lot) | E29: {=Common_InputFunctions.Utility_DisplayArrayInTable(SourceData_Swine.SourceData_Swine_MMS_MCFs_Data(),Table_SourceData_Swine_MMSMCF[[#Headers],[MMS]],0)} -> 0.01 | F29: {=Common_InputFunctions.Utility_DisplayArrayInTable(SourceData_Swine.SourceData_Swine_MMS_MCFs_Data(),Table_SourceData_Swine_MMSMCF[[#Headers],[MMS]],0)} -> 0.01 | G29: {=Common_InputFunctions.Utility_DisplayArrayInTable(SourceData_Swine.SourceData_Swine_MMS_MCFs_Data(),Table_SourceData_Swine_MMSMCF[[#Headers],[MMS]],0)} -> 0.03 | H29: {=Common_InputFunctions.Utility_DisplayArrayInTable(SourceData_Swine.SourceData_Swine_MMS_MCFs_Data(),Table_SourceData_Swine_MMSMCF[[#Headers],[MMS]],0)} -> 0.03 | I29: {=Common_InputFunctions.Utility_DisplayArrayInTable(SourceData_Swine.SourceData_Swine_MMS_MCFs_Data(),Table_SourceData_Swine_MMSMCF[[#Headers],[MMS]],0)} -> 0.01 | J29: {=Common_InputFunctions.Utility_DisplayArrayInTable(SourceData_Swine.SourceData_Swine_MMS_MCFs_Data(),Table_SourceData_Swine_MMSMCF[[#Headers],[MMS]],0)} -> 0.01 | K29: {=Common_InputFunctions.Utility_DisplayArrayInTable(SourceData_Swine.SourceData_Swine_MMS_MCFs_Data(),Table_SourceData_Swine_MMSMCF[[#Headers],[MMS]],0)} -> 0.01 | ... M29: {=Common_InputFunctions.Utility_DisplayArrayInTable(SourceData_Swine.SourceData_Swine_MMS_MCFs_Data(),Table_SourceData_Swine_MMSMCF[[#Headers],[MMS]],0)} -> Drylot (feed pad)
D30: {=Common_InputFunctions.Utility_DisplayArrayInTable(SourceData_Swine.SourceData_Swine_MMS_MCFs_Data(),Table_SourceData_Swine_MMSMCF[[#Headers],[MMS]],0)} -> Deep litter | E30: {=Common_InputFunctions.Utility_DisplayArrayInTable(SourceData_Swine.SourceData_Swine_MMS_MCFs_Data(),Table_SourceData_Swine_MMSMCF[[#Headers],[MMS]],0)} -> 0.04 | F30: {=Common_InputFunctions.Utility_DisplayArrayInTable(SourceData_Swine.SourceData_Swine_MMS_MCFs_Data(),Table_SourceData_Swine_MMSMCF[[#Headers],[MMS]],0)} -> 0.04 | G30: {=Common_InputFunctions.Utility_DisplayArrayInTable(SourceData_Swine.SourceData_Swine_MMS_MCFs_Data(),Table_SourceData_Swine_MMSMCF[[#Headers],[MMS]],0)} -> 0.04 | H30: {=Common_InputFunctions.Utility_DisplayArrayInTable(SourceData_Swine.SourceData_Swine_MMS_MCFs_Data(),Table_SourceData_Swine_MMSMCF[[#Headers],[MMS]],0)} -> 0.04 | I30: {=Common_InputFunctions.Utility_DisplayArrayInTable(SourceData_Swine.SourceData_Swine_MMS_MCFs_Data(),Table_SourceData_Swine_MMSMCF[[#Headers],[MMS]],0)} -> 0.04 | J30: {=Common_InputFunctions.Utility_DisplayArrayInTable(SourceData_Swine.SourceData_Swine_MMS_MCFs_Data(),Table_SourceData_Swine_MMSMCF[[#Headers],[MMS]],0)} -> 0.04 | K30: {=Common_InputFunctions.Utility_DisplayArrayInTable(SourceData_Swine.SourceData_Swine_MMS_MCFs_Data(),Table_SourceData_Swine_MMSMCF[[#Headers],[MMS]],0)} -> 0.04 | ... M30: {=Common_InputFunctions.Utility_DisplayArrayInTable(SourceData_Swine.SourceData_Swine_MMS_MCFs_Data(),Table_SourceData_Swine_MMSMCF[[#Headers],[MMS]],0)} -> Deep litter
D31: {=Common_InputFunctions.Utility_DisplayArrayInTable(SourceData_Swine.SourceData_Swine_MMS_MCFs_Data(),Table_SourceData_Swine_MMSMCF[[#Headers],[MMS]],0)} -> Stockpile (Solid storage) | E31: {=Common_InputFunctions.Utility_DisplayArrayInTable(SourceData_Swine.SourceData_Swine_MMS_MCFs_Data(),Table_SourceData_Swine_MMSMCF[[#Headers],[MMS]],0)} -> 0.02 | F31: {=Common_InputFunctions.Utility_DisplayArrayInTable(SourceData_Swine.SourceData_Swine_MMS_MCFs_Data(),Table_SourceData_Swine_MMSMCF[[#Headers],[MMS]],0)} -> 0.02 | G31: {=Common_InputFunctions.Utility_DisplayArrayInTable(SourceData_Swine.SourceData_Swine_MMS_MCFs_Data(),Table_SourceData_Swine_MMSMCF[[#Headers],[MMS]],0)} -> 0.02 | H31: {=Common_InputFunctions.Utility_DisplayArrayInTable(SourceData_Swine.SourceData_Swine_MMS_MCFs_Data(),Table_SourceData_Swine_MMSMCF[[#Headers],[MMS]],0)} -> 0.02 | I31: {=Common_InputFunctions.Utility_DisplayArrayInTable(SourceData_Swine.SourceData_Swine_MMS_MCFs_Data(),Table_SourceData_Swine_MMSMCF[[#Headers],[MMS]],0)} -> 0.02 | J31: {=Common_InputFunctions.Utility_DisplayArrayInTable(SourceData_Swine.SourceData_Swine_MMS_MCFs_Data(),Table_SourceData_Swine_MMSMCF[[#Headers],[MMS]],0)} -> 0.02 | K31: {=Common_InputFunctions.Utility_DisplayArrayInTable(SourceData_Swine.SourceData_Swine_MMS_MCFs_Data(),Table_SourceData_Swine_MMSMCF[[#Headers],[MMS]],0)} -> 0.02 | ... M31: {=Common_InputFunctions.Utility_DisplayArrayInTable(SourceData_Swine.SourceData_Swine_MMS_MCFs_Data(),Table_SourceData_Swine_MMSMCF[[#Headers],[MMS]],0)} -> Solid storage
D32: {=Common_InputFunctions.Utility_DisplayArrayInTable(SourceData_Swine.SourceData_Swine_MMS_MCFs_Data(),Table_SourceData_Swine_MMSMCF[[#Headers],[MMS]],0)} -> Effluent pond (Uncovered anaerobic lagoon) | E32: {=Common_InputFunctions.Utility_DisplayArrayInTable(SourceData_Swine.SourceData_Swine_MMS_MCFs_Data(),Table_SourceData_Swine_MMSMCF[[#Headers],[MMS]],0)} -> 0.75 | F32: {=Common_InputFunctions.Utility_DisplayArrayInTable(SourceData_Swine.SourceData_Swine_MMS_MCFs_Data(),Table_SourceData_Swine_MMSMCF[[#Headers],[MMS]],0)} -> 0.75 | G32: {=Common_InputFunctions.Utility_DisplayArrayInTable(SourceData_Swine.SourceData_Swine_MMS_MCFs_Data(),Table_SourceData_Swine_MMSMCF[[#Headers],[MMS]],0)} -> 0.78 | H32: {=Common_InputFunctions.Utility_DisplayArrayInTable(SourceData_Swine.SourceData_Swine_MMS_MCFs_Data(),Table_SourceData_Swine_MMSMCF[[#Headers],[MMS]],0)} -> 0.78 | I32: {=Common_InputFunctions.Utility_DisplayArrayInTable(SourceData_Swine.SourceData_Swine_MMS_MCFs_Data(),Table_SourceData_Swine_MMSMCF[[#Headers],[MMS]],0)} -> 0.75 | J32: {=Common_InputFunctions.Utility_DisplayArrayInTable(SourceData_Swine.SourceData_Swine_MMS_MCFs_Data(),Table_SourceData_Swine_MMSMCF[[#Headers],[MMS]],0)} -> 0.7 | K32: {=Common_InputFunctions.Utility_DisplayArrayInTable(SourceData_Swine.SourceData_Swine_MMS_MCFs_Data(),Table_SourceData_Swine_MMSMCF[[#Headers],[MMS]],0)} -> 0.74 | ... M32: {=Common_InputFunctions.Utility_DisplayArrayInTable(SourceData_Swine.SourceData_Swine_MMS_MCFs_Data(),Table_SourceData_Swine_MMSMCF[[#Headers],[MMS]],0)} -> Anaerobic lagoon
D33: {=Common_InputFunctions.Utility_DisplayArrayInTable(SourceData_Swine.SourceData_Swine_MMS_MCFs_Data(),Table_SourceData_Swine_MMSMCF[[#Headers],[MMS]],0)} -> Anaerobic digester / Covered lagoon | E33: {=Common_InputFunctions.Utility_DisplayArrayInTable(SourceData_Swine.SourceData_Swine_MMS_MCFs_Data(),Table_SourceData_Swine_MMSMCF[[#Headers],[MMS]],0)} -> 0.1 | F33: {=Common_InputFunctions.Utility_DisplayArrayInTable(SourceData_Swine.SourceData_Swine_MMS_MCFs_Data(),Table_SourceData_Swine_MMSMCF[[#Headers],[MMS]],0)} -> 0.1 | G33: {=Common_InputFunctions.Utility_DisplayArrayInTable(SourceData_Swine.SourceData_Swine_MMS_MCFs_Data(),Table_SourceData_Swine_MMSMCF[[#Headers],[MMS]],0)} -> 0.1 | H33: {=Common_InputFunctions.Utility_DisplayArrayInTable(SourceData_Swine.SourceData_Swine_MMS_MCFs_Data(),Table_SourceData_Swine_MMSMCF[[#Headers],[MMS]],0)} -> 0.1 | I33: {=Common_InputFunctions.Utility_DisplayArrayInTable(SourceData_Swine.SourceData_Swine_MMS_MCFs_Data(),Table_SourceData_Swine_MMSMCF[[#Headers],[MMS]],0)} -> 0.1 | J33: {=Common_InputFunctions.Utility_DisplayArrayInTable(SourceData_Swine.SourceData_Swine_MMS_MCFs_Data(),Table_SourceData_Swine_MMSMCF[[#Headers],[MMS]],0)} -> 0.1 | K33: {=Common_InputFunctions.Utility_DisplayArrayInTable(SourceData_Swine.SourceData_Swine_MMS_MCFs_Data(),Table_SourceData_Swine_MMSMCF[[#Headers],[MMS]],0)} -> 0.1 | ... M33: {=Common_InputFunctions.Utility_DisplayArrayInTable(SourceData_Swine.SourceData_Swine_MMS_MCFs_Data(),Table_SourceData_Swine_MMSMCF[[#Headers],[MMS]],0)} -> Digester / covered lagoons
D34: {=Common_InputFunctions.Utility_DisplayArrayInTable(SourceData_Swine.SourceData_Swine_MMS_MCFs_Data(),Table_SourceData_Swine_MMSMCF[[#Headers],[MMS]],0)} -> Short HRT tank storage < 1 month (pit storage) | E34: {=Common_InputFunctions.Utility_DisplayArrayInTable(SourceData_Swine.SourceData_Swine_MMS_MCFs_Data(),Table_SourceData_Swine_MMSMCF[[#Headers],[MMS]],0)} -> 0.03 | F34: {=Common_InputFunctions.Utility_DisplayArrayInTable(SourceData_Swine.SourceData_Swine_MMS_MCFs_Data(),Table_SourceData_Swine_MMSMCF[[#Headers],[MMS]],0)} -> 0.03 | G34: {=Common_InputFunctions.Utility_DisplayArrayInTable(SourceData_Swine.SourceData_Swine_MMS_MCFs_Data(),Table_SourceData_Swine_MMSMCF[[#Headers],[MMS]],0)} -> 0.03 | H34: {=Common_InputFunctions.Utility_DisplayArrayInTable(SourceData_Swine.SourceData_Swine_MMS_MCFs_Data(),Table_SourceData_Swine_MMSMCF[[#Headers],[MMS]],0)} -> 0.03 | I34: {=Common_InputFunctions.Utility_DisplayArrayInTable(SourceData_Swine.SourceData_Swine_MMS_MCFs_Data(),Table_SourceData_Swine_MMSMCF[[#Headers],[MMS]],0)} -> 0.03 | J34: {=Common_InputFunctions.Utility_DisplayArrayInTable(SourceData_Swine.SourceData_Swine_MMS_MCFs_Data(),Table_SourceData_Swine_MMSMCF[[#Headers],[MMS]],0)} -> 0.03 | K34: {=Common_InputFunctions.Utility_DisplayArrayInTable(SourceData_Swine.SourceData_Swine_MMS_MCFs_Data(),Table_SourceData_Swine_MMSMCF[[#Headers],[MMS]],0)} -> 0.03 | ... M34: {=Common_InputFunctions.Utility_DisplayArrayInTable(SourceData_Swine.SourceData_Swine_MMS_MCFs_Data(),Table_SourceData_Swine_MMSMCF[[#Headers],[MMS]],0)} -> Pit storage
D35: {=Common_InputFunctions.Utility_DisplayArrayInTable(SourceData_Swine.SourceData_Swine_MMS_MCFs_Data(),Table_SourceData_Swine_MMSMCF[[#Headers],[MMS]],0)} -> Direct Application to soil | E35: {=Common_InputFunctions.Utility_DisplayArrayInTable(SourceData_Swine.SourceData_Swine_MMS_MCFs_Data(),Table_SourceData_Swine_MMSMCF[[#Headers],[MMS]],0)} -> 0 | F35: {=Common_InputFunctions.Utility_DisplayArrayInTable(SourceData_Swine.SourceData_Swine_MMS_MCFs_Data(),Table_SourceData_Swine_MMSMCF[[#Headers],[MMS]],0)} -> 0 | G35: {=Common_InputFunctions.Utility_DisplayArrayInTable(SourceData_Swine.SourceData_Swine_MMS_MCFs_Data(),Table_SourceData_Swine_MMSMCF[[#Headers],[MMS]],0)} -> 0 | H35: {=Common_InputFunctions.Utility_DisplayArrayInTable(SourceData_Swine.SourceData_Swine_MMS_MCFs_Data(),Table_SourceData_Swine_MMSMCF[[#Headers],[MMS]],0)} -> 0 | I35: {=Common_InputFunctions.Utility_DisplayArrayInTable(SourceData_Swine.SourceData_Swine_MMS_MCFs_Data(),Table_SourceData_Swine_MMSMCF[[#Headers],[MMS]],0)} -> 0 | J35: {=Common_InputFunctions.Utility_DisplayArrayInTable(SourceData_Swine.SourceData_Swine_MMS_MCFs_Data(),Table_SourceData_Swine_MMSMCF[[#Headers],[MMS]],0)} -> 0 | K35: {=Common_InputFunctions.Utility_DisplayArrayInTable(SourceData_Swine.SourceData_Swine_MMS_MCFs_Data(),Table_SourceData_Swine_MMSMCF[[#Headers],[MMS]],0)} -> 0 | ... M35: {=Common_InputFunctions.Utility_DisplayArrayInTable(SourceData_Swine.SourceData_Swine_MMS_MCFs_Data(),Table_SourceData_Swine_MMSMCF[[#Headers],[MMS]],0)} -> Direct application
D38: Swine Manure management systems | G38: Swine Manure management systems excl. solid storage and direct application | K38: Swine Manure management systems excl. direct application
D40: MMS | E40: Symbol and MMS | G40: MMS | H40: Symbol and MMS | K40: MMS | L40: Symbol and MMS
D41: ='Constants - Livestock'!$E$10 -> Anaerobic lagoon | E41: ='Constants - Livestock'!$F$10 -> Anaerobic lagoon (m=1) | G41: ='Constants - Livestock'!$E$10 -> Anaerobic lagoon | H41: ='Constants - Livestock'!$F$10 -> Anaerobic lagoon (m=1) | K41: ='Constants - Livestock'!$E$10 -> Anaerobic lagoon | L41: ='Constants - Livestock'!$F$10 -> Anaerobic lagoon (m=1)
D42: ='Constants - Livestock'!$E$15 -> Solid storage | E42: ='Constants - Livestock'!$F$15 -> Solid storage (m=4) | G42: ='Constants - Livestock'!$E$16 -> Drylot (feed pad) | H42: ='Constants - Livestock'!$F$16 -> Drylot (feed pad) (m=5) | K42: ='Constants - Livestock'!$E$15 -> Solid storage | L42: ='Constants - Livestock'!$F$15 -> Solid storage (m=4)
D43: ='Constants - Livestock'!$E$16 -> Drylot (feed pad) | E43: ='Constants - Livestock'!$F$16 -> Drylot (feed pad) (m=5) | G43: ='Constants - Livestock'!$E$18 -> Digester / covered lagoons | H43: ='Constants - Livestock'!$F$18 -> Digester / covered lagoons (m=7) | K43: ='Constants - Livestock'!$E$16 -> Drylot (feed pad) | L43: ='Constants - Livestock'!$F$16 -> Drylot (feed pad) (m=5)
D44: ='Constants - Livestock'!$E$18 -> Digester / covered lagoons | E44: ='Constants - Livestock'!$F$18 -> Digester / covered lagoons (m=7) | G44: ='Constants - Livestock'!$E$19 -> Deep litter | H44: ='Constants - Livestock'!$F$19 -> Deep litter (m=8) | K44: ='Constants - Livestock'!$E$18 -> Digester / covered lagoons | L44: ='Constants - Livestock'!$F$18 -> Digester / covered lagoons (m=7)
D45: ='Constants - Livestock'!$E$19 -> Deep litter | E45: ='Constants - Livestock'!$F$19 -> Deep litter (m=8) | G45: ='Constants - Livestock'!$E$20 -> Pit storage | H45: ='Constants - Livestock'!$F$20 -> Pit storage (m=9) | K45: ='Constants - Livestock'!$E$19 -> Deep litter | L45: ='Constants - Livestock'!$F$19 -> Deep litter (m=8)
D46: ='Constants - Livestock'!$E$20 -> Pit storage | E46: ='Constants - Livestock'!$F$20 -> Pit storage (m=9) | K46: ='Constants - Livestock'!$E$20 -> Pit storage | L46: ='Constants - Livestock'!$F$20 -> Pit storage (m=9)
D47: ='Constants - Livestock'!$E$26 -> Direct application | E47: ='Constants - Livestock'!$F$26 -> Direct application (m=13)
...

Sheet Constants - Common
A1: #VALUE! | C1: Constants - Common
D5: {=Common_SourceData.Common_SourceData_AustralianStatesTerritories_Title()} -> Australian states and territories
D6: State/Territory | E6: Common Name | F6: Abbreviation
D7: {=Common_InputFunctions.Utility_DisplayArrayInTable(Common_SourceData.Common_SourceData_AustralianStatesTerritories_Data(),Table_AustralianStates[[#Headers],[State/Territory]],0)} -> New South Wales | E7: {=Common_InputFunctions.Utility_DisplayArrayInTable(Common_SourceData.Common_SourceData_AustralianStatesTerritories_Data(),Table_AustralianStates[[#Headers],[State/Territory]],0)} -> New South Wales | F7: {=Common_InputFunctions.Utility_DisplayArrayInTable(Common_SourceData.Common_SourceData_AustralianStatesTerritories_Data(),Table_AustralianStates[[#Headers],[State/Territory]],0)} -> NSW
D8: {=Common_InputFunctions.Utility_DisplayArrayInTable(Common_SourceData.Common_SourceData_AustralianStatesTerritories_Data(),Table_AustralianStates[[#Headers],[State/Territory]],0)} -> Australian Capital Territory | E8: {=Common_InputFunctions.Utility_DisplayArrayInTable(Common_SourceData.Common_SourceData_AustralianStatesTerritories_Data(),Table_AustralianStates[[#Headers],[State/Territory]],0)} -> ACT | F8: {=Common_InputFunctions.Utility_DisplayArrayInTable(Common_SourceData.Common_SourceData_AustralianStatesTerritories_Data(),Table_AustralianStates[[#Headers],[State/Territory]],0)} -> ACT
D9: {=Common_InputFunctions.Utility_DisplayArrayInTable(Common_SourceData.Common_SourceData_AustralianStatesTerritories_Data(),Table_AustralianStates[[#Headers],[State/Territory]],0)} -> Victoria | E9: {=Common_InputFunctions.Utility_DisplayArrayInTable(Common_SourceData.Common_SourceData_AustralianStatesTerritories_Data(),Table_AustralianStates[[#Headers],[State/Territory]],0)} -> Victoria | F9: {=Common_InputFunctions.Utility_DisplayArrayInTable(Common_SourceData.Common_SourceData_AustralianStatesTerritories_Data(),Table_AustralianStates[[#Headers],[State/Territory]],0)} -> VIC
D10: {=Common_InputFunctions.Utility_DisplayArrayInTable(Common_SourceData.Common_SourceData_AustralianStatesTerritories_Data(),Table_AustralianStates[[#Headers],[State/Territory]],0)} -> Queensland | E10: {=Common_InputFunctions.Utility_DisplayArrayInTable(Common_SourceData.Common_SourceData_AustralianStatesTerritories_Data(),Table_AustralianStates[[#Headers],[State/Territory]],0)} -> Queensland | F10: {=Common_InputFunctions.Utility_DisplayArrayInTable(Common_SourceData.Common_SourceData_AustralianStatesTerritories_Data(),Table_AustralianStates[[#Headers],[State/Territory]],0)} -> QLD
D11: {=Common_InputFunctions.Utility_DisplayArrayInTable(Common_SourceData.Common_SourceData_AustralianStatesTerritories_Data(),Table_AustralianStates[[#Headers],[State/Territory]],0)} -> South Australia | E11: {=Common_InputFunctions.Utility_DisplayArrayInTable(Common_SourceData.Common_SourceData_AustralianStatesTerritories_Data(),Table_AustralianStates[[#Headers],[State/Territory]],0)} -> South Australia | F11: {=Common_InputFunctions.Utility_DisplayArrayInTable(Common_SourceData.Common_SourceData_AustralianStatesTerritories_Data(),Table_AustralianStates[[#Headers],[State/Territory]],0)} -> SA
D12: {=Common_InputFunctions.Utility_DisplayArrayInTable(Common_SourceData.Common_SourceData_AustralianStatesTerritories_Data(),Table_AustralianStates[[#Headers],[State/Territory]],0)} -> Western Australia | E12: {=Common_InputFunctions.Utility_DisplayArrayInTable(Common_SourceData.Common_SourceData_AustralianStatesTerritories_Data(),Table_AustralianStates[[#Headers],[State/Territory]],0)} -> Western Australia | F12: {=Common_InputFunctions.Utility_DisplayArrayInTable(Common_SourceData.Common_SourceData_AustralianStatesTerritories_Data(),Table_AustralianStates[[#Headers],[State/Territory]],0)} -> WA
D13: {=Common_InputFunctions.Utility_DisplayArrayInTable(Common_SourceData.Common_SourceData_AustralianStatesTerritories_Data(),Table_AustralianStates[[#Headers],[State/Territory]],0)} -> Tasmania | E13: {=Common_InputFunctions.Utility_DisplayArrayInTable(Common_SourceData.Common_SourceData_AustralianStatesTerritories_Data(),Table_AustralianStates[[#Headers],[State/Territory]],0)} -> Tasmania | F13: {=Common_InputFunctions.Utility_DisplayArrayInTable(Common_SourceData.Common_SourceData_AustralianStatesTerritories_Data(),Table_AustralianStates[[#Headers],[State/Territory]],0)} -> TAS
D14: {=Common_InputFunctions.Utility_DisplayArrayInTable(Common_SourceData.Common_SourceData_AustralianStatesTerritories_Data(),Table_AustralianStates[[#Headers],[State/Territory]],0)} -> Northern Territory | E14: {=Common_InputFunctions.Utility_DisplayArrayInTable(Common_SourceData.Common_SourceData_AustralianStatesTerritories_Data(),Table_AustralianStates[[#Headers],[State/Territory]],0)} -> Northern Territory | F14: {=Common_InputFunctions.Utility_DisplayArrayInTable(Common_SourceData.Common_SourceData_AustralianStatesTerritories_Data(),Table_AustralianStates[[#Headers],[State/Territory]],0)} -> NT
D18: {=Common_SourceData.Common_SourceData_WASA4Areas_Title()} -> ABS Statistcal Areas Level 4 - Western Australia
D19: {=Common_SourceData.Common_SourceData_WASA4Areas_Source()} -> Australian Bureau of Statistics (ABS) - Statistical Areas Level 2 - 2021 - Shapefile
D20: SA 4 Name
D21: {=Common_InputFunctions.Utility_DisplayArrayInTable(Common_SourceData.Common_SourceData_WASA4Areas_Data(), Table_WASA4Areas[[#Headers],[SA 4 Name]], 0)} -> Bunbury
D22: {=Common_InputFunctions.Utility_DisplayArrayInTable(Common_SourceData.Common_SourceData_WASA4Areas_Data(), Table_WASA4Areas[[#Headers],[SA 4 Name]], 0)} -> Mandurah
D23: {=Common_InputFunctions.Utility_DisplayArrayInTable(Common_SourceData.Common_SourceData_WASA4Areas_Data(), Table_WASA4Areas[[#Headers],[SA 4 Name]], 0)} -> Perth - Inner
D24: {=Common_InputFunctions.Utility_DisplayArrayInTable(Common_SourceData.Common_SourceData_WASA4Areas_Data(), Table_WASA4Areas[[#Headers],[SA 4 Name]], 0)} -> Perth - North East
D25: {=Common_InputFunctions.Utility_DisplayArrayInTable(Common_SourceData.Common_SourceData_WASA4Areas_Data(), Table_WASA4Areas[[#Headers],[SA 4 Name]], 0)} -> Perth - North West
D26: {=Common_InputFunctions.Utility_DisplayArrayInTable(Common_SourceData.Common_SourceData_WASA4Areas_Data(), Table_WASA4Areas[[#Headers],[SA 4 Name]], 0)} -> Perth - South East
D27: {=Common_InputFunctions.Utility_DisplayArrayInTable(Common_SourceData.Common_SourceData_WASA4Areas_Data(), Table_WASA4Areas[[#Headers],[SA 4 Name]], 0)} -> Perth - South West
D28: {=Common_InputFunctions.Utility_DisplayArrayInTable(Common_SourceData.Common_SourceData_WASA4Areas_Data(), Table_WASA4Areas[[#Headers],[SA 4 Name]], 0)} -> Western Australia - Wheat Belt
D29: {=Common_InputFunctions.Utility_DisplayArrayInTable(Common_SourceData.Common_SourceData_WASA4Areas_Data(), Table_WASA4Areas[[#Headers],[SA 4 Name]], 0)} -> Western Australia - Outback (North)
D30: {=Common_InputFunctions.Utility_DisplayArrayInTable(Common_SourceData.Common_SourceData_WASA4Areas_Data(), Table_WASA4Areas[[#Headers],[SA 4 Name]], 0)} -> Western Australia - Outback (South)
D34: {=Common_SourceData.Common_SourceData_GWP_Title()} -> Global warming potential for greenhouse gases
D35: {=Common_SourceData.Common_SourceData_GWP_Source()} -> XXXXXXX
D36: Gas | E36: CO2-e factor
D37: {=Common_InputFunctions.Utility_DisplayArrayInTable(Common_SourceData.Common_SourceData_GWP_Data(), Table_GWPData[[#Headers],[Gas]], 0)} -> CO2 | E37: {=Common_InputFunctions.Utility_DisplayArrayInTable(Common_SourceData.Common_SourceData_GWP_Data(), Table_GWPData[[#Headers],[Gas]], 0)} -> 1
D38: {=Common_InputFunctions.Utility_DisplayArrayInTable(Common_SourceData.Common_SourceData_GWP_Data(), Table_GWPData[[#Headers],[Gas]], 0)} -> CH4 | E38: {=Common_InputFunctions.Utility_DisplayArrayInTable(Common_SourceData.Common_SourceData_GWP_Data(), Table_GWPData[[#Headers],[Gas]], 0)} -> 28
D39: {=Common_InputFunctions.Utility_DisplayArrayInTable(Common_SourceData.Common_SourceData_GWP_Data(), Table_GWPData[[#Headers],[Gas]], 0)} -> N2O | E39: {=Common_InputFunctions.Utility_DisplayArrayInTable(Common_SourceData.Common_SourceData_GWP_Data(), Table_GWPData[[#Headers],[Gas]], 0)} -> 265
D40: {=Common_InputFunctions.Utility_DisplayArrayInTable(Common_SourceData.Common_SourceData_GWP_Data(), Table_GWPData[[#Headers],[Gas]], 0)} -> CF4 | E40: {=Common_InputFunctions.Utility_DisplayArrayInTable(Common_SourceData.Common_SourceData_GWP_Data(), Table_GWPData[[#Headers],[Gas]], 0)} -> 6630
D41: {=Common_InputFunctions.Utility_DisplayArrayInTable(Common_SourceData.Common_SourceData_GWP_Data(), Table_GWPData[[#Headers],[Gas]], 0)} -> C2F6 | E41: {=Common_InputFunctions.Utility_DisplayArrayInTable(Common_SourceData.Common_SourceData_GWP_Data(), Table_GWPData[[#Headers],[Gas]], 0)} -> 12200
D42: {=Common_InputFunctions.Utility_DisplayArrayInTable(Common_SourceData.Common_SourceData_GWP_Data(), Table_GWPData[[#Headers],[Gas]], 0)} -> SF6 | E42: {=Common_InputFunctions.Utility_DisplayArrayInTable(Common_SourceData.Common_SourceData_GWP_Data(), Table_GWPData[[#Headers],[Gas]], 0)} -> 22800
D43: {=Common_InputFunctions.Utility_DisplayArrayInTable(Common_SourceData.Common_SourceData_GWP_Data(), Table_GWPData[[#Headers],[Gas]], 0)} -> NF3 | E43: {=Common_InputFunctions.Utility_DisplayArrayInTable(Common_SourceData.Common_SourceData_GWP_Data(), Table_GWPData[[#Headers],[Gas]], 0)} -> 17200
D45: {=Common_SourceData.Common_SourceData_ConvertGasElementalToMolecular_Title()} -> Factor to convert elemental mass of gas to molecular mass
D46: {=Common_SourceData.Common_SourceData_ConvertGasElementalToMolecular_Source()} -> XXXXXXX
D47: Gas | E47: Conversion factor | F47: Conversion factor 1 | G47: Conversion factor 2 | H47: Conversion factor combined
D48: {=Common_InputFunctions.Utility_DisplayArrayInTable(Common_SourceData.Common_SourceData_ConvertGasElementalToMolecular_Data(),Table_GasToMolecularConversionFactor[[#Headers],[Gas]], 0)} -> CO2 | E48: {=Common_InputFunctions.Utility_DisplayArrayInTable(Common_SourceData.Common_SourceData_ConvertGasElementalToMolecular_Data(),Table_GasToMolecularConversionFactor[[#Headers],[Gas]], 0)} -> 44/12 | F48: {=Common_InputFunctions.Utility_DisplayArrayInTable(Common_SourceData.Common_SourceData_ConvertGasElementalToMolecular_Data(),Table_GasToMolecularConversionFactor[[#Headers],[Gas]], 0)} -> 44 | G48: {=Common_InputFunctions.Utility_DisplayArrayInTable(Common_SourceData.Common_SourceData_ConvertGasElementalToMolecular_Data(),Table_GasToMolecularConversionFactor[[#Headers],[Gas]], 0)} -> 12 | H48: =Table_GasToMolecularConversionFactor[[#This Row],[Conversion factor 1]]/Table_GasToMolecularConversionFactor[[#This Row],[Conversion factor 2]] -> 3.6666667
D49: {=Common_InputFunctions.Utility_DisplayArrayInTable(Common_SourceData.Common_SourceData_ConvertGasElementalToMolecular_Data(),Table_GasToMolecularConversionFactor[[#Headers],[Gas]], 0)} -> CH4 | E49: {=Common_InputFunctions.Utility_DisplayArrayInTable(Common_SourceData.Common_SourceData_ConvertGasElementalToMolecular_Data(),Table_GasToMolecularConversionFactor[[#Headers],[Gas]], 0)} -> 16/12 | F49: {=Common_InputFunctions.Utility_DisplayArrayInTable(Common_SourceData.Common_SourceData_ConvertGasElementalToMolecular_Data(),Table_GasToMolecularConversionFactor[[#Headers],[Gas]], 0)} -> 16 | G49: {=Common_InputFunctions.Utility_DisplayArrayInTable(Common_SourceData.Common_SourceData_ConvertGasElementalToMolecular_Data(),Table_GasToMolecularConversionFactor[[#Headers],[Gas]], 0)} -> 12 | H49: =Table_GasToMolecularConversionFactor[[#This Row],[Conversion factor 1]]/Table_GasToMolecularConversionFactor[[#This Row],[Conversion factor 2]] -> 1.3333333
D50: {=Common_InputFunctions.Utility_DisplayArrayInTable(Common_SourceData.Common_SourceData_ConvertGasElementalToMolecular_Data(),Table_GasToMolecularConversionFactor[[#Headers],[Gas]], 0)} -> N2O | E50: {=Common_InputFunctions.Utility_DisplayArrayInTable(Common_SourceData.Common_SourceData_ConvertGasElementalToMolecular_Data(),Table_GasToMolecularConversionFactor[[#Headers],[Gas]], 0)} -> 44/28 | F50: {=Common_InputFunctions.Utility_DisplayArrayInTable(Common_SourceData.Common_SourceData_ConvertGasElementalToMolecular_Data(),Table_GasToMolecularConversionFactor[[#Headers],[Gas]], 0)} -> 44 | G50: {=Common_InputFunctions.Utility_DisplayArrayInTable(Common_SourceData.Common_SourceData_ConvertGasElementalToMolecular_Data(),Table_GasToMolecularConversionFactor[[#Headers],[Gas]], 0)} -> 28 | H50: =Table_GasToMolecularConversionFactor[[#This Row],[Conversion factor 1]]/Table_GasToMolecularConversionFactor[[#This Row],[Conversion factor 2]] -> 1.5714286
...

Sheet Constants - Livestock
A1: #VALUE! | C1: Constants - Livestock
A3: =HYPERLINK("#'Home'!A1", "Home") -> Home
A4: =HYPERLINK("#'Overview'!A1", "Overview") -> Overview
A5: =HYPERLINK("#'Results'!A1", "Results") -> Results
D6: {=CommonLivestock_SourceData.SourceData_Livestock_Common_SymbolsMMS_Title()} -> Table 5.12 Additional symbols used in algorithms for manure related emissions
A7: INPUTS | D7: {=CommonLivestock_SourceData.SourceData_Livestock_Common_SymbolsMMS_Vairable()} -> MMS
A8: =HYPERLINK("#'Input - Site'!A1", "Site") -> Site | D8: {=CommonLivestock_SourceData.SourceData_Livestock_Common_SymbolsMMS_Source()} -> National Inventory Report 2023 Volume 1: Table 5.12
A9: =HYPERLINK("#'Input - Swine'!A1", "Swine") -> Swine | D9: Symbol | E9: Manure management system | F9: Symbol and MMS
D10: {=Common_InputFunctions.Utility_DisplayArrayInTable(CommonLivestock_SourceData.SourceData_Livestock_Common_SymbolsMMS_Data(), Table_Data_MMSSymbols[[#Headers],[Symbol]], 0)} -> 1 | E10: {=Common_InputFunctions.Utility_DisplayArrayInTable(CommonLivestock_SourceData.SourceData_Livestock_Common_SymbolsMMS_Data(), Table_Data_MMSSymbols[[#Headers],[Symbol]], 0)} -> Anaerobic lagoon | F10: {=Common_InputFunctions.Utility_DisplayArrayInTable(CommonLivestock_SourceData.SourceData_Livestock_Common_SymbolsMMS_Data(), Table_Data_MMSSymbols[[#Headers],[Symbol]], 0)} -> Anaerobic lagoon (m=1)
A11: CALCULATIONS | D11: {=Common_InputFunctions.Utility_DisplayArrayInTable(CommonLivestock_SourceData.SourceData_Livestock_Common_SymbolsMMS_Data(), Table_Data_MMSSymbols[[#Headers],[Symbol]], 0)} -> 2 | E11: {=Common_InputFunctions.Utility_DisplayArrayInTable(CommonLivestock_SourceData.SourceData_Livestock_Common_SymbolsMMS_Data(), Table_Data_MMSSymbols[[#Headers],[Symbol]], 0)} -> Liquid systems | F11: {=Common_InputFunctions.Utility_DisplayArrayInTable(CommonLivestock_SourceData.SourceData_Livestock_Common_SymbolsMMS_Data(), Table_Data_MMSSymbols[[#Headers],[Symbol]], 0)} -> Liquid systems (m=2)
A12: =HYPERLINK("#'3.5.1.1-2 Enteric Methane'!A1", "3.5.1.1-2 Enteric Methane") -> 3.5.1.1-2 Enteric Methane | D12: {=Common_InputFunctions.Utility_DisplayArrayInTable(CommonLivestock_SourceData.SourceData_Livestock_Common_SymbolsMMS_Data(), Table_Data_MMSSymbols[[#Headers],[Symbol]], 0)} -> 3 | E12: {=Common_InputFunctions.Utility_DisplayArrayInTable(CommonLivestock_SourceData.SourceData_Livestock_Common_SymbolsMMS_Data(), Table_Data_MMSSymbols[[#Headers],[Symbol]], 0)} -> Daily spread | F12: {=Common_InputFunctions.Utility_DisplayArrayInTable(CommonLivestock_SourceData.SourceData_Livestock_Common_SymbolsMMS_Data(), Table_Data_MMSSymbols[[#Headers],[Symbol]], 0)} -> Daily spread (m=3)
D13: {=Common_InputFunctions.Utility_DisplayArrayInTable(CommonLivestock_SourceData.SourceData_Livestock_Common_SymbolsMMS_Data(), Table_Data_MMSSymbols[[#Headers],[Symbol]], 0)} -> 3a | E13: {=Common_InputFunctions.Utility_DisplayArrayInTable(CommonLivestock_SourceData.SourceData_Livestock_Common_SymbolsMMS_Data(), Table_Data_MMSSymbols[[#Headers],[Symbol]], 0)} -> Sump and dispersal system | F13: {=Common_InputFunctions.Utility_DisplayArrayInTable(CommonLivestock_SourceData.SourceData_Livestock_Common_SymbolsMMS_Data(), Table_Data_MMSSymbols[[#Headers],[Symbol]], 0)} -> Sump and dispersal system (m=3a)
A14: APPENDICES | D14: {=Common_InputFunctions.Utility_DisplayArrayInTable(CommonLivestock_SourceData.SourceData_Livestock_Common_SymbolsMMS_Data(), Table_Data_MMSSymbols[[#Headers],[Symbol]], 0)} -> 3b | E14: {=Common_InputFunctions.Utility_DisplayArrayInTable(CommonLivestock_SourceData.SourceData_Livestock_Common_SymbolsMMS_Data(), Table_Data_MMSSymbols[[#Headers],[Symbol]], 0)} -> Drains to paddock | F14: {=Common_InputFunctions.Utility_DisplayArrayInTable(CommonLivestock_SourceData.SourceData_Livestock_Common_SymbolsMMS_Data(), Table_Data_MMSSymbols[[#Headers],[Symbol]], 0)} -> Drains to paddock (m=3b)
A15: =HYPERLINK("#'Constants - Swine'!A1", "Constants - Swine") -> Constants - Swine | D15: {=Common_InputFunctions.Utility_DisplayArrayInTable(CommonLivestock_SourceData.SourceData_Livestock_Common_SymbolsMMS_Data(), Table_Data_MMSSymbols[[#Headers],[Symbol]], 0)} -> 4 | E15: {=Common_InputFunctions.Utility_DisplayArrayInTable(CommonLivestock_SourceData.SourceData_Livestock_Common_SymbolsMMS_Data(), Table_Data_MMSSymbols[[#Headers],[Symbol]], 0)} -> Solid storage | F15: {=Common_InputFunctions.Utility_DisplayArrayInTable(CommonLivestock_SourceData.SourceData_Livestock_Common_SymbolsMMS_Data(), Table_Data_MMSSymbols[[#Headers],[Symbol]], 0)} -> Solid storage (m=4)
A16: =HYPERLINK("#'Constants - Livestock'!A1", "Constants - Livestock") -> Constants - Livestock | D16: {=Common_InputFunctions.Utility_DisplayArrayInTable(CommonLivestock_SourceData.SourceData_Livestock_Common_SymbolsMMS_Data(), Table_Data_MMSSymbols[[#Headers],[Symbol]], 0)} -> 5 | E16: {=Common_InputFunctions.Utility_DisplayArrayInTable(CommonLivestock_SourceData.SourceData_Livestock_Common_SymbolsMMS_Data(), Table_Data_MMSSymbols[[#Headers],[Symbol]], 0)} -> Drylot (feed pad) | F16: {=Common_InputFunctions.Utility_DisplayArrayInTable(CommonLivestock_SourceData.SourceData_Livestock_Common_SymbolsMMS_Data(), Table_Data_MMSSymbols[[#Headers],[Symbol]], 0)} -> Drylot (feed pad) (m=5)
A17: =HYPERLINK("#'Constants - Common'!A1", "Constants - Common") -> Constants - Common | D17: {=Common_InputFunctions.Utility_DisplayArrayInTable(CommonLivestock_SourceData.SourceData_Livestock_Common_SymbolsMMS_Data(), Table_Data_MMSSymbols[[#Headers],[Symbol]], 0)} -> 6 | E17: {=Common_InputFunctions.Utility_DisplayArrayInTable(CommonLivestock_SourceData.SourceData_Livestock_Common_SymbolsMMS_Data(), Table_Data_MMSSymbols[[#Headers],[Symbol]], 0)} -> Composting (passive windrow) | F17: {=Common_InputFunctions.Utility_DisplayArrayInTable(CommonLivestock_SourceData.SourceData_Livestock_Common_SymbolsMMS_Data(), Table_Data_MMSSymbols[[#Headers],[Symbol]], 0)} -> Composting (passive windrow) (m=6)
A18: =HYPERLINK("#'Acknowledgements'!A1", "Acknowledgements") -> Acknowledgements | D18: {=Common_InputFunctions.Utility_DisplayArrayInTable(CommonLivestock_SourceData.SourceData_Livestock_Common_SymbolsMMS_Data(), Table_Data_MMSSymbols[[#Headers],[Symbol]], 0)} -> 7 | E18: {=Common_InputFunctions.Utility_DisplayArrayInTable(CommonLivestock_SourceData.SourceData_Livestock_Common_SymbolsMMS_Data(), Table_Data_MMSSymbols[[#Headers],[Symbol]], 0)} -> Digester / covered lagoons | F18: {=Common_InputFunctions.Utility_DisplayArrayInTable(CommonLivestock_SourceData.SourceData_Livestock_Common_SymbolsMMS_Data(), Table_Data_MMSSymbols[[#Headers],[Symbol]], 0)} -> Digester / covered lagoons (m=7)
D19: {=Common_InputFunctions.Utility_DisplayArrayInTable(CommonLivestock_SourceData.SourceData_Livestock_Common_SymbolsMMS_Data(), Table_Data_MMSSymbols[[#Headers],[Symbol]], 0)} -> 8 | E19: {=Common_InputFunctions.Utility_DisplayArrayInTable(CommonLivestock_SourceData.SourceData_Livestock_Common_SymbolsMMS_Data(), Table_Data_MMSSymbols[[#Headers],[Symbol]], 0)} -> Deep litter | F19: {=Common_InputFunctions.Utility_DisplayArrayInTable(CommonLivestock_SourceData.SourceData_Livestock_Common_SymbolsMMS_Data(), Table_Data_MMSSymbols[[#Headers],[Symbol]], 0)} -> Deep litter (m=8)
D20: {=Common_InputFunctions.Utility_DisplayArrayInTable(CommonLivestock_SourceData.SourceData_Livestock_Common_SymbolsMMS_Data(), Table_Data_MMSSymbols[[#Headers],[Symbol]], 0)} -> 9 | E20: {=Common_InputFunctions.Utility_DisplayArrayInTable(CommonLivestock_SourceData.SourceData_Livestock_Common_SymbolsMMS_Data(), Table_Data_MMSSymbols[[#Headers],[Symbol]], 0)} -> Pit storage | F20: {=Common_InputFunctions.Utility_DisplayArrayInTable(CommonLivestock_SourceData.SourceData_Livestock_Common_SymbolsMMS_Data(), Table_Data_MMSSymbols[[#Headers],[Symbol]], 0)} -> Pit storage (m=9)
D21: {=Common_InputFunctions.Utility_DisplayArrayInTable(CommonLivestock_SourceData.SourceData_Livestock_Common_SymbolsMMS_Data(), Table_Data_MMSSymbols[[#Headers],[Symbol]], 0)} -> 10 | E21: {=Common_InputFunctions.Utility_DisplayArrayInTable(CommonLivestock_SourceData.SourceData_Livestock_Common_SymbolsMMS_Data(), Table_Data_MMSSymbols[[#Headers],[Symbol]], 0)} -> Poultry manure with bedding | F21: {=Common_InputFunctions.Utility_DisplayArrayInTable(CommonLivestock_SourceData.SourceData_Livestock_Common_SymbolsMMS_Data(), Table_Data_MMSSymbols[[#Headers],[Symbol]], 0)} -> Poultry manure with bedding (m=10)
D22: {=Common_InputFunctions.Utility_DisplayArrayInTable(CommonLivestock_SourceData.SourceData_Livestock_Common_SymbolsMMS_Data(), Table_Data_MMSSymbols[[#Headers],[Symbol]], 0)} -> 11 | E22: {=Common_InputFunctions.Utility_DisplayArrayInTable(CommonLivestock_SourceData.SourceData_Livestock_Common_SymbolsMMS_Data(), Table_Data_MMSSymbols[[#Headers],[Symbol]], 0)} -> Poultry manure without bedding | F22: {=Common_InputFunctions.Utility_DisplayArrayInTable(CommonLivestock_SourceData.SourceData_Livestock_Common_SymbolsMMS_Data(), Table_Data_MMSSymbols[[#Headers],[Symbol]], 0)} -> Poultry manure without bedding (m=11)
D23: {=Common_InputFunctions.Utility_DisplayArrayInTable(CommonLivestock_SourceData.SourceData_Livestock_Common_SymbolsMMS_Data(), Table_Data_MMSSymbols[[#Headers],[Symbol]], 0)} -> 11a | E23: {=Common_InputFunctions.Utility_DisplayArrayInTable(CommonLivestock_SourceData.SourceData_Livestock_Common_SymbolsMMS_Data(), Table_Data_MMSSymbols[[#Headers],[Symbol]], 0)} -> Belt manure removal | F23: {=Common_InputFunctions.Utility_DisplayArrayInTable(CommonLivestock_SourceData.SourceData_Livestock_Common_SymbolsMMS_Data(), Table_Data_MMSSymbols[[#Headers],[Symbol]], 0)} -> Belt manure removal (m=11a)
D24: {=Common_InputFunctions.Utility_DisplayArrayInTable(CommonLivestock_SourceData.SourceData_Livestock_Common_SymbolsMMS_Data(), Table_Data_MMSSymbols[[#Headers],[Symbol]], 0)} -> 11b | E24: {=Common_InputFunctions.Utility_DisplayArrayInTable(CommonLivestock_SourceData.SourceData_Livestock_Common_SymbolsMMS_Data(), Table_Data_MMSSymbols[[#Headers],[Symbol]], 0)} -> Manure stored in house | F24: {=Common_InputFunctions.Utility_DisplayArrayInTable(CommonLivestock_SourceData.SourceData_Livestock_Common_SymbolsMMS_Data(), Table_Data_MMSSymbols[[#Headers],[Symbol]], 0)} -> Manure stored in house (m=11b)
