Workbook
Name Common_Equations.Common_ConvertCH4ToCO2e: _xlfn.LAMBDA(_xlpm.E_CH4,_xlpm.GWP_CH4, _xlpm.E_CH4 * _xlpm.GWP_CH4)
Name Common_Equations.Common_ConvertCH4ToCO2e_Arguments: _xlfn.LAMBDA(_xlfn.MAKEARRAY(2, 2, _xlfn.LAMBDA(_xlpm.r,_xlpm.c, INDEX({"ECH4","Methane emissions (t CH4)";"GWPCH4","Global warming potential for methane (t CO2-e / t CH4)"}, _xlpm.r, _xlpm.c))))
Name Common_Equations.Common_ConvertCH4ToCO2e_LatexEquation: _xlfn.LAMBDA("CO2_e = E_{CH4} \times GWP_{CH4}")
Name Common_Equations.Common_ConvertCH4ToCO2e_NIRReference: _xlfn.LAMBDA("")
Name Common_Equations.Common_ConvertCH4ToCO2e_Title: _xlfn.LAMBDA("Convert methane emissions to carbon dioxide equivalent emissions")
Name Common_Equations.Common_ConvertCH4ToCO2e_Unit: _xlfn.LAMBDA("t CO2e")
Name Common_Equations.Common_ConvertCH4ToCO2e_Variable: _xlfn.LAMBDA("ECH4 CO2e")
Name Common_Equations.Common_ConvertN2OToCO2e: _xlfn.LAMBDA(_xlpm.E_N2O,_xlpm.GWP_N2O, _xlpm.E_N2O * _xlpm.GWP_N2O)
Name Common_Equations.Common_ConvertN2OToCO2e_LatexEquation: _xlfn.LAMBDA("CO2_e = E_{N2O} \times GWP_{N2O}")
Name Common_Equations.Common_ConvertN2OToCO2e_NIRReference: _xlfn.LAMBDA("")
Name Common_Equations.Common_ConvertN2OToCO2e_Title: _xlfn.LAMBDA("Convert nitrous oxide emissions to carbon dioxide equivalent emissions")
Name Common_Equations.Common_ConvertN2OToCO2e_Unit: _xlfn.LAMBDA("t CO2e")
Name Common_Equations.Common_ConvertN2OToCO2e_Variable: _xlfn.LAMBDA("EN2O CO2e")
Name Common_InputFunctions.Utility_ConvertStateCommonNameToAbbreviation: _xlfn.LAMBDA(_xlpm.StateCommonName,_xlpm.StateCommonNameArray,_xlpm.StateAbbreviationArray, _xlfn.XLOOKUP(_xlpm.StateCommonName, _xlpm.StateCommonNameArray, _xlpm.StateAbbreviationArray, ""))
Name Common_InputFunctions.Utility_DisplayArguments_1_2: _xlfn.LAMBDA(_xlpm.ArgumentsArray, _xlfn.CHOOSECOLS(_xlpm.ArgumentsArray, 1, 2))
Name Common_InputFunctions.Utility_DisplayArguments_3_4: _xlfn.LAMBDA(_xlpm.ArgumentsArray, _xlfn.CHOOSECOLS(_xlpm.ArgumentsArray, 3, 4))
Name Common_InputFunctions.Utility_DisplayFunctionName: _xlfn.LAMBDA(_xlpm.Function, _xlfn.TEXTBEFORE(_xlfn.FORMULATEXT(_xlpm.Function), "("))
Name Common_InputFunctions.Utility_GetArrayTableColumnStartNumber: _xlfn.LAMBDA(_xlpm.TableHeaderCell, COLUMN(_xlpm.TableHeaderCell))
Name Common_InputFunctions.Utility_GetArrayTableRowStartNumber: _xlfn.LAMBDA(_xlpm.TableheaderCell,_xlpm.RowsBetweenHeaderandArray, ROW(_xlpm.TableheaderCell) + _xlpm.RowsBetweenHeaderandArray - 1)
Name Common_InputFunctions.Utility_LookupValueInTable: _xlfn.LAMBDA(_xlpm.LookupValue,_xlpm.LookupArray,_xlpm.ReturnArray, _xlfn.XLOOKUP(_xlpm.LookupValue, _xlpm.LookupArray, _xlpm.ReturnArray, ""))
Name Common_InputFunctions.Utility_SourceHyperlink: _xlfn.LAMBDA(_xlpm.TargetCell, _xlfn.LET(_xlpm.sh, _xlfn.TEXTAFTER(CELL("filename", _xlpm.TargetCell), "]"), _xlpm.addr, CELL("address", _xlpm.TargetCell), "#'" & _xlpm.sh & "'!" & _xlpm.addr))
Name Common_SourceData.Common_SourceData_AustralianStatesTerritories_Source: _xlfn.LAMBDA("")
Name Common_SourceData.Common_SourceData_AustralianStatesTerritories_Title: _xlfn.LAMBDA("Australian states and territories")
Name Common_SourceData.Common_SourceData_AustralianStatesTerritories_Unit: _xlfn.LAMBDA("")
Name Common_SourceData.Common_SourceData_AustralianStatesTerritories_Variable: _xlfn.LAMBDA("")
Name Common_SourceData.Common_SourceData_ClimateZones_Source: _xlfn.LAMBDA("VEERG 2026: Table 1.3: Climate and Rainfall zone classifications and definitions")
Name Common_SourceData.Common_SourceData_ClimateZones_Title: _xlfn.LAMBDA("VEERG Australian climate zones")
Name Common_SourceData.Common_SourceData_ClimateZones_Unit: _xlfn.LAMBDA("")
Name Common_SourceData.Common_SourceData_ClimateZones_Variable: _xlfn.LAMBDA("")
Name Common_SourceData.Common_SourceData_ConvertGasElementalToMolecular_Source: _xlfn.LAMBDA("XXXXXXX")
Name Common_SourceData.Common_SourceData_ConvertGasElementalToMolecular_Title: _xlfn.LAMBDA("Factor to convert elemental mass of gas to molecular mass")
Name Common_SourceData.Common_SourceData_ConvertGasElementalToMolecular_Unit: _xlfn.LAMBDA("factor")
Name Common_SourceData.Common_SourceData_ConvertGasElementalToMolecular_Variable: _xlfn.LAMBDA("Cg")
Name Common_SourceData.Common_SourceData_ConvertN2oElementalToMolecularCg_Data: _xlfn.LAMBDA(44 / 28)
Name Common_SourceData.Common_SourceData_ConvertN2oElementalToMolecularCg_Source: _xlfn.LAMBDA("National Inventory Report 2023 Volume 1")
Name Common_SourceData.Common_SourceData_ConvertN2oElementalToMolecularCg_Title: _xlfn.LAMBDA("Factor to convert elemental mass of N2O to molecular mass")
Name Common_SourceData.Common_SourceData_ConvertN2oElementalToMolecularCg_Unit: _xlfn.LAMBDA("factor")
Name Common_SourceData.Common_SourceData_ConvertN2oElementalToMolecularCg_Variable: _xlfn.LAMBDA("CgN2O")
Name Common_SourceData.Common_SourceData_DataScores_Scope3_Source: _xlfn.LAMBDA("VEERG 2026: XXXXXXXX")
Name Common_SourceData.Common_SourceData_DataScores_Scope3_Title: _xlfn.LAMBDA("Australian data scores for scope 3")
Name Common_SourceData.Common_SourceData_DataScores_Scope3_Unit: _xlfn.LAMBDA("")
Name Common_SourceData.Common_SourceData_DataScores_Scope3_Variable: _xlfn.LAMBDA("")
Name Common_SourceData.Common_SourceData_DataScores_Scope3_Variation: _xlfn.LAMBDA("")
Name Common_SourceData.Common_SourceData_DensityOfMethane_Data: _xlfn.LAMBDA(0.6784)
Name Common_SourceData.Common_SourceData_DensityOfMethane_Source: _xlfn.LAMBDA("National Inventory Report 2023 Volume 1: Equations 3.B.1a_2, 3.B.1c_2, 3.B.3_1, 3.B.4g_2")
Name Common_SourceData.Common_SourceData_DensityOfMethane_Title: _xlfn.LAMBDA("p = density of methane")
Name Common_SourceData.Common_SourceData_DensityOfMethane_Unit: _xlfn.LAMBDA("kg/m3")
Name Common_SourceData.Common_SourceData_EFleach_Data: _xlfn.LAMBDA(_xlfn.MAKEARRAY(1, 2, _xlfn.LAMBDA(_xlpm.r,_xlpm.c, INDEX({"EFleach",0.011}, _xlpm.r, _xlpm.c))))
Name Common_SourceData.Common_SourceData_EFleach_NIRReference: _xlfn.LAMBDA("National Inventory Report Volume 1: Equation 3.D.B_10")
Name Common_SourceData.Common_SourceData_EFleach_Source: _xlfn.LAMBDA("VEERG 2026:5.5.2.3 Constant Parameters")
Name Common_SourceData.Common_SourceData_EFleach_Title: _xlfn.LAMBDA("Emission factor for nitrogen leaching and runoff")
Name Common_SourceData.Common_SourceData_EFleach_Unit: _xlfn.LAMBDA("(kg N2O-N / kg N")
Name Common_SourceData.Common_SourceData_EFleach_Variation: _xlfn.LAMBDA((""))
Name Common_SourceData.Common_SourceData_EFN2O_NIRReference: _xlfn.LAMBDA("")
Name Common_SourceData.Common_SourceData_EFN2O_Source: _xlfn.LAMBDA("VEERG 2026: Table A.2.2.1")
Name Common_SourceData.Common_SourceData_EFN2O_Title: _xlfn.LAMBDA("Nitrous oxide emission factors for inorganic fertiliser application")
Name Common_SourceData.Common_SourceData_EFN2O_Unit: _xlfn.LAMBDA("(kg N2O-N / kg N")
Name Common_SourceData.Common_SourceData_EFOrganicFertiliserAndCropResidues_Data: _xlfn.LAMBDA(_xlfn.MAKEARRAY(3, 2, _xlfn.LAMBDA(_xlpm.r,_xlpm.c, INDEX({"Climate zone","EFNi & EFN2O";"Wet climate zone",0.006;"Dry climate zone",0.005}, _xlpm.r, _xlpm.c))))
Name Common_SourceData.Common_SourceData_EFOrganicFertiliserAndCropResidues_NIRReference: _xlfn.LAMBDA("")
Name Common_SourceData.Common_SourceData_EFOrganicFertiliserAndCropResidues_Source: _xlfn.LAMBDA("VEERG 2026: Table A.2.1.4")

Sheet Home
A1: Home

Sheet Overview
A1: #VALUE! | C1: 3.6: Enteric Methane: Other Livestock: Overview
A3: =HYPERLINK("#'Home'!A1", "Home") -> Home
A4: =HYPERLINK("#'Overview'!A1", "Overview") -> Overview
A5: =HYPERLINK("#'Results'!A1", "Results") -> Results | D5: 💡 Below is a diagram that maps the equations used to calculate emissions and how they interact with each other.
D6: Click on a box to go to the corresponding calculation.
A7: INPUTS
A8: =HYPERLINK("#'Input - Site'!A1", "Site") -> Site
A9: =HYPERLINK("#'Input - Other Livestock'!A1", "Other Livestock") -> Other Livestock
A11: CALCULATIONS
A12: =HYPERLINK("#'3.6.1.1-2 Enteric Methane'!A1", "3.6.1.1-2 Enteric Methane") -> 3.6.1.1-2 Enteric Methane
A14: APPENDICES
A15: =HYPERLINK("#'Constants - Other Livestock'!A1", "Constants - Other Livestock") -> Constants - Other Livestock
A16: =HYPERLINK("#'Constants - Common'!A1", "Constants - Common") -> Constants - Common
A17: =HYPERLINK("#'Acknowledgements'!A1", "Acknowledgements") -> Acknowledgements

Sheet Results
A1: #VALUE! | C1: 3.6 Enteric Methane: Other Livestock: Results
A3: =HYPERLINK("#'Home'!A1", "Home") -> Home
A4: =HYPERLINK("#'Overview'!A1", "Overview") -> Overview | D4: Emissions breakdown
A5: =HYPERLINK("#'Results'!A1", "Results") -> Results
D6: Scope 1 source | E6: GHG emissions method 1 | F6: GHG emissions method 2 | G6: GHG Unit | H6: CO2-e emissions method 1 | I6: CO2-e emissions method 2 | J6: CO2-e unit
A7: INPUTS | D7: 3.1.1.1-2 Enteric Methane | E7: ='3.6.1.1-2 Enteric Methane'!E28 -> 630.7 | F7: =E7 -> 630.7 | G7: t CH4 | H7: ='3.6.1.1-2 Enteric Methane'!E33 -> 17659.6 | I7: =H7 -> 17659.6 | J7: t CO2e
A8: =HYPERLINK("#'Input - Site'!A1", "Site") -> Site | D8: Total | H8: =SUM(H7:H7) -> 17659.6 | I8: =SUM(I7:I7) -> 17659.6 | J8: t CO2e
A9: =HYPERLINK("#'Input - Other Livestock'!A1", "Other Livestock") -> Other Livestock
A11: CALCULATIONS
A12: =HYPERLINK("#'3.6.1.1-2 Enteric Methane'!A1", "3.6.1.1-2 Enteric Methane") -> 3.6.1.1-2 Enteric Methane
A14: APPENDICES
A15: =HYPERLINK("#'Constants - Other Livestock'!A1", "Constants - Other Livestock") -> Constants - Other Livestock
A16: =HYPERLINK("#'Constants - Common'!A1", "Constants - Common") -> Constants - Common
A17: =HYPERLINK("#'Acknowledgements'!A1", "Acknowledgements") -> Acknowledgements

Sheet Input - Site
A1: #VALUE! | C1: Input - Site
A3: =HYPERLINK("#'Home'!A1", "Home") -> Home
A4: =HYPERLINK("#'Overview'!A1", "Overview") -> Overview
A5: =HYPERLINK("#'Results'!A1", "Results") -> Results | D5: Your business
A7: INPUTS | D7: Farm name | E7: Test Farms
A8: =HYPERLINK("#'Input - Site'!A1", "Site") -> Site | D8: Reporting entity name | E8: Test Farms Pty Ltd
A9: =HYPERLINK("#'Input - Other Livestock'!A1", "Other Livestock") -> Other Livestock
D10: 💡An 'Emissions accounting period' is a 12 month period where the business can report on the emissions, and is typically the same as the business' financial accounting period.
A11: CALCULATIONS
A12: =HYPERLINK("#'3.6.1.1-2 Enteric Methane'!A1", "3.6.1.1-2 Enteric Methane") -> 3.6.1.1-2 Enteric Methane | D12: Emissions calculation period start date | E12: 45292 | F12: ← DD/MM/YYYY or DD Month YYYY
D13: Emissions calculation period end date | E13: =DATE(YEAR(E12)+1,MONTH(E12),DAY(E12))-1 -> 45657 | F13: ← Automatically calculated, 12 months after start date
A14: APPENDICES
A15: =HYPERLINK("#'Constants - Other Livestock'!A1", "Constants - Other Livestock") -> Constants - Other Livestock
A16: =HYPERLINK("#'Constants - Common'!A1", "Constants - Common") -> Constants - Common
A17: =HYPERLINK("#'Acknowledgements'!A1", "Acknowledgements") -> Acknowledgements

Sheet Input - Other Livestock
A1: #VALUE! | C1: Input - Other Livestock
A3: =HYPERLINK("#'Home'!A1", "Home") -> Home
A4: =HYPERLINK("#'Overview'!A1", "Overview") -> Overview
A5: =HYPERLINK("#'Results'!A1", "Results") -> Results | D5: Buffalo
A7: INPUTS | E7: Bulls | F7: Cows | G7: Steers | H7: Calves
A8: =HYPERLINK("#'Input - Site'!A1", "Site") -> Site | D8: ="Average number of head between " & TEXT('Input - Site'!$E$12, "dd mmm yy") & " and " & TEXT('Input - Site'!$E$13, "dd mmm yy") -> Average number of head between 01 Jan 24 and 31 Dec 24 | E8: 4300 | F8: 100 | G8: 100 | H8: 100 | I8: head
A9: =HYPERLINK("#'Input - Other Livestock'!A1", "Other Livestock") -> Other Livestock
A11: CALCULATIONS | D11: Goats
A12: =HYPERLINK("#'3.6.1.1-2 Enteric Methane'!A1", "3.6.1.1-2 Enteric Methane") -> 3.6.1.1-2 Enteric Methane
E13: Bucks / billy | F13: Wethers | G13: Maiden breeding does / nannies | H13: Breeding does / nannies | I13: Other | J13: Kids
A14: APPENDICES | D14: ="Average number of head between " & TEXT('Input - Site'!$E$12, "dd mmm yy") & " and " & TEXT('Input - Site'!$E$13, "dd mmm yy") -> Average number of head between 01 Jan 24 and 31 Dec 24 | E14: 4300 | F14: 100 | G14: 100 | H14: 100 | I14: 100 | J14: 100 | K14: head
A15: =HYPERLINK("#'Constants - Other Livestock'!A1", "Constants - Other Livestock") -> Constants - Other Livestock
A16: =HYPERLINK("#'Constants - Common'!A1", "Constants - Common") -> Constants - Common
A17: =HYPERLINK("#'Acknowledgements'!A1", "Acknowledgements") -> Acknowledgements | D17: Deer
E19: Bucks | F19: Breeding does | G19: Other does | H19: Fawn
D20: ="Average number of head between " & TEXT('Input - Site'!$E$12, "dd mmm yy") & " and " & TEXT('Input - Site'!$E$13, "dd mmm yy") -> Average number of head between 01 Jan 24 and 31 Dec 24 | E20: 4300 | F20: 100 | G20: 100 | H20: 100 | I20: head
D23: Others
E25: Camels | F25: Alpacas | G25: Horses | H25: Mules / asses | I25: Emus / ostriches
D26: ="Average number of head between " & TEXT('Input - Site'!$E$12, "dd mmm yy") & " and " & TEXT('Input - Site'!$E$13, "dd mmm yy") -> Average number of head between 01 Jan 24 and 31 Dec 24 | E26: 4300 | F26: 100 | G26: 100 | H26: 100 | I26: 100 | J26: head

Sheet 3.6.1.1-2 Enteric Methane
A1: #VALUE! | C1: 3.6.1.1-2 Manure Methane
A3: =HYPERLINK("#'Home'!A1", "Home") -> Home | D3: Method 1 | M3: Method 2
A4: =HYPERLINK("#'Overview'!A1", "Overview") -> Overview
A5: =HYPERLINK("#'Results'!A1", "Results") -> Results | D5: {=EntericMethane_OtherLivestock_Equations.VEERG_3_6_1_1__1_TotalAnnualMethaneFromEntericFermentationOtherLivestock_Title()} -> Total annual methane production from enteric fermentation in other livestock
D6: {=EntericMethane_OtherLivestock_Equations.VEERG_3_6_1_1__1_TotalAnnualMethaneFromEntericFermentationOtherLivestock_Source()} -> VEERG 2026: 3.6.1.1, Equation (1)
A7: INPUTS | D7: Function name | E7: {=Common_InputFunctions.Utility_DisplayFunctionName(G19)} -> =EntericMethane_OtherLivestock_Equations.VEERG_3_6_1_1__1_TotalAnnualMethaneFromEntericFermentationOtherLivestock
A8: =HYPERLINK("#'Input - Site'!A1", "Site") -> Site
A9: =HYPERLINK("#'Input - Other Livestock'!A1", "Other Livestock") -> Other Livestock
D10: Variable | E10: {=EntericMethane_OtherLivestock_Equations.VEERG_3_6_1_1__1_TotalAnnualMethaneFromEntericFermentationOtherLivestock_Variable()} -> E_enteric
A11: CALCULATIONS | D11: Unit | E11: {=EntericMethane_OtherLivestock_Equations.VEERG_3_6_1_1__1_TotalAnnualMethaneFromEntericFermentationOtherLivestock_Unit()} -> t CH4
A12: =HYPERLINK("#'3.6.1.1-2 Enteric Methane'!A1", "3.6.1.1-2 Enteric Methane") -> 3.6.1.1-2 Enteric Methane
D13: {=_xlfn.CHOOSECOLS(EntericMethane_OtherLivestock_Equations.VEERG_3_6_1_1__1_TotalAnnualMethaneFromEntericFermentationOtherLivestock_Arguments(),1,2)} -> N_j | E13: number of livestock of each livestock type j | G13: {=_xlfn.CHOOSECOLS(EntericMethane_OtherLivestock_Equations.VEERG_3_6_1_1__1_TotalAnnualMethaneFromEntericFermentationOtherLivestock_Arguments(),3,4)} -> head | H13: Input
A14: APPENDICES | D14: M_j | E14: enteric fermentation emission factor | G14: kg CH4/head/year | H14: Constant
A15: =HYPERLINK("#'Constants - Other Livestock'!A1", "Constants - Other Livestock") -> Constants - Other Livestock | D15: j | E15: livestock type | H15: Input
A16: =HYPERLINK("#'Constants - Common'!A1", "Constants - Common") -> Constants - Common
A17: =HYPERLINK("#'Acknowledgements'!A1", "Acknowledgements") -> Acknowledgements
D18: Livestock type | E18: Nj | F18: Mj | G18: Eenteric
D19: ='Constants - Other Livestock'!D10 -> Buffalo | E19: =SUM(X_Table_OtherLivestock_Buffalo_Head) -> 4600 | F19: {=Common_InputFunctions.Utility_LookupValueInTableNumber(D19, Table_SourceData_OtherLivestock_EntericEF[Other livestock type],Table_SourceData_OtherLivestock_EntericEF[Mj])} -> 68 | G19: {=EntericMethane_OtherLivestock_Equations.VEERG_3_6_1_1__1_TotalAnnualMethaneFromEntericFermentationOtherLivestock(E19,F19)} -> 312.8 | H19: =$E$11 -> t CH4
D20: ='Constants - Other Livestock'!D11 -> Goats | E20: =SUM(X_Table_OtherLivestock_Goats_Head) -> 4800 | F20: {=Common_InputFunctions.Utility_LookupValueInTableNumber(D20, Table_SourceData_OtherLivestock_EntericEF[Other livestock type],Table_SourceData_OtherLivestock_EntericEF[Mj])} -> 5 | G20: {=EntericMethane_OtherLivestock_Equations.VEERG_3_6_1_1__1_TotalAnnualMethaneFromEntericFermentationOtherLivestock(E20,F20)} -> 24
D21: ='Constants - Other Livestock'!D12 -> Deer | E21: =SUM(X_Table_OtherLivestock_Deer_Head) -> 4600 | F21: {=Common_InputFunctions.Utility_LookupValueInTableNumber(D21, Table_SourceData_OtherLivestock_EntericEF[Other livestock type],Table_SourceData_OtherLivestock_EntericEF[Mj])} -> 20 | G21: {=EntericMethane_OtherLivestock_Equations.VEERG_3_6_1_1__1_TotalAnnualMethaneFromEntericFermentationOtherLivestock(E21,F21)} -> 92
D22: ='Constants - Other Livestock'!D13 -> Camels | E22: =X_Cell_OtherLivestock_Others_Camels_Head -> 4300 | F22: {=Common_InputFunctions.Utility_LookupValueInTableNumber(D22, Table_SourceData_OtherLivestock_EntericEF[Other livestock type],Table_SourceData_OtherLivestock_EntericEF[Mj])} -> 46 | G22: {=EntericMethane_OtherLivestock_Equations.VEERG_3_6_1_1__1_TotalAnnualMethaneFromEntericFermentationOtherLivestock(E22,F22)} -> 197.8
D23: ='Constants - Other Livestock'!D14 -> Alpacas | E23: =X_Cell_OtherLivestock_Others_Alpacas_Head -> 100 | F23: {=Common_InputFunctions.Utility_LookupValueInTableNumber(D23, Table_SourceData_OtherLivestock_EntericEF[Other livestock type],Table_SourceData_OtherLivestock_EntericEF[Mj])} -> 8 | G23: {=EntericMethane_OtherLivestock_Equations.VEERG_3_6_1_1__1_TotalAnnualMethaneFromEntericFermentationOtherLivestock(E23,F23)} -> 0.8
D24: ='Constants - Other Livestock'!D15 -> Horses | E24: =X_Cell_OtherLivestock_Others_Horses_Head -> 100 | F24: {=Common_InputFunctions.Utility_LookupValueInTableNumber(D24, Table_SourceData_OtherLivestock_EntericEF[Other livestock type],Table_SourceData_OtherLivestock_EntericEF[Mj])} -> 18 | G24: {=EntericMethane_OtherLivestock_Equations.VEERG_3_6_1_1__1_TotalAnnualMethaneFromEntericFermentationOtherLivestock(E24,F24)} -> 1.8
D25: ='Constants - Other Livestock'!D16 -> Mules/asses | E25: =X_Cell_OtherLivestock_Others_Mules_Head -> 100 | F25: {=Common_InputFunctions.Utility_LookupValueInTableNumber(D25, Table_SourceData_OtherLivestock_EntericEF[Other livestock type],Table_SourceData_OtherLivestock_EntericEF[Mj])} -> 10 | G25: {=EntericMethane_OtherLivestock_Equations.VEERG_3_6_1_1__1_TotalAnnualMethaneFromEntericFermentationOtherLivestock(E25,F25)} -> 1
D26: ='Constants - Other Livestock'!D17 -> Emus/ostriches | E26: =X_Cell_OtherLivestock_Others_Emus_Head -> 100 | F26: {=Common_InputFunctions.Utility_LookupValueInTableNumber(D26, Table_SourceData_OtherLivestock_EntericEF[Other livestock type],Table_SourceData_OtherLivestock_EntericEF[Mj])} -> 5 | G26: {=EntericMethane_OtherLivestock_Equations.VEERG_3_6_1_1__1_TotalAnnualMethaneFromEntericFermentationOtherLivestock(E26,F26)} -> 0.5
D28: Eenteric | E28: =SUM(G19:G26) -> 630.7 | F28: =$E$11 -> t CH4
D30: {=Common_Equations.Common_ConvertCH4ToCO2e_Arguments()} -> ECH4 | E30: Methane emissions (t CH4) | G30: =E28 -> 630.7 | H30: =E11 -> t CH4
D31: GWPCH4 | E31: Global warming potential for methane (t CO2-e / t CH4) | G31: =Common_InputFunctions.Utility_LookupValueInTableNumber("CH4",Table_GWPData[Gas],Table_GWPData[CO2-e factor]) -> 28
D33: ECO2e (Method 1) | E33: {=Common_Equations.Common_ConvertCH4ToCO2e(G30,G31)} -> 17659.6 | F33: {=Common_Equations.Common_ConvertN2OToCO2e_Unit()} -> t CO2e

Sheet Constants - Other Livestock
A1: #VALUE! | C1: Source Data - Other Livestock
A3: =HYPERLINK("#'Home'!A1", "Home") -> Home
A4: =HYPERLINK("#'Overview'!A1", "Overview") -> Overview
A5: =HYPERLINK("#'Results'!A1", "Results") -> Results | D5: {=SourceData_OtherLivestock.SourceData_OtherLivestock_EntericFermentationEmissionFactor_Title()} -> Other Livestock - Enteric fermentation emission factor for each other livestock type
D6: {=SourceData_OtherLivestock.SourceData_OtherLivestock_EntericFermentationEmissionFactor_Source()} -> VEERG 2026: Table A.1.5.1
A7: INPUTS | D7: {=SourceData_OtherLivestock.SourceData_OtherLivestock_EntericFermentationEmissionFactor_Variable()} -> Mj
A8: =HYPERLINK("#'Input - Site'!A1", "Site") -> Site | D8: {=SourceData_OtherLivestock.SourceData_OtherLivestock_EntericFermentationEmissionFactor_Unit()} -> kg CH4 / head / year
A9: =HYPERLINK("#'Input - Other Livestock'!A1", "Other Livestock") -> Other Livestock | D9: Other livestock type | E9: Mj
D10: {=Common_InputFunctions.Utility_DisplayArrayInTable(SourceData_OtherLivestock.SourceData_OtherLivestock_EntericFermentationEmissionFactor_Data(),Table_SourceData_OtherLivestock_EntericEF[[#Headers],[Other livestock type]],0)} -> Buffalo | E10: {=Common_InputFunctions.Utility_DisplayArrayInTable(SourceData_OtherLivestock.SourceData_OtherLivestock_EntericFermentationEmissionFactor_Data(),Table_SourceData_OtherLivestock_EntericEF[[#Headers],[Other livestock type]],0)} -> 68
A11: CALCULATIONS | D11: {=Common_InputFunctions.Utility_DisplayArrayInTable(SourceData_OtherLivestock.SourceData_OtherLivestock_EntericFermentationEmissionFactor_Data(),Table_SourceData_OtherLivestock_EntericEF[[#Headers],[Other livestock type]],0)} -> Goats | E11: {=Common_InputFunctions.Utility_DisplayArrayInTable(SourceData_OtherLivestock.SourceData_OtherLivestock_EntericFermentationEmissionFactor_Data(),Table_SourceData_OtherLivestock_EntericEF[[#Headers],[Other livestock type]],0)} -> 5
A12: =HYPERLINK("#'3.6.1.1-2 Enteric Methane'!A1", "3.6.1.1-2 Enteric Methane") -> 3.6.1.1-2 Enteric Methane | D12: {=Common_InputFunctions.Utility_DisplayArrayInTable(SourceData_OtherLivestock.SourceData_OtherLivestock_EntericFermentationEmissionFactor_Data(),Table_SourceData_OtherLivestock_EntericEF[[#Headers],[Other livestock type]],0)} -> Deer | E12: {=Common_InputFunctions.Utility_DisplayArrayInTable(SourceData_OtherLivestock.SourceData_OtherLivestock_EntericFermentationEmissionFactor_Data(),Table_SourceData_OtherLivestock_EntericEF[[#Headers],[Other livestock type]],0)} -> 20
D13: {=Common_InputFunctions.Utility_DisplayArrayInTable(SourceData_OtherLivestock.SourceData_OtherLivestock_EntericFermentationEmissionFactor_Data(),Table_SourceData_OtherLivestock_EntericEF[[#Headers],[Other livestock type]],0)} -> Camels | E13: {=Common_InputFunctions.Utility_DisplayArrayInTable(SourceData_OtherLivestock.SourceData_OtherLivestock_EntericFermentationEmissionFactor_Data(),Table_SourceData_OtherLivestock_EntericEF[[#Headers],[Other livestock type]],0)} -> 46
A14: APPENDICES | D14: {=Common_InputFunctions.Utility_DisplayArrayInTable(SourceData_OtherLivestock.SourceData_OtherLivestock_EntericFermentationEmissionFactor_Data(),Table_SourceData_OtherLivestock_EntericEF[[#Headers],[Other livestock type]],0)} -> Alpacas | E14: {=Common_InputFunctions.Utility_DisplayArrayInTable(SourceData_OtherLivestock.SourceData_OtherLivestock_EntericFermentationEmissionFactor_Data(),Table_SourceData_OtherLivestock_EntericEF[[#Headers],[Other livestock type]],0)} -> 8
A15: =HYPERLINK("#'Constants - Other Livestock'!A1", "Constants - Other Livestock") -> Constants - Other Livestock | D15: {=Common_InputFunctions.Utility_DisplayArrayInTable(SourceData_OtherLivestock.SourceData_OtherLivestock_EntericFermentationEmissionFactor_Data(),Table_SourceData_OtherLivestock_EntericEF[[#Headers],[Other livestock type]],0)} -> Horses | E15: {=Common_InputFunctions.Utility_DisplayArrayInTable(SourceData_OtherLivestock.SourceData_OtherLivestock_EntericFermentationEmissionFactor_Data(),Table_SourceData_OtherLivestock_EntericEF[[#Headers],[Other livestock type]],0)} -> 18
A16: =HYPERLINK("#'Constants - Common'!A1", "Constants - Common") -> Constants - Common | D16: {=Common_InputFunctions.Utility_DisplayArrayInTable(SourceData_OtherLivestock.SourceData_OtherLivestock_EntericFermentationEmissionFactor_Data(),Table_SourceData_OtherLivestock_EntericEF[[#Headers],[Other livestock type]],0)} -> Mules/asses | E16: {=Common_InputFunctions.Utility_DisplayArrayInTable(SourceData_OtherLivestock.SourceData_OtherLivestock_EntericFermentationEmissionFactor_Data(),Table_SourceData_OtherLivestock_EntericEF[[#Headers],[Other livestock type]],0)} -> 10
A17: =HYPERLINK("#'Acknowledgements'!A1", "Acknowledgements") -> Acknowledgements | D17: {=Common_InputFunctions.Utility_DisplayArrayInTable(SourceData_OtherLivestock.SourceData_OtherLivestock_EntericFermentationEmissionFactor_Data(),Table_SourceData_OtherLivestock_EntericEF[[#Headers],[Other livestock type]],0)} -> Emus/ostriches | E17: {=Common_InputFunctions.Utility_DisplayArrayInTable(SourceData_OtherLivestock.SourceData_OtherLivestock_EntericFermentationEmissionFactor_Data(),Table_SourceData_OtherLivestock_EntericEF[[#Headers],[Other livestock type]],0)} -> 5
D20: {=SourceData_OtherLivestock.SourceData_OtherLivestock_VolatileSolidsProduced_Title()} -> Other Livestock - Volatile solids produced by each other livestock type
D21: {=SourceData_OtherLivestock.SourceData_OtherLivestock_VolatileSolidsProduced_Source()} -> VEERG 2026: Table A.1.5.2
D22: {=SourceData_OtherLivestock.SourceData_OtherLivestock_VolatileSolidsProduced_Variable()} -> VSj
D23: {=SourceData_OtherLivestock.SourceData_OtherLivestock_VolatileSolidsProduced_Unit()} -> kg VS / head / day
D24: Other livestock type | E24: VSj
D25: {=Common_InputFunctions.Utility_DisplayArrayInTable(SourceData_OtherLivestock.SourceData_OtherLivestock_VolatileSolidsProduced_Data(),Table_SourceData_OtherLivestock_VolatileSolids[[#Headers],[Other livestock type]],0)} -> Buffalo | E25: {=Common_InputFunctions.Utility_DisplayArrayInTable(SourceData_OtherLivestock.SourceData_OtherLivestock_VolatileSolidsProduced_Data(),Table_SourceData_OtherLivestock_VolatileSolids[[#Headers],[Other livestock type]],0)} -> 2.73
D26: {=Common_InputFunctions.Utility_DisplayArrayInTable(SourceData_OtherLivestock.SourceData_OtherLivestock_VolatileSolidsProduced_Data(),Table_SourceData_OtherLivestock_VolatileSolids[[#Headers],[Other livestock type]],0)} -> Goats | E26: {=Common_InputFunctions.Utility_DisplayArrayInTable(SourceData_OtherLivestock.SourceData_OtherLivestock_VolatileSolidsProduced_Data(),Table_SourceData_OtherLivestock_VolatileSolids[[#Headers],[Other livestock type]],0)} -> 0.34
D27: {=Common_InputFunctions.Utility_DisplayArrayInTable(SourceData_OtherLivestock.SourceData_OtherLivestock_VolatileSolidsProduced_Data(),Table_SourceData_OtherLivestock_VolatileSolids[[#Headers],[Other livestock type]],0)} -> Deer | E27: {=Common_InputFunctions.Utility_DisplayArrayInTable(SourceData_OtherLivestock.SourceData_OtherLivestock_VolatileSolidsProduced_Data(),Table_SourceData_OtherLivestock_VolatileSolids[[#Headers],[Other livestock type]],0)} -> 0.91
D28: {=Common_InputFunctions.Utility_DisplayArrayInTable(SourceData_OtherLivestock.SourceData_OtherLivestock_VolatileSolidsProduced_Data(),Table_SourceData_OtherLivestock_VolatileSolids[[#Headers],[Other livestock type]],0)} -> Camels | E28: {=Common_InputFunctions.Utility_DisplayArrayInTable(SourceData_OtherLivestock.SourceData_OtherLivestock_VolatileSolidsProduced_Data(),Table_SourceData_OtherLivestock_VolatileSolids[[#Headers],[Other livestock type]],0)} -> 2.73
D29: {=Common_InputFunctions.Utility_DisplayArrayInTable(SourceData_OtherLivestock.SourceData_OtherLivestock_VolatileSolidsProduced_Data(),Table_SourceData_OtherLivestock_VolatileSolids[[#Headers],[Other livestock type]],0)} -> Alpacas | E29: {=Common_InputFunctions.Utility_DisplayArrayInTable(SourceData_OtherLivestock.SourceData_OtherLivestock_VolatileSolidsProduced_Data(),Table_SourceData_OtherLivestock_VolatileSolids[[#Headers],[Other livestock type]],0)} -> 0.34
D30: {=Common_InputFunctions.Utility_DisplayArrayInTable(SourceData_OtherLivestock.SourceData_OtherLivestock_VolatileSolidsProduced_Data(),Table_SourceData_OtherLivestock_VolatileSolids[[#Headers],[Other livestock type]],0)} -> Horses | E30: {=Common_InputFunctions.Utility_DisplayArrayInTable(SourceData_OtherLivestock.SourceData_OtherLivestock_VolatileSolidsProduced_Data(),Table_SourceData_OtherLivestock_VolatileSolids[[#Headers],[Other livestock type]],0)} -> 2.73
D31: {=Common_InputFunctions.Utility_DisplayArrayInTable(SourceData_OtherLivestock.SourceData_OtherLivestock_VolatileSolidsProduced_Data(),Table_SourceData_OtherLivestock_VolatileSolids[[#Headers],[Other livestock type]],0)} -> Mules/asses | E31: {=Common_InputFunctions.Utility_DisplayArrayInTable(SourceData_OtherLivestock.SourceData_OtherLivestock_VolatileSolidsProduced_Data(),Table_SourceData_OtherLivestock_VolatileSolids[[#Headers],[Other livestock type]],0)} -> 0.91
D32: {=Common_InputFunctions.Utility_DisplayArrayInTable(SourceData_OtherLivestock.SourceData_OtherLivestock_VolatileSolidsProduced_Data(),Table_SourceData_OtherLivestock_VolatileSolids[[#Headers],[Other livestock type]],0)} -> Emus/ostriches | E32: {=Common_InputFunctions.Utility_DisplayArrayInTable(SourceData_OtherLivestock.SourceData_OtherLivestock_VolatileSolidsProduced_Data(),Table_SourceData_OtherLivestock_VolatileSolids[[#Headers],[Other livestock type]],0)} -> 0.34
D35: {=SourceData_OtherLivestock.SourceData_OtherLivestock_NitrogenExcreted_Title()} -> Other Livestock - Nitrogen excreted per livestock type
D36: {=SourceData_OtherLivestock.SourceData_OtherLivestock_NitrogenExcreted_Source()} -> VEERG 2026: Table A.1.5.3
D37: {=SourceData_OtherLivestock.SourceData_OtherLivestock_NitrogenExcreted_Variable()} -> NEj
D38: {=SourceData_OtherLivestock.SourceData_OtherLivestock_NitrogenExcreted_Unit()} -> kg N2O / head / year
D39: Other livestock type | E39: NEj
D40: {=Common_InputFunctions.Utility_DisplayArrayInTable(SourceData_OtherLivestock.SourceData_OtherLivestock_NitrogenExcreted_Data(),Table_SourceData_OtherLivestock_NitrogenExcreted[[#Headers],[Other livestock type]],0)} -> Buffalo | E40: {=Common_InputFunctions.Utility_DisplayArrayInTable(SourceData_OtherLivestock.SourceData_OtherLivestock_NitrogenExcreted_Data(),Table_SourceData_OtherLivestock_NitrogenExcreted[[#Headers],[Other livestock type]],0)} -> 39.5
D41: {=Common_InputFunctions.Utility_DisplayArrayInTable(SourceData_OtherLivestock.SourceData_OtherLivestock_NitrogenExcreted_Data(),Table_SourceData_OtherLivestock_NitrogenExcreted[[#Headers],[Other livestock type]],0)} -> Goats | E41: {=Common_InputFunctions.Utility_DisplayArrayInTable(SourceData_OtherLivestock.SourceData_OtherLivestock_NitrogenExcreted_Data(),Table_SourceData_OtherLivestock_NitrogenExcreted[[#Headers],[Other livestock type]],0)} -> 7
D42: {=Common_InputFunctions.Utility_DisplayArrayInTable(SourceData_OtherLivestock.SourceData_OtherLivestock_NitrogenExcreted_Data(),Table_SourceData_OtherLivestock_NitrogenExcreted[[#Headers],[Other livestock type]],0)} -> Deer | E42: {=Common_InputFunctions.Utility_DisplayArrayInTable(SourceData_OtherLivestock.SourceData_OtherLivestock_NitrogenExcreted_Data(),Table_SourceData_OtherLivestock_NitrogenExcreted[[#Headers],[Other livestock type]],0)} -> 13.2
D43: {=Common_InputFunctions.Utility_DisplayArrayInTable(SourceData_OtherLivestock.SourceData_OtherLivestock_NitrogenExcreted_Data(),Table_SourceData_OtherLivestock_NitrogenExcreted[[#Headers],[Other livestock type]],0)} -> Camels | E43: {=Common_InputFunctions.Utility_DisplayArrayInTable(SourceData_OtherLivestock.SourceData_OtherLivestock_NitrogenExcreted_Data(),Table_SourceData_OtherLivestock_NitrogenExcreted[[#Headers],[Other livestock type]],0)} -> 39.5
D44: {=Common_InputFunctions.Utility_DisplayArrayInTable(SourceData_OtherLivestock.SourceData_OtherLivestock_NitrogenExcreted_Data(),Table_SourceData_OtherLivestock_NitrogenExcreted[[#Headers],[Other livestock type]],0)} -> Alpacas | E44: {=Common_InputFunctions.Utility_DisplayArrayInTable(SourceData_OtherLivestock.SourceData_OtherLivestock_NitrogenExcreted_Data(),Table_SourceData_OtherLivestock_NitrogenExcreted[[#Headers],[Other livestock type]],0)} -> 7
D45: {=Common_InputFunctions.Utility_DisplayArrayInTable(SourceData_OtherLivestock.SourceData_OtherLivestock_NitrogenExcreted_Data(),Table_SourceData_OtherLivestock_NitrogenExcreted[[#Headers],[Other livestock type]],0)} -> Horses | E45: {=Common_InputFunctions.Utility_DisplayArrayInTable(SourceData_OtherLivestock.SourceData_OtherLivestock_NitrogenExcreted_Data(),Table_SourceData_OtherLivestock_NitrogenExcreted[[#Headers],[Other livestock type]],0)} -> 39.5
...

Sheet Constants - Common
A1: #VALUE! | C1: Constants - Common
D5: {=Common_SourceData.Common_SourceData_AustralianStatesTerritories_Title()} -> Australian states and territories
D6: State/Territory | E6: Common Name | F6: Abbreviation
D7: {=Common_InputFunctions.Utility_DisplayArrayInTable(Common_SourceData.Common_SourceData_AustralianStatesTerritories_Data(),Table_AustralianStates[[#Headers],[State/Territory]],0)} -> New South Wales | E7: {=Common_InputFunctions.Utility_DisplayArrayInTable(Common_SourceData.Common_SourceData_AustralianStatesTerritories_Data(),Table_AustralianStates[[#Headers],[State/Territory]],0)} -> New South Wales | F7: {=Common_InputFunctions.Utility_DisplayArrayInTable(Common_SourceData.Common_SourceData_AustralianStatesTerritories_Data(),Table_AustralianStates[[#Headers],[State/Territory]],0)} -> NSW
D8: {=Common_InputFunctions.Utility_DisplayArrayInTable(Common_SourceData.Common_SourceData_AustralianStatesTerritories_Data(),Table_AustralianStates[[#Headers],[State/Territory]],0)} -> Australian Capital Territory | E8: {=Common_InputFunctions.Utility_DisplayArrayInTable(Common_SourceData.Common_SourceData_AustralianStatesTerritories_Data(),Table_AustralianStates[[#Headers],[State/Territory]],0)} -> ACT | F8: {=Common_InputFunctions.Utility_DisplayArrayInTable(Common_SourceData.Common_SourceData_AustralianStatesTerritories_Data(),Table_AustralianStates[[#Headers],[State/Territory]],0)} -> ACT
D9: {=Common_InputFunctions.Utility_DisplayArrayInTable(Common_SourceData.Common_SourceData_AustralianStatesTerritories_Data(),Table_AustralianStates[[#Headers],[State/Territory]],0)} -> Victoria | E9: {=Common_InputFunctions.Utility_DisplayArrayInTable(Common_SourceData.Common_SourceData_AustralianStatesTerritories_Data(),Table_AustralianStates[[#Headers],[State/Territory]],0)} -> Victoria | F9: {=Common_InputFunctions.Utility_DisplayArrayInTable(Common_SourceData.Common_SourceData_AustralianStatesTerritories_Data(),Table_AustralianStates[[#Headers],[State/Territory]],0)} -> VIC
D10: {=Common_InputFunctions.Utility_DisplayArrayInTable(Common_SourceData.Common_SourceData_AustralianStatesTerritories_Data(),Table_AustralianStates[[#Headers],[State/Territory]],0)} -> Queensland | E10: {=Common_InputFunctions.Utility_DisplayArrayInTable(Common_SourceData.Common_SourceData_AustralianStatesTerritories_Data(),Table_AustralianStates[[#Headers],[State/Territory]],0)} -> Queensland | F10: {=Common_InputFunctions.Utility_DisplayArrayInTable(Common_SourceData.Common_SourceData_AustralianStatesTerritories_Data(),Table_AustralianStates[[#Headers],[State/Territory]],0)} -> QLD
D11: {=Common_InputFunctions.Utility_DisplayArrayInTable(Common_SourceData.Common_SourceData_AustralianStatesTerritories_Data(),Table_AustralianStates[[#Headers],[State/Territory]],0)} -> South Australia | E11: {=Common_InputFunctions.Utility_DisplayArrayInTable(Common_SourceData.Common_SourceData_AustralianStatesTerritories_Data(),Table_AustralianStates[[#Headers],[State/Territory]],0)} -> South Australia | F11: {=Common_InputFunctions.Utility_DisplayArrayInTable(Common_SourceData.Common_SourceData_AustralianStatesTerritories_Data(),Table_AustralianStates[[#Headers],[State/Territory]],0)} -> SA
D12: {=Common_InputFunctions.Utility_DisplayArrayInTable(Common_SourceData.Common_SourceData_AustralianStatesTerritories_Data(),Table_AustralianStates[[#Headers],[State/Territory]],0)} -> Western Australia | E12: {=Common_InputFunctions.Utility_DisplayArrayInTable(Common_SourceData.Common_SourceData_AustralianStatesTerritories_Data(),Table_AustralianStates[[#Headers],[State/Territory]],0)} -> Western Australia | F12: {=Common_InputFunctions.Utility_DisplayArrayInTable(Common_SourceData.Common_SourceData_AustralianStatesTerritories_Data(),Table_AustralianStates[[#Headers],[State/Territory]],0)} -> WA
D13: {=Common_InputFunctions.Utility_DisplayArrayInTable(Common_SourceData.Common_SourceData_AustralianStatesTerritories_Data(),Table_AustralianStates[[#Headers],[State/Territory]],0)} -> Tasmania | E13: {=Common_InputFunctions.Utility_DisplayArrayInTable(Common_SourceData.Common_SourceData_AustralianStatesTerritories_Data(),Table_AustralianStates[[#Headers],[State/Territory]],0)} -> Tasmania | F13: {=Common_InputFunctions.Utility_DisplayArrayInTable(Common_SourceData.Common_SourceData_AustralianStatesTerritories_Data(),Table_AustralianStates[[#Headers],[State/Territory]],0)} -> TAS
D14: {=Common_InputFunctions.Utility_DisplayArrayInTable(Common_SourceData.Common_SourceData_AustralianStatesTerritories_Data(),Table_AustralianStates[[#Headers],[State/Territory]],0)} -> Northern Territory | E14: {=Common_InputFunctions.Utility_DisplayArrayInTable(Common_SourceData.Common_SourceData_AustralianStatesTerritories_Data(),Table_AustralianStates[[#Headers],[State/Territory]],0)} -> Northern Territory | F14: {=Common_InputFunctions.Utility_DisplayArrayInTable(Common_SourceData.Common_SourceData_AustralianStatesTerritories_Data(),Table_AustralianStates[[#Headers],[State/Territory]],0)} -> NT
D18: {=Common_SourceData.Common_SourceData_WASA4Areas_Title()} -> ABS Statistcal Areas Level 4 - Western Australia
D19: {=Common_SourceData.Common_SourceData_WASA4Areas_Source()} -> Australian Bureau of Statistics (ABS) - Statistical Areas Level 2 - 2021 - Shapefile
D20: SA 4 Name
D21: {=Common_InputFunctions.Utility_DisplayArrayInTable(Common_SourceData.Common_SourceData_WASA4Areas_Data(), Table_WASA4Areas[[#Headers],[SA 4 Name]], 0)} -> Bunbury
D22: {=Common_InputFunctions.Utility_DisplayArrayInTable(Common_SourceData.Common_SourceData_WASA4Areas_Data(), Table_WASA4Areas[[#Headers],[SA 4 Name]], 0)} -> Mandurah
D23: {=Common_InputFunctions.Utility_DisplayArrayInTable(Common_SourceData.Common_SourceData_WASA4Areas_Data(), Table_WASA4Areas[[#Headers],[SA 4 Name]], 0)} -> Perth - Inner
D24: {=Common_InputFunctions.Utility_DisplayArrayInTable(Common_SourceData.Common_SourceData_WASA4Areas_Data(), Table_WASA4Areas[[#Headers],[SA 4 Name]], 0)} -> Perth - North East
D25: {=Common_InputFunctions.Utility_DisplayArrayInTable(Common_SourceData.Common_SourceData_WASA4Areas_Data(), Table_WASA4Areas[[#Headers],[SA 4 Name]], 0)} -> Perth - North West
D26: {=Common_InputFunctions.Utility_DisplayArrayInTable(Common_SourceData.Common_SourceData_WASA4Areas_Data(), Table_WASA4Areas[[#Headers],[SA 4 Name]], 0)} -> Perth - South East
D27: {=Common_InputFunctions.Utility_DisplayArrayInTable(Common_SourceData.Common_SourceData_WASA4Areas_Data(), Table_WASA4Areas[[#Headers],[SA 4 Name]], 0)} -> Perth - South West
D28: {=Common_InputFunctions.Utility_DisplayArrayInTable(Common_SourceData.Common_SourceData_WASA4Areas_Data(), Table_WASA4Areas[[#Headers],[SA 4 Name]], 0)} -> Western Australia - Wheat Belt
D29: {=Common_InputFunctions.Utility_DisplayArrayInTable(Common_SourceData.Common_SourceData_WASA4Areas_Data(), Table_WASA4Areas[[#Headers],[SA 4 Name]], 0)} -> Western Australia - Outback (North)
D30: {=Common_InputFunctions.Utility_DisplayArrayInTable(Common_SourceData.Common_SourceData_WASA4Areas_Data(), Table_WASA4Areas[[#Headers],[SA 4 Name]], 0)} -> Western Australia - Outback (South)
D34: {=Common_SourceData.Common_SourceData_GWP_Title()} -> Global warming potential for greenhouse gases
D35: {=Common_SourceData.Common_SourceData_GWP_Source()} -> XXXXXXX
D36: Gas | E36: CO2-e factor
D37: {=Common_InputFunctions.Utility_DisplayArrayInTable(Common_SourceData.Common_SourceData_GWP_Data(), Table_GWPData[[#Headers],[Gas]], 0)} -> CO2 | E37: {=Common_InputFunctions.Utility_DisplayArrayInTable(Common_SourceData.Common_SourceData_GWP_Data(), Table_GWPData[[#Headers],[Gas]], 0)} -> 1
D38: {=Common_InputFunctions.Utility_DisplayArrayInTable(Common_SourceData.Common_SourceData_GWP_Data(), Table_GWPData[[#Headers],[Gas]], 0)} -> CH4 | E38: {=Common_InputFunctions.Utility_DisplayArrayInTable(Common_SourceData.Common_SourceData_GWP_Data(), Table_GWPData[[#Headers],[Gas]], 0)} -> 28
D39: {=Common_InputFunctions.Utility_DisplayArrayInTable(Common_SourceData.Common_SourceData_GWP_Data(), Table_GWPData[[#Headers],[Gas]], 0)} -> N2O | E39: {=Common_InputFunctions.Utility_DisplayArrayInTable(Common_SourceData.Common_SourceData_GWP_Data(), Table_GWPData[[#Headers],[Gas]], 0)} -> 265
D40: {=Common_InputFunctions.Utility_DisplayArrayInTable(Common_SourceData.Common_SourceData_GWP_Data(), Table_GWPData[[#Headers],[Gas]], 0)} -> CF4 | E40: {=Common_InputFunctions.Utility_DisplayArrayInTable(Common_SourceData.Common_SourceData_GWP_Data(), Table_GWPData[[#Headers],[Gas]], 0)} -> 6630
D41: {=Common_InputFunctions.Utility_DisplayArrayInTable(Common_SourceData.Common_SourceData_GWP_Data(), Table_GWPData[[#Headers],[Gas]], 0)} -> C2F6 | E41: {=Common_InputFunctions.Utility_DisplayArrayInTable(Common_SourceData.Common_SourceData_GWP_Data(), Table_GWPData[[#Headers],[Gas]], 0)} -> 12200
D42: {=Common_InputFunctions.Utility_DisplayArrayInTable(Common_SourceData.Common_SourceData_GWP_Data(), Table_GWPData[[#Headers],[Gas]], 0)} -> SF6 | E42: {=Common_InputFunctions.Utility_DisplayArrayInTable(Common_SourceData.Common_SourceData_GWP_Data(), Table_GWPData[[#Headers],[Gas]], 0)} -> 22800
D43: {=Common_InputFunctions.Utility_DisplayArrayInTable(Common_SourceData.Common_SourceData_GWP_Data(), Table_GWPData[[#Headers],[Gas]], 0)} -> NF3 | E43: {=Common_InputFunctions.Utility_DisplayArrayInTable(Common_SourceData.Common_SourceData_GWP_Data(), Table_GWPData[[#Headers],[Gas]], 0)} -> 17200
D45: {=Common_SourceData.Common_SourceData_ConvertGasElementalToMolecular_Title()} -> Factor to convert elemental mass of gas to molecular mass
D46: {=Common_SourceData.Common_SourceData_ConvertGasElementalToMolecular_Source()} -> XXXXXXX
D47: Gas | E47: Conversion factor | F47: Conversion factor 1 | G47: Conversion factor 2 | H47: Conversion factor combined
D48: {=Common_InputFunctions.Utility_DisplayArrayInTable(Common_SourceData.Common_SourceData_ConvertGasElementalToMolecular_Data(),Table_GasToMolecularConversionFactor[[#Headers],[Gas]], 0)} -> CO2 | E48: {=Common_InputFunctions.Utility_DisplayArrayInTable(Common_SourceData.Common_SourceData_ConvertGasElementalToMolecular_Data(),Table_GasToMolecularConversionFactor[[#Headers],[Gas]], 0)} -> 44/12 | F48: {=Common_InputFunctions.Utility_DisplayArrayInTable(Common_SourceData.Common_SourceData_ConvertGasElementalToMolecular_Data(),Table_GasToMolecularConversionFactor[[#Headers],[Gas]], 0)} -> 44 | G48: {=Common_InputFunctions.Utility_DisplayArrayInTable(Common_SourceData.Common_SourceData_ConvertGasElementalToMolecular_Data(),Table_GasToMolecularConversionFactor[[#Headers],[Gas]], 0)} -> 12 | H48: =Table_GasToMolecularConversionFactor[[#This Row],[Conversion factor 1]]/Table_GasToMolecularConversionFactor[[#This Row],[Conversion factor 2]] -> 3.6666667
D49: {=Common_InputFunctions.Utility_DisplayArrayInTable(Common_SourceData.Common_SourceData_ConvertGasElementalToMolecular_Data(),Table_GasToMolecularConversionFactor[[#Headers],[Gas]], 0)} -> CH4 | E49: {=Common_InputFunctions.Utility_DisplayArrayInTable(Common_SourceData.Common_SourceData_ConvertGasElementalToMolecular_Data(),Table_GasToMolecularConversionFactor[[#Headers],[Gas]], 0)} -> 16/12 | F49: {=Common_InputFunctions.Utility_DisplayArrayInTable(Common_SourceData.Common_SourceData_ConvertGasElementalToMolecular_Data(),Table_GasToMolecularConversionFactor[[#Headers],[Gas]], 0)} -> 16 | G49: {=Common_InputFunctions.Utility_DisplayArrayInTable(Common_SourceData.Common_SourceData_ConvertGasElementalToMolecular_Data(),Table_GasToMolecularConversionFactor[[#Headers],[Gas]], 0)} -> 12 | H49: =Table_GasToMolecularConversionFactor[[#This Row],[Conversion factor 1]]/Table_GasToMolecularConversionFactor[[#This Row],[Conversion factor 2]] -> 1.3333333
D50: {=Common_InputFunctions.Utility_DisplayArrayInTable(Common_SourceData.Common_SourceData_ConvertGasElementalToMolecular_Data(),Table_GasToMolecularConversionFactor[[#Headers],[Gas]], 0)} -> N2O | E50: {=Common_InputFunctions.Utility_DisplayArrayInTable(Common_SourceData.Common_SourceData_ConvertGasElementalToMolecular_Data(),Table_GasToMolecularConversionFactor[[#Headers],[Gas]], 0)} -> 44/28 | F50: {=Common_InputFunctions.Utility_DisplayArrayInTable(Common_SourceData.Common_SourceData_ConvertGasElementalToMolecular_Data(),Table_GasToMolecularConversionFactor[[#Headers],[Gas]], 0)} -> 44 | G50: {=Common_InputFunctions.Utility_DisplayArrayInTable(Common_SourceData.Common_SourceData_ConvertGasElementalToMolecular_Data(),Table_GasToMolecularConversionFactor[[#Headers],[Gas]], 0)} -> 28 | H50: =Table_GasToMolecularConversionFactor[[#This Row],[Conversion factor 1]]/Table_GasToMolecularConversionFactor[[#This Row],[Conversion factor 2]] -> 1.5714286
...

Sheet Acknowledgements
A1: Acknowledgements

Sheet Tab template
A1: #VALUE!
A3: Home
A4: =HYPERLINK("#'Results'!A1", "Results") -> Results
A6: INPUTS
A7: =HYPERLINK("#'Input - Site'!A1", "Site") -> Site
A8: =HYPERLINK("#'Input - Production'!A1", "Production and outputs") -> Production and outputs
A9: =HYPERLINK("#'Input - Herd - Dairy'!A1", "Herd - Dairy") -> Herd - Dairy
A10: =HYPERLINK("#'Input - Feed - Dairy'!A1", "Purchased feed - Livestock") -> Purchased feed - Livestock
A11: =HYPERLINK("#'Input - Herd - Feedlot'!A1", "Herd - Feedlot") -> Herd - Feedlot
A12: =HYPERLINK("#'Input - Pasture'!A1", "Pasture") -> Pasture
A13: =HYPERLINK("#'Input - Grains'!A1", "Crop - Grains") -> Crop - Grains
A14: =HYPERLINK("#'Input - Fert Lime Chem'!A1", "Fertiliser, Lime & Chemicals") -> Fertiliser, Lime & Chemicals
A15: =HYPERLINK("#'Input - Fuel & Energy'!A1", "Electricity and fuel") -> Electricity and fuel
A16: Waste
A17: Freight and transport
A18: =HYPERLINK("#'Input - Other Farm Inputs'!A1", "Other farm inputs") -> Other farm inputs
A19: =HYPERLINK("#'Input - Data quality'!A1", "Data quality") -> Data quality
A21: CALCULATIONS
A22: N2O MMS
A23: Enteric methane
A24: =HYPERLINK("#'Calcs - Fert Lime'!A1", "Fertiliser & soil amendments") -> Fertiliser & soil amendments
A25: =HYPERLINK("#'Calcs - Residue mgmt - Crop'!A1", "Residue management - Crop") -> Residue management - Crop
A26: =HYPERLINK("#'Calcs - Residue mgmt - Pasture'!A1", "Residue management - Pasture") -> Residue management - Pasture
A27: =HYPERLINK("#'Calcs - Field burning'!A1", "Field burning - Crop") -> Field burning - Crop
A28: =HYPERLINK("#'Calcs - Fuel'!A1", "Fuel") -> Fuel
A29: =HYPERLINK("#'Calcs - Electricity'!A1", "Electricity") -> Electricity
A30: =HYPERLINK("#'Calcs - Refrigerants'!A1", "Refrigerants") -> Refrigerants
A31: Waste
A32: Freight and transport
A33: =HYPERLINK("#'Calcs - Scope 3'!A1", "Purchased goods scope 3") -> Purchased goods scope 3
A35: APPENDICES
A36: =HYPERLINK("#'Constants - Common'!A1", "Constants - Common") -> Constants - Common
A37: =HYPERLINK("#'Constants - Cropping'!A1", "Constants - Cropping") -> Constants - Cropping
A38: =HYPERLINK("#'Constants - Livestock'!A1", "Constants - Livestock") -> Constants - Livestock
A39: =HYPERLINK("#'Constants - Dairy'!A1", "Constants - Dairy") -> Constants - Dairy
A40: Sources & acknowledgements
