Workbook
Name Common_Equations.Common_ConvertCH4ToCO2e: _xlfn.LAMBDA(_xlpm.E_CH4,_xlpm.GWP_CH4, _xlpm.E_CH4 * _xlpm.GWP_CH4)
Name Common_Equations.Common_ConvertCH4ToCO2e_Arguments: _xlfn.LAMBDA(_xlfn.MAKEARRAY(2, 2, _xlfn.LAMBDA(_xlpm.r,_xlpm.c, INDEX({"ECH4","Methane emissions (t CH4)";"GWPCH4","Global warming potential for methane (t CO2-e / t CH4)"}, _xlpm.r, _xlpm.c))))
Name Common_Equations.Common_ConvertCH4ToCO2e_LatexEquation: _xlfn.LAMBDA("CO2_e = E_{CH4} \times GWP_{CH4}")
Name Common_Equations.Common_ConvertCH4ToCO2e_NIRReference: _xlfn.LAMBDA("")
Name Common_Equations.Common_ConvertCH4ToCO2e_Title: _xlfn.LAMBDA("Convert methane emissions to carbon dioxide equivalent emissions")
Name Common_Equations.Common_ConvertCH4ToCO2e_Unit: _xlfn.LAMBDA("t CO2e")
Name Common_Equations.Common_ConvertCH4ToCO2e_Variable: _xlfn.LAMBDA("ECH4 CO2e")
Name Common_Equations.Common_ConvertN2OToCO2e: _xlfn.LAMBDA(_xlpm.E_N2O,_xlpm.GWP_N2O, _xlpm.E_N2O * _xlpm.GWP_N2O)
Name Common_Equations.Common_ConvertN2OToCO2e_LatexEquation: _xlfn.LAMBDA("CO2_e = E_{N2O} \times GWP_{N2O}")
Name Common_Equations.Common_ConvertN2OToCO2e_NIRReference: _xlfn.LAMBDA("")
Name Common_Equations.Common_ConvertN2OToCO2e_Title: _xlfn.LAMBDA("Convert nitrous oxide emissions to carbon dioxide equivalent emissions")
Name Common_Equations.Common_ConvertN2OToCO2e_Unit: _xlfn.LAMBDA("t CO2e")
Name Common_Equations.Common_ConvertN2OToCO2e_Variable: _xlfn.LAMBDA("EN2O CO2e")
Name Common_InputFunctions.Utility_ConvertStateCommonNameToAbbreviation: _xlfn.LAMBDA(_xlpm.StateCommonName,_xlpm.StateCommonNameArray,_xlpm.StateAbbreviationArray, _xlfn.XLOOKUP(_xlpm.StateCommonName, _xlpm.StateCommonNameArray, _xlpm.StateAbbreviationArray, ""))
Name Common_InputFunctions.Utility_DisplayArguments_1_2: _xlfn.LAMBDA(_xlpm.ArgumentsArray, _xlfn.CHOOSECOLS(_xlpm.ArgumentsArray, 1, 2))
Name Common_InputFunctions.Utility_DisplayArguments_3_4: _xlfn.LAMBDA(_xlpm.ArgumentsArray, _xlfn.CHOOSECOLS(_xlpm.ArgumentsArray, 3, 4))
Name Common_InputFunctions.Utility_DisplayFunctionName: _xlfn.LAMBDA(_xlpm.Function, _xlfn.TEXTBEFORE(_xlfn.FORMULATEXT(_xlpm.Function), "("))
Name Common_InputFunctions.Utility_GetArrayTableColumnStartNumber: _xlfn.LAMBDA(_xlpm.TableHeaderCell, COLUMN(_xlpm.TableHeaderCell))
Name Common_InputFunctions.Utility_GetArrayTableRowStartNumber: _xlfn.LAMBDA(_xlpm.TableheaderCell,_xlpm.RowsBetweenHeaderandArray, ROW(_xlpm.TableheaderCell) + _xlpm.RowsBetweenHeaderandArray - 1)
Name Common_InputFunctions.Utility_LookupValueInTable: _xlfn.LAMBDA(_xlpm.LookupValue,_xlpm.LookupArray,_xlpm.ReturnArray, _xlfn.XLOOKUP(_xlpm.LookupValue, _xlpm.LookupArray, _xlpm.ReturnArray, ""))
Name Common_InputFunctions.Utility_SourceHyperlink: _xlfn.LAMBDA(_xlpm.TargetCell, _xlfn.LET(_xlpm.sh, _xlfn.TEXTAFTER(CELL("filename", _xlpm.TargetCell), "]"), _xlpm.addr, CELL("address", _xlpm.TargetCell), "#'" & _xlpm.sh & "'!" & _xlpm.addr))
Name Common_SourceData.Common_SourceData_AustralianStatesTerritories_Source: _xlfn.LAMBDA("")
Name Common_SourceData.Common_SourceData_AustralianStatesTerritories_Title: _xlfn.LAMBDA("Australian states and territories")
Name Common_SourceData.Common_SourceData_AustralianStatesTerritories_Unit: _xlfn.LAMBDA("")
Name Common_SourceData.Common_SourceData_AustralianStatesTerritories_Variable: _xlfn.LAMBDA("")
Name Common_SourceData.Common_SourceData_ClimateZones_Source: _xlfn.LAMBDA("VEERG 2026: Table 1.3: Climate and Rainfall zone classifications and definitions")
Name Common_SourceData.Common_SourceData_ClimateZones_Title: _xlfn.LAMBDA("VEERG Australian climate zones")
Name Common_SourceData.Common_SourceData_ClimateZones_Unit: _xlfn.LAMBDA("")
Name Common_SourceData.Common_SourceData_ClimateZones_Variable: _xlfn.LAMBDA("")
Name Common_SourceData.Common_SourceData_ConvertGasElementalToMolecular_Source: _xlfn.LAMBDA("XXXXXXX")
Name Common_SourceData.Common_SourceData_ConvertGasElementalToMolecular_Title: _xlfn.LAMBDA("Factor to convert elemental mass of gas to molecular mass")
Name Common_SourceData.Common_SourceData_ConvertGasElementalToMolecular_Unit: _xlfn.LAMBDA("factor")
Name Common_SourceData.Common_SourceData_ConvertGasElementalToMolecular_Variable: _xlfn.LAMBDA("Cg")
Name Common_SourceData.Common_SourceData_ConvertN2oElementalToMolecularCg_Data: _xlfn.LAMBDA(44 / 28)
Name Common_SourceData.Common_SourceData_ConvertN2oElementalToMolecularCg_Source: _xlfn.LAMBDA("National Inventory Report 2023 Volume 1")
Name Common_SourceData.Common_SourceData_ConvertN2oElementalToMolecularCg_Title: _xlfn.LAMBDA("Factor to convert elemental mass of N2O to molecular mass")
Name Common_SourceData.Common_SourceData_ConvertN2oElementalToMolecularCg_Unit: _xlfn.LAMBDA("factor")
Name Common_SourceData.Common_SourceData_ConvertN2oElementalToMolecularCg_Variable: _xlfn.LAMBDA("CgN2O")
Name Common_SourceData.Common_SourceData_DataScores_Scope3_Source: _xlfn.LAMBDA("VEERG 2026: XXXXXXXX")
Name Common_SourceData.Common_SourceData_DataScores_Scope3_Title: _xlfn.LAMBDA("Australian data scores for scope 3")
Name Common_SourceData.Common_SourceData_DataScores_Scope3_Unit: _xlfn.LAMBDA("")
Name Common_SourceData.Common_SourceData_DataScores_Scope3_Variable: _xlfn.LAMBDA("")
Name Common_SourceData.Common_SourceData_DataScores_Scope3_Variation: _xlfn.LAMBDA("")
Name Common_SourceData.Common_SourceData_DensityOfMethane_Data: _xlfn.LAMBDA(0.6784)
Name Common_SourceData.Common_SourceData_DensityOfMethane_Source: _xlfn.LAMBDA("National Inventory Report 2023 Volume 1: Equations 3.B.1a_2, 3.B.1c_2, 3.B.3_1, 3.B.4g_2")
Name Common_SourceData.Common_SourceData_DensityOfMethane_Title: _xlfn.LAMBDA("p = density of methane")
Name Common_SourceData.Common_SourceData_DensityOfMethane_Unit: _xlfn.LAMBDA("kg/m3")
Name Common_SourceData.Common_SourceData_EFleach_Data: _xlfn.LAMBDA(_xlfn.MAKEARRAY(1, 2, _xlfn.LAMBDA(_xlpm.r,_xlpm.c, INDEX({"EFleach",0.011}, _xlpm.r, _xlpm.c))))
Name Common_SourceData.Common_SourceData_EFleach_NIRReference: _xlfn.LAMBDA("National Inventory Report Volume 1: Equation 3.D.B_10")
Name Common_SourceData.Common_SourceData_EFleach_Source: _xlfn.LAMBDA("VEERG 2026:5.5.2.3 Constant Parameters")
Name Common_SourceData.Common_SourceData_EFleach_Title: _xlfn.LAMBDA("Emission factor for nitrogen leaching and runoff")
Name Common_SourceData.Common_SourceData_EFleach_Unit: _xlfn.LAMBDA("(kg N2O-N / kg N")
Name Common_SourceData.Common_SourceData_EFleach_Variation: _xlfn.LAMBDA((""))
Name Common_SourceData.Common_SourceData_EFN2O_NIRReference: _xlfn.LAMBDA("")
Name Common_SourceData.Common_SourceData_EFN2O_Source: _xlfn.LAMBDA("VEERG 2026: Table A.2.2.1")
Name Common_SourceData.Common_SourceData_EFN2O_Title: _xlfn.LAMBDA("Nitrous oxide emission factors for inorganic fertiliser application")
Name Common_SourceData.Common_SourceData_EFN2O_Unit: _xlfn.LAMBDA("(kg N2O-N / kg N")
Name Common_SourceData.Common_SourceData_EFPastureRangeAndPaddock_Data: _xlfn.LAMBDA(_xlfn.MAKEARRAY(3, 2, _xlfn.LAMBDA(_xlpm.r,_xlpm.c, INDEX({"Climate zone","EFPRP";"Wet climate zone",0.006;"Dry climate zone",0.002}, _xlpm.r, _xlpm.c))))
Name Common_SourceData.Common_SourceData_EFPastureRangeAndPaddock_NIRReference: _xlfn.LAMBDA("")
Name Common_SourceData.Common_SourceData_EFPastureRangeAndPaddock_Source: _xlfn.LAMBDA("VEERG 2026: Table A.2.2.2")

Sheet Home
A1: Home

Sheet Overview
A1: #VALUE! | C1: 4.1: Manure Management: Beef feedlot: Overview
A3: =HYPERLINK("#'Home'!A1", "Home") -> Home
A4: =HYPERLINK("#'Overview'!A1", "Overview") -> Overview
A5: =HYPERLINK("#'Results'!A1", "Results") -> Results | D5: 💡 Below is a diagram that maps the equations used to calculate emissions, how they interact with each other and how they align with dairy manure management processes.
D6: Click on a box to go to the corresponding calculation.
A7: INPUTS
A8: =HYPERLINK("#'Input - Site'!A1", "Site") -> Site
A9: =HYPERLINK("#'Input - Feedlot'!A1", "Feedlot") -> Feedlot
A11: CALCULATIONS
A12: =HYPERLINK("#'4.1.1.1-2 Methane'!A1", "4.1.1.1-2 Methane") -> 4.1.1.1-2 Methane
A13: =HYPERLINK("#'4.1.1.3-4 Direct N20'!A1", "4.1.1.3-4 Direct N2O") -> 4.1.1.3-4 Direct N2O
A14: =HYPERLINK("#'4.1.1.5-6 Atmos Deposition'!A1", "4.1.1.5-6 Atmospheric deposition") -> 4.1.1.5-6 Atmospheric deposition
A15: =HYPERLINK("#'4.1.1.9 Manure applied to soils'!A1", "4.1.1.9 Manure applied to soils") -> 4.1.1.9 Manure applied to soils
A17: APPENDICES
A18: =HYPERLINK("#'Constants - Feedlot'!A1", "Constants - Feedlot") -> Constants - Feedlot
A19: =HYPERLINK("#'Constants - Livestock'!A1", "Constants - Livestock") -> Constants - Livestock
A20: =HYPERLINK("#'Constants - Common'!A1", "Constants - Common") -> Constants - Common
A21: =HYPERLINK("#'Acknowledgements'!A1", "Acknowledgements") -> Acknowledgements

Sheet Results
A1: #VALUE! | C1: 4.1 Manure management: Beef Feedlot: Results
A3: =HYPERLINK("#'Home'!A1", "Home") -> Home
A4: =HYPERLINK("#'Overview'!A1", "Overview") -> Overview | D4: Emissions breakdown
A5: =HYPERLINK("#'Results'!A1", "Results") -> Results
D6: Scope 1 source | E6: GHG emissions method 1 | F6: GHG emissions method 2 | G6: GHG Unit | H6: CO2-e emissions method 1 | I6: CO2-e emissions method 2 | J6: CO2-e unit
A7: INPUTS | D7: 4.1.1.1-2 Method 1 Manure methane | E7: ='4.1.1.1-2 Methane'!E171 -> 2.5235018 | F7: ='4.1.1.1-2 Methane'!N171 -> 2.5595518 | G7: ='4.1.1.1-2 Methane'!F171 -> t CH4 | H7: ='4.1.1.1-2 Methane'!E176 -> 70.658049 | I7: ='4.1.1.1-2 Methane'!N176 -> 71.66745 | J7: t CO2e
A8: =HYPERLINK("#'Input - Site'!A1", "Site") -> Site | D8: 4.1.1.3-4 Method 1 Manure direct N2O | E8: ='4.1.1.3-4 Direct N20'!E212 -> 0.79920735 | F8: ='4.1.1.3-4 Direct N20'!P212 -> 0.79920735 | G8: ='4.1.1.3-4 Direct N20'!F212 -> t N2O | H8: ='4.1.1.3-4 Direct N20'!E217 -> 211.78995 | I8: ='4.1.1.3-4 Direct N20'!P217 -> 211.78995 | J8: t CO2e
A9: =HYPERLINK("#'Input - Feedlot'!A1", "Feedlot") -> Feedlot | D9: 4.1.1.5-6 Method 1 Manure atmospheric deposition | E9: ='4.1.1.5-6 Atmos Deposition'!$E$65 -> 0.14458898 | F9: ='4.1.1.5-6 Atmos Deposition'!$N$65 -> 0.14458898 | G9: ='4.1.1.5-6 Atmos Deposition'!$F$65 -> t N2O | H9: ='4.1.1.5-6 Atmos Deposition'!$E$70 -> 38.31608 | I9: ='4.1.1.5-6 Atmos Deposition'!$N$70 -> 38.31608 | J9: t CO2e
D10: Total | H10: =SUM(H7:H8) -> 282.448 | I10: =SUM(I7:I8) -> 283.4574 | J10: t CO2e
A11: CALCULATIONS
A12: =HYPERLINK("#'4.1.1.1-2 Methane'!A1", "4.1.1.1-2 Methane") -> 4.1.1.1-2 Methane | D12: 4.1.1.9 Manure applied to soils
A13: =HYPERLINK("#'4.1.1.3-4 Direct N20'!A1", "4.1.1.3-4 Direct N2O") -> 4.1.1.3-4 Direct N2O | D13: WARNING: Manure nitrogen that was applied to soils must be accounted for
A14: =HYPERLINK("#'4.1.1.5-6 Atmos Deposition'!A1", "4.1.1.5-6 Atmospheric deposition") -> 4.1.1.5-6 Atmospheric deposition | D14: See the table below for how to account for manure applied to soils for scope 1 and 3.
A15: =HYPERLINK("#'4.1.1.9 Manure applied to soils'!A1", "4.1.1.9 Manure applied to soils") -> 4.1.1.9 Manure applied to soils | D15: Manure nitrogen use | E15: Amount of N in manure | F15: N unit | G15: Emissions allocated to | H15: VEERG Calculation method
D16: Manure nitrogen deposited on farm soils (including use as fertiliser for other enterprises on own farm eg crops) | E16: ='4.1.1.9 Manure applied to soils'!$E$61 -> 24130.039 | F16: ='4.1.1.9 Manure applied to soils'!$F$61 -> kg N | G16: Scope 1 - This feedlot | H16: 5.2.2.1 (1), 5.4.1.3 (1, 2), 5.5.1.1 (1, 3)
A17: APPENDICES | D17: Manure nitrogen deposited on farm soils as fertiliser for other farm enterpsies (eg crops) | E17: ='4.1.1.9 Manure applied to soils'!$E$111 -> 2202.6859 | F17: ='4.1.1.9 Manure applied to soils'!$F$111 -> kg N | G17: Scope 1 - This feedlot | H17: 5.2.2.1 (1), 5.4.1.3 (1, 2), 5.5.1.1 (1, 3)
A18: =HYPERLINK("#'Constants - Feedlot'!A1", "Constants - Feedlot") -> Constants - Feedlot | D18: Manure nitrogen sold | E18: ='4.1.1.9 Manure applied to soils'!E87 -> 2202.6859 | F18: ='4.1.1.9 Manure applied to soils'!F87 -> kg N | G18: Scope 3 (downstream) | H18: 15.13.1.1 (1), 5.2.2.1 (1), 5.4.1.3 (1, 2), 5.5.1.1 (1, 3)
A19: =HYPERLINK("#'Constants - Livestock'!A1", "Constants - Livestock") -> Constants - Livestock
A20: =HYPERLINK("#'Constants - Common'!A1", "Constants - Common") -> Constants - Common
A21: =HYPERLINK("#'Acknowledgements'!A1", "Acknowledgements") -> Acknowledgements

Sheet Input - Site
A1: #VALUE! | C1: Input - Site
A3: =HYPERLINK("#'Home'!A1", "Home") -> Home
A4: =HYPERLINK("#'Overview'!A1", "Overview") -> Overview
A5: =HYPERLINK("#'Results'!A1", "Results") -> Results | D5: Your business
A7: INPUTS | D7: Farm name | E7: Test Farms
A8: =HYPERLINK("#'Input - Site'!A1", "Site") -> Site | D8: Reporting entity name | E8: Test Farms Pty Ltd
A9: =HYPERLINK("#'Input - Feedlot'!A1", "Feedlot") -> Feedlot
D10: 💡An 'Emissions accounting period' is a 12 month period where the business can report on the emissions, and is typically the same as the business' financial accounting period.
A11: CALCULATIONS
A12: =HYPERLINK("#'4.1.1.1-2 Methane'!A1", "4.1.1.1-2 Methane") -> 4.1.1.1-2 Methane | D12: Emissions calculation period start date | E12: 45292 | F12: ← DD/MM/YYYY or DD Month YYYY
A13: =HYPERLINK("#'4.1.1.3-4 Direct N20'!A1", "4.1.1.3-4 Direct N2O") -> 4.1.1.3-4 Direct N2O | D13: Emissions calculation period end date | E13: =DATE(YEAR(E12)+1,MONTH(E12),DAY(E12))-1 -> 45657 | F13: ← Automatically calculated, 12 months after start date
A14: =HYPERLINK("#'4.1.1.5-6 Atmos Deposition'!A1", "4.1.1.5-6 Atmospheric deposition") -> 4.1.1.5-6 Atmospheric deposition
A15: =HYPERLINK("#'4.1.1.9 Manure applied to soils'!A1", "4.1.1.9 Manure applied to soils") -> 4.1.1.9 Manure applied to soils
D16: Location and climate
A17: APPENDICES
A18: =HYPERLINK("#'Constants - Feedlot'!A1", "Constants - Feedlot") -> Constants - Feedlot | D18: Location information is used to reference some region and climate-specific emission factors
A19: =HYPERLINK("#'Constants - Livestock'!A1", "Constants - Livestock") -> Constants - Livestock | D19: Tip: Use the web-based GAF Location Helper tool to easily get region and climate information. You will need an internet connection to use the GAF Location Helper.
A20: =HYPERLINK("#'Constants - Common'!A1", "Constants - Common") -> Constants - Common
A21: =HYPERLINK("#'Acknowledgements'!A1", "Acknowledgements") -> Acknowledgements | D21: State | E21: New South Wales | F21: ← Please select
D22: Region (ABS Statistical area level 4) if state is WA | E22: Western Australia - Outback (South) | F22: ← Please select
D23: Leaching zone | E23: NO - Not in leaching zone | F23: ← Please select
D24: Elevation | E24: 307.7 | F24: Meters
D25: Average temperature for reporting period | E25: 18 | F25: Degrees celsius
D26: Total rainfall for reporting period | E26: 601 | F26: Millimetres
D27: Potential evapotranspiration for reporting period | E27: 1326 | F27: Millimetres
D28: Number of frost days for reporting period | E28: 7 | F28: Days
D29: MAP:PET ratio | E29: =E26/E27 -> 0.45324284
D30: Rainfall zone | E30: =Common_InputFunctions.Utility_LookupItemFromMinMax(E26,Table_SourceData_RainfallZones[Min rainfall],Table_SourceData_RainfallZones[Max rainfall],Table_SourceData_RainfallZones[Rainfall Zone]) -> High rainfall
D31: Climate zone | E31: =Common_InputFunctions.Utility_GetClimateZone(E25,E26,E28,E24,E29,Table_SourceData_ClimateZones[Min temp],Table_SourceData_ClimateZones[Max temp],Table_SourceData_ClimateZones[Min rainfall],Table_SourceData_ClimateZones[Max rainfall],Table_SourceData_ClimateZones[Min frost days],Table_SourceData_ClimateZones[Max frost days],Table_SourceData_ClimateZones[Min elevation],Table_SourceData_ClimateZones[Max elevation],Table_SourceData_ClimateZones[Min MAP:PET],Table_SourceData_ClimateZones[Max MAP:PET],Table_SourceData_ClimateZones[Climate zone]) -> Warm temperate dry
D32: Wet or dry climate zone | E32: =Common_InputFunctions.Utility_LookupValueInTable($E$31,Table_SourceData_WetDryZones[Climate zone],Table_SourceData_WetDryZones[Wet or Dry Zone]) -> Dry climate zone
D33: Temperature zone | E33: =Common_InputFunctions.Utility_LookupItemFromMinMax(E25,Table_SourceData_TemperatureZones[Min MAT],Table_SourceData_TemperatureZones[Max MAT],Table_SourceData_TemperatureZones[Temperature Zone]) -> Temperate

Sheet Input - Feedlot
A1: #VALUE! | C1: Input - MMS - Feedlot
A3: =HYPERLINK("#'Home'!A1", "Home") -> Home
A4: =HYPERLINK("#'Overview'!A1", "Overview") -> Overview
A5: =HYPERLINK("#'Results'!A1", "Results") -> Results | D5: Herd movement
A7: INPUTS | E7: Domestic | F7: Mid-fed | G7: Long-fed
A8: =HYPERLINK("#'Input - Site'!A1", "Site") -> Site | D8: ="Average number of head between " & TEXT('Input - Site'!$E$12, "dd mmm yy") & " and " & TEXT('Input - Site'!$E$13, "dd mmm yy") -> Average number of head between 01 Jan 24 and 31 Dec 24 | E8: 4300 | F8: 100 | G8: 100 | H8: head
A9: =HYPERLINK("#'Input - Feedlot'!A1", "Feedlot") -> Feedlot | D9: ="Average duration of stay between " & TEXT('Input - Site'!$E$12, "dd mmm yy") & " and " & TEXT('Input - Site'!$E$13, "dd mmm yy") -> Average duration of stay between 01 Jan 24 and 31 Dec 24 | E9: 90 | F9: 140 | G9: 250 | H9: days
A11: CALCULATIONS | D11: Intake
A12: =HYPERLINK("#'4.1.1.1-2 Methane'!A1", "4.1.1.1-2 Methane") -> 4.1.1.1-2 Methane
A13: =HYPERLINK("#'4.1.1.3-4 Direct N20'!A1", "4.1.1.3-4 Direct N2O") -> 4.1.1.3-4 Direct N2O | D13: Method 1 default values (Do not edit) | E13: Domestic | F13: Mid-fed | G13: Long-fed
A14: =HYPERLINK("#'4.1.1.5-6 Atmos Deposition'!A1", "4.1.1.5-6 Atmospheric deposition") -> 4.1.1.5-6 Atmospheric deposition | D14: Feed intake | E14: {=_xlfn.XLOOKUP(1, (Table_SourceData_Feedlot_AnimalCharacteristics[Feedlot type] = E$13) * (Table_SourceData_Feedlot_AnimalCharacteristics[Characteristic] = $D$14), Table_SourceData_Feedlot_AnimalCharacteristics[2020-2023], "Not Found")} -> 10.4 | F14: {=_xlfn.XLOOKUP(1, (Table_SourceData_Feedlot_AnimalCharacteristics[Feedlot type] = F$13) * (Table_SourceData_Feedlot_AnimalCharacteristics[Characteristic] = $D$14), Table_SourceData_Feedlot_AnimalCharacteristics[2020-2023], "Not Found")} -> 10.8 | G14: {=_xlfn.XLOOKUP(1, (Table_SourceData_Feedlot_AnimalCharacteristics[Feedlot type] = G$13) * (Table_SourceData_Feedlot_AnimalCharacteristics[Characteristic] = $D$14), Table_SourceData_Feedlot_AnimalCharacteristics[2020-2023], "Not Found")} -> 8.2 | H14: kg dry matter / head day
A15: =HYPERLINK("#'4.1.1.9 Manure applied to soils'!A1", "4.1.1.9 Manure applied to soils") -> 4.1.1.9 Manure applied to soils | D15: Dry matter digestibility | E15: {=_xlfn.XLOOKUP(1, (Table_SourceData_Feedlot_DietProperties[Feedlot type] = E$13) * (Table_SourceData_Feedlot_DietProperties[Nutrient analysis] = $D$15), Table_SourceData_Feedlot_DietProperties[2020-2023 Converted to fraction], "Not Found")} -> 0.81 | F15: {=_xlfn.XLOOKUP(1, (Table_SourceData_Feedlot_DietProperties[Feedlot type] = F$13) * (Table_SourceData_Feedlot_DietProperties[Nutrient analysis] = $D$15), Table_SourceData_Feedlot_DietProperties[2020-2023 Converted to fraction], "Not Found")} -> 0.81 | G15: {=_xlfn.XLOOKUP(1, (Table_SourceData_Feedlot_DietProperties[Feedlot type] = G$13) * (Table_SourceData_Feedlot_DietProperties[Nutrient analysis] = $D$15), Table_SourceData_Feedlot_DietProperties[2020-2023 Converted to fraction], "Not Found")} -> 0.81 | H15: fraction
D16: Crude protein | E16: {=_xlfn.XLOOKUP(1, (Table_SourceData_Feedlot_DietProperties[Feedlot type] = E$13) * (Table_SourceData_Feedlot_DietProperties[Nutrient analysis] = $D$16), Table_SourceData_Feedlot_DietProperties[2020-2023 Converted to fraction], "Not Found")} -> 0.14 | F16: {=_xlfn.XLOOKUP(1, (Table_SourceData_Feedlot_DietProperties[Feedlot type] = F$13) * (Table_SourceData_Feedlot_DietProperties[Nutrient analysis] = $D$16), Table_SourceData_Feedlot_DietProperties[2020-2023 Converted to fraction], "Not Found")} -> 0.12 | G16: {=_xlfn.XLOOKUP(1, (Table_SourceData_Feedlot_DietProperties[Feedlot type] = G$13) * (Table_SourceData_Feedlot_DietProperties[Nutrient analysis] = $D$16), Table_SourceData_Feedlot_DietProperties[2020-2023 Converted to fraction], "Not Found")} -> 0.12 | H16: fraction
A17: APPENDICES | D17: N retention | E17: {=_xlfn.XLOOKUP(1, (Table_SourceData_Feedlot_AnimalCharacteristics[Feedlot type] = E$13) * (Table_SourceData_Feedlot_AnimalCharacteristics[Characteristic] = $D$17), Table_SourceData_Feedlot_AnimalCharacteristics[2020-2023], "Not Found")} -> 20.4 | F17: {=_xlfn.XLOOKUP(1, (Table_SourceData_Feedlot_AnimalCharacteristics[Feedlot type] = F$13) * (Table_SourceData_Feedlot_AnimalCharacteristics[Characteristic] = $D$17), Table_SourceData_Feedlot_AnimalCharacteristics[2020-2023], "Not Found")} -> 12.7 | G17: {=_xlfn.XLOOKUP(1, (Table_SourceData_Feedlot_AnimalCharacteristics[Feedlot type] = G$13) * (Table_SourceData_Feedlot_AnimalCharacteristics[Characteristic] = $D$17), Table_SourceData_Feedlot_AnimalCharacteristics[2020-2023], "Not Found")} -> 7 | H17: percent of intake
A18: =HYPERLINK("#'Constants - Feedlot'!A1", "Constants - Feedlot") -> Constants - Feedlot
A19: =HYPERLINK("#'Constants - Livestock'!A1", "Constants - Livestock") -> Constants - Livestock | D19: Method 2 custom values (Edit if known) | E19: Domestic | F19: Mid-fed | G19: Long-fed
A20: =HYPERLINK("#'Constants - Common'!A1", "Constants - Common") -> Constants - Common | D20: Feed intake | E20: {=_xlfn.XLOOKUP(1, (Table_SourceData_Feedlot_AnimalCharacteristics[Feedlot type] = E$19) * (Table_SourceData_Feedlot_AnimalCharacteristics[Characteristic] = $D$20), Table_SourceData_Feedlot_AnimalCharacteristics[2020-2023], "Not Found")} -> 10.4 | F20: {=_xlfn.XLOOKUP(1, (Table_SourceData_Feedlot_AnimalCharacteristics[Feedlot type] = F$19) * (Table_SourceData_Feedlot_AnimalCharacteristics[Characteristic] = $D$20), Table_SourceData_Feedlot_AnimalCharacteristics[2020-2023], "Not Found")} -> 10.8 | G20: {=_xlfn.XLOOKUP(1, (Table_SourceData_Feedlot_AnimalCharacteristics[Feedlot type] = G$19) * (Table_SourceData_Feedlot_AnimalCharacteristics[Characteristic] = $D$20), Table_SourceData_Feedlot_AnimalCharacteristics[2020-2023], "Not Found")} -> 8.2 | H20: kg dry matter / head day
A21: =HYPERLINK("#'Acknowledgements'!A1", "Acknowledgements") -> Acknowledgements | D21: Dry matter digestibility | E21: {=_xlfn.XLOOKUP(1, (Table_SourceData_Feedlot_DietProperties[Feedlot type] = E$19) * (Table_SourceData_Feedlot_DietProperties[Nutrient analysis] = $D$21), Table_SourceData_Feedlot_DietProperties[2020-2023 Converted to fraction], "Not Found")} -> 0.81 | F21: {=_xlfn.XLOOKUP(1, (Table_SourceData_Feedlot_DietProperties[Feedlot type] = F$19) * (Table_SourceData_Feedlot_DietProperties[Nutrient analysis] = $D$21), Table_SourceData_Feedlot_DietProperties[2020-2023 Converted to fraction], "Not Found")} -> 0.81 | G21: {=_xlfn.XLOOKUP(1, (Table_SourceData_Feedlot_DietProperties[Feedlot type] = G$19) * (Table_SourceData_Feedlot_DietProperties[Nutrient analysis] = $D$21), Table_SourceData_Feedlot_DietProperties[2020-2023 Converted to fraction], "Not Found")} -> 0.81 | H21: fraction
D22: Crude protein | E22: {=_xlfn.XLOOKUP(1, (Table_SourceData_Feedlot_DietProperties[Feedlot type] = E$19) * (Table_SourceData_Feedlot_DietProperties[Nutrient analysis] = $D$22), Table_SourceData_Feedlot_DietProperties[2020-2023 Converted to fraction], "Not Found")} -> 0.14 | F22: {=_xlfn.XLOOKUP(1, (Table_SourceData_Feedlot_DietProperties[Feedlot type] = F$19) * (Table_SourceData_Feedlot_DietProperties[Nutrient analysis] = $D$22), Table_SourceData_Feedlot_DietProperties[2020-2023 Converted to fraction], "Not Found")} -> 0.12 | G22: {=_xlfn.XLOOKUP(1, (Table_SourceData_Feedlot_DietProperties[Feedlot type] = G$19) * (Table_SourceData_Feedlot_DietProperties[Nutrient analysis] = $D$22), Table_SourceData_Feedlot_DietProperties[2020-2023 Converted to fraction], "Not Found")} -> 0.12 | H22: fraction
D23: N retention | E23: {=_xlfn.XLOOKUP(1, (Table_SourceData_Feedlot_AnimalCharacteristics[Feedlot type] = E$19) * (Table_SourceData_Feedlot_AnimalCharacteristics[Characteristic] = $D$23), Table_SourceData_Feedlot_AnimalCharacteristics[2020-2023], "Not Found")} -> 20.4 | F23: {=_xlfn.XLOOKUP(1, (Table_SourceData_Feedlot_AnimalCharacteristics[Feedlot type] = F$19) * (Table_SourceData_Feedlot_AnimalCharacteristics[Characteristic] = $D$23), Table_SourceData_Feedlot_AnimalCharacteristics[2020-2023], "Not Found")} -> 12.7 | G23: {=_xlfn.XLOOKUP(1, (Table_SourceData_Feedlot_AnimalCharacteristics[Feedlot type] = G$19) * (Table_SourceData_Feedlot_AnimalCharacteristics[Characteristic] = $D$23), Table_SourceData_Feedlot_AnimalCharacteristics[2020-2023], "Not Found")} -> 7 | H23: percent of intake
D25: Manure management systems
D27: Stage 1 MMS | E27: Domestic | F27: Mid-fed | G27: Long-fed
D28: Drylot (feed pad) | E28: 1 | F28: 1 | G28: 1 | H28: percent
D29: ▼
D30: Stage 2 MMS | E30: Domestic | F30: Mid-fed | G30: Long-fed | H30: ► | I30: Destination after stage 2 MMS (Percent)
D31: ="From Stage 1: " & $D$28 & " to:" -> From Stage 1: Drylot (feed pad) to: | I31: Sold | J31: Fert for own farm (eg crop) | K31: Direct application to soil
D32: ='Constants - Feedlot'!D29 -> Solid storage | E32: 0.2 | F32: 0.2 | G32: 0.2 | H32: percent | I32: 0.25 | J32: 0.25 | K32: =1-SUM(I32:J32) -> 0.5
D33: ='Constants - Feedlot'!D30 -> Composting (passive windrow) | E33: 0.2 | F33: 0.2 | G33: 0.2 | H33: percent | I33: 0.25 | J33: 0.25 | K33: =1-SUM(I33:J33) -> 0.5
D34: Direct application | E34: =1-SUM(E32, E33) -> 0.6 | F34: =1-SUM(F32, F33) -> 0.6 | G34: =1-SUM(G32, G33) -> 0.6 | H34: percent | I34: 0 | J34: 0 | K34: =1-SUM(I34:J34) -> 1
D36: Stage 3 MMS | E36: Domestic | F36: Mid-fed | G36: Long-fed | H36: ► | I36: Destination after stage 3 MMS (Percent)
D37: ="From Stage 1: " & $D$28 & " to:" -> From Stage 1: Drylot (feed pad) to: | I37: Sold | J37: Fert for own farm (eg crop) | K37: Direct application to soil
D38: ='Constants - Feedlot'!$D$32 -> Anaerobic lagoon | E38: ='Constants - Feedlot'!$E$12 -> 0.02 | F38: ='Constants - Feedlot'!$E$12 -> 0.02 | G38: ='Constants - Feedlot'!$E$12 -> 0.02 | H38: percent | I38: 0.25 | J38: 0.25 | K38: =1-SUM(I38:J38) -> 0.5
D41: Where manure was deposited on farm soils, what is the closest match? | E41: Pasture | F41: ← Please select
E42: Not irrigated | F42: ← Please select

Sheet 4.1.1.1-2 Methane
A1: #VALUE! | C1: 4.1.1.1-2 Manure Methane
A3: =HYPERLINK("#'Home'!A1", "Home") -> Home | D3: Method 1 | M3: Method 2
A4: =HYPERLINK("#'Overview'!A1", "Overview") -> Overview
A5: =HYPERLINK("#'Results'!A1", "Results") -> Results | D5: {=MMS_Feedlot_Methane_Equations.VEERG_4_1_1_1__5_VolatileSolidProduction_Title()} -> Volatile solid production
D6: {=MMS_Feedlot_Methane_Equations.VEERG_4_1_1_1__5_VolatileSolidProduction_Source()} -> VEERG 2026: 4.1.1.1, Equation (5)
A7: INPUTS | D7: Function name | E7: {=Common_InputFunctions.Utility_DisplayFunctionName(D30)} -> =MMS_Feedlot_Methane_Equations.VEERG_4_1_1_1__5_VolatileSolidProduction
A8: =HYPERLINK("#'Input - Site'!A1", "Site") -> Site
A9: =HYPERLINK("#'Input - Feedlot'!A1", "Feedlot") -> Feedlot
D10: Variable | E10: {=MMS_Feedlot_Methane_Equations.VEERG_4_1_1_1__5_VolatileSolidProduction_Variable()} -> VS_j
A11: CALCULATIONS | D11: Unit | E11: {=MMS_Feedlot_Methane_Equations.VEERG_4_1_1_1__5_VolatileSolidProduction_Unit()} -> kg/head/day
A12: =HYPERLINK("#'4.1.1.1-2 Methane'!A1", "4.1.1.1-2 Methane") -> 4.1.1.1-2 Methane
A13: =HYPERLINK("#'4.1.1.3-4 Direct N20'!A1", "4.1.1.3-4 Direct N2O") -> 4.1.1.3-4 Direct N2O | D13: {=MMS_Feedlot_Methane_Equations.VEERG_4_1_1_1__5_VolatileSolidProduction_Arguments()} -> I_j | E13: dry matter intake for each group j | F13: kg DM/head/day | G13: Input | H13: {=HYPERLINK(Common_InputFunctions.Utility_SourceHyperlink($D$17),$D$17)} -> M1_Table_I_j
A14: =HYPERLINK("#'4.1.1.5-6 Atmos Deposition'!A1", "4.1.1.5-6 Atmospheric deposition") -> 4.1.1.5-6 Atmospheric deposition | D14: DMD_j | E14: dry matter digestibility for each group j | F14: fraction | G14: Input | H14: {=HYPERLINK(Common_InputFunctions.Utility_SourceHyperlink($D$22),$D$22)} -> M1_Table_DMD_j
A15: =HYPERLINK("#'4.1.1.9 Manure applied to soils'!A1", "4.1.1.9 Manure applied to soils") -> 4.1.1.9 Manure applied to soils | D15: A | E15: ash content of manure | F15: fraction | G15: Constant | H15: ='Constants - Feedlot'!$E$17 -> 0.16
A17: APPENDICES | D17: M1_Table_I_j | M17: M2_Table_I_j
A18: =HYPERLINK("#'Constants - Feedlot'!A1", "Constants - Feedlot") -> Constants - Feedlot | D18: Dry matter intake (Method 1) | M18: Dry matter intake (Method 2)
A19: =HYPERLINK("#'Constants - Livestock'!A1", "Constants - Livestock") -> Constants - Livestock | D19: Domestic | E19: Mid-fed | F19: Long-fed | M19: Domestic | N19: Mid-fed | O19: Long-fed
A20: =HYPERLINK("#'Constants - Common'!A1", "Constants - Common") -> Constants - Common | D20: ='Input - Feedlot'!$E$14 -> 10.4 | E20: ='Input - Feedlot'!$F$14 -> 10.8 | F20: ='Input - Feedlot'!$G$14 -> 8.2 | G20: kg DM/head/day | M20: ='Input - Feedlot'!$E$20 -> 10.4 | N20: ='Input - Feedlot'!$F$20 -> 10.8 | O20: ='Input - Feedlot'!$G$20 -> 8.2 | P20: kg DM/head/day
A21: =HYPERLINK("#'Acknowledgements'!A1", "Acknowledgements") -> Acknowledgements
D22: M1_Table_DMD_j | M22: M2_Table_DMD_j
D23: Dry matter digestibility (Method 1) | M23: Dry matter digestibility (Method 1)
D24: Domestic | E24: Mid-fed | F24: Long-fed | M24: Domestic | N24: Mid-fed | O24: Long-fed
D25: ='Input - Feedlot'!$E$15 -> 0.81 | E25: ='Input - Feedlot'!$F$15 -> 0.81 | F25: ='Input - Feedlot'!$G$15 -> 0.81 | G25: fraction | M25: ='Input - Feedlot'!$E$21 -> 0.81 | N25: ='Input - Feedlot'!$F$21 -> 0.81 | O25: ='Input - Feedlot'!$G$21 -> 0.81 | P25: fraction
D27: M1_Table_VS_j | M27: M2_Table_VS_j
D28: Volatile solid production (Method 1) | M28: Volatile solid production (Method 2)
D29: Domestic | E29: Mid-fed | F29: Long-fed | M29: Domestic | N29: Mid-fed | O29: Long-fed
D30: {=MMS_Feedlot_Methane_Equations.VEERG_4_1_1_1__5_VolatileSolidProduction(D20,D25,$H$15)} -> 1.65984 | E30: {=MMS_Feedlot_Methane_Equations.VEERG_4_1_1_1__5_VolatileSolidProduction(E20,E25,$H$15)} -> 1.72368 | F30: {=MMS_Feedlot_Methane_Equations.VEERG_4_1_1_1__5_VolatileSolidProduction(F20,F25,$H$15)} -> 1.30872 | G30: =$E$11 -> kg/head/day | M30: {=MMS_Feedlot_Methane_Equations.VEERG_4_1_1_1__5_VolatileSolidProduction(M20,M25,$H$15)} -> 1.65984 | N30: {=MMS_Feedlot_Methane_Equations.VEERG_4_1_1_1__5_VolatileSolidProduction(N20,N25,$H$15)} -> 1.72368 | O30: {=MMS_Feedlot_Methane_Equations.VEERG_4_1_1_1__5_VolatileSolidProduction(O20,O25,$H$15)} -> 1.30872 | P30: =$E$11 -> kg/head/day
D34: {=MMS_Feedlot_Methane_Equations.VEERG_4_1_1_1__2_Stage1MethaneProductionDrylot_Title()} -> Production of methane in treatment stage 1 MMS
D35: {=MMS_Feedlot_Methane_Equations.VEERG_4_1_1_1__2_Stage1MethaneProductionDrylot_Source()} -> VEERG 2026: 4.1.1.1, Equation (2)
D36: Function name | E36: {=Common_InputFunctions.Utility_DisplayFunctionName(E57)} -> =MMS_Feedlot_Methane_Equations.VEERG_4_1_1_1__2_Stage1MethaneProductionDrylot
D39: Variable | E39: {=MMS_Feedlot_Methane_Equations.VEERG_4_1_1_1__2_Stage1MethaneProductionDrylot_Variable()} -> M_jm5T1
D40: Unit | E40: {=MMS_Feedlot_Methane_Equations.VEERG_4_1_1_1__2_Stage1MethaneProductionDrylot_Unit()} -> kg CH4/head/day | M40: NOTE: Drylot MCF is state based
D42: {=_xlfn.CHOOSECOLS(MMS_Feedlot_Methane_Equations.VEERG_4_1_1_1__2_Stage1MethaneProductionDrylot_Arguments(),1,2)} -> VS_j | E42: volatile solid production from feedlot cattle in each group | G42: {=_xlfn.CHOOSECOLS(MMS_Feedlot_Methane_Equations.VEERG_4_1_1_1__2_Stage1MethaneProductionDrylot_Arguments(),3,4)} -> kg/head/day | H42: Calculated from 4.1.1.1 (5) | I42: {=HYPERLINK(Common_InputFunctions.Utility_SourceHyperlink($D$27),$D$27)} -> M1_Table_VS_j | M42: {=_xlfn.CHOOSECOLS(MMS_Feedlot_Methane_Equations.VEERG_4_1_1_1__2_Stage1MethaneProductionDrylot_Arguments_Method2(),1,2)} -> VS_j | N42: volatile solid production from feedlot cattle in each group | P42: {=_xlfn.CHOOSECOLS(MMS_Feedlot_Methane_Equations.VEERG_4_1_1_1__2_Stage1MethaneProductionDrylot_Arguments_Method2(),3,4)} -> kg/head/day | Q42: Calculated from 4.1.1.1 (5) | R42: {=HYPERLINK(Common_InputFunctions.Utility_SourceHyperlink($D$27),$D$27)} -> M1_Table_VS_j
D43: BO | E43: emissions potential | G43: m3 CH4/kg VS | H43: Constant | I43: ='Constants - Feedlot'!$E$22 -> 0.19 | M43: BO | N43: emissions potential | P43: m3 CH4/kg VS | Q43: Constant | R43: ='Constants - Feedlot'!$E$22 -> 0.19
D44: MMS_m5T1 | E44: fraction of manure in primary system drylot MMS | G44: fraction | H44: Input | I44: {=HYPERLINK(Common_InputFunctions.Utility_SourceHyperlink($D$49),$D$49)} -> Table_MMS_m-5_T-1 | M44: MMS_m5T1 | N44: fraction of manure in primary system drylot MMS | P44: fraction | Q44: Input | R44: {=HYPERLINK(Common_InputFunctions.Utility_SourceHyperlink($D$49),$D$49)} -> Table_MMS_m-5_T-1
D45: MCF_im5 | E45: methane conversion factor for state and drylot system | G45: fraction | H45: Constant | I45: =HLOOKUP(I47, Table_SourceData_Feedlot_MCF[#All], 2, FALSE) -> 0.01 | M45: MCF_im5 | N45: methane conversion factor for state and drylot system | P45: fraction | Q45: Constant | R45: =HLOOKUP(I47, Table_SourceData_Feedlot_MCF[#All], 2, FALSE) -> 0.01
D46: rho | E46: density of methane | G46: kg/m3 | H46: Constant | I46: ='Constants - Common'!$D$175 -> 0.6784 | M46: rho | N46: density of methane | P46: kg/m3 | Q46: Constant | R46: ='Constants - Common'!$D$175 -> 0.6784
D47: i | E47: state | H47: Input | I47: =Common_InputFunctions.Utility_LookupValueInTable('Input - Site'!$E$21,Table_AustralianStates[Common Name],Table_AustralianStates[Abbreviation]) -> NSW | M47: i | N47: state | Q47: Input | R47: =Common_InputFunctions.Utility_LookupValueInTable('Input - Site'!$E$21,Table_AustralianStates[Common Name],Table_AustralianStates[Abbreviation]) -> NSW
D49: Table_MMS_m-5_T-1
D50: Fraction of manure in primary system drylot
...

Sheet 4.1.1.3-4 Direct N20
A1: #VALUE! | C1: 4.1.1.3-4 Manure Direct N2O
A3: =HYPERLINK("#'Home'!A1", "Home") -> Home | D3: Method 1 | O3: Method 2
A4: =HYPERLINK("#'Overview'!A1", "Overview") -> Overview
A5: =HYPERLINK("#'Results'!A1", "Results") -> Results | D5: {=MMS_Feedlot_N2ODirect_Equations.VEERG_4_1_1_3__5_NitrogenIntake_Title()} -> Nitrogen intake of feedlot cattle
D6: {=MMS_Feedlot_N2ODirect_Equations.VEERG_4_1_1_3__5_NitrogenIntake_Source()} -> VEERG 2026: 4.1.1.3, Equation (5)
A7: INPUTS | D7: Formula name | E7: {=Common_InputFunctions.Utility_DisplayFunctionName(D30)} -> =MMS_Feedlot_N2ODirect_Equations.VEERG_4_1_1_3__5_NitrogenIntake
A8: =HYPERLINK("#'Input - Site'!A1", "Site") -> Site
A9: =HYPERLINK("#'Input - Feedlot'!A1", "Feedlot") -> Feedlot
D10: Variable | E10: {=MMS_Feedlot_N2ODirect_Equations.VEERG_4_1_1_3__5_NitrogenIntake_Variable()} -> NI_j
A11: CALCULATIONS | D11: Unit | E11: {=MMS_Feedlot_N2ODirect_Equations.VEERG_4_1_1_3__5_NitrogenIntake_Unit()} -> kg N/head/day
A12: =HYPERLINK("#'4.1.1.1-2 Methane'!A1", "4.1.1.1-2 Methane") -> 4.1.1.1-2 Methane
A13: =HYPERLINK("#'4.1.1.3-4 Direct N20'!A1", "4.1.1.3-4 Direct N2O") -> 4.1.1.3-4 Direct N2O | D13: {=_xlfn.CHOOSECOLS(MMS_Feedlot_N2ODirect_Equations.VEERG_4_1_1_3__5_NitrogenIntake_Arguments(),1,2)} -> I_j | E13: dry matter intake | G13: {=_xlfn.CHOOSECOLS(MMS_Feedlot_N2ODirect_Equations.VEERG_4_1_1_3__5_NitrogenIntake_Arguments(),3,4)} -> kg DM/head/day | H13: Input | I13: {=HYPERLINK(Common_InputFunctions.Utility_SourceHyperlink($D$17),$D$17)} -> M1_Table_I_j
A14: =HYPERLINK("#'4.1.1.5-6 Atmos Deposition'!A1", "4.1.1.5-6 Atmospheric deposition") -> 4.1.1.5-6 Atmospheric deposition | D14: CP_j | E14: crude protein content of feed | G14: fraction | H14: Input | I14: {=HYPERLINK(Common_InputFunctions.Utility_SourceHyperlink($D$22),$D$22)} -> M1_Table_CP_j
A15: =HYPERLINK("#'4.1.1.9 Manure applied to soils'!A1", "4.1.1.9 Manure applied to soils") -> 4.1.1.9 Manure applied to soils | D15: 6.25 | E15: factor for converting crude protein into nitrogen | G15: ratio | H15: Constant | I15: =D15 -> 6.25
A17: APPENDICES | D17: M1_Table_I_j | O17: M2_Table_I_j
A18: =HYPERLINK("#'Constants - Feedlot'!A1", "Constants - Feedlot") -> Constants - Feedlot | D18: Dry matter intake (Method 1) | O18: Dry matter intake (Method 2)
A19: =HYPERLINK("#'Constants - Livestock'!A1", "Constants - Livestock") -> Constants - Livestock | D19: Domestic | E19: Mid-fed | F19: Long-fed | O19: Domestic | P19: Mid-fed | Q19: Long-fed
A20: =HYPERLINK("#'Constants - Common'!A1", "Constants - Common") -> Constants - Common | D20: ='Input - Feedlot'!$E$14 -> 10.4 | E20: ='Input - Feedlot'!$F$14 -> 10.8 | F20: ='Input - Feedlot'!$G$14 -> 8.2 | G20: kg DM/head/day | O20: ='Input - Feedlot'!$E$20 -> 10.4 | P20: ='Input - Feedlot'!$F$20 -> 10.8 | Q20: ='Input - Feedlot'!$G$20 -> 8.2 | R20: kg DM/head/day
A21: =HYPERLINK("#'Acknowledgements'!A1", "Acknowledgements") -> Acknowledgements
D22: M1_Table_CP_j | O22: M2_Table_CP_j
D23: Crude protein content of feed (Method 1) | O23: Crude protein content of feed (Method 2)
D24: Domestic | E24: Mid-fed | F24: Long-fed | O24: Domestic | P24: Mid-fed | Q24: Long-fed
D25: ='Input - Feedlot'!$E$16 -> 0.14 | E25: ='Input - Feedlot'!$F$16 -> 0.12 | F25: ='Input - Feedlot'!$G$16 -> 0.12 | G25: fraction | O25: ='Input - Feedlot'!$E$22 -> 0.14 | P25: ='Input - Feedlot'!$F$22 -> 0.12 | Q25: ='Input - Feedlot'!$G$22 -> 0.12 | R25: fraction
D27: M1_Table_NI_j | O27: M2_Table_NI_j
D28: Nitrogen intake (Method 1) | O28: Nitrogen intake (Method 2)
D29: Domestic | E29: Mid-fed | F29: Long-fed | O29: Domestic | P29: Mid-fed | Q29: Long-fed
D30: {=MMS_Feedlot_N2ODirect_Equations.VEERG_4_1_1_3__5_NitrogenIntake(D20,D25)} -> 0.23296 | E30: {=MMS_Feedlot_N2ODirect_Equations.VEERG_4_1_1_3__5_NitrogenIntake(E20,E25)} -> 0.20736 | F30: {=MMS_Feedlot_N2ODirect_Equations.VEERG_4_1_1_3__5_NitrogenIntake(F20,F25)} -> 0.15744 | G30: =$E$11 -> kg N/head/day | O30: {=MMS_Feedlot_N2ODirect_Equations.VEERG_4_1_1_3__5_NitrogenIntake(O20,O25)} -> 0.23296 | P30: {=MMS_Feedlot_N2ODirect_Equations.VEERG_4_1_1_3__5_NitrogenIntake(P20,P25)} -> 0.20736 | Q30: {=MMS_Feedlot_N2ODirect_Equations.VEERG_4_1_1_3__5_NitrogenIntake(Q20,Q25)} -> 0.15744 | R30: =$E$11 -> kg N/head/day
D34: {=MMS_Feedlot_N2ODirect_Equations.VEERG_4_1_1_3__4_NitrogenExcretionPerHead_Title()} -> Nitrogen excretion per head per day
D35: {=MMS_Feedlot_N2ODirect_Equations.VEERG_4_1_1_3__4_NitrogenExcretionPerHead_Source()} -> VEERG 2026: 4.1.1.3, Equation (4)
D36: Function name | E36: {=Common_InputFunctions.Utility_DisplayFunctionName(D54)} -> =MMS_Feedlot_N2ODirect_Equations.VEERG_4_1_1_3__4_NitrogenExcretionPerHead
D40: Variable | E40: {=MMS_Feedlot_N2ODirect_Equations.VEERG_4_1_1_3__4_NitrogenExcretionPerHead_Variable()} -> NE_j
D41: Unit | E41: {=MMS_Feedlot_N2ODirect_Equations.VEERG_4_1_1_3__4_NitrogenExcretionPerHead_Unit()} -> kg N/head/day
D43: {=_xlfn.CHOOSECOLS(MMS_Feedlot_N2ODirect_Equations.VEERG_4_1_1_3__4_NitrogenExcretionPerHead_Arguments(),1,2)} -> NI_j | E43: nitrogen intake | G43: {=_xlfn.CHOOSECOLS(MMS_Feedlot_N2ODirect_Equations.VEERG_4_1_1_3__4_NitrogenExcretionPerHead_Arguments(),3,4)} -> kg N/head/day | H43: Calculated from 4.1.1.3 (5) | I43: {=HYPERLINK(Common_InputFunctions.Utility_SourceHyperlink($D$27),$D$27)} -> M1_Table_NI_j
D44: NR_j | E44: nitrogen retention expressed as a fraction of intake | G44: fraction | H44: Input | I44: {=HYPERLINK(Common_InputFunctions.Utility_SourceHyperlink($D$46),$D$46)} -> M1_Table_NR_j
D46: M1_Table_NR_j | O46: M2_Table_NR_j
D47: Nitrogen retention (Method 1) | O47: Nitrogen retention (Method 2)
D48: Domestic | E48: Mid-fed | F48: Long-fed | O48: Domestic | P48: Mid-fed | Q48: Long-fed
D49: ='Input - Feedlot'!$E$17/100 -> 0.204 | E49: ='Input - Feedlot'!$F$17/100 -> 0.127 | F49: ='Input - Feedlot'!$G$17/100 -> 0.07 | G49: Fraction of intake | O49: ='Input - Feedlot'!$E$23/100 -> 0.204 | P49: ='Input - Feedlot'!$F$23/100 -> 0.127 | Q49: ='Input - Feedlot'!$G$23/100 -> 0.07 | R49: fraction
D51: M1_Table_NE_j | O51: M2_Table_NE_j
D52: Nitrogen retention (Method 1) | O52: Nitrogen retention (Method 2)
...

Sheet 4.1.1.5-6 Atmos Deposition
A1: #VALUE! | C1: 4.1.1.5-6 Manure Atmospheric Deposition
A3: =HYPERLINK("#'Home'!A1", "Home") -> Home | D3: Method 1 | M3: Method 2
A4: =HYPERLINK("#'Overview'!A1", "Overview") -> Overview
A5: =HYPERLINK("#'Results'!A1", "Results") -> Results | D5: {=MMS_Feedlot_AtmosphericDeposition_Equations.VEERG_4_1_1_5__2_VolatilisedNitrogenFromManureManagement_Title()} -> Volatilised nitrogen from manure management
D6: {=MMS_Feedlot_AtmosphericDeposition_Equations.VEERG_4_1_1_5__2_VolatilisedNitrogenFromManureManagement_Source()} -> VEERG 2026: 4.1.1.5, Equation (2)
A7: INPUTS | D7: Function name | E7: {=Common_InputFunctions.Utility_DisplayFunctionName(E40)} -> =MMS_Feedlot_AtmosphericDeposition_Equations.VEERG_4_1_1_5__2_VolatilisedNitrogenFromManureManagement
A8: =HYPERLINK("#'Input - Site'!A1", "Site") -> Site
A9: =HYPERLINK("#'Input - Feedlot'!A1", "Feedlot") -> Feedlot
A11: CALCULATIONS | D11: Variable | E11: {=MMS_Feedlot_AtmosphericDeposition_Equations.VEERG_4_1_1_5__2_VolatilisedNitrogenFromManureManagement_Variable()} -> MMS_ATMOS
A12: =HYPERLINK("#'4.1.1.1-2 Methane'!A1", "4.1.1.1-2 Methane") -> 4.1.1.1-2 Methane | D12: Unit | E12: {=MMS_Feedlot_AtmosphericDeposition_Equations.VEERG_4_1_1_5__2_VolatilisedNitrogenFromManureManagement_Unit()} -> kg N
A13: =HYPERLINK("#'4.1.1.3-4 Direct N20'!A1", "4.1.1.3-4 Direct N2O") -> 4.1.1.3-4 Direct N2O
A14: =HYPERLINK("#'4.1.1.5-6 Atmos Deposition'!A1", "4.1.1.5-6 Atmospheric deposition") -> 4.1.1.5-6 Atmospheric deposition | D14: {=_xlfn.CHOOSECOLS(MMS_Feedlot_AtmosphericDeposition_Equations.VEERG_4_1_1_5__2_VolatilisedNitrogenFromManureManagement_Arguments(),1,2)} -> MN_jmT | E14: nitrogen in each treatment stage MMS (excluding MN_ijm13T2) | G14: {=_xlfn.CHOOSECOLS(MMS_Feedlot_AtmosphericDeposition_Equations.VEERG_4_1_1_5__2_VolatilisedNitrogenFromManureManagement_Arguments(),3,4)} -> kg N | H14: Calculated from 4.1.1.3 (2)(6)(8) | I14: {=HYPERLINK(Common_InputFunctions.Utility_SourceHyperlink($D$20),$D$20)} -> M1_Table_MN_j_m_T
A15: =HYPERLINK("#'4.1.1.9 Manure applied to soils'!A1", "4.1.1.9 Manure applied to soils") -> 4.1.1.9 Manure applied to soils | D15: FracGASM_mT | E15: fraction of N volatilised in each MMS | G15: (kg NH3-N + NOx-N)/kg N | H15: Constant | I15: {=HYPERLINK(Common_InputFunctions.Utility_SourceHyperlink($D$29),$D$29)} -> Table_FracGASM_m_T-2-3
A17: APPENDICES | D17: Note: Manure that is directly applied to soil after stage 1 is not included in Atmospheric Deposition calculations
A18: =HYPERLINK("#'Constants - Feedlot'!A1", "Constants - Feedlot") -> Constants - Feedlot | D18: and instead is handled in 'Manure applied to soils'.
A19: =HYPERLINK("#'Constants - Livestock'!A1", "Constants - Livestock") -> Constants - Livestock
A20: =HYPERLINK("#'Constants - Common'!A1", "Constants - Common") -> Constants - Common | D20: M1_Table_MN_j_m_T | M20: M2_Table_MN_j_m_T
A21: =HYPERLINK("#'Acknowledgements'!A1", "Acknowledgements") -> Acknowledgements | D21: Nitrogen in each MMS excluding direct application (Method 1) | M21: Nitrogen in each MMS excluding direct application (Method 2)
D22: MMS | E22: Domestic | F22: Mid-fed | G22: Long-fed | M22: MMS | N22: Domestic | O22: Mid-fed | P22: Long-fed
D23: ='Input - Feedlot'!$D$28 -> Drylot (feed pad) | E23: ='4.1.1.3-4 Direct N20'!$E$106 -> 71763.794 | F23: ='4.1.1.3-4 Direct N20'!$F$106 -> 2534.3539 | G23: ='4.1.1.3-4 Direct N20'!$G$106 -> 3660.48 | H23: =$G$14 -> kg N | M23: ='Input - Feedlot'!$D$28 -> Drylot (feed pad) | N23: ='4.1.1.3-4 Direct N20'!$P$106 -> 71763.794 | O23: ='4.1.1.3-4 Direct N20'!$Q$106 -> 2534.3539 | P23: ='4.1.1.3-4 Direct N20'!$R$106 -> 3660.48 | Q23: =$G$14 -> kg N
D24: ='Input - Feedlot'!$D$32 -> Solid storage | E24: ='4.1.1.3-4 Direct N20'!$E$174 -> 5376.5434 | F24: ='4.1.1.3-4 Direct N20'!$F$174 -> 189.8738 | G24: ='4.1.1.3-4 Direct N20'!$G$174 -> 274.24316 | M24: ='Input - Feedlot'!$D$32 -> Solid storage | N24: ='4.1.1.3-4 Direct N20'!$P$174 -> 5376.5434 | O24: ='4.1.1.3-4 Direct N20'!$Q$174 -> 189.8738 | P24: ='4.1.1.3-4 Direct N20'!$R$174 -> 274.24316
D25: ='Input - Feedlot'!$D$33 -> Composting (passive windrow) | E25: ='4.1.1.3-4 Direct N20'!$E$175 -> 5376.5434 | F25: ='4.1.1.3-4 Direct N20'!$F$175 -> 189.8738 | G25: ='4.1.1.3-4 Direct N20'!$G$175 -> 274.24316 | M25: ='Input - Feedlot'!$D$33 -> Composting (passive windrow) | N25: ='4.1.1.3-4 Direct N20'!$P$175 -> 5376.5434 | O25: ='4.1.1.3-4 Direct N20'!$Q$175 -> 189.8738 | P25: ='4.1.1.3-4 Direct N20'!$R$175 -> 274.24316
D26: ='Input - Feedlot'!$D$34 -> Direct application | E26: N/A | F26: N/A | G26: N/A | M26: ='Input - Feedlot'!$D$34 -> Direct application | N26: N/A | O26: N/A | P26: N/A
D27: ='Input - Feedlot'!$D$38 -> Anaerobic lagoon | E27: ='4.1.1.3-4 Direct N20'!$E$129 -> 1435.2759 | F27: ='4.1.1.3-4 Direct N20'!$F$129 -> 50.687078 | G27: ='4.1.1.3-4 Direct N20'!$G$129 -> 73.2096 | M27: ='Input - Feedlot'!$D$38 -> Anaerobic lagoon | N27: ='4.1.1.3-4 Direct N20'!$P$129 -> 1435.2759 | O27: ='4.1.1.3-4 Direct N20'!$Q$129 -> 50.687078 | P27: ='4.1.1.3-4 Direct N20'!$R$129 -> 73.2096
D29: Table_FracGASM_m_T-2-3
D30: Fraction of N volatilised in each MMS
D31: MMS | E31: EFjm
D32: ='Input - Feedlot'!$D$28 -> Drylot (feed pad) | E32: =_xlfn.XLOOKUP(D32, Table_SourceData_Feedlot_FracGASMmT[NIR definition], Table_SourceData_Feedlot_FracGASMmT[FracGASMmT]) -> 0.6 | F32: =G15 -> (kg NH3-N + NOx-N)/kg N
D33: ='Input - Feedlot'!$D$32 -> Solid storage | E33: =_xlfn.XLOOKUP(D33, Table_SourceData_Feedlot_FracGASMmT[NIR definition], Table_SourceData_Feedlot_FracGASMmT[FracGASMmT]) -> 0.25
D34: ='Input - Feedlot'!$D$33 -> Composting (passive windrow) | E34: =_xlfn.XLOOKUP(D34, Table_SourceData_Feedlot_FracGASMmT[NIR definition], Table_SourceData_Feedlot_FracGASMmT[FracGASMmT]) -> 0.4
D35: ='Input - Feedlot'!$D$38 -> Anaerobic lagoon | E35: =_xlfn.XLOOKUP(D35, Table_SourceData_Feedlot_FracGASMmT[NIR definition], Table_SourceData_Feedlot_FracGASMmT[FracGASMmT]) -> 0.35
D37: M1_Table_MMS_ATMOS | M37: M1_Table_MMS_ATMOS
D38: Nitrogen in each MMS excluding direct application (Method 1) | M38: Nitrogen in each MMS excluding direct application (Method 1)
D39: MMS | E39: Domestic | F39: Mid-fed | G39: Long-fed | M39: MMS | N39: Domestic | O39: Mid-fed | P39: Long-fed
D40: ='Input - Feedlot'!$D$28 -> Drylot (feed pad) | E40: {=MMS_Feedlot_AtmosphericDeposition_Equations.VEERG_4_1_1_5__2_VolatilisedNitrogenFromManureManagement(E23,$E32)} -> 43058.276 | F40: {=MMS_Feedlot_AtmosphericDeposition_Equations.VEERG_4_1_1_5__2_VolatilisedNitrogenFromManureManagement(F23,$E32)} -> 1520.6124 | G40: {=MMS_Feedlot_AtmosphericDeposition_Equations.VEERG_4_1_1_5__2_VolatilisedNitrogenFromManureManagement(G23,$E32)} -> 2196.288 | H40: =$E$12 -> kg N | M40: ='Input - Feedlot'!$D$28 -> Drylot (feed pad) | N40: {=MMS_Feedlot_AtmosphericDeposition_Equations.VEERG_4_1_1_5__2_VolatilisedNitrogenFromManureManagement(N23,$E32)} -> 43058.276 | O40: {=MMS_Feedlot_AtmosphericDeposition_Equations.VEERG_4_1_1_5__2_VolatilisedNitrogenFromManureManagement(O23,$E32)} -> 1520.6124 | P40: {=MMS_Feedlot_AtmosphericDeposition_Equations.VEERG_4_1_1_5__2_VolatilisedNitrogenFromManureManagement(P23,$E32)} -> 2196.288 | Q40: =$E$12 -> kg N
D41: ='Input - Feedlot'!$D$32 -> Solid storage | E41: {=MMS_Feedlot_AtmosphericDeposition_Equations.VEERG_4_1_1_5__2_VolatilisedNitrogenFromManureManagement(E24,$E33)} -> 1344.1359 | F41: {=MMS_Feedlot_AtmosphericDeposition_Equations.VEERG_4_1_1_5__2_VolatilisedNitrogenFromManureManagement(F24,$E33)} -> 47.468449 | G41: {=MMS_Feedlot_AtmosphericDeposition_Equations.VEERG_4_1_1_5__2_VolatilisedNitrogenFromManureManagement(G24,$E33)} -> 68.56079 | M41: ='Input - Feedlot'!$D$32 -> Solid storage | N41: {=MMS_Feedlot_AtmosphericDeposition_Equations.VEERG_4_1_1_5__2_VolatilisedNitrogenFromManureManagement(N24,$E33)} -> 1344.1359 | O41: {=MMS_Feedlot_AtmosphericDeposition_Equations.VEERG_4_1_1_5__2_VolatilisedNitrogenFromManureManagement(O24,$E33)} -> 47.468449 | P41: {=MMS_Feedlot_AtmosphericDeposition_Equations.VEERG_4_1_1_5__2_VolatilisedNitrogenFromManureManagement(P24,$E33)} -> 68.56079
D42: ='Input - Feedlot'!$D$33 -> Composting (passive windrow) | E42: {=MMS_Feedlot_AtmosphericDeposition_Equations.VEERG_4_1_1_5__2_VolatilisedNitrogenFromManureManagement(E25,$E34)} -> 2150.6174 | F42: {=MMS_Feedlot_AtmosphericDeposition_Equations.VEERG_4_1_1_5__2_VolatilisedNitrogenFromManureManagement(F25,$E34)} -> 75.949518 | G42: {=MMS_Feedlot_AtmosphericDeposition_Equations.VEERG_4_1_1_5__2_VolatilisedNitrogenFromManureManagement(G25,$E34)} -> 109.69726 | M42: ='Input - Feedlot'!$D$33 -> Composting (passive windrow) | N42: {=MMS_Feedlot_AtmosphericDeposition_Equations.VEERG_4_1_1_5__2_VolatilisedNitrogenFromManureManagement(N25,$E34)} -> 2150.6174 | O42: {=MMS_Feedlot_AtmosphericDeposition_Equations.VEERG_4_1_1_5__2_VolatilisedNitrogenFromManureManagement(O25,$E34)} -> 75.949518 | P42: {=MMS_Feedlot_AtmosphericDeposition_Equations.VEERG_4_1_1_5__2_VolatilisedNitrogenFromManureManagement(P25,$E34)} -> 109.69726
D43: ='Input - Feedlot'!$D$34 -> Direct application | E43: N/A | F43: N/A | G43: N/A | M43: ='Input - Feedlot'!$D$34 -> Direct application | N43: N/A | O43: N/A | P43: N/A
D44: ='Input - Feedlot'!$D$38 -> Anaerobic lagoon | E44: {=MMS_Feedlot_AtmosphericDeposition_Equations.VEERG_4_1_1_5__2_VolatilisedNitrogenFromManureManagement(E27,$E35)} -> 502.34656 | F44: {=MMS_Feedlot_AtmosphericDeposition_Equations.VEERG_4_1_1_5__2_VolatilisedNitrogenFromManureManagement(F27,$E35)} -> 17.740477 | G44: {=MMS_Feedlot_AtmosphericDeposition_Equations.VEERG_4_1_1_5__2_VolatilisedNitrogenFromManureManagement(G27,$E35)} -> 25.62336 | M44: ='Input - Feedlot'!$D$38 -> Anaerobic lagoon | N44: {=MMS_Feedlot_AtmosphericDeposition_Equations.VEERG_4_1_1_5__2_VolatilisedNitrogenFromManureManagement(N27,$E35)} -> 502.34656 | O44: {=MMS_Feedlot_AtmosphericDeposition_Equations.VEERG_4_1_1_5__2_VolatilisedNitrogenFromManureManagement(O27,$E35)} -> 17.740477 | P44: {=MMS_Feedlot_AtmosphericDeposition_Equations.VEERG_4_1_1_5__2_VolatilisedNitrogenFromManureManagement(P27,$E35)} -> 25.62336
D46: MMSATMOS | E46: =SUM(E40:G44) -> 51117.316 | F46: =$E$12 -> kg N | M46: MMSATMOS | N46: =SUM(N40:P44) -> 51117.316 | O46: =$E$12 -> kg N
...

Sheet 4.1.1.9 Manure applied to soils
A1: #VALUE! | C1: 4.1.1.9 Manure applied to soils
A3: =HYPERLINK("#'Home'!A1", "Home") -> Home | D3: Method 1 | N3: Method 2
A4: =HYPERLINK("#'Overview'!A1", "Overview") -> Overview
A5: =HYPERLINK("#'Results'!A1", "Results") -> Results | D5: {=MMS_Feedlot_ManureAppliedToSoils_Equations.VEERG_4_1_1_9__1_MassOfNitrogenAppliedToSoilsScope1_Title()} -> Mass of nitrogen applied to soils for scope 1 emissions
D6: {=MMS_Feedlot_ManureAppliedToSoils_Equations.VEERG_4_1_1_9__1_MassOfNitrogenAppliedToSoilsScope1_Source()} -> VEERG 2026: 4.1.1.9, Equation (1)
A7: INPUTS | D7: Function name | E7: {=Common_InputFunctions.Utility_DisplayFunctionName(E56)} -> =MMS_Feedlot_ManureAppliedToSoils_Equations.VEERG_4_1_1_9__1_MassOfNitrogenAppliedToSoilsScope1
A8: =HYPERLINK("#'Input - Site'!A1", "Site") -> Site
A9: =HYPERLINK("#'Input - Feedlot'!A1", "Feedlot") -> Feedlot
A11: CALCULATIONS | D11: Variable | E11: {=MMS_Feedlot_ManureAppliedToSoils_Equations.VEERG_4_1_1_9__1_MassOfNitrogenAppliedToSoilsScope1_Variable()} -> MNSoil_scope1
A12: =HYPERLINK("#'4.1.1.1-2 Methane'!A1", "4.1.1.1-2 Methane") -> 4.1.1.1-2 Methane | D12: Unit | E12: {=MMS_Feedlot_ManureAppliedToSoils_Equations.VEERG_4_1_1_9__1_MassOfNitrogenAppliedToSoilsScope1_Unit()} -> kg N
A13: =HYPERLINK("#'4.1.1.3-4 Direct N20'!A1", "4.1.1.3-4 Direct N2O") -> 4.1.1.3-4 Direct N2O
A14: =HYPERLINK("#'4.1.1.5-6 Atmos Deposition'!A1", "4.1.1.5-6 Atmospheric deposition") -> 4.1.1.5-6 Atmospheric deposition | D14: {=_xlfn.CHOOSECOLS(MMS_Feedlot_ManureAppliedToSoils_Equations.VEERG_4_1_1_9__1_MassOfNitrogenAppliedToSoilsScope1_Arguments(),1,2)} -> MN_jmT23 | E14: mass of N in secondary and tertiary treatment MMS stages as calculated for manure management | H14: {=_xlfn.CHOOSECOLS(MMS_Feedlot_ManureAppliedToSoils_Equations.VEERG_4_1_1_9__1_MassOfNitrogenAppliedToSoilsScope1_Arguments(),3,4)} -> kg N | I14: Calculated from 4.1.1.3 (6)(8) | J14: {=HYPERLINK(Common_InputFunctions.Utility_SourceHyperlink($D$19),$D$19)} -> M1_Table_MN_j_m_T-2-3
A15: =HYPERLINK("#'4.1.1.9 Manure applied to soils'!A1", "4.1.1.9 Manure applied to soils") -> 4.1.1.9 Manure applied to soils | D15: EF_mT23 | E15: nitrous oxide emission factor for each MMS | H15: kg N2O-N/kg N | I15: Constant | J15: {=HYPERLINK(Common_InputFunctions.Utility_SourceHyperlink($D$27),$D$27)} -> Table_EF_j_m_T-2-3
D16: FracGASM_mT23 | E16: fraction of animal waste N volatilised in each MMS for each cattle group | H16: (kg NH3-N + NOx-N)/kg N | I16: Constant | J16: {=HYPERLINK(Common_InputFunctions.Utility_SourceHyperlink($D$36),$D$36)} -> Table_FracGASM_m_T-2-3
A17: APPENDICES | D17: PF | E17: fraction of manure applied to soil within the feedlot boundary | H17: fraction | I17: Input | J17: {=HYPERLINK(Common_InputFunctions.Utility_SourceHyperlink($D$45),$D$45)} -> Table_PF
A18: =HYPERLINK("#'Constants - Feedlot'!A1", "Constants - Feedlot") -> Constants - Feedlot
A19: =HYPERLINK("#'Constants - Livestock'!A1", "Constants - Livestock") -> Constants - Livestock | D19: M1_Table_MN_j_m_T-2-3 | N19: M2_Table_MN_j_m_T-2-3
A20: =HYPERLINK("#'Constants - Common'!A1", "Constants - Common") -> Constants - Common | D20: Mass on N in stage 2 and 3 MMS (Method 1) | N20: Mass on N in stage 2 and 3 MMS (Method 2)
A21: =HYPERLINK("#'Acknowledgements'!A1", "Acknowledgements") -> Acknowledgements | D21: MMS | E21: Domestic | F21: Mid-fed | G21: Long-fed | N21: MMS | O21: Domestic | P21: Mid-fed | Q21: Long-fed
D22: ='Input - Feedlot'!$D$32 -> Solid storage | E22: ='4.1.1.3-4 Direct N20'!$E$174 -> 5376.5434 | F22: ='4.1.1.3-4 Direct N20'!$F$174 -> 189.8738 | G22: ='4.1.1.3-4 Direct N20'!$G$174 -> 274.24316 | H22: kg N | N22: ='Input - Feedlot'!$D$32 -> Solid storage | O22: ='4.1.1.3-4 Direct N20'!$P$174 -> 5376.5434 | P22: ='4.1.1.3-4 Direct N20'!$Q$174 -> 189.8738 | Q22: ='4.1.1.3-4 Direct N20'!$R$174 -> 274.24316 | R22: kg N
D23: ='Input - Feedlot'!$D$33 -> Composting (passive windrow) | E23: ='4.1.1.3-4 Direct N20'!$E$175 -> 5376.5434 | F23: ='4.1.1.3-4 Direct N20'!$F$175 -> 189.8738 | G23: ='4.1.1.3-4 Direct N20'!$G$175 -> 274.24316 | H23: kg N | N23: ='Input - Feedlot'!$D$33 -> Composting (passive windrow) | O23: ='4.1.1.3-4 Direct N20'!$P$175 -> 5376.5434 | P23: ='4.1.1.3-4 Direct N20'!$Q$175 -> 189.8738 | Q23: ='4.1.1.3-4 Direct N20'!$R$175 -> 274.24316 | R23: kg N
D24: ='Input - Feedlot'!$D$34 -> Direct application | E24: ='4.1.1.3-4 Direct N20'!$E$176 -> 16129.63 | F24: ='4.1.1.3-4 Direct N20'!$F$176 -> 569.62139 | G24: ='4.1.1.3-4 Direct N20'!$G$176 -> 822.72948 | N24: ='Input - Feedlot'!$D$34 -> Direct application | O24: ='4.1.1.3-4 Direct N20'!$P$176 -> 16129.63 | P24: ='4.1.1.3-4 Direct N20'!$Q$176 -> 569.62139 | Q24: ='4.1.1.3-4 Direct N20'!$R$176 -> 822.72948 | R24: kg N
D25: ='Input - Feedlot'!$D$38 -> Anaerobic lagoon | E25: ='4.1.1.3-4 Direct N20'!$E$129 -> 1435.2759 | F25: ='4.1.1.3-4 Direct N20'!$F$129 -> 50.687078 | G25: ='4.1.1.3-4 Direct N20'!$G$129 -> 73.2096 | H25: kg N | N25: ='Input - Feedlot'!$D$38 -> Anaerobic lagoon | O25: ='4.1.1.3-4 Direct N20'!$P$129 -> 1435.2759 | P25: ='4.1.1.3-4 Direct N20'!$Q$129 -> 50.687078 | Q25: ='4.1.1.3-4 Direct N20'!$R$129 -> 73.2096 | R25: kg N
D27: Table_EF_j_m_T-2-3
D28: EFs for MMS
D29: MMS | E29: EFjm
D30: ='Input - Feedlot'!$D$28 -> Drylot (feed pad) | E30: =_xlfn.XLOOKUP(D30, Table_SourceData_Feedlot_NO2EFs[NIR definition], Table_SourceData_Feedlot_NO2EFs[EF mT]) -> 0.0054 | F30: kg N2O/kg N
D31: ='Input - Feedlot'!$D$32 -> Solid storage | E31: =_xlfn.XLOOKUP($D$31, Table_SourceData_Feedlot_NO2EFs[NIR definition], Table_SourceData_Feedlot_NO2EFs[EF mT]) -> 0.005 | F31: kg N2O/kg N
D32: ='Input - Feedlot'!$D$33 -> Composting (passive windrow) | E32: =_xlfn.XLOOKUP($D$32, Table_SourceData_Feedlot_NO2EFs[NIR definition], Table_SourceData_Feedlot_NO2EFs[EF mT]) -> 0.01 | F32: kg N2O/kg N
D33: Direct application | E33: =_xlfn.XLOOKUP($D$33, Table_SourceData_Feedlot_NO2EFs[NIR definition], Table_SourceData_Feedlot_NO2EFs[EF mT]) -> 0 | F33: kg N2O/kg N
D34: ='Input - Feedlot'!$D$38 -> Anaerobic lagoon | E34: =_xlfn.XLOOKUP($D$34, Table_SourceData_Feedlot_NO2EFs[NIR definition], Table_SourceData_Feedlot_NO2EFs[EF mT]) -> 0 | F34: kg N2O/kg N
D36: Table_FracGASM_m_T-2-3
D37: Fraction of N volatilised in each MMS
D38: MMS | E38: EFjm
D39: ='Input - Feedlot'!$D$28 -> Drylot (feed pad) | E39: =_xlfn.XLOOKUP(D39, Table_SourceData_Feedlot_FracGASMmT[NIR definition], Table_SourceData_Feedlot_FracGASMmT[FracGASMmT]) -> 0.6 | F39: (kg NH3-N + NOx-N)/kg N
D40: ='Input - Feedlot'!$D$32 -> Solid storage | E40: =_xlfn.XLOOKUP(D40, Table_SourceData_Feedlot_FracGASMmT[NIR definition], Table_SourceData_Feedlot_FracGASMmT[FracGASMmT]) -> 0.25 | F40: (kg NH3-N + NOx-N)/kg N
D41: ='Input - Feedlot'!$D$33 -> Composting (passive windrow) | E41: =_xlfn.XLOOKUP(D41, Table_SourceData_Feedlot_FracGASMmT[NIR definition], Table_SourceData_Feedlot_FracGASMmT[FracGASMmT]) -> 0.4 | F41: (kg NH3-N + NOx-N)/kg N
D42: ='Input - Feedlot'!$D$34 -> Direct application | E42: =_xlfn.XLOOKUP(D42, Table_SourceData_Feedlot_FracGASMmT[NIR definition], Table_SourceData_Feedlot_FracGASMmT[FracGASMmT]) -> 0 | F42: (kg NH3-N + NOx-N)/kg N
D43: ='Input - Feedlot'!$D$38 -> Anaerobic lagoon | E43: =_xlfn.XLOOKUP(D43, Table_SourceData_Feedlot_FracGASMmT[NIR definition], Table_SourceData_Feedlot_FracGASMmT[FracGASMmT]) -> 0.35 | F43: (kg NH3-N + NOx-N)/kg N
D45: Table_PF
...

Sheet Constants - Feedlot
A1: #VALUE! | C1: Source Data - Feedlot
A3: =HYPERLINK("#'Home'!A1", "Home") -> Home
A4: =HYPERLINK("#'Overview'!A1", "Overview") -> Overview
A5: =HYPERLINK("#'Results'!A1", "Results") -> Results | D5: {=SourceData_Feedlot.SourceData_Feedlot_VSL_Title()} -> Feedlot - Fraction of volatile solids lost during storage in the primary system
D6: {=SourceData_Feedlot.SourceData_Feedlot_VSL_Source()} -> VEERG 2026: 4.1.2.3 CONSTANTS
A7: INPUTS | D7: {=SourceData_Feedlot.SourceData_Feedlot_VSL_Variable()} -> VSL | E7: {=SourceData_Feedlot.SourceData_Feedlot_VSL_Data()} -> 0.5 | F7: {=SourceData_Feedlot.SourceData_Feedlot_VSL_Unit()} -> Fraction
A8: =HYPERLINK("#'Input - Site'!A1", "Site") -> Site
A9: =HYPERLINK("#'Input - Feedlot'!A1", "Feedlot") -> Feedlot
D10: {=SourceData_Feedlot.SourceData_Feedlot_MMSm1T3_Title()} -> Fraction of volatile solids to each tertiary system assumed that 2 per cent is run - off from the feed pad.
A11: CALCULATIONS | D11: {=SourceData_Feedlot.SourceData_Feedlot_MMSm1T3_Source()} -> VEERG 2026: 4.1.2.3 CONSTANTS
A12: =HYPERLINK("#'4.1.1.1-2 Methane'!A1", "4.1.1.1-2 Methane") -> 4.1.1.1-2 Methane | D12: {=SourceData_Feedlot.SourceData_Feedlot_MMSm1T3_Variable()} -> MMSm1T3 | E12: {=SourceData_Feedlot.SourceData_Feedlot_MMSm1T3_Data()} -> 0.02 | F12: {=SourceData_Feedlot.SourceData_Feedlot_MMSm1T3_Unit()} -> Fraction
A13: =HYPERLINK("#'4.1.1.3-4 Direct N20'!A1", "4.1.1.3-4 Direct N2O") -> 4.1.1.3-4 Direct N2O
A14: =HYPERLINK("#'4.1.1.5-6 Atmos Deposition'!A1", "4.1.1.5-6 Atmospheric deposition") -> 4.1.1.5-6 Atmospheric deposition
A15: =HYPERLINK("#'4.1.1.9 Manure applied to soils'!A1", "4.1.1.9 Manure applied to soils") -> 4.1.1.9 Manure applied to soils | D15: {=SourceData_Feedlot.SourceData_Feedlot_AshContent_Title()} -> Ash content of manure.
D16: {=SourceData_Feedlot.SourceData_Feedlot_AshContent_Source()} -> VEERG 2026: 4.1.2.3 CONSTANTS
A17: APPENDICES | D17: {=SourceData_Feedlot.SourceData_Feedlot_AshContent_Variable()} -> A | E17: {=SourceData_Feedlot.SourceData_Feedlot_AshContent_Data()} -> 0.16 | F17: {=SourceData_Feedlot.SourceData_Feedlot_AshContent_Unit()} -> Fraction
A18: =HYPERLINK("#'Constants - Feedlot'!A1", "Constants - Feedlot") -> Constants - Feedlot
