Workbook
Name Common_Equations.Common_ConvertCH4ToCO2e: _xlfn.LAMBDA(_xlpm.E_CH4,_xlpm.GWP_CH4, _xlpm.E_CH4 * _xlpm.GWP_CH4)
Name Common_Equations.Common_ConvertCH4ToCO2e_Arguments: _xlfn.LAMBDA(_xlfn.MAKEARRAY(2, 2, _xlfn.LAMBDA(_xlpm.r,_xlpm.c, INDEX({"ECH4","Methane emissions (t CH4)";"GWPCH4","Global warming potential for methane (t CO2-e / t CH4)"}, _xlpm.r, _xlpm.c))))
Name Common_Equations.Common_ConvertCH4ToCO2e_LatexEquation: _xlfn.LAMBDA("CO2_e = E_{CH4} \times GWP_{CH4}")
Name Common_Equations.Common_ConvertCH4ToCO2e_NIRReference: _xlfn.LAMBDA("")
Name Common_Equations.Common_ConvertCH4ToCO2e_Title: _xlfn.LAMBDA("Convert methane emissions to carbon dioxide equivalent emissions")
Name Common_Equations.Common_ConvertCH4ToCO2e_Unit: _xlfn.LAMBDA("t CO2e")
Name Common_Equations.Common_ConvertCH4ToCO2e_Variable: _xlfn.LAMBDA("ECH4 CO2e")
Name Common_Equations.Common_ConvertN2OToCO2e: _xlfn.LAMBDA(_xlpm.E_N2O,_xlpm.GWP_N2O, _xlpm.E_N2O * _xlpm.GWP_N2O)
Name Common_Equations.Common_ConvertN2OToCO2e_LatexEquation: _xlfn.LAMBDA("CO2_e = E_{N2O} \times GWP_{N2O}")
Name Common_Equations.Common_ConvertN2OToCO2e_NIRReference: _xlfn.LAMBDA("")
Name Common_Equations.Common_ConvertN2OToCO2e_Title: _xlfn.LAMBDA("Convert nitrous oxide emissions to carbon dioxide equivalent emissions")
Name Common_Equations.Common_ConvertN2OToCO2e_Unit: _xlfn.LAMBDA("t CO2e")
Name Common_Equations.Common_ConvertN2OToCO2e_Variable: _xlfn.LAMBDA("EN2O CO2e")
Name Common_InputFunctions.Utility_DisplayFunctionName: _xlfn.LAMBDA(_xlpm.Function, _xlfn.TEXTBEFORE(_xlfn.FORMULATEXT(_xlpm.Function), "("))
Name Common_InputFunctions.Utility_GetArrayTableColumnStartNumber: _xlfn.LAMBDA(_xlpm.TableHeaderCell, COLUMN(_xlpm.TableHeaderCell))
Name Common_InputFunctions.Utility_GetArrayTableRowStartNumber: _xlfn.LAMBDA(_xlpm.TableheaderCell,_xlpm.RowsBetweenHeaderandArray, ROW(_xlpm.TableheaderCell) + _xlpm.RowsBetweenHeaderandArray - 1)
Name Common_InputFunctions.Utility_LookupValueInTable: _xlfn.LAMBDA(_xlpm.LookupValue,_xlpm.LookupArray,_xlpm.ReturnArray, _xlfn.XLOOKUP(_xlpm.LookupValue, _xlpm.LookupArray, _xlpm.ReturnArray, ""))
Name Common_SourceData.Common_SourceData_AustralianStatesTerritories_Source: _xlfn.LAMBDA("")
Name Common_SourceData.Common_SourceData_AustralianStatesTerritories_Title: _xlfn.LAMBDA("Australian states and territories")
Name Common_SourceData.Common_SourceData_AustralianStatesTerritories_Unit: _xlfn.LAMBDA("")
Name Common_SourceData.Common_SourceData_AustralianStatesTerritories_Variable: _xlfn.LAMBDA("")
Name Common_SourceData.Common_SourceData_ClimateZones_Source: _xlfn.LAMBDA("VEERG 2026: Table 1.3: Climate and Rainfall zone classifications and definitions")
Name Common_SourceData.Common_SourceData_ClimateZones_Title: _xlfn.LAMBDA("VEERG Australian climate zones")
Name Common_SourceData.Common_SourceData_ClimateZones_Unit: _xlfn.LAMBDA("")
Name Common_SourceData.Common_SourceData_ClimateZones_Variable: _xlfn.LAMBDA("")
Name Common_SourceData.Common_SourceData_ConvertGasElementalToMolecular_Source: _xlfn.LAMBDA("XXXXXXX")
Name Common_SourceData.Common_SourceData_ConvertGasElementalToMolecular_Title: _xlfn.LAMBDA("Factor to convert elemental mass of gas to molecular mass")
Name Common_SourceData.Common_SourceData_ConvertGasElementalToMolecular_Unit: _xlfn.LAMBDA("factor")
Name Common_SourceData.Common_SourceData_ConvertGasElementalToMolecular_Variable: _xlfn.LAMBDA("Cg")
Name Common_SourceData.Common_SourceData_ConvertN2oElementalToMolecularCg_Data: _xlfn.LAMBDA(44 / 28)
Name Common_SourceData.Common_SourceData_ConvertN2oElementalToMolecularCg_Source: _xlfn.LAMBDA("National Inventory Report 2023 Volume 1")
Name Common_SourceData.Common_SourceData_ConvertN2oElementalToMolecularCg_Title: _xlfn.LAMBDA("Factor to convert elemental mass of N2O to molecular mass")
Name Common_SourceData.Common_SourceData_ConvertN2oElementalToMolecularCg_Unit: _xlfn.LAMBDA("factor")
Name Common_SourceData.Common_SourceData_ConvertN2oElementalToMolecularCg_Variable: _xlfn.LAMBDA("CgN2O")
Name Common_SourceData.Common_SourceData_DataScores_Scope3_Source: _xlfn.LAMBDA("VEERG 2026: XXXXXXXX")
Name Common_SourceData.Common_SourceData_DataScores_Scope3_Title: _xlfn.LAMBDA("Australian data scores for scope 3")
Name Common_SourceData.Common_SourceData_DataScores_Scope3_Unit: _xlfn.LAMBDA("")
Name Common_SourceData.Common_SourceData_DataScores_Scope3_Variable: _xlfn.LAMBDA("")
Name Common_SourceData.Common_SourceData_DataScores_Scope3_Variation: _xlfn.LAMBDA("")
Name Common_SourceData.Common_SourceData_DensityOfMethane_Data: _xlfn.LAMBDA(0.6784)
Name Common_SourceData.Common_SourceData_DensityOfMethane_Source: _xlfn.LAMBDA("National Inventory Report 2023 Volume 1: Equations 3.B.1a_2, 3.B.1c_2, 3.B.3_1, 3.B.4g_2")
Name Common_SourceData.Common_SourceData_DensityOfMethane_Title: _xlfn.LAMBDA("p = density of methane")
Name Common_SourceData.Common_SourceData_DensityOfMethane_Unit: _xlfn.LAMBDA("kg/m3")
Name Common_SourceData.Common_SourceData_EFleach_Data: _xlfn.LAMBDA(_xlfn.MAKEARRAY(1, 2, _xlfn.LAMBDA(_xlpm.r,_xlpm.c, INDEX({"EFleach",0.011}, _xlpm.r, _xlpm.c))))
Name Common_SourceData.Common_SourceData_EFleach_NIRReference: _xlfn.LAMBDA("National Inventory Report Volume 1: Equation 3.D.B_10")
Name Common_SourceData.Common_SourceData_EFleach_Source: _xlfn.LAMBDA("VEERG 2026:5.5.2.3 Constant Parameters")
Name Common_SourceData.Common_SourceData_EFleach_Title: _xlfn.LAMBDA("Emission factor for nitrogen leaching and runoff")
Name Common_SourceData.Common_SourceData_EFleach_Unit: _xlfn.LAMBDA("(kg N2O-N / kg N")
Name Common_SourceData.Common_SourceData_EFleach_Variation: _xlfn.LAMBDA((""))
Name Common_SourceData.Common_SourceData_EFN2O_NIRReference: _xlfn.LAMBDA("")
Name Common_SourceData.Common_SourceData_EFN2O_Source: _xlfn.LAMBDA("VEERG 2026: Table A.2.2.1")
Name Common_SourceData.Common_SourceData_EFN2O_Title: _xlfn.LAMBDA("Nitrous oxide emission factors for inorganic fertiliser application")
Name Common_SourceData.Common_SourceData_EFN2O_Unit: _xlfn.LAMBDA("(kg N2O-N / kg N")
Name Common_SourceData.Common_SourceData_EFPastureRangeAndPaddock_Data: _xlfn.LAMBDA(_xlfn.MAKEARRAY(3, 2, _xlfn.LAMBDA(_xlpm.r,_xlpm.c, INDEX({"Climate zone","EFPRP";"Wet climate zone",0.006;"Dry climate zone",0.002}, _xlpm.r, _xlpm.c))))
Name Common_SourceData.Common_SourceData_EFPastureRangeAndPaddock_NIRReference: _xlfn.LAMBDA("")
Name Common_SourceData.Common_SourceData_EFPastureRangeAndPaddock_Source: _xlfn.LAMBDA("VEERG 2026: Table A.2.2.2")
Name Common_SourceData.Common_SourceData_EFPastureRangeAndPaddock_Title: _xlfn.LAMBDA("Emission factor for urine and dung deposited on pasture, range or paddock")
Name Common_SourceData.Common_SourceData_EFPastureRangeAndPaddock_Unit: _xlfn.LAMBDA("kg N2O - N / kg N")
Name Common_SourceData.Common_SourceData_EFPastureRangeAndPaddock_Variation: _xlfn.LAMBDA("VARIATION FROM SOURCE DATA: Changed 'Dry climate zones' to singular 'Dry climate zone' to aid lookup.")
Name Common_SourceData.Common_SourceData_FracLEACH_Data: _xlfn.LAMBDA(_xlfn.MAKEARRAY(1, 2, _xlfn.LAMBDA(_xlpm.r,_xlpm.c, INDEX({"FracLEACH",0.24}, _xlpm.r, _xlpm.c))))

Sheet Home

Sheet Results
A1: #VALUE! | C1: 4.2 Manure management: Pasture Beef: Results
A3: =HYPERLINK("#'Home'!A1", "Home") -> Home
A4: =HYPERLINK("#'Results'!A1", "Results") -> Results | D4: Emissions breakdown
A6: INPUTS | D6: Scope 1 source | E6: GHG emissions method 1 | F6: GHG emissions method 2 | G6: GHG Unit | H6: CO2-e emissions method 1 | I6: CO2-e emissions method 2 | J6: CO2-e unit
A7: =HYPERLINK("#'Input - Site'!A1", "Site") -> Site | D7: 4.2.1.1-2 Manure methane | E7: =[2]Results!$E$264 -> #REF! | F7: =[2]Results!$P$264 -> #REF! | G7: =[2]Results!$F$264 -> #REF! | H7: =[2]Results!$E$269 -> #REF! | I7: =[2]Results!$P$269 -> #REF! | J7: =[2]Results!$F$269 -> 0
A8: =HYPERLINK("#'Input - Pasture Beef'!A1", "Pasture Beef") -> Pasture Beef | D8: 4.2.1.3-4 Manure direct N2O | E8: ='[3]4.2.1'!$E$280 -> #REF! | F8: ='[3]4.2.1'!$O$280 -> #REF! | G8: ='[3]4.2.1'!$F$280 -> #REF! | H8: ='[3]4.2.1'!$E$285 -> #REF! | I8: ='[3]4.2.1'!$O$285 -> #REF! | J8: ='[3]4.2.1'!$F$285 -> #REF!
D9: 4.2.1.5 Manure atmospheric deposition | E9: ='[4]4.2.1'!$E$68 -> #REF! | F9: ='[4]4.2.1'!$P$68 -> #REF! | G9: ='[4]4.2.1'!$F$68 -> #REF! | H9: ='[4]4.2.1'!$E$73 -> #REF! | I9: ='4.3.1.5 Atmos deposition'!$P$73 -> #REF! | J9: ='4.3.1.5 Atmos deposition'!$F$73 -> t CO2e
A10: CALCULATIONS | D10: 4.2.1.6-7 Manure leaching and runoff | E10: ='4.3.1.6-7 Leaching and runoff'!$E$52 -> #REF! | F10: ='4.3.1.6-7 Leaching and runoff'!$P$52 -> #VALUE! | G10: ='4.3.1.6-7 Leaching and runoff'!$F$52 -> t N2O | H10: ='4.3.1.6-7 Leaching and runoff'!$E$57 -> #REF! | I10: ='4.3.1.6-7 Leaching and runoff'!$P$57 -> #VALUE! | J10: ='4.3.1.6-7 Leaching and runoff'!$F$57 -> t CO2e
A11: =HYPERLINK("#'4.2.1.1-2 Methane'!A1", "4.2.1.1-2 Methane") -> 4.2.1.1-2 Methane | D11: 4.2.1.8 Manure applied to soils | E11: N/A | F11: N/A | H11: N/A | I11: N/A
A12: =HYPERLINK("#'4.3.1.3-4 Direct N20'!A1", "4.3.1.3-4 Direct N2O") -> 4.3.1.3-4 Direct N2O | D12: 4.2.1.9 Soil direct N2O | E12: ='4.3.1.9 Soil direct N2O'!$E$53 -> #REF! | F12: ='4.3.1.9 Soil direct N2O'!$P$53 -> #REF! | G12: ='4.3.1.9 Soil direct N2O'!$F$53 -> t N2O | H12: ='4.3.1.9 Soil direct N2O'!$E$58 -> #REF! | I12: ='4.3.1.9 Soil direct N2O'!$P$58 -> #REF! | J12: ='4.3.1.9 Soil direct N2O'!$F$58 -> t CO2e
A13: =HYPERLINK("#'4.3.1.5 Atmos Deposition'!A1", "4.3.1.5 Atmospheric deposition") -> 4.3.1.5 Atmospheric deposition | D13: 4.3.1.10-11 Soil atmospheric deposition | E13: ='4.3.1.10-11 Soil Atmos Dep'!$E$45 -> #REF! | F13: ='4.3.1.10-11 Soil Atmos Dep'!$P$45 -> #REF! | G13: ='4.3.1.10-11 Soil Atmos Dep'!$F$45 -> t N2O | H13: ='4.3.1.10-11 Soil Atmos Dep'!$E$50 -> #REF! | I13: ='4.3.1.10-11 Soil Atmos Dep'!$P$50 -> #REF! | J13: ='4.3.1.10-11 Soil Atmos Dep'!$F$50 -> t CO2e
A14: =HYPERLINK("#'4.3.1.6-7 Leaching and runoff'!A1", "4.3.1.6-7 Leaching and runoff") -> 4.3.1.6-7 Leaching and runoff | D14: 4.3.1.12-13 Soil leaching and runoff | E14: ='4.3.1.12-13 Soil leach runoff'!$E$47 -> #REF! | F14: ='4.3.1.12-13 Soil leach runoff'!$P$47 -> #REF! | G14: ='4.3.1.12-13 Soil leach runoff'!$F$47 -> t N2O | H14: ='4.3.1.12-13 Soil leach runoff'!$E$52 -> #REF! | I14: ='4.3.1.12-13 Soil leach runoff'!$P$52 -> #REF! | J14: ='4.3.1.12-13 Soil leach runoff'!$F$52 -> t CO2e
A15: =HYPERLINK("#'4.3.1.8 Manure applied to soils'!A1", "4.3.1.8 Manure applied to soils") -> 4.3.1.8 Manure applied to soils | D15: Total | H15: =SUM(H7:H15) -> #REF! | I15: =SUM(I7:I15) -> #REF! | J15: t CO2e
A16: =HYPERLINK("#'4.3.1.9 Soil direct N2O'!A1", "4.3.1.9 Soil direct N2O") -> 4.3.1.9 Soil direct N2O
A17: =HYPERLINK("#'4.3.1.10-11 Soil Atmos Dep'!A1", "4.3.1.10-11 Soil atm. deposition") -> 4.3.1.10-11 Soil atm. deposition | D17: WARNING: Manure nitrogen that was applied to soils must be accounted for
A18: =HYPERLINK("#'4.3.1.12-13 Soil leach runoff'!A1", "4.3.1.12-13 Soil leach & runoff") -> 4.3.1.12-13 Soil leach & runoff | D18: See the table below for how to account for manure applied to soils for scope 1 and 3.
A20: APPENDICES | D20: Manure nitrogen use | E20: Amount of N in manure | F20: N unit | G20: Emissions allocated to | H20: VEERG Calculation method
A21: =HYPERLINK("#'Constants - Pasture Beef'!A1", "Constants - Pasture Beef") -> Constants - Pasture Beef | D21: Manure nitrogen deposited on farm soils with no other purpose (aka waste) | E21: ='4.3.1.8 Manure applied to soils'!$E$102 -> #REF! | F21: ='4.3.1.8 Manure applied to soils'!$F$102 -> kg N | G21: This feedlot | H21: 5.2.2.1 (1), 5.4.1.3 (1, 2), 5.5.1.1 (1, 3)
A22: =HYPERLINK("#'Constants - Livestock'!A1", "Constants - Livestock") -> Constants - Livestock | D22: Manure nitrogen deposited on farm soils as fertiliser for other farm enterpsies (eg crops) | E22: ='4.3.1.8 Manure applied to soils'!$E$166 -> #REF! | F22: ='4.3.1.8 Manure applied to soils'!$F$166 -> kg N | G22: Crops or pasture that use manure as fertiliser | H22: 5.2.2.1 (1), 5.4.1.3 (1, 2), 5.5.1.1 (1, 3)
A23: =HYPERLINK("#'Constants - Common'!A1", "Constants - Common") -> Constants - Common | D23: Manure nitrogen sold | E23: ='4.3.1.8 Manure applied to soils'!$E$196 -> #REF! | F23: ='4.3.1.8 Manure applied to soils'!$F$196 -> kg N | G23: Scope 3 (downstream) | H23: 15.13.1.1 (1), 5.2.2.1 (1), 5.4.1.3 (1, 2), 5.5.1.1 (1, 3)
A24: =HYPERLINK("#'Acknowledgements'!A1", "Acknowledgements") -> Acknowledgements

Sheet Input - Site
A1: #VALUE! | C1: Input - Site
A3: =HYPERLINK("#'Home'!A1", "Home") -> Home
A4: =HYPERLINK("#'Results'!A1", "Results") -> Results
D5: Your business
A6: INPUTS
A7: =HYPERLINK("#'Input - Site'!A1", "Site") -> Site | D7: Farm name | E7: Test Farms
A8: =HYPERLINK("#'Input - Pasture Beef'!A1", "Pasture Beef") -> Pasture Beef | D8: Reporting entity name | E8: Test Farms Pty Ltd
A10: CALCULATIONS | D10: 💡An 'Emissions accounting period' is a 12 month period where the business can report on the emissions, and is typically the same as the business' financial accounting period.
A11: =HYPERLINK("#'4.2.1.1-2 Methane'!A1", "4.2.1.1-2 Methane") -> 4.2.1.1-2 Methane
A12: =HYPERLINK("#'4.3.1.3-4 Direct N20'!A1", "4.3.1.3-4 Direct N2O") -> 4.3.1.3-4 Direct N2O | D12: Emissions calculation period start date | E12: 45292 | F12: ← DD/MM/YYYY or DD Month YYYY
A13: =HYPERLINK("#'4.3.1.5 Atmos Deposition'!A1", "4.3.1.5 Atmospheric deposition") -> 4.3.1.5 Atmospheric deposition | D13: Emissions calculation period end date | E13: =DATE(YEAR(E12)+1,MONTH(E12),DAY(E12))-1 -> 45657 | F13: ← Automatically calculated, 12 months after start date
A14: =HYPERLINK("#'4.3.1.6-7 Leaching and runoff'!A1", "4.3.1.6-7 Leaching and runoff") -> 4.3.1.6-7 Leaching and runoff
A15: =HYPERLINK("#'4.3.1.8 Manure applied to soils'!A1", "4.3.1.8 Manure applied to soils") -> 4.3.1.8 Manure applied to soils
A16: =HYPERLINK("#'4.3.1.9 Soil direct N2O'!A1", "4.3.1.9 Soil direct N2O") -> 4.3.1.9 Soil direct N2O | D16: Location and climate
A17: =HYPERLINK("#'4.3.1.10-11 Soil Atmos Dep'!A1", "4.3.1.10-11 Soil atm. deposition") -> 4.3.1.10-11 Soil atm. deposition
A18: =HYPERLINK("#'4.3.1.12-13 Soil leach runoff'!A1", "4.3.1.12-13 Soil leach & runoff") -> 4.3.1.12-13 Soil leach & runoff | D18: Location information is used to reference some region and climate-specific emission factors
D19: Tip: Use the web-based GAF Location Helper tool to easily get region and climate information. You will need an internet connection to use the GAF Location Helper.
A20: APPENDICES
A21: =HYPERLINK("#'Constants - Pasture Beef'!A1", "Constants - Pasture Beef") -> Constants - Pasture Beef | D21: State | E21: Western Australia | F21: ← Please select
A22: =HYPERLINK("#'Constants - Livestock'!A1", "Constants - Livestock") -> Constants - Livestock | D22: Region (ABS Statistical area level 4) if state is WA | E22: Western Australia - Outback (South) | F22: ← Please select
A23: =HYPERLINK("#'Constants - Common'!A1", "Constants - Common") -> Constants - Common | D23: Leaching zone | E23: NO - Not in leaching zone | F23: ← Please select
A24: =HYPERLINK("#'Acknowledgements'!A1", "Acknowledgements") -> Acknowledgements | D24: Elevation | E24: 307.7 | F24: Meters
D25: Average temperature for reporting period | E25: 18 | F25: Degrees celsius
D26: Total rainfall for reporting period | E26: 601 | F26: Millimetres
D27: Potential evapotranspiration for reporting period | E27: 1326 | F27: Millimetres
D28: Number of frost days for reporting period | E28: 7 | F28: Days
D29: MAP:PET ratio | E29: =E26/E27 -> 0.45324284
D30: Rainfall zone | E30: =Common_InputFunctions.Utility_LookupItemFromMinMax(E26,Table_SourceData_RainfallZones[Min rainfall],Table_SourceData_RainfallZones[Max rainfall],Table_SourceData_RainfallZones[Rainfall Zone]) -> High rainfall
D31: Climate zone | E31: =Common_InputFunctions.Utility_GetClimateZone(E25,E26,E28,E24,E29,Table_SourceData_ClimateZones[Min temp],Table_SourceData_ClimateZones[Max temp],Table_SourceData_ClimateZones[Min rainfall],Table_SourceData_ClimateZones[Max rainfall],Table_SourceData_ClimateZones[Min frost days],Table_SourceData_ClimateZones[Max frost days],Table_SourceData_ClimateZones[Min elevation],Table_SourceData_ClimateZones[Max elevation],Table_SourceData_ClimateZones[Min MAP:PET],Table_SourceData_ClimateZones[Max MAP:PET],Table_SourceData_ClimateZones[Climate zone]) -> Warm temperate dry
D32: Wet or dry climate zone | E32: =Common_InputFunctions.Utility_LookupValueInTable($E$31,Table_SourceData_WetDryZones[Climate zone],Table_SourceData_WetDryZones[Wet or Dry Zone]) -> Dry climate zone
D33: Temperature zone | E33: =Common_InputFunctions.Utility_LookupItemFromMinMax(E25,Table_SourceData_TemperatureZones[Min MAT],Table_SourceData_TemperatureZones[Max MAT],Table_SourceData_TemperatureZones[Temperature Zone]) -> Temperate

Sheet Input - Pasture Beef
A1: #VALUE! | C1: Input -Pasture Beef
A3: =HYPERLINK("#'Home'!A1", "Home") -> Home
A4: =HYPERLINK("#'Results'!A1", "Results") -> Results
D5: Herd movement
A6: INPUTS
A7: =HYPERLINK("#'Input - Site'!A1", "Site") -> Site | D7: State | E7: ='Input - Site'!$E$21 -> Western Australia
A8: =HYPERLINK("#'Input - Pasture Beef'!A1", "Pasture Beef") -> Pasture Beef | D8: Livestock production region | E8: South West | F8: ← Please select
A10: CALCULATIONS | D10: NOTE: VEERG states that under method 2, time periods may be seasons, months or a custom time period. In this example, method 2 time periods are months.
A11: =HYPERLINK("#'4.2.1.1-2 Methane'!A1", "4.2.1.1-2 Methane") -> 4.2.1.1-2 Methane
A12: =HYPERLINK("#'4.3.1.3-4 Direct N20'!A1", "4.3.1.3-4 Direct N2O") -> 4.3.1.3-4 Direct N2O | D12: Duration on farm
A13: =HYPERLINK("#'4.3.1.5 Atmos Deposition'!A1", "4.3.1.5 Atmospheric deposition") -> 4.3.1.5 Atmospheric deposition | D13: Method 1 default values (do not edit) | E13: Bulls < 1 year | F13: Bulls > 1 year | G13: Cows < 1 year | H13: Cows 1-2 years | I13: Cows 2-3 years | J13: Cows > 3 years | K13: Steers < 1 year | L13: Steers 1-2 years | M13: Steers 2-3 years | N13: Steers >3 years
A14: =HYPERLINK("#'4.3.1.6-7 Leaching and runoff'!A1", "4.3.1.6-7 Leaching and runoff") -> 4.3.1.6-7 Leaching and runoff | D14: Summer | E14: 91.25 | F14: 91.25 | G14: 91.25 | H14: 91.25 | I14: 91.25 | J14: 91.25 | K14: 91.25 | L14: 91.25 | M14: 91.25 | N14: 91.25 | O14: Days
A15: =HYPERLINK("#'4.3.1.8 Manure applied to soils'!A1", "4.3.1.8 Manure applied to soils") -> 4.3.1.8 Manure applied to soils | D15: Autumn | E15: 91.25 | F15: 91.25 | G15: 91.25 | H15: 91.25 | I15: 91.25 | J15: 91.25 | K15: 91.25 | L15: 91.25 | M15: 91.25 | N15: 91.25 | O15: Days
A16: =HYPERLINK("#'4.3.1.9 Soil direct N2O'!A1", "4.3.1.9 Soil direct N2O") -> 4.3.1.9 Soil direct N2O | D16: Winter | E16: 91.25 | F16: 91.25 | G16: 91.25 | H16: 91.25 | I16: 91.25 | J16: 91.25 | K16: 91.25 | L16: 91.25 | M16: 91.25 | N16: 91.25 | O16: Days
A17: =HYPERLINK("#'4.3.1.10-11 Soil Atmos Dep'!A1", "4.3.1.10-11 Soil atm. deposition") -> 4.3.1.10-11 Soil atm. deposition | D17: Spring | E17: 91.25 | F17: 91.25 | G17: 91.25 | H17: 91.25 | I17: 91.25 | J17: 91.25 | K17: 91.25 | L17: 91.25 | M17: 91.25 | N17: 91.25 | O17: Days
A18: =HYPERLINK("#'4.3.1.12-13 Soil leach runoff'!A1", "4.3.1.12-13 Soil leach & runoff") -> 4.3.1.12-13 Soil leach & runoff
D19: Method 2 custom values (edit if known) | E19: Bulls < 1 year | F19: Bulls > 1 year | G19: Cows < 1 year | H19: Cows 1-2 years | I19: Cows 2-3 years | J19: Cows > 3 years | K19: Steers < 1 year | L19: Steers 1-2 years | M19: Steers 2-3 years | N19: Steers >3 years
A20: APPENDICES | D20: =TEXT('Input - Site'!$E$12, "mmmm yyyy") -> January 2024 | E20: =DAY(EOMONTH($D20,0)) -> 31 | F20: =DAY(EOMONTH($D20,0)) -> 31 | G20: =DAY(EOMONTH($D20,0)) -> 31 | H20: =DAY(EOMONTH($D20,0)) -> 31 | I20: =DAY(EOMONTH($D20,0)) -> 31 | J20: =DAY(EOMONTH($D20,0)) -> 31 | K20: =DAY(EOMONTH($D20,0)) -> 31 | L20: =DAY(EOMONTH($D20,0)) -> 31 | ... N20: =DAY(EOMONTH($D20,0)) -> 31 | O20: Days
A21: =HYPERLINK("#'Constants - Dairy'!A1", "Constants - Dairy") -> Constants - Dairy | D21: =TEXT(EDATE('Input - Site'!$E$12,1), "mmmm yyyy") -> February 2024 | E21: =DAY(EOMONTH($D21,0)) -> 29 | F21: =DAY(EOMONTH($D21,0)) -> 29 | G21: =DAY(EOMONTH($D21,0)) -> 29 | H21: =DAY(EOMONTH($D21,0)) -> 29 | I21: =DAY(EOMONTH($D21,0)) -> 29 | J21: =DAY(EOMONTH($D21,0)) -> 29 | K21: =DAY(EOMONTH($D21,0)) -> 29 | L21: =DAY(EOMONTH($D21,0)) -> 29 | ... N21: =DAY(EOMONTH($D21,0)) -> 29 | O21: Days
A22: =HYPERLINK("#'Constants - Livestock'!A1", "Constants - Livestock") -> Constants - Livestock | D22: =TEXT(EDATE('Input - Site'!$E$12,2), "mmmm yyyy") -> March 2024 | E22: =DAY(EOMONTH($D22,0)) -> 31 | F22: =DAY(EOMONTH($D22,0)) -> 31 | G22: =DAY(EOMONTH($D22,0)) -> 31 | H22: =DAY(EOMONTH($D22,0)) -> 31 | I22: =DAY(EOMONTH($D22,0)) -> 31 | J22: =DAY(EOMONTH($D22,0)) -> 31 | K22: =DAY(EOMONTH($D22,0)) -> 31 | L22: =DAY(EOMONTH($D22,0)) -> 31 | ... N22: =DAY(EOMONTH($D22,0)) -> 31 | O22: Days
A23: =HYPERLINK("#'Constants - Common'!A1", "Constants - Common") -> Constants - Common | D23: =TEXT(EDATE('Input - Site'!$E$12,3), "mmmm yyyy") -> April 2024 | E23: =DAY(EOMONTH($D23,0)) -> 30 | F23: =DAY(EOMONTH($D23,0)) -> 30 | G23: =DAY(EOMONTH($D23,0)) -> 30 | H23: =DAY(EOMONTH($D23,0)) -> 30 | I23: =DAY(EOMONTH($D23,0)) -> 30 | J23: =DAY(EOMONTH($D23,0)) -> 30 | K23: =DAY(EOMONTH($D23,0)) -> 30 | L23: =DAY(EOMONTH($D23,0)) -> 30 | ... N23: =DAY(EOMONTH($D23,0)) -> 30 | O23: Days
A24: =HYPERLINK("#'Acknowledgements'!A1", "Acknowledgements") -> Acknowledgements | D24: =TEXT(EDATE('Input - Site'!$E$12,4), "mmmm yyyy") -> May 2024 | E24: =DAY(EOMONTH($D24,0)) -> 31 | F24: =DAY(EOMONTH($D24,0)) -> 31 | G24: =DAY(EOMONTH($D24,0)) -> 31 | H24: =DAY(EOMONTH($D24,0)) -> 31 | I24: =DAY(EOMONTH($D24,0)) -> 31 | J24: =DAY(EOMONTH($D24,0)) -> 31 | K24: =DAY(EOMONTH($D24,0)) -> 31 | L24: =DAY(EOMONTH($D24,0)) -> 31 | ... N24: =DAY(EOMONTH($D24,0)) -> 31 | O24: Days
D25: =TEXT(EDATE('Input - Site'!$E$12,5), "mmmm yyyy") -> June 2024 | E25: =DAY(EOMONTH($D25,0)) -> 30 | F25: =DAY(EOMONTH($D25,0)) -> 30 | G25: =DAY(EOMONTH($D25,0)) -> 30 | H25: =DAY(EOMONTH($D25,0)) -> 30 | I25: =DAY(EOMONTH($D25,0)) -> 30 | J25: =DAY(EOMONTH($D25,0)) -> 30 | K25: =DAY(EOMONTH($D25,0)) -> 30 | L25: =DAY(EOMONTH($D25,0)) -> 30 | ... N25: =DAY(EOMONTH($D25,0)) -> 30 | O25: Days
D26: =TEXT(EDATE('Input - Site'!$E$12,6), "mmmm yyyy") -> July 2024 | E26: =DAY(EOMONTH($D26,0)) -> 31 | F26: =DAY(EOMONTH($D26,0)) -> 31 | G26: =DAY(EOMONTH($D26,0)) -> 31 | H26: =DAY(EOMONTH($D26,0)) -> 31 | I26: =DAY(EOMONTH($D26,0)) -> 31 | J26: =DAY(EOMONTH($D26,0)) -> 31 | K26: =DAY(EOMONTH($D26,0)) -> 31 | L26: =DAY(EOMONTH($D26,0)) -> 31 | ... N26: =DAY(EOMONTH($D26,0)) -> 31 | O26: Days
D27: =TEXT(EDATE('Input - Site'!$E$12,7), "mmmm yyyy") -> August 2024 | E27: =DAY(EOMONTH($D27,0)) -> 31 | F27: =DAY(EOMONTH($D27,0)) -> 31 | G27: =DAY(EOMONTH($D27,0)) -> 31 | H27: =DAY(EOMONTH($D27,0)) -> 31 | I27: =DAY(EOMONTH($D27,0)) -> 31 | J27: =DAY(EOMONTH($D27,0)) -> 31 | K27: =DAY(EOMONTH($D27,0)) -> 31 | L27: =DAY(EOMONTH($D27,0)) -> 31 | ... N27: =DAY(EOMONTH($D27,0)) -> 31 | O27: Days
D28: =TEXT(EDATE('Input - Site'!$E$12,8), "mmmm yyyy") -> September 2024 | E28: =DAY(EOMONTH($D28,0)) -> 30 | F28: =DAY(EOMONTH($D28,0)) -> 30 | G28: =DAY(EOMONTH($D28,0)) -> 30 | H28: =DAY(EOMONTH($D28,0)) -> 30 | I28: =DAY(EOMONTH($D28,0)) -> 30 | J28: =DAY(EOMONTH($D28,0)) -> 30 | K28: =DAY(EOMONTH($D28,0)) -> 30 | L28: =DAY(EOMONTH($D28,0)) -> 30 | ... N28: =DAY(EOMONTH($D28,0)) -> 30 | O28: Days
D29: =TEXT(EDATE('Input - Site'!$E$12,9), "mmmm yyyy") -> October 2024 | E29: =DAY(EOMONTH($D29,0)) -> 31 | F29: =DAY(EOMONTH($D29,0)) -> 31 | G29: =DAY(EOMONTH($D29,0)) -> 31 | H29: =DAY(EOMONTH($D29,0)) -> 31 | I29: =DAY(EOMONTH($D29,0)) -> 31 | J29: =DAY(EOMONTH($D29,0)) -> 31 | K29: =DAY(EOMONTH($D29,0)) -> 31 | L29: =DAY(EOMONTH($D29,0)) -> 31 | ... N29: =DAY(EOMONTH($D29,0)) -> 31 | O29: Days
D30: =TEXT(EDATE('Input - Site'!$E$12,10), "mmmm yyyy") -> November 2024 | E30: =DAY(EOMONTH($D30,0)) -> 30 | F30: =DAY(EOMONTH($D30,0)) -> 30 | G30: =DAY(EOMONTH($D30,0)) -> 30 | H30: =DAY(EOMONTH($D30,0)) -> 30 | I30: =DAY(EOMONTH($D30,0)) -> 30 | J30: =DAY(EOMONTH($D30,0)) -> 30 | K30: =DAY(EOMONTH($D30,0)) -> 30 | L30: =DAY(EOMONTH($D30,0)) -> 30 | ... N30: =DAY(EOMONTH($D30,0)) -> 30 | O30: Days
D31: =TEXT(EDATE('Input - Site'!$E$12,11), "mmmm yyyy") -> December 2024 | E31: =DAY(EOMONTH($D31,0)) -> 31 | F31: =DAY(EOMONTH($D31,0)) -> 31 | G31: =DAY(EOMONTH($D31,0)) -> 31 | H31: =DAY(EOMONTH($D31,0)) -> 31 | I31: =DAY(EOMONTH($D31,0)) -> 31 | J31: =DAY(EOMONTH($D31,0)) -> 31 | K31: =DAY(EOMONTH($D31,0)) -> 31 | L31: =DAY(EOMONTH($D31,0)) -> 31 | ... N31: =DAY(EOMONTH($D31,0)) -> 31 | O31: Days
D34: Head
D35: Method 1 values | E35: Bulls < 1 year | F35: Bulls > 1 year | G35: Cows < 1 year | H35: Cows 1-2 years | I35: Cows 2-3 years | J35: Cows > 3 years | K35: Steers < 1 year | L35: Steers 1-2 years | M35: Steers 2-3 years | N35: Steers >3 years
D36: Summer | E36: 100 | F36: 100 | G36: 100 | H36: 100 | I36: 100 | J36: 100 | K36: 100 | L36: 100 | M36: 100 | N36: 100 | O36: Head
D37: Autumn | E37: 100 | F37: 100 | G37: 100 | H37: 100 | I37: 100 | J37: 100 | K37: 100 | L37: 100 | M37: 100 | N37: 100 | O37: Head
D38: Winter | E38: 100 | F38: 100 | G38: 100 | H38: 100 | I38: 100 | J38: 100 | K38: 100 | L38: 100 | M38: 100 | N38: 100 | O38: Head
D39: Spring | E39: 100 | F39: 100 | G39: 100 | H39: 100 | I39: 100 | J39: 100 | K39: 100 | L39: 100 | M39: 100 | N39: 100 | O39: Head
D41: Method values | E41: Bulls < 1 year | F41: Bulls > 1 year | G41: Cows < 1 year | H41: Cows 1-2 years | I41: Cows 2-3 years | J41: Cows > 3 years | K41: Steers < 1 year | L41: Steers 1-2 years | M41: Steers 2-3 years | N41: Steers >3 years
D42: =TEXT('Input - Site'!$E$12, "mmmm yyyy") -> January 2024 | E42: 100 | F42: 100 | G42: 100 | H42: 100 | I42: 100 | J42: 100 | K42: 100 | L42: 100 | M42: 100 | N42: 100 | O42: Head
D43: =TEXT(EDATE('Input - Site'!$E$12,1), "mmmm yyyy") -> February 2024 | E43: 100 | F43: 100 | G43: 100 | H43: 100 | I43: 100 | J43: 100 | K43: 100 | L43: 100 | M43: 100 | N43: 100 | O43: Head
D44: =TEXT(EDATE('Input - Site'!$E$12,2), "mmmm yyyy") -> March 2024 | E44: 100 | F44: 100 | G44: 100 | H44: 100 | I44: 100 | J44: 100 | K44: 100 | L44: 100 | M44: 100 | N44: 100 | O44: Head
D45: =TEXT(EDATE('Input - Site'!$E$12,3), "mmmm yyyy") -> April 2024 | E45: 100 | F45: 100 | G45: 100 | H45: 100 | I45: 100 | J45: 100 | K45: 100 | L45: 100 | M45: 100 | N45: 100 | O45: Head
...

Sheet 4.2.1.1-2 Methane
A1: #VALUE! | C1: 4.2.1.1-2 Manure Methane
D3: Method 1 | O3: Method 2
D5: {=EntericMethane_PastureBeef_Equations.VEERG_3_2_1_1__4_AdditionalIntakeForMilkProduction_Title()} -> Additional intake for milk production in the season of calving and the season after calving
D6: {=EntericMethane_PastureBeef_Equations.VEERG_3_2_1_1__4_AdditionalIntakeForMilkProduction_Source()} -> VEERG 2026: 3.2.1.1, Equation (4)
D10: Variable | E10: {=EntericMethane_PastureBeef_Equations.VEERG_3_2_1_1__4_AdditionalIntakeForMilkProduction_Variable()} -> MA_jk45
D11: Unit | E11: {=EntericMethane_PastureBeef_Equations.VEERG_3_2_1_1__4_AdditionalIntakeForMilkProduction_Unit()} -> fraction
D13: {=EntericMethane_PastureBeef_Equations.VEERG_3_2_1_1__4_AdditionalIntakeForMilkProduction_Arguments()} -> LC_jk45 | E13: proportion of cows greater than 1 year in calf in the season of calving expressed as a fraction
D14: FA_jk45 | E14: feed adjustment value for lactating cows in the season of calving and the season immediately after calving expressed as a fraction
D43: {=MMS_PastureBeef_Methane_Equations.VEERG_4_2_1_1__3_VolatileSolidProductionFromGrazingBeef_Title()} -> Volatile solid production from grazing beef
D44: {=MMS_PastureBeef_Methane_Equations.VEERG_4_2_1_1__3_VolatileSolidProductionFromGrazingBeef_Source()} -> VEERG 2026: 4.2.1.1, Equation (3)
D45: Function name | E45: {=Common_InputFunctions.Utility_DisplayFunctionName()} -> #VALUE!
D49: Variable | E49: {=MMS_PastureBeef_Methane_Equations.VEERG_4_2_1_1__3_VolatileSolidProductionFromGrazingBeef_Variable()} -> VS_jkl
D50: Unit | E50: {=MMS_PastureBeef_Methane_Equations.VEERG_4_2_1_1__3_VolatileSolidProductionFromGrazingBeef_Unit()} -> kg/head/day
D52: {=MMS_PastureBeef_Methane_Equations.VEERG_4_2_1_1__3_VolatileSolidProductionFromGrazingBeef_Arguments()} -> I_jkl | E52: dry matter intake as calculated in Chapter 3 Section 3.2.1 (kg/head/day)
D53: DMD_jkl | E53: dry matter digestibility expressed as a fraction
D54: A | E54: ash content of feed intake expressed as a fraction

Sheet 4.3.1.3-4 Direct N20
A1: #VALUE! | C1: 4.3.1.3-4 Manure Direct N2O
A3: =HYPERLINK("#'Home'!A1", "Home") -> Home | D3: Method 1 | N3: Method 2
A4: =HYPERLINK("#'Results'!A1", "Results") -> Results
D5: {=MMS_Dairy_N2ODirect_Equations.VEERG_4_3_1_3__8_RelativeSize_Title()} -> Relative size
A6: INPUTS | D6: {=MMS_Dairy_N2ODirect_Equations.VEERG_4_3_1_3__8_RelativeSize_Source()} -> VEERG 2026: 4.3.1.3, Equation (8)
A7: =HYPERLINK("#'Input - Site'!A1", "Site") -> Site | D7: Function name | E7: {=Common_InputFunctions.Utility_DisplayFunctionName(D29)} -> =MMS_Dairy_N2ODirect_Equations.VEERG_4_3_1_3__8_RelativeSize
A8: =HYPERLINK("#'Input - Dairy'!A1", "Dairy") -> Dairy
A10: CALCULATIONS | D10: Variable | E10: {=MMS_Dairy_N2ODirect_Equations.VEERG_4_3_1_3__8_RelativeSize_Variable()} -> Z_j
A11: =HYPERLINK("#'4.2.1.1-2 Methane'!A1", "4.2.1.1-2 Methane") -> 4.2.1.1-2 Methane | D11: Unit | E11: {=MMS_Dairy_N2ODirect_Equations.VEERG_4_3_1_3__8_RelativeSize_Unit()} -> ratio
A12: =HYPERLINK("#'4.3.1.3-4 Direct N20'!A1", "4.3.1.3-4 Direct N2O") -> 4.3.1.3-4 Direct N2O
A13: =HYPERLINK("#'4.3.1.5 Atmos Deposition'!A1", "4.3.1.5 Atmospheric deposition") -> 4.3.1.5 Atmospheric deposition | D13: {=MMS_Dairy_N2ODirect_Equations.VEERG_4_3_1_3__8_RelativeSize_Arguments()} -> W_j | E13: liveweight (kg) | F13: ="See " & D16 -> See M1_Table_W_j
A14: =HYPERLINK("#'4.3.1.6-7 Leaching and runoff'!A1", "4.3.1.6-7 Leaching and runoff") -> 4.3.1.6-7 Leaching and runoff | D14: WR_j | E14: reference weight (kg) | F14: ="See " & D21 -> See Table_WR_j
A15: =HYPERLINK("#'4.3.1.8 Manure applied to soils'!A1", "4.3.1.8 Manure applied to soils") -> 4.3.1.8 Manure applied to soils
A16: =HYPERLINK("#'4.3.1.9 Soil direct N2O'!A1", "4.3.1.9 Soil direct N2O") -> 4.3.1.9 Soil direct N2O | D16: M1_Table_W_j | N16: M2_Table_W_j
A17: =HYPERLINK("#'4.3.1.10-11 Soil Atmos Dep'!A1", "4.3.1.10-11 Soil atm. deposition") -> 4.3.1.10-11 Soil atm. deposition | D17: Liveweight for each animal class j (Method 1) | N17: Liveweight for each animal class j (Method 2)
A18: =HYPERLINK("#'4.3.1.12-13 Soil leach runoff'!A1", "4.3.1.12-13 Soil leach & runoff") -> 4.3.1.12-13 Soil leach & runoff | D18: Milking cows | E18: Heifers > 1 year | F18: Heifers < 1 year | G18: Bulls > 1 year | H18: Bulls < 1 year | N18: Milking cows | O18: Heifers > 1 year | P18: Heifers < 1 year | Q18: Bulls > 1 year | R18: Bulls < 1 year
D19: ='Input - Pasture Beef'!$E$104 -> 0.25 | E19: ='Input - Pasture Beef'!$F$104 -> 0 | F19: ='Input - Pasture Beef'!$G$104 -> 0 | G19: ='Input - Pasture Beef'!$H$104 -> Percent | H19: ='Input - Pasture Beef'!$I$104 -> 0 | I19: kg/head | N19: ='Input - Pasture Beef'!$E$108 -> Cows 1-2 years | O19: ='Input - Pasture Beef'!$F$108 -> Cows 2-3 years | P19: ='Input - Pasture Beef'!$G$108 -> Cows > 3 years | Q19: ='Input - Pasture Beef'!$H$108 -> 0 | R19: ='Input - Pasture Beef'!$I$108 -> 0 | S19: kg/head
A20: APPENDICES
A21: =HYPERLINK("#'Constants - Dairy'!A1", "Constants - Dairy") -> Constants - Dairy | D21: Table_WR_j
A22: =HYPERLINK("#'Constants - Livestock'!A1", "Constants - Livestock") -> Constants - Livestock | D22: Reference weight for each animal class
A23: =HYPERLINK("#'Constants - Common'!A1", "Constants - Common") -> Constants - Common | D23: Milking cows | E23: Heifers > 1 year | F23: Heifers < 1 year | G23: Bulls > 1 year | H23: Bulls < 1 year
A24: =HYPERLINK("#'Acknowledgements'!A1", "Acknowledgements") -> Acknowledgements | D24: {=#REF!} -> #REF! | E24: {=#REF!} -> #REF! | F24: {=#REF!} -> #REF! | G24: {=#REF!} -> #REF! | H24: {=#REF!} -> #REF! | I24: kg/head
D26: M1_Table_Z_j | N26: M1_Table_Z_j
D27: Relative size for each animal class (Method 1) | N27: Relative size for each animal class (Method 1)
D28: Milking cows | E28: Heifers > 1 year | F28: Heifers < 1 year | G28: Bulls > 1 year | H28: Bulls < 1 year | N28: Milking cows | O28: Heifers > 1 year | P28: Heifers < 1 year | Q28: Bulls > 1 year | R28: Bulls < 1 year
D29: {=MMS_Dairy_N2ODirect_Equations.VEERG_4_3_1_3__8_RelativeSize(D19,D24)} -> #REF! | E29: {=MMS_Dairy_N2ODirect_Equations.VEERG_4_3_1_3__8_RelativeSize(E19,E24)} -> #REF! | F29: {=MMS_Dairy_N2ODirect_Equations.VEERG_4_3_1_3__8_RelativeSize(F19,F24)} -> #REF! | G29: {=MMS_Dairy_N2ODirect_Equations.VEERG_4_3_1_3__8_RelativeSize(G19,G24)} -> #VALUE! | H29: {=MMS_Dairy_N2ODirect_Equations.VEERG_4_3_1_3__8_RelativeSize(H19,H24)} -> #REF! | I29: =$E$11 -> ratio | N29: {=MMS_Dairy_N2ODirect_Equations.VEERG_4_3_1_3__8_RelativeSize(N19,D24)} -> #VALUE! | O29: {=MMS_Dairy_N2ODirect_Equations.VEERG_4_3_1_3__8_RelativeSize(O19,E24)} -> #VALUE! | P29: {=MMS_Dairy_N2ODirect_Equations.VEERG_4_3_1_3__8_RelativeSize(P19,F24)} -> #VALUE! | Q29: {=MMS_Dairy_N2ODirect_Equations.VEERG_4_3_1_3__8_RelativeSize(Q19,G24)} -> #REF! | R29: {=MMS_Dairy_N2ODirect_Equations.VEERG_4_3_1_3__8_RelativeSize(R19,H24)} -> #REF! | S29: =$E$11 -> ratio
D33: {=MMS_Dairy_N2ODirect_Equations.VEERG_4_3_1_3__7_IntakeRelativeToMaintenance_Title()} -> Intake relative to maintenance
D34: {=MMS_Dairy_N2ODirect_Equations.VEERG_4_3_1_3__7_IntakeRelativeToMaintenance_Source()} -> VEERG 2026: 4.3.1.3, Equation (7)
D35: Function name | E35: {=Common_InputFunctions.Utility_DisplayFunctionName(D65)} -> =MMS_Dairy_N2ODirect_Equations.VEERG_4_3_1_3__7_IntakeRelativeToMaintenance
D39: Variable | E39: {=MMS_Dairy_N2ODirect_Equations.VEERG_4_3_1_3__7_IntakeRelativeToMaintenance_Variable()} -> L_j
D40: Unit | E40: {=MMS_Dairy_N2ODirect_Equations.VEERG_4_3_1_3__7_IntakeRelativeToMaintenance_Unit()} -> ratio
D42: {=MMS_Dairy_N2ODirect_Equations.VEERG_4_3_1_3__7_IntakeRelativeToMaintenance_Arguments()} -> I_j | E42: dry matter intake (kgDM/head/day) | G42: ="See " & D47 -> See M1_Table_I_j
D43: W_j | E43: liveweight (kg) | G43: ="See " & D16 -> See M1_Table_W_j
D44: MR_j | E44: increase in metabolic rate when producing milk | G44: ="See " & D52 -> See Table_MR_j
D45: MI_j | E45: additional intake required for milk production (kgDM/head/day) | G45: ="See " & D57 -> See M1_Table_MI_j
D47: M1_Table_I_j | N47: M2_Table_I_j
D48: Feed intake (Method 1) | N48: Feed intake (Method 2)
D49: Milking cows | E49: Heifers > 1 year | F49: Heifers < 1 year | G49: Bulls > 1 year | H49: Bulls < 1 year | N49: Milking cows | O49: Heifers > 1 year | P49: Heifers < 1 year | Q49: Bulls > 1 year | R49: Bulls < 1 year
D50: ='[2]4.2.1'!D84 -> #REF! | E50: ='[2]4.2.1'!E84 -> #REF! | F50: ='4.2.1.1-2 Methane'!F84 -> 0 | G50: ='4.2.1.1-2 Methane'!G84 -> 0 | H50: ='4.2.1.1-2 Methane'!H84 -> 0 | I50: ='4.2.1.1-2 Methane'!I84 -> 0 | N50: ='4.2.1.1-2 Methane'!O84 -> 0 | O50: ='4.2.1.1-2 Methane'!P84 -> 0 | P50: ='4.2.1.1-2 Methane'!Q84 -> 0 | Q50: ='4.2.1.1-2 Methane'!R84 -> 0 | R50: ='4.2.1.1-2 Methane'!S84 -> 0 | S50: ='4.2.1.1-2 Methane'!T84 -> 0
D52: Table_MR_j
...

Sheet 4.3.1.5 Atmos deposition
A1: #VALUE! | C1: 4.3.1.5 Manure Atmospheric Deposition
A3: =HYPERLINK("#'Home'!A1", "Home") -> Home | D3: Method 1 | O3: Method 2
A4: =HYPERLINK("#'Results'!A1", "Results") -> Results
D5: {=MMS_Dairy_AtmosphericDeposition_Equations.VEERG_4_3_1_5__2_TotalNitrogenVolatilisedFromMMS_Title()} -> Total nitrogen volatilised from MMS | G5: There is no method 2 in VEERG doc, but there are method 2 flow-ons from direct N2O
A6: INPUTS | D6: {=MMS_Dairy_AtmosphericDeposition_Equations.VEERG_4_3_1_5__2_TotalNitrogenVolatilisedFromMMS_Source()} -> VEERG 2026: 4.3.1.5, Equation (2)
A7: =HYPERLINK("#'Input - Site'!A1", "Site") -> Site | D7: Function name | E7: {=Common_InputFunctions.Utility_DisplayFunctionName(F40)} -> =MMS_Dairy_AtmosphericDeposition_Equations.VEERG_4_3_1_5__2_TotalNitrogenVolatilisedFromMMS
A8: =HYPERLINK("#'Input - Dairy'!A1", "Dairy") -> Dairy
A10: CALCULATIONS | D10: Variable | E10: {=MMS_Dairy_AtmosphericDeposition_Equations.VEERG_4_3_1_5__2_TotalNitrogenVolatilisedFromMMS_Variable()} -> MN_ATMOS
A11: =HYPERLINK("#'4.3.1.1-2 Methane'!A1", "4.3.1.1-2 Methane") -> 4.3.1.1-2 Methane | D11: Unit | E11: {=MMS_Dairy_AtmosphericDeposition_Equations.VEERG_4_3_1_5__2_TotalNitrogenVolatilisedFromMMS_Unit()} -> kg N
A12: =HYPERLINK("#'4.3.1.3-4 Direct N20'!A1", "4.3.1.3-4 Direct N2O") -> 4.3.1.3-4 Direct N2O
A13: =HYPERLINK("#'4.3.1.5 Atmos Deposition'!A1", "4.3.1.5 Atmospheric deposition") -> 4.3.1.5 Atmospheric deposition | D13: {=MMS_Dairy_AtmosphericDeposition_Equations.VEERG_4_3_1_5__2_TotalNitrogenVolatilisedFromMMS_Arguments()} -> MN_jm | E13: total nitrogen in each MMS for dairy cattle classes (kg N) | G13: ="See " & $D$16 -> See M1_Table_MN_j_m
A14: =HYPERLINK("#'4.3.1.6-7 Leaching and runoff'!A1", "4.3.1.6-7 Leaching and runoff") -> 4.3.1.6-7 Leaching and runoff | D14: FracGASM_m | E14: fraction of N volatilised from MMS (fraction) | G14: ="See " & $D$28 -> See Table_FracGASM_m
A15: =HYPERLINK("#'4.3.1.8 Manure applied to soils'!A1", "4.3.1.8 Manure applied to soils") -> 4.3.1.8 Manure applied to soils
A16: =HYPERLINK("#'4.3.1.9 Soil direct N2O'!A1", "4.3.1.9 Soil direct N2O") -> 4.3.1.9 Soil direct N2O | D16: M1_Table_MN_j_m | O16: M2_Table_MN_j_m
A17: =HYPERLINK("#'4.3.1.10-11 Soil Atmos Dep'!A1", "4.3.1.10-11 Soil atm. deposition") -> 4.3.1.10-11 Soil atm. deposition | D17: Total nitrogen in each MMS (Method 1) | O17: Total nitrogen in each MMS (Method 2)
A18: =HYPERLINK("#'4.3.1.12-13 Soil leach runoff'!A1", "4.3.1.12-13 Soil leach & runoff") -> 4.3.1.12-13 Soil leach & runoff | D18: Production system | E18: MMS | F18: Milking cows | G18: Heifers > 1 year | H18: Heifers < 1 year | I18: Bulls > 1 year | J18: Bulls < 1 year | O18: Production system | P18: MMS | Q18: Milking cows | R18: Heifers > 1 year | S18: Heifers < 1 year | T18: Bulls > 1 year | U18: Bulls < 1 year
D19: ='Input - Pasture Beef'!$D$144 -> Milking shed | E19: ='Input - Pasture Beef'!$D$157 -> Anaerobic lagoon | F19: ='4.3.1.3-4 Direct N20'!$F$236 -> #REF! | G19: ='4.3.1.3-4 Direct N20'!$G$236 -> #REF! | H19: ='4.3.1.3-4 Direct N20'!$H$236 -> #VALUE! | I19: ='4.3.1.3-4 Direct N20'!$I$236 -> #VALUE! | J19: ='4.3.1.3-4 Direct N20'!$J$236 -> #VALUE! | K19: kg N | O19: ='Input - Pasture Beef'!$D$144 -> Milking shed | P19: ='Input - Pasture Beef'!$D$157 -> Anaerobic lagoon | Q19: ='4.3.1.3-4 Direct N20'!$P$236 -> #VALUE! | R19: ='4.3.1.3-4 Direct N20'!$Q$236 -> #VALUE! | S19: ='4.3.1.3-4 Direct N20'!$R$236 -> #VALUE! | T19: ='4.3.1.3-4 Direct N20'!$S$236 -> #VALUE! | U19: ='4.3.1.3-4 Direct N20'!$T$236 -> #VALUE! | V19: kg N
A20: APPENDICES | D20: ='Input - Pasture Beef'!$D$144 -> Milking shed | E20: ='Input - Pasture Beef'!$D$162 -> Sump and dispersal system | F20: ='4.3.1.3-4 Direct N20'!$F$237 -> #REF! | G20: ='4.3.1.3-4 Direct N20'!$G$237 -> #REF! | H20: ='4.3.1.3-4 Direct N20'!$H$237 -> #VALUE! | I20: ='4.3.1.3-4 Direct N20'!$I$237 -> #VALUE! | J20: ='4.3.1.3-4 Direct N20'!$J$237 -> #VALUE! | K20: kg N | O20: ='Input - Pasture Beef'!$D$144 -> Milking shed | P20: ='Input - Pasture Beef'!$D$162 -> Sump and dispersal system | Q20: ='4.3.1.3-4 Direct N20'!$P$237 -> #VALUE! | R20: ='4.3.1.3-4 Direct N20'!$Q$237 -> #VALUE! | S20: ='4.3.1.3-4 Direct N20'!$R$237 -> #VALUE! | T20: ='4.3.1.3-4 Direct N20'!$S$237 -> #VALUE! | U20: ='4.3.1.3-4 Direct N20'!$T$237 -> #VALUE! | V20: kg N
A21: =HYPERLINK("#'Constants - Dairy'!A1", "Constants - Dairy") -> Constants - Dairy | D21: ='Input - Pasture Beef'!$D$144 -> Milking shed | E21: ='Input - Pasture Beef'!$D$167 -> Drains to paddock | F21: ='4.3.1.3-4 Direct N20'!$F$238 -> #REF! | G21: ='4.3.1.3-4 Direct N20'!$G$238 -> #REF! | H21: ='4.3.1.3-4 Direct N20'!$H$238 -> #VALUE! | I21: ='4.3.1.3-4 Direct N20'!$I$238 -> #VALUE! | J21: ='4.3.1.3-4 Direct N20'!$J$238 -> #VALUE! | K21: kg N | O21: ='Input - Pasture Beef'!$D$144 -> Milking shed | P21: ='Input - Pasture Beef'!$D$167 -> Drains to paddock | Q21: ='4.3.1.3-4 Direct N20'!$P$238 -> #VALUE! | R21: ='4.3.1.3-4 Direct N20'!$Q$238 -> #VALUE! | S21: ='4.3.1.3-4 Direct N20'!$R$238 -> #VALUE! | T21: ='4.3.1.3-4 Direct N20'!$S$238 -> #VALUE! | U21: ='4.3.1.3-4 Direct N20'!$T$238 -> #VALUE! | V21: kg N
A22: =HYPERLINK("#'Constants - Livestock'!A1", "Constants - Livestock") -> Constants - Livestock | D22: ='Input - Pasture Beef'!$D$144 -> Milking shed | E22: ='Input - Pasture Beef'!$D$172 -> Solid storage | F22: ='4.3.1.3-4 Direct N20'!$F$239 -> #REF! | G22: ='4.3.1.3-4 Direct N20'!$G$239 -> #REF! | H22: ='4.3.1.3-4 Direct N20'!$H$239 -> #VALUE! | I22: ='4.3.1.3-4 Direct N20'!$I$239 -> #VALUE! | J22: ='4.3.1.3-4 Direct N20'!$J$239 -> #VALUE! | K22: kg N | O22: ='Input - Pasture Beef'!$D$144 -> Milking shed | P22: ='Input - Pasture Beef'!$D$172 -> Solid storage | Q22: ='4.3.1.3-4 Direct N20'!$P$239 -> #VALUE! | R22: ='4.3.1.3-4 Direct N20'!$Q$239 -> #VALUE! | S22: ='4.3.1.3-4 Direct N20'!$R$239 -> #VALUE! | T22: ='4.3.1.3-4 Direct N20'!$S$239 -> #VALUE! | U22: ='4.3.1.3-4 Direct N20'!$T$239 -> #VALUE! | V22: kg N
A23: =HYPERLINK("#'Constants - Common'!A1", "Constants - Common") -> Constants - Common | D23: ='Input - Pasture Beef'!$D$145 -> Feed pad | E23: ='Input - Pasture Beef'!$D$191 -> Anaerobic lagoon | F23: ='4.3.1.3-4 Direct N20'!$F$240 -> #REF! | G23: ='4.3.1.3-4 Direct N20'!$G$240 -> #REF! | H23: ='4.3.1.3-4 Direct N20'!$H$240 -> #VALUE! | I23: ='4.3.1.3-4 Direct N20'!$I$240 -> #VALUE! | J23: ='4.3.1.3-4 Direct N20'!$J$240 -> #VALUE! | K23: kg N | O23: ='Input - Pasture Beef'!$D$145 -> Feed pad | P23: ='Input - Pasture Beef'!$D$191 -> Anaerobic lagoon | Q23: ='4.3.1.3-4 Direct N20'!$P$240 -> #VALUE! | R23: ='4.3.1.3-4 Direct N20'!$Q$240 -> #VALUE! | S23: ='4.3.1.3-4 Direct N20'!$R$240 -> #VALUE! | T23: ='4.3.1.3-4 Direct N20'!$S$240 -> #VALUE! | U23: ='4.3.1.3-4 Direct N20'!$T$240 -> #VALUE! | V23: kg N
A24: =HYPERLINK("#'Acknowledgements'!A1", "Acknowledgements") -> Acknowledgements | D24: ='Input - Pasture Beef'!$D$145 -> Feed pad | E24: ='Input - Pasture Beef'!$D$196 -> Sump and dispersal system | F24: ='4.3.1.3-4 Direct N20'!$F$241 -> #REF! | G24: ='4.3.1.3-4 Direct N20'!$G$241 -> #REF! | H24: ='4.3.1.3-4 Direct N20'!$H$241 -> #VALUE! | I24: ='4.3.1.3-4 Direct N20'!$I$241 -> #VALUE! | J24: ='4.3.1.3-4 Direct N20'!$J$241 -> #VALUE! | K24: kg N | O24: ='Input - Pasture Beef'!$D$145 -> Feed pad | P24: ='Input - Pasture Beef'!$D$196 -> Sump and dispersal system | Q24: ='4.3.1.3-4 Direct N20'!$P$241 -> #VALUE! | R24: ='4.3.1.3-4 Direct N20'!$Q$241 -> #VALUE! | S24: ='4.3.1.3-4 Direct N20'!$R$241 -> #VALUE! | T24: ='4.3.1.3-4 Direct N20'!$S$241 -> #VALUE! | U24: ='4.3.1.3-4 Direct N20'!$T$241 -> #VALUE! | V24: kg N
D25: ='Input - Pasture Beef'!$D$145 -> Feed pad | E25: ='Input - Pasture Beef'!$D$201 -> Drains to paddock | F25: ='4.3.1.3-4 Direct N20'!$F$242 -> #REF! | G25: ='4.3.1.3-4 Direct N20'!$G$242 -> #REF! | H25: ='4.3.1.3-4 Direct N20'!$H$242 -> #VALUE! | I25: ='4.3.1.3-4 Direct N20'!$I$242 -> #VALUE! | J25: ='4.3.1.3-4 Direct N20'!$J$242 -> #VALUE! | K25: kg N | O25: ='Input - Pasture Beef'!$D$145 -> Feed pad | P25: ='Input - Pasture Beef'!$D$201 -> Drains to paddock | Q25: ='4.3.1.3-4 Direct N20'!$P$242 -> #VALUE! | R25: ='4.3.1.3-4 Direct N20'!$Q$242 -> #VALUE! | S25: ='4.3.1.3-4 Direct N20'!$R$242 -> #VALUE! | T25: ='4.3.1.3-4 Direct N20'!$S$242 -> #VALUE! | U25: ='4.3.1.3-4 Direct N20'!$T$242 -> #VALUE! | V25: kg N
D26: ='Input - Pasture Beef'!$D$145 -> Feed pad | E26: ='Input - Pasture Beef'!$D$206 -> Solid storage | F26: ='4.3.1.3-4 Direct N20'!$F$243 -> #REF! | G26: ='4.3.1.3-4 Direct N20'!$G$243 -> #REF! | H26: ='4.3.1.3-4 Direct N20'!$H$243 -> #VALUE! | I26: ='4.3.1.3-4 Direct N20'!$I$243 -> #VALUE! | J26: ='4.3.1.3-4 Direct N20'!$J$243 -> #VALUE! | K26: kg N | O26: ='Input - Pasture Beef'!$D$145 -> Feed pad | P26: ='Input - Pasture Beef'!$D$206 -> Solid storage | Q26: ='4.3.1.3-4 Direct N20'!$P$243 -> #VALUE! | R26: ='4.3.1.3-4 Direct N20'!$Q$243 -> #VALUE! | S26: ='4.3.1.3-4 Direct N20'!$R$243 -> #VALUE! | T26: ='4.3.1.3-4 Direct N20'!$S$243 -> #VALUE! | U26: ='4.3.1.3-4 Direct N20'!$T$243 -> #VALUE! | V26: kg N
D28: Table_FracGASM_m
D29: Fraction N volatilised from each MS
D30: MMS | E30: FracGASMm
D31: {=#REF!} -> #REF! | E31: {=#REF!} -> #REF! | F31: ='Constants - Pature Beef'!$D$103 -> VIC
F32: ='Constants - Pature Beef'!$D$103 -> VIC
F33: ='Constants - Pature Beef'!$D$103 -> VIC
F34: ='Constants - Pature Beef'!$D$103 -> VIC
F35: ='Constants - Pature Beef'!$D$103 -> VIC
D37: M1_Table_MN_atmos | O37: M2_Table_MN_atmos
D38: Total nitrogen volatilised from each MMS (Method 1) | O38: Total nitrogen volatilised from each MMS (Method 2)
D39: Production system | E39: MMS | F39: Milking cows | G39: Heifers > 1 year | H39: Heifers < 1 year | I39: Bulls > 1 year | J39: Bulls < 1 year | O39: Production system | P39: MMS | Q39: Milking cows | R39: Heifers > 1 year | S39: Heifers < 1 year | T39: Bulls > 1 year | U39: Bulls < 1 year
D40: ='Input - Pasture Beef'!$D$144 -> Milking shed | E40: ='Input - Pasture Beef'!$D$157 -> Anaerobic lagoon | F40: {=MMS_Dairy_AtmosphericDeposition_Equations.VEERG_4_3_1_5__2_TotalNitrogenVolatilisedFromMMS(F19,$E32)} -> #REF! | G40: {=MMS_Dairy_AtmosphericDeposition_Equations.VEERG_4_3_1_5__2_TotalNitrogenVolatilisedFromMMS(G19,$E32)} -> #REF! | H40: {=MMS_Dairy_AtmosphericDeposition_Equations.VEERG_4_3_1_5__2_TotalNitrogenVolatilisedFromMMS(H19,$E32)} -> #VALUE! | I40: {=MMS_Dairy_AtmosphericDeposition_Equations.VEERG_4_3_1_5__2_TotalNitrogenVolatilisedFromMMS(I19,$E32)} -> #VALUE! | J40: {=MMS_Dairy_AtmosphericDeposition_Equations.VEERG_4_3_1_5__2_TotalNitrogenVolatilisedFromMMS(J19,$E32)} -> #VALUE! | K40: kg N | O40: ='Input - Pasture Beef'!$D$144 -> Milking shed | P40: ='Input - Pasture Beef'!$D$157 -> Anaerobic lagoon | Q40: {=MMS_Dairy_AtmosphericDeposition_Equations.VEERG_4_3_1_5__2_TotalNitrogenVolatilisedFromMMS(Q19,$E32)} -> #VALUE! | R40: {=MMS_Dairy_AtmosphericDeposition_Equations.VEERG_4_3_1_5__2_TotalNitrogenVolatilisedFromMMS(R19,$E32)} -> #VALUE! | S40: {=MMS_Dairy_AtmosphericDeposition_Equations.VEERG_4_3_1_5__2_TotalNitrogenVolatilisedFromMMS(S19,$E32)} -> #VALUE! | T40: {=MMS_Dairy_AtmosphericDeposition_Equations.VEERG_4_3_1_5__2_TotalNitrogenVolatilisedFromMMS(T19,$E32)} -> #VALUE! | U40: {=MMS_Dairy_AtmosphericDeposition_Equations.VEERG_4_3_1_5__2_TotalNitrogenVolatilisedFromMMS(U19,$E32)} -> #VALUE! | V40: kg N
D41: ='Input - Pasture Beef'!$D$144 -> Milking shed | E41: ='Input - Pasture Beef'!$D$162 -> Sump and dispersal system | F41: {=MMS_Dairy_AtmosphericDeposition_Equations.VEERG_4_3_1_5__2_TotalNitrogenVolatilisedFromMMS(F20,$E33)} -> #REF! | G41: {=MMS_Dairy_AtmosphericDeposition_Equations.VEERG_4_3_1_5__2_TotalNitrogenVolatilisedFromMMS(G20,$E33)} -> #REF! | H41: {=MMS_Dairy_AtmosphericDeposition_Equations.VEERG_4_3_1_5__2_TotalNitrogenVolatilisedFromMMS(H20,$E33)} -> #VALUE! | I41: {=MMS_Dairy_AtmosphericDeposition_Equations.VEERG_4_3_1_5__2_TotalNitrogenVolatilisedFromMMS(I20,$E33)} -> #VALUE! | J41: {=MMS_Dairy_AtmosphericDeposition_Equations.VEERG_4_3_1_5__2_TotalNitrogenVolatilisedFromMMS(J20,$E33)} -> #VALUE! | K41: kg N | O41: ='Input - Pasture Beef'!$D$144 -> Milking shed | P41: ='Input - Pasture Beef'!$D$162 -> Sump and dispersal system | Q41: {=MMS_Dairy_AtmosphericDeposition_Equations.VEERG_4_3_1_5__2_TotalNitrogenVolatilisedFromMMS(Q20,$E33)} -> #VALUE! | R41: {=MMS_Dairy_AtmosphericDeposition_Equations.VEERG_4_3_1_5__2_TotalNitrogenVolatilisedFromMMS(R20,$E33)} -> #VALUE! | S41: {=MMS_Dairy_AtmosphericDeposition_Equations.VEERG_4_3_1_5__2_TotalNitrogenVolatilisedFromMMS(S20,$E33)} -> #VALUE! | T41: {=MMS_Dairy_AtmosphericDeposition_Equations.VEERG_4_3_1_5__2_TotalNitrogenVolatilisedFromMMS(T20,$E33)} -> #VALUE! | U41: {=MMS_Dairy_AtmosphericDeposition_Equations.VEERG_4_3_1_5__2_TotalNitrogenVolatilisedFromMMS(U20,$E33)} -> #VALUE! | V41: kg N
D42: ='Input - Pasture Beef'!$D$144 -> Milking shed | E42: ='Input - Pasture Beef'!$D$167 -> Drains to paddock | F42: {=MMS_Dairy_AtmosphericDeposition_Equations.VEERG_4_3_1_5__2_TotalNitrogenVolatilisedFromMMS(F21,$E34)} -> #REF! | G42: {=MMS_Dairy_AtmosphericDeposition_Equations.VEERG_4_3_1_5__2_TotalNitrogenVolatilisedFromMMS(G21,$E34)} -> #REF! | H42: {=MMS_Dairy_AtmosphericDeposition_Equations.VEERG_4_3_1_5__2_TotalNitrogenVolatilisedFromMMS(H21,$E34)} -> #VALUE! | I42: {=MMS_Dairy_AtmosphericDeposition_Equations.VEERG_4_3_1_5__2_TotalNitrogenVolatilisedFromMMS(I21,$E34)} -> #VALUE! | J42: {=MMS_Dairy_AtmosphericDeposition_Equations.VEERG_4_3_1_5__2_TotalNitrogenVolatilisedFromMMS(J21,$E34)} -> #VALUE! | K42: kg N | O42: ='Input - Pasture Beef'!$D$144 -> Milking shed | P42: ='Input - Pasture Beef'!$D$167 -> Drains to paddock | Q42: {=MMS_Dairy_AtmosphericDeposition_Equations.VEERG_4_3_1_5__2_TotalNitrogenVolatilisedFromMMS(Q21,$E34)} -> #VALUE! | R42: {=MMS_Dairy_AtmosphericDeposition_Equations.VEERG_4_3_1_5__2_TotalNitrogenVolatilisedFromMMS(R21,$E34)} -> #VALUE! | S42: {=MMS_Dairy_AtmosphericDeposition_Equations.VEERG_4_3_1_5__2_TotalNitrogenVolatilisedFromMMS(S21,$E34)} -> #VALUE! | T42: {=MMS_Dairy_AtmosphericDeposition_Equations.VEERG_4_3_1_5__2_TotalNitrogenVolatilisedFromMMS(T21,$E34)} -> #VALUE! | U42: {=MMS_Dairy_AtmosphericDeposition_Equations.VEERG_4_3_1_5__2_TotalNitrogenVolatilisedFromMMS(U21,$E34)} -> #VALUE! | V42: kg N
D43: ='Input - Pasture Beef'!$D$144 -> Milking shed | E43: ='Input - Pasture Beef'!$D$172 -> Solid storage | F43: {=MMS_Dairy_AtmosphericDeposition_Equations.VEERG_4_3_1_5__2_TotalNitrogenVolatilisedFromMMS(F22,$E35)} -> #REF! | G43: {=MMS_Dairy_AtmosphericDeposition_Equations.VEERG_4_3_1_5__2_TotalNitrogenVolatilisedFromMMS(G22,$E35)} -> #REF! | H43: {=MMS_Dairy_AtmosphericDeposition_Equations.VEERG_4_3_1_5__2_TotalNitrogenVolatilisedFromMMS(H22,$E35)} -> #VALUE! | I43: {=MMS_Dairy_AtmosphericDeposition_Equations.VEERG_4_3_1_5__2_TotalNitrogenVolatilisedFromMMS(I22,$E35)} -> #VALUE! | J43: {=MMS_Dairy_AtmosphericDeposition_Equations.VEERG_4_3_1_5__2_TotalNitrogenVolatilisedFromMMS(J22,$E35)} -> #VALUE! | K43: kg N | O43: ='Input - Pasture Beef'!$D$144 -> Milking shed | P43: ='Input - Pasture Beef'!$D$172 -> Solid storage | Q43: {=MMS_Dairy_AtmosphericDeposition_Equations.VEERG_4_3_1_5__2_TotalNitrogenVolatilisedFromMMS(Q22,$E35)} -> #VALUE! | R43: {=MMS_Dairy_AtmosphericDeposition_Equations.VEERG_4_3_1_5__2_TotalNitrogenVolatilisedFromMMS(R22,$E35)} -> #VALUE! | S43: {=MMS_Dairy_AtmosphericDeposition_Equations.VEERG_4_3_1_5__2_TotalNitrogenVolatilisedFromMMS(S22,$E35)} -> #VALUE! | T43: {=MMS_Dairy_AtmosphericDeposition_Equations.VEERG_4_3_1_5__2_TotalNitrogenVolatilisedFromMMS(T22,$E35)} -> #VALUE! | U43: {=MMS_Dairy_AtmosphericDeposition_Equations.VEERG_4_3_1_5__2_TotalNitrogenVolatilisedFromMMS(U22,$E35)} -> #VALUE! | V43: kg N
D44: ='Input - Pasture Beef'!$D$145 -> Feed pad | E44: ='Input - Pasture Beef'!$D$191 -> Anaerobic lagoon | F44: {=MMS_Dairy_AtmosphericDeposition_Equations.VEERG_4_3_1_5__2_TotalNitrogenVolatilisedFromMMS(F23, $E32)} -> #REF! | G44: {=MMS_Dairy_AtmosphericDeposition_Equations.VEERG_4_3_1_5__2_TotalNitrogenVolatilisedFromMMS(G23, $E32)} -> #REF! | H44: {=MMS_Dairy_AtmosphericDeposition_Equations.VEERG_4_3_1_5__2_TotalNitrogenVolatilisedFromMMS(H23, $E32)} -> #VALUE! | I44: {=MMS_Dairy_AtmosphericDeposition_Equations.VEERG_4_3_1_5__2_TotalNitrogenVolatilisedFromMMS(I23, $E32)} -> #VALUE! | J44: {=MMS_Dairy_AtmosphericDeposition_Equations.VEERG_4_3_1_5__2_TotalNitrogenVolatilisedFromMMS(J23, $E32)} -> #VALUE! | K44: kg N | O44: ='Input - Pasture Beef'!$D$145 -> Feed pad | P44: ='Input - Pasture Beef'!$D$191 -> Anaerobic lagoon | Q44: {=MMS_Dairy_AtmosphericDeposition_Equations.VEERG_4_3_1_5__2_TotalNitrogenVolatilisedFromMMS(Q23, $E32)} -> #VALUE! | R44: {=MMS_Dairy_AtmosphericDeposition_Equations.VEERG_4_3_1_5__2_TotalNitrogenVolatilisedFromMMS(R23, $E32)} -> #VALUE! | S44: {=MMS_Dairy_AtmosphericDeposition_Equations.VEERG_4_3_1_5__2_TotalNitrogenVolatilisedFromMMS(S23, $E32)} -> #VALUE! | T44: {=MMS_Dairy_AtmosphericDeposition_Equations.VEERG_4_3_1_5__2_TotalNitrogenVolatilisedFromMMS(T23, $E32)} -> #VALUE! | U44: {=MMS_Dairy_AtmosphericDeposition_Equations.VEERG_4_3_1_5__2_TotalNitrogenVolatilisedFromMMS(U23, $E32)} -> #VALUE! | V44: kg N
...

Sheet 4.3.1.6-7 Leaching and runoff
A1: #VALUE! | C1: 4.1.1.6-7 Manure leaching and runoff
A3: =HYPERLINK("#'Home'!A1", "Home") -> Home | D3: Method 1 | O3: Method 2
A4: =HYPERLINK("#'Results'!A1", "Results") -> Results
D5: {=MMS_Dairy_LeachingAndRunoff_Equations.VEERG_4_3_1_6__2_MassOfNitrogenLostToLeachingAndRunoffFromSolidStorage_Title()} -> Mass of nitrogen lost to leaching and runoff from solid storage systems
A6: INPUTS | D6: {=MMS_Dairy_LeachingAndRunoff_Equations.VEERG_4_3_1_6__2_MassOfNitrogenLostToLeachingAndRunoffFromSolidStorage_Source()} -> VEERG 2026: 4.3.1.6, Equation (2)
A7: =HYPERLINK("#'Input - Site'!A1", "Site") -> Site | D7: Function name | E7: {=Common_InputFunctions.Utility_DisplayFunctionName($F$29)} -> =MMS_Dairy_LeachingAndRunoff_Equations.VEERG_4_3_1_6__2_MassOfNitrogenLostToLeachingAndRunoffFromSolidStorage
A8: =HYPERLINK("#'Input - Dairy'!A1", "Dairy") -> Dairy | G8: There is no method 2 in VEERG doc, but there are method 2 flow-ons from direct N2O
A10: CALCULATIONS | D10: Variable | E10: {=MMS_Dairy_LeachingAndRunoff_Equations.VEERG_4_3_1_6__2_MassOfNitrogenLostToLeachingAndRunoffFromSolidStorage_Variable()} -> MNLeach_jm4
A11: =HYPERLINK("#'4.3.1.1-2 Methane'!A1", "4.3.1.1-2 Methane") -> 4.3.1.1-2 Methane | D11: Unit | E11: {=MMS_Dairy_LeachingAndRunoff_Equations.VEERG_4_3_1_6__2_MassOfNitrogenLostToLeachingAndRunoffFromSolidStorage_Unit()} -> kg N
A12: =HYPERLINK("#'4.3.1.3-4 Direct N20'!A1", "4.3.1.3-4 Direct N2O") -> 4.3.1.3-4 Direct N2O
A13: =HYPERLINK("#'4.3.1.5 Atmos Deposition'!A1", "4.3.1.5 Atmospheric deposition") -> 4.3.1.5 Atmospheric deposition | D13: {=MMS_Dairy_LeachingAndRunoff_Equations.VEERG_4_3_1_6__2_MassOfNitrogenLostToLeachingAndRunoffFromSolidStorage_Arguments()} -> MN_jm4 | E13: total nitrogen in solid storage system m=4 (kg N) | H13: ="See " & D20 -> See M1_Table_MN_j_m-4
A14: =HYPERLINK("#'4.3.1.6-7 Leaching and runoff'!A1", "4.3.1.6-7 Leaching and runoff") -> 4.3.1.6-7 Leaching and runoff | D14: FracWET_i | E14: fraction of N that is available for leaching and runoff from the leaching zone z and irrigation type ir (dimensionless) | H14: {=Common_InputFunctions.CommonCropping_GetFracWET(H16,H18,Table_SourceData_FracWET[Is in leaching zone],Table_SourceData_FracWET[FracWET],Table_SourceData_FracWETIrrigation[Irrigation type i],Table_SourceData_FracWETIrrigation[FracWET])} -> 1
A15: =HYPERLINK("#'4.3.1.8 Manure applied to soils'!A1", "4.3.1.8 Manure applied to soils") -> 4.3.1.8 Manure applied to soils | D15: FracLEACH_MS | E15: fraction of N that is lost through leaching and runoff (dimensionless) | H15: ='Constants - Pature Beef'!$D$237 -> VIC
A16: =HYPERLINK("#'4.3.1.9 Soil direct N2O'!A1", "4.3.1.9 Soil direct N2O") -> 4.3.1.9 Soil direct N2O | D16: z | E16: location in leaching zone | H16: ='Input - Site'!$E$23 -> NO - Not in leaching zone
A17: =HYPERLINK("#'4.3.1.10-11 Soil Atmos Dep'!A1", "4.3.1.10-11 Soil atm. deposition") -> 4.3.1.10-11 Soil atm. deposition | D17: j | E17: production system | H17: ='Input - Pasture Beef'!$E$273 -> Pasture
A18: =HYPERLINK("#'4.3.1.12-13 Soil leach runoff'!A1", "4.3.1.12-13 Soil leach & runoff") -> 4.3.1.12-13 Soil leach & runoff | D18: ir | E18: irrigation method | H18: ='Input - Pasture Beef'!$E$274 -> Sprinkler irrigation
A20: APPENDICES | D20: M1_Table_MN_j_m-4 | O20: M2_Table_MN_j_m-4
A21: =HYPERLINK("#'Constants - Dairy'!A1", "Constants - Dairy") -> Constants - Dairy | D21: Total nitrogen in solid storage MMS (Method 1) | O21: Total nitrogen in solid storage MMS (Method 2)
A22: =HYPERLINK("#'Constants - Livestock'!A1", "Constants - Livestock") -> Constants - Livestock | D22: Production system | E22: MMS | F22: Milking cows | G22: Heifers > 1 year | H22: Heifers < 1 year | I22: Bulls > 1 year | J22: Bulls < 1 year | O22: Production system | P22: MMS | Q22: Milking cows | R22: Heifers > 1 year | S22: Heifers < 1 year | T22: Bulls > 1 year | U22: Bulls < 1 year
A23: =HYPERLINK("#'Constants - Common'!A1", "Constants - Common") -> Constants - Common | D23: ='Input - Pasture Beef'!$D$144 -> Milking shed | E23: ='Input - Pasture Beef'!$D$172 -> Solid storage | F23: ='4.3.1.3-4 Direct N20'!F239 -> #REF! | G23: ='4.3.1.3-4 Direct N20'!G239 -> #REF! | H23: ='4.3.1.3-4 Direct N20'!H239 -> #VALUE! | I23: ='4.3.1.3-4 Direct N20'!I239 -> #VALUE! | J23: ='4.3.1.3-4 Direct N20'!J239 -> #VALUE! | K23: kg N | O23: ='Input - Pasture Beef'!$D$144 -> Milking shed | P23: ='Input - Pasture Beef'!$D$172 -> Solid storage | Q23: ='4.3.1.3-4 Direct N20'!P239 -> #VALUE! | R23: ='4.3.1.3-4 Direct N20'!Q239 -> #VALUE! | S23: ='4.3.1.3-4 Direct N20'!R239 -> #VALUE! | T23: ='4.3.1.3-4 Direct N20'!S239 -> #VALUE! | U23: ='4.3.1.3-4 Direct N20'!T239 -> #VALUE! | V23: kg N
A24: =HYPERLINK("#'Acknowledgements'!A1", "Acknowledgements") -> Acknowledgements | D24: ='Input - Pasture Beef'!$D$145 -> Feed pad | E24: ='Input - Pasture Beef'!$D$206 -> Solid storage | F24: ='4.3.1.3-4 Direct N20'!F243 -> #REF! | G24: ='4.3.1.3-4 Direct N20'!G243 -> #REF! | H24: ='4.3.1.3-4 Direct N20'!H243 -> #VALUE! | I24: ='4.3.1.3-4 Direct N20'!I243 -> #VALUE! | J24: ='4.3.1.3-4 Direct N20'!J243 -> #VALUE! | K24: kg N | O24: ='Input - Pasture Beef'!$D$145 -> Feed pad | P24: ='Input - Pasture Beef'!$D$206 -> Solid storage | Q24: ='4.3.1.3-4 Direct N20'!P243 -> #VALUE! | R24: ='4.3.1.3-4 Direct N20'!Q243 -> #VALUE! | S24: ='4.3.1.3-4 Direct N20'!R243 -> #VALUE! | T24: ='4.3.1.3-4 Direct N20'!S243 -> #VALUE! | U24: ='4.3.1.3-4 Direct N20'!T243 -> #VALUE! | V24: kg N
D26: M1_Table_MN_leach_j_m-4 | O26: M2_Table_MN_leach_j_m-4
D27: Mass of N lost to leaching and runoff from solid storage (Method 1) | O27: Mass of N lost to leaching and runoff from solid storage (Method 2)
D28: Production system | E28: MMS | F28: Milking cows | G28: Heifers > 1 year | H28: Heifers < 1 year | I28: Bulls > 1 year | J28: Bulls < 1 year | O28: Production system | P28: MMS | Q28: Milking cows | R28: Heifers > 1 year | S28: Heifers < 1 year | T28: Bulls > 1 year | U28: Bulls < 1 year
