Workbook
Name Common_Equations.Common_ConvertCH4ToCO2e: _xlfn.LAMBDA(_xlpm.E_CH4,_xlpm.GWP_CH4, _xlpm.E_CH4 * _xlpm.GWP_CH4)
Name Common_Equations.Common_ConvertCH4ToCO2e_Arguments: _xlfn.LAMBDA(_xlfn.MAKEARRAY(2, 2, _xlfn.LAMBDA(_xlpm.r,_xlpm.c, INDEX({"ECH4","Methane emissions (t CH4)";"GWPCH4","Global warming potential for methane (t CO2-e / t CH4)"}, _xlpm.r, _xlpm.c))))
Name Common_Equations.Common_ConvertCH4ToCO2e_LatexEquation: _xlfn.LAMBDA("CO2_e = E_{CH4} \times GWP_{CH4}")
Name Common_Equations.Common_ConvertCH4ToCO2e_NIRReference: _xlfn.LAMBDA("")
Name Common_Equations.Common_ConvertCH4ToCO2e_Title: _xlfn.LAMBDA("Convert methane emissions to carbon dioxide equivalent emissions")
Name Common_Equations.Common_ConvertCH4ToCO2e_Unit: _xlfn.LAMBDA("t CO2e")
Name Common_Equations.Common_ConvertCH4ToCO2e_Variable: _xlfn.LAMBDA("ECH4 CO2e")
Name Common_Equations.Common_ConvertN2OToCO2e: _xlfn.LAMBDA(_xlpm.E_N2O,_xlpm.GWP_N2O, _xlpm.E_N2O * _xlpm.GWP_N2O)
Name Common_Equations.Common_ConvertN2OToCO2e_LatexEquation: _xlfn.LAMBDA("CO2_e = E_{N2O} \times GWP_{N2O}")
Name Common_Equations.Common_ConvertN2OToCO2e_NIRReference: _xlfn.LAMBDA("")
Name Common_Equations.Common_ConvertN2OToCO2e_Title: _xlfn.LAMBDA("Convert nitrous oxide emissions to carbon dioxide equivalent emissions")
Name Common_Equations.Common_ConvertN2OToCO2e_Unit: _xlfn.LAMBDA("t CO2e")
Name Common_Equations.Common_ConvertN2OToCO2e_Variable: _xlfn.LAMBDA("EN2O CO2e")
Name Common_InputFunctions.Utility_ConvertStateCommonNameToAbbreviation: _xlfn.LAMBDA(_xlpm.StateCommonName,_xlpm.StateCommonNameArray,_xlpm.StateAbbreviationArray, _xlfn.XLOOKUP(_xlpm.StateCommonName, _xlpm.StateCommonNameArray, _xlpm.StateAbbreviationArray, ""))
Name Common_InputFunctions.Utility_DisplayFunctionName: _xlfn.LAMBDA(_xlpm.Function, _xlfn.TEXTBEFORE(_xlfn.FORMULATEXT(_xlpm.Function), "("))
Name Common_InputFunctions.Utility_GetArrayTableColumnStartNumber: _xlfn.LAMBDA(_xlpm.TableHeaderCell, COLUMN(_xlpm.TableHeaderCell))
Name Common_InputFunctions.Utility_GetArrayTableRowStartNumber: _xlfn.LAMBDA(_xlpm.TableheaderCell,_xlpm.RowsBetweenHeaderandArray, ROW(_xlpm.TableheaderCell) + _xlpm.RowsBetweenHeaderandArray - 1)
Name Common_InputFunctions.Utility_LookupValueInTable: _xlfn.LAMBDA(_xlpm.LookupValue,_xlpm.LookupArray,_xlpm.ReturnArray, _xlfn.XLOOKUP(_xlpm.LookupValue, _xlpm.LookupArray, _xlpm.ReturnArray, ""))
Name Common_SourceData.Common_SourceData_AustralianStatesTerritories_Source: _xlfn.LAMBDA("")
Name Common_SourceData.Common_SourceData_AustralianStatesTerritories_Title: _xlfn.LAMBDA("Australian states and territories")
Name Common_SourceData.Common_SourceData_AustralianStatesTerritories_Unit: _xlfn.LAMBDA("")
Name Common_SourceData.Common_SourceData_AustralianStatesTerritories_Variable: _xlfn.LAMBDA("")
Name Common_SourceData.Common_SourceData_ClimateZones_Source: _xlfn.LAMBDA("VEERG 2026: Table 1.3: Climate and Rainfall zone classifications and definitions")
Name Common_SourceData.Common_SourceData_ClimateZones_Title: _xlfn.LAMBDA("VEERG Australian climate zones")
Name Common_SourceData.Common_SourceData_ClimateZones_Unit: _xlfn.LAMBDA("")
Name Common_SourceData.Common_SourceData_ClimateZones_Variable: _xlfn.LAMBDA("")
Name Common_SourceData.Common_SourceData_ConvertGasElementalToMolecular_Source: _xlfn.LAMBDA("XXXXXXX")
Name Common_SourceData.Common_SourceData_ConvertGasElementalToMolecular_Title: _xlfn.LAMBDA("Factor to convert elemental mass of gas to molecular mass")
Name Common_SourceData.Common_SourceData_ConvertGasElementalToMolecular_Unit: _xlfn.LAMBDA("factor")
Name Common_SourceData.Common_SourceData_ConvertGasElementalToMolecular_Variable: _xlfn.LAMBDA("Cg")
Name Common_SourceData.Common_SourceData_ConvertN2oElementalToMolecularCg_Data: _xlfn.LAMBDA(44 / 28)
Name Common_SourceData.Common_SourceData_ConvertN2oElementalToMolecularCg_Source: _xlfn.LAMBDA("National Inventory Report 2023 Volume 1")
Name Common_SourceData.Common_SourceData_ConvertN2oElementalToMolecularCg_Title: _xlfn.LAMBDA("Factor to convert elemental mass of N2O to molecular mass")
Name Common_SourceData.Common_SourceData_ConvertN2oElementalToMolecularCg_Unit: _xlfn.LAMBDA("factor")
Name Common_SourceData.Common_SourceData_ConvertN2oElementalToMolecularCg_Variable: _xlfn.LAMBDA("CgN2O")
Name Common_SourceData.Common_SourceData_DataScores_Scope3_Source: _xlfn.LAMBDA("VEERG 2026: XXXXXXXX")
Name Common_SourceData.Common_SourceData_DataScores_Scope3_Title: _xlfn.LAMBDA("Australian data scores for scope 3")
Name Common_SourceData.Common_SourceData_DataScores_Scope3_Unit: _xlfn.LAMBDA("")
Name Common_SourceData.Common_SourceData_DataScores_Scope3_Variable: _xlfn.LAMBDA("")
Name Common_SourceData.Common_SourceData_DataScores_Scope3_Variation: _xlfn.LAMBDA("")
Name Common_SourceData.Common_SourceData_DensityOfMethane_Data: _xlfn.LAMBDA(0.6784)
Name Common_SourceData.Common_SourceData_DensityOfMethane_Source: _xlfn.LAMBDA("National Inventory Report 2023 Volume 1: Equations 3.B.1a_2, 3.B.1c_2, 3.B.3_1, 3.B.4g_2")
Name Common_SourceData.Common_SourceData_DensityOfMethane_Title: _xlfn.LAMBDA("p = density of methane")
Name Common_SourceData.Common_SourceData_DensityOfMethane_Unit: _xlfn.LAMBDA("kg/m3")
Name Common_SourceData.Common_SourceData_EFleach_Data: _xlfn.LAMBDA(_xlfn.MAKEARRAY(1, 2, _xlfn.LAMBDA(_xlpm.r,_xlpm.c, INDEX({"EFleach",0.011}, _xlpm.r, _xlpm.c))))
Name Common_SourceData.Common_SourceData_EFleach_NIRReference: _xlfn.LAMBDA("National Inventory Report Volume 1: Equation 3.D.B_10")
Name Common_SourceData.Common_SourceData_EFleach_Source: _xlfn.LAMBDA("VEERG 2026:5.5.2.3 Constant Parameters")
Name Common_SourceData.Common_SourceData_EFleach_Title: _xlfn.LAMBDA("Emission factor for nitrogen leaching and runoff")
Name Common_SourceData.Common_SourceData_EFleach_Unit: _xlfn.LAMBDA("(kg N2O-N / kg N")
Name Common_SourceData.Common_SourceData_EFleach_Variation: _xlfn.LAMBDA((""))
Name Common_SourceData.Common_SourceData_EFN2O_NIRReference: _xlfn.LAMBDA("")
Name Common_SourceData.Common_SourceData_EFN2O_Source: _xlfn.LAMBDA("VEERG 2026: Table A.2.2.1")
Name Common_SourceData.Common_SourceData_EFN2O_Title: _xlfn.LAMBDA("Nitrous oxide emission factors for inorganic fertiliser application")
Name Common_SourceData.Common_SourceData_EFN2O_Unit: _xlfn.LAMBDA("(kg N2O-N / kg N")
Name Common_SourceData.Common_SourceData_EFPastureRangeAndPaddock_Data: _xlfn.LAMBDA(_xlfn.MAKEARRAY(3, 2, _xlfn.LAMBDA(_xlpm.r,_xlpm.c, INDEX({"Climate zone","EFPRP";"Wet climate zone",0.006;"Dry climate zone",0.002}, _xlpm.r, _xlpm.c))))
Name Common_SourceData.Common_SourceData_EFPastureRangeAndPaddock_NIRReference: _xlfn.LAMBDA("")
Name Common_SourceData.Common_SourceData_EFPastureRangeAndPaddock_Source: _xlfn.LAMBDA("VEERG 2026: Table A.2.2.2")
Name Common_SourceData.Common_SourceData_EFPastureRangeAndPaddock_Title: _xlfn.LAMBDA("Emission factor for urine and dung deposited on pasture, range or paddock")
Name Common_SourceData.Common_SourceData_EFPastureRangeAndPaddock_Unit: _xlfn.LAMBDA("kg N2O - N / kg N")
Name Common_SourceData.Common_SourceData_EFPastureRangeAndPaddock_Variation: _xlfn.LAMBDA("VARIATION FROM SOURCE DATA: Changed 'Dry climate zones' to singular 'Dry climate zone' to aid lookup.")

Sheet Home
A1: Home

Sheet Results
A1: #VALUE! | C1: 4.5 Manure management: Swine: Results
A3: =HYPERLINK("#'Home'!A1", "Home") -> Home
A4: =HYPERLINK("#'Results'!A1", "Results") -> Results | D4: Emissions breakdown
A6: INPUTS | D6: Scope 1 source | E6: GHG emissions method 1 | F6: GHG emissions method 2 | G6: GHG Unit | H6: CO2-e emissions method 1 | I6: CO2-e emissions method 2 | J6: CO2-e unit
A7: =HYPERLINK("#'Input - Site'!A1", "Site") -> Site | D7: 4.2.1.1-2 Manure methane | E7: ='4.5.1.1-2 Methane'!$D$276 -> 365 | F7: ='4.5.1.1-2 Methane'!O276 -> 0 | G7: t CH4 | H7: ='4.5.1.1-2 Methane'!#REF! -> #REF! | I7: ='4.5.1.1-2 Methane'!$O$281 -> 0 | J7: t CO2e
A8: =HYPERLINK("#'Input - Swine'!A1", "Swine") -> Swine | D8: 4.2.1.3-4 Soil direct N2O | E8: ='4.5.1.3-4 Direct N20'!$E$227 -> Drylot (feed pad) | F8: ='4.5.1.3-4 Direct N20'!$O$259 -> N/A | G8: t N2O | H8: ='4.5.1.3-4 Direct N20'!$E$232 -> Digester / covered lagoons | I8: ='4.5.1.3-4 Direct N20'!$O$264 -> Digester / covered lagoons | J8: t CO2e
D9: 4.2.1.5-6 Soil atmospheric deposition | E9: ='4.5.1.5-6 Atmos Dep'!$E$35 -> Deep litter | F9: ='4.5.1.5-6 Atmos Dep'!$O$35 -> Deep litter | G9: ='4.5.1.5-6 Atmos Dep'!$F$35 -> 27.40128 | H9: ='4.5.1.5-6 Atmos Dep'!$E$40 -> Pit storage | I9: ='4.5.1.5-6 Atmos Dep'!$O$40 -> Pit storage | J9: t CO2e
A10: CALCULATIONS | D10: 4.2.1.7-8 Soil leaching and runoff | E10: ='4.5.1.7-8 Soil leach runoff'!$E$36 -> 0 | F10: ='4.5.1.7-8 Soil leach runoff'!$N$36 -> 0 | G10: ='4.5.1.7-8 Soil leach runoff'!$F$36 -> 0 | H10: ='4.5.1.7-8 Soil leach runoff'!$E$41 -> emission factor for leaching and runoff (kg N2O-N/kg N) | I10: ='4.5.1.7-8 Soil leach runoff'!$N$41 -> 0 | J10: t CO2e
A11: =HYPERLINK("#'4.2.1.1-2 Methane'!A1", "4.2.1.1-2 Methane") -> 4.2.1.1-2 Methane | D11: Total | H11: =SUM(H7:H10) -> #REF! | I11: =SUM(I7:I10) -> 0 | J11: t CO2e
A12: =HYPERLINK("#'4.2.1.3-4 Soil direct N2O'!A1", "4.2.1.3-4 Soil direct N2O") -> 4.2.1.3-4 Soil direct N2O
A13: =HYPERLINK("#'4.2.1.5-6 Soil Atmos Dep'!A1", "4.2.1.5-6 Soil atm. deposition") -> 4.2.1.5-6 Soil atm. deposition
A14: =HYPERLINK("#'4.2.1.7-8 Soil leach runoff'!A1", "4.2.1.7-8 Soil leach & runoff") -> 4.2.1.7-8 Soil leach & runoff
A16: APPENDICES
A17: =HYPERLINK("#'Constants - Swine'!A1", "Constants - Swine") -> Constants - Swine
A18: =HYPERLINK("#'Constants - Livestock'!A1", "Constants - Livestock") -> Constants - Livestock
A19: =HYPERLINK("#'Constants - Common'!A1", "Constants - Common") -> Constants - Common
A20: =HYPERLINK("#'Acknowledgements'!A1", "Acknowledgements") -> Acknowledgements

Sheet Input - Site
A1: #VALUE! | C1: Input - Site
A3: =HYPERLINK("#'Home'!A1", "Home") -> Home
A4: =HYPERLINK("#'Results'!A1", "Results") -> Results
D5: Your business
A6: INPUTS
A7: =HYPERLINK("#'Input - Site'!A1", "Site") -> Site | D7: Farm name | E7: Test Farms
A8: =HYPERLINK("#'Input - Swine'!A1", "Swine") -> Swine | D8: Reporting entity name | E8: Test Farms Pty Ltd
A10: CALCULATIONS | D10: 💡An 'Emissions accounting period' is a 12 month period where the business can report on the emissions, and is typically the same as the business' financial accounting period.
A11: =HYPERLINK("#'4.2.1.1-2 Methane'!A1", "4.2.1.1-2 Methane") -> 4.2.1.1-2 Methane
A12: =HYPERLINK("#'4.2.1.3-4 Soil direct N2O'!A1", "4.2.1.3-4 Soil direct N2O") -> 4.2.1.3-4 Soil direct N2O | D12: Emissions calculation period start date | E12: 45292 | F12: ← DD/MM/YYYY or DD Month YYYY
A13: =HYPERLINK("#'4.2.1.5-6 Soil Atmos Dep'!A1", "4.2.1.5-6 Soil atm. deposition") -> 4.2.1.5-6 Soil atm. deposition | D13: Emissions calculation period end date | E13: =DATE(YEAR(E12)+1,MONTH(E12),DAY(E12))-1 -> 45657 | F13: ← Automatically calculated, 12 months after start date
A14: =HYPERLINK("#'4.2.1.7-8 Soil leach runoff'!A1", "4.2.1.7-8 Soil leach & runoff") -> 4.2.1.7-8 Soil leach & runoff
A16: APPENDICES | D16: Location and climate
A17: =HYPERLINK("#'Constants - Swine'!A1", "Constants - Swine") -> Constants - Swine
A18: =HYPERLINK("#'Constants - Livestock'!A1", "Constants - Livestock") -> Constants - Livestock | D18: Location information is used to reference some region and climate-specific emission factors
A19: =HYPERLINK("#'Constants - Common'!A1", "Constants - Common") -> Constants - Common | D19: Tip: Use the web-based GAF Location Helper tool to easily get region and climate information. You will need an internet connection to use the GAF Location Helper.
A20: =HYPERLINK("#'Acknowledgements'!A1", "Acknowledgements") -> Acknowledgements
D21: State | E21: Western Australia | F21: ← Please select
D22: Region (ABS Statistical area level 4) if state is WA | E22: Western Australia - Outback (South) | F22: ← Please select
D23: Leaching zone | E23: NO - Not in leaching zone | F23: ← Please select
D24: Elevation | E24: 307.7 | F24: Meters
D25: Average temperature for reporting period | E25: 18 | F25: Degrees celsius
D26: Total rainfall for reporting period | E26: 601 | F26: Millimetres
D27: Potential evapotranspiration for reporting period | E27: 1326 | F27: Millimetres
D28: Number of frost days for reporting period | E28: 7 | F28: Days
D29: MAP:PET ratio | E29: =E26/E27 -> 0.45324284
D30: Rainfall zone | E30: =Common_InputFunctions.Utility_LookupItemFromMinMax(E26,Table_SourceData_RainfallZones[Min rainfall],Table_SourceData_RainfallZones[Max rainfall],Table_SourceData_RainfallZones[Rainfall Zone]) -> High rainfall
D31: Climate zone | E31: =Common_InputFunctions.Utility_GetClimateZone(E25,E26,E28,E24,E29,Table_SourceData_ClimateZones[Min temp],Table_SourceData_ClimateZones[Max temp],Table_SourceData_ClimateZones[Min rainfall],Table_SourceData_ClimateZones[Max rainfall],Table_SourceData_ClimateZones[Min frost days],Table_SourceData_ClimateZones[Max frost days],Table_SourceData_ClimateZones[Min elevation],Table_SourceData_ClimateZones[Max elevation],Table_SourceData_ClimateZones[Min MAP:PET],Table_SourceData_ClimateZones[Max MAP:PET],Table_SourceData_ClimateZones[Climate zone]) -> Warm temperate dry
D32: Wet or dry climate zone | E32: =Common_InputFunctions.Utility_LookupValueInTable($E$31,Table_SourceData_WetDryZones[Climate zone],Table_SourceData_WetDryZones[Wet or Dry Zone]) -> Dry climate zone
D33: Temperature zone | E33: =Common_InputFunctions.Utility_LookupItemFromMinMax(E25,Table_SourceData_TemperatureZones[Min MAT],Table_SourceData_TemperatureZones[Max MAT],Table_SourceData_TemperatureZones[Temperature Zone]) -> Temperate

Sheet Input - Swine
A1: #VALUE! | C1: Input -Swine
A3: =HYPERLINK("#'Home'!A1", "Home") -> Home
A4: =HYPERLINK("#'Results'!A1", "Results") -> Results
D5: This tool demostrates inputs for one production system.
A6: INPUTS | D6: Because the type of production system is not relevant in emissions calculations, you can select any kind.
A7: =HYPERLINK("#'Input - Site'!A1", "Site") -> Site
A8: =HYPERLINK("#'Input - Swine'!A1", "Swine") -> Swine
E9: Boars | F9: Sows | G9: Gilts | H9: Others
A10: CALCULATIONS | D10: ="Average duration of stay between " & TEXT('Input - Site'!$E$12, "dd mmm yy") & " and " & TEXT('Input - Site'!$E$13, "dd mmm yy") -> Average duration of stay between 01 Jan 24 and 31 Dec 24 | E10: 365 | F10: 365 | G10: 365 | H10: 365 | I10: Days
A11: =HYPERLINK("#'4.2.1.1-2 Methane'!A1", "4.2.1.1-2 Methane") -> 4.2.1.1-2 Methane | D11: ="Average number of head between " & TEXT('Input - Site'!$E$12, "dd mmm yy") & " and " & TEXT('Input - Site'!$E$13, "dd mmm yy") -> Average number of head between 01 Jan 24 and 31 Dec 24 | E11: 100 | F11: 100 | G11: 100 | H11: 100 | I11: Head
A12: =HYPERLINK("#'4.2.1.3-4 Soil direct N2O'!A1", "4.2.1.3-4 Soil direct N2O") -> 4.2.1.3-4 Soil direct N2O
A13: =HYPERLINK("#'4.2.1.5-6 Soil Atmos Dep'!A1", "4.2.1.5-6 Soil atm. deposition") -> 4.2.1.5-6 Soil atm. deposition | D13: Manure production
A14: =HYPERLINK("#'4.2.1.7-8 Soil leach runoff'!A1", "4.2.1.7-8 Soil leach & runoff") -> 4.2.1.7-8 Soil leach & runoff
D15: Method 1 default values (Do not edit) | E15: Boars | F15: Sows | G15: Gilts | H15: Others
A16: APPENDICES | D16: Volatile solids produced per head per day | E16: {=Common_InputFunctions.Utility_LookupValueInTableNumber(E15, Table_SourceData_Swine_VolatileSolids[Class], Table_SourceData_Swine_VolatileSolids[VSj])} -> 0.4 | F16: {=Common_InputFunctions.Utility_LookupValueInTableNumber(F15, Table_SourceData_Swine_VolatileSolids[Class], Table_SourceData_Swine_VolatileSolids[VSj])} -> 0.46 | G16: {=Common_InputFunctions.Utility_LookupValueInTableNumber(G15, Table_SourceData_Swine_VolatileSolids[Class], Table_SourceData_Swine_VolatileSolids[VSj])} -> 0.55 | H16: {=Common_InputFunctions.Utility_LookupValueInTableNumber(H15, Table_SourceData_Swine_VolatileSolids[Class], Table_SourceData_Swine_VolatileSolids[VSj])} -> 0.39 | I16: kg/head/day
A17: =HYPERLINK("#'Constants - Swine'!A1", "Constants - Swine") -> Constants - Swine | D17: Nitrogen produced in swine waste per head per day | I17: kg N/head/day
A18: =HYPERLINK("#'Constants - Livestock'!A1", "Constants - Livestock") -> Constants - Livestock
A19: =HYPERLINK("#'Constants - Common'!A1", "Constants - Common") -> Constants - Common | D19: Method 2 custom values (Edit if known) | E19: Boars | F19: Sows | G19: Gilts | H19: Others
A20: =HYPERLINK("#'Acknowledgements'!A1", "Acknowledgements") -> Acknowledgements | D20: Volatile solids produced per head per day | E20: {=Common_InputFunctions.Utility_LookupValueInTableNumber(E19, Table_SourceData_Swine_VolatileSolids[Class], Table_SourceData_Swine_VolatileSolids[VSj])} -> 0.4 | F20: {=Common_InputFunctions.Utility_LookupValueInTableNumber(F19, Table_SourceData_Swine_VolatileSolids[Class], Table_SourceData_Swine_VolatileSolids[VSj])} -> 0.46 | G20: {=Common_InputFunctions.Utility_LookupValueInTableNumber(G19, Table_SourceData_Swine_VolatileSolids[Class], Table_SourceData_Swine_VolatileSolids[VSj])} -> 0.55 | H20: {=Common_InputFunctions.Utility_LookupValueInTableNumber(H19, Table_SourceData_Swine_VolatileSolids[Class], Table_SourceData_Swine_VolatileSolids[VSj])} -> 0.39 | I20: kg/head/day
D21: Nitrogen produced in swine waste per head per day | I21: kg N/head/day
D24: Manure management systems
D26: Production system | E26: Conventional housing | F26: ← Please select
D28: Stage 1 MMS | E28: Boars | F28: Sows | G28: Gilts | H28: Others
D29: ='Constants - Swine'!$G$41 -> Anaerobic lagoon | E29: 0.15 | F29: 0.15 | G29: 0.15 | H29: 0.15 | I29: Percent
D30: ='Constants - Swine'!$G$42 -> Drylot (feed pad) | E30: 0.15 | F30: 0.15 | G30: 0.15 | H30: 0.15 | I30: Percent
D31: ='Constants - Swine'!$G$43 -> Digester / covered lagoons | E31: 0.15 | F31: 0.15 | G31: 0.15 | H31: 0.15 | I31: Percent
D32: ='Constants - Swine'!$G$44 -> Deep litter | E32: 0.15 | F32: 0.15 | G32: 0.15 | H32: 0.15 | I32: Percent
D33: ='Constants - Swine'!$G$45 -> Pit storage | E33: 0.15 | F33: 0.15 | G33: 0.15 | H33: 0.15 | I33: Percent
D34: Solid storage | E34: 0.25 | F34: 0.25 | G34: 0.25 | H34: 0.25 | I34: Percent
D35: Total sent to all MMS (Must equal 100%) | E35: =SUM(E29,E30,E31,E32,E33,E34) -> 1 | F35: =SUM(F29,F30,F31,F32,F33,F34) -> 1 | G35: =SUM(G29,G30,G31,G32,G33,G34) -> 1 | H35: =SUM(H29,H30,H31,H32,H33,H34) -> 1
D37: ▼
D38: Solid separation from stage 1 MMS | E38: Were solids separated? (select) | F38: Percent separated (Method 1) | G38: Percent separated (Method 2)
D39: ="Solids separated from " & $D$29 -> Solids separated from Anaerobic lagoon | E39: Yes | F39: 0.2 | G39: 0.2
D40: ="Solids separated from " & $D$30 -> Solids separated from Drylot (feed pad) | E40: Yes | F40: 0.2 | G40: 0.2
D41: ="Solids separated from " & $D$31 -> Solids separated from Digester / covered lagoons | E41: Yes | F41: 0.2 | G41: 0.2
D42: ="Solids separated from " & $D$32 -> Solids separated from Deep litter | E42: Yes | F42: 0.2 | G42: 0.2
D43: ="Solids separated from " & $D$33 -> Solids separated from Pit storage | E43: Yes | F43: 0.2 | G43: 0.2
D45: ▼
D46: Stage 2 MMS | E46: Boars | F46: Sows | G46: Gilts | H46: Others | I46: ► | J46: Destination after stage 2 MMS (Percent)
D47: ="Stage 2 MMS From " & $D$29 -> Stage 2 MMS From Anaerobic lagoon | E47: =IF(SUM(E29:K29)>0,"Manure was sent to this MMS, please complete this section.","No manure was sent to this MMS. Leave this section blank.") -> Manure was sent to this MMS, please complete this section. | J47: Sold | K47: Fert for own farm (eg crop) | L47: Direct application to soil
...

Sheet 4.5.1.1-2 Methane
A1: #VALUE! | C1: 4.5.1.1-2 Manure Methane
A3: =HYPERLINK("#'Home'!A1", "Home") -> Home | D3: Method 1 | N3: Method 2
A4: =HYPERLINK("#'Results'!A1", "Results") -> Results
D5: {=ManureManagement_Swine_Methane.VEERG_4_5_1_1__4_FractionVolatileSolidsPrimarySystem_Title()} -> Fraction of volatile solids in each primary system other than solid storage
A6: INPUTS | D6: {=ManureManagement_Swine_Methane.VEERG_4_5_1_1__4_FractionVolatileSolidsPrimarySystem_Source()} -> VEERG 2026: 4.5.1.1, Equation (4)
A7: =HYPERLINK("#'Input - Site'!A1", "Site") -> Site | D7: Function name | E7: {=Common_InputFunctions.Utility_DisplayFunctionName($E$40)} -> =ManureManagement_Swine_Methane.VEERG_4_5_1_1__4_FractionVolatileSolidsPrimarySystem
A8: =HYPERLINK("#'Input - Swine'!A1", "Swine") -> Swine
A10: CALCULATIONS | D10: Variable | E10: {=ManureManagement_Swine_Methane.VEERG_4_5_1_1__4_FractionVolatileSolidsPrimarySystem_Variable()} -> FVSjmT1 | G10: Inconsistencies - 'primary system' vs 'stage 1'
A11: =HYPERLINK("#'4.2.1.1-2 Methane'!A1", "4.2.1.1-2 Methane") -> 4.2.1.1-2 Methane | D11: Unit | E11: {=ManureManagement_Swine_Methane.VEERG_4_5_1_1__4_FractionVolatileSolidsPrimarySystem_Unit()} -> fraction
A12: =HYPERLINK("#'4.2.1.3-4 Soil direct N2O'!A1", "4.2.1.3-4 Soil direct N2O") -> 4.2.1.3-4 Soil direct N2O
A13: =HYPERLINK("#'4.2.1.5-6 Soil Atmos Dep'!A1", "4.2.1.5-6 Soil atm. deposition") -> 4.2.1.5-6 Soil atm. deposition | D13: {=ManureManagement_Swine_Methane.VEERG_4_5_1_1__4_FractionVolatileSolidsPrimarySystem_Arguments()} -> MMSjmT1 | E13: fraction of manure to each primary MMS for each class prior to solid separation : fraction | H13: ="See " & $D$16 -> See Table_MMS_j_m_T-1 | I13: If this is directly related to equation 5, the mms numbers should be the same eg 1,7,9 (and probably 8,)
A14: =HYPERLINK("#'4.2.1.7-8 Soil leach runoff'!A1", "4.2.1.7-8 Soil leach & runoff") -> 4.2.1.7-8 Soil leach & runoff | D14: SSm | E14: fraction of volatile solids separated to solid storage for each MMS : fraction | H14: ="See " & $D$26 -> See M1_Table_SS_m | I14: SSm should be SSjm
A16: APPENDICES | D16: Table_MMS_j_m_T-1
A17: =HYPERLINK("#'Constants - Swine'!A1", "Constants - Swine") -> Constants - Swine | D17: Fraction VS sent to MMS other than solid storage in stage 1
A18: =HYPERLINK("#'Constants - Livestock'!A1", "Constants - Livestock") -> Constants - Livestock | E18: Boars | F18: Sows | G18: Gilts | H18: Others
A19: =HYPERLINK("#'Constants - Common'!A1", "Constants - Common") -> Constants - Common | D19: Stage 1 management | E19: MMSj=1,m=1,7,9,8,13,T=1 | F19: MMSj=2,m=1,7,9,8,13,T=1 | G19: MMSj=3,m=1,7,9,8,13,T=1 | H19: MMSj=4,m=1,7,9,8,13,T=1
A20: =HYPERLINK("#'Acknowledgements'!A1", "Acknowledgements") -> Acknowledgements | D20: ='Input - Swine'!$D$29 -> Anaerobic lagoon | E20: ='Input - Swine'!E29 -> 0.15 | F20: ='Input - Swine'!F29 -> 0.15 | G20: ='Input - Swine'!G29 -> 0.15 | H20: ='Input - Swine'!H29 -> 0.15 | I20: Fraction
D21: ='Input - Swine'!$D$30 -> Drylot (feed pad) | E21: ='Input - Swine'!E30 -> 0.15 | F21: ='Input - Swine'!F30 -> 0.15 | G21: ='Input - Swine'!G30 -> 0.15 | H21: ='Input - Swine'!H30 -> 0.15 | I21: Fraction
D22: ='Input - Swine'!$D$31 -> Digester / covered lagoons | E22: ='Input - Swine'!E31 -> 0.15 | F22: ='Input - Swine'!F31 -> 0.15 | G22: ='Input - Swine'!G31 -> 0.15 | H22: ='Input - Swine'!H31 -> 0.15 | I22: Fraction
D23: ='Input - Swine'!$D$32 -> Deep litter | E23: ='Input - Swine'!E32 -> 0.15 | F23: ='Input - Swine'!F32 -> 0.15 | G23: ='Input - Swine'!G32 -> 0.15 | H23: ='Input - Swine'!H32 -> 0.15 | I23: Fraction
D24: ='Input - Swine'!$D$33 -> Pit storage | E24: ='Input - Swine'!E33 -> 0.15 | F24: ='Input - Swine'!F33 -> 0.15 | G24: ='Input - Swine'!G33 -> 0.15 | H24: ='Input - Swine'!H33 -> 0.15 | I24: Fraction
D26: M1_Table_SS_m | N26: M2_Table_SS_m-1-7-9
D27: Fraction separated solids sent from MMS other than solid storage to solid storage in stage 1 (Method 1) | N27: Fraction separated solids sent from MMS other than solid storage to solid storage in stage 1 (Method 2)
E28: Boars | F28: Sows | G28: Gilts | H28: Others | O28: Boars | P28: Sows | Q28: Gilts | R28: Others
D29: Stage 1 management | E29: SSj=1m=1,7,9 | F29: SSj=2m=1,7,9 | G29: SSj=3m=1,7,9 | H29: SSj=4m=1,7,9 | N29: Stage 1 management | O29: SSj=1m=1,7,9 | P29: SSj=2m=1,7,9 | Q29: SSj=3m=1,7,9 | R29: SSj=4m=1,7,9
D30: ='Input - Swine'!$D$29 -> Anaerobic lagoon | E30: ='Input - Swine'!$F$39 -> 0.2 | F30: ='Input - Swine'!$F$39 -> 0.2 | G30: ='Input - Swine'!$F$39 -> 0.2 | H30: ='Input - Swine'!$F$39 -> 0.2 | I30: Fraction | N30: ='Input - Swine'!$D$29 -> Anaerobic lagoon | O30: ='Input - Swine'!$G$39 -> 0.2 | P30: ='Input - Swine'!$G$39 -> 0.2 | Q30: ='Input - Swine'!$G$39 -> 0.2 | R30: ='Input - Swine'!$G$39 -> 0.2 | S30: Fraction
D31: ='Input - Swine'!$D$30 -> Drylot (feed pad) | E31: ='Input - Swine'!$F$40 -> 0.2 | F31: ='Input - Swine'!$F$40 -> 0.2 | G31: ='Input - Swine'!$F$40 -> 0.2 | H31: ='Input - Swine'!$F$40 -> 0.2 | I31: Fraction | N31: ='Input - Swine'!$D$30 -> Drylot (feed pad) | O31: ='Input - Swine'!$G$40 -> 0.2 | P31: ='Input - Swine'!$G$40 -> 0.2 | Q31: ='Input - Swine'!$G$40 -> 0.2 | R31: ='Input - Swine'!$G$40 -> 0.2 | S31: Fraction
D32: ='Input - Swine'!$D$31 -> Digester / covered lagoons | E32: ='Input - Swine'!$F$41 -> 0.2 | F32: ='Input - Swine'!$F$41 -> 0.2 | G32: ='Input - Swine'!$F$41 -> 0.2 | H32: ='Input - Swine'!$F$41 -> 0.2 | I32: Fraction | N32: ='Input - Swine'!$D$31 -> Digester / covered lagoons | O32: ='Input - Swine'!$G$41 -> 0.2 | P32: ='Input - Swine'!$G$41 -> 0.2 | Q32: ='Input - Swine'!$G$41 -> 0.2 | R32: ='Input - Swine'!$G$41 -> 0.2 | S32: Fraction
D33: ='Input - Swine'!$D$32 -> Deep litter | E33: ='Input - Swine'!$F$42 -> 0.2 | F33: ='Input - Swine'!$F$42 -> 0.2 | G33: ='Input - Swine'!$F$42 -> 0.2 | H33: ='Input - Swine'!$F$42 -> 0.2 | I33: Fraction | N33: ='Input - Swine'!$D$32 -> Deep litter | O33: ='Input - Swine'!$G$42 -> 0.2 | P33: ='Input - Swine'!$G$42 -> 0.2 | Q33: ='Input - Swine'!$G$42 -> 0.2 | R33: ='Input - Swine'!$G$42 -> 0.2 | S33: Fraction
D34: ='Input - Swine'!$D$33 -> Pit storage | E34: ='Input - Swine'!$F$43 -> 0.2 | F34: ='Input - Swine'!$F$43 -> 0.2 | G34: ='Input - Swine'!$F$43 -> 0.2 | H34: ='Input - Swine'!$F$43 -> 0.2 | I34: Fraction | N34: ='Input - Swine'!$D$33 -> Pit storage | O34: ='Input - Swine'!$G$43 -> 0.2 | P34: ='Input - Swine'!$G$43 -> 0.2 | Q34: ='Input - Swine'!$G$43 -> 0.2 | R34: ='Input - Swine'!$G$43 -> 0.2 | S34: Fraction
D36: M1_Table_FVS_j_m_T-1 | N36: M2_Table_FVS_j_m_T-1
D37: Fraction VS in MMS other than solid storage in stage 1 (Method 1) | N37: Fraction VS in MMS other than solid storage in stage 1 (Method 2)
E38: Boars | F38: Sows | G38: Gilts | H38: Others | O38: Boars | P38: Sows | Q38: Gilts | R38: Others
D39: Stage 1 management | E39: FVSj,m=1,7,9,T=1 | F39: FVSj,m=1,7,9,T=1 | G39: FVSj,m=1,7,9,T=1 | H39: FVSj,m=1,7,9,T=1 | N39: Stage 1 management | O39: FVSj,m=1,7,9,T=1 | P39: FVSj,m=1,7,9,T=1 | Q39: FVSj,m=1,7,9,T=1 | R39: FVSj,m=1,7,9,T=1
D40: ='Input - Swine'!$D$29 -> Anaerobic lagoon | E40: {=ManureManagement_Swine_Methane.VEERG_4_5_1_1__4_FractionVolatileSolidsPrimarySystem(E20,E30)} -> 0.12 | F40: {=ManureManagement_Swine_Methane.VEERG_4_5_1_1__4_FractionVolatileSolidsPrimarySystem(F20,F30)} -> 0.12 | G40: {=ManureManagement_Swine_Methane.VEERG_4_5_1_1__4_FractionVolatileSolidsPrimarySystem(G20,G30)} -> 0.12 | H40: {=ManureManagement_Swine_Methane.VEERG_4_5_1_1__4_FractionVolatileSolidsPrimarySystem(H20,H30)} -> 0.12 | I40: =$E$11 -> fraction | N40: ='Input - Swine'!$D$29 -> Anaerobic lagoon | O40: {=ManureManagement_Swine_Methane.VEERG_4_5_1_1__4_FractionVolatileSolidsPrimarySystem(E20,O30)} -> 0.12 | P40: {=ManureManagement_Swine_Methane.VEERG_4_5_1_1__4_FractionVolatileSolidsPrimarySystem(F20,P30)} -> 0.12 | Q40: {=ManureManagement_Swine_Methane.VEERG_4_5_1_1__4_FractionVolatileSolidsPrimarySystem(G20,Q30)} -> 0.12 | R40: {=ManureManagement_Swine_Methane.VEERG_4_5_1_1__4_FractionVolatileSolidsPrimarySystem(H20,R30)} -> 0.12 | S40: =$E$11 -> fraction
D41: ='Input - Swine'!$D$30 -> Drylot (feed pad) | E41: {=ManureManagement_Swine_Methane.VEERG_4_5_1_1__4_FractionVolatileSolidsPrimarySystem(E21,E31)} -> 0.12 | F41: {=ManureManagement_Swine_Methane.VEERG_4_5_1_1__4_FractionVolatileSolidsPrimarySystem(F21,F31)} -> 0.12 | G41: {=ManureManagement_Swine_Methane.VEERG_4_5_1_1__4_FractionVolatileSolidsPrimarySystem(G21,G31)} -> 0.12 | H41: {=ManureManagement_Swine_Methane.VEERG_4_5_1_1__4_FractionVolatileSolidsPrimarySystem(H21,H31)} -> 0.12 | I41: =$E$11 -> fraction | N41: ='Input - Swine'!$D$30 -> Drylot (feed pad) | O41: {=ManureManagement_Swine_Methane.VEERG_4_5_1_1__4_FractionVolatileSolidsPrimarySystem(E21,O31)} -> 0.12 | P41: {=ManureManagement_Swine_Methane.VEERG_4_5_1_1__4_FractionVolatileSolidsPrimarySystem(F21,P31)} -> 0.12 | Q41: {=ManureManagement_Swine_Methane.VEERG_4_5_1_1__4_FractionVolatileSolidsPrimarySystem(G21,Q31)} -> 0.12 | R41: {=ManureManagement_Swine_Methane.VEERG_4_5_1_1__4_FractionVolatileSolidsPrimarySystem(H21,R31)} -> 0.12 | S41: =$E$11 -> fraction
D42: ='Input - Swine'!$D$31 -> Digester / covered lagoons | E42: {=ManureManagement_Swine_Methane.VEERG_4_5_1_1__4_FractionVolatileSolidsPrimarySystem(E22,E32)} -> 0.12 | F42: {=ManureManagement_Swine_Methane.VEERG_4_5_1_1__4_FractionVolatileSolidsPrimarySystem(F22,F32)} -> 0.12 | G42: {=ManureManagement_Swine_Methane.VEERG_4_5_1_1__4_FractionVolatileSolidsPrimarySystem(G22,G32)} -> 0.12 | H42: {=ManureManagement_Swine_Methane.VEERG_4_5_1_1__4_FractionVolatileSolidsPrimarySystem(H22,H32)} -> 0.12 | I42: =$E$11 -> fraction | N42: ='Input - Swine'!$D$31 -> Digester / covered lagoons | O42: {=ManureManagement_Swine_Methane.VEERG_4_5_1_1__4_FractionVolatileSolidsPrimarySystem(E22,O32)} -> 0.12 | P42: {=ManureManagement_Swine_Methane.VEERG_4_5_1_1__4_FractionVolatileSolidsPrimarySystem(F22,P32)} -> 0.12 | Q42: {=ManureManagement_Swine_Methane.VEERG_4_5_1_1__4_FractionVolatileSolidsPrimarySystem(G22,Q32)} -> 0.12 | R42: {=ManureManagement_Swine_Methane.VEERG_4_5_1_1__4_FractionVolatileSolidsPrimarySystem(H22,R32)} -> 0.12 | S42: =$E$11 -> fraction
D43: ='Input - Swine'!$D$32 -> Deep litter | E43: {=ManureManagement_Swine_Methane.VEERG_4_5_1_1__4_FractionVolatileSolidsPrimarySystem(E23,E33)} -> 0.12 | F43: {=ManureManagement_Swine_Methane.VEERG_4_5_1_1__4_FractionVolatileSolidsPrimarySystem(F23,F33)} -> 0.12 | G43: {=ManureManagement_Swine_Methane.VEERG_4_5_1_1__4_FractionVolatileSolidsPrimarySystem(G23,G33)} -> 0.12 | H43: {=ManureManagement_Swine_Methane.VEERG_4_5_1_1__4_FractionVolatileSolidsPrimarySystem(H23,H33)} -> 0.12 | I43: =$E$11 -> fraction | N43: ='Input - Swine'!$D$32 -> Deep litter | O43: {=ManureManagement_Swine_Methane.VEERG_4_5_1_1__4_FractionVolatileSolidsPrimarySystem(E23,O33)} -> 0.12 | P43: {=ManureManagement_Swine_Methane.VEERG_4_5_1_1__4_FractionVolatileSolidsPrimarySystem(F23,P33)} -> 0.12 | Q43: {=ManureManagement_Swine_Methane.VEERG_4_5_1_1__4_FractionVolatileSolidsPrimarySystem(G23,Q33)} -> 0.12 | R43: {=ManureManagement_Swine_Methane.VEERG_4_5_1_1__4_FractionVolatileSolidsPrimarySystem(H23,R33)} -> 0.12 | S43: =$E$11 -> fraction
D44: ='Input - Swine'!$D$33 -> Pit storage | E44: {=ManureManagement_Swine_Methane.VEERG_4_5_1_1__4_FractionVolatileSolidsPrimarySystem(E24,E34)} -> 0.12 | F44: {=ManureManagement_Swine_Methane.VEERG_4_5_1_1__4_FractionVolatileSolidsPrimarySystem(F24,F34)} -> 0.12 | G44: {=ManureManagement_Swine_Methane.VEERG_4_5_1_1__4_FractionVolatileSolidsPrimarySystem(G24,G34)} -> 0.12 | H44: {=ManureManagement_Swine_Methane.VEERG_4_5_1_1__4_FractionVolatileSolidsPrimarySystem(H24,H34)} -> 0.12 | I44: =$E$11 -> fraction | N44: ='Input - Swine'!$D$33 -> Pit storage | O44: {=ManureManagement_Swine_Methane.VEERG_4_5_1_1__4_FractionVolatileSolidsPrimarySystem(E24,O34)} -> 0.12 | P44: {=ManureManagement_Swine_Methane.VEERG_4_5_1_1__4_FractionVolatileSolidsPrimarySystem(F24,P34)} -> 0.12 | Q44: {=ManureManagement_Swine_Methane.VEERG_4_5_1_1__4_FractionVolatileSolidsPrimarySystem(G24,Q34)} -> 0.12 | R44: {=ManureManagement_Swine_Methane.VEERG_4_5_1_1__4_FractionVolatileSolidsPrimarySystem(H24,R34)} -> 0.12 | S44: =$E$11 -> fraction
D48: {=ManureManagement_Swine_Methane.VEERG_4_5_1_1__5_FractionVolatileSolidsSolidStorage_Title()} -> Fraction of volatile solids in solid storage | F48: Rename to 'Fraction of volatile solids in primary system in solid storage'
...

Sheet 4.5.1.3-4 Direct N20
A1: #VALUE! | C1: 4.5.1.3-4 Manure Direct N2O
A3: =HYPERLINK("#'Home'!A1", "Home") -> Home | D3: Method 1 | N3: Method 2
A4: =HYPERLINK("#'Results'!A1", "Results") -> Results
D5: {=MMS_Swine_N2ODirect_Equations.VEERG_4_5_1_3__5_AnnualNitrogenExcretion_Title()} -> Annual nitrogen excretion from each swine group
A6: INPUTS | D6: {=MMS_Swine_N2ODirect_Equations.VEERG_4_5_1_3__5_AnnualNitrogenExcretion_Source()} -> VEERG 2026: 4.5.1.3, Equation (5)
A7: =HYPERLINK("#'Input - Site'!A1", "Site") -> Site | D7: Function name | E7: {=Common_InputFunctions.Utility_DisplayFunctionName($E$35)} -> =MMS_Swine_N2ODirect_Equations.VEERG_4_5_1_3__5_AnnualNitrogenExcretion
A8: =HYPERLINK("#'Input - Swine'!A1", "Swine") -> Swine
A10: CALCULATIONS | D10: Variable | E10: {=MMS_Swine_N2ODirect_Equations.VEERG_4_5_1_3__5_AnnualNitrogenExcretion_Variable()} -> AE_j
A11: =HYPERLINK("#'4.2.1.1-2 Methane'!A1", "4.2.1.1-2 Methane") -> 4.2.1.1-2 Methane | D11: Unit | E11: {=MMS_Swine_N2ODirect_Equations.VEERG_4_5_1_3__5_AnnualNitrogenExcretion_Unit()} -> kg N
A12: =HYPERLINK("#'4.2.1.3-4 Soil direct N2O'!A1", "4.2.1.3-4 Soil direct N2O") -> 4.2.1.3-4 Soil direct N2O
A13: =HYPERLINK("#'4.2.1.5-6 Soil Atmos Dep'!A1", "4.2.1.5-6 Soil atm. deposition") -> 4.2.1.5-6 Soil atm. deposition | D13: {=MMS_Swine_N2ODirect_Equations.VEERG_4_5_1_3__5_AnnualNitrogenExcretion_Arguments()} -> N_j | E13: number of swine in each group (head) | H13: ="See " & D17 -> See Table_N_j
A14: =HYPERLINK("#'4.2.1.7-8 Soil leach runoff'!A1", "4.2.1.7-8 Soil leach & runoff") -> 4.2.1.7-8 Soil leach & runoff | D14: NW_j | E14: nitrogen produced in swine manure and waste feed in each class (kg N/head/day) | H14: ="See " & D22 -> See Table_NW_j
D15: D_j | E15: duration of stay of swine group (days)
A16: APPENDICES
A17: =HYPERLINK("#'Constants - Swine'!A1", "Constants - Swine") -> Constants - Swine | D17: Table_N_j
A18: =HYPERLINK("#'Constants - Livestock'!A1", "Constants - Livestock") -> Constants - Livestock | D18: Number of head for each swine class
A19: =HYPERLINK("#'Constants - Common'!A1", "Constants - Common") -> Constants - Common | D19: Boars | E19: Sows | F19: Gilts | G19: Others
A20: =HYPERLINK("#'Acknowledgements'!A1", "Acknowledgements") -> Acknowledgements | D20: ='Input - Swine'!$E$11 -> 100 | E20: ='Input - Swine'!$F$11 -> 100 | F20: ='Input - Swine'!$G$11 -> 100 | G20: ='Input - Swine'!$H$11 -> 100 | H20: Head
D22: Table_NW_j
D23: Nitrogen produced per class
D24: Boars | E24: Sows | F24: Gilts | G24: Others
D25: ='Constants - Swine'!F90 -> 0.046 | E25: ='Constants - Swine'!F91 -> 0.049 | F25: ='Constants - Swine'!$F$92 -> 0.046 | G25: ='Constants - Swine'!$F$93 -> 0.0312 | H25: Kg N/head/day
D27: Table_D_j
D28: Duration of stay for each swine class
D29: Boars | E29: Sows | F29: Gilts | G29: Others
D30: ='Input - Swine'!E10 -> 365 | E30: ='Input - Swine'!F10 -> 365 | F30: ='Input - Swine'!G10 -> 365 | G30: ='Input - Swine'!H10 -> 365 | H30: Head
D32: Table_AE_j
D33: Annual nitrogen excretion
D34: Boars | E34: Sows | F34: Gilts | G34: Others
D35: {=MMS_Swine_N2ODirect_Equations.VEERG_4_5_1_3__5_AnnualNitrogenExcretion(D20,D25,D30)} -> 1679 | E35: {=MMS_Swine_N2ODirect_Equations.VEERG_4_5_1_3__5_AnnualNitrogenExcretion(E20,E25,E30)} -> 1788.5 | F35: {=MMS_Swine_N2ODirect_Equations.VEERG_4_5_1_3__5_AnnualNitrogenExcretion(F20,F25,F30)} -> 1679 | G35: {=MMS_Swine_N2ODirect_Equations.VEERG_4_5_1_3__5_AnnualNitrogenExcretion(G20,G25,G30)} -> 1138.8 | H35: =$E$11 -> kg N
D39: {=MMS_Swine_N2ODirect_Equations.VEERG_4_5_1_3__3_FractionOfNitrogenInPrimaryMMS_Title()} -> Fraction of nitrogen in each primary MMS (excluding solid storage)
D40: {=MMS_Swine_N2ODirect_Equations.VEERG_4_5_1_3__3_FractionOfNitrogenInPrimaryMMS_Source()} -> VEERG 2026: 4.5.1.3, Equation (3)
D41: Function name | E41: {=Common_InputFunctions.Utility_DisplayFunctionName($E$71)} -> =MMS_Swine_N2ODirect_Equations.VEERG_4_5_1_3__3_FractionOfNitrogenInPrimaryMMS
D44: Variable | E44: {=MMS_Swine_N2ODirect_Equations.VEERG_4_5_1_3__3_FractionOfNitrogenInPrimaryMMS_Variable()} -> FN_jmT1
D45: Unit | E45: {=MMS_Swine_N2ODirect_Equations.VEERG_4_5_1_3__3_FractionOfNitrogenInPrimaryMMS_Unit()} -> fraction | F45: This is a duplicate of | G45: {=ManureManagement_Swine_Methane.VEERG_4_5_1_1__4_FractionVolatileSolidsPrimarySystem_Source()} -> VEERG 2026: 4.5.1.1, Equation (4)
D47: {=MMS_Swine_N2ODirect_Equations.VEERG_4_5_1_3__3_FractionOfNitrogenInPrimaryMMS_Arguments()} -> MMS_jmT1 | E47: fraction of manure in primary MMS | G47: ="See " & D50 -> See Table_MMS_j_m-1-7-9-8_T-1
D48: SN_m | E48: fraction of nitrogen separated to solid storage for each MMS | G48: ="See " & D59 -> See M1_Table_SN_m-1-7-9
D50: Table_MMS_j_m-1-7-9-8_T-1
D51: Fraction N sent to MMS other than solid storage in stage 1
D52: Stage 1 management | E52: Boars | F52: Sows | G52: Gilts | H52: Others
...

Sheet 4.5.1.5-6 Atmos Dep
A1: #VALUE! | C1: 4.5.1.5-6 Atmospheric deposition N2O
A3: =HYPERLINK("#'Home'!A1", "Home") -> Home | D3: Method 1 | N3: Method 2
A4: =HYPERLINK("#'Results'!A1", "Results") -> Results
D5: {=MMS_Swine_AtmosphericDeposition_Equations.VEERG_4_5_1_5__2_TotalNitrogenVolatilisedFromMMS_Title()} -> Total nitrogen volatilised from MMS
A6: INPUTS | D6: {=MMS_Swine_AtmosphericDeposition_Equations.VEERG_4_5_1_5__2_TotalNitrogenVolatilisedFromMMS_Source()} -> VEERG 2026: 4.5.1.1, Equation (2)
A7: =HYPERLINK("#'Input - Site'!A1", "Site") -> Site | D7: Function name | E7: {=Common_InputFunctions.Utility_DisplayFunctionName(F68)} -> =MMS_Swine_AtmosphericDeposition_Equations.VEERG_4_5_1_5__2_TotalNitrogenVolatilisedFromMMS
A8: =HYPERLINK("#'Input - Swine'!A1", "Swine") -> Swine
A10: CALCULATIONS | D10: Variable | E10: {=MMS_Swine_AtmosphericDeposition_Equations.VEERG_4_5_1_5__2_TotalNitrogenVolatilisedFromMMS_Variable()} -> MMS_ATMOS
A11: =HYPERLINK("#'4.2.1.1-2 Methane'!A1", "4.2.1.1-2 Methane") -> 4.2.1.1-2 Methane | D11: Unit | E11: {=MMS_Swine_AtmosphericDeposition_Equations.VEERG_4_5_1_5__2_TotalNitrogenVolatilisedFromMMS_Unit()} -> kg N
A12: =HYPERLINK("#'4.2.1.3-4 Soil direct N2O'!A1", "4.2.1.3-4 Soil direct N2O") -> 4.2.1.3-4 Soil direct N2O
A13: =HYPERLINK("#'4.2.1.5-6 Soil Atmos Dep'!A1", "4.2.1.5-6 Soil atm. deposition") -> 4.2.1.5-6 Soil atm. deposition | D13: {=MMS_Swine_AtmosphericDeposition_Equations.VEERG_4_5_1_5__2_TotalNitrogenVolatilisedFromMMS_Arguments()} -> MN_jmT | E13: nitrogen per swine class, MMS and treatment stage (kg N) | G13: ="See " & D16 & " and " & D26 -> See M1_Table_MN_j_m_T-1 and M1_Table_MN_j_m_T-2
A14: =HYPERLINK("#'4.2.1.7-8 Soil leach runoff'!A1", "4.2.1.7-8 Soil leach & runoff") -> 4.2.1.7-8 Soil leach & runoff | D14: FracGASMmT | E14: fraction of N volatilised in each MMS ((kg NH3-N + NOx-N)/kg N) | G14: ="See " & D55 -> See Table_FracGASM_m_t-1
A16: APPENDICES | D16: M1_Table_MN_j_m_T-1 | N16: M1_Table_MN_j_m_T-1
A17: =HYPERLINK("#'Constants - Swine'!A1", "Constants - Swine") -> Constants - Swine | D17: Nitrogen in treatment stage 1 MMS (Method 1) | N17: Nitrogen in treatment stage 1 MMS (Method 1)
A18: =HYPERLINK("#'Constants - Livestock'!A1", "Constants - Livestock") -> Constants - Livestock | D18: Stage 1 management | E18: Boars | F18: Sows | G18: Gilts | H18: Others | N18: Stage 1 management | O18: Boars | P18: Sows | Q18: Gilts | R18: Others
A19: =HYPERLINK("#'Constants - Common'!A1", "Constants - Common") -> Constants - Common | D19: ='Input - Swine'!$D$29 -> Anaerobic lagoon | E19: ='4.5.1.3-4 Direct N20'!E118 -> 201.48 | F19: ='4.5.1.3-4 Direct N20'!F118 -> 214.62 | G19: ='4.5.1.3-4 Direct N20'!G118 -> 201.48 | H19: ='4.5.1.3-4 Direct N20'!H118 -> 136.656 | I19: ='4.5.1.3-4 Direct N20'!I118 -> kg N | N19: ='Input - Swine'!$D$29 -> Anaerobic lagoon | O19: ='4.5.1.3-4 Direct N20'!O118 -> 201.48 | P19: ='4.5.1.3-4 Direct N20'!P118 -> 214.62 | Q19: ='4.5.1.3-4 Direct N20'!Q118 -> 201.48 | R19: ='4.5.1.3-4 Direct N20'!R118 -> 136.656 | S19: ='4.5.1.3-4 Direct N20'!S118 -> kg N
A20: =HYPERLINK("#'Acknowledgements'!A1", "Acknowledgements") -> Acknowledgements | D20: ='Input - Swine'!$D$30 -> Drylot (feed pad) | E20: ='4.5.1.3-4 Direct N20'!E119 -> 201.48 | F20: ='4.5.1.3-4 Direct N20'!F119 -> 214.62 | G20: ='4.5.1.3-4 Direct N20'!G119 -> 201.48 | H20: ='4.5.1.3-4 Direct N20'!H119 -> 136.656 | I20: ='4.5.1.3-4 Direct N20'!I119 -> kg N | N20: ='Input - Swine'!$D$30 -> Drylot (feed pad) | O20: ='4.5.1.3-4 Direct N20'!O119 -> 201.48 | P20: ='4.5.1.3-4 Direct N20'!P119 -> 214.62 | Q20: ='4.5.1.3-4 Direct N20'!Q119 -> 201.48 | R20: ='4.5.1.3-4 Direct N20'!R119 -> 136.656 | S20: ='4.5.1.3-4 Direct N20'!S119 -> kg N
D21: ='Input - Swine'!$D$31 -> Digester / covered lagoons | E21: ='4.5.1.3-4 Direct N20'!E120 -> 201.48 | F21: ='4.5.1.3-4 Direct N20'!F120 -> 214.62 | G21: ='4.5.1.3-4 Direct N20'!G120 -> 201.48 | H21: ='4.5.1.3-4 Direct N20'!H120 -> 136.656 | I21: ='4.5.1.3-4 Direct N20'!I120 -> kg N | N21: ='Input - Swine'!$D$31 -> Digester / covered lagoons | O21: ='4.5.1.3-4 Direct N20'!O120 -> 201.48 | P21: ='4.5.1.3-4 Direct N20'!P120 -> 214.62 | Q21: ='4.5.1.3-4 Direct N20'!Q120 -> 201.48 | R21: ='4.5.1.3-4 Direct N20'!R120 -> 136.656 | S21: ='4.5.1.3-4 Direct N20'!S120 -> kg N
D22: ='Input - Swine'!$D$32 -> Deep litter | E22: ='4.5.1.3-4 Direct N20'!E121 -> 201.48 | F22: ='4.5.1.3-4 Direct N20'!F121 -> 214.62 | G22: ='4.5.1.3-4 Direct N20'!G121 -> 201.48 | H22: ='4.5.1.3-4 Direct N20'!H121 -> 136.656 | I22: ='4.5.1.3-4 Direct N20'!I121 -> kg N | N22: ='Input - Swine'!$D$32 -> Deep litter | O22: ='4.5.1.3-4 Direct N20'!O121 -> 201.48 | P22: ='4.5.1.3-4 Direct N20'!P121 -> 214.62 | Q22: ='4.5.1.3-4 Direct N20'!Q121 -> 201.48 | R22: ='4.5.1.3-4 Direct N20'!R121 -> 136.656 | S22: ='4.5.1.3-4 Direct N20'!S121 -> kg N
D23: ='Input - Swine'!$D$33 -> Pit storage | E23: ='4.5.1.3-4 Direct N20'!E122 -> 201.48 | F23: ='4.5.1.3-4 Direct N20'!F122 -> 214.62 | G23: ='4.5.1.3-4 Direct N20'!G122 -> 201.48 | H23: ='4.5.1.3-4 Direct N20'!H122 -> 136.656 | I23: ='4.5.1.3-4 Direct N20'!I122 -> kg N | N23: ='Input - Swine'!$D$33 -> Pit storage | O23: ='4.5.1.3-4 Direct N20'!O122 -> 201.48 | P23: ='4.5.1.3-4 Direct N20'!P122 -> 214.62 | Q23: ='4.5.1.3-4 Direct N20'!Q122 -> 201.48 | R23: ='4.5.1.3-4 Direct N20'!R122 -> 136.656 | S23: ='4.5.1.3-4 Direct N20'!S122 -> kg N
D24: ='Input - Swine'!$D$34 -> Solid storage | E24: ='4.5.1.3-4 Direct N20'!E123 -> 671.6 | F24: ='4.5.1.3-4 Direct N20'!F123 -> 715.4 | G24: ='4.5.1.3-4 Direct N20'!G123 -> 671.6 | H24: ='4.5.1.3-4 Direct N20'!H123 -> 455.52 | I24: ='4.5.1.3-4 Direct N20'!I123 -> kg N | N24: ='Input - Swine'!$D$34 -> Solid storage | O24: ='4.5.1.3-4 Direct N20'!O123 -> 671.6 | P24: ='4.5.1.3-4 Direct N20'!P123 -> 715.4 | Q24: ='4.5.1.3-4 Direct N20'!Q123 -> 671.6 | R24: ='4.5.1.3-4 Direct N20'!R123 -> 455.52 | S24: ='4.5.1.3-4 Direct N20'!S123 -> kg N
D26: M1_Table_MN_j_m_T-2 | N26: M1_Table_MN_j_m_T-2
D27: Nitrogen in stage 2 MMS (Method 1) | N27: Nitrogen in stage 2 MMS (Method 1)
D28: Stage 1 management | E28: Stage 2 management | F28: Boars | G28: Sows | H28: Gilts | I28: Others | N28: Stage 1 management | O28: Stage 2 management | P28: Boars | Q28: Sows | R28: Gilts | S28: Others
D29: ='Input - Swine'!$D$29 -> Anaerobic lagoon | E29: ='Input - Swine'!$D$48 -> Drylot (feed pad) | F29: ='4.5.1.3-4 Direct N20'!F214 -> 18.1332 | G29: ='4.5.1.3-4 Direct N20'!G214 -> 24.14475 | H29: ='4.5.1.3-4 Direct N20'!H214 -> 22.6665 | I29: ='4.5.1.3-4 Direct N20'!I214 -> 15.3738 | J29: ='4.5.1.3-4 Direct N20'!J214 -> kg N | N29: ='Input - Swine'!$D$29 -> Anaerobic lagoon | O29: ='Input - Swine'!$D$48 -> Drylot (feed pad) | P29: ='4.5.1.3-4 Direct N20'!P214 -> 18.1332 | Q29: ='4.5.1.3-4 Direct N20'!Q214 -> 24.14475 | R29: ='4.5.1.3-4 Direct N20'!R214 -> 22.6665 | S29: ='4.5.1.3-4 Direct N20'!S214 -> 15.3738 | T29: ='4.5.1.3-4 Direct N20'!T214 -> kg N
E30: ='Input - Swine'!$D$49 -> Digester / covered lagoons | F30: ='4.5.1.3-4 Direct N20'!F215 -> 18.1332 | G30: ='4.5.1.3-4 Direct N20'!G215 -> 24.14475 | H30: ='4.5.1.3-4 Direct N20'!H215 -> 22.6665 | I30: ='4.5.1.3-4 Direct N20'!I215 -> 15.3738 | J30: ='4.5.1.3-4 Direct N20'!J215 -> kg N | O30: ='Input - Swine'!$D$49 -> Digester / covered lagoons | P30: ='4.5.1.3-4 Direct N20'!P215 -> 18.1332 | Q30: ='4.5.1.3-4 Direct N20'!Q215 -> 24.14475 | R30: ='4.5.1.3-4 Direct N20'!R215 -> 22.6665 | S30: ='4.5.1.3-4 Direct N20'!S215 -> 15.3738 | T30: ='4.5.1.3-4 Direct N20'!T215 -> kg N
E31: ='Input - Swine'!$D$50 -> Deep litter | F31: ='4.5.1.3-4 Direct N20'!F216 -> 18.1332 | G31: ='4.5.1.3-4 Direct N20'!G216 -> 24.14475 | H31: ='4.5.1.3-4 Direct N20'!H216 -> 22.6665 | I31: ='4.5.1.3-4 Direct N20'!I216 -> 15.3738 | J31: ='4.5.1.3-4 Direct N20'!J216 -> kg N | O31: ='Input - Swine'!$D$50 -> Deep litter | P31: ='4.5.1.3-4 Direct N20'!P216 -> 18.1332 | Q31: ='4.5.1.3-4 Direct N20'!Q216 -> 24.14475 | R31: ='4.5.1.3-4 Direct N20'!R216 -> 22.6665 | S31: ='4.5.1.3-4 Direct N20'!S216 -> 15.3738 | T31: ='4.5.1.3-4 Direct N20'!T216 -> kg N
E32: ='Input - Swine'!$D$51 -> Pit storage | F32: ='4.5.1.3-4 Direct N20'!F217 -> 18.1332 | G32: ='4.5.1.3-4 Direct N20'!G217 -> 24.14475 | H32: ='4.5.1.3-4 Direct N20'!H217 -> 22.6665 | I32: ='4.5.1.3-4 Direct N20'!I217 -> 15.3738 | J32: ='4.5.1.3-4 Direct N20'!J217 -> kg N | O32: ='Input - Swine'!$D$51 -> Pit storage | P32: ='4.5.1.3-4 Direct N20'!P217 -> 18.1332 | Q32: ='4.5.1.3-4 Direct N20'!Q217 -> 24.14475 | R32: ='4.5.1.3-4 Direct N20'!R217 -> 22.6665 | S32: ='4.5.1.3-4 Direct N20'!S217 -> 15.3738 | T32: ='4.5.1.3-4 Direct N20'!T217 -> kg N
D33: ='Input - Swine'!$D$30 -> Drylot (feed pad) | E33: ='Input - Swine'!$D$56 -> Anaerobic lagoon | F33: ='4.5.1.3-4 Direct N20'!F218 -> 27.40128 | G33: ='4.5.1.3-4 Direct N20'!G218 -> 36.4854 | H33: ='4.5.1.3-4 Direct N20'!H218 -> 34.2516 | I33: ='4.5.1.3-4 Direct N20'!I218 -> 23.23152 | J33: ='4.5.1.3-4 Direct N20'!J218 -> kg N | N33: ='Input - Swine'!$D$30 -> Drylot (feed pad) | O33: ='Input - Swine'!$D$56 -> Anaerobic lagoon | P33: ='4.5.1.3-4 Direct N20'!P218 -> 27.40128 | Q33: ='4.5.1.3-4 Direct N20'!Q218 -> 36.4854 | R33: ='4.5.1.3-4 Direct N20'!R218 -> 34.2516 | S33: ='4.5.1.3-4 Direct N20'!S218 -> 23.23152 | T33: ='4.5.1.3-4 Direct N20'!T218 -> kg N
E34: ='Input - Swine'!$D$57 -> Digester / covered lagoons | F34: ='4.5.1.3-4 Direct N20'!F219 -> 27.40128 | G34: ='4.5.1.3-4 Direct N20'!G219 -> 36.4854 | H34: ='4.5.1.3-4 Direct N20'!H219 -> 34.2516 | I34: ='4.5.1.3-4 Direct N20'!I219 -> 23.23152 | J34: ='4.5.1.3-4 Direct N20'!J219 -> kg N | O34: ='Input - Swine'!$D$57 -> Digester / covered lagoons | P34: ='4.5.1.3-4 Direct N20'!P219 -> 27.40128 | Q34: ='4.5.1.3-4 Direct N20'!Q219 -> 36.4854 | R34: ='4.5.1.3-4 Direct N20'!R219 -> 34.2516 | S34: ='4.5.1.3-4 Direct N20'!S219 -> 23.23152 | T34: ='4.5.1.3-4 Direct N20'!T219 -> kg N
E35: ='Input - Swine'!$D$58 -> Deep litter | F35: ='4.5.1.3-4 Direct N20'!F220 -> 27.40128 | G35: ='4.5.1.3-4 Direct N20'!G220 -> 36.4854 | H35: ='4.5.1.3-4 Direct N20'!H220 -> 34.2516 | I35: ='4.5.1.3-4 Direct N20'!I220 -> 23.23152 | J35: ='4.5.1.3-4 Direct N20'!J220 -> kg N | O35: ='Input - Swine'!$D$58 -> Deep litter | P35: ='4.5.1.3-4 Direct N20'!P220 -> 27.40128 | Q35: ='4.5.1.3-4 Direct N20'!Q220 -> 36.4854 | R35: ='4.5.1.3-4 Direct N20'!R220 -> 34.2516 | S35: ='4.5.1.3-4 Direct N20'!S220 -> 23.23152 | T35: ='4.5.1.3-4 Direct N20'!T220 -> kg N
E36: ='Input - Swine'!$D$59 -> Pit storage | F36: ='4.5.1.3-4 Direct N20'!F221 -> 27.40128 | G36: ='4.5.1.3-4 Direct N20'!G221 -> 36.4854 | H36: ='4.5.1.3-4 Direct N20'!H221 -> 34.2516 | I36: ='4.5.1.3-4 Direct N20'!I221 -> 23.23152 | J36: ='4.5.1.3-4 Direct N20'!J221 -> kg N | O36: ='Input - Swine'!$D$59 -> Pit storage | P36: ='4.5.1.3-4 Direct N20'!P221 -> 27.40128 | Q36: ='4.5.1.3-4 Direct N20'!Q221 -> 36.4854 | R36: ='4.5.1.3-4 Direct N20'!R221 -> 34.2516 | S36: ='4.5.1.3-4 Direct N20'!S221 -> 23.23152 | T36: ='4.5.1.3-4 Direct N20'!T221 -> kg N
D37: ='Input - Swine'!$D$31 -> Digester / covered lagoons | E37: ='Input - Swine'!$D$64 -> Anaerobic lagoon | F37: ='4.5.1.3-4 Direct N20'!F222 -> 40.296 | G37: ='4.5.1.3-4 Direct N20'!G222 -> 53.655 | H37: ='4.5.1.3-4 Direct N20'!H222 -> 50.37 | I37: ='4.5.1.3-4 Direct N20'!I222 -> 34.164 | J37: ='4.5.1.3-4 Direct N20'!J222 -> kg N | N37: ='Input - Swine'!$D$31 -> Digester / covered lagoons | O37: ='Input - Swine'!$D$64 -> Anaerobic lagoon | P37: ='4.5.1.3-4 Direct N20'!P222 -> 40.296 | Q37: ='4.5.1.3-4 Direct N20'!Q222 -> 53.655 | R37: ='4.5.1.3-4 Direct N20'!R222 -> 50.37 | S37: ='4.5.1.3-4 Direct N20'!S222 -> 34.164 | T37: ='4.5.1.3-4 Direct N20'!T222 -> kg N
E38: ='Input - Swine'!$D$65 -> Drylot (feed pad) | F38: ='4.5.1.3-4 Direct N20'!F223 -> 40.296 | G38: ='4.5.1.3-4 Direct N20'!G223 -> 53.655 | H38: ='4.5.1.3-4 Direct N20'!H223 -> 50.37 | I38: ='4.5.1.3-4 Direct N20'!I223 -> 34.164 | J38: ='4.5.1.3-4 Direct N20'!J223 -> kg N | O38: ='Input - Swine'!$D$65 -> Drylot (feed pad) | P38: ='4.5.1.3-4 Direct N20'!P223 -> 40.296 | Q38: ='4.5.1.3-4 Direct N20'!Q223 -> 53.655 | R38: ='4.5.1.3-4 Direct N20'!R223 -> 50.37 | S38: ='4.5.1.3-4 Direct N20'!S223 -> 34.164 | T38: ='4.5.1.3-4 Direct N20'!T223 -> kg N
E39: ='Input - Swine'!$D$66 -> Deep litter | F39: ='4.5.1.3-4 Direct N20'!F224 -> 40.296 | G39: ='4.5.1.3-4 Direct N20'!G224 -> 53.655 | H39: ='4.5.1.3-4 Direct N20'!H224 -> 50.37 | I39: ='4.5.1.3-4 Direct N20'!I224 -> 34.164 | J39: ='4.5.1.3-4 Direct N20'!J224 -> kg N | O39: ='Input - Swine'!$D$66 -> Deep litter | P39: ='4.5.1.3-4 Direct N20'!P224 -> 40.296 | Q39: ='4.5.1.3-4 Direct N20'!Q224 -> 53.655 | R39: ='4.5.1.3-4 Direct N20'!R224 -> 50.37 | S39: ='4.5.1.3-4 Direct N20'!S224 -> 34.164 | T39: ='4.5.1.3-4 Direct N20'!T224 -> kg N
E40: ='Input - Swine'!$D$67 -> Pit storage | F40: ='4.5.1.3-4 Direct N20'!F225 -> 40.296 | G40: ='4.5.1.3-4 Direct N20'!G225 -> 53.655 | H40: ='4.5.1.3-4 Direct N20'!H225 -> 50.37 | I40: ='4.5.1.3-4 Direct N20'!I225 -> 34.164 | J40: ='4.5.1.3-4 Direct N20'!J225 -> kg N | O40: ='Input - Swine'!$D$67 -> Pit storage | P40: ='4.5.1.3-4 Direct N20'!P225 -> 40.296 | Q40: ='4.5.1.3-4 Direct N20'!Q225 -> 53.655 | R40: ='4.5.1.3-4 Direct N20'!R225 -> 50.37 | S40: ='4.5.1.3-4 Direct N20'!S225 -> 34.164 | T40: ='4.5.1.3-4 Direct N20'!T225 -> kg N
D41: ='Input - Swine'!$D$32 -> Deep litter | E41: ='Input - Swine'!$D$72 -> Anaerobic lagoon | F41: ='4.5.1.3-4 Direct N20'!F226 -> 34.85604 | G41: ='4.5.1.3-4 Direct N20'!G226 -> 46.411575 | H41: ='4.5.1.3-4 Direct N20'!H226 -> 43.57005 | I41: ='4.5.1.3-4 Direct N20'!I226 -> 29.55186 | J41: ='4.5.1.3-4 Direct N20'!J226 -> kg N | N41: ='Input - Swine'!$D$32 -> Deep litter | O41: ='Input - Swine'!$D$72 -> Anaerobic lagoon | P41: ='4.5.1.3-4 Direct N20'!P226 -> 34.85604 | Q41: ='4.5.1.3-4 Direct N20'!Q226 -> 46.411575 | R41: ='4.5.1.3-4 Direct N20'!R226 -> 43.57005 | S41: ='4.5.1.3-4 Direct N20'!S226 -> 29.55186 | T41: ='4.5.1.3-4 Direct N20'!T226 -> kg N
E42: ='Input - Swine'!$D$73 -> Drylot (feed pad) | F42: ='4.5.1.3-4 Direct N20'!F227 -> 34.85604 | G42: ='4.5.1.3-4 Direct N20'!G227 -> 46.411575 | H42: ='4.5.1.3-4 Direct N20'!H227 -> 43.57005 | I42: ='4.5.1.3-4 Direct N20'!I227 -> 29.55186 | J42: ='4.5.1.3-4 Direct N20'!J227 -> kg N | O42: ='Input - Swine'!$D$73 -> Drylot (feed pad) | P42: ='4.5.1.3-4 Direct N20'!P227 -> 34.85604 | Q42: ='4.5.1.3-4 Direct N20'!Q227 -> 46.411575 | R42: ='4.5.1.3-4 Direct N20'!R227 -> 43.57005 | S42: ='4.5.1.3-4 Direct N20'!S227 -> 29.55186 | T42: ='4.5.1.3-4 Direct N20'!T227 -> kg N
E43: ='Input - Swine'!$D$74 -> Digester / covered lagoons | F43: ='4.5.1.3-4 Direct N20'!F228 -> 34.85604 | G43: ='4.5.1.3-4 Direct N20'!G228 -> 46.411575 | H43: ='4.5.1.3-4 Direct N20'!H228 -> 43.57005 | I43: ='4.5.1.3-4 Direct N20'!I228 -> 29.55186 | J43: ='4.5.1.3-4 Direct N20'!J228 -> kg N | O43: ='Input - Swine'!$D$74 -> Digester / covered lagoons | P43: ='4.5.1.3-4 Direct N20'!P228 -> 34.85604 | Q43: ='4.5.1.3-4 Direct N20'!Q228 -> 46.411575 | R43: ='4.5.1.3-4 Direct N20'!R228 -> 43.57005 | S43: ='4.5.1.3-4 Direct N20'!S228 -> 29.55186 | T43: ='4.5.1.3-4 Direct N20'!T228 -> kg N
E44: ='Input - Swine'!$D$75 -> Pit storage | F44: ='4.5.1.3-4 Direct N20'!F229 -> 34.85604 | G44: ='4.5.1.3-4 Direct N20'!G229 -> 46.411575 | H44: ='4.5.1.3-4 Direct N20'!H229 -> 43.57005 | I44: ='4.5.1.3-4 Direct N20'!I229 -> 29.55186 | J44: ='4.5.1.3-4 Direct N20'!J229 -> kg N | O44: ='Input - Swine'!$D$75 -> Pit storage | P44: ='4.5.1.3-4 Direct N20'!P229 -> 34.85604 | Q44: ='4.5.1.3-4 Direct N20'!Q229 -> 46.411575 | R44: ='4.5.1.3-4 Direct N20'!R229 -> 43.57005 | S44: ='4.5.1.3-4 Direct N20'!S229 -> 29.55186 | T44: ='4.5.1.3-4 Direct N20'!T229 -> kg N
...

Sheet 4.5.1.7-8 Soil leach runoff
A1: #VALUE! | C1: 4.5.1.7-8 Leaching and runoff
A3: =HYPERLINK("#'Home'!A1", "Home") -> Home | D3: Method 1 | M3: Method 2
A4: =HYPERLINK("#'Results'!A1", "Results") -> Results
D5: {=MMS_Swine_LeachingAndRunoff_Equations.VEERG_4_5_1_7__2_MassOfNitrogenLostToLeachingAndRunoffFromDrylotMMS_Title()} -> Mass of nitrogen lost to leaching and runoff from drylot MMS
A6: INPUTS | D6: {=MMS_Swine_LeachingAndRunoff_Equations.VEERG_4_5_1_7__2_MassOfNitrogenLostToLeachingAndRunoffFromDrylotMMS_Source()} -> VEERG 2026: 4.5.1.7, Equation (2)
A7: =HYPERLINK("#'Input - Site'!A1", "Site") -> Site | D7: Function name | E7: {=Common_InputFunctions.Utility_DisplayFunctionName($E$28)} -> =MMS_Swine_LeachingAndRunoff_Equations.VEERG_4_5_1_7__2_MassOfNitrogenLostToLeachingAndRunoffFromDrylotMMS
A8: =HYPERLINK("#'Input - Swine'!A1", "Swine") -> Swine
A10: CALCULATIONS | D10: Variable | E10: {=MMS_Swine_LeachingAndRunoff_Equations.VEERG_4_5_1_7__2_MassOfNitrogenLostToLeachingAndRunoffFromDrylotMMS_Variable()} -> MNLeach_jm5 | F10: This infers that drylot is not a stage 2 MMS option
A11: =HYPERLINK("#'4.2.1.1-2 Methane'!A1", "4.2.1.1-2 Methane") -> 4.2.1.1-2 Methane | D11: Unit | E11: {=MMS_Swine_LeachingAndRunoff_Equations.VEERG_4_5_1_7__2_MassOfNitrogenLostToLeachingAndRunoffFromDrylotMMS_Unit()} -> kg N | F11: Doc has typo - refers to 'solid storage'
A12: =HYPERLINK("#'4.2.1.3-4 Soil direct N2O'!A1", "4.2.1.3-4 Soil direct N2O") -> 4.2.1.3-4 Soil direct N2O
A13: =HYPERLINK("#'4.2.1.5-6 Soil Atmos Dep'!A1", "4.2.1.5-6 Soil atm. deposition") -> 4.2.1.5-6 Soil atm. deposition | D13: {=MMS_Swine_LeachingAndRunoff_Equations.VEERG_4_5_1_7__2_MassOfNitrogenLostToLeachingAndRunoffFromDrylotMMS_Arguments()} -> MN_jm5T1 | E13: nitrogen in treatment stage 1 drylot MMS (kg N) | G13: ="See " & D20 -> See M1_Table_MN_j_m-5_T-1
A14: =HYPERLINK("#'4.2.1.7-8 Soil leach runoff'!A1", "4.2.1.7-8 Soil leach & runoff") -> 4.2.1.7-8 Soil leach & runoff | D14: FracWET | E14: fraction of N available for leaching and runoff | G14: =Common_InputFunctions.CommonCropping_GetFracWET(G16,G18,Table_SourceData_FracWET[Is in leaching zone],Table_SourceData_FracWET[FracWET],Table_SourceData_FracWETIrrigation[Irrigation type i],Table_SourceData_FracWETIrrigation[FracWET]) -> 1
D15: FracLEACH_MS | E15: fraction of N lost through leaching and runoff | G15: ='Constants - Swine'!$E$17 -> 0.02
A16: APPENDICES | D16: z | E16: location in leaching zone | G16: ='Input - Site'!$E$23 -> NO - Not in leaching zone
A17: =HYPERLINK("#'Constants - Swine'!A1", "Constants - Swine") -> Constants - Swine | D17: j | E17: production system | G17: ='Input - Swine'!$E$96 -> Crop
A18: =HYPERLINK("#'Constants - Livestock'!A1", "Constants - Livestock") -> Constants - Livestock | D18: ir | E18: irrigation method | G18: ='Input - Swine'!$E$97 -> Sprinkler irrigation
A19: =HYPERLINK("#'Constants - Common'!A1", "Constants - Common") -> Constants - Common
A20: =HYPERLINK("#'Acknowledgements'!A1", "Acknowledgements") -> Acknowledgements | D20: M1_Table_MN_j_m-5_T-1 | M20: M2_Table_MN_j_m-5_T-1
D21: Nitrogen in stage 1 drylot (Method 1) | M21: Nitrogen in stage 1 drylot (Method 2)
D22: Stage 1 management | E22: Boars | F22: Sows | G22: Gilts | H22: Others | M22: Stage 1 management | N22: Boars | O22: Sows | P22: Gilts | Q22: Others
D23: ='Input - Swine'!$D$30 -> Drylot (feed pad) | E23: ='4.5.1.3-4 Direct N20'!E119 -> 201.48 | F23: ='4.5.1.3-4 Direct N20'!F119 -> 214.62 | G23: ='4.5.1.3-4 Direct N20'!G119 -> 201.48 | H23: ='4.5.1.3-4 Direct N20'!H119 -> 136.656 | I23: kg N | M23: ='Input - Swine'!$D$30 -> Drylot (feed pad) | N23: ='4.5.1.3-4 Direct N20'!O119 -> 201.48 | O23: ='4.5.1.3-4 Direct N20'!P119 -> 214.62 | P23: ='4.5.1.3-4 Direct N20'!Q119 -> 201.48 | Q23: ='4.5.1.3-4 Direct N20'!R119 -> 136.656 | R23: kg N
D25: M1_Table_MN_leach_j_m-5 | M25: M1_Table_MN_leach_j_m-5
D26: Mass of nitrogen lost to leaching (Method 1) | M26: Mass of nitrogen lost to leaching (Method 1)
D27: Stage 1 management | E27: Boars | F27: Sows | G27: Gilts | H27: Others | M27: Stage 1 management | N27: Boars | O27: Sows | P27: Gilts | Q27: Others
D28: ='Input - Swine'!$D$30 -> Drylot (feed pad) | E28: {=MMS_Swine_LeachingAndRunoff_Equations.VEERG_4_5_1_7__2_MassOfNitrogenLostToLeachingAndRunoffFromDrylotMMS(E23,$G$14,$G$15)} -> 4.0296 | F28: {=MMS_Swine_LeachingAndRunoff_Equations.VEERG_4_5_1_7__2_MassOfNitrogenLostToLeachingAndRunoffFromDrylotMMS(F23,$G$14,$G$15)} -> 4.2924 | G28: {=MMS_Swine_LeachingAndRunoff_Equations.VEERG_4_5_1_7__2_MassOfNitrogenLostToLeachingAndRunoffFromDrylotMMS(G23,$G$14,$G$15)} -> 4.0296 | H28: {=MMS_Swine_LeachingAndRunoff_Equations.VEERG_4_5_1_7__2_MassOfNitrogenLostToLeachingAndRunoffFromDrylotMMS(H23,$G$14,$G$15)} -> 2.73312 | I28: =$E$11 -> kg N | M28: ='Input - Swine'!$D$30 -> Drylot (feed pad) | N28: {=MMS_Swine_LeachingAndRunoff_Equations.VEERG_4_5_1_7__2_MassOfNitrogenLostToLeachingAndRunoffFromDrylotMMS(N23,$G$14,$G$15)} -> 4.0296 | O28: {=MMS_Swine_LeachingAndRunoff_Equations.VEERG_4_5_1_7__2_MassOfNitrogenLostToLeachingAndRunoffFromDrylotMMS(O23,$G$14,$G$15)} -> 4.2924 | P28: {=MMS_Swine_LeachingAndRunoff_Equations.VEERG_4_5_1_7__2_MassOfNitrogenLostToLeachingAndRunoffFromDrylotMMS(P23,$G$14,$G$15)} -> 4.0296 | Q28: {=MMS_Swine_LeachingAndRunoff_Equations.VEERG_4_5_1_7__2_MassOfNitrogenLostToLeachingAndRunoffFromDrylotMMS(Q23,$G$14,$G$15)} -> 2.73312 | R28: =$E$11 -> kg N
D32: {=MMS_Swine_LeachingAndRunoff_Equations.VEERG_4_5_1_7__1_AnnualEmissionsFromLeachingAndRunoffFromMMS_Title()} -> Annual emissions from leaching and runoff from each MMS
D33: {=MMS_Swine_LeachingAndRunoff_Equations.VEERG_4_5_1_7__1_AnnualEmissionsFromLeachingAndRunoffFromMMS_Source()} -> VEERG 2026: 4.5.1.7, Equation (1)
D34: Function name | E34: {=Common_InputFunctions.Utility_DisplayFunctionName($E$47)} -> =MMS_Swine_LeachingAndRunoff_Equations.VEERG_4_5_1_7__1_AnnualEmissionsFromLeachingAndRunoffFromMMS
D37: Variable | E37: {=MMS_Swine_LeachingAndRunoff_Equations.VEERG_4_5_1_7__1_AnnualEmissionsFromLeachingAndRunoffFromMMS_Variable()} -> E_N2Oleach
D38: Unit | E38: {=MMS_Swine_LeachingAndRunoff_Equations.VEERG_4_5_1_7__1_AnnualEmissionsFromLeachingAndRunoffFromMMS_Unit()} -> t N2O
D40: {=MMS_Swine_LeachingAndRunoff_Equations.VEERG_4_5_1_7__1_AnnualEmissionsFromLeachingAndRunoffFromMMS_Arguments()} -> MNLeach_jm5 | E40: mass of N lost through leaching and runoff from drylot MMS (kg N) | G40: ="See " & D25 -> See M1_Table_MN_leach_j_m-5
D41: EF_leach | E41: emission factor for leaching and runoff (kg N2O-N/kg N) | G41: ='Constants - Common'!$E$170 -> 0.011
D42: C_N2O | E42: factor to convert elemental mass of N2O to molecular mass | G42: =Common_InputFunctions.Utility_LookupValueInTableNumber("N2O",Table_GasToMolecularConversionFactor[Gas],Table_GasToMolecularConversionFactor[Conversion factor combined]) -> 1.5714286
D44: M1_Table_E_N2O_leach | M44: M2_Table_E_N2O_leach
D45: Annual emissions from leaching and runoff (Method 1) | M45: Annual emissions from leaching and runoff (Method 2)
D46: Stage 1 management | E46: Boars | F46: Sows | G46: Gilts | H46: Others | M46: Stage 1 management | N46: Boars | O46: Sows | P46: Gilts | Q46: Others
