Workbook
Name Common_Equations.Common_ConvertCH4ToCO2e: _xlfn.LAMBDA(_xlpm.E_CH4,_xlpm.GWP_CH4, _xlpm.E_CH4 * _xlpm.GWP_CH4)
Name Common_Equations.Common_ConvertCH4ToCO2e_Arguments: _xlfn.LAMBDA(_xlfn.MAKEARRAY(2, 2, _xlfn.LAMBDA(_xlpm.r,_xlpm.c, INDEX({"ECH4","Methane emissions (t CH4)";"GWPCH4","Global warming potential for methane (t CO2-e / t CH4)"}, _xlpm.r, _xlpm.c))))
Name Common_Equations.Common_ConvertCH4ToCO2e_LatexEquation: _xlfn.LAMBDA("CO2_e = E_{CH4} \times GWP_{CH4}")
Name Common_Equations.Common_ConvertCH4ToCO2e_NIRReference: _xlfn.LAMBDA("")
Name Common_Equations.Common_ConvertCH4ToCO2e_Title: _xlfn.LAMBDA("Convert methane emissions to carbon dioxide equivalent emissions")
Name Common_Equations.Common_ConvertCH4ToCO2e_Unit: _xlfn.LAMBDA("t CO2e")
Name Common_Equations.Common_ConvertCH4ToCO2e_Variable: _xlfn.LAMBDA("ECH4 CO2e")
Name Common_Equations.Common_ConvertN2OToCO2e: _xlfn.LAMBDA(_xlpm.E_N2O,_xlpm.GWP_N2O, _xlpm.E_N2O * _xlpm.GWP_N2O)
Name Common_Equations.Common_ConvertN2OToCO2e_LatexEquation: _xlfn.LAMBDA("CO2_e = E_{N2O} \times GWP_{N2O}")
Name Common_Equations.Common_ConvertN2OToCO2e_NIRReference: _xlfn.LAMBDA("")
Name Common_Equations.Common_ConvertN2OToCO2e_Title: _xlfn.LAMBDA("Convert nitrous oxide emissions to carbon dioxide equivalent emissions")
Name Common_Equations.Common_ConvertN2OToCO2e_Unit: _xlfn.LAMBDA("t CO2e")
Name Common_Equations.Common_ConvertN2OToCO2e_Variable: _xlfn.LAMBDA("EN2O CO2e")
Name Common_InputFunctions.Utility_ConvertStateCommonNameToAbbreviation: _xlfn.LAMBDA(_xlpm.StateCommonName,_xlpm.StateCommonNameArray,_xlpm.StateAbbreviationArray, _xlfn.XLOOKUP(_xlpm.StateCommonName, _xlpm.StateCommonNameArray, _xlpm.StateAbbreviationArray, ""))
Name Common_InputFunctions.Utility_DisplayFunctionName: _xlfn.LAMBDA(_xlpm.Function, _xlfn.TEXTBEFORE(_xlfn.FORMULATEXT(_xlpm.Function), "("))
Name Common_InputFunctions.Utility_GetArrayTableColumnStartNumber: _xlfn.LAMBDA(_xlpm.TableHeaderCell, COLUMN(_xlpm.TableHeaderCell))
Name Common_InputFunctions.Utility_GetArrayTableRowStartNumber: _xlfn.LAMBDA(_xlpm.TableheaderCell,_xlpm.RowsBetweenHeaderandArray, ROW(_xlpm.TableheaderCell) + _xlpm.RowsBetweenHeaderandArray - 1)
Name Common_InputFunctions.Utility_LookupValueInTable: _xlfn.LAMBDA(_xlpm.LookupValue,_xlpm.LookupArray,_xlpm.ReturnArray, _xlfn.XLOOKUP(_xlpm.LookupValue, _xlpm.LookupArray, _xlpm.ReturnArray, ""))
Name Common_SourceData.Common_SourceData_AustralianStatesTerritories_Source: _xlfn.LAMBDA("")
Name Common_SourceData.Common_SourceData_AustralianStatesTerritories_Title: _xlfn.LAMBDA("Australian states and territories")
Name Common_SourceData.Common_SourceData_AustralianStatesTerritories_Unit: _xlfn.LAMBDA("")
Name Common_SourceData.Common_SourceData_AustralianStatesTerritories_Variable: _xlfn.LAMBDA("")
Name Common_SourceData.Common_SourceData_ClimateZones_Source: _xlfn.LAMBDA("VEERG 2026: Table 1.3: Climate and Rainfall zone classifications and definitions")
Name Common_SourceData.Common_SourceData_ClimateZones_Title: _xlfn.LAMBDA("VEERG Australian climate zones")
Name Common_SourceData.Common_SourceData_ClimateZones_Unit: _xlfn.LAMBDA("")
Name Common_SourceData.Common_SourceData_ClimateZones_Variable: _xlfn.LAMBDA("")
Name Common_SourceData.Common_SourceData_ConvertGasElementalToMolecular_Source: _xlfn.LAMBDA("XXXXXXX")
Name Common_SourceData.Common_SourceData_ConvertGasElementalToMolecular_Title: _xlfn.LAMBDA("Factor to convert elemental mass of gas to molecular mass")
Name Common_SourceData.Common_SourceData_ConvertGasElementalToMolecular_Unit: _xlfn.LAMBDA("factor")
Name Common_SourceData.Common_SourceData_ConvertGasElementalToMolecular_Variable: _xlfn.LAMBDA("Cg")
Name Common_SourceData.Common_SourceData_ConvertN2oElementalToMolecularCg_Data: _xlfn.LAMBDA(44 / 28)
Name Common_SourceData.Common_SourceData_ConvertN2oElementalToMolecularCg_Source: _xlfn.LAMBDA("National Inventory Report 2023 Volume 1")
Name Common_SourceData.Common_SourceData_ConvertN2oElementalToMolecularCg_Title: _xlfn.LAMBDA("Factor to convert elemental mass of N2O to molecular mass")
Name Common_SourceData.Common_SourceData_ConvertN2oElementalToMolecularCg_Unit: _xlfn.LAMBDA("factor")
Name Common_SourceData.Common_SourceData_ConvertN2oElementalToMolecularCg_Variable: _xlfn.LAMBDA("CgN2O")
Name Common_SourceData.Common_SourceData_DataScores_Scope3_Source: _xlfn.LAMBDA("VEERG 2026: XXXXXXXX")
Name Common_SourceData.Common_SourceData_DataScores_Scope3_Title: _xlfn.LAMBDA("Australian data scores for scope 3")
Name Common_SourceData.Common_SourceData_DataScores_Scope3_Unit: _xlfn.LAMBDA("")
Name Common_SourceData.Common_SourceData_DataScores_Scope3_Variable: _xlfn.LAMBDA("")
Name Common_SourceData.Common_SourceData_DataScores_Scope3_Variation: _xlfn.LAMBDA("")
Name Common_SourceData.Common_SourceData_DensityOfMethane_Data: _xlfn.LAMBDA(0.6784)
Name Common_SourceData.Common_SourceData_DensityOfMethane_Source: _xlfn.LAMBDA("National Inventory Report 2023 Volume 1: Equations 3.B.1a_2, 3.B.1c_2, 3.B.3_1, 3.B.4g_2")
Name Common_SourceData.Common_SourceData_DensityOfMethane_Title: _xlfn.LAMBDA("p = density of methane")
Name Common_SourceData.Common_SourceData_DensityOfMethane_Unit: _xlfn.LAMBDA("kg/m3")
Name Common_SourceData.Common_SourceData_EFleach_Data: _xlfn.LAMBDA(_xlfn.MAKEARRAY(1, 2, _xlfn.LAMBDA(_xlpm.r,_xlpm.c, INDEX({"EFleach",0.011}, _xlpm.r, _xlpm.c))))
Name Common_SourceData.Common_SourceData_EFleach_NIRReference: _xlfn.LAMBDA("National Inventory Report Volume 1: Equation 3.D.B_10")
Name Common_SourceData.Common_SourceData_EFleach_Source: _xlfn.LAMBDA("VEERG 2026:5.5.2.3 Constant Parameters")
Name Common_SourceData.Common_SourceData_EFleach_Title: _xlfn.LAMBDA("Emission factor for nitrogen leaching and runoff")
Name Common_SourceData.Common_SourceData_EFleach_Unit: _xlfn.LAMBDA("(kg N2O-N / kg N")
Name Common_SourceData.Common_SourceData_EFleach_Variation: _xlfn.LAMBDA((""))
Name Common_SourceData.Common_SourceData_EFN2O_NIRReference: _xlfn.LAMBDA("")
Name Common_SourceData.Common_SourceData_EFN2O_Source: _xlfn.LAMBDA("VEERG 2026: Table A.2.2.1")
Name Common_SourceData.Common_SourceData_EFN2O_Title: _xlfn.LAMBDA("Nitrous oxide emission factors for inorganic fertiliser application")
Name Common_SourceData.Common_SourceData_EFN2O_Unit: _xlfn.LAMBDA("(kg N2O-N / kg N")
Name Common_SourceData.Common_SourceData_EFPastureRangeAndPaddock_Data: _xlfn.LAMBDA(_xlfn.MAKEARRAY(3, 2, _xlfn.LAMBDA(_xlpm.r,_xlpm.c, INDEX({"Climate zone","EFPRP";"Wet climate zone",0.006;"Dry climate zone",0.002}, _xlpm.r, _xlpm.c))))
Name Common_SourceData.Common_SourceData_EFPastureRangeAndPaddock_NIRReference: _xlfn.LAMBDA("")
Name Common_SourceData.Common_SourceData_EFPastureRangeAndPaddock_Source: _xlfn.LAMBDA("VEERG 2026: Table A.2.2.2")
Name Common_SourceData.Common_SourceData_EFPastureRangeAndPaddock_Title: _xlfn.LAMBDA("Emission factor for urine and dung deposited on pasture, range or paddock")
Name Common_SourceData.Common_SourceData_EFPastureRangeAndPaddock_Unit: _xlfn.LAMBDA("kg N2O - N / kg N")
Name Common_SourceData.Common_SourceData_EFPastureRangeAndPaddock_Variation: _xlfn.LAMBDA("VARIATION FROM SOURCE DATA: Changed 'Dry climate zones' to singular 'Dry climate zone' to aid lookup.")

Sheet Home
A1: Home

Sheet Results
A1: #VALUE! | C1: 4.6 Manure management: Poultry: Results
A3: =HYPERLINK("#'Home'!A1", "Home") -> Home
A4: =HYPERLINK("#'Results'!A1", "Results") -> Results | D4: Emissions breakdown
A6: INPUTS | D6: Scope 1 source | E6: GHG emissions method 1 | F6: GHG emissions method 2 | G6: GHG Unit | H6: CO2-e emissions method 1 | I6: CO2-e emissions method 2 | J6: CO2-e unit
A7: =HYPERLINK("#'Input - Site'!A1", "Site") -> Site | D7: 4.5.1.1-2 Manure methane | E7: ='4.6.1.1-2 Methane'!E280 -> 0 | F7: ='4.6.1.1-2 Methane'!O280 -> 0 | G7: t CH4 | H7: ='4.6.1.1-2 Methane'!E285 -> 0 | I7: ='4.6.1.1-2 Methane'!O285 -> 0 | J7: t CO2e
A8: =HYPERLINK("#'Input - Poultry'!A1", "Poultry") -> Poultry | D8: 4.5.1.3-4 Direct N2O | E8: ='4.6.1.3-4 Direct N20'!E274 -> 0 | F8: ='4.6.1.3-4 Direct N20'!O274 -> 0 | G8: t N2O | H8: ='4.6.1.3-4 Direct N20'!E279 -> 0 | I8: ='4.6.1.3-4 Direct N20'!O279 -> 0 | J8: t CO2e
D9: 4.5.1.5-6 Atmospheric deposition | E9: ='4.6.1.5-6 Atmos Dep'!E114 -> 0 | F9: ='4.6.1.5-6 Atmos Dep'!O114 -> 0 | G9: t N2O | H9: ='4.6.1.5-6 Atmos Dep'!E119 -> 0 | I9: ='4.6.1.5-6 Atmos Dep'!O119 -> 0 | J9: t CO2e
A10: CALCULATIONS | D10: 4.2.1.7-8 Leaching and runoff | E10: ='4.6.1.7-8 Leaching and runoff'!$E$30 -> Solid storage | F10: ='4.6.1.7-8 Leaching and runoff'!$O$36 -> 0 | G10: t N2O | H10: ='4.6.1.7-8 Leaching and runoff'!E54 -> 0 | I10: ='4.6.1.7-8 Leaching and runoff'!O54 -> 0 | J10: t CO2e
A11: =HYPERLINK("#'4.6.1.1-2 Methane'!A1", "4.6.1.1-2 Methane") -> 4.6.1.1-2 Methane | D11: Total | H11: =SUM(H7:H10) -> 0 | I11: =SUM(I7:I10) -> 0 | J11: t CO2e
A12: =HYPERLINK("#'4.6.1.3-4 Direct N20'!A1", "4.6.1.3-4 Direct N2O") -> 4.6.1.3-4 Direct N2O
A13: =HYPERLINK("#'4.6.1.5-6 Atmos Dep'!A1", "4.6.1.5-6 Soil atm. deposition") -> 4.6.1.5-6 Soil atm. deposition | D13: WARNING: Manure nitrogen that was applied to soils must be accounted for
A14: =HYPERLINK("#'4.6.1.7-8 Leaching and runoff'!A1", "4.6.1.7-8 Leaching & runoff") -> 4.6.1.7-8 Leaching & runoff | D14: See the table below for how to account for manure applied to soils for scope 1 and 3.
A15: =HYPERLINK("#'4.6.1.9 Manure applied to soils'!A1", "4.6.1.9 Manure applied to soils") -> 4.6.1.9 Manure applied to soils
A16: =HYPERLINK("#'4.6.1.10-11 Soil direct N2O'!A1", "4.6.1.10-11 Soil direct N2O") -> 4.6.1.10-11 Soil direct N2O | D16: Manure nitrogen use | E16: Amount of N in manure | F16: N unit | G16: Emissions allocated to | H16: VEERG Calculation method
A17: =HYPERLINK("#'4.6.1.12-13 Soil atmos dep'!A1", "4.6.1.12-13 Soil Atm. deposition") -> 4.6.1.12-13 Soil Atm. deposition | D17: Manure nitrogen deposited on farm soils (including use as fertiliser for other enterprises on own farm eg crops) | E17: ='4.6.1.9 Manure applied to soils'!E136 -> Solid storage | F17: ='4.6.1.9 Manure applied to soils'!F136 -> 0.11833281 | G17: Scope 1 - This piggery | H17: 5.2.2.1 (1), 5.4.1.3 (1, 2), 5.5.1.1 (1, 3)
A18: =HYPERLINK("#'4.6.1.14-15 Soil leach runoff'!A1", "4.6.1.14-15 Soil leach & runoff") -> 4.6.1.14-15 Soil leach & runoff | D18: Manure nitrogen deposited on farm soils as fertiliser for other farm enterpsies (eg crops) | E18: ='4.6.1.9 Manure applied to soils'!E235 -> 0 | F18: ='4.6.1.9 Manure applied to soils'!F235 -> 0 | G18: Scope 1 - This piggery | H18: 5.2.2.1 (1), 5.4.1.3 (1, 2), 5.5.1.1 (1, 3)
D19: Manure nitrogen sold | E19: ='4.6.1.9 Manure applied to soils'!E178 -> Composting (passive windrow) | F19: ='4.6.1.9 Manure applied to soils'!F178 -> 0.12062312 | G19: Scope 3 (downstream) | H19: 15.13.1.1 (1), 5.2.2.1 (1), 5.4.1.3 (1, 2), 5.5.1.1 (1, 3)
A20: APPENDICES
A21: =HYPERLINK("#'Constants - Poultry'!A1", "Constants - Poultry") -> Constants - Poultry
A22: =HYPERLINK("#'Constants - Livestock'!A1", "Constants - Livestock") -> Constants - Livestock
A23: =HYPERLINK("#'Constants - Common'!A1", "Constants - Common") -> Constants - Common
A24: =HYPERLINK("#'Acknowledgements'!A1", "Acknowledgements") -> Acknowledgements

Sheet Input - Site
A1: #VALUE! | C1: Input - Site
A3: =HYPERLINK("#'Home'!A1", "Home") -> Home
A4: =HYPERLINK("#'Results'!A1", "Results") -> Results
D5: Your business
A6: INPUTS
A7: =HYPERLINK("#'Input - Site'!A1", "Site") -> Site | D7: Farm name | E7: Test Farms
A8: =HYPERLINK("#'Input - Poultry'!A1", "Poultry") -> Poultry | D8: Reporting entity name | E8: Test Farms Pty Ltd
A10: CALCULATIONS | D10: 💡An 'Emissions accounting period' is a 12 month period where the business can report on the emissions, and is typically the same as the business' financial accounting period.
A11: =HYPERLINK("#'4.6.1.1-2 Methane'!A1", "4.6.1.1-2 Methane") -> 4.6.1.1-2 Methane
A12: =HYPERLINK("#'4.6.1.3-4 Direct N20'!A1", "4.6.1.3-4 Direct N2O") -> 4.6.1.3-4 Direct N2O | D12: Emissions calculation period start date | E12: 45292 | F12: ← DD/MM/YYYY or DD Month YYYY
A13: =HYPERLINK("#'4.6.1.5-6 Atmos Dep'!A1", "4.6.1.5-6 Soil atm. deposition") -> 4.6.1.5-6 Soil atm. deposition | D13: Emissions calculation period end date | E13: =DATE(YEAR(E12)+1,MONTH(E12),DAY(E12))-1 -> 45657 | F13: ← Automatically calculated, 12 months after start date
A14: =HYPERLINK("#'4.6.1.7-8 Leaching and runoff'!A1", "4.6.1.7-8 Leaching & runoff") -> 4.6.1.7-8 Leaching & runoff
A15: =HYPERLINK("#'4.6.1.9 Manure applied to soils'!A1", "4.6.1.9 Manure applied to soils") -> 4.6.1.9 Manure applied to soils
A16: =HYPERLINK("#'4.6.1.10-11 Soil direct N2O'!A1", "4.6.1.10-11 Soil direct N2O") -> 4.6.1.10-11 Soil direct N2O | D16: Location and climate
A17: =HYPERLINK("#'4.6.1.12-13 Soil atmos dep'!A1", "4.6.1.12-13 Soil Atm. deposition") -> 4.6.1.12-13 Soil Atm. deposition
A18: =HYPERLINK("#'4.6.1.14-15 Soil leach runoff'!A1", "4.6.1.14-15 Soil leach & runoff") -> 4.6.1.14-15 Soil leach & runoff | D18: Location information is used to reference some region and climate-specific emission factors
D19: Tip: Use the web-based GAF Location Helper tool to easily get region and climate information. You will need an internet connection to use the GAF Location Helper.
A20: APPENDICES
A21: =HYPERLINK("#'Constants - Poultry'!A1", "Constants - Poultry") -> Constants - Poultry | D21: State | E21: Western Australia | F21: ← Please select
A22: =HYPERLINK("#'Constants - Livestock'!A1", "Constants - Livestock") -> Constants - Livestock | D22: Region (ABS Statistical area level 4) if state is WA | E22: Western Australia - Outback (South) | F22: ← Please select
A23: =HYPERLINK("#'Constants - Common'!A1", "Constants - Common") -> Constants - Common | D23: Leaching zone | E23: NO - Not in leaching zone | F23: ← Please select
A24: =HYPERLINK("#'Acknowledgements'!A1", "Acknowledgements") -> Acknowledgements | D24: Elevation | E24: 307.7 | F24: Meters
D25: Average temperature for reporting period | E25: 18 | F25: Degrees celsius
D26: Total rainfall for reporting period | E26: 601 | F26: Millimetres
D27: Potential evapotranspiration for reporting period | E27: 1326 | F27: Millimetres
D28: Number of frost days for reporting period | E28: 7 | F28: Days
D29: MAP:PET ratio | E29: =E26/E27 -> 0.45324284
D30: Rainfall zone | E30: =Common_InputFunctions.Utility_LookupItemFromMinMax(E26,Table_SourceData_RainfallZones[Min rainfall],Table_SourceData_RainfallZones[Max rainfall],Table_SourceData_RainfallZones[Rainfall Zone]) -> High rainfall
D31: Climate zone | E31: =Common_InputFunctions.Utility_GetClimateZone(E25,E26,E28,E24,E29,Table_SourceData_ClimateZones[Min temp],Table_SourceData_ClimateZones[Max temp],Table_SourceData_ClimateZones[Min rainfall],Table_SourceData_ClimateZones[Max rainfall],Table_SourceData_ClimateZones[Min frost days],Table_SourceData_ClimateZones[Max frost days],Table_SourceData_ClimateZones[Min elevation],Table_SourceData_ClimateZones[Max elevation],Table_SourceData_ClimateZones[Min MAP:PET],Table_SourceData_ClimateZones[Max MAP:PET],Table_SourceData_ClimateZones[Climate zone]) -> Warm temperate dry
D32: Wet or dry climate zone | E32: =Common_InputFunctions.Utility_LookupValueInTable($E$31,Table_SourceData_WetDryZones[Climate zone],Table_SourceData_WetDryZones[Wet or Dry Zone]) -> Dry climate zone
D33: Temperature zone | E33: =Common_InputFunctions.Utility_LookupItemFromMinMax(E25,Table_SourceData_TemperatureZones[Min MAT],Table_SourceData_TemperatureZones[Max MAT],Table_SourceData_TemperatureZones[Temperature Zone]) -> Temperate

Sheet Input - Poultry
A1: #VALUE! | C1: Input -Poultry
A3: =HYPERLINK("#'Home'!A1", "Home") -> Home
A4: =HYPERLINK("#'Results'!A1", "Results") -> Results
D5: This tool demostrates inputs for one production system.
A6: INPUTS
A7: =HYPERLINK("#'Input - Site'!A1", "Site") -> Site
A8: =HYPERLINK("#'Input - Poultry'!A1", "Poultry") -> Poultry
E9: Layers | F9: Meat chicken growers | G9: Meat chicken breeders | H9: Other
A10: CALCULATIONS | D10: ="Average duration of stay between " & TEXT('Input - Site'!$E$12, "dd mmm yy") & " and " & TEXT('Input - Site'!$E$13, "dd mmm yy") -> Average duration of stay between 01 Jan 24 and 31 Dec 24 | E10: 365 | F10: 365 | G10: 365 | H10: 365 | I10: Days
A11: =HYPERLINK("#'4.6.1.1-2 Methane'!A1", "4.6.1.1-2 Methane") -> 4.6.1.1-2 Methane | D11: ="Average number of birds between " & TEXT('Input - Site'!$E$12, "dd mmm yy") & " and " & TEXT('Input - Site'!$E$13, "dd mmm yy") -> Average number of birds between 01 Jan 24 and 31 Dec 24 | E11: 100 | F11: 100 | G11: 100 | H11: 100 | I11: Head
A12: =HYPERLINK("#'4.6.1.3-4 Direct N20'!A1", "4.6.1.3-4 Direct N2O") -> 4.6.1.3-4 Direct N2O
A13: =HYPERLINK("#'4.6.1.5-6 Atmos Dep'!A1", "4.6.1.5-6 Soil atm. deposition") -> 4.6.1.5-6 Soil atm. deposition | D13: Manure production
A14: =HYPERLINK("#'4.6.1.7-8 Leaching and runoff'!A1", "4.6.1.7-8 Leaching & runoff") -> 4.6.1.7-8 Leaching & runoff
A15: =HYPERLINK("#'4.6.1.9 Manure applied to soils'!A1", "4.6.1.9 Manure applied to soils") -> 4.6.1.9 Manure applied to soils | D15: Method 1 default values (Do not edit) | E15: Layers | F15: Meat chicken growers | G15: Meat chicken breeders | H15: Other
A16: =HYPERLINK("#'4.6.1.10-11 Soil direct N2O'!A1", "4.6.1.10-11 Soil direct N2O") -> 4.6.1.10-11 Soil direct N2O | D16: Dry matter intake | E16: ='Constants - Poultry'!E9 -> 0.086 | F16: ='Constants - Poultry'!F9 -> 0.093 | G16: ='Constants - Poultry'!G9 -> 0.103 | H16: ='Constants - Poultry'!H9 -> 0.093 | I16: kg/DM/bird/day
A17: =HYPERLINK("#'4.6.1.12-13 Soil atmos dep'!A1", "4.6.1.12-13 Soil Atm. deposition") -> 4.6.1.12-13 Soil Atm. deposition | D17: Dry matter digestibility (DMD) | E17: ='Constants - Poultry'!E10 -> 0.8 | F17: ='Constants - Poultry'!F10 -> 0.8 | G17: ='Constants - Poultry'!G10 -> 0.8 | H17: ='Constants - Poultry'!H10 -> 0.8 | I17: fraction
A18: =HYPERLINK("#'4.6.1.14-15 Soil leach runoff'!A1", "4.6.1.14-15 Soil leach & runoff") -> 4.6.1.14-15 Soil leach & runoff | D18: Crude protein (CP) | E18: ='Constants - Poultry'!E11 -> 0.19 | F18: ='Constants - Poultry'!F11 -> 0.23 | G18: ='Constants - Poultry'!G11 -> 0.19 | H18: ='Constants - Poultry'!H11 -> 0.23 | I18: fraction
A20: APPENDICES | D20: Method 2 custom values (Edit if known) | E20: Layers | F20: Meat chicken growers | G20: Meat chicken breeders | H20: Other
A21: =HYPERLINK("#'Constants - Poultry'!A1", "Constants - Poultry") -> Constants - Poultry | D21: Dry matter intake | E21: ='Constants - Poultry'!E9 -> 0.086 | F21: ='Constants - Poultry'!F9 -> 0.093 | G21: ='Constants - Poultry'!G9 -> 0.103 | H21: ='Constants - Poultry'!H9 -> 0.093 | I21: kg/DM/bird/day
A22: =HYPERLINK("#'Constants - Livestock'!A1", "Constants - Livestock") -> Constants - Livestock | D22: Dry matter digestibility (DMD) | E22: ='Constants - Poultry'!E10 -> 0.8 | F22: ='Constants - Poultry'!F10 -> 0.8 | G22: ='Constants - Poultry'!G10 -> 0.8 | H22: ='Constants - Poultry'!H10 -> 0.8 | I22: fraction
A23: =HYPERLINK("#'Constants - Common'!A1", "Constants - Common") -> Constants - Common | D23: Crude protein (CP) | E23: ='Constants - Poultry'!E11 -> 0.19 | F23: ='Constants - Poultry'!F11 -> 0.23 | G23: ='Constants - Poultry'!G11 -> 0.19 | H23: ='Constants - Poultry'!H11 -> 0.23 | I23: fraction
A24: =HYPERLINK("#'Acknowledgements'!A1", "Acknowledgements") -> Acknowledgements
D25: Manure management systems
D27: Production system | E27: Free range | F27: ← Please select
D29: Stage 1 MMS | E29: Layers | F29: Meat chicken growers | G29: Meat chicken breeders | H29: Other
D30: ='Constants - Poultry'!G29 -> Poultry manure with bedding | E30: 0.3 | F30: 0.3 | G30: 0.3 | H30: 0.3 | I30: Percent
D31: ='Constants - Poultry'!G30 -> Belt manure removal | E31: 0.3 | F31: 0.3 | G31: 0.3 | H31: 0.3 | I31: Percent
D32: ='Constants - Poultry'!G31 -> Manure stored in house | E32: 0.3 | F32: 0.3 | G32: 0.3 | H32: 0.3 | I32: Percent
D33: ='Constants - Poultry'!G32 -> Pasture range and paddock | E33: 0.1 | F33: 0.1 | G33: 0.1 | H33: 0.1 | I33: Percent
D34: Total sent to all MMS (Must equal 100%) | E34: =SUM(E30,E31,E32,E33) -> 1 | F34: =SUM(F30,F31,F32,F33) -> 1 | G34: =SUM(G30,G31,G32,G33) -> 1 | H34: =SUM(H30,H31,H32,H33) -> 1
D35: ▼
D36: Stage 2 MMS | E36: Layers | F36: Meat chicken growers | G36: Meat chicken breeders | H36: Other | I36: ► | J36: Destination after stage 2 MMS (Percent)
D37: ="From stage 1: " & $D$30 -> From stage 1: Poultry manure with bedding | E37: =IF(SUM(E30:H30)>0,"Manure was sent to this MMS, please complete this section.","No manure was sent to this MMS. Leave this section blank.") -> Manure was sent to this MMS, please complete this section. | J37: Sold | K37: Fert for own farm (eg crop) | L37: Direct application to soil
D38: ='Constants - Poultry'!$J$29 -> Solid storage | E38: 0.2 | F38: 0.2 | G38: 0.2 | H38: 0.2 | I38: Percent | J38: 0.25 | K38: 0.25 | L38: =1-SUM(J38:K38) -> 0.5
D39: ='Constants - Poultry'!$J$30 -> Composting (passive windrow) | E39: 0.2 | F39: 0.2 | G39: 0.2 | H39: 0.2 | I39: Percent | J39: 0.25 | K39: 0.25 | L39: =1-SUM(J39:K39) -> 0.5
D40: ='Constants - Poultry'!$J$31 -> Digester / covered lagoons | E40: 0.2 | F40: 0.2 | G40: 0.2 | H40: 0.2 | I40: Percent | J40: 0.25 | K40: 0.25 | L40: =1-SUM(J40:K40) -> 0.5
D41: ='Constants - Poultry'!$J$32 -> Direct processing | E41: 0.2 | F41: 0.2 | G41: 0.2 | H41: 0.2 | I41: Percent | J41: 0.25 | K41: 0.25 | L41: =1-SUM(J41:K41) -> 0.5
D42: Direct application to soil | E42: =1-SUM(E38:E41) -> 0.2 | F42: =1-SUM(F38:F41) -> 0.2 | G42: =1-SUM(G38:G41) -> 0.2 | H42: =1-SUM(H38:H41) -> 0.2 | I42: Percent
D44: ="From stage 1: " & $D$31 -> From stage 1: Belt manure removal | E44: =IF(SUM(E31:H31)>0,"Manure was sent to this MMS, please complete this section.","No manure was sent to this MMS. Leave this section blank.") -> Manure was sent to this MMS, please complete this section. | J44: Sold | K44: Fert for own farm (eg crop) | L44: Direct application to soil
D45: ='Constants - Poultry'!$J$29 -> Solid storage | E45: 0.2 | F45: 0.2 | G45: 0.2 | H45: 0.2 | I45: Percent | J45: 0.25 | K45: 0.25 | L45: =1-SUM(J45:K45) -> 0.5
...

Sheet 4.6.1.1-2 Methane
A1: #VALUE! | C1: 4.6.1.1-2 Manure Methane
A3: =HYPERLINK("#'Home'!A1", "Home") -> Home | D3: Method 1 | N3: Method 2
A4: =HYPERLINK("#'Results'!A1", "Results") -> Results
D5: {=MMS_Poultry_Methane_Equations.VEERG_4_6_1_1__5_VolatileSolidProduction_Title()} -> Volatile solid production poultry classes
A6: INPUTS | D6: {=MMS_Poultry_Methane_Equations.VEERG_4_6_1_1__5_VolatileSolidProduction_Source()} -> VEERG 2026: 4.4.1.1, Equation (5)
A7: =HYPERLINK("#'Input - Site'!A1", "Site") -> Site | D7: Function name | E7: {=Common_InputFunctions.Utility_DisplayFunctionName(D35)} -> =MMS_Poultry_Methane_Equations.VEERG_4_6_1_1__5_VolatileSolidProduction
A8: =HYPERLINK("#'Input - Poultry'!A1", "Poultry") -> Poultry
A10: CALCULATIONS | D10: Variable | E10: {=MMS_Poultry_Methane_Equations.VEERG_4_6_1_1__5_VolatileSolidProduction_Variable()} -> VS_jk
A11: =HYPERLINK("#'4.6.1.1-2 Methane'!A1", "4.6.1.1-2 Methane") -> 4.6.1.1-2 Methane | D11: Unit | E11: {=MMS_Poultry_Methane_Equations.VEERG_4_6_1_1__5_VolatileSolidProduction_Unit()} -> kg VS/bird/day
A12: =HYPERLINK("#'4.6.1.3-4 Direct N20'!A1", "4.6.1.3-4 Direct N2O") -> 4.6.1.3-4 Direct N2O
A13: =HYPERLINK("#'4.6.1.5-6 Atmos Dep'!A1", "4.6.1.5-6 Soil atm. deposition") -> 4.6.1.5-6 Soil atm. deposition | D13: {=MMS_Poultry_Methane_Equations.VEERG_4_6_1_1__5_VolatileSolidProduction_Arguments()} -> I_jk | E13: dry matter intake for each class and subclass : kg DM/bird/day | G13: ="See " & D17 -> See M1_Table_I_j_k
A14: =HYPERLINK("#'4.6.1.7-8 Leaching and runoff'!A1", "4.6.1.7-8 Leaching & runoff") -> 4.6.1.7-8 Leaching & runoff | D14: DMD_jk | E14: dry matter digestibility for each class and subclass : fraction | G14: ="See " & D22 -> See M1_Table_DMD_j_k
A15: =HYPERLINK("#'4.6.1.9 Manure applied to soils'!A1", "4.6.1.9 Manure applied to soils") -> 4.6.1.9 Manure applied to soils | D15: A_j | E15: ash content of manure for each class and subclass : fraction | G15: ="See " & D32 -> See M1_Table_VS_j_k
A16: =HYPERLINK("#'4.6.1.10-11 Soil direct N2O'!A1", "4.6.1.10-11 Soil direct N2O") -> 4.6.1.10-11 Soil direct N2O
A17: =HYPERLINK("#'4.6.1.12-13 Soil atmos dep'!A1", "4.6.1.12-13 Soil Atm. deposition") -> 4.6.1.12-13 Soil Atm. deposition | D17: M1_Table_I_j_k | N17: M2_Table_I_j_k
A18: =HYPERLINK("#'4.6.1.14-15 Soil leach runoff'!A1", "4.6.1.14-15 Soil leach & runoff") -> 4.6.1.14-15 Soil leach & runoff | D18: Dry matter intake (Method 1) | N18: Dry matter intake (Method 2)
D19: Layers | E19: Meat chicken growers | F19: Meat chicken breeders | G19: Other | N19: Layers | O19: Meat chicken growers | P19: Meat chicken breeders | Q19: Other
A20: APPENDICES | D20: ='Input - Poultry'!E16 -> 0.086 | E20: ='Input - Poultry'!F16 -> 0.093 | F20: ='Input - Poultry'!G16 -> 0.103 | G20: ='Input - Poultry'!H16 -> 0.093 | H20: kg/DM/bird/day | N20: ='Input - Poultry'!E21 -> 0.086 | O20: ='Input - Poultry'!F21 -> 0.093 | P20: ='Input - Poultry'!G21 -> 0.103 | Q20: ='Input - Poultry'!H21 -> 0.093 | R20: kg/DM/bird/day
A21: =HYPERLINK("#'Constants - Poultry'!A1", "Constants - Poultry") -> Constants - Poultry
A22: =HYPERLINK("#'Constants - Livestock'!A1", "Constants - Livestock") -> Constants - Livestock | D22: M1_Table_DMD_j_k | N22: M1_Table_DMD_j_k
A23: =HYPERLINK("#'Constants - Common'!A1", "Constants - Common") -> Constants - Common | D23: Dry matter digestibility (Method 1) | N23: Dry matter digestibility (Method 1)
A24: =HYPERLINK("#'Acknowledgements'!A1", "Acknowledgements") -> Acknowledgements | D24: Layers | E24: Meat chicken growers | F24: Meat chicken breeders | G24: Other | N24: Layers | O24: Meat chicken growers | P24: Meat chicken breeders | Q24: Other
D25: ='Input - Poultry'!E17 -> 0.8 | E25: ='Input - Poultry'!F17 -> 0.8 | F25: ='Input - Poultry'!G17 -> 0.8 | G25: ='Input - Poultry'!H17 -> 0.8 | H25: fraction | N25: ='Input - Poultry'!E22 -> 0.8 | O25: ='Input - Poultry'!F22 -> 0.8 | P25: ='Input - Poultry'!G22 -> 0.8 | Q25: ='Input - Poultry'!H22 -> 0.8 | R25: fraction
D27: Table_A_j
D28: Ash content of manure
D29: Layers | E29: Meat chicken growers | F29: Meat chicken breeders | G29: Other
D30: ='Constants - Poultry'!E13 -> 0.18 | E30: ='Constants - Poultry'!F13 -> 0.15 | F30: ='Constants - Poultry'!G13 -> 0.18 | G30: ='Constants - Poultry'!H13 -> 0.15 | H30: fraction
D32: M1_Table_VS_j_k | N32: M2_Table_VS_j_k
D33: Volatile solid production (Method 1) | N33: Volatile solid production (Method 2)
D34: Layers | E34: Meat chicken growers | F34: Meat chicken breeders | G34: Other | N34: Layers | O34: Meat chicken growers | P34: Meat chicken breeders | Q34: Other
D35: {=MMS_Poultry_Methane_Equations.VEERG_4_6_1_1__5_VolatileSolidProduction(D20,D25,D30)} -> 0.014104 | E35: {=MMS_Poultry_Methane_Equations.VEERG_4_6_1_1__5_VolatileSolidProduction(E20,E25,E30)} -> 0.01581 | F35: {=MMS_Poultry_Methane_Equations.VEERG_4_6_1_1__5_VolatileSolidProduction(F20,F25,F30)} -> 0.016892 | G35: {=MMS_Poultry_Methane_Equations.VEERG_4_6_1_1__5_VolatileSolidProduction(G20,G25,G30)} -> 0.01581 | H35: =$E$11 -> kg VS/bird/day | N35: {=MMS_Poultry_Methane_Equations.VEERG_4_6_1_1__5_VolatileSolidProduction(N20,N25,D30)} -> 0.014104 | O35: {=MMS_Poultry_Methane_Equations.VEERG_4_6_1_1__5_VolatileSolidProduction(O20,O25,E30)} -> 0.01581 | P35: {=MMS_Poultry_Methane_Equations.VEERG_4_6_1_1__5_VolatileSolidProduction(P20,P25,F30)} -> 0.016892 | Q35: {=MMS_Poultry_Methane_Equations.VEERG_4_6_1_1__5_VolatileSolidProduction(Q20,Q25,G30)} -> 0.01581 | R35: =$E$11 -> kg VS/bird/day
D39: {=MMS_Poultry_Methane_Equations.VEERG_4_6_1_1__2_Stage1MethaneProduction_Title()} -> Production of methane in treatment stage 1 MMS
D40: {=MMS_Poultry_Methane_Equations.VEERG_4_6_1_1__2_Stage1MethaneProduction_Source()} -> VEERG 2026: 4.4.1.1, Equation (2)
D41: Function name | E41: {=Common_InputFunctions.Utility_DisplayFunctionName(E83)} -> =MMS_Poultry_Methane_Equations.VEERG_4_6_1_1__2_Stage1MethaneProduction
D44: Variable | E44: {=MMS_Poultry_Methane_Equations.VEERG_4_6_1_1__2_Stage1MethaneProduction_Variable()} -> M_jkmT1
D45: Unit | E45: {=MMS_Poultry_Methane_Equations.VEERG_4_6_1_1__2_Stage1MethaneProduction_Unit()} -> kg CH4/bird/day
D47: {=MMS_Poultry_Methane_Equations.VEERG_4_6_1_1__2_Stage1MethaneProduction_Arguments()} -> VS_jk | E47: volatile solid production poultry classes : kg VS/bird/day | G47: ="See " & D32 -> See M1_Table_VS_j_k
D48: BO_j | E48: emissions potential per class : m3 CH4/kg VS | G48: ="See " & D62 -> See Table_B_0_j
D49: MMS_jmT1 | E49: fraction of manure in each primary system : fraction | G49: ="See " & D54 -> See Table_MMS_j_m_T-1
D50: MCF_im | E50: methane conversion factor for temperature zone and MMS : fraction | G50: ="See " & D67 -> See Table_MCF_i_m
...

Sheet 4.6.1.3-4 Direct N20
A1: #VALUE! | C1: 4.6.1.3-4 Manure Direct N2O
A3: =HYPERLINK("#'Home'!A1", "Home") -> Home | D3: Method 1 | N3: Method 2
A4: =HYPERLINK("#'Results'!A1", "Results") -> Results
D5: {=MMS_Poultry_N2ODirect_Equations.VEERG_4_6_1_3__5_NitrogenIntake_Title()} -> Nitrogen intake of poultry
A6: INPUTS | D6: {=MMS_Poultry_N2ODirect_Equations.VEERG_4_6_1_3__5_NitrogenIntake_Source()} -> VEERG 2026: 4.6.1.3, Equation (5)
A7: =HYPERLINK("#'Input - Site'!A1", "Site") -> Site | D7: Function name | E7: {=Common_InputFunctions.Utility_DisplayFunctionName(D30)} -> =MMS_Poultry_N2ODirect_Equations.VEERG_4_6_1_3__5_NitrogenIntake
A8: =HYPERLINK("#'Input - Poultry'!A1", "Poultry") -> Poultry
A10: CALCULATIONS | D10: Variable | E10: {=MMS_Poultry_N2ODirect_Equations.VEERG_4_6_1_3__5_NitrogenIntake_Variable()} -> NI_jk
A11: =HYPERLINK("#'4.6.1.1-2 Methane'!A1", "4.6.1.1-2 Methane") -> 4.6.1.1-2 Methane | D11: Unit | E11: {=MMS_Poultry_N2ODirect_Equations.VEERG_4_6_1_3__5_NitrogenIntake_Unit()} -> kg N/bird/day
A12: =HYPERLINK("#'4.6.1.3-4 Direct N20'!A1", "4.6.1.3-4 Direct N2O") -> 4.6.1.3-4 Direct N2O
A13: =HYPERLINK("#'4.6.1.5-6 Atmos Dep'!A1", "4.6.1.5-6 Soil atm. deposition") -> 4.6.1.5-6 Soil atm. deposition | D13: {=MMS_Poultry_N2ODirect_Equations.VEERG_4_6_1_3__5_NitrogenIntake_Arguments()} -> I_jk | E13: dry matter intake for each class and subclass : kg DM/bird/day | G13: ="See " & D17 -> See M1_Table_I_j_k
A14: =HYPERLINK("#'4.6.1.7-8 Leaching and runoff'!A1", "4.6.1.7-8 Leaching & runoff") -> 4.6.1.7-8 Leaching & runoff | D14: CP_jk | E14: crude protein content of feed : fraction | G14: ="See " & D22 -> See M1_Table_CP_j_k
A15: =HYPERLINK("#'4.6.1.9 Manure applied to soils'!A1", "4.6.1.9 Manure applied to soils") -> 4.6.1.9 Manure applied to soils | D15: 6.25 | E15: factor for converting crude protein into nitrogen : ratio | G15: =$D$15 -> 6.25
A16: =HYPERLINK("#'4.6.1.10-11 Soil direct N2O'!A1", "4.6.1.10-11 Soil direct N2O") -> 4.6.1.10-11 Soil direct N2O
A17: =HYPERLINK("#'4.6.1.12-13 Soil atmos dep'!A1", "4.6.1.12-13 Soil Atm. deposition") -> 4.6.1.12-13 Soil Atm. deposition | D17: M1_Table_I_j_k | N17: M2_Table_I_j_k
A18: =HYPERLINK("#'4.6.1.14-15 Soil leach runoff'!A1", "4.6.1.14-15 Soil leach & runoff") -> 4.6.1.14-15 Soil leach & runoff | D18: Dry matter intake (Method 1) | N18: Dry matter intake (Method 2)
D19: Layers | E19: Meat chicken growers | F19: Meat chicken breeders | G19: Other | N19: Layers | O19: Meat chicken growers | P19: Meat chicken breeders | Q19: Other
A20: APPENDICES | D20: ='Input - Poultry'!E16 -> 0.086 | E20: ='Input - Poultry'!F16 -> 0.093 | F20: ='Input - Poultry'!G16 -> 0.103 | G20: ='Input - Poultry'!H16 -> 0.093 | H20: kg/DM/bird/day | N20: ='Input - Poultry'!E21 -> 0.086 | O20: ='Input - Poultry'!F21 -> 0.093 | P20: ='Input - Poultry'!G21 -> 0.103 | Q20: ='Input - Poultry'!H21 -> 0.093 | R20: kg/DM/bird/day
A21: =HYPERLINK("#'Constants - Poultry'!A1", "Constants - Poultry") -> Constants - Poultry
A22: =HYPERLINK("#'Constants - Livestock'!A1", "Constants - Livestock") -> Constants - Livestock | D22: M1_Table_CP_j_k | N22: M2_Table_CP_j_k
A23: =HYPERLINK("#'Constants - Common'!A1", "Constants - Common") -> Constants - Common | D23: Crude protein content of feed (Method 1) | N23: Crude protein content of feed (Method 2)
A24: =HYPERLINK("#'Acknowledgements'!A1", "Acknowledgements") -> Acknowledgements | D24: Layers | E24: Meat chicken growers | F24: Meat chicken breeders | G24: Other | N24: Layers | O24: Meat chicken growers | P24: Meat chicken breeders | Q24: Other
D25: ='Input - Poultry'!E18 -> 0.19 | E25: ='Input - Poultry'!F18 -> 0.23 | F25: ='Input - Poultry'!G18 -> 0.19 | G25: ='Input - Poultry'!H18 -> 0.23 | H25: fraction | N25: ='Input - Poultry'!E23 -> 0.19 | O25: ='Input - Poultry'!F23 -> 0.23 | P25: ='Input - Poultry'!G23 -> 0.19 | Q25: ='Input - Poultry'!H23 -> 0.23 | R25: fraction
D27: M1_Table_NI_j_k | N27: M1_Table_NI_j_k
D28: Nitrogen intake (Method 1) | N28: Nitrogen intake (Method 1)
D29: Layers | E29: Meat chicken growers | F29: Meat chicken breeders | G29: Other | N29: Layers | O29: Meat chicken growers | P29: Meat chicken breeders | Q29: Other
D30: {=MMS_Poultry_N2ODirect_Equations.VEERG_4_6_1_3__5_NitrogenIntake(D20,D25)} -> 0.0026144 | E30: {=MMS_Poultry_N2ODirect_Equations.VEERG_4_6_1_3__5_NitrogenIntake(E20,E25)} -> 0.0034224 | F30: {=MMS_Poultry_N2ODirect_Equations.VEERG_4_6_1_3__5_NitrogenIntake(F20,F25)} -> 0.0031312 | G30: {=MMS_Poultry_N2ODirect_Equations.VEERG_4_6_1_3__5_NitrogenIntake(G20,G25)} -> 0.0034224 | H30: =$E$11 -> kg N/bird/day | N30: {=MMS_Poultry_N2ODirect_Equations.VEERG_4_6_1_3__5_NitrogenIntake(N20,N25)} -> 0.0026144 | O30: {=MMS_Poultry_N2ODirect_Equations.VEERG_4_6_1_3__5_NitrogenIntake(O20,O25)} -> 0.0034224 | P30: {=MMS_Poultry_N2ODirect_Equations.VEERG_4_6_1_3__5_NitrogenIntake(P20,P25)} -> 0.0031312 | Q30: {=MMS_Poultry_N2ODirect_Equations.VEERG_4_6_1_3__5_NitrogenIntake(Q20,Q25)} -> 0.0034224 | R30: =$E$11 -> kg N/bird/day
D34: {=MMS_Poultry_N2ODirect_Equations.VEERG_4_6_1_3__4_NitrogenExcretionPerBird_Title()} -> Nitrogen excretion per bird per day
D35: {=MMS_Poultry_N2ODirect_Equations.VEERG_4_6_1_3__4_NitrogenExcretionPerBird_Source()} -> VEERG 2026: 4.6.1.3, Equation (4)
D36: Function name | E36: {=Common_InputFunctions.Utility_DisplayFunctionName(D53)} -> =MMS_Poultry_N2ODirect_Equations.VEERG_4_6_1_3__4_NitrogenExcretionPerBird
D39: Variable | E39: {=MMS_Poultry_N2ODirect_Equations.VEERG_4_6_1_3__4_NitrogenExcretionPerBird_Variable()} -> NE_jk
D40: Unit | E40: {=MMS_Poultry_N2ODirect_Equations.VEERG_4_6_1_3__4_NitrogenExcretionPerBird_Unit()} -> kg N/bird/day
D42: {=MMS_Poultry_N2ODirect_Equations.VEERG_4_6_1_3__4_NitrogenExcretionPerBird_Arguments()} -> NI_jk | E42: nitrogen intake : kg N/bird/day | G42: ="See " & D27 -> See M1_Table_NI_j_k
D43: NR_jk | E43: nitrogen retention expressed as a fraction of intake : fraction
D45: Table_NR_j_k
D46: Nitrogen retention rate
D47: Layers | E47: Meat chicken growers | F47: Meat chicken breeders | G47: Other
D48: ='Constants - Poultry'!E12 -> 0.35 | E48: ='Constants - Poultry'!F12 -> 0.47 | F48: ='Constants - Poultry'!G12 -> 0.32 | G48: ='Constants - Poultry'!H12 -> 0.47 | H48: fraction
D50: M1_Table_NE_j_k | N50: M1_Table_NE_j_k
D51: Nitrogen excretion (Method 1) | N51: Nitrogen excretion (Method 1)
...

Sheet 4.6.1.5-6 Atmos Dep
A1: #VALUE! | C1: 4.6.1.5-6 Atmospheric deposition N2O
A3: =HYPERLINK("#'Home'!A1", "Home") -> Home | D3: Method 1 | N3: Method 2
A4: =HYPERLINK("#'Results'!A1", "Results") -> Results
D5: {=MMS_Poultry_AtmosphericDeposition_Equations.VEERG_4_6_1_5__2_TotalNitrogenVolatilisedFromMMS_Title()} -> Total nitrogen volatilised from manure management systems
A6: INPUTS | D6: {=MMS_Poultry_AtmosphericDeposition_Equations.VEERG_4_6_1_5__2_TotalNitrogenVolatilisedFromMMS_Source()} -> VEERG 2026: 4.6.1.5, Equation (2)
A7: =HYPERLINK("#'Input - Site'!A1", "Site") -> Site | D7: Function name | E7: {=Common_InputFunctions.Utility_DisplayFunctionName(F51)} -> =MMS_Poultry_AtmosphericDeposition_Equations.VEERG_4_6_1_5__2_TotalNitrogenVolatilisedFromMMS
A8: =HYPERLINK("#'Input - Poultry'!A1", "Poultry") -> Poultry
A10: CALCULATIONS | D10: Variable | E10: {=MMS_Poultry_AtmosphericDeposition_Equations.VEERG_4_6_1_5__2_TotalNitrogenVolatilisedFromMMS_Variable()} -> MMS_ATMOS
A11: =HYPERLINK("#'4.6.1.1-2 Methane'!A1", "4.6.1.1-2 Methane") -> 4.6.1.1-2 Methane | D11: Unit | E11: {=MMS_Poultry_AtmosphericDeposition_Equations.VEERG_4_6_1_5__2_TotalNitrogenVolatilisedFromMMS_Unit()} -> kg N
A12: =HYPERLINK("#'4.6.1.3-4 Direct N20'!A1", "4.6.1.3-4 Direct N2O") -> 4.6.1.3-4 Direct N2O
A13: =HYPERLINK("#'4.6.1.5-6 Atmos Dep'!A1", "4.6.1.5-6 Soil atm. deposition") -> 4.6.1.5-6 Soil atm. deposition | D13: {=MMS_Poultry_AtmosphericDeposition_Equations.VEERG_4_6_1_5__2_TotalNitrogenVolatilisedFromMMS_Arguments()} -> MN_jkmT | E13: nitrogen in each treatment stage MMS (excluding MN_jkm13T2) : kg N | G13: ="See " & D16 -> See M1_Table_MN_j_k_m_T
A14: =HYPERLINK("#'4.6.1.7-8 Leaching and runoff'!A1", "4.6.1.7-8 Leaching & runoff") -> 4.6.1.7-8 Leaching & runoff | D14: FracGASM_mT | E14: fraction of N volatilised in each MMS : (kg NH3-N + NOx-N)/kg N | G14: ="See " & D36 -> See Table_FracGASM_m_T
A15: =HYPERLINK("#'4.6.1.9 Manure applied to soils'!A1", "4.6.1.9 Manure applied to soils") -> 4.6.1.9 Manure applied to soils
A16: =HYPERLINK("#'4.6.1.10-11 Soil direct N2O'!A1", "4.6.1.10-11 Soil direct N2O") -> 4.6.1.10-11 Soil direct N2O | D16: M1_Table_MN_j_k_m_T | N16: M2_Table_MN_j_k_m_T
A17: =HYPERLINK("#'4.6.1.12-13 Soil atmos dep'!A1", "4.6.1.12-13 Soil Atm. deposition") -> 4.6.1.12-13 Soil Atm. deposition | D17: Nitrogen in each MMS (Method 1) | N17: Nitrogen in each MMS (Method 2)
A18: =HYPERLINK("#'4.6.1.14-15 Soil leach runoff'!A1", "4.6.1.14-15 Soil leach & runoff") -> 4.6.1.14-15 Soil leach & runoff | D18: Stage 1 MMS | E18: Stage 2 MMS | F18: Layers | G18: Meat chicken growers | H18: Meat chicken breeders | I18: Other | N18: Stage 1 MMS | O18: Stage 2 MMS | P18: Layers | Q18: Meat chicken growers | R18: Meat chicken breeders | S18: Other
D19: ='Input - Poultry'!$D$30 -> Poultry manure with bedding | E19: N/A | F19: ='4.6.1.3-4 Direct N20'!E108 -> 5.09808 | G19: ='4.6.1.3-4 Direct N20'!F108 -> 5.441616 | H19: ='4.6.1.3-4 Direct N20'!G108 -> 6.387648 | I19: ='4.6.1.3-4 Direct N20'!H108 -> 5.441616 | J19: kg N | N19: ='Input - Poultry'!$D$30 -> Poultry manure with bedding | O19: N/A | P19: ='4.6.1.3-4 Direct N20'!O108 -> 5.09808 | Q19: ='4.6.1.3-4 Direct N20'!P108 -> 5.441616 | R19: ='4.6.1.3-4 Direct N20'!Q108 -> 6.387648 | S19: ='4.6.1.3-4 Direct N20'!R108 -> 5.441616 | T19: kg N
A20: APPENDICES | D20: ='Input - Poultry'!$D$31 -> Belt manure removal | E20: N/A | F20: ='4.6.1.3-4 Direct N20'!E109 -> 5.09808 | G20: ='4.6.1.3-4 Direct N20'!F109 -> 5.441616 | H20: ='4.6.1.3-4 Direct N20'!G109 -> 6.387648 | I20: ='4.6.1.3-4 Direct N20'!H109 -> 5.441616 | J20: kg N | N20: ='Input - Poultry'!$D$31 -> Belt manure removal | O20: N/A | P20: ='4.6.1.3-4 Direct N20'!O109 -> 5.09808 | Q20: ='4.6.1.3-4 Direct N20'!P109 -> 5.441616 | R20: ='4.6.1.3-4 Direct N20'!Q109 -> 6.387648 | S20: ='4.6.1.3-4 Direct N20'!R109 -> 5.441616 | T20: kg N
A21: =HYPERLINK("#'Constants - Poultry'!A1", "Constants - Poultry") -> Constants - Poultry | D21: ='Input - Poultry'!$D$32 -> Manure stored in house | E21: N/A | F21: ='4.6.1.3-4 Direct N20'!E110 -> 5.09808 | G21: ='4.6.1.3-4 Direct N20'!F110 -> 5.441616 | H21: ='4.6.1.3-4 Direct N20'!G110 -> 6.387648 | I21: ='4.6.1.3-4 Direct N20'!H110 -> 5.441616 | J21: kg N | N21: ='Input - Poultry'!$D$32 -> Manure stored in house | O21: N/A | P21: ='4.6.1.3-4 Direct N20'!O110 -> 5.09808 | Q21: ='4.6.1.3-4 Direct N20'!P110 -> 5.441616 | R21: ='4.6.1.3-4 Direct N20'!Q110 -> 6.387648 | S21: ='4.6.1.3-4 Direct N20'!R110 -> 5.441616 | T21: kg N
A22: =HYPERLINK("#'Constants - Livestock'!A1", "Constants - Livestock") -> Constants - Livestock | D22: ='Input - Poultry'!$D$33 -> Pasture range and paddock | E22: N/A | F22: ='4.6.1.3-4 Direct N20'!E111 -> 1.69936 | G22: ='4.6.1.3-4 Direct N20'!F111 -> 1.813872 | H22: ='4.6.1.3-4 Direct N20'!G111 -> 2.129216 | I22: ='4.6.1.3-4 Direct N20'!H111 -> 1.813872 | J22: kg N | N22: ='Input - Poultry'!$D$33 -> Pasture range and paddock | O22: N/A | P22: ='4.6.1.3-4 Direct N20'!O111 -> 1.69936 | Q22: ='4.6.1.3-4 Direct N20'!P111 -> 1.813872 | R22: ='4.6.1.3-4 Direct N20'!Q111 -> 2.129216 | S22: ='4.6.1.3-4 Direct N20'!R111 -> 1.813872 | T22: kg N
A23: =HYPERLINK("#'Constants - Common'!A1", "Constants - Common") -> Constants - Common | D23: ='Input - Poultry'!$D$30 -> Poultry manure with bedding | E23: ='Input - Poultry'!$D$38 -> Solid storage | F23: ='4.6.1.3-4 Direct N20'!F186 -> 0.71271158 | G23: ='4.6.1.3-4 Direct N20'!G186 -> 0.76073792 | H23: ='4.6.1.3-4 Direct N20'!H186 -> 0.89299319 | I23: ='4.6.1.3-4 Direct N20'!I186 -> 0.76073792 | J23: kg N | N23: ='Input - Poultry'!$D$30 -> Poultry manure with bedding | O23: ='Input - Poultry'!$D$38 -> Solid storage | P23: ='4.6.1.3-4 Direct N20'!P186 -> 0.71271158 | Q23: ='4.6.1.3-4 Direct N20'!Q186 -> 0.76073792 | R23: ='4.6.1.3-4 Direct N20'!R186 -> 0.89299319 | S23: ='4.6.1.3-4 Direct N20'!S186 -> 0.76073792 | T23: kg N
A24: =HYPERLINK("#'Acknowledgements'!A1", "Acknowledgements") -> Acknowledgements | E24: ='Input - Poultry'!$D$39 -> Composting (passive windrow) | F24: ='4.6.1.3-4 Direct N20'!F187 -> 0.71271158 | G24: ='4.6.1.3-4 Direct N20'!G187 -> 0.76073792 | H24: ='4.6.1.3-4 Direct N20'!H187 -> 0.89299319 | I24: ='4.6.1.3-4 Direct N20'!I187 -> 0.76073792 | J24: kg N | O24: ='Input - Poultry'!$D$39 -> Composting (passive windrow) | P24: ='4.6.1.3-4 Direct N20'!P187 -> 0.71271158 | Q24: ='4.6.1.3-4 Direct N20'!Q187 -> 0.76073792 | R24: ='4.6.1.3-4 Direct N20'!R187 -> 0.89299319 | S24: ='4.6.1.3-4 Direct N20'!S187 -> 0.76073792 | T24: kg N
E25: ='Input - Poultry'!$D$40 -> Digester / covered lagoons | F25: ='4.6.1.3-4 Direct N20'!F188 -> 0.71271158 | G25: ='4.6.1.3-4 Direct N20'!G188 -> 0.76073792 | H25: ='4.6.1.3-4 Direct N20'!H188 -> 0.89299319 | I25: ='4.6.1.3-4 Direct N20'!I188 -> 0.76073792 | J25: kg N | O25: ='Input - Poultry'!$D$40 -> Digester / covered lagoons | P25: ='4.6.1.3-4 Direct N20'!P188 -> 0.71271158 | Q25: ='4.6.1.3-4 Direct N20'!Q188 -> 0.76073792 | R25: ='4.6.1.3-4 Direct N20'!R188 -> 0.89299319 | S25: ='4.6.1.3-4 Direct N20'!S188 -> 0.76073792 | T25: kg N
E26: ='Input - Poultry'!$D$41 -> Direct processing | F26: ='4.6.1.3-4 Direct N20'!F189 -> 0.71271158 | G26: ='4.6.1.3-4 Direct N20'!G189 -> 0.76073792 | H26: ='4.6.1.3-4 Direct N20'!H189 -> 0.89299319 | I26: ='4.6.1.3-4 Direct N20'!I189 -> 0.76073792 | J26: kg N | O26: ='Input - Poultry'!$D$41 -> Direct processing | P26: ='4.6.1.3-4 Direct N20'!P189 -> 0.71271158 | Q26: ='4.6.1.3-4 Direct N20'!Q189 -> 0.76073792 | R26: ='4.6.1.3-4 Direct N20'!R189 -> 0.89299319 | S26: ='4.6.1.3-4 Direct N20'!S189 -> 0.76073792 | T26: kg N
D27: ='Input - Poultry'!$D$31 -> Belt manure removal | E27: ='Input - Poultry'!$D$45 -> Solid storage | F27: ='4.6.1.3-4 Direct N20'!F190 -> 0.96761558 | G27: ='4.6.1.3-4 Direct N20'!G190 -> 1.0328187 | H27: ='4.6.1.3-4 Direct N20'!H190 -> 1.2123756 | I27: ='4.6.1.3-4 Direct N20'!I190 -> 1.0328187 | J27: kg N | N27: ='Input - Poultry'!$D$31 -> Belt manure removal | O27: ='Input - Poultry'!$D$45 -> Solid storage | P27: ='4.6.1.3-4 Direct N20'!P190 -> 0.96761558 | Q27: ='4.6.1.3-4 Direct N20'!Q190 -> 1.0328187 | R27: ='4.6.1.3-4 Direct N20'!R190 -> 1.2123756 | S27: ='4.6.1.3-4 Direct N20'!S190 -> 1.0328187 | T27: kg N
E28: ='Input - Poultry'!$D$46 -> Composting (passive windrow) | F28: ='4.6.1.3-4 Direct N20'!F191 -> 0.96761558 | G28: ='4.6.1.3-4 Direct N20'!G191 -> 1.0328187 | H28: ='4.6.1.3-4 Direct N20'!H191 -> 1.2123756 | I28: ='4.6.1.3-4 Direct N20'!I191 -> 1.0328187 | J28: kg N | O28: ='Input - Poultry'!$D$46 -> Composting (passive windrow) | P28: ='4.6.1.3-4 Direct N20'!P191 -> 0.96761558 | Q28: ='4.6.1.3-4 Direct N20'!Q191 -> 1.0328187 | R28: ='4.6.1.3-4 Direct N20'!R191 -> 1.2123756 | S28: ='4.6.1.3-4 Direct N20'!S191 -> 1.0328187 | T28: kg N
E29: ='Input - Poultry'!$D$47 -> Digester / covered lagoons | F29: ='4.6.1.3-4 Direct N20'!F192 -> 0.96761558 | G29: ='4.6.1.3-4 Direct N20'!G192 -> 1.0328187 | H29: ='4.6.1.3-4 Direct N20'!H192 -> 1.2123756 | I29: ='4.6.1.3-4 Direct N20'!I192 -> 1.0328187 | J29: kg N | O29: ='Input - Poultry'!$D$47 -> Digester / covered lagoons | P29: ='4.6.1.3-4 Direct N20'!P192 -> 0.96761558 | Q29: ='4.6.1.3-4 Direct N20'!Q192 -> 1.0328187 | R29: ='4.6.1.3-4 Direct N20'!R192 -> 1.2123756 | S29: ='4.6.1.3-4 Direct N20'!S192 -> 1.0328187 | T29: kg N
E30: ='Input - Poultry'!$D$48 -> Direct processing | F30: ='4.6.1.3-4 Direct N20'!F193 -> 0.96761558 | G30: ='4.6.1.3-4 Direct N20'!G193 -> 1.0328187 | H30: ='4.6.1.3-4 Direct N20'!H193 -> 1.2123756 | I30: ='4.6.1.3-4 Direct N20'!I193 -> 1.0328187 | J30: kg N | O30: ='Input - Poultry'!$D$48 -> Direct processing | P30: ='4.6.1.3-4 Direct N20'!P193 -> 0.96761558 | Q30: ='4.6.1.3-4 Direct N20'!Q193 -> 1.0328187 | R30: ='4.6.1.3-4 Direct N20'!R193 -> 1.2123756 | S30: ='4.6.1.3-4 Direct N20'!S193 -> 1.0328187 | T30: kg N
D31: ='Input - Poultry'!$D$32 -> Manure stored in house | E31: ='Input - Poultry'!$D$52 -> Solid storage | F31: ='4.6.1.3-4 Direct N20'!F194 -> 0.61074998 | G31: ='4.6.1.3-4 Direct N20'!G194 -> 0.6519056 | H31: ='4.6.1.3-4 Direct N20'!H194 -> 0.76524023 | I31: ='4.6.1.3-4 Direct N20'!I194 -> 0.6519056 | J31: kg N | N31: ='Input - Poultry'!$D$32 -> Manure stored in house | O31: ='Input - Poultry'!$D$52 -> Solid storage | P31: ='4.6.1.3-4 Direct N20'!P194 -> 0.61074998 | Q31: ='4.6.1.3-4 Direct N20'!Q194 -> 0.6519056 | R31: ='4.6.1.3-4 Direct N20'!R194 -> 0.76524023 | S31: ='4.6.1.3-4 Direct N20'!S194 -> 0.6519056 | T31: kg N
E32: ='Input - Poultry'!$D$53 -> Composting (passive windrow) | F32: ='4.6.1.3-4 Direct N20'!F195 -> 0.61074998 | G32: ='4.6.1.3-4 Direct N20'!G195 -> 0.6519056 | H32: ='4.6.1.3-4 Direct N20'!H195 -> 0.76524023 | I32: ='4.6.1.3-4 Direct N20'!I195 -> 0.6519056 | J32: kg N | O32: ='Input - Poultry'!$D$53 -> Composting (passive windrow) | P32: ='4.6.1.3-4 Direct N20'!P195 -> 0.61074998 | Q32: ='4.6.1.3-4 Direct N20'!Q195 -> 0.6519056 | R32: ='4.6.1.3-4 Direct N20'!R195 -> 0.76524023 | S32: ='4.6.1.3-4 Direct N20'!S195 -> 0.6519056 | T32: kg N
E33: ='Input - Poultry'!$D$54 -> Digester / covered lagoons | F33: ='4.6.1.3-4 Direct N20'!F196 -> 0.61074998 | G33: ='4.6.1.3-4 Direct N20'!G196 -> 0.6519056 | H33: ='4.6.1.3-4 Direct N20'!H196 -> 0.76524023 | I33: ='4.6.1.3-4 Direct N20'!I196 -> 0.6519056 | J33: kg N | O33: ='Input - Poultry'!$D$54 -> Digester / covered lagoons | P33: ='4.6.1.3-4 Direct N20'!P196 -> 0.61074998 | Q33: ='4.6.1.3-4 Direct N20'!Q196 -> 0.6519056 | R33: ='4.6.1.3-4 Direct N20'!R196 -> 0.76524023 | S33: ='4.6.1.3-4 Direct N20'!S196 -> 0.6519056 | T33: kg N
E34: ='Input - Poultry'!$D$55 -> Direct processing | F34: ='4.6.1.3-4 Direct N20'!F197 -> 0.61074998 | G34: ='4.6.1.3-4 Direct N20'!G197 -> 0.6519056 | H34: ='4.6.1.3-4 Direct N20'!H197 -> 0.76524023 | I34: ='4.6.1.3-4 Direct N20'!I197 -> 0.6519056 | J34: kg N | O34: ='Input - Poultry'!$D$55 -> Direct processing | P34: ='4.6.1.3-4 Direct N20'!P197 -> 0.61074998 | Q34: ='4.6.1.3-4 Direct N20'!Q197 -> 0.6519056 | R34: ='4.6.1.3-4 Direct N20'!R197 -> 0.76524023 | S34: ='4.6.1.3-4 Direct N20'!S197 -> 0.6519056 | T34: kg N
D36: Table_FracGASM_m_T
D37: Faction N volatilised in MMS
D38: Stage 1 MMS | E38: FracGASM
D39: ='Constants - Poultry'!$D$29 -> Poultry manure with bedding | E39: {=Common_InputFunctions.Utility_LookupValueInTableNumber(D39, Table_SourceData_Poultry_FracGASM[NIR reference],Table_SourceData_Poultry_FracGASM[FracGASMmT])} -> 0.3
D40: ='Constants - Poultry'!$D$30 -> Belt manure removal | E40: {=Common_InputFunctions.Utility_LookupValueInTableNumber(D40, Table_SourceData_Poultry_FracGASM[NIR reference],Table_SourceData_Poultry_FracGASM[FracGASMmT])} -> 0.05
D41: ='Constants - Poultry'!$D$31 -> Manure stored in house | E41: {=Common_InputFunctions.Utility_LookupValueInTableNumber(D41, Table_SourceData_Poultry_FracGASM[NIR reference],Table_SourceData_Poultry_FracGASM[FracGASMmT])} -> 0.4
D42: ='Constants - Poultry'!$D$32 -> Pasture range and paddock | E42: {=Common_InputFunctions.Utility_LookupValueInTableNumber(D42, Table_SourceData_Poultry_FracGASM[NIR reference],Table_SourceData_Poultry_FracGASM[FracGASMmT])} -> 0
D43: ='Constants - Poultry'!$D$33 -> Solid storage | E43: {=Common_InputFunctions.Utility_LookupValueInTableNumber(D43, Table_SourceData_Poultry_FracGASM[NIR reference],Table_SourceData_Poultry_FracGASM[FracGASMmT])} -> 0.2
...

Sheet 4.6.1.7-8 Leaching and runoff
A1: #VALUE! | C1: 4.6.1.7-8 Leaching and runoff
A3: =HYPERLINK("#'Home'!A1", "Home") -> Home | D3: Method 1 | N3: Method 2
A4: =HYPERLINK("#'Results'!A1", "Results") -> Results
D5: {=MMS_Poultry_LeachingAndRunoff_Equations.VEERG_4_6_1_7__2_MassOfNitrogenLostToLeachingAndRunoffFromSolidStorage_Title()} -> Mass of nitrogen lost to leaching and runoff from solid storage systems
A6: INPUTS | D6: {=MMS_Poultry_LeachingAndRunoff_Equations.VEERG_4_6_1_7__2_MassOfNitrogenLostToLeachingAndRunoffFromSolidStorage_Source()} -> VEERG 2026: 4.6.1.7, Equation (2)
A7: =HYPERLINK("#'Input - Site'!A1", "Site") -> Site | D7: Function name | E7: {=Common_InputFunctions.Utility_DisplayFunctionName(F30)} -> =MMS_Poultry_LeachingAndRunoff_Equations.VEERG_4_6_1_7__2_MassOfNitrogenLostToLeachingAndRunoffFromSolidStorage
A8: =HYPERLINK("#'Input - Poultry'!A1", "Poultry") -> Poultry
A10: CALCULATIONS | D10: Variable | E10: {=MMS_Poultry_LeachingAndRunoff_Equations.VEERG_4_6_1_7__2_MassOfNitrogenLostToLeachingAndRunoffFromSolidStorage_Variable()} -> MNLeach_jkm4
A11: =HYPERLINK("#'4.6.1.1-2 Methane'!A1", "4.6.1.1-2 Methane") -> 4.6.1.1-2 Methane | D11: Unit | E11: {=MMS_Poultry_LeachingAndRunoff_Equations.VEERG_4_6_1_7__2_MassOfNitrogenLostToLeachingAndRunoffFromSolidStorage_Unit()} -> kg N
A12: =HYPERLINK("#'4.6.1.3-4 Direct N20'!A1", "4.6.1.3-4 Direct N2O") -> 4.6.1.3-4 Direct N2O
A13: =HYPERLINK("#'4.6.1.5-6 Atmos Dep'!A1", "4.6.1.5-6 Soil atm. deposition") -> 4.6.1.5-6 Soil atm. deposition | D13: {=MMS_Poultry_LeachingAndRunoff_Equations.VEERG_4_6_1_7__2_MassOfNitrogenLostToLeachingAndRunoffFromSolidStorage_Arguments()} -> MN_jkm4T1 | E13: nitrogen in solid storage MMS treatment stage 1 : kg N | G13: ="See " & D20 -> See M1_Table_MN_j_k_m-4
A14: =HYPERLINK("#'4.6.1.7-8 Leaching and runoff'!A1", "4.6.1.7-8 Leaching & runoff") -> 4.6.1.7-8 Leaching & runoff | D14: FracWET | E14: fraction of N available for leaching and runoff : fraction | G14: =Common_InputFunctions.CommonCropping_GetFracWET(G16,G18,Table_SourceData_FracWET[Is in leaching zone],Table_SourceData_FracWET[FracWET],Table_SourceData_FracWETIrrigation[Irrigation type i],Table_SourceData_FracWETIrrigation[FracWET]) -> 1
A15: =HYPERLINK("#'4.6.1.9 Manure applied to soils'!A1", "4.6.1.9 Manure applied to soils") -> 4.6.1.9 Manure applied to soils | D15: FracLEACH_MS | E15: fraction of N lost through leaching and runoff : fraction | G15: ='Constants - Poultry'!$E$111 -> 0.02
A16: =HYPERLINK("#'4.6.1.10-11 Soil direct N2O'!A1", "4.6.1.10-11 Soil direct N2O") -> 4.6.1.10-11 Soil direct N2O | D16: z | E16: location in leaching zone | G16: ='Input - Site'!$E$23 -> NO - Not in leaching zone
A17: =HYPERLINK("#'4.6.1.12-13 Soil atmos dep'!A1", "4.6.1.12-13 Soil Atm. deposition") -> 4.6.1.12-13 Soil Atm. deposition | D17: j | E17: production system | G17: ='Input - Poultry'!$E$59 -> Crop
A18: =HYPERLINK("#'4.6.1.14-15 Soil leach runoff'!A1", "4.6.1.14-15 Soil leach & runoff") -> 4.6.1.14-15 Soil leach & runoff | D18: ir | E18: irrigation method | G18: ='Input - Poultry'!$E$60 -> Sprinkler irrigation
A20: APPENDICES | D20: M1_Table_MN_j_k_m-4 | N20: M1_Table_MN_j_k_m-4
A21: =HYPERLINK("#'Constants - Poultry'!A1", "Constants - Poultry") -> Constants - Poultry | D21: Nitrogen in solid storage MMS (Method 1) | N21: Nitrogen in solid storage MMS (Method 1)
A22: =HYPERLINK("#'Constants - Livestock'!A1", "Constants - Livestock") -> Constants - Livestock | D22: Stage 1 MMS | E22: Stage 2 MMS | F22: Layers | G22: Meat chicken growers | H22: Meat chicken breeders | I22: Other | N22: Stage 1 MMS | O22: Stage 2 MMS | P22: Layers | Q22: Meat chicken growers | R22: Meat chicken breeders | S22: Other
A23: =HYPERLINK("#'Constants - Common'!A1", "Constants - Common") -> Constants - Common | D23: ='Input - Poultry'!$D$30 -> Poultry manure with bedding | E23: ='Input - Poultry'!$D$38 -> Solid storage | F23: ='4.6.1.3-4 Direct N20'!F186 -> 0.71271158 | G23: ='4.6.1.3-4 Direct N20'!G186 -> 0.76073792 | H23: ='4.6.1.3-4 Direct N20'!H186 -> 0.89299319 | I23: ='4.6.1.3-4 Direct N20'!I186 -> 0.76073792 | J23: kg N | N23: ='Input - Poultry'!$D$30 -> Poultry manure with bedding | O23: ='Input - Poultry'!$D$38 -> Solid storage | P23: ='4.6.1.3-4 Direct N20'!P186 -> 0.71271158 | Q23: ='4.6.1.3-4 Direct N20'!Q186 -> 0.76073792 | R23: ='4.6.1.3-4 Direct N20'!R186 -> 0.89299319 | S23: ='4.6.1.3-4 Direct N20'!S186 -> 0.76073792 | T23: kg N
A24: =HYPERLINK("#'Acknowledgements'!A1", "Acknowledgements") -> Acknowledgements | D24: ='Input - Poultry'!$D$31 -> Belt manure removal | E24: ='Input - Poultry'!$D$45 -> Solid storage | F24: ='4.6.1.3-4 Direct N20'!F190 -> 0.96761558 | G24: ='4.6.1.3-4 Direct N20'!G190 -> 1.0328187 | H24: ='4.6.1.3-4 Direct N20'!H190 -> 1.2123756 | I24: ='4.6.1.3-4 Direct N20'!I190 -> 1.0328187 | J24: kg N | N24: ='Input - Poultry'!$D$31 -> Belt manure removal | O24: ='Input - Poultry'!$D$45 -> Solid storage | P24: ='4.6.1.3-4 Direct N20'!P190 -> 0.96761558 | Q24: ='4.6.1.3-4 Direct N20'!Q190 -> 1.0328187 | R24: ='4.6.1.3-4 Direct N20'!R190 -> 1.2123756 | S24: ='4.6.1.3-4 Direct N20'!S190 -> 1.0328187 | T24: kg N
D25: ='Input - Poultry'!$D$32 -> Manure stored in house | E25: ='Input - Poultry'!$D$52 -> Solid storage | F25: ='4.6.1.3-4 Direct N20'!F194 -> 0.61074998 | G25: ='4.6.1.3-4 Direct N20'!G194 -> 0.6519056 | H25: ='4.6.1.3-4 Direct N20'!H194 -> 0.76524023 | I25: ='4.6.1.3-4 Direct N20'!I194 -> 0.6519056 | J25: kg N | N25: ='Input - Poultry'!$D$32 -> Manure stored in house | O25: ='Input - Poultry'!$D$52 -> Solid storage | P25: ='4.6.1.3-4 Direct N20'!P194 -> 0.61074998 | Q25: ='4.6.1.3-4 Direct N20'!Q194 -> 0.6519056 | R25: ='4.6.1.3-4 Direct N20'!R194 -> 0.76524023 | S25: ='4.6.1.3-4 Direct N20'!S194 -> 0.6519056 | T25: kg N
D27: M1_Table_MN_Leach_j_k_m-4 | N27: M2_Table_MN_j_k_m-4
D28: Mass of N lost to leaching and runoff (Method 1) | N28: Mass of N lost to leaching and runoff (Method 2)
D29: Stage 1 MMS | E29: Stage 2 MMS | F29: Layers | G29: Meat chicken growers | H29: Meat chicken breeders | I29: Other | N29: Stage 1 MMS | O29: Stage 2 MMS | P29: Layers | Q29: Meat chicken growers | R29: Meat chicken breeders | S29: Other
D30: ='Input - Poultry'!$D$30 -> Poultry manure with bedding | E30: ='Input - Poultry'!$D$38 -> Solid storage | F30: {=MMS_Poultry_LeachingAndRunoff_Equations.VEERG_4_6_1_7__2_MassOfNitrogenLostToLeachingAndRunoffFromSolidStorage(F23,$G$14,$G$15)} -> 0.014254232 | G30: {=MMS_Poultry_LeachingAndRunoff_Equations.VEERG_4_6_1_7__2_MassOfNitrogenLostToLeachingAndRunoffFromSolidStorage(G23,$G$14,$G$15)} -> 0.015214758 | H30: {=MMS_Poultry_LeachingAndRunoff_Equations.VEERG_4_6_1_7__2_MassOfNitrogenLostToLeachingAndRunoffFromSolidStorage(H23,$G$14,$G$15)} -> 0.017859864 | I30: {=MMS_Poultry_LeachingAndRunoff_Equations.VEERG_4_6_1_7__2_MassOfNitrogenLostToLeachingAndRunoffFromSolidStorage(I23,$G$14,$G$15)} -> 0.015214758 | J30: =$E$11 -> kg N | N30: ='Input - Poultry'!$D$30 -> Poultry manure with bedding | O30: ='Input - Poultry'!$D$38 -> Solid storage | P30: {=MMS_Poultry_LeachingAndRunoff_Equations.VEERG_4_6_1_7__2_MassOfNitrogenLostToLeachingAndRunoffFromSolidStorage(P23,$G$14,$G$15)} -> 0.014254232 | Q30: {=MMS_Poultry_LeachingAndRunoff_Equations.VEERG_4_6_1_7__2_MassOfNitrogenLostToLeachingAndRunoffFromSolidStorage(Q23,$G$14,$G$15)} -> 0.015214758 | R30: {=MMS_Poultry_LeachingAndRunoff_Equations.VEERG_4_6_1_7__2_MassOfNitrogenLostToLeachingAndRunoffFromSolidStorage(R23,$G$14,$G$15)} -> 0.017859864 | S30: {=MMS_Poultry_LeachingAndRunoff_Equations.VEERG_4_6_1_7__2_MassOfNitrogenLostToLeachingAndRunoffFromSolidStorage(S23,$G$14,$G$15)} -> 0.015214758 | T30: =$E$11 -> kg N
D31: ='Input - Poultry'!$D$31 -> Belt manure removal | E31: ='Input - Poultry'!$D$45 -> Solid storage | F31: {=MMS_Poultry_LeachingAndRunoff_Equations.VEERG_4_6_1_7__2_MassOfNitrogenLostToLeachingAndRunoffFromSolidStorage(F24,$G$14,$G$15)} -> 0.019352312 | G31: {=MMS_Poultry_LeachingAndRunoff_Equations.VEERG_4_6_1_7__2_MassOfNitrogenLostToLeachingAndRunoffFromSolidStorage(G24,$G$14,$G$15)} -> 0.020656374 | H31: {=MMS_Poultry_LeachingAndRunoff_Equations.VEERG_4_6_1_7__2_MassOfNitrogenLostToLeachingAndRunoffFromSolidStorage(H24,$G$14,$G$15)} -> 0.024247512 | I31: {=MMS_Poultry_LeachingAndRunoff_Equations.VEERG_4_6_1_7__2_MassOfNitrogenLostToLeachingAndRunoffFromSolidStorage(I24,$G$14,$G$15)} -> 0.020656374 | J31: =$E$11 -> kg N | N31: ='Input - Poultry'!$D$31 -> Belt manure removal | O31: ='Input - Poultry'!$D$45 -> Solid storage | P31: {=MMS_Poultry_LeachingAndRunoff_Equations.VEERG_4_6_1_7__2_MassOfNitrogenLostToLeachingAndRunoffFromSolidStorage(P24,$G$14,$G$15)} -> 0.019352312 | Q31: {=MMS_Poultry_LeachingAndRunoff_Equations.VEERG_4_6_1_7__2_MassOfNitrogenLostToLeachingAndRunoffFromSolidStorage(Q24,$G$14,$G$15)} -> 0.020656374 | R31: {=MMS_Poultry_LeachingAndRunoff_Equations.VEERG_4_6_1_7__2_MassOfNitrogenLostToLeachingAndRunoffFromSolidStorage(R24,$G$14,$G$15)} -> 0.024247512 | S31: {=MMS_Poultry_LeachingAndRunoff_Equations.VEERG_4_6_1_7__2_MassOfNitrogenLostToLeachingAndRunoffFromSolidStorage(S24,$G$14,$G$15)} -> 0.020656374 | T31: =$E$11 -> kg N
D32: ='Input - Poultry'!$D$32 -> Manure stored in house | E32: ='Input - Poultry'!$D$52 -> Solid storage | F32: {=MMS_Poultry_LeachingAndRunoff_Equations.VEERG_4_6_1_7__2_MassOfNitrogenLostToLeachingAndRunoffFromSolidStorage(F25,$G$14,$G$15)} -> 0.012215 | G32: {=MMS_Poultry_LeachingAndRunoff_Equations.VEERG_4_6_1_7__2_MassOfNitrogenLostToLeachingAndRunoffFromSolidStorage(G25,$G$14,$G$15)} -> 0.013038112 | H32: {=MMS_Poultry_LeachingAndRunoff_Equations.VEERG_4_6_1_7__2_MassOfNitrogenLostToLeachingAndRunoffFromSolidStorage(H25,$G$14,$G$15)} -> 0.015304805 | I32: {=MMS_Poultry_LeachingAndRunoff_Equations.VEERG_4_6_1_7__2_MassOfNitrogenLostToLeachingAndRunoffFromSolidStorage(I25,$G$14,$G$15)} -> 0.013038112 | J32: =$E$11 -> kg N | N32: ='Input - Poultry'!$D$32 -> Manure stored in house | O32: ='Input - Poultry'!$D$52 -> Solid storage | P32: {=MMS_Poultry_LeachingAndRunoff_Equations.VEERG_4_6_1_7__2_MassOfNitrogenLostToLeachingAndRunoffFromSolidStorage(P25,$G$14,$G$15)} -> 0.012215 | Q32: {=MMS_Poultry_LeachingAndRunoff_Equations.VEERG_4_6_1_7__2_MassOfNitrogenLostToLeachingAndRunoffFromSolidStorage(Q25,$G$14,$G$15)} -> 0.013038112 | R32: {=MMS_Poultry_LeachingAndRunoff_Equations.VEERG_4_6_1_7__2_MassOfNitrogenLostToLeachingAndRunoffFromSolidStorage(R25,$G$14,$G$15)} -> 0.015304805 | S32: {=MMS_Poultry_LeachingAndRunoff_Equations.VEERG_4_6_1_7__2_MassOfNitrogenLostToLeachingAndRunoffFromSolidStorage(S25,$G$14,$G$15)} -> 0.013038112 | T32: =$E$11 -> kg N
D36: {=MMS_Poultry_LeachingAndRunoff_Equations.VEERG_4_6_1_7__1_AnnualEmissionsFromLeachingAndRunoffFromMMS_Title()} -> Annual emissions from leaching and runoff from each MMS
D37: {=MMS_Poultry_LeachingAndRunoff_Equations.VEERG_4_6_1_7__1_AnnualEmissionsFromLeachingAndRunoffFromMMS_Source()} -> VEERG 2026: 4.6.1.7, Equation (1)
D38: Function name | E38: {=Common_InputFunctions.Utility_DisplayFunctionName(F51)} -> =MMS_Poultry_LeachingAndRunoff_Equations.VEERG_4_6_1_7__1_AnnualEmissionsFromLeachingAndRunoffFromMMS
D41: Variable | E41: {=MMS_Poultry_LeachingAndRunoff_Equations.VEERG_4_6_1_7__1_AnnualEmissionsFromLeachingAndRunoffFromMMS_Variable()} -> E_N2Oleach
D42: Unit | E42: {=MMS_Poultry_LeachingAndRunoff_Equations.VEERG_4_6_1_7__1_AnnualEmissionsFromLeachingAndRunoffFromMMS_Unit()} -> t N2O
