Workbook
Name Common_Equations.Common_ConvertCH4ToCO2e: _xlfn.LAMBDA(_xlpm.E_CH4,_xlpm.GWP_CH4, _xlpm.E_CH4 * _xlpm.GWP_CH4)
Name Common_Equations.Common_ConvertCH4ToCO2e_Arguments: _xlfn.LAMBDA(_xlfn.MAKEARRAY(2, 2, _xlfn.LAMBDA(_xlpm.r,_xlpm.c, INDEX({"ECH4","Methane emissions (t CH4)";"GWPCH4","Global warming potential for methane (t CO2-e / t CH4)"}, _xlpm.r, _xlpm.c))))
Name Common_Equations.Common_ConvertCH4ToCO2e_LatexEquation: _xlfn.LAMBDA("CO2_e = E_{CH4} \times GWP_{CH4}")
Name Common_Equations.Common_ConvertCH4ToCO2e_NIRReference: _xlfn.LAMBDA("")
Name Common_Equations.Common_ConvertCH4ToCO2e_Title: _xlfn.LAMBDA("Convert methane emissions to carbon dioxide equivalent emissions")
Name Common_Equations.Common_ConvertCH4ToCO2e_Unit: _xlfn.LAMBDA("t CO2e")
Name Common_Equations.Common_ConvertCH4ToCO2e_Variable: _xlfn.LAMBDA("ECH4 CO2e")
Name Common_Equations.Common_ConvertN2OToCO2e: _xlfn.LAMBDA(_xlpm.E_N2O,_xlpm.GWP_N2O, _xlpm.E_N2O * _xlpm.GWP_N2O)
Name Common_Equations.Common_ConvertN2OToCO2e_LatexEquation: _xlfn.LAMBDA("CO2_e = E_{N2O} \times GWP_{N2O}")
Name Common_Equations.Common_ConvertN2OToCO2e_NIRReference: _xlfn.LAMBDA("")
Name Common_Equations.Common_ConvertN2OToCO2e_Title: _xlfn.LAMBDA("Convert nitrous oxide emissions to carbon dioxide equivalent emissions")
Name Common_Equations.Common_ConvertN2OToCO2e_Unit: _xlfn.LAMBDA("t CO2e")
Name Common_Equations.Common_ConvertN2OToCO2e_Variable: _xlfn.LAMBDA("EN2O CO2e")
Name Common_InputFunctions.Utility_DisplayFunctionName: _xlfn.LAMBDA(_xlpm.Function, _xlfn.TEXTBEFORE(_xlfn.FORMULATEXT(_xlpm.Function), "("))
Name Common_InputFunctions.Utility_GetArrayTableColumnStartNumber: _xlfn.LAMBDA(_xlpm.TableHeaderCell, COLUMN(_xlpm.TableHeaderCell))
Name Common_InputFunctions.Utility_GetArrayTableRowStartNumber: _xlfn.LAMBDA(_xlpm.TableheaderCell,_xlpm.RowsBetweenHeaderandArray, ROW(_xlpm.TableheaderCell) + _xlpm.RowsBetweenHeaderandArray - 1)
Name Common_InputFunctions.Utility_LookupValueInTable: _xlfn.LAMBDA(_xlpm.LookupValue,_xlpm.LookupArray,_xlpm.ReturnArray, _xlfn.XLOOKUP(_xlpm.LookupValue, _xlpm.LookupArray, _xlpm.ReturnArray, ""))
Name Common_SourceData.Common_SourceData_AustralianStatesTerritories_Source: _xlfn.LAMBDA("")
Name Common_SourceData.Common_SourceData_AustralianStatesTerritories_Title: _xlfn.LAMBDA("Australian states and territories")
Name Common_SourceData.Common_SourceData_AustralianStatesTerritories_Unit: _xlfn.LAMBDA("")
Name Common_SourceData.Common_SourceData_AustralianStatesTerritories_Variable: _xlfn.LAMBDA("")
Name Common_SourceData.Common_SourceData_ClimateZones_Source: _xlfn.LAMBDA("VEERG 2026: Table 1.3: Climate and Rainfall zone classifications and definitions")
Name Common_SourceData.Common_SourceData_ClimateZones_Title: _xlfn.LAMBDA("VEERG Australian climate zones")
Name Common_SourceData.Common_SourceData_ClimateZones_Unit: _xlfn.LAMBDA("")
Name Common_SourceData.Common_SourceData_ClimateZones_Variable: _xlfn.LAMBDA("")
Name Common_SourceData.Common_SourceData_ConvertGasElementalToMolecular_Source: _xlfn.LAMBDA("XXXXXXX")
Name Common_SourceData.Common_SourceData_ConvertGasElementalToMolecular_Title: _xlfn.LAMBDA("Factor to convert elemental mass of gas to molecular mass")
Name Common_SourceData.Common_SourceData_ConvertGasElementalToMolecular_Unit: _xlfn.LAMBDA("factor")
Name Common_SourceData.Common_SourceData_ConvertGasElementalToMolecular_Variable: _xlfn.LAMBDA("Cg")
Name Common_SourceData.Common_SourceData_ConvertN2oElementalToMolecularCg_Data: _xlfn.LAMBDA(44 / 28)
Name Common_SourceData.Common_SourceData_ConvertN2oElementalToMolecularCg_Source: _xlfn.LAMBDA("National Inventory Report 2023 Volume 1")
Name Common_SourceData.Common_SourceData_ConvertN2oElementalToMolecularCg_Title: _xlfn.LAMBDA("Factor to convert elemental mass of N2O to molecular mass")
Name Common_SourceData.Common_SourceData_ConvertN2oElementalToMolecularCg_Unit: _xlfn.LAMBDA("factor")
Name Common_SourceData.Common_SourceData_ConvertN2oElementalToMolecularCg_Variable: _xlfn.LAMBDA("CgN2O")
Name Common_SourceData.Common_SourceData_DataScores_Scope3_Source: _xlfn.LAMBDA("VEERG 2026: XXXXXXXX")
Name Common_SourceData.Common_SourceData_DataScores_Scope3_Title: _xlfn.LAMBDA("Australian data scores for scope 3")
Name Common_SourceData.Common_SourceData_DataScores_Scope3_Unit: _xlfn.LAMBDA("")
Name Common_SourceData.Common_SourceData_DataScores_Scope3_Variable: _xlfn.LAMBDA("")
Name Common_SourceData.Common_SourceData_DataScores_Scope3_Variation: _xlfn.LAMBDA("")
Name Common_SourceData.Common_SourceData_DensityOfMethane_Data: _xlfn.LAMBDA(0.6784)
Name Common_SourceData.Common_SourceData_DensityOfMethane_Source: _xlfn.LAMBDA("National Inventory Report 2023 Volume 1: Equations 3.B.1a_2, 3.B.1c_2, 3.B.3_1, 3.B.4g_2")
Name Common_SourceData.Common_SourceData_DensityOfMethane_Title: _xlfn.LAMBDA("p = density of methane")
Name Common_SourceData.Common_SourceData_DensityOfMethane_Unit: _xlfn.LAMBDA("kg/m3")
Name Common_SourceData.Common_SourceData_EFleach_Data: _xlfn.LAMBDA(_xlfn.MAKEARRAY(1, 2, _xlfn.LAMBDA(_xlpm.r,_xlpm.c, INDEX({"EFleach",0.011}, _xlpm.r, _xlpm.c))))
Name Common_SourceData.Common_SourceData_EFleach_NIRReference: _xlfn.LAMBDA("National Inventory Report Volume 1: Equation 3.D.B_10")
Name Common_SourceData.Common_SourceData_EFleach_Source: _xlfn.LAMBDA("VEERG 2026:5.5.2.3 Constant Parameters")
Name Common_SourceData.Common_SourceData_EFleach_Title: _xlfn.LAMBDA("Emission factor for nitrogen leaching and runoff")
Name Common_SourceData.Common_SourceData_EFleach_Unit: _xlfn.LAMBDA("(kg N2O-N / kg N")
Name Common_SourceData.Common_SourceData_EFleach_Variation: _xlfn.LAMBDA((""))
Name Common_SourceData.Common_SourceData_EFN2O_NIRReference: _xlfn.LAMBDA("")
Name Common_SourceData.Common_SourceData_EFN2O_Source: _xlfn.LAMBDA("VEERG 2026: Table A.2.2.1")
Name Common_SourceData.Common_SourceData_EFN2O_Title: _xlfn.LAMBDA("Nitrous oxide emission factors for inorganic fertiliser application")
Name Common_SourceData.Common_SourceData_EFN2O_Unit: _xlfn.LAMBDA("(kg N2O-N / kg N")
Name Common_SourceData.Common_SourceData_FracLEACH_Data: _xlfn.LAMBDA(_xlfn.MAKEARRAY(1, 2, _xlfn.LAMBDA(_xlpm.r,_xlpm.c, INDEX({"FracLEACH",0.24}, _xlpm.r, _xlpm.c))))
Name Common_SourceData.Common_SourceData_FracLEACH_NIRReference: _xlfn.LAMBDA("National Inventory Report Volume 1: Leaching and runoff (3.D.b.2)")
Name Common_SourceData.Common_SourceData_FracLEACH_Source: _xlfn.LAMBDA("VEERG 2026:5.5.2.3 Constant Parameters")
Name Common_SourceData.Common_SourceData_FracLEACH_Title: _xlfn.LAMBDA("Fraction of N that is available for leaching and runoff")
Name Common_SourceData.Common_SourceData_FracLEACH_Unit: _xlfn.LAMBDA("(Dimensionless")
Name Common_SourceData.Common_SourceData_FracLEACH_Variation: _xlfn.LAMBDA((""))
Name Common_SourceData.Common_SourceData_FracWET_Data: _xlfn.LAMBDA(_xlfn.MAKEARRAY(3, 2, _xlfn.LAMBDA(_xlpm.r,_xlpm.c, INDEX({"Is in leaching zone","FracWET";"Yes - in leaching zone",1;"No - not in leaching zone",0}, _xlpm.r, _xlpm.c))))

Sheet Home

Sheet Results
A1: #VALUE! | C1: 4.1 Manure management: Beef Feedlot: Results
A3: =HYPERLINK("#'Home'!A1", "Home") -> Home
A4: =HYPERLINK("#'Results'!A1", "Results") -> Results | D4: Emissions breakdown
A6: INPUTS | D6: Scope 1 source | E6: GHG emissions | F6: GHG Unit | G6: CO2-e emissions | H6: CO2-e unit
A7: =HYPERLINK("#'Input - Site'!A1", "Site") -> Site | D7: 4.1.1.1 Method 1 Manure methane | E7: ='4.1.1.1-2 Methane'!E164 -> 0 | F7: ='4.1.1.1-2 Methane'!F164 -> 0 | G7: ='4.1.1.1-2 Methane'!E169 -> 0 | H7: ='4.1.1.1-2 Methane'!F169 -> 0
A8: =HYPERLINK("#'Input - Feedlot'!A1", "Feedlot") -> Feedlot | D8: 4.1.1.2 Method 2 Manure methane | E8: ='4.1.1.1-2 Methane'!N164 -> 0 | F8: ='4.1.1.1-2 Methane'!O164 -> 0 | G8: ='4.1.1.1-2 Methane'!N169 -> 0 | H8: ='4.1.1.1-2 Methane'!O169 -> 0
D9: 4.1.1.3 Method 1 Manure direct N2O | E9: ='4.1.1.3-4 Direct N20'!E207 -> #REF! | F9: ='4.1.1.3-4 Direct N20'!F207 -> t N2O | G9: ='4.1.1.3-4 Direct N20'!E212 -> #REF! | H9: ='4.1.1.3-4 Direct N20'!F212 -> t CO2e
A10: CALCULATIONS | D10: 4.1.1.4 Method 2 Manure direct N2O | E10: ='4.1.1.3-4 Direct N20'!M207 -> #REF! | F10: ='4.1.1.3-4 Direct N20'!N207 -> t N2O | G10: ='4.1.1.3-4 Direct N20'!M212 -> #REF! | H10: ='4.1.1.3-4 Direct N20'!N212 -> t CO2e
A11: =HYPERLINK("#'4.1.1.1-2 Methane'!A1", "4.1.1.1-2 Methane") -> 4.1.1.1-2 Methane | D11: 4.1.1.5 Method 1 Manure atmospheric deposition | E11: ='4.1.1.5-6 Atmos Deposition'!$E$60 -> #REF! | F11: ='4.1.1.5-6 Atmos Deposition'!$F$60 -> t N2O | G11: ='4.1.1.5-6 Atmos Deposition'!$E$65 -> #REF! | H11: ='4.1.1.5-6 Atmos Deposition'!$F$65 -> t CO2e
A12: =HYPERLINK("#'4.1.1.3-4 Direct N20'!A1", "4.1.1.3-4 Direct N2O") -> 4.1.1.3-4 Direct N2O | D12: 4.1.1.6 Method 2 Manure atmospheric deposition | E12: ='4.1.1.5-6 Atmos Deposition'!$M$60 -> #REF! | F12: ='4.1.1.5-6 Atmos Deposition'!$N$60 -> t N2O | G12: ='4.1.1.5-6 Atmos Deposition'!$M$65 -> #REF! | H12: ='4.1.1.5-6 Atmos Deposition'!$N$65 -> t CO2e
A13: =HYPERLINK("#'4.1.1.5-6 Atmos Deposition'!A1", "4.1.1.5-6 Atmospheric deposition") -> 4.1.1.5-6 Atmospheric deposition | D13: 4.1.1.7 Method 1 Manure leaching and runoff | E13: N/A | F13: N/A | G13: 0 | H13: N/A
A14: =HYPERLINK("#'4.1.1.9 Manure applied to soils'!A1", "4.1.1.9 Manure applied to soils") -> 4.1.1.9 Manure applied to soils | D14: 4.1.1.8 Method 1 Manure leaching and runoff | E14: N/A | F14: N/A | G14: 0 | H14: N/A
D15: Total | G15: =SUM(G7:G14) -> #REF! | H15: ='4.1.1.5-6 Atmos Deposition'!$N$65 -> t CO2e
A16: APPENDICES
A17: =HYPERLINK("#'Constants - Feedlot'!A1", "Constants - Feedlot") -> Constants - Feedlot | D17: WARNING: Manure nitrogen that was applied to soils must be accounted for
A18: =HYPERLINK("#'Constants - Livestock'!A1", "Constants - Livestock") -> Constants - Livestock | D18: See the table below for how to account for manure applied to soils for scope 1 and 3.
A19: =HYPERLINK("#'Constants - Common'!A1", "Constants - Common") -> Constants - Common
A20: =HYPERLINK("#'Acknowledgements'!A1", "Acknowledgements") -> Acknowledgements | D20: Manure nitrogen use | E20: Amount of N in manure | F20: N unit | G20: Emissions allocated to | H20: VEERG Calculation method
D21: Manure nitrogen deposited on farm soils with no other purpose (aka waste) | E21: ='4.1.1.9 Manure applied to soils'!$E$56 -> #REF! | F21: ='4.1.1.9 Manure applied to soils'!$F$56 -> kg N | G21: This feedlot | H21: 5.2.2.1 (1), 5.4.1.3 (1, 2), 5.5.1.1 (1, 3)
D22: Manure nitrogen deposited on farm soils as fertiliser for other farm enterpsies (eg crops) | E22: ='4.1.1.9 Manure applied to soils'!$E$104 -> #REF! | F22: ='4.1.1.9 Manure applied to soils'!$F$104 -> kg N | G22: Crops or pasture that use manure as fertiliser | H22: 5.2.2.1 (1), 5.4.1.3 (1, 2), 5.5.1.1 (1, 3)
D23: Manure nitrogen sold | E23: ='4.1.1.9 Manure applied to soils'!$E$123 -> #REF! | F23: ='4.1.1.9 Manure applied to soils'!$F$123 -> kg N | G23: Scope 3 (downstream) | H23: 15.13.1.1 (1), 5.2.2.1 (1), 5.4.1.3 (1, 2), 5.5.1.1 (1, 3)

Sheet Input - Site
A1: #VALUE! | C1: Input - Site
A3: =HYPERLINK("#'Home'!A1", "Home") -> Home
A4: =HYPERLINK("#'Results'!A1", "Results") -> Results
D5: Your business
A6: INPUTS
A7: =HYPERLINK("#'Input - Site'!A1", "Site") -> Site | D7: Farm name | E7: Test Farms
A8: =HYPERLINK("#'Input - Feedlot'!A1", "Feedlot") -> Feedlot | D8: Reporting entity name | E8: Test Farms Pty Ltd
A10: CALCULATIONS | D10: 💡An 'Emissions accounting period' is a 12 month period where the business can report on the emissions, and is typically the same as the business' financial accounting period.
A11: =HYPERLINK("#'4.1.1.1-2 Methane'!A1", "4.1.1.1-2 Methane") -> 4.1.1.1-2 Methane
A12: =HYPERLINK("#'4.1.1.3-4 Direct N20'!A1", "4.1.1.3-4 Direct N2O") -> 4.1.1.3-4 Direct N2O | D12: Emissions calculation period start date | E12: 45292 | F12: ← DD/MM/YYYY or DD Month YYYY
A13: =HYPERLINK("#'4.1.1.5-6 Atmos Deposition'!A1", "4.1.1.5-6 Atmospheric deposition") -> 4.1.1.5-6 Atmospheric deposition | D13: Emissions calculation period end date | E13: =DATE(YEAR(E12)+1,MONTH(E12),DAY(E12))-1 -> 45657 | F13: ← Automatically calculated, 12 months after start date
A14: =HYPERLINK("#'4.1.1.9 Manure applied to soils'!A1", "4.1.1.9 Manure applied to soils") -> 4.1.1.9 Manure applied to soils
A16: APPENDICES | D16: Location and climate
A17: =HYPERLINK("#'Constants - Feedlot'!A1", "Constants - Feedlot") -> Constants - Feedlot
A18: =HYPERLINK("#'Constants - Livestock'!A1", "Constants - Livestock") -> Constants - Livestock | D18: Location information is used to reference some region and climate-specific emission factors
A19: =HYPERLINK("#'Constants - Common'!A1", "Constants - Common") -> Constants - Common | D19: Tip: Use the web-based GAF Location Helper tool to easily get region and climate information. You will need an internet connection to use the GAF Location Helper.
A20: =HYPERLINK("#'Acknowledgements'!A1", "Acknowledgements") -> Acknowledgements
D21: State | E21: New South Wales | F21: ← Please select
D22: Region (ABS Statistical area level 4) if state is WA | E22: Western Australia - Outback (South) | F22: ← Please select
D23: Leaching zone | E23: NO - Not in leaching zone | F23: ← Please select
D24: Elevation | E24: 307.7 | F24: Meters
D25: Average temperature for reporting period | E25: 18 | F25: Degrees celsius
D26: Total rainfall for reporting period | E26: 601 | F26: Millimetres
D27: Potential evapotranspiration for reporting period | E27: 1326 | F27: Millimetres
D28: Number of frost days for reporting period | E28: 7 | F28: Days
D29: MAP:PET ratio | E29: =E26/E27 -> 0.45324284
D30: Rainfall zone | E30: =Common_InputFunctions.Utility_LookupItemFromMinMax(E26,Table_SourceData_RainfallZones[Min rainfall],Table_SourceData_RainfallZones[Max rainfall],Table_SourceData_RainfallZones[Rainfall Zone]) -> High rainfall
D31: Climate zone | E31: =Common_InputFunctions.Utility_GetClimateZone(E25,E26,E28,E24,E29,Table_SourceData_ClimateZones[Min temp],Table_SourceData_ClimateZones[Max temp],Table_SourceData_ClimateZones[Min rainfall],Table_SourceData_ClimateZones[Max rainfall],Table_SourceData_ClimateZones[Min frost days],Table_SourceData_ClimateZones[Max frost days],Table_SourceData_ClimateZones[Min elevation],Table_SourceData_ClimateZones[Max elevation],Table_SourceData_ClimateZones[Min MAP:PET],Table_SourceData_ClimateZones[Max MAP:PET],Table_SourceData_ClimateZones[Climate zone]) -> Warm temperate dry
D32: Wet or dry climate zone | E32: =Common_InputFunctions.Utility_LookupValueInTable($E$31,Table_SourceData_WetDryZones[Climate zone],Table_SourceData_WetDryZones[Wet or Dry Zone]) -> Dry climate zone
D33: Temperature zone | E33: =Common_InputFunctions.Utility_LookupItemFromMinMax(E25,Table_SourceData_TemperatureZones[Min MAT],Table_SourceData_TemperatureZones[Max MAT],Table_SourceData_TemperatureZones[Temperature Zone]) -> Temperate

Sheet Input - Dairy
A1: #VALUE! | C1: Input -Dairy
A3: =HYPERLINK("#'Home'!A1", "Home") -> Home
A4: =HYPERLINK("#'Results'!A1", "Results") -> Results
D5: Herd movement
A6: INPUTS
A7: =HYPERLINK("#'Input - Site'!A1", "Site") -> Site | E7: Milking cows | F7: Heifers > 1 year | G7: Heifers < 1 year | H7: Bulls > 1 year | I7: Bulls < 1 year
A8: =HYPERLINK("#'Input - Dairy'!A1", "Dairy") -> Dairy | D8: ="Average number of head between " & TEXT('Input - Site'!$E$12, "dd mmm yy") & " and " & TEXT('Input - Site'!$E$13, "dd mmm yy") -> Average number of head between 01 Jan 24 and 31 Dec 24 | E8: 100 | F8: 100 | G8: 100 | H8: 100 | I8: 100 | J8: head
A10: CALCULATIONS | D10: Duration of stay
A11: =HYPERLINK("#'4.1.1.1-2 Methane'!A1", "4.1.1.1-2 Methane") -> 4.1.1.1-2 Methane
A12: =HYPERLINK("#'4.1.1.3-4 Direct N20'!A1", "4.1.1.3-4 Direct N2O") -> 4.1.1.3-4 Direct N2O | D12: Method 1 default values (Do not edit) | E12: Milking cows | F12: Heifers > 1 year | G12: Heifers < 1 year | H12: Bulls > 1 year | I12: Bulls < 1 year
A13: =HYPERLINK("#'4.1.1.5-6 Atmos Deposition'!A1", "4.1.1.5-6 Atmospheric deposition") -> 4.1.1.5-6 Atmospheric deposition | D13: ="Average duration of stay between " & TEXT('Input - Site'!$E$12, "dd mmm yy") & " and " & TEXT('Input - Site'!$E$13, "dd mmm yy") & " weaned livestock" -> Average duration of stay between 01 Jan 24 and 31 Dec 24 weaned livestock | E13: {=Common_InputFunctions.Utility_LookupValueInTableNumber(E12,Table_SourceData_Dairy_Duration[Animal class j],Table_SourceData_Dairy_Duration[Duration (weaned)])} -> 365 | F13: {=Common_InputFunctions.Utility_LookupValueInTableNumber(F12,Table_SourceData_Dairy_Duration[Animal class j],Table_SourceData_Dairy_Duration[Duration (weaned)])} -> 365 | G13: {=Common_InputFunctions.Utility_LookupValueInTableNumber(G12,Table_SourceData_Dairy_Duration[Animal class j],Table_SourceData_Dairy_Duration[Duration (weaned)])} -> 281 | H13: {=Common_InputFunctions.Utility_LookupValueInTableNumber(H12,Table_SourceData_Dairy_Duration[Animal class j],Table_SourceData_Dairy_Duration[Duration (weaned)])} -> 365 | I13: {=Common_InputFunctions.Utility_LookupValueInTableNumber(I12,Table_SourceData_Dairy_Duration[Animal class j],Table_SourceData_Dairy_Duration[Duration (weaned)])} -> 281 | J13: Days
A14: =HYPERLINK("#'4.1.1.9 Manure applied to soils'!A1", "4.1.1.9 Manure applied to soils") -> 4.1.1.9 Manure applied to soils | D14: ="Average duration of stay between " & TEXT('Input - Site'!$E$12, "dd mmm yy") & " and " & TEXT('Input - Site'!$E$13, "dd mmm yy") & " pre-weaned livestock" -> Average duration of stay between 01 Jan 24 and 31 Dec 24 pre-weaned livestock | E14: {=Common_InputFunctions.Utility_LookupValueInTableNumber(E12,Table_SourceData_Dairy_Duration[Animal class j],Table_SourceData_Dairy_Duration[Duration (pre-weaned)])} -> 0 | F14: {=Common_InputFunctions.Utility_LookupValueInTableNumber(F12,Table_SourceData_Dairy_Duration[Animal class j],Table_SourceData_Dairy_Duration[Duration (pre-weaned)])} -> 0 | G14: {=Common_InputFunctions.Utility_LookupValueInTableNumber(G12,Table_SourceData_Dairy_Duration[Animal class j],Table_SourceData_Dairy_Duration[Duration (pre-weaned)])} -> 84 | H14: {=Common_InputFunctions.Utility_LookupValueInTableNumber(H12,Table_SourceData_Dairy_Duration[Animal class j],Table_SourceData_Dairy_Duration[Duration (pre-weaned)])} -> 0 | I14: {=Common_InputFunctions.Utility_LookupValueInTableNumber(I12,Table_SourceData_Dairy_Duration[Animal class j],Table_SourceData_Dairy_Duration[Duration (pre-weaned)])} -> 84 | J14: Days
A16: APPENDICES | D16: Method 2 custom values (Edit if known) | E16: Milking cows | F16: Heifers > 1 year | G16: Heifers < 1 year | H16: Bulls > 1 year | I16: Bulls < 1 year
A17: =HYPERLINK("#'Constants - Dairy'!A1", "Constants - Dairy") -> Constants - Dairy | D17: ="Average duration of stay between " & TEXT('Input - Site'!$E$12, "dd mmm yy") & " and " & TEXT('Input - Site'!$E$13, "dd mmm yy") & " weaned livestock" -> Average duration of stay between 01 Jan 24 and 31 Dec 24 weaned livestock | E17: {=Common_InputFunctions.Utility_LookupValueInTableNumber(E16,Table_SourceData_Dairy_Duration[Animal class j],Table_SourceData_Dairy_Duration[Duration (weaned)])} -> 365 | F17: {=Common_InputFunctions.Utility_LookupValueInTableNumber(F16,Table_SourceData_Dairy_Duration[Animal class j],Table_SourceData_Dairy_Duration[Duration (weaned)])} -> 365 | G17: {=Common_InputFunctions.Utility_LookupValueInTableNumber(G16,Table_SourceData_Dairy_Duration[Animal class j],Table_SourceData_Dairy_Duration[Duration (weaned)])} -> 281 | H17: {=Common_InputFunctions.Utility_LookupValueInTableNumber(H16,Table_SourceData_Dairy_Duration[Animal class j],Table_SourceData_Dairy_Duration[Duration (weaned)])} -> 365 | I17: {=Common_InputFunctions.Utility_LookupValueInTableNumber(I16,Table_SourceData_Dairy_Duration[Animal class j],Table_SourceData_Dairy_Duration[Duration (weaned)])} -> 281 | J17: Days
A18: =HYPERLINK("#'Constants - Livestock'!A1", "Constants - Livestock") -> Constants - Livestock | D18: ="Average duration of stay between " & TEXT('Input - Site'!$E$12, "dd mmm yy") & " and " & TEXT('Input - Site'!$E$13, "dd mmm yy") & " pre-weaned livestock" -> Average duration of stay between 01 Jan 24 and 31 Dec 24 pre-weaned livestock | E18: {=Common_InputFunctions.Utility_LookupValueInTableNumber(E16,Table_SourceData_Dairy_Duration[Animal class j],Table_SourceData_Dairy_Duration[Duration (pre-weaned)])} -> 0 | F18: {=Common_InputFunctions.Utility_LookupValueInTableNumber(F16,Table_SourceData_Dairy_Duration[Animal class j],Table_SourceData_Dairy_Duration[Duration (pre-weaned)])} -> 0 | G18: {=Common_InputFunctions.Utility_LookupValueInTableNumber(G16,Table_SourceData_Dairy_Duration[Animal class j],Table_SourceData_Dairy_Duration[Duration (pre-weaned)])} -> 84 | H18: {=Common_InputFunctions.Utility_LookupValueInTableNumber(H16,Table_SourceData_Dairy_Duration[Animal class j],Table_SourceData_Dairy_Duration[Duration (pre-weaned)])} -> 0 | I18: {=Common_InputFunctions.Utility_LookupValueInTableNumber(I16,Table_SourceData_Dairy_Duration[Animal class j],Table_SourceData_Dairy_Duration[Duration (pre-weaned)])} -> 84 | J18: Days
A19: =HYPERLINK("#'Constants - Common'!A1", "Constants - Common") -> Constants - Common
A20: =HYPERLINK("#'Acknowledgements'!A1", "Acknowledgements") -> Acknowledgements
D21: Milk production
D22: Average daily milk production | E22: 44 | F22: litres/head/day
D25: Production systems
D26: Time spent in production systems
D27: Production system template | E27: System 3: Pasture-grazed 3-9 months/year | F27: ← Please select
D29: Method 1 default values (Do not edit) | E29: Milking cows | F29: Heifers > 1 year | G29: Heifers < 1 year | H29: Bulls > 1 year | I29: Bulls < 1 year
D30: Pasture | E30: {=Common_InputFunctions.Utility_LookupValueInTableNumber($E$27, Table_SourceData_Dairy_ProductionSystemTemplates[Area],Table_SourceData_Dairy_ProductionSystemTemplates[Pasture])} -> 0.534 | F30: {=Common_InputFunctions.Utility_LookupValueInTableNumber($E$27, Table_SourceData_Dairy_ProductionSystemTemplates[Area],Table_SourceData_Dairy_ProductionSystemTemplates[Pasture])} -> 0.534 | G30: {=Common_InputFunctions.Utility_LookupValueInTableNumber($E$27, Table_SourceData_Dairy_ProductionSystemTemplates[Area],Table_SourceData_Dairy_ProductionSystemTemplates[Pasture])} -> 0.534 | H30: {=Common_InputFunctions.Utility_LookupValueInTableNumber($E$27, Table_SourceData_Dairy_ProductionSystemTemplates[Area],Table_SourceData_Dairy_ProductionSystemTemplates[Pasture])} -> 0.534 | I30: {=Common_InputFunctions.Utility_LookupValueInTableNumber($E$27, Table_SourceData_Dairy_ProductionSystemTemplates[Area],Table_SourceData_Dairy_ProductionSystemTemplates[Pasture])} -> 0.534 | J30: Percent
D31: Milking shed | E31: {=Common_InputFunctions.Utility_LookupValueInTableNumber($E$27, Table_SourceData_Dairy_ProductionSystemTemplates[Area],Table_SourceData_Dairy_ProductionSystemTemplates[Milking shed])} -> 0.11 | F31: {=Common_InputFunctions.Utility_LookupValueInTableNumber($E$27, Table_SourceData_Dairy_ProductionSystemTemplates[Area],Table_SourceData_Dairy_ProductionSystemTemplates[Milking shed])} -> 0.11 | G31: {=Common_InputFunctions.Utility_LookupValueInTableNumber($E$27, Table_SourceData_Dairy_ProductionSystemTemplates[Area],Table_SourceData_Dairy_ProductionSystemTemplates[Milking shed])} -> 0.11 | H31: {=Common_InputFunctions.Utility_LookupValueInTableNumber($E$27, Table_SourceData_Dairy_ProductionSystemTemplates[Area],Table_SourceData_Dairy_ProductionSystemTemplates[Milking shed])} -> 0.11 | I31: {=Common_InputFunctions.Utility_LookupValueInTableNumber($E$27, Table_SourceData_Dairy_ProductionSystemTemplates[Area],Table_SourceData_Dairy_ProductionSystemTemplates[Milking shed])} -> 0.11 | J31: Percent
D32: Feed pad | E32: {=Common_InputFunctions.Utility_LookupValueInTableNumber($E$27, Table_SourceData_Dairy_ProductionSystemTemplates[Area],Table_SourceData_Dairy_ProductionSystemTemplates[Feedpad])} -> 0.356 | F32: {=Common_InputFunctions.Utility_LookupValueInTableNumber($E$27, Table_SourceData_Dairy_ProductionSystemTemplates[Area],Table_SourceData_Dairy_ProductionSystemTemplates[Feedpad])} -> 0.356 | G32: {=Common_InputFunctions.Utility_LookupValueInTableNumber($E$27, Table_SourceData_Dairy_ProductionSystemTemplates[Area],Table_SourceData_Dairy_ProductionSystemTemplates[Feedpad])} -> 0.356 | H32: {=Common_InputFunctions.Utility_LookupValueInTableNumber($E$27, Table_SourceData_Dairy_ProductionSystemTemplates[Area],Table_SourceData_Dairy_ProductionSystemTemplates[Feedpad])} -> 0.356 | I32: {=Common_InputFunctions.Utility_LookupValueInTableNumber($E$27, Table_SourceData_Dairy_ProductionSystemTemplates[Area],Table_SourceData_Dairy_ProductionSystemTemplates[Feedpad])} -> 0.356 | J32: Percent
D34: Method 2 custom values (Edit if known) | E34: Milking cows | F34: Heifers > 1 year | G34: Heifers < 1 year | H34: Bulls > 1 year | I34: Bulls < 1 year
D35: Pasture | E35: {=Common_InputFunctions.Utility_LookupValueInTableNumber($E$27, Table_SourceData_Dairy_ProductionSystemTemplates[Area],Table_SourceData_Dairy_ProductionSystemTemplates[Pasture])} -> 0.534 | F35: {=Common_InputFunctions.Utility_LookupValueInTableNumber($E$27, Table_SourceData_Dairy_ProductionSystemTemplates[Area],Table_SourceData_Dairy_ProductionSystemTemplates[Pasture])} -> 0.534 | G35: {=Common_InputFunctions.Utility_LookupValueInTableNumber($E$27, Table_SourceData_Dairy_ProductionSystemTemplates[Area],Table_SourceData_Dairy_ProductionSystemTemplates[Pasture])} -> 0.534 | H35: {=Common_InputFunctions.Utility_LookupValueInTableNumber($E$27, Table_SourceData_Dairy_ProductionSystemTemplates[Area],Table_SourceData_Dairy_ProductionSystemTemplates[Pasture])} -> 0.534 | I35: {=Common_InputFunctions.Utility_LookupValueInTableNumber($E$27, Table_SourceData_Dairy_ProductionSystemTemplates[Area],Table_SourceData_Dairy_ProductionSystemTemplates[Pasture])} -> 0.534 | J35: Percent
D36: Milking shed | E36: {=Common_InputFunctions.Utility_LookupValueInTableNumber($E$27, Table_SourceData_Dairy_ProductionSystemTemplates[Area],Table_SourceData_Dairy_ProductionSystemTemplates[Milking shed])} -> 0.11 | F36: {=Common_InputFunctions.Utility_LookupValueInTableNumber($E$27, Table_SourceData_Dairy_ProductionSystemTemplates[Area],Table_SourceData_Dairy_ProductionSystemTemplates[Milking shed])} -> 0.11 | G36: {=Common_InputFunctions.Utility_LookupValueInTableNumber($E$27, Table_SourceData_Dairy_ProductionSystemTemplates[Area],Table_SourceData_Dairy_ProductionSystemTemplates[Milking shed])} -> 0.11 | H36: {=Common_InputFunctions.Utility_LookupValueInTableNumber($E$27, Table_SourceData_Dairy_ProductionSystemTemplates[Area],Table_SourceData_Dairy_ProductionSystemTemplates[Milking shed])} -> 0.11 | I36: {=Common_InputFunctions.Utility_LookupValueInTableNumber($E$27, Table_SourceData_Dairy_ProductionSystemTemplates[Area],Table_SourceData_Dairy_ProductionSystemTemplates[Milking shed])} -> 0.11 | J36: Percent
D37: Feed pad | E37: {=Common_InputFunctions.Utility_LookupValueInTableNumber($E$27, Table_SourceData_Dairy_ProductionSystemTemplates[Area],Table_SourceData_Dairy_ProductionSystemTemplates[Feedpad])} -> 0.356 | F37: {=Common_InputFunctions.Utility_LookupValueInTableNumber($E$27, Table_SourceData_Dairy_ProductionSystemTemplates[Area],Table_SourceData_Dairy_ProductionSystemTemplates[Feedpad])} -> 0.356 | G37: {=Common_InputFunctions.Utility_LookupValueInTableNumber($E$27, Table_SourceData_Dairy_ProductionSystemTemplates[Area],Table_SourceData_Dairy_ProductionSystemTemplates[Feedpad])} -> 0.356 | H37: {=Common_InputFunctions.Utility_LookupValueInTableNumber($E$27, Table_SourceData_Dairy_ProductionSystemTemplates[Area],Table_SourceData_Dairy_ProductionSystemTemplates[Feedpad])} -> 0.356 | I37: {=Common_InputFunctions.Utility_LookupValueInTableNumber($E$27, Table_SourceData_Dairy_ProductionSystemTemplates[Area],Table_SourceData_Dairy_ProductionSystemTemplates[Feedpad])} -> 0.356 | J37: Percent
D40: Manure management systems
D41: ="From " & $D$31 -> From Milking shed
D43: Stage 1 MMS | E43: Milking cows | F43: Heifers > 1 year | G43: Heifers < 1 year | H43: Bulls > 1 year | I43: Bulls < 1 year
D44: ='Constants - Dairy'!$D$8 -> Anaerobic lagoon | E44: 0.25 | F44: 0.25 | G44: 0.25 | H44: 0.25 | I44: 0.25 | J44: Percent
D45: ="Were solids separated from " & $D$44 & "?" -> Were solids separated from Anaerobic lagoon? | E45: Yes | F45: ← Please select
D46: ="Percent solids separated from " & $D$44 & " (Method 1 - Do not edit)" -> Percent solids separated from Anaerobic lagoon (Method 1 - Do not edit) | E46: 0.2 | F46: Percent
D47: ="Percent solids separated from " & $D$44 & " (Method 2 - Edit if known)" -> Percent solids separated from Anaerobic lagoon (Method 2 - Edit if known) | E47: 0.2 | F47: Percent
D49: ='Constants - Dairy'!$D$9 -> Sump and dispersal system | E49: 0.25 | F49: 0.25 | G49: 0.25 | H49: 0.25 | I49: 0.25 | J49: Percent
D50: ="Were solids separated from " & $D$49 & "?" -> Were solids separated from Sump and dispersal system? | E50: Yes | F50: ← Please select
D51: ="Percent solids separated from " & $D$49 & " (Method 1 - Do not edit)" -> Percent solids separated from Sump and dispersal system (Method 1 - Do not edit) | E51: 0.2 | F51: Percent
...

Sheet 4.1.1.1-2 Methane
A1: #VALUE! | C1: 4.1.1.1-2 Manure Methane
A3: =HYPERLINK("#'Home'!A1", "Home") -> Home | D3: Method 1 | M3: Method 2
A4: =HYPERLINK("#'Results'!A1", "Results") -> Results
A6: INPUTS
A7: =HYPERLINK("#'Input - Site'!A1", "Site") -> Site
A8: =HYPERLINK("#'Input - Feedlot'!A1", "Feedlot") -> Feedlot
A10: CALCULATIONS
A11: =HYPERLINK("#'4.1.1.1-2 Methane'!A1", "4.1.1.1-2 Methane") -> 4.1.1.1-2 Methane
A12: =HYPERLINK("#'4.1.1.3-4 Direct N20'!A1", "4.1.1.3-4 Direct N2O") -> 4.1.1.3-4 Direct N2O
A13: =HYPERLINK("#'4.1.1.5-6 Atmos Deposition'!A1", "4.1.1.5-6 Atmospheric deposition") -> 4.1.1.5-6 Atmospheric deposition
A14: =HYPERLINK("#'4.1.1.9 Manure applied to soils'!A1", "4.1.1.9 Manure applied to soils") -> 4.1.1.9 Manure applied to soils
A16: APPENDICES
A17: =HYPERLINK("#'Constants - Feedlot'!A1", "Constants - Feedlot") -> Constants - Feedlot
A18: =HYPERLINK("#'Constants - Livestock'!A1", "Constants - Livestock") -> Constants - Livestock
A19: =HYPERLINK("#'Constants - Common'!A1", "Constants - Common") -> Constants - Common
A20: =HYPERLINK("#'Acknowledgements'!A1", "Acknowledgements") -> Acknowledgements

Sheet 4.1.1.3-4 Direct N20
A1: #VALUE! | C1: 4.1.1.3-4 Manure Direct N2O
A3: =HYPERLINK("#'Home'!A1", "Home") -> Home | D3: Method 1 | L3: Method 2
A4: =HYPERLINK("#'Results'!A1", "Results") -> Results
D5: {=MMS_Feedlot_N2O_Direct_Equations.VEERG_4_1_1_3__5_NitrogenIntake_Title()} -> Nitrogen intake of feedlot cattle
A6: INPUTS | D6: {=MMS_Feedlot_N2O_Direct_Equations.VEERG_4_1_1_3__5_NitrogenIntake_Source()} -> VEERG 2026: 4.1.1.3, Equation (5)
A7: =HYPERLINK("#'Input - Site'!A1", "Site") -> Site | D7: Formula name | E7: {=Common_InputFunctions.Utility_DisplayFunctionName(D30)} -> =MMS_Feedlot_N2O_Direct_Equations.VEERG_4_1_1_3__5_NitrogenIntake
A8: =HYPERLINK("#'Input - Feedlot'!A1", "Feedlot") -> Feedlot
A10: CALCULATIONS | D10: Variable | E10: {=MMS_Feedlot_N2O_Direct_Equations.VEERG_4_1_1_3__5_NitrogenIntake_Variable()} -> NI_j
A11: =HYPERLINK("#'4.1.1.1-2 Methane'!A1", "4.1.1.1-2 Methane") -> 4.1.1.1-2 Methane | D11: Unit | E11: {=MMS_Feedlot_N2O_Direct_Equations.VEERG_4_1_1_3__5_NitrogenIntake_Unit()} -> kg N/head/day
A12: =HYPERLINK("#'4.1.1.3-4 Direct N20'!A1", "4.1.1.3-4 Direct N2O") -> 4.1.1.3-4 Direct N2O
A13: =HYPERLINK("#'4.1.1.5-6 Atmos Deposition'!A1", "4.1.1.5-6 Atmospheric deposition") -> 4.1.1.5-6 Atmospheric deposition | D13: {=MMS_Feedlot_N2O_Direct_Equations.VEERG_4_1_1_3__5_NitrogenIntake_Arguments()} -> I_j | E13: dry matter intake : kg DM/head/day | G13: ="See " &D17 -> See M1_Table_I_j
A14: =HYPERLINK("#'4.1.1.9 Manure applied to soils'!A1", "4.1.1.9 Manure applied to soils") -> 4.1.1.9 Manure applied to soils | D14: CP_j | E14: crude protein content of feed : fraction | G14: ="See " & D22 -> See M1_Table_CP_j
D15: 6.25 | E15: factor for converting crude protein into nitrogen : ratio | G15: =D15 -> 6.25
A16: APPENDICES
A17: =HYPERLINK("#'Constants - Feedlot'!A1", "Constants - Feedlot") -> Constants - Feedlot | D17: M1_Table_I_j | L17: M2_Table_I_j
A18: =HYPERLINK("#'Constants - Livestock'!A1", "Constants - Livestock") -> Constants - Livestock | D18: Dry matter intake (Method 1) | L18: Dry matter intake (Method 2)
A19: =HYPERLINK("#'Constants - Common'!A1", "Constants - Common") -> Constants - Common | D19: Domestic | E19: Mid-fed | F19: Long-fed | L19: Domestic | M19: Mid-fed | N19: Long-fed
A20: =HYPERLINK("#'Acknowledgements'!A1", "Acknowledgements") -> Acknowledgements | D20: ='Input - Dairy'!$E$17 -> 365 | E20: ='Input - Dairy'!$F$17 -> 365 | F20: ='Input - Dairy'!$G$17 -> 281 | G20: kg DM/head/day | L20: ='Input - Dairy'!#REF! -> #REF! | M20: ='Input - Dairy'!#REF! -> #REF! | N20: ='Input - Dairy'!#REF! -> #REF! | O20: kg DM/head/day
D22: M1_Table_CP_j | L22: M2_Table_CP_j
D23: Crude protein content of feed (Method 1) | L23: Crude protein content of feed (Method 2)
D24: Domestic | E24: Mid-fed | F24: Long-fed | L24: Domestic | M24: Mid-fed | N24: Long-fed
D25: ='Input - Dairy'!#REF! -> #REF! | E25: ='Input - Dairy'!#REF! -> #REF! | F25: ='Input - Dairy'!#REF! -> #REF! | G25: Fraction | L25: ='Input - Dairy'!#REF! -> #REF! | M25: ='Input - Dairy'!#REF! -> #REF! | N25: ='Input - Dairy'!#REF! -> #REF! | O25: Fraction
D27: M1_Table_NI_j | L27: M2_Table_NI_j
D28: Nitrogen intake (Method 1) | L28: Nitrogen intake (Method 2)
D29: Domestic | E29: Mid-fed | F29: Long-fed | L29: Domestic | M29: Mid-fed | N29: Long-fed
D30: {=MMS_Feedlot_N2O_Direct_Equations.VEERG_4_1_1_3__5_NitrogenIntake(D20,D25)} -> #REF! | E30: {=MMS_Feedlot_N2O_Direct_Equations.VEERG_4_1_1_3__5_NitrogenIntake(E20,E25)} -> #REF! | F30: {=MMS_Feedlot_N2O_Direct_Equations.VEERG_4_1_1_3__5_NitrogenIntake(F20,F25)} -> #REF! | G30: =$E$11 -> kg N/head/day | L30: {=MMS_Feedlot_N2O_Direct_Equations.VEERG_4_1_1_3__5_NitrogenIntake(L20,L25)} -> #REF! | M30: {=MMS_Feedlot_N2O_Direct_Equations.VEERG_4_1_1_3__5_NitrogenIntake(M20,M25)} -> #REF! | N30: {=MMS_Feedlot_N2O_Direct_Equations.VEERG_4_1_1_3__5_NitrogenIntake(N20,N25)} -> #REF! | O30: =$E$11 -> kg N/head/day
D34: {=MMS_Feedlot_N2O_Direct_Equations.VEERG_4_1_1_3__4_NitrogenExcretionPerHead_Title()} -> Nitrogen excretion per head per day
D35: {=MMS_Feedlot_N2O_Direct_Equations.VEERG_4_1_1_3__4_NitrogenExcretionPerHead_Source()} -> VEERG 2026: 4.1.1.3, Equation (4)
D36: Function name | E36: {=Common_InputFunctions.Utility_DisplayFunctionName(D54)} -> =MMS_Feedlot_N2O_Direct_Equations.VEERG_4_1_1_3__4_NitrogenExcretionPerHead
D40: Variable | E40: {=MMS_Feedlot_N2O_Direct_Equations.VEERG_4_1_1_3__4_NitrogenExcretionPerHead_Variable()} -> NE_j
D41: Unit | E41: {=MMS_Feedlot_N2O_Direct_Equations.VEERG_4_1_1_3__4_NitrogenExcretionPerHead_Unit()} -> kg N/head/day
D43: {=MMS_Feedlot_N2O_Direct_Equations.VEERG_4_1_1_3__4_NitrogenExcretionPerHead_Arguments()} -> NI_j | E43: nitrogen intake : kg N/head/day | G43: ="See " & D27 -> See M1_Table_NI_j
D44: NR_j | E44: nitrogen retention expressed as a fraction of intake : fraction | G44: ="See " & D46 -> See M1_Table_NR_j
D46: M1_Table_NR_j | E46: Percent of intake needs converting to faction of intake before going to equation - needs conversion in equation or change of input unit | L46: M2_Table_NR_j | M46: Percent of intake needs converting to faction of intake before going to equation - needs conversion in equation or change of input unit
D47: Nitrogen retention (Method 1) | L47: Nitrogen retention (Method 2)
D48: Domestic | E48: Mid-fed | F48: Long-fed | L48: Domestic | M48: Mid-fed | N48: Long-fed
D49: ='Input - Dairy'!#REF!/100 -> #REF! | E49: ='Input - Dairy'!#REF!/100 -> #REF! | F49: ='Input - Dairy'!#REF!/100 -> #REF! | G49: Fraction of intake | L49: ='Input - Dairy'!#REF!/100 -> #REF! | M49: ='Input - Dairy'!#REF!/100 -> #REF! | N49: ='Input - Dairy'!#REF!/100 -> #REF! | O49: Fraction
D51: M1_Table_NE_j | L51: M2_Table_NE_j
D52: Nitrogen retention (Method 1) | L52: Nitrogen retention (Method 2)
D53: Domestic | E53: Mid-fed | F53: Long-fed | L53: Domestic | M53: Mid-fed | N53: Long-fed
...

Sheet 4.1.1.5-6 Atmos Deposition
A1: #VALUE! | C1: 4.1.1.5-6 Manure Atmospheric Deposition
A3: =HYPERLINK("#'Home'!A1", "Home") -> Home | D3: Method 1 | L3: Method 2
A4: =HYPERLINK("#'Results'!A1", "Results") -> Results
D5: {=MMS_Feedlot_AtmosphericDeposition_Equations.VEERG_4_1_1_5__2_VolatilisedNitrogenFromManureManagement_Title()} -> Volatilised nitrogen from manure management
A6: INPUTS | D6: {=MMS_Feedlot_AtmosphericDeposition_Equations.VEERG_4_1_1_5__2_VolatilisedNitrogenFromManureManagement_Source()} -> VEERG 2026: 4.1.1.5, Equation (2)
A7: =HYPERLINK("#'Input - Site'!A1", "Site") -> Site | D7: Function name | E7: {=Common_InputFunctions.Utility_DisplayFunctionName(E36)} -> =MMS_Feedlot_AtmosphericDeposition_Equations.VEERG_4_1_1_5__2_VolatilisedNitrogenFromManureManagement
A8: =HYPERLINK("#'Input - Feedlot'!A1", "Feedlot") -> Feedlot
A10: CALCULATIONS
A11: =HYPERLINK("#'4.1.1.1-2 Methane'!A1", "4.1.1.1-2 Methane") -> 4.1.1.1-2 Methane | D11: Variable | E11: {=MMS_Feedlot_AtmosphericDeposition_Equations.VEERG_4_1_1_5__2_VolatilisedNitrogenFromManureManagement_Variable()} -> MMS_ATMOS
A12: =HYPERLINK("#'4.1.1.3-4 Direct N20'!A1", "4.1.1.3-4 Direct N2O") -> 4.1.1.3-4 Direct N2O | D12: Unit | E12: {=MMS_Feedlot_AtmosphericDeposition_Equations.VEERG_4_1_1_5__2_VolatilisedNitrogenFromManureManagement_Unit()} -> kg N
A13: =HYPERLINK("#'4.1.1.5-6 Atmos Deposition'!A1", "4.1.1.5-6 Atmospheric deposition") -> 4.1.1.5-6 Atmospheric deposition
A14: =HYPERLINK("#'4.1.1.9 Manure applied to soils'!A1", "4.1.1.9 Manure applied to soils") -> 4.1.1.9 Manure applied to soils | D14: {=MMS_Feedlot_AtmosphericDeposition_Equations.VEERG_4_1_1_5__2_VolatilisedNitrogenFromManureManagement_Arguments()} -> MN_jmT | E14: nitrogen in each treatment stage MMS (excluding MN_ijm13T2) : kg N | G14: ="See " & D17 -> See M1_Table_MN_j_m_T
D15: FracGASM_mT | E15: fraction of N volatilised in each MMS : (kg NH3-N + NOx-N)/kg N | G15: ="See " & D25 -> See Table_FracGASM_m_T-2-3
A16: APPENDICES
A17: =HYPERLINK("#'Constants - Feedlot'!A1", "Constants - Feedlot") -> Constants - Feedlot | D17: M1_Table_MN_j_m_T | L17: M2_Table_MN_j_m_T
A18: =HYPERLINK("#'Constants - Livestock'!A1", "Constants - Livestock") -> Constants - Livestock | D18: Nitrogen in each MMS excluding direct application (Method 1) | L18: Nitrogen in each MMS excluding direct application (Method 2)
A19: =HYPERLINK("#'Constants - Common'!A1", "Constants - Common") -> Constants - Common | D19: MMS | E19: Domestic | F19: Mid-fed | G19: Long-fed | L19: MMS | M19: Domestic | N19: Mid-fed | O19: Long-fed
A20: =HYPERLINK("#'Acknowledgements'!A1", "Acknowledgements") -> Acknowledgements | D20: ='Input - Dairy'!$D$72 -> Total manure sent to MMS (Must equal 100%) (Method 2) | E20: ='4.1.1.3-4 Direct N20'!$E$106 -> #REF! | F20: ='4.1.1.3-4 Direct N20'!$F$106 -> #REF! | G20: ='4.1.1.3-4 Direct N20'!$G$106 -> #REF! | H20: kg N | L20: ='Input - Dairy'!$D$72 -> Total manure sent to MMS (Must equal 100%) (Method 2) | M20: ='4.1.1.3-4 Direct N20'!$M$106 -> #REF! | N20: ='4.1.1.3-4 Direct N20'!$N$106 -> #REF! | O20: ='4.1.1.3-4 Direct N20'!$O$106 -> #REF! | P20: kg N
D21: ='Input - Dairy'!$D$78 -> Anaerobic lagoon | E21: ='4.1.1.3-4 Direct N20'!$E$173 -> #REF! | F21: ='4.1.1.3-4 Direct N20'!$F$173 -> #REF! | G21: ='4.1.1.3-4 Direct N20'!$G$173 -> #REF! | H21: kg N | L21: ='Input - Dairy'!$D$78 -> Anaerobic lagoon | M21: ='4.1.1.3-4 Direct N20'!$M$173 -> #REF! | N21: ='4.1.1.3-4 Direct N20'!$N$173 -> #REF! | O21: ='4.1.1.3-4 Direct N20'!$O$173 -> #REF! | P21: kg N
D22: ='Input - Dairy'!$D$79 -> Were solids separated from Anaerobic lagoon? | E22: ='4.1.1.3-4 Direct N20'!$E$174 -> #REF! | F22: ='4.1.1.3-4 Direct N20'!$F$174 -> #REF! | G22: ='4.1.1.3-4 Direct N20'!$G$174 -> #REF! | H22: kg N | L22: ='Input - Dairy'!$D$79 -> Were solids separated from Anaerobic lagoon? | M22: ='4.1.1.3-4 Direct N20'!$M$174 -> #REF! | N22: ='4.1.1.3-4 Direct N20'!$N$174 -> #REF! | O22: ='4.1.1.3-4 Direct N20'!$O$174 -> #REF! | P22: kg N
D23: ='Input - Dairy'!$D$84 -> Were solids separated from Sump and dispersal system? | E23: ='4.1.1.3-4 Direct N20'!$E$129 -> #REF! | F23: ='4.1.1.3-4 Direct N20'!$F$129 -> #REF! | G23: ='4.1.1.3-4 Direct N20'!$G$129 -> #REF! | H23: kg N | L23: ='Input - Dairy'!$D$84 -> Were solids separated from Sump and dispersal system? | M23: ='4.1.1.3-4 Direct N20'!$M$129 -> #REF! | N23: ='4.1.1.3-4 Direct N20'!$N$129 -> #REF! | O23: ='4.1.1.3-4 Direct N20'!$O$129 -> #REF! | P23: kg N
D25: Table_FracGASM_m_T-2-3
D26: Fraction of N volatilised in each MMS
D27: MMS | E27: EFjm
D28: ='Input - Dairy'!$D$72 -> Total manure sent to MMS (Must equal 100%) (Method 2) | E28: =_xlfn.XLOOKUP(D28, #REF!, #REF!) -> #REF! | F28: (kg NH3-N + NOx-N)/kg N
D29: ='Input - Dairy'!$D$78 -> Anaerobic lagoon | E29: =_xlfn.XLOOKUP(D29, #REF!, #REF!) -> #REF! | F29: (kg NH3-N + NOx-N)/kg N
D30: ='Input - Dairy'!$D$79 -> Were solids separated from Anaerobic lagoon? | E30: =_xlfn.XLOOKUP(D30, #REF!, #REF!) -> #REF! | F30: (kg NH3-N + NOx-N)/kg N
D31: ='Input - Dairy'!$D$84 -> Were solids separated from Sump and dispersal system? | E31: =_xlfn.XLOOKUP(D31, #REF!, #REF!) -> #REF! | F31: (kg NH3-N + NOx-N)/kg N
D33: M1_Table_MMS_ATMOS | L33: M1_Table_MMS_ATMOS
D34: Nitrogen in each MMS excluding direct application (Method 1) | L34: Nitrogen in each MMS excluding direct application (Method 1)
D35: MMS | E35: Domestic | F35: Mid-fed | G35: Long-fed | L35: MMS | M35: Domestic | N35: Mid-fed | O35: Long-fed
D36: ='Input - Dairy'!$D$72 -> Total manure sent to MMS (Must equal 100%) (Method 2) | E36: {=MMS_Feedlot_AtmosphericDeposition_Equations.VEERG_4_1_1_5__2_VolatilisedNitrogenFromManureManagement(E20,$E28)} -> #REF! | F36: {=MMS_Feedlot_AtmosphericDeposition_Equations.VEERG_4_1_1_5__2_VolatilisedNitrogenFromManureManagement(F20,$E28)} -> #REF! | G36: {=MMS_Feedlot_AtmosphericDeposition_Equations.VEERG_4_1_1_5__2_VolatilisedNitrogenFromManureManagement(G20,$E28)} -> #REF! | H36: =$E$12 -> kg N | L36: ='Input - Dairy'!$D$72 -> Total manure sent to MMS (Must equal 100%) (Method 2) | M36: {=MMS_Feedlot_AtmosphericDeposition_Equations.VEERG_4_1_1_5__2_VolatilisedNitrogenFromManureManagement(M20,$E28)} -> #REF! | N36: {=MMS_Feedlot_AtmosphericDeposition_Equations.VEERG_4_1_1_5__2_VolatilisedNitrogenFromManureManagement(N20,$E28)} -> #REF! | O36: {=MMS_Feedlot_AtmosphericDeposition_Equations.VEERG_4_1_1_5__2_VolatilisedNitrogenFromManureManagement(O20,$E28)} -> #REF! | P36: kg N
D37: ='Input - Dairy'!$D$78 -> Anaerobic lagoon | E37: {=MMS_Feedlot_AtmosphericDeposition_Equations.VEERG_4_1_1_5__2_VolatilisedNitrogenFromManureManagement(E21,$E29)} -> #REF! | F37: {=MMS_Feedlot_AtmosphericDeposition_Equations.VEERG_4_1_1_5__2_VolatilisedNitrogenFromManureManagement(F21,$E29)} -> #REF! | G37: {=MMS_Feedlot_AtmosphericDeposition_Equations.VEERG_4_1_1_5__2_VolatilisedNitrogenFromManureManagement(G21,$E29)} -> #REF! | H37: =$E$12 -> kg N | L37: ='Input - Dairy'!$D$78 -> Anaerobic lagoon | M37: {=MMS_Feedlot_AtmosphericDeposition_Equations.VEERG_4_1_1_5__2_VolatilisedNitrogenFromManureManagement(M21,$E29)} -> #REF! | N37: {=MMS_Feedlot_AtmosphericDeposition_Equations.VEERG_4_1_1_5__2_VolatilisedNitrogenFromManureManagement(N21,$E29)} -> #REF! | O37: {=MMS_Feedlot_AtmosphericDeposition_Equations.VEERG_4_1_1_5__2_VolatilisedNitrogenFromManureManagement(O21,$E29)} -> #REF! | P37: kg N
D38: ='Input - Dairy'!$D$79 -> Were solids separated from Anaerobic lagoon? | E38: {=MMS_Feedlot_AtmosphericDeposition_Equations.VEERG_4_1_1_5__2_VolatilisedNitrogenFromManureManagement(E22,$E30)} -> #REF! | F38: {=MMS_Feedlot_AtmosphericDeposition_Equations.VEERG_4_1_1_5__2_VolatilisedNitrogenFromManureManagement(F22,$E30)} -> #REF! | G38: {=MMS_Feedlot_AtmosphericDeposition_Equations.VEERG_4_1_1_5__2_VolatilisedNitrogenFromManureManagement(G22,$E30)} -> #REF! | H38: =$E$12 -> kg N | L38: ='Input - Dairy'!$D$79 -> Were solids separated from Anaerobic lagoon? | M38: {=MMS_Feedlot_AtmosphericDeposition_Equations.VEERG_4_1_1_5__2_VolatilisedNitrogenFromManureManagement(M22,$E30)} -> #REF! | N38: {=MMS_Feedlot_AtmosphericDeposition_Equations.VEERG_4_1_1_5__2_VolatilisedNitrogenFromManureManagement(N22,$E30)} -> #REF! | O38: {=MMS_Feedlot_AtmosphericDeposition_Equations.VEERG_4_1_1_5__2_VolatilisedNitrogenFromManureManagement(O22,$E30)} -> #REF! | P38: kg N
D39: ='Input - Dairy'!$D$84 -> Were solids separated from Sump and dispersal system? | E39: {=MMS_Feedlot_AtmosphericDeposition_Equations.VEERG_4_1_1_5__2_VolatilisedNitrogenFromManureManagement(E23,$E31)} -> #REF! | F39: {=MMS_Feedlot_AtmosphericDeposition_Equations.VEERG_4_1_1_5__2_VolatilisedNitrogenFromManureManagement(F23,$E31)} -> #REF! | G39: {=MMS_Feedlot_AtmosphericDeposition_Equations.VEERG_4_1_1_5__2_VolatilisedNitrogenFromManureManagement(G23,$E31)} -> #REF! | H39: =$E$12 -> kg N | L39: ='Input - Dairy'!$D$84 -> Were solids separated from Sump and dispersal system? | M39: {=MMS_Feedlot_AtmosphericDeposition_Equations.VEERG_4_1_1_5__2_VolatilisedNitrogenFromManureManagement(M23,$E31)} -> #REF! | N39: {=MMS_Feedlot_AtmosphericDeposition_Equations.VEERG_4_1_1_5__2_VolatilisedNitrogenFromManureManagement(N23,$E31)} -> #REF! | O39: {=MMS_Feedlot_AtmosphericDeposition_Equations.VEERG_4_1_1_5__2_VolatilisedNitrogenFromManureManagement(O23,$E31)} -> #REF! | P39: kg N
D41: MMSATMOS | E41: =SUM(E36:G39) -> #REF! | F41: =$E$12 -> kg N | L41: MMSATMOS | M41: =SUM(M36:O39) -> #REF! | N41: =$E$12 -> kg N
D45: {=MMS_Feedlot_AtmosphericDeposition_Equations.VEERG_4_1_1_5__1_TotalAnnualAtmosphericDepositionEmissions_Title()} -> Total annual atmospheric deposition emissions from manure management
D46: {=MMS_Feedlot_AtmosphericDeposition_Equations.VEERG_4_1_1_5__1_TotalAnnualAtmosphericDepositionEmissions_Source()} -> VEERG 2026: 4.1.1.5, Equation (1)
D47: Function name | E47: {=Common_InputFunctions.Utility_DisplayFunctionName(E60)} -> =MMS_Feedlot_AtmosphericDeposition_Equations.VEERG_4_1_1_5__1_TotalAnnualAtmosphericDepositionEmissions
D50: Variable | E50: {=MMS_Feedlot_AtmosphericDeposition_Equations.VEERG_4_1_1_5__1_TotalAnnualAtmosphericDepositionEmissions_Variable()} -> E_N2Oad
...

Sheet 4.1.1.9 Manure applied to soils
A1: #VALUE! | C1: 4.1.1.9 Manure applied to soils
A3: =HYPERLINK("#'Home'!A1", "Home") -> Home | D3: Method 1 | L3: Method 2
A4: =HYPERLINK("#'Results'!A1", "Results") -> Results
D5: {=MMS_Feedlot_ManureAppliedToSoils_Equations.VEERG_4_1_1_9__1_MassOfNitrogenAppliedToSoilsScope1_Title()} -> Mass of nitrogen applied to soils for scope 1 emissions
A6: INPUTS | D6: {=MMS_Feedlot_ManureAppliedToSoils_Equations.VEERG_4_1_1_9__1_MassOfNitrogenAppliedToSoilsScope1_Source()} -> VEERG 2026: 4.1.1.9, Equation (1)
A7: =HYPERLINK("#'Input - Site'!A1", "Site") -> Site | D7: Function name | E7: {=Common_InputFunctions.Utility_DisplayFunctionName(E52)} -> =MMS_Feedlot_ManureAppliedToSoils_Equations.VEERG_4_1_1_9__1_MassOfNitrogenAppliedToSoilsScope1
A8: =HYPERLINK("#'Input - Feedlot'!A1", "Feedlot") -> Feedlot
A10: CALCULATIONS
A11: =HYPERLINK("#'4.1.1.1-2 Methane'!A1", "4.1.1.1-2 Methane") -> 4.1.1.1-2 Methane | D11: Variable | E11: {=MMS_Feedlot_ManureAppliedToSoils_Equations.VEERG_4_1_1_9__1_MassOfNitrogenAppliedToSoilsScope1_Variable()} -> MNSoil_scope1
A12: =HYPERLINK("#'4.1.1.3-4 Direct N20'!A1", "4.1.1.3-4 Direct N2O") -> 4.1.1.3-4 Direct N2O | D12: Unit | E12: {=MMS_Feedlot_ManureAppliedToSoils_Equations.VEERG_4_1_1_9__1_MassOfNitrogenAppliedToSoilsScope1_Unit()} -> kg N
A13: =HYPERLINK("#'4.1.1.5-6 Atmos Deposition'!A1", "4.1.1.5-6 Atmospheric deposition") -> 4.1.1.5-6 Atmospheric deposition
A14: =HYPERLINK("#'4.1.1.9 Manure applied to soils'!A1", "4.1.1.9 Manure applied to soils") -> 4.1.1.9 Manure applied to soils | D14: {=MMS_Feedlot_ManureAppliedToSoils_Equations.VEERG_4_1_1_9__1_MassOfNitrogenAppliedToSoilsScope1_Arguments()} -> MN_jmT23 | E14: mass of N in secondary and tertiary treatment MMS stages as calculated for manure management : kg N | H14: ="See " & $D$19 -> See M1_Table_MN_j_m_T-2-3
D15: EF_mT23 | E15: nitrous oxide emission factor for each MMS : kg N2O-N/kg N | H15: ="See " & $D$26 -> See Table_EF_j_m_T-2-3
A16: APPENDICES | D16: FracGASM_mT23 | E16: fraction of animal waste N volatilised in each MMS for each cattle group : (kg NH3-N + NOx-N)/kg N | H16: ="See " & $D$34 -> See Table_FracGASM_m_T-2-3
A17: =HYPERLINK("#'Constants - Feedlot'!A1", "Constants - Feedlot") -> Constants - Feedlot | D17: PF | E17: fraction of manure applied to soil within the feedlot boundary : fraction | H17: ="See " & $D$42 -> See Table_PF
A18: =HYPERLINK("#'Constants - Livestock'!A1", "Constants - Livestock") -> Constants - Livestock
A19: =HYPERLINK("#'Constants - Common'!A1", "Constants - Common") -> Constants - Common | D19: M1_Table_MN_j_m_T-2-3 | L19: M2_Table_MN_j_m_T-2-3
A20: =HYPERLINK("#'Acknowledgements'!A1", "Acknowledgements") -> Acknowledgements | D20: Mass on N in stage 2 and 3 MMS (Method 1) | L20: Mass on N in stage 2 and 3 MMS (Method 2)
D21: MMS | E21: Domestic | F21: Mid-fed | G21: Long-fed | L21: MMS | M21: Domestic | N21: Mid-fed | O21: Long-fed
D22: ='Input - Dairy'!$D$78 -> Anaerobic lagoon | E22: ='4.1.1.3-4 Direct N20'!$E$173 -> #REF! | F22: ='4.1.1.3-4 Direct N20'!$F$173 -> #REF! | G22: ='4.1.1.3-4 Direct N20'!$G$173 -> #REF! | H22: kg N | L22: ='Input - Dairy'!$D$78 -> Anaerobic lagoon | M22: ='4.1.1.3-4 Direct N20'!$M$173 -> #REF! | N22: ='4.1.1.3-4 Direct N20'!$N$173 -> #REF! | O22: ='4.1.1.3-4 Direct N20'!$O$173 -> #REF! | P22: kg N
D23: ='Input - Dairy'!$D$79 -> Were solids separated from Anaerobic lagoon? | E23: ='4.1.1.3-4 Direct N20'!$E$174 -> #REF! | F23: ='4.1.1.3-4 Direct N20'!$F$174 -> #REF! | G23: ='4.1.1.3-4 Direct N20'!$G$174 -> #REF! | H23: kg N | L23: ='Input - Dairy'!$D$79 -> Were solids separated from Anaerobic lagoon? | M23: ='4.1.1.3-4 Direct N20'!$M$174 -> #REF! | N23: ='4.1.1.3-4 Direct N20'!$N$174 -> #REF! | O23: ='4.1.1.3-4 Direct N20'!$O$174 -> #REF! | P23: kg N
D24: ='Input - Dairy'!$D$84 -> Were solids separated from Sump and dispersal system? | E24: ='4.1.1.3-4 Direct N20'!$E$129 -> #REF! | F24: ='4.1.1.3-4 Direct N20'!$F$129 -> #REF! | G24: ='4.1.1.3-4 Direct N20'!$G$129 -> #REF! | H24: kg N | L24: ='Input - Dairy'!$D$84 -> Were solids separated from Sump and dispersal system? | M24: ='4.1.1.3-4 Direct N20'!$M$129 -> #REF! | N24: ='4.1.1.3-4 Direct N20'!$N$129 -> #REF! | O24: ='4.1.1.3-4 Direct N20'!$O$129 -> #REF! | P24: kg N
D26: Table_EF_j_m_T-2-3
D27: EFs for MMS
D28: MMS | E28: EFjm
D29: ='Input - Dairy'!$D$72 -> Total manure sent to MMS (Must equal 100%) (Method 2) | E29: =_xlfn.XLOOKUP(D29, #REF!, #REF!) -> #REF! | F29: kg N2O/kg N
D30: ='Input - Dairy'!$D$78 -> Anaerobic lagoon | E30: =_xlfn.XLOOKUP($D$30, #REF!, #REF!) -> #REF! | F30: kg N2O/kg N
D31: ='Input - Dairy'!$D$79 -> Were solids separated from Anaerobic lagoon? | E31: =_xlfn.XLOOKUP($D$31, #REF!, #REF!) -> #REF! | F31: kg N2O/kg N
D32: ='Input - Dairy'!$D$84 -> Were solids separated from Sump and dispersal system? | E32: =_xlfn.XLOOKUP($D$32, #REF!, #REF!) -> #REF! | F32: kg N2O/kg N
D34: Table_FracGASM_m_T-2-3
D35: Fraction of N volatilised in each MMS
D36: MMS | E36: EFjm
D37: ='Input - Dairy'!$D$72 -> Total manure sent to MMS (Must equal 100%) (Method 2) | E37: =_xlfn.XLOOKUP(D37, #REF!, #REF!) -> #REF! | F37: (kg NH3-N + NOx-N)/kg N
D38: ='Input - Dairy'!$D$78 -> Anaerobic lagoon | E38: =_xlfn.XLOOKUP(D38, #REF!, #REF!) -> #REF! | F38: (kg NH3-N + NOx-N)/kg N
D39: ='Input - Dairy'!$D$79 -> Were solids separated from Anaerobic lagoon? | E39: =_xlfn.XLOOKUP(D39, #REF!, #REF!) -> #REF! | F39: (kg NH3-N + NOx-N)/kg N
D40: ='Input - Dairy'!$D$84 -> Were solids separated from Sump and dispersal system? | E40: =_xlfn.XLOOKUP(D40, #REF!, #REF!) -> #REF! | F40: (kg NH3-N + NOx-N)/kg N
D42: Table_PF
D43: Fraction of manure applied to soil from MMS
D44: MMS | E44: Domestic | F44: Mid-fed | G44: Long-fed
D45: ='Input - Dairy'!$D$78 -> Anaerobic lagoon | E45: ='Input - Dairy'!E116 -> 0.5 | F45: ='Input - Dairy'!F116 -> 0.5 | G45: ='Input - Dairy'!G116 -> 0.5 | H45: Fraction
...

Sheet Constants - Dairy
A1: #VALUE! | C1: Source Data - Feedlot
A3: =HYPERLINK("#'Home'!A1", "Home") -> Home
A4: =HYPERLINK("#'Results'!A1", "Results") -> Results
D5: Dairy manure management systems | G5: Dairy crop or pasture production systems | J5: Irrigation methods
A6: INPUTS
A7: =HYPERLINK("#'Input - Site'!A1", "Site") -> Site | D7: MMS | E7: Symbol and MMS | G7: Production system | J7: Irrigation method
A8: =HYPERLINK("#'Input - Feedlot'!A1", "Feedlot") -> Feedlot | D8: ='Constants - Livestock'!$E$10 -> Anaerobic lagoon | E8: ='Constants - Livestock'!$F$10 -> Anaerobic lagoon (m=1) | G8: ='Constants - Common'!$F$176 -> Pasture | J8: Not irrigated
D9: ='Constants - Livestock'!$E$13 -> Sump and dispersal system | E9: ='Constants - Livestock'!$F$13 -> Sump and dispersal system (m=3a) | G9: ='Constants - Common'!$F$177 -> Crop | J9: Drip irrigation
A10: CALCULATIONS | D10: ='Constants - Livestock'!$E$14 -> Drains to paddock | E10: ='Constants - Livestock'!$F$14 -> Drains to paddock (m=3b) | J10: Sprinkler irrigation
A11: =HYPERLINK("#'4.1.1.1-2 Methane'!A1", "4.1.1.1-2 Methane") -> 4.1.1.1-2 Methane | D11: ='Constants - Livestock'!$E$15 -> Solid storage | E11: ='Constants - Livestock'!$F$15 -> Solid storage (m=4) | J11: Surface irrigation
A12: =HYPERLINK("#'4.1.1.3-4 Direct N20'!A1", "4.1.1.3-4 Direct N2O") -> 4.1.1.3-4 Direct N2O | J12: Other irrigation
A13: =HYPERLINK("#'4.1.1.5-6 Atmos Deposition'!A1", "4.1.1.5-6 Atmospheric deposition") -> 4.1.1.5-6 Atmospheric deposition
A14: =HYPERLINK("#'4.1.1.9 Manure applied to soils'!A1", "4.1.1.9 Manure applied to soils") -> 4.1.1.9 Manure applied to soils
A16: APPENDICES | D16: {=SourceData_Dairy.SourceData_Dairy_LiveweightCowsAndHeifers_Title()} -> Table A.1.3.1: Dairy cattle - Liveweight (kg) - Cows and Heifers (Wj)
A17: =HYPERLINK("#'Constants - Feedlot'!A1", "Constants - Feedlot") -> Constants - Feedlot | D17: {=SourceData_Dairy.SourceData_Dairy_LiveweightCowsAndHeifers_Source()} -> VEERG 2026: Table A.1.3.1
A18: =HYPERLINK("#'Constants - Livestock'!A1", "Constants - Livestock") -> Constants - Livestock | D18: {=SourceData_Dairy.SourceData_Dairy_LiveweightCowsAndHeifers_Variable()} -> Wj
A19: =HYPERLINK("#'Constants - Common'!A1", "Constants - Common") -> Constants - Common | D19: {=SourceData_Dairy.SourceData_Dairy_LiveweightCowsAndHeifers_Unit()} -> kg
A20: =HYPERLINK("#'Acknowledgements'!A1", "Acknowledgements") -> Acknowledgements | D20: {=SourceData_Dairy.SourceData_Dairy_LiveweightCowsAndHeifers_Variation()} -> VARIATION OF SOURCE: Excluded 'Reference', as the value is consistently 'Dairy Australia [1]' and is not used in calculation.
D21: Breed | E21: Milking cows | F21: Heifers > 1 | G21: Heifers < 1 (weaned)
D22: {=Common_InputFunctions.Utility_DisplayArrayInTable(SourceData_Dairy.SourceData_Dairy_LiveweightCowsAndHeifers_Data(), Table_SourceData_Dairy_WjCowsHeifers[[#Headers],[Breed]], 0)} -> Medium Friesian | E22: {=Common_InputFunctions.Utility_DisplayArrayInTable(SourceData_Dairy.SourceData_Dairy_LiveweightCowsAndHeifers_Data(), Table_SourceData_Dairy_WjCowsHeifers[[#Headers],[Breed]], 0)} -> 550 | F22: {=Common_InputFunctions.Utility_DisplayArrayInTable(SourceData_Dairy.SourceData_Dairy_LiveweightCowsAndHeifers_Data(), Table_SourceData_Dairy_WjCowsHeifers[[#Headers],[Breed]], 0)} -> 380 | G22: {=Common_InputFunctions.Utility_DisplayArrayInTable(SourceData_Dairy.SourceData_Dairy_LiveweightCowsAndHeifers_Data(), Table_SourceData_Dairy_WjCowsHeifers[[#Headers],[Breed]], 0)} -> 155
D23: {=Common_InputFunctions.Utility_DisplayArrayInTable(SourceData_Dairy.SourceData_Dairy_LiveweightCowsAndHeifers_Data(), Table_SourceData_Dairy_WjCowsHeifers[[#Headers],[Breed]], 0)} -> Large Friesian | E23: {=Common_InputFunctions.Utility_DisplayArrayInTable(SourceData_Dairy.SourceData_Dairy_LiveweightCowsAndHeifers_Data(), Table_SourceData_Dairy_WjCowsHeifers[[#Headers],[Breed]], 0)} -> 600 | F23: {=Common_InputFunctions.Utility_DisplayArrayInTable(SourceData_Dairy.SourceData_Dairy_LiveweightCowsAndHeifers_Data(), Table_SourceData_Dairy_WjCowsHeifers[[#Headers],[Breed]], 0)} -> 415 | G23: {=Common_InputFunctions.Utility_DisplayArrayInTable(SourceData_Dairy.SourceData_Dairy_LiveweightCowsAndHeifers_Data(), Table_SourceData_Dairy_WjCowsHeifers[[#Headers],[Breed]], 0)} -> 170
D24: {=Common_InputFunctions.Utility_DisplayArrayInTable(SourceData_Dairy.SourceData_Dairy_LiveweightCowsAndHeifers_Data(), Table_SourceData_Dairy_WjCowsHeifers[[#Headers],[Breed]], 0)} -> Holstein-Friesian | E24: {=Common_InputFunctions.Utility_DisplayArrayInTable(SourceData_Dairy.SourceData_Dairy_LiveweightCowsAndHeifers_Data(), Table_SourceData_Dairy_WjCowsHeifers[[#Headers],[Breed]], 0)} -> 650 | F24: {=Common_InputFunctions.Utility_DisplayArrayInTable(SourceData_Dairy.SourceData_Dairy_LiveweightCowsAndHeifers_Data(), Table_SourceData_Dairy_WjCowsHeifers[[#Headers],[Breed]], 0)} -> 450 | G24: {=Common_InputFunctions.Utility_DisplayArrayInTable(SourceData_Dairy.SourceData_Dairy_LiveweightCowsAndHeifers_Data(), Table_SourceData_Dairy_WjCowsHeifers[[#Headers],[Breed]], 0)} -> 185
D25: {=Common_InputFunctions.Utility_DisplayArrayInTable(SourceData_Dairy.SourceData_Dairy_LiveweightCowsAndHeifers_Data(), Table_SourceData_Dairy_WjCowsHeifers[[#Headers],[Breed]], 0)} -> Friesian crossbred | E25: {=Common_InputFunctions.Utility_DisplayArrayInTable(SourceData_Dairy.SourceData_Dairy_LiveweightCowsAndHeifers_Data(), Table_SourceData_Dairy_WjCowsHeifers[[#Headers],[Breed]], 0)} -> 500 | F25: {=Common_InputFunctions.Utility_DisplayArrayInTable(SourceData_Dairy.SourceData_Dairy_LiveweightCowsAndHeifers_Data(), Table_SourceData_Dairy_WjCowsHeifers[[#Headers],[Breed]], 0)} -> 350 | G25: {=Common_InputFunctions.Utility_DisplayArrayInTable(SourceData_Dairy.SourceData_Dairy_LiveweightCowsAndHeifers_Data(), Table_SourceData_Dairy_WjCowsHeifers[[#Headers],[Breed]], 0)} -> 145
D26: {=Common_InputFunctions.Utility_DisplayArrayInTable(SourceData_Dairy.SourceData_Dairy_LiveweightCowsAndHeifers_Data(), Table_SourceData_Dairy_WjCowsHeifers[[#Headers],[Breed]], 0)} -> Jersey | E26: {=Common_InputFunctions.Utility_DisplayArrayInTable(SourceData_Dairy.SourceData_Dairy_LiveweightCowsAndHeifers_Data(), Table_SourceData_Dairy_WjCowsHeifers[[#Headers],[Breed]], 0)} -> 400 | F26: {=Common_InputFunctions.Utility_DisplayArrayInTable(SourceData_Dairy.SourceData_Dairy_LiveweightCowsAndHeifers_Data(), Table_SourceData_Dairy_WjCowsHeifers[[#Headers],[Breed]], 0)} -> 275 | G26: {=Common_InputFunctions.Utility_DisplayArrayInTable(SourceData_Dairy.SourceData_Dairy_LiveweightCowsAndHeifers_Data(), Table_SourceData_Dairy_WjCowsHeifers[[#Headers],[Breed]], 0)} -> 115
D27: {=Common_InputFunctions.Utility_DisplayArrayInTable(SourceData_Dairy.SourceData_Dairy_LiveweightCowsAndHeifers_Data(), Table_SourceData_Dairy_WjCowsHeifers[[#Headers],[Breed]], 0)} -> Jersey crossbred | E27: {=Common_InputFunctions.Utility_DisplayArrayInTable(SourceData_Dairy.SourceData_Dairy_LiveweightCowsAndHeifers_Data(), Table_SourceData_Dairy_WjCowsHeifers[[#Headers],[Breed]], 0)} -> 450 | F27: {=Common_InputFunctions.Utility_DisplayArrayInTable(SourceData_Dairy.SourceData_Dairy_LiveweightCowsAndHeifers_Data(), Table_SourceData_Dairy_WjCowsHeifers[[#Headers],[Breed]], 0)} -> 315 | G27: {=Common_InputFunctions.Utility_DisplayArrayInTable(SourceData_Dairy.SourceData_Dairy_LiveweightCowsAndHeifers_Data(), Table_SourceData_Dairy_WjCowsHeifers[[#Headers],[Breed]], 0)} -> 130
