Workbook
Name Common_Equations.Common_ConvertCH4ToCO2e: _xlfn.LAMBDA(_xlpm.E_CH4,_xlpm.GWP_CH4, _xlpm.E_CH4 * _xlpm.GWP_CH4)
Name Common_Equations.Common_ConvertCH4ToCO2e_Arguments: _xlfn.LAMBDA(_xlfn.MAKEARRAY(2, 2, _xlfn.LAMBDA(_xlpm.r,_xlpm.c, INDEX({"ECH4","Methane emissions (t CH4)";"GWPCH4","Global warming potential for methane (t CO2-e / t CH4)"}, _xlpm.r, _xlpm.c))))
Name Common_Equations.Common_ConvertCH4ToCO2e_LatexEquation: _xlfn.LAMBDA("CO2_e = E_{CH4} \times GWP_{CH4}")
Name Common_Equations.Common_ConvertCH4ToCO2e_NIRReference: _xlfn.LAMBDA("")
Name Common_Equations.Common_ConvertCH4ToCO2e_Title: _xlfn.LAMBDA("Convert methane emissions to carbon dioxide equivalent emissions")
Name Common_Equations.Common_ConvertCH4ToCO2e_Unit: _xlfn.LAMBDA("t CO2e")
Name Common_Equations.Common_ConvertCH4ToCO2e_Variable: _xlfn.LAMBDA("ECH4 CO2e")
Name Common_Equations.Common_ConvertN2OToCO2e: _xlfn.LAMBDA(_xlpm.E_N2O,_xlpm.GWP_N2O, _xlpm.E_N2O * _xlpm.GWP_N2O)
Name Common_Equations.Common_ConvertN2OToCO2e_LatexEquation: _xlfn.LAMBDA("CO2_e = E_{N2O} \times GWP_{N2O}")
Name Common_Equations.Common_ConvertN2OToCO2e_NIRReference: _xlfn.LAMBDA("")
Name Common_Equations.Common_ConvertN2OToCO2e_Title: _xlfn.LAMBDA("Convert nitrous oxide emissions to carbon dioxide equivalent emissions")
Name Common_Equations.Common_ConvertN2OToCO2e_Unit: _xlfn.LAMBDA("t CO2e")
Name Common_Equations.Common_ConvertN2OToCO2e_Variable: _xlfn.LAMBDA("EN2O CO2e")
Name Common_InputFunctions.Utility_DisplayFunctionName: _xlfn.LAMBDA(_xlpm.Function, _xlfn.TEXTBEFORE(_xlfn.FORMULATEXT(_xlpm.Function), "("))
Name Common_InputFunctions.Utility_GetArrayTableColumnStartNumber: _xlfn.LAMBDA(_xlpm.TableHeaderCell, COLUMN(_xlpm.TableHeaderCell))
Name Common_InputFunctions.Utility_GetArrayTableRowStartNumber: _xlfn.LAMBDA(_xlpm.TableheaderCell,_xlpm.RowsBetweenHeaderandArray, ROW(_xlpm.TableheaderCell) + _xlpm.RowsBetweenHeaderandArray - 1)
Name Common_InputFunctions.Utility_LookupValueInTable: _xlfn.LAMBDA(_xlpm.LookupValue,_xlpm.LookupArray,_xlpm.ReturnArray, _xlfn.XLOOKUP(_xlpm.LookupValue, _xlpm.LookupArray, _xlpm.ReturnArray, ""))
Name Common_SourceData.Common_SourceData_AustralianStatesTerritories_Source: _xlfn.LAMBDA("")
Name Common_SourceData.Common_SourceData_AustralianStatesTerritories_Title: _xlfn.LAMBDA("Australian states and territories")
Name Common_SourceData.Common_SourceData_AustralianStatesTerritories_Unit: _xlfn.LAMBDA("")
Name Common_SourceData.Common_SourceData_AustralianStatesTerritories_Variable: _xlfn.LAMBDA("")
Name Common_SourceData.Common_SourceData_ClimateZones_Source: _xlfn.LAMBDA("VEERG 2026: Table 1.3: Climate and Rainfall zone classifications and definitions")
Name Common_SourceData.Common_SourceData_ClimateZones_Title: _xlfn.LAMBDA("VEERG Australian climate zones")
Name Common_SourceData.Common_SourceData_ClimateZones_Unit: _xlfn.LAMBDA("")
Name Common_SourceData.Common_SourceData_ClimateZones_Variable: _xlfn.LAMBDA("")
Name Common_SourceData.Common_SourceData_ConvertGasElementalToMolecular_Source: _xlfn.LAMBDA("XXXXXXX")
Name Common_SourceData.Common_SourceData_ConvertGasElementalToMolecular_Title: _xlfn.LAMBDA("Factor to convert elemental mass of gas to molecular mass")
Name Common_SourceData.Common_SourceData_ConvertGasElementalToMolecular_Unit: _xlfn.LAMBDA("factor")
Name Common_SourceData.Common_SourceData_ConvertGasElementalToMolecular_Variable: _xlfn.LAMBDA("Cg")
Name Common_SourceData.Common_SourceData_ConvertN2oElementalToMolecularCg_Data: _xlfn.LAMBDA(44 / 28)
Name Common_SourceData.Common_SourceData_ConvertN2oElementalToMolecularCg_Source: _xlfn.LAMBDA("National Inventory Report 2023 Volume 1")
Name Common_SourceData.Common_SourceData_ConvertN2oElementalToMolecularCg_Title: _xlfn.LAMBDA("Factor to convert elemental mass of N2O to molecular mass")
Name Common_SourceData.Common_SourceData_ConvertN2oElementalToMolecularCg_Unit: _xlfn.LAMBDA("factor")
Name Common_SourceData.Common_SourceData_ConvertN2oElementalToMolecularCg_Variable: _xlfn.LAMBDA("CgN2O")
Name Common_SourceData.Common_SourceData_DataScores_Scope3_Source: _xlfn.LAMBDA("VEERG 2026: XXXXXXXX")
Name Common_SourceData.Common_SourceData_DataScores_Scope3_Title: _xlfn.LAMBDA("Australian data scores for scope 3")
Name Common_SourceData.Common_SourceData_DataScores_Scope3_Unit: _xlfn.LAMBDA("")
Name Common_SourceData.Common_SourceData_DataScores_Scope3_Variable: _xlfn.LAMBDA("")
Name Common_SourceData.Common_SourceData_DataScores_Scope3_Variation: _xlfn.LAMBDA("")
Name Common_SourceData.Common_SourceData_DensityOfMethane_Data: _xlfn.LAMBDA(0.6784)
Name Common_SourceData.Common_SourceData_DensityOfMethane_Source: _xlfn.LAMBDA("National Inventory Report 2023 Volume 1: Equations 3.B.1a_2, 3.B.1c_2, 3.B.3_1, 3.B.4g_2")
Name Common_SourceData.Common_SourceData_DensityOfMethane_Title: _xlfn.LAMBDA("p = density of methane")
Name Common_SourceData.Common_SourceData_DensityOfMethane_Unit: _xlfn.LAMBDA("kg/m3")
Name Common_SourceData.Common_SourceData_EFleach_Data: _xlfn.LAMBDA(_xlfn.MAKEARRAY(1, 2, _xlfn.LAMBDA(_xlpm.r,_xlpm.c, INDEX({"EFleach",0.011}, _xlpm.r, _xlpm.c))))
Name Common_SourceData.Common_SourceData_EFleach_NIRReference: _xlfn.LAMBDA("National Inventory Report Volume 1: Equation 3.D.B_10")
Name Common_SourceData.Common_SourceData_EFleach_Source: _xlfn.LAMBDA("VEERG 2026:5.5.2.3 Constant Parameters")
Name Common_SourceData.Common_SourceData_EFleach_Title: _xlfn.LAMBDA("Emission factor for nitrogen leaching and runoff")
Name Common_SourceData.Common_SourceData_EFleach_Unit: _xlfn.LAMBDA("(kg N2O-N / kg N")
Name Common_SourceData.Common_SourceData_EFleach_Variation: _xlfn.LAMBDA((""))
Name Common_SourceData.Common_SourceData_EFN2O_NIRReference: _xlfn.LAMBDA("")
Name Common_SourceData.Common_SourceData_EFN2O_Source: _xlfn.LAMBDA("VEERG 2026: Table A.2.2.1")
Name Common_SourceData.Common_SourceData_EFN2O_Title: _xlfn.LAMBDA("Nitrous oxide emission factors for inorganic fertiliser application")
Name Common_SourceData.Common_SourceData_EFN2O_Unit: _xlfn.LAMBDA("(kg N2O-N / kg N")
Name Common_SourceData.Common_SourceData_EFPastureRangeAndPaddock_Data: _xlfn.LAMBDA(_xlfn.MAKEARRAY(3, 2, _xlfn.LAMBDA(_xlpm.r,_xlpm.c, INDEX({"Climate zone","EFPRP";"Wet climate zone",0.006;"Dry climate zone",0.002}, _xlpm.r, _xlpm.c))))
Name Common_SourceData.Common_SourceData_EFPastureRangeAndPaddock_NIRReference: _xlfn.LAMBDA("")
Name Common_SourceData.Common_SourceData_EFPastureRangeAndPaddock_Source: _xlfn.LAMBDA("VEERG 2026: Table A.2.2.2")
Name Common_SourceData.Common_SourceData_EFPastureRangeAndPaddock_Title: _xlfn.LAMBDA("Emission factor for urine and dung deposited on pasture, range or paddock")
Name Common_SourceData.Common_SourceData_EFPastureRangeAndPaddock_Unit: _xlfn.LAMBDA("kg N2O - N / kg N")
Name Common_SourceData.Common_SourceData_EFPastureRangeAndPaddock_Variation: _xlfn.LAMBDA("VARIATION FROM SOURCE DATA: Changed 'Dry climate zones' to singular 'Dry climate zone' to aid lookup.")
Name Common_SourceData.Common_SourceData_FracLEACH_Data: _xlfn.LAMBDA(_xlfn.MAKEARRAY(1, 2, _xlfn.LAMBDA(_xlpm.r,_xlpm.c, INDEX({"FracLEACH",0.24}, _xlpm.r, _xlpm.c))))

Sheet Home

Sheet Results
A1: #VALUE! | C1: 4.1 Manure management: Beef Feedlot: Results
A3: =HYPERLINK("#'Home'!A1", "Home") -> Home
A4: =HYPERLINK("#'Results'!A1", "Results") -> Results | D4: Emissions breakdown
A6: INPUTS | D6: Scope 1 source | E6: GHG emissions | F6: GHG Unit | G6: CO2-e emissions | H6: CO2-e unit
A7: =HYPERLINK("#'Input - Site'!A1", "Site") -> Site | D7: 4.1.1.1 Method 1 Manure methane | E7: ='4.1.1.1-2 Methane'!E164 -> 2.7938769 | F7: ='4.1.1.1-2 Methane'!F164 -> t CH4 | G7: ='4.1.1.1-2 Methane'!E169 -> 78.228555 | H7: ='4.1.1.1-2 Methane'!F169 -> t CO2e
A8: =HYPERLINK("#'Input - Feedlot'!A1", "Feedlot") -> Feedlot | D8: 4.1.1.2 Method 2 Manure methane | E8: ='4.1.1.1-2 Methane'!N164 -> 2.7938769 | F8: ='4.1.1.1-2 Methane'!O164 -> t CH4 | G8: ='4.1.1.1-2 Methane'!N169 -> 78.228555 | H8: ='4.1.1.1-2 Methane'!O169 -> t CO2e
D9: 4.1.1.3 Method 1 Manure direct N2O | E9: ='4.1.1.3-4 Direct N20'!E207 -> 1.0745528 | F9: ='4.1.1.3-4 Direct N20'!F207 -> t N2O | G9: ='4.1.1.3-4 Direct N20'!E212 -> 284.75648 | H9: ='4.1.1.3-4 Direct N20'!F212 -> t CO2e
A10: CALCULATIONS | D10: 4.1.1.4 Method 2 Manure direct N2O | E10: ='4.1.1.3-4 Direct N20'!M207 -> 1.0745528 | F10: ='4.1.1.3-4 Direct N20'!N207 -> t N2O | G10: ='4.1.1.3-4 Direct N20'!M212 -> 284.75648 | H10: ='4.1.1.3-4 Direct N20'!N212 -> t CO2e
A11: =HYPERLINK("#'4.1.1.1-2 Methane'!A1", "4.1.1.1-2 Methane") -> 4.1.1.1-2 Methane | D11: 4.1.1.5 Method 1 Manure atmospheric deposition | E11: ='4.1.1.5-6 Atmos Deposition'!$E$60 -> 0.16441385 | F11: ='4.1.1.5-6 Atmos Deposition'!$F$60 -> t N2O | G11: ='4.1.1.5-6 Atmos Deposition'!$E$65 -> 43.56967 | H11: ='4.1.1.5-6 Atmos Deposition'!$F$65 -> t CO2e
A12: =HYPERLINK("#'4.1.1.3-4 Direct N20'!A1", "4.1.1.3-4 Direct N2O") -> 4.1.1.3-4 Direct N2O | D12: 4.1.1.6 Method 2 Manure atmospheric deposition | E12: ='4.1.1.5-6 Atmos Deposition'!$M$60 -> 0.16441385 | F12: ='4.1.1.5-6 Atmos Deposition'!$N$60 -> t N2O | G12: ='4.1.1.5-6 Atmos Deposition'!$M$65 -> 43.56967 | H12: ='4.1.1.5-6 Atmos Deposition'!$N$65 -> t CO2e
A13: =HYPERLINK("#'4.1.1.5-6 Atmos Deposition'!A1", "4.1.1.5-6 Atmospheric deposition") -> 4.1.1.5-6 Atmospheric deposition | D13: 4.1.1.7 Method 1 Manure leaching and runoff | E13: N/A | F13: N/A | G13: 0 | H13: N/A
A14: =HYPERLINK("#'4.1.1.9 Manure applied to soils'!A1", "4.1.1.9 Manure applied to soils") -> 4.1.1.9 Manure applied to soils | D14: 4.1.1.8 Method 1 Manure leaching and runoff | E14: N/A | F14: N/A | G14: 0 | H14: N/A
D15: Total | G15: =SUM(G7:G14) -> 813.10942 | H15: ='4.1.1.5-6 Atmos Deposition'!$N$65 -> t CO2e
A16: APPENDICES
A17: =HYPERLINK("#'Constants - Feedlot'!A1", "Constants - Feedlot") -> Constants - Feedlot | D17: WARNING: Manure nitrogen that was applied to soils must be accounted for
A18: =HYPERLINK("#'Constants - Livestock'!A1", "Constants - Livestock") -> Constants - Livestock | D18: See the table below for how to account for manure applied to soils for scope 1 and 3.
A19: =HYPERLINK("#'Constants - Common'!A1", "Constants - Common") -> Constants - Common
A20: =HYPERLINK("#'Acknowledgements'!A1", "Acknowledgements") -> Acknowledgements | D20: Manure nitrogen use | E20: Amount of N in manure | F20: N unit | G20: Emissions allocated to | H20: VEERG Calculation method
D21: Manure nitrogen deposited on farm soils with no other purpose (aka waste) | E21: ='4.1.1.9 Manure applied to soils'!$E$56 -> 9574.3563 | F21: ='4.1.1.9 Manure applied to soils'!$F$56 -> kg N | G21: This feedlot | H21: 5.2.2.1 (1), 5.4.1.3 (1, 2), 5.5.1.1 (1, 3)
D22: Manure nitrogen deposited on farm soils as fertiliser for other farm enterpsies (eg crops) | E22: ='4.1.1.9 Manure applied to soils'!$E$104 -> 4787.1782 | F22: ='4.1.1.9 Manure applied to soils'!$F$104 -> kg N | G22: Crops or pasture that use manure as fertiliser | H22: 5.2.2.1 (1), 5.4.1.3 (1, 2), 5.5.1.1 (1, 3)
D23: Manure nitrogen sold | E23: ='4.1.1.9 Manure applied to soils'!$E$123 -> 4787.1782 | F23: ='4.1.1.9 Manure applied to soils'!$F$123 -> kg N | G23: Scope 3 (downstream) | H23: 15.13.1.1 (1), 5.2.2.1 (1), 5.4.1.3 (1, 2), 5.5.1.1 (1, 3)

Sheet Input - Site
A1: #VALUE! | C1: Input - Site
A3: =HYPERLINK("#'Home'!A1", "Home") -> Home
A4: =HYPERLINK("#'Results'!A1", "Results") -> Results
D5: Your business
A6: INPUTS
A7: =HYPERLINK("#'Input - Site'!A1", "Site") -> Site | D7: Farm name | E7: Test Farms
A8: =HYPERLINK("#'Input - Feedlot'!A1", "Feedlot") -> Feedlot | D8: Reporting entity name | E8: Test Farms Pty Ltd
A10: CALCULATIONS | D10: 💡An 'Emissions accounting period' is a 12 month period where the business can report on the emissions, and is typically the same as the business' financial accounting period.
A11: =HYPERLINK("#'4.1.1.1-2 Methane'!A1", "4.1.1.1-2 Methane") -> 4.1.1.1-2 Methane
A12: =HYPERLINK("#'4.1.1.3-4 Direct N20'!A1", "4.1.1.3-4 Direct N2O") -> 4.1.1.3-4 Direct N2O | D12: Emissions calculation period start date | E12: 45292 | F12: ← DD/MM/YYYY or DD Month YYYY
A13: =HYPERLINK("#'4.1.1.5-6 Atmos Deposition'!A1", "4.1.1.5-6 Atmospheric deposition") -> 4.1.1.5-6 Atmospheric deposition | D13: Emissions calculation period end date | E13: =DATE(YEAR(E12)+1,MONTH(E12),DAY(E12))-1 -> 45657 | F13: ← Automatically calculated, 12 months after start date
A14: =HYPERLINK("#'4.1.1.9 Manure applied to soils'!A1", "4.1.1.9 Manure applied to soils") -> 4.1.1.9 Manure applied to soils
A16: APPENDICES | D16: Location and climate
A17: =HYPERLINK("#'Constants - Feedlot'!A1", "Constants - Feedlot") -> Constants - Feedlot
A18: =HYPERLINK("#'Constants - Livestock'!A1", "Constants - Livestock") -> Constants - Livestock | D18: Location information is used to reference some region and climate-specific emission factors
A19: =HYPERLINK("#'Constants - Common'!A1", "Constants - Common") -> Constants - Common | D19: Tip: Use the web-based GAF Location Helper tool to easily get region and climate information. You will need an internet connection to use the GAF Location Helper.
A20: =HYPERLINK("#'Acknowledgements'!A1", "Acknowledgements") -> Acknowledgements
D21: State | E21: New South Wales | F21: ← Please select
D22: Region (ABS Statistical area level 4) if state is WA | E22: Western Australia - Outback (South) | F22: ← Please select
D23: Leaching zone | E23: NO - Not in leaching zone | F23: ← Please select
D24: Elevation | E24: 307.7 | F24: Meters
D25: Average temperature for reporting period | E25: 18 | F25: Degrees celsius
D26: Total rainfall for reporting period | E26: 601 | F26: Millimetres
D27: Potential evapotranspiration for reporting period | E27: 1326 | F27: Millimetres
D28: Number of frost days for reporting period | E28: 7 | F28: Days
D29: MAP:PET ratio | E29: =E26/E27 -> 0.45324284
D30: Rainfall zone | E30: =Common_InputFunctions.Utility_LookupItemFromMinMax(E26,Table_SourceData_RainfallZones[Min rainfall],Table_SourceData_RainfallZones[Max rainfall],Table_SourceData_RainfallZones[Rainfall Zone]) -> High rainfall
D31: Climate zone | E31: =Common_InputFunctions.Utility_GetClimateZone(E25,E26,E28,E24,E29,Table_SourceData_ClimateZones[Min temp],Table_SourceData_ClimateZones[Max temp],Table_SourceData_ClimateZones[Min rainfall],Table_SourceData_ClimateZones[Max rainfall],Table_SourceData_ClimateZones[Min frost days],Table_SourceData_ClimateZones[Max frost days],Table_SourceData_ClimateZones[Min elevation],Table_SourceData_ClimateZones[Max elevation],Table_SourceData_ClimateZones[Min MAP:PET],Table_SourceData_ClimateZones[Max MAP:PET],Table_SourceData_ClimateZones[Climate zone]) -> Warm temperate dry
D32: Wet or dry climate zone | E32: =Common_InputFunctions.Utility_LookupValueInTable($E$31,Table_SourceData_WetDryZones[Climate zone],Table_SourceData_WetDryZones[Wet or Dry Zone]) -> Dry climate zone
D33: Temperature zone | E33: =Common_InputFunctions.Utility_LookupItemFromMinMax(E25,Table_SourceData_TemperatureZones[Min MAT],Table_SourceData_TemperatureZones[Max MAT],Table_SourceData_TemperatureZones[Temperature Zone]) -> Temperate

Sheet Input - Feedlot
A1: #VALUE! | C1: Input - MMS - Feedlot
A3: =HYPERLINK("#'Home'!A1", "Home") -> Home
A4: =HYPERLINK("#'Results'!A1", "Results") -> Results
D5: Herd movement
A6: INPUTS
A7: =HYPERLINK("#'Input - Site'!A1", "Site") -> Site | E7: Domestic | F7: Mid-fed | G7: Long-fed
A8: =HYPERLINK("#'Input - Feedlot'!A1", "Feedlot") -> Feedlot | D8: ="Average number of head between " & TEXT('Input - Site'!$E$12, "dd mmm yy") & " and " & TEXT('Input - Site'!$E$13, "dd mmm yy") -> Average number of head between 01 Jan 24 and 31 Dec 24 | E8: 4300 | F8: 100 | G8: 100 | H8: head
D9: ="Average duration of stay between " & TEXT('Input - Site'!$E$12, "dd mmm yy") & " and " & TEXT('Input - Site'!$E$13, "dd mmm yy") -> Average duration of stay between 01 Jan 24 and 31 Dec 24 | E9: 90 | F9: 140 | G9: 250 | H9: Days
A10: CALCULATIONS
A11: =HYPERLINK("#'4.1.1.1-2 Methane'!A1", "4.1.1.1-2 Methane") -> 4.1.1.1-2 Methane | D11: Intake
A12: =HYPERLINK("#'4.1.1.3-4 Direct N20'!A1", "4.1.1.3-4 Direct N2O") -> 4.1.1.3-4 Direct N2O
A13: =HYPERLINK("#'4.1.1.5-6 Atmos Deposition'!A1", "4.1.1.5-6 Atmospheric deposition") -> 4.1.1.5-6 Atmospheric deposition | D13: Method 1 default values (Do not edit) | E13: Domestic | F13: Mid-fed | G13: Long-fed
A14: =HYPERLINK("#'4.1.1.9 Manure applied to soils'!A1", "4.1.1.9 Manure applied to soils") -> 4.1.1.9 Manure applied to soils | D14: Feed intake | E14: {=_xlfn.XLOOKUP(1, (Table_SourceData_Feedlot_AnimalCharacteristics[Feedlot type] = E$13) * (Table_SourceData_Feedlot_AnimalCharacteristics[Characteristic] = $D$14), Table_SourceData_Feedlot_AnimalCharacteristics[2020-2023], "Not Found")} -> 10.4 | F14: {=_xlfn.XLOOKUP(1, (Table_SourceData_Feedlot_AnimalCharacteristics[Feedlot type] = F$13) * (Table_SourceData_Feedlot_AnimalCharacteristics[Characteristic] = $D$14), Table_SourceData_Feedlot_AnimalCharacteristics[2020-2023], "Not Found")} -> 10.8 | G14: {=_xlfn.XLOOKUP(1, (Table_SourceData_Feedlot_AnimalCharacteristics[Feedlot type] = G$13) * (Table_SourceData_Feedlot_AnimalCharacteristics[Characteristic] = $D$14), Table_SourceData_Feedlot_AnimalCharacteristics[2020-2023], "Not Found")} -> 8.2 | H14: kg dry matter / head day
D15: Dry matter digestibility | E15: {=_xlfn.XLOOKUP(1, (Table_SourceData_Feedlot_DietProperties[Feedlot type] = E$13) * (Table_SourceData_Feedlot_DietProperties[Nutrient analysis] = $D$15), Table_SourceData_Feedlot_DietProperties[2020-2023 Converted to fraction], "Not Found")} -> 0.81 | F15: {=_xlfn.XLOOKUP(1, (Table_SourceData_Feedlot_DietProperties[Feedlot type] = F$13) * (Table_SourceData_Feedlot_DietProperties[Nutrient analysis] = $D$15), Table_SourceData_Feedlot_DietProperties[2020-2023 Converted to fraction], "Not Found")} -> 0.81 | G15: {=_xlfn.XLOOKUP(1, (Table_SourceData_Feedlot_DietProperties[Feedlot type] = G$13) * (Table_SourceData_Feedlot_DietProperties[Nutrient analysis] = $D$15), Table_SourceData_Feedlot_DietProperties[2020-2023 Converted to fraction], "Not Found")} -> 0.81 | H15: Fraction
A16: APPENDICES | D16: Crude protein | E16: {=_xlfn.XLOOKUP(1, (Table_SourceData_Feedlot_DietProperties[Feedlot type] = E$13) * (Table_SourceData_Feedlot_DietProperties[Nutrient analysis] = $D$16), Table_SourceData_Feedlot_DietProperties[2020-2023 Converted to fraction], "Not Found")} -> 0.14 | F16: {=_xlfn.XLOOKUP(1, (Table_SourceData_Feedlot_DietProperties[Feedlot type] = F$13) * (Table_SourceData_Feedlot_DietProperties[Nutrient analysis] = $D$16), Table_SourceData_Feedlot_DietProperties[2020-2023 Converted to fraction], "Not Found")} -> 0.12 | G16: {=_xlfn.XLOOKUP(1, (Table_SourceData_Feedlot_DietProperties[Feedlot type] = G$13) * (Table_SourceData_Feedlot_DietProperties[Nutrient analysis] = $D$16), Table_SourceData_Feedlot_DietProperties[2020-2023 Converted to fraction], "Not Found")} -> 0.12 | H16: Fraction
A17: =HYPERLINK("#'Constants - Feedlot'!A1", "Constants - Feedlot") -> Constants - Feedlot | D17: N retention | E17: {=_xlfn.XLOOKUP(1, (Table_SourceData_Feedlot_AnimalCharacteristics[Feedlot type] = E$13) * (Table_SourceData_Feedlot_AnimalCharacteristics[Characteristic] = $D$17), Table_SourceData_Feedlot_AnimalCharacteristics[2020-2023], "Not Found")} -> 20.4 | F17: {=_xlfn.XLOOKUP(1, (Table_SourceData_Feedlot_AnimalCharacteristics[Feedlot type] = F$13) * (Table_SourceData_Feedlot_AnimalCharacteristics[Characteristic] = $D$17), Table_SourceData_Feedlot_AnimalCharacteristics[2020-2023], "Not Found")} -> 12.7 | G17: {=_xlfn.XLOOKUP(1, (Table_SourceData_Feedlot_AnimalCharacteristics[Feedlot type] = G$13) * (Table_SourceData_Feedlot_AnimalCharacteristics[Characteristic] = $D$17), Table_SourceData_Feedlot_AnimalCharacteristics[2020-2023], "Not Found")} -> 7 | H17: Percent of intake
A18: =HYPERLINK("#'Constants - Livestock'!A1", "Constants - Livestock") -> Constants - Livestock
A19: =HYPERLINK("#'Constants - Common'!A1", "Constants - Common") -> Constants - Common | D19: Method 2 custom values (Edit if known) | E19: Domestic | F19: Mid-fed | G19: Long-fed
A20: =HYPERLINK("#'Acknowledgements'!A1", "Acknowledgements") -> Acknowledgements | D20: Feed intake | E20: {=_xlfn.XLOOKUP(1, (Table_SourceData_Feedlot_AnimalCharacteristics[Feedlot type] = E$19) * (Table_SourceData_Feedlot_AnimalCharacteristics[Characteristic] = $D$20), Table_SourceData_Feedlot_AnimalCharacteristics[2020-2023], "Not Found")} -> 10.4 | F20: {=_xlfn.XLOOKUP(1, (Table_SourceData_Feedlot_AnimalCharacteristics[Feedlot type] = F$19) * (Table_SourceData_Feedlot_AnimalCharacteristics[Characteristic] = $D$20), Table_SourceData_Feedlot_AnimalCharacteristics[2020-2023], "Not Found")} -> 10.8 | G20: {=_xlfn.XLOOKUP(1, (Table_SourceData_Feedlot_AnimalCharacteristics[Feedlot type] = G$19) * (Table_SourceData_Feedlot_AnimalCharacteristics[Characteristic] = $D$20), Table_SourceData_Feedlot_AnimalCharacteristics[2020-2023], "Not Found")} -> 8.2 | H20: kg dry matter / head day
D21: Dry matter digestibility | E21: {=_xlfn.XLOOKUP(1, (Table_SourceData_Feedlot_DietProperties[Feedlot type] = E$19) * (Table_SourceData_Feedlot_DietProperties[Nutrient analysis] = $D$21), Table_SourceData_Feedlot_DietProperties[2020-2023 Converted to fraction], "Not Found")} -> 0.81 | F21: {=_xlfn.XLOOKUP(1, (Table_SourceData_Feedlot_DietProperties[Feedlot type] = F$19) * (Table_SourceData_Feedlot_DietProperties[Nutrient analysis] = $D$21), Table_SourceData_Feedlot_DietProperties[2020-2023 Converted to fraction], "Not Found")} -> 0.81 | G21: {=_xlfn.XLOOKUP(1, (Table_SourceData_Feedlot_DietProperties[Feedlot type] = G$19) * (Table_SourceData_Feedlot_DietProperties[Nutrient analysis] = $D$21), Table_SourceData_Feedlot_DietProperties[2020-2023 Converted to fraction], "Not Found")} -> 0.81 | H21: Fraction
D22: Crude protein | E22: {=_xlfn.XLOOKUP(1, (Table_SourceData_Feedlot_DietProperties[Feedlot type] = E$19) * (Table_SourceData_Feedlot_DietProperties[Nutrient analysis] = $D$22), Table_SourceData_Feedlot_DietProperties[2020-2023 Converted to fraction], "Not Found")} -> 0.14 | F22: {=_xlfn.XLOOKUP(1, (Table_SourceData_Feedlot_DietProperties[Feedlot type] = F$19) * (Table_SourceData_Feedlot_DietProperties[Nutrient analysis] = $D$22), Table_SourceData_Feedlot_DietProperties[2020-2023 Converted to fraction], "Not Found")} -> 0.12 | G22: {=_xlfn.XLOOKUP(1, (Table_SourceData_Feedlot_DietProperties[Feedlot type] = G$19) * (Table_SourceData_Feedlot_DietProperties[Nutrient analysis] = $D$22), Table_SourceData_Feedlot_DietProperties[2020-2023 Converted to fraction], "Not Found")} -> 0.12 | H22: Fraction
D23: N retention | E23: {=_xlfn.XLOOKUP(1, (Table_SourceData_Feedlot_AnimalCharacteristics[Feedlot type] = E$19) * (Table_SourceData_Feedlot_AnimalCharacteristics[Characteristic] = $D$23), Table_SourceData_Feedlot_AnimalCharacteristics[2020-2023], "Not Found")} -> 20.4 | F23: {=_xlfn.XLOOKUP(1, (Table_SourceData_Feedlot_AnimalCharacteristics[Feedlot type] = F$19) * (Table_SourceData_Feedlot_AnimalCharacteristics[Characteristic] = $D$23), Table_SourceData_Feedlot_AnimalCharacteristics[2020-2023], "Not Found")} -> 12.7 | G23: {=_xlfn.XLOOKUP(1, (Table_SourceData_Feedlot_AnimalCharacteristics[Feedlot type] = G$19) * (Table_SourceData_Feedlot_AnimalCharacteristics[Characteristic] = $D$23), Table_SourceData_Feedlot_AnimalCharacteristics[2020-2023], "Not Found")} -> 7 | H23: Percent of intake
D25: Manure management systems
D27: Stage 1
D28: Stage 1 MMS | E28: Domestic | F28: Mid-fed | G28: Long-fed
D29: Drylot (feed pad) | E29: 1 | F29: 1 | G29: 1 | H29: Percent
D32: Stage 2
D33: Stage 2 MMS | E33: Domestic | F33: Mid-fed | G33: Long-fed
D34: ="Sent from Stage 1: " & $D$29 & " to:" -> Sent from Stage 1: Drylot (feed pad) to:
D35: ='Constants - Feedlot'!D29 -> Solid storage | E35: 0.2 | F35: 0.2 | G35: 0.2 | H35: Percent
D36: ='Constants - Feedlot'!D30 -> Composting (passive windrow) | E36: =1-E35 -> 0.8 | F36: =1-F35 -> 0.8 | G36: =1-G35 -> 0.8 | H36: Percent
D39: Stage 3
D40: Stage 3 MMS | E40: Domestic | F40: Mid-fed | G40: Long-fed
D41: ='Constants - Feedlot'!$D$32 -> Anaerobic lagoon | E41: ='Constants - Feedlot'!$E$12 -> 0.02 | F41: ='Constants - Feedlot'!$E$12 -> 0.02 | G41: ='Constants - Feedlot'!$E$12 -> 0.02 | H41: Percent
D44: Production system 1: Post-treatment destinations
D45: Stage 3 MMS | E45: Domestic | F45: Mid-fed | G45: Long-fed
D46: ="Sent from stage 2: " & $D$35 & " to:" -> Sent from stage 2: Solid storage to:
D47: Sold as fertiliser | E47: 0.25 | F47: 0.25 | G47: 0.25 | H47: Percent
D48: Applied to farm soils as fertiliser | E48: 0.25 | F48: 0.25 | G48: 0.25 | H48: Percent
D49: Deposited on farm soils as waste (Direct application MMS) | E49: =1-SUM(E47:E48) -> 0.5 | F49: =1-SUM(F47:F48) -> 0.5 | G49: =1-SUM(G47:G48) -> 0.5 | H49: Percent
...

Sheet 4.1.1.1-2 Methane
A1: #VALUE! | C1: 4.1.1.1-2 Manure Methane
A3: =HYPERLINK("#'Home'!A1", "Home") -> Home | D3: Method 1 | M3: Method 2
A4: =HYPERLINK("#'Results'!A1", "Results") -> Results
D5: {=MMS_Feedlot_Methane_Equations.VEERG_4_1_1_1__5_VolatileSolidProduction_Title()} -> Volatile solid production
A6: INPUTS | D6: {=MMS_Feedlot_Methane_Equations.VEERG_4_1_1_1__5_VolatileSolidProduction_Source()} -> VEERG 2026: 4.1.1.1, Equation (5)
A7: =HYPERLINK("#'Input - Site'!A1", "Site") -> Site | D7: Function name | E7: {=Common_InputFunctions.Utility_DisplayFunctionName(D30)} -> =MMS_Feedlot_Methane_Equations.VEERG_4_1_1_1__5_VolatileSolidProduction
A8: =HYPERLINK("#'Input - Feedlot'!A1", "Feedlot") -> Feedlot
A10: CALCULATIONS | D10: Variable | E10: {=MMS_Feedlot_Methane_Equations.VEERG_4_1_1_1__5_VolatileSolidProduction_Variable()} -> VS_j
A11: =HYPERLINK("#'4.1.1.1-2 Methane'!A1", "4.1.1.1-2 Methane") -> 4.1.1.1-2 Methane | D11: Unit | E11: {=MMS_Feedlot_Methane_Equations.VEERG_4_1_1_1__5_VolatileSolidProduction_Unit()} -> kg/head/day
A12: =HYPERLINK("#'4.1.1.3-4 Direct N20'!A1", "4.1.1.3-4 Direct N2O") -> 4.1.1.3-4 Direct N2O
A13: =HYPERLINK("#'4.1.1.5-6 Atmos Deposition'!A1", "4.1.1.5-6 Atmospheric deposition") -> 4.1.1.5-6 Atmospheric deposition | D13: {=MMS_Feedlot_Methane_Equations.VEERG_4_1_1_1__5_VolatileSolidProduction_Arguments()} -> I_j | E13: dry matter intake for each group j : kg DM/head/day | G13: ="See " & D17 -> See M1_Table_I_j
A14: =HYPERLINK("#'4.1.1.9 Manure applied to soils'!A1", "4.1.1.9 Manure applied to soils") -> 4.1.1.9 Manure applied to soils | D14: DMD_j | E14: dry matter digestibility for each group j : fraction | G14: ="See " & D22 -> See M1_Table_DMD_j
D15: A | E15: ash content of manure : fraction | G15: ='Constants - Feedlot'!$E$17 -> 0.16
A16: APPENDICES
A17: =HYPERLINK("#'Constants - Feedlot'!A1", "Constants - Feedlot") -> Constants - Feedlot | D17: M1_Table_I_j | M17: M2_Table_I_j
A18: =HYPERLINK("#'Constants - Livestock'!A1", "Constants - Livestock") -> Constants - Livestock | D18: Dry matter intake (Method 1) | M18: Dry matter intake (Method 2)
A19: =HYPERLINK("#'Constants - Common'!A1", "Constants - Common") -> Constants - Common | D19: Domestic | E19: Mid-fed | F19: Long-fed | M19: Domestic | N19: Mid-fed | O19: Long-fed
A20: =HYPERLINK("#'Acknowledgements'!A1", "Acknowledgements") -> Acknowledgements | D20: ='Input - Feedlot'!$E$14 -> 10.4 | E20: ='Input - Feedlot'!$F$14 -> 10.8 | F20: ='Input - Feedlot'!$G$14 -> 8.2 | G20: kg DM/head/day | M20: ='Input - Feedlot'!$E$20 -> 10.4 | N20: ='Input - Feedlot'!$F$20 -> 10.8 | O20: ='Input - Feedlot'!$G$20 -> 8.2 | P20: kg DM/head/day
D22: M1_Table_DMD_j | M22: M2_Table_DMD_j
D23: Dry matter digestibility (Method 1) | M23: Dry matter digestibility (Method 1)
D24: Domestic | E24: Mid-fed | F24: Long-fed | M24: Domestic | N24: Mid-fed | O24: Long-fed
D25: ='Input - Feedlot'!$E$15 -> 0.81 | E25: ='Input - Feedlot'!$F$15 -> 0.81 | F25: ='Input - Feedlot'!$G$15 -> 0.81 | G25: Fraction | M25: ='Input - Feedlot'!$E$21 -> 0.81 | N25: ='Input - Feedlot'!$F$21 -> 0.81 | O25: ='Input - Feedlot'!$G$21 -> 0.81 | P25: Fraction
D27: M1_Table_VS_j | M27: M2_Table_VS_j
D28: Volatile solid production (Method 1) | M28: Volatile solid production (Method 2)
D29: Domestic | E29: Mid-fed | F29: Long-fed | M29: Domestic | N29: Mid-fed | O29: Long-fed
D30: {=MMS_Feedlot_Methane_Equations.VEERG_4_1_1_1__5_VolatileSolidProduction(D20,D25,$G$15)} -> 1.65984 | E30: {=MMS_Feedlot_Methane_Equations.VEERG_4_1_1_1__5_VolatileSolidProduction(E20,E25,$G$15)} -> 1.72368 | F30: {=MMS_Feedlot_Methane_Equations.VEERG_4_1_1_1__5_VolatileSolidProduction(F20,F25,$G$15)} -> 1.30872 | G30: =$E$11 -> kg/head/day | M30: {=MMS_Feedlot_Methane_Equations.VEERG_4_1_1_1__5_VolatileSolidProduction(M20,M25,$G$15)} -> 1.65984 | N30: {=MMS_Feedlot_Methane_Equations.VEERG_4_1_1_1__5_VolatileSolidProduction(N20,N25,$G$15)} -> 1.72368 | O30: {=MMS_Feedlot_Methane_Equations.VEERG_4_1_1_1__5_VolatileSolidProduction(O20,O25,$G$15)} -> 1.30872 | P30: =$E$11 -> kg/head/day
D34: {=MMS_Feedlot_Methane_Equations.VEERG_4_1_1_1__2_Stage1MethaneProductionDrylot_Title()} -> Production of methane in treatment stage 1 MMS
D35: {=MMS_Feedlot_Methane_Equations.VEERG_4_1_1_1__2_Stage1MethaneProductionDrylot_Source()} -> VEERG 2026: 4.1.1.1, Equation (2)
D36: Function name | E36: {=Common_InputFunctions.Utility_DisplayFunctionName(E57)} -> =MMS_Feedlot_Methane_Equations.VEERG_4_1_1_1__2_Stage1MethaneProductionDrylot
D39: Variable | E39: {=MMS_Feedlot_Methane_Equations.VEERG_4_1_1_1__2_Stage1MethaneProductionDrylot_Variable()} -> M_jm5T1
D40: Unit | E40: {=MMS_Feedlot_Methane_Equations.VEERG_4_1_1_1__2_Stage1MethaneProductionDrylot_Unit()} -> kg CH4/head/day
D42: {=MMS_Feedlot_Methane_Equations.VEERG_4_1_1_1__2_Stage1MethaneProductionDrylot_Arguments()} -> VS_j | E42: volatile solid production from feedlot cattle in each group : kg/head/day | G42: ="See " & $D$27 -> See M1_Table_VS_j
D43: BO | E43: emissions potential : m3 CH4/kg VS | G43: ='Constants - Feedlot'!$E$22 -> 0.19
D44: MMS_m5T1 | E44: fraction of manure in primary system drylot MMS : fraction | G44: ="See" & D49 -> SeeTable_MMS_m-5_T-1
D45: MCF_im5 | E45: methane conversion factor for temperature zone and drylot system : fraction | G45: =HLOOKUP(G47, Table_SourceData_Feedlot_MCF[#All], 2, FALSE) -> 0.01
D46: rho | E46: density of methane : kg/m3 | G46: ='Constants - Common'!$D$175 -> 0.6784
D47: i | E47: state | G47: =Common_InputFunctions.Utility_LookupValueInTable('Input - Site'!$E$21,Table_AustralianStates[Common Name],Table_AustralianStates[Abbreviation]) -> NSW
D49: Table_MMS_m-5_T-1
D50: Fraction of manure in primary system drylot
D51: Stage 1 MMS | E51: Domestic | F51: Mid-fed | G51: Long-fed
...

Sheet 4.1.1.3-4 Direct N20
A1: #VALUE! | C1: 4.1.1.3-4 Manure Direct N2O
A3: =HYPERLINK("#'Home'!A1", "Home") -> Home | D3: Method 1 | L3: Method 2
A4: =HYPERLINK("#'Results'!A1", "Results") -> Results
D5: {=MMS_Feedlot_N2ODirect_Equations.VEERG_4_1_1_3__5_NitrogenIntake_Title()} -> Nitrogen intake of feedlot cattle
A6: INPUTS | D6: {=MMS_Feedlot_N2ODirect_Equations.VEERG_4_1_1_3__5_NitrogenIntake_Source()} -> VEERG 2026: 4.1.1.3, Equation (5)
A7: =HYPERLINK("#'Input - Site'!A1", "Site") -> Site | D7: Formula name | E7: {=Common_InputFunctions.Utility_DisplayFunctionName(D30)} -> =MMS_Feedlot_N2ODirect_Equations.VEERG_4_1_1_3__5_NitrogenIntake
A8: =HYPERLINK("#'Input - Feedlot'!A1", "Feedlot") -> Feedlot
A10: CALCULATIONS | D10: Variable | E10: {=MMS_Feedlot_N2ODirect_Equations.VEERG_4_1_1_3__5_NitrogenIntake_Variable()} -> NI_j
A11: =HYPERLINK("#'4.1.1.1-2 Methane'!A1", "4.1.1.1-2 Methane") -> 4.1.1.1-2 Methane | D11: Unit | E11: {=MMS_Feedlot_N2ODirect_Equations.VEERG_4_1_1_3__5_NitrogenIntake_Unit()} -> kg N/head/day
A12: =HYPERLINK("#'4.1.1.3-4 Direct N20'!A1", "4.1.1.3-4 Direct N2O") -> 4.1.1.3-4 Direct N2O
A13: =HYPERLINK("#'4.1.1.5-6 Atmos Deposition'!A1", "4.1.1.5-6 Atmospheric deposition") -> 4.1.1.5-6 Atmospheric deposition | D13: {=MMS_Feedlot_N2ODirect_Equations.VEERG_4_1_1_3__5_NitrogenIntake_Arguments()} -> I_j | E13: dry matter intake : kg DM/head/day | G13: ="See " &D17 -> See M1_Table_I_j
A14: =HYPERLINK("#'4.1.1.9 Manure applied to soils'!A1", "4.1.1.9 Manure applied to soils") -> 4.1.1.9 Manure applied to soils | D14: CP_j | E14: crude protein content of feed : fraction | G14: ="See " & D22 -> See M1_Table_CP_j
D15: 6.25 | E15: factor for converting crude protein into nitrogen : ratio | G15: =D15 -> 6.25
A16: APPENDICES
A17: =HYPERLINK("#'Constants - Feedlot'!A1", "Constants - Feedlot") -> Constants - Feedlot | D17: M1_Table_I_j | L17: M2_Table_I_j
A18: =HYPERLINK("#'Constants - Livestock'!A1", "Constants - Livestock") -> Constants - Livestock | D18: Dry matter intake (Method 1) | L18: Dry matter intake (Method 2)
A19: =HYPERLINK("#'Constants - Common'!A1", "Constants - Common") -> Constants - Common | D19: Domestic | E19: Mid-fed | F19: Long-fed | L19: Domestic | M19: Mid-fed | N19: Long-fed
A20: =HYPERLINK("#'Acknowledgements'!A1", "Acknowledgements") -> Acknowledgements | D20: ='Input - Feedlot'!$E$14 -> 10.4 | E20: ='Input - Feedlot'!$F$14 -> 10.8 | F20: ='Input - Feedlot'!$G$14 -> 8.2 | G20: kg DM/head/day | L20: ='Input - Feedlot'!$E$20 -> 10.4 | M20: ='Input - Feedlot'!$F$20 -> 10.8 | N20: ='Input - Feedlot'!$G$20 -> 8.2 | O20: kg DM/head/day
D22: M1_Table_CP_j | L22: M2_Table_CP_j
D23: Crude protein content of feed (Method 1) | L23: Crude protein content of feed (Method 2)
D24: Domestic | E24: Mid-fed | F24: Long-fed | L24: Domestic | M24: Mid-fed | N24: Long-fed
D25: ='Input - Feedlot'!$E$16 -> 0.14 | E25: ='Input - Feedlot'!$F$16 -> 0.12 | F25: ='Input - Feedlot'!$G$16 -> 0.12 | G25: Fraction | L25: ='Input - Feedlot'!$E$22 -> 0.14 | M25: ='Input - Feedlot'!$F$22 -> 0.12 | N25: ='Input - Feedlot'!$G$22 -> 0.12 | O25: Fraction
D27: M1_Table_NI_j | L27: M2_Table_NI_j
D28: Nitrogen intake (Method 1) | L28: Nitrogen intake (Method 2)
D29: Domestic | E29: Mid-fed | F29: Long-fed | L29: Domestic | M29: Mid-fed | N29: Long-fed
D30: {=MMS_Feedlot_N2ODirect_Equations.VEERG_4_1_1_3__5_NitrogenIntake(D20,D25)} -> 0.23296 | E30: {=MMS_Feedlot_N2ODirect_Equations.VEERG_4_1_1_3__5_NitrogenIntake(E20,E25)} -> 0.20736 | F30: {=MMS_Feedlot_N2ODirect_Equations.VEERG_4_1_1_3__5_NitrogenIntake(F20,F25)} -> 0.15744 | G30: =$E$11 -> kg N/head/day | L30: {=MMS_Feedlot_N2ODirect_Equations.VEERG_4_1_1_3__5_NitrogenIntake(L20,L25)} -> 0.23296 | M30: {=MMS_Feedlot_N2ODirect_Equations.VEERG_4_1_1_3__5_NitrogenIntake(M20,M25)} -> 0.20736 | N30: {=MMS_Feedlot_N2ODirect_Equations.VEERG_4_1_1_3__5_NitrogenIntake(N20,N25)} -> 0.15744 | O30: =$E$11 -> kg N/head/day
D34: {=MMS_Feedlot_N2ODirect_Equations.VEERG_4_1_1_3__4_NitrogenExcretionPerHead_Title()} -> Nitrogen excretion per head per day
D35: {=MMS_Feedlot_N2ODirect_Equations.VEERG_4_1_1_3__4_NitrogenExcretionPerHead_Source()} -> VEERG 2026: 4.1.1.3, Equation (4)
D36: Function name | E36: {=Common_InputFunctions.Utility_DisplayFunctionName(D54)} -> =MMS_Feedlot_N2ODirect_Equations.VEERG_4_1_1_3__4_NitrogenExcretionPerHead
D40: Variable | E40: {=MMS_Feedlot_N2ODirect_Equations.VEERG_4_1_1_3__4_NitrogenExcretionPerHead_Variable()} -> NE_j
D41: Unit | E41: {=MMS_Feedlot_N2ODirect_Equations.VEERG_4_1_1_3__4_NitrogenExcretionPerHead_Unit()} -> kg N/head/day
D43: {=MMS_Feedlot_N2ODirect_Equations.VEERG_4_1_1_3__4_NitrogenExcretionPerHead_Arguments()} -> NI_j | E43: nitrogen intake : kg N/head/day | G43: ="See " & D27 -> See M1_Table_NI_j
D44: NR_j | E44: nitrogen retention expressed as a fraction of intake : fraction | G44: ="See " & D46 -> See M1_Table_NR_j
D46: M1_Table_NR_j | E46: Percent of intake needs converting to faction of intake before going to equation - needs conversion in equation or change of input unit | L46: M2_Table_NR_j | M46: Percent of intake needs converting to faction of intake before going to equation - needs conversion in equation or change of input unit
D47: Nitrogen retention (Method 1) | L47: Nitrogen retention (Method 2)
D48: Domestic | E48: Mid-fed | F48: Long-fed | L48: Domestic | M48: Mid-fed | N48: Long-fed
D49: ='Input - Feedlot'!$E$17/100 -> 0.204 | E49: ='Input - Feedlot'!$F$17/100 -> 0.127 | F49: ='Input - Feedlot'!$G$17/100 -> 0.07 | G49: Fraction of intake | L49: ='Input - Feedlot'!$E$23/100 -> 0.204 | M49: ='Input - Feedlot'!$F$23/100 -> 0.127 | N49: ='Input - Feedlot'!$G$23/100 -> 0.07 | O49: Fraction
D51: M1_Table_NE_j | L51: M2_Table_NE_j
D52: Nitrogen retention (Method 1) | L52: Nitrogen retention (Method 2)
D53: Domestic | E53: Mid-fed | F53: Long-fed | L53: Domestic | M53: Mid-fed | N53: Long-fed
...

Sheet 4.1.1.5-6 Atmos Deposition
A1: #VALUE! | C1: 4.1.1.5-6 Manure Atmospheric Deposition
A3: =HYPERLINK("#'Home'!A1", "Home") -> Home | D3: Method 1 | L3: Method 2
A4: =HYPERLINK("#'Results'!A1", "Results") -> Results
D5: {=MMS_Feedlot_AtmosphericDeposition_Equations.VEERG_4_1_1_5__2_VolatilisedNitrogenFromManureManagement_Title()} -> Volatilised nitrogen from manure management
A6: INPUTS | D6: {=MMS_Feedlot_AtmosphericDeposition_Equations.VEERG_4_1_1_5__2_VolatilisedNitrogenFromManureManagement_Source()} -> VEERG 2026: 4.1.1.5, Equation (2)
A7: =HYPERLINK("#'Input - Site'!A1", "Site") -> Site | D7: Function name | E7: {=Common_InputFunctions.Utility_DisplayFunctionName(E36)} -> =MMS_Feedlot_AtmosphericDeposition_Equations.VEERG_4_1_1_5__2_VolatilisedNitrogenFromManureManagement
A8: =HYPERLINK("#'Input - Feedlot'!A1", "Feedlot") -> Feedlot
A10: CALCULATIONS
A11: =HYPERLINK("#'4.1.1.1-2 Methane'!A1", "4.1.1.1-2 Methane") -> 4.1.1.1-2 Methane | D11: Variable | E11: {=MMS_Feedlot_AtmosphericDeposition_Equations.VEERG_4_1_1_5__2_VolatilisedNitrogenFromManureManagement_Variable()} -> MMS_ATMOS
A12: =HYPERLINK("#'4.1.1.3-4 Direct N20'!A1", "4.1.1.3-4 Direct N2O") -> 4.1.1.3-4 Direct N2O | D12: Unit | E12: {=MMS_Feedlot_AtmosphericDeposition_Equations.VEERG_4_1_1_5__2_VolatilisedNitrogenFromManureManagement_Unit()} -> kg N
A13: =HYPERLINK("#'4.1.1.5-6 Atmos Deposition'!A1", "4.1.1.5-6 Atmospheric deposition") -> 4.1.1.5-6 Atmospheric deposition
A14: =HYPERLINK("#'4.1.1.9 Manure applied to soils'!A1", "4.1.1.9 Manure applied to soils") -> 4.1.1.9 Manure applied to soils | D14: {=MMS_Feedlot_AtmosphericDeposition_Equations.VEERG_4_1_1_5__2_VolatilisedNitrogenFromManureManagement_Arguments()} -> MN_jmT | E14: nitrogen in each treatment stage MMS (excluding MN_ijm13T2) : kg N | G14: ="See " & D17 -> See M1_Table_MN_j_m_T
D15: FracGASM_mT | E15: fraction of N volatilised in each MMS : (kg NH3-N + NOx-N)/kg N | G15: ="See " & D25 -> See Table_FracGASM_m_T-2-3
A16: APPENDICES
A17: =HYPERLINK("#'Constants - Feedlot'!A1", "Constants - Feedlot") -> Constants - Feedlot | D17: M1_Table_MN_j_m_T | L17: M2_Table_MN_j_m_T
A18: =HYPERLINK("#'Constants - Livestock'!A1", "Constants - Livestock") -> Constants - Livestock | D18: Nitrogen in each MMS excluding direct application (Method 1) | L18: Nitrogen in each MMS excluding direct application (Method 2)
A19: =HYPERLINK("#'Constants - Common'!A1", "Constants - Common") -> Constants - Common | D19: MMS | E19: Domestic | F19: Mid-fed | G19: Long-fed | L19: MMS | M19: Domestic | N19: Mid-fed | O19: Long-fed
A20: =HYPERLINK("#'Acknowledgements'!A1", "Acknowledgements") -> Acknowledgements | D20: ='Input - Feedlot'!$D$29 -> Drylot (feed pad) | E20: ='4.1.1.3-4 Direct N20'!$E$106 -> 71763.794 | F20: ='4.1.1.3-4 Direct N20'!$F$106 -> 2534.3539 | G20: ='4.1.1.3-4 Direct N20'!$G$106 -> 3660.48 | H20: kg N | L20: ='Input - Feedlot'!$D$29 -> Drylot (feed pad) | M20: ='4.1.1.3-4 Direct N20'!$M$106 -> 71763.794 | N20: ='4.1.1.3-4 Direct N20'!$N$106 -> 2534.3539 | O20: ='4.1.1.3-4 Direct N20'!$O$106 -> 3660.48 | P20: kg N
D21: ='Input - Feedlot'!$D$35 -> Solid storage | E21: ='4.1.1.3-4 Direct N20'!$E$173 -> 5376.5434 | F21: ='4.1.1.3-4 Direct N20'!$F$173 -> 189.8738 | G21: ='4.1.1.3-4 Direct N20'!$G$173 -> 274.24316 | H21: kg N | L21: ='Input - Feedlot'!$D$35 -> Solid storage | M21: ='4.1.1.3-4 Direct N20'!$M$173 -> 5376.5434 | N21: ='4.1.1.3-4 Direct N20'!$N$173 -> 189.8738 | O21: ='4.1.1.3-4 Direct N20'!$O$173 -> 274.24316 | P21: kg N
D22: ='Input - Feedlot'!$D$36 -> Composting (passive windrow) | E22: ='4.1.1.3-4 Direct N20'!$E$174 -> 21506.174 | F22: ='4.1.1.3-4 Direct N20'!$F$174 -> 759.49518 | G22: ='4.1.1.3-4 Direct N20'!$G$174 -> 1096.9726 | H22: kg N | L22: ='Input - Feedlot'!$D$36 -> Composting (passive windrow) | M22: ='4.1.1.3-4 Direct N20'!$M$174 -> 21506.174 | N22: ='4.1.1.3-4 Direct N20'!$N$174 -> 759.49518 | O22: ='4.1.1.3-4 Direct N20'!$O$174 -> 1096.9726 | P22: kg N
D23: ='Input - Feedlot'!$D$41 -> Anaerobic lagoon | E23: ='4.1.1.3-4 Direct N20'!$E$129 -> 1435.2759 | F23: ='4.1.1.3-4 Direct N20'!$F$129 -> 50.687078 | G23: ='4.1.1.3-4 Direct N20'!$G$129 -> 73.2096 | H23: kg N | L23: ='Input - Feedlot'!$D$41 -> Anaerobic lagoon | M23: ='4.1.1.3-4 Direct N20'!$M$129 -> 1435.2759 | N23: ='4.1.1.3-4 Direct N20'!$N$129 -> 50.687078 | O23: ='4.1.1.3-4 Direct N20'!$O$129 -> 73.2096 | P23: kg N
D25: Table_FracGASM_m_T-2-3
D26: Fraction of N volatilised in each MMS
D27: MMS | E27: EFjm
D28: ='Input - Feedlot'!$D$29 -> Drylot (feed pad) | E28: =_xlfn.XLOOKUP(D28, Table_SourceData_Feedlot_FracGASMmT[NIR definition], Table_SourceData_Feedlot_FracGASMmT[FracGASMmT]) -> 0.6 | F28: (kg NH3-N + NOx-N)/kg N
D29: ='Input - Feedlot'!$D$35 -> Solid storage | E29: =_xlfn.XLOOKUP(D29, Table_SourceData_Feedlot_FracGASMmT[NIR definition], Table_SourceData_Feedlot_FracGASMmT[FracGASMmT]) -> 0.25 | F29: (kg NH3-N + NOx-N)/kg N
D30: ='Input - Feedlot'!$D$36 -> Composting (passive windrow) | E30: =_xlfn.XLOOKUP(D30, Table_SourceData_Feedlot_FracGASMmT[NIR definition], Table_SourceData_Feedlot_FracGASMmT[FracGASMmT]) -> 0.4 | F30: (kg NH3-N + NOx-N)/kg N
D31: ='Input - Feedlot'!$D$41 -> Anaerobic lagoon | E31: =_xlfn.XLOOKUP(D31, Table_SourceData_Feedlot_FracGASMmT[NIR definition], Table_SourceData_Feedlot_FracGASMmT[FracGASMmT]) -> 0.35 | F31: (kg NH3-N + NOx-N)/kg N
D33: M1_Table_MMS_ATMOS | L33: M1_Table_MMS_ATMOS
D34: Nitrogen in each MMS excluding direct application (Method 1) | L34: Nitrogen in each MMS excluding direct application (Method 1)
D35: MMS | E35: Domestic | F35: Mid-fed | G35: Long-fed | L35: MMS | M35: Domestic | N35: Mid-fed | O35: Long-fed
D36: ='Input - Feedlot'!$D$29 -> Drylot (feed pad) | E36: {=MMS_Feedlot_AtmosphericDeposition_Equations.VEERG_4_1_1_5__2_VolatilisedNitrogenFromManureManagement(E20,$E28)} -> 43058.276 | F36: {=MMS_Feedlot_AtmosphericDeposition_Equations.VEERG_4_1_1_5__2_VolatilisedNitrogenFromManureManagement(F20,$E28)} -> 1520.6124 | G36: {=MMS_Feedlot_AtmosphericDeposition_Equations.VEERG_4_1_1_5__2_VolatilisedNitrogenFromManureManagement(G20,$E28)} -> 2196.288 | H36: =$E$12 -> kg N | L36: ='Input - Feedlot'!$D$29 -> Drylot (feed pad) | M36: {=MMS_Feedlot_AtmosphericDeposition_Equations.VEERG_4_1_1_5__2_VolatilisedNitrogenFromManureManagement(M20,$E28)} -> 43058.276 | N36: {=MMS_Feedlot_AtmosphericDeposition_Equations.VEERG_4_1_1_5__2_VolatilisedNitrogenFromManureManagement(N20,$E28)} -> 1520.6124 | O36: {=MMS_Feedlot_AtmosphericDeposition_Equations.VEERG_4_1_1_5__2_VolatilisedNitrogenFromManureManagement(O20,$E28)} -> 2196.288 | P36: kg N
D37: ='Input - Feedlot'!$D$35 -> Solid storage | E37: {=MMS_Feedlot_AtmosphericDeposition_Equations.VEERG_4_1_1_5__2_VolatilisedNitrogenFromManureManagement(E21,$E29)} -> 1344.1359 | F37: {=MMS_Feedlot_AtmosphericDeposition_Equations.VEERG_4_1_1_5__2_VolatilisedNitrogenFromManureManagement(F21,$E29)} -> 47.468449 | G37: {=MMS_Feedlot_AtmosphericDeposition_Equations.VEERG_4_1_1_5__2_VolatilisedNitrogenFromManureManagement(G21,$E29)} -> 68.56079 | H37: =$E$12 -> kg N | L37: ='Input - Feedlot'!$D$35 -> Solid storage | M37: {=MMS_Feedlot_AtmosphericDeposition_Equations.VEERG_4_1_1_5__2_VolatilisedNitrogenFromManureManagement(M21,$E29)} -> 1344.1359 | N37: {=MMS_Feedlot_AtmosphericDeposition_Equations.VEERG_4_1_1_5__2_VolatilisedNitrogenFromManureManagement(N21,$E29)} -> 47.468449 | O37: {=MMS_Feedlot_AtmosphericDeposition_Equations.VEERG_4_1_1_5__2_VolatilisedNitrogenFromManureManagement(O21,$E29)} -> 68.56079 | P37: kg N
D38: ='Input - Feedlot'!$D$36 -> Composting (passive windrow) | E38: {=MMS_Feedlot_AtmosphericDeposition_Equations.VEERG_4_1_1_5__2_VolatilisedNitrogenFromManureManagement(E22,$E30)} -> 8602.4695 | F38: {=MMS_Feedlot_AtmosphericDeposition_Equations.VEERG_4_1_1_5__2_VolatilisedNitrogenFromManureManagement(F22,$E30)} -> 303.79807 | G38: {=MMS_Feedlot_AtmosphericDeposition_Equations.VEERG_4_1_1_5__2_VolatilisedNitrogenFromManureManagement(G22,$E30)} -> 438.78906 | H38: =$E$12 -> kg N | L38: ='Input - Feedlot'!$D$36 -> Composting (passive windrow) | M38: {=MMS_Feedlot_AtmosphericDeposition_Equations.VEERG_4_1_1_5__2_VolatilisedNitrogenFromManureManagement(M22,$E30)} -> 8602.4695 | N38: {=MMS_Feedlot_AtmosphericDeposition_Equations.VEERG_4_1_1_5__2_VolatilisedNitrogenFromManureManagement(N22,$E30)} -> 303.79807 | O38: {=MMS_Feedlot_AtmosphericDeposition_Equations.VEERG_4_1_1_5__2_VolatilisedNitrogenFromManureManagement(O22,$E30)} -> 438.78906 | P38: kg N
D39: ='Input - Feedlot'!$D$41 -> Anaerobic lagoon | E39: {=MMS_Feedlot_AtmosphericDeposition_Equations.VEERG_4_1_1_5__2_VolatilisedNitrogenFromManureManagement(E23,$E31)} -> 502.34656 | F39: {=MMS_Feedlot_AtmosphericDeposition_Equations.VEERG_4_1_1_5__2_VolatilisedNitrogenFromManureManagement(F23,$E31)} -> 17.740477 | G39: {=MMS_Feedlot_AtmosphericDeposition_Equations.VEERG_4_1_1_5__2_VolatilisedNitrogenFromManureManagement(G23,$E31)} -> 25.62336 | H39: =$E$12 -> kg N | L39: ='Input - Feedlot'!$D$41 -> Anaerobic lagoon | M39: {=MMS_Feedlot_AtmosphericDeposition_Equations.VEERG_4_1_1_5__2_VolatilisedNitrogenFromManureManagement(M23,$E31)} -> 502.34656 | N39: {=MMS_Feedlot_AtmosphericDeposition_Equations.VEERG_4_1_1_5__2_VolatilisedNitrogenFromManureManagement(N23,$E31)} -> 17.740477 | O39: {=MMS_Feedlot_AtmosphericDeposition_Equations.VEERG_4_1_1_5__2_VolatilisedNitrogenFromManureManagement(O23,$E31)} -> 25.62336 | P39: kg N
D41: MMSATMOS | E41: =SUM(E36:G39) -> 58126.109 | F41: =$E$12 -> kg N | L41: MMSATMOS | M41: =SUM(M36:O39) -> 58126.109 | N41: =$E$12 -> kg N
D45: {=MMS_Feedlot_AtmosphericDeposition_Equations.VEERG_4_1_1_5__1_TotalAnnualAtmosphericDepositionEmissions_Title()} -> Total annual atmospheric deposition emissions from manure management
D46: {=MMS_Feedlot_AtmosphericDeposition_Equations.VEERG_4_1_1_5__1_TotalAnnualAtmosphericDepositionEmissions_Source()} -> VEERG 2026: 4.1.1.5, Equation (1)
D47: Function name | E47: {=Common_InputFunctions.Utility_DisplayFunctionName(E60)} -> =MMS_Feedlot_AtmosphericDeposition_Equations.VEERG_4_1_1_5__1_TotalAnnualAtmosphericDepositionEmissions
D50: Variable | E50: {=MMS_Feedlot_AtmosphericDeposition_Equations.VEERG_4_1_1_5__1_TotalAnnualAtmosphericDepositionEmissions_Variable()} -> E_N2Oad
...

Sheet 4.1.1.9 Manure applied to soils
A1: #VALUE! | C1: 4.1.1.9 Manure applied to soils
A3: =HYPERLINK("#'Home'!A1", "Home") -> Home | D3: Method 1 | L3: Method 2
A4: =HYPERLINK("#'Results'!A1", "Results") -> Results
D5: {=MMS_Feedlot_ManureAppliedToSoils_Equations.VEERG_4_1_1_9__1_MassOfNitrogenAppliedToSoilsScope1_Title()} -> Mass of nitrogen applied to soils for scope 1 emissions
A6: INPUTS | D6: {=MMS_Feedlot_ManureAppliedToSoils_Equations.VEERG_4_1_1_9__1_MassOfNitrogenAppliedToSoilsScope1_Source()} -> VEERG 2026: 4.1.1.9, Equation (1)
A7: =HYPERLINK("#'Input - Site'!A1", "Site") -> Site | D7: Function name | E7: {=Common_InputFunctions.Utility_DisplayFunctionName(E52)} -> =MMS_Feedlot_ManureAppliedToSoils_Equations.VEERG_4_1_1_9__1_MassOfNitrogenAppliedToSoilsScope1
A8: =HYPERLINK("#'Input - Feedlot'!A1", "Feedlot") -> Feedlot
A10: CALCULATIONS
A11: =HYPERLINK("#'4.1.1.1-2 Methane'!A1", "4.1.1.1-2 Methane") -> 4.1.1.1-2 Methane | D11: Variable | E11: {=MMS_Feedlot_ManureAppliedToSoils_Equations.VEERG_4_1_1_9__1_MassOfNitrogenAppliedToSoilsScope1_Variable()} -> MNSoil_scope1
A12: =HYPERLINK("#'4.1.1.3-4 Direct N20'!A1", "4.1.1.3-4 Direct N2O") -> 4.1.1.3-4 Direct N2O | D12: Unit | E12: {=MMS_Feedlot_ManureAppliedToSoils_Equations.VEERG_4_1_1_9__1_MassOfNitrogenAppliedToSoilsScope1_Unit()} -> kg N
A13: =HYPERLINK("#'4.1.1.5-6 Atmos Deposition'!A1", "4.1.1.5-6 Atmospheric deposition") -> 4.1.1.5-6 Atmospheric deposition
A14: =HYPERLINK("#'4.1.1.9 Manure applied to soils'!A1", "4.1.1.9 Manure applied to soils") -> 4.1.1.9 Manure applied to soils | D14: {=MMS_Feedlot_ManureAppliedToSoils_Equations.VEERG_4_1_1_9__1_MassOfNitrogenAppliedToSoilsScope1_Arguments()} -> MN_jmT23 | E14: mass of N in secondary and tertiary treatment MMS stages as calculated for manure management : kg N | H14: ="See " & $D$19 -> See M1_Table_MN_j_m_T-2-3
D15: EF_mT23 | E15: nitrous oxide emission factor for each MMS : kg N2O-N/kg N | H15: ="See " & $D$26 -> See Table_EF_j_m_T-2-3
A16: APPENDICES | D16: FracGASM_mT23 | E16: fraction of animal waste N volatilised in each MMS for each cattle group : (kg NH3-N + NOx-N)/kg N | H16: ="See " & $D$34 -> See Table_FracGASM_m_T-2-3
A17: =HYPERLINK("#'Constants - Feedlot'!A1", "Constants - Feedlot") -> Constants - Feedlot | D17: PF | E17: fraction of manure applied to soil within the feedlot boundary : fraction | H17: ="See " & $D$42 -> See Table_PF
A18: =HYPERLINK("#'Constants - Livestock'!A1", "Constants - Livestock") -> Constants - Livestock
A19: =HYPERLINK("#'Constants - Common'!A1", "Constants - Common") -> Constants - Common | D19: M1_Table_MN_j_m_T-2-3 | L19: M2_Table_MN_j_m_T-2-3
A20: =HYPERLINK("#'Acknowledgements'!A1", "Acknowledgements") -> Acknowledgements | D20: Mass on N in stage 2 and 3 MMS (Method 1) | L20: Mass on N in stage 2 and 3 MMS (Method 2)
D21: MMS | E21: Domestic | F21: Mid-fed | G21: Long-fed | L21: MMS | M21: Domestic | N21: Mid-fed | O21: Long-fed
D22: ='Input - Feedlot'!$D$35 -> Solid storage | E22: ='4.1.1.3-4 Direct N20'!$E$173 -> 5376.5434 | F22: ='4.1.1.3-4 Direct N20'!$F$173 -> 189.8738 | G22: ='4.1.1.3-4 Direct N20'!$G$173 -> 274.24316 | H22: kg N | L22: ='Input - Feedlot'!$D$35 -> Solid storage | M22: ='4.1.1.3-4 Direct N20'!$M$173 -> 5376.5434 | N22: ='4.1.1.3-4 Direct N20'!$N$173 -> 189.8738 | O22: ='4.1.1.3-4 Direct N20'!$O$173 -> 274.24316 | P22: kg N
D23: ='Input - Feedlot'!$D$36 -> Composting (passive windrow) | E23: ='4.1.1.3-4 Direct N20'!$E$174 -> 21506.174 | F23: ='4.1.1.3-4 Direct N20'!$F$174 -> 759.49518 | G23: ='4.1.1.3-4 Direct N20'!$G$174 -> 1096.9726 | H23: kg N | L23: ='Input - Feedlot'!$D$36 -> Composting (passive windrow) | M23: ='4.1.1.3-4 Direct N20'!$M$174 -> 21506.174 | N23: ='4.1.1.3-4 Direct N20'!$N$174 -> 759.49518 | O23: ='4.1.1.3-4 Direct N20'!$O$174 -> 1096.9726 | P23: kg N
D24: ='Input - Feedlot'!$D$41 -> Anaerobic lagoon | E24: ='4.1.1.3-4 Direct N20'!$E$129 -> 1435.2759 | F24: ='4.1.1.3-4 Direct N20'!$F$129 -> 50.687078 | G24: ='4.1.1.3-4 Direct N20'!$G$129 -> 73.2096 | H24: kg N | L24: ='Input - Feedlot'!$D$41 -> Anaerobic lagoon | M24: ='4.1.1.3-4 Direct N20'!$M$129 -> 1435.2759 | N24: ='4.1.1.3-4 Direct N20'!$N$129 -> 50.687078 | O24: ='4.1.1.3-4 Direct N20'!$O$129 -> 73.2096 | P24: kg N
D26: Table_EF_j_m_T-2-3
D27: EFs for MMS
D28: MMS | E28: EFjm
D29: ='Input - Feedlot'!$D$29 -> Drylot (feed pad) | E29: =_xlfn.XLOOKUP(D29, Table_SourceData_Feedlot_NO2EFs[NIR definition], Table_SourceData_Feedlot_NO2EFs[EF mT]) -> 0.0054 | F29: kg N2O/kg N
D30: ='Input - Feedlot'!$D$35 -> Solid storage | E30: =_xlfn.XLOOKUP($D$30, Table_SourceData_Feedlot_NO2EFs[NIR definition], Table_SourceData_Feedlot_NO2EFs[EF mT]) -> 0.005 | F30: kg N2O/kg N
D31: ='Input - Feedlot'!$D$36 -> Composting (passive windrow) | E31: =_xlfn.XLOOKUP($D$31, Table_SourceData_Feedlot_NO2EFs[NIR definition], Table_SourceData_Feedlot_NO2EFs[EF mT]) -> 0.01 | F31: kg N2O/kg N
D32: ='Input - Feedlot'!$D$41 -> Anaerobic lagoon | E32: =_xlfn.XLOOKUP($D$32, Table_SourceData_Feedlot_NO2EFs[NIR definition], Table_SourceData_Feedlot_NO2EFs[EF mT]) -> 0 | F32: kg N2O/kg N
D34: Table_FracGASM_m_T-2-3
D35: Fraction of N volatilised in each MMS
D36: MMS | E36: EFjm
D37: ='Input - Feedlot'!$D$29 -> Drylot (feed pad) | E37: =_xlfn.XLOOKUP(D37, Table_SourceData_Feedlot_FracGASMmT[NIR definition], Table_SourceData_Feedlot_FracGASMmT[FracGASMmT]) -> 0.6 | F37: (kg NH3-N + NOx-N)/kg N
D38: ='Input - Feedlot'!$D$35 -> Solid storage | E38: =_xlfn.XLOOKUP(D38, Table_SourceData_Feedlot_FracGASMmT[NIR definition], Table_SourceData_Feedlot_FracGASMmT[FracGASMmT]) -> 0.25 | F38: (kg NH3-N + NOx-N)/kg N
D39: ='Input - Feedlot'!$D$36 -> Composting (passive windrow) | E39: =_xlfn.XLOOKUP(D39, Table_SourceData_Feedlot_FracGASMmT[NIR definition], Table_SourceData_Feedlot_FracGASMmT[FracGASMmT]) -> 0.4 | F39: (kg NH3-N + NOx-N)/kg N
D40: ='Input - Feedlot'!$D$41 -> Anaerobic lagoon | E40: =_xlfn.XLOOKUP(D40, Table_SourceData_Feedlot_FracGASMmT[NIR definition], Table_SourceData_Feedlot_FracGASMmT[FracGASMmT]) -> 0.35 | F40: (kg NH3-N + NOx-N)/kg N
D42: Table_PF
D43: Fraction of manure applied to soil from MMS
D44: MMS | E44: Domestic | F44: Mid-fed | G44: Long-fed
D45: ='Input - Feedlot'!$D$35 -> Solid storage | E45: ='Input - Feedlot'!E49 -> 0.5 | F45: ='Input - Feedlot'!F49 -> 0.5 | G45: ='Input - Feedlot'!G49 -> 0.5 | H45: Fraction
...

Sheet Constants - Feedlot
A1: #VALUE! | C1: Source Data - Feedlot
A3: =HYPERLINK("#'Home'!A1", "Home") -> Home
A4: =HYPERLINK("#'Results'!A1", "Results") -> Results
D5: {=SourceData_Feedlot.SourceData_Feedlot_VSL_Title()} -> Feedlot - Fraction of volatile solids lost during storage in the primary system
A6: INPUTS | D6: {=SourceData_Feedlot.SourceData_Feedlot_VSL_Source()} -> VEERG 2026: 4.1.2.3 CONSTANTS
A7: =HYPERLINK("#'Input - Site'!A1", "Site") -> Site | D7: {=SourceData_Feedlot.SourceData_Feedlot_VSL_Variable()} -> VSL | E7: {=SourceData_Feedlot.SourceData_Feedlot_VSL_Data()} -> 0.5 | F7: {=SourceData_Feedlot.SourceData_Feedlot_VSL_Unit()} -> Fraction
A8: =HYPERLINK("#'Input - Feedlot'!A1", "Feedlot") -> Feedlot
A10: CALCULATIONS | D10: {=SourceData_Feedlot.SourceData_Feedlot_MMSm1T3_Title()} -> Fraction of volatile solids to each tertiary system assumed that 2 per cent is run - off from the feed pad.
A11: =HYPERLINK("#'4.1.1.1-2 Methane'!A1", "4.1.1.1-2 Methane") -> 4.1.1.1-2 Methane | D11: {=SourceData_Feedlot.SourceData_Feedlot_MMSm1T3_Source()} -> VEERG 2026: 4.1.2.3 CONSTANTS
A12: =HYPERLINK("#'4.1.1.3-4 Direct N20'!A1", "4.1.1.3-4 Direct N2O") -> 4.1.1.3-4 Direct N2O | D12: {=SourceData_Feedlot.SourceData_Feedlot_MMSm1T3_Variable()} -> MMSm1T3 | E12: {=SourceData_Feedlot.SourceData_Feedlot_MMSm1T3_Data()} -> 0.02 | F12: {=SourceData_Feedlot.SourceData_Feedlot_MMSm1T3_Unit()} -> Fraction
A13: =HYPERLINK("#'4.1.1.5-6 Atmos Deposition'!A1", "4.1.1.5-6 Atmospheric deposition") -> 4.1.1.5-6 Atmospheric deposition
A14: =HYPERLINK("#'4.1.1.9 Manure applied to soils'!A1", "4.1.1.9 Manure applied to soils") -> 4.1.1.9 Manure applied to soils
D15: {=SourceData_Feedlot.SourceData_Feedlot_AshContent_Title()} -> Ash content of manure.
A16: APPENDICES | D16: {=SourceData_Feedlot.SourceData_Feedlot_AshContent_Source()} -> VEERG 2026: 4.1.2.3 CONSTANTS
A17: =HYPERLINK("#'Constants - Feedlot'!A1", "Constants - Feedlot") -> Constants - Feedlot | D17: {=SourceData_Feedlot.SourceData_Feedlot_AshContent_Variable()} -> A | E17: {=SourceData_Feedlot.SourceData_Feedlot_AshContent_Data()} -> 0.16 | F17: {=SourceData_Feedlot.SourceData_Feedlot_AshContent_Unit()} -> Fraction
A18: =HYPERLINK("#'Constants - Livestock'!A1", "Constants - Livestock") -> Constants - Livestock
A19: =HYPERLINK("#'Constants - Common'!A1", "Constants - Common") -> Constants - Common
A20: =HYPERLINK("#'Acknowledgements'!A1", "Acknowledgements") -> Acknowledgements | D20: {=SourceData_Feedlot.SourceData_Feedlot_MethaneEmissionsPotential_Title()} -> Methane emissions potential.
D21: {=SourceData_Feedlot.SourceData_Feedlot_MethaneEmissionsPotential_Source()} -> VEERG 2026: 4.1.2.3 CONSTANTS
D22: {=SourceData_Feedlot.SourceData_Feedlot_MethaneEmissionsPotential_Variable()} -> B0 | E22: {=SourceData_Feedlot.SourceData_Feedlot_MethaneEmissionsPotential_Data()} -> 0.19 | F22: {=SourceData_Feedlot.SourceData_Feedlot_MethaneEmissionsPotential_Unit()} -> m3 CH4 / kg VS
D25: Feedlot manure management systems | G25: Feedlot crop or pasture production systems | J25: Irrigation methods
D27: MMS | E27: Symbol and MMS | G27: Production system | J27: Irrigation method
D28: ='Constants - Livestock'!$E$16 -> Drylot (feed pad) | E28: ='Constants - Livestock'!$F$16 -> Drylot (feed pad) (m=5) | G28: ='Constants - Common'!$F$188 -> Crop | J28: Not irrigated
D29: ='Constants - Livestock'!$E$15 -> Solid storage | E29: ='Constants - Livestock'!$F$15 -> Solid storage (m=4) | G29: ='Constants - Common'!$F$187 -> Pasture | J29: Drip irrigation
D30: ='Constants - Livestock'!$E$17 -> Composting (passive windrow) | E30: ='Constants - Livestock'!$F$17 -> Composting (passive windrow) (m=6) | J30: Sprinkler irrigation
D31: ='Constants - Livestock'!$E$26 -> Direct application | E31: ='Constants - Livestock'!$F$26 -> Direct application (m=13) | J31: Surface irrigation
D32: ='Constants - Livestock'!$E$10 -> Anaerobic lagoon | E32: ='Constants - Livestock'!$F$10 -> Anaerobic lagoon (m=1) | J32: Other irrigation
D36: {=SourceData_Feedlot.SourceData_Feedlot_DurationOfStay_Title()} -> Beef feedlot cattle - Duration of stay (days)
D37: {=SourceData_Feedlot.SourceData_Feedlot_DurationOfStay_Source()} -> VEERG 2026: Table A.1.1.1: Beef feedlot cattle - Duration of stay (days)
D38: Feedlot type | E38: Length of stay
D39: {=Common_InputFunctions.Utility_DisplayArrayInTable(SourceData_Feedlot.SourceData_Feedlot_DurationOfStay_Data(), Table_SourceData_Feedlot_LengthOfStay[[#Headers],[Feedlot type]], 0)} -> Domestic | E39: {=Common_InputFunctions.Utility_DisplayArrayInTable(SourceData_Feedlot.SourceData_Feedlot_DurationOfStay_Data(), Table_SourceData_Feedlot_LengthOfStay[[#Headers],[Feedlot type]], 0)} -> 1-80 days
D40: {=Common_InputFunctions.Utility_DisplayArrayInTable(SourceData_Feedlot.SourceData_Feedlot_DurationOfStay_Data(), Table_SourceData_Feedlot_LengthOfStay[[#Headers],[Feedlot type]], 0)} -> Mid-fed | E40: {=Common_InputFunctions.Utility_DisplayArrayInTable(SourceData_Feedlot.SourceData_Feedlot_DurationOfStay_Data(), Table_SourceData_Feedlot_LengthOfStay[[#Headers],[Feedlot type]], 0)} -> 81-200 days
D41: {=Common_InputFunctions.Utility_DisplayArrayInTable(SourceData_Feedlot.SourceData_Feedlot_DurationOfStay_Data(), Table_SourceData_Feedlot_LengthOfStay[[#Headers],[Feedlot type]], 0)} -> Long-fed | E41: {=Common_InputFunctions.Utility_DisplayArrayInTable(SourceData_Feedlot.SourceData_Feedlot_DurationOfStay_Data(), Table_SourceData_Feedlot_LengthOfStay[[#Headers],[Feedlot type]], 0)} -> 201+ days
D44: {=SourceData_Feedlot.SourceData_Feedlot_AnimalCharacteristics_Title()} -> Beef feedlot cattle - Animal characteristics
D45: {=SourceData_Feedlot.SourceData_Feedlot_AnimalCharacteristics_Source()} -> VEERG 2026: Table A.1.1.2: Beef feedlot cattle - Animal characteristics
D46: {=SourceData_Feedlot.SourceData_Feedlot_AnimalCharacteristics_Variation()} -> VARIATION ON SOURCE:
D47: Moved feedlot types to a separate column to aid lookup.
D48: Named 'characteristic' column - original has header 'Unit' which covers two columns)
D49: Feedlot type | E49: Characteristic | F49: Unit | G49: 2005-2009 | H49: 2010-2014 | I49: 2015-2019 | J49: 2020-2023
