Workbook
Name Common_Equations.Common_ConvertCH4ToCO2e: _xlfn.LAMBDA(_xlpm.E_CH4,_xlpm.GWP_CH4, _xlpm.E_CH4 * _xlpm.GWP_CH4)
Name Common_Equations.Common_ConvertCH4ToCO2e_Arguments: _xlfn.LAMBDA(_xlfn.MAKEARRAY(2, 2, _xlfn.LAMBDA(_xlpm.r,_xlpm.c, INDEX({"ECH4","Methane emissions (t CH4)";"GWPCH4","Global warming potential for methane (t CO2-e / t CH4)"}, _xlpm.r, _xlpm.c))))
Name Common_Equations.Common_ConvertCH4ToCO2e_LatexEquation: _xlfn.LAMBDA("CO2_e = E_{CH4} \times GWP_{CH4}")
Name Common_Equations.Common_ConvertCH4ToCO2e_NIRReference: _xlfn.LAMBDA("")
Name Common_Equations.Common_ConvertCH4ToCO2e_Title: _xlfn.LAMBDA("Convert methane emissions to carbon dioxide equivalent emissions")
Name Common_Equations.Common_ConvertCH4ToCO2e_Unit: _xlfn.LAMBDA("t CO2e")
Name Common_Equations.Common_ConvertCH4ToCO2e_Variable: _xlfn.LAMBDA("ECH4 CO2e")
Name Common_Equations.Common_ConvertN2OToCO2e: _xlfn.LAMBDA(_xlpm.E_N2O,_xlpm.GWP_N2O, _xlpm.E_N2O * _xlpm.GWP_N2O)
Name Common_Equations.Common_ConvertN2OToCO2e_LatexEquation: _xlfn.LAMBDA("CO2_e = E_{N2O} \times GWP_{N2O}")
Name Common_Equations.Common_ConvertN2OToCO2e_NIRReference: _xlfn.LAMBDA("")
Name Common_Equations.Common_ConvertN2OToCO2e_Title: _xlfn.LAMBDA("Convert nitrous oxide emissions to carbon dioxide equivalent emissions")
Name Common_Equations.Common_ConvertN2OToCO2e_Unit: _xlfn.LAMBDA("t CO2e")
Name Common_Equations.Common_ConvertN2OToCO2e_Variable: _xlfn.LAMBDA("EN2O CO2e")
Name Common_InputFunctions.Utility_ConvertStateCommonNameToAbbreviation: _xlfn.LAMBDA(_xlpm.StateCommonName,_xlpm.StateCommonNameArray,_xlpm.StateAbbreviationArray, _xlfn.XLOOKUP(_xlpm.StateCommonName, _xlpm.StateCommonNameArray, _xlpm.StateAbbreviationArray, ""))
Name Common_InputFunctions.Utility_DisplayArguments_1_2: _xlfn.LAMBDA(_xlpm.ArgumentsArray, _xlfn.CHOOSECOLS(_xlpm.ArgumentsArray, 1, 2))
Name Common_InputFunctions.Utility_DisplayArguments_3_4: _xlfn.LAMBDA(_xlpm.ArgumentsArray, _xlfn.CHOOSECOLS(_xlpm.ArgumentsArray, 3, 4))
Name Common_InputFunctions.Utility_DisplayFunctionName: _xlfn.LAMBDA(_xlpm.Function, _xlfn.TEXTBEFORE(_xlfn.FORMULATEXT(_xlpm.Function), "("))
Name Common_InputFunctions.Utility_GetArrayTableColumnStartNumber: _xlfn.LAMBDA(_xlpm.TableHeaderCell, COLUMN(_xlpm.TableHeaderCell))
Name Common_InputFunctions.Utility_GetArrayTableRowStartNumber: _xlfn.LAMBDA(_xlpm.TableheaderCell,_xlpm.RowsBetweenHeaderandArray, ROW(_xlpm.TableheaderCell) + _xlpm.RowsBetweenHeaderandArray - 1)
Name Common_InputFunctions.Utility_LookupValueInTable: _xlfn.LAMBDA(_xlpm.LookupValue,_xlpm.LookupArray,_xlpm.ReturnArray, _xlfn.XLOOKUP(_xlpm.LookupValue, _xlpm.LookupArray, _xlpm.ReturnArray, ""))
Name Common_InputFunctions.Utility_SourceHyperlink: _xlfn.LAMBDA(_xlpm.TargetCell, _xlfn.LET(_xlpm.sh, _xlfn.TEXTAFTER(CELL("filename", _xlpm.TargetCell), "]"), _xlpm.addr, CELL("address", _xlpm.TargetCell), "#'" & _xlpm.sh & "'!" & _xlpm.addr))
Name Common_SourceData.Common_SourceData_AustralianStatesTerritories_Source: _xlfn.LAMBDA("")
Name Common_SourceData.Common_SourceData_AustralianStatesTerritories_Title: _xlfn.LAMBDA("Australian states and territories")
Name Common_SourceData.Common_SourceData_AustralianStatesTerritories_Unit: _xlfn.LAMBDA("")
Name Common_SourceData.Common_SourceData_AustralianStatesTerritories_Variable: _xlfn.LAMBDA("")
Name Common_SourceData.Common_SourceData_ClimateZones_Source: _xlfn.LAMBDA("VEERG 2026: Table 1.3: Climate and Rainfall zone classifications and definitions")
Name Common_SourceData.Common_SourceData_ClimateZones_Title: _xlfn.LAMBDA("VEERG Australian climate zones")
Name Common_SourceData.Common_SourceData_ClimateZones_Unit: _xlfn.LAMBDA("")
Name Common_SourceData.Common_SourceData_ClimateZones_Variable: _xlfn.LAMBDA("")
Name Common_SourceData.Common_SourceData_ConvertGasElementalToMolecular_Source: _xlfn.LAMBDA("XXXXXXX")
Name Common_SourceData.Common_SourceData_ConvertGasElementalToMolecular_Title: _xlfn.LAMBDA("Factor to convert elemental mass of gas to molecular mass")
Name Common_SourceData.Common_SourceData_ConvertGasElementalToMolecular_Unit: _xlfn.LAMBDA("factor")
Name Common_SourceData.Common_SourceData_ConvertGasElementalToMolecular_Variable: _xlfn.LAMBDA("Cg")
Name Common_SourceData.Common_SourceData_ConvertN2oElementalToMolecularCg_Data: _xlfn.LAMBDA(44 / 28)
Name Common_SourceData.Common_SourceData_ConvertN2oElementalToMolecularCg_Source: _xlfn.LAMBDA("National Inventory Report 2023 Volume 1")
Name Common_SourceData.Common_SourceData_ConvertN2oElementalToMolecularCg_Title: _xlfn.LAMBDA("Factor to convert elemental mass of N2O to molecular mass")
Name Common_SourceData.Common_SourceData_ConvertN2oElementalToMolecularCg_Unit: _xlfn.LAMBDA("factor")
Name Common_SourceData.Common_SourceData_ConvertN2oElementalToMolecularCg_Variable: _xlfn.LAMBDA("CgN2O")
Name Common_SourceData.Common_SourceData_DataScores_Scope3_Source: _xlfn.LAMBDA("VEERG 2026: XXXXXXXX")
Name Common_SourceData.Common_SourceData_DataScores_Scope3_Title: _xlfn.LAMBDA("Australian data scores for scope 3")
Name Common_SourceData.Common_SourceData_DataScores_Scope3_Unit: _xlfn.LAMBDA("")
Name Common_SourceData.Common_SourceData_DataScores_Scope3_Variable: _xlfn.LAMBDA("")
Name Common_SourceData.Common_SourceData_DataScores_Scope3_Variation: _xlfn.LAMBDA("")
Name Common_SourceData.Common_SourceData_DensityOfMethane_Data: _xlfn.LAMBDA(0.6784)
Name Common_SourceData.Common_SourceData_DensityOfMethane_Source: _xlfn.LAMBDA("National Inventory Report 2023 Volume 1: Equations 3.B.1a_2, 3.B.1c_2, 3.B.3_1, 3.B.4g_2")
Name Common_SourceData.Common_SourceData_DensityOfMethane_Title: _xlfn.LAMBDA("p = density of methane")
Name Common_SourceData.Common_SourceData_DensityOfMethane_Unit: _xlfn.LAMBDA("kg/m3")
Name Common_SourceData.Common_SourceData_EFleach_Data: _xlfn.LAMBDA(_xlfn.MAKEARRAY(1, 2, _xlfn.LAMBDA(_xlpm.r,_xlpm.c, INDEX({"EFleach",0.011}, _xlpm.r, _xlpm.c))))
Name Common_SourceData.Common_SourceData_EFleach_NIRReference: _xlfn.LAMBDA("National Inventory Report Volume 1: Equation 3.D.B_10")
Name Common_SourceData.Common_SourceData_EFleach_Source: _xlfn.LAMBDA("VEERG 2026:5.5.2.3 Constant Parameters")
Name Common_SourceData.Common_SourceData_EFleach_Title: _xlfn.LAMBDA("Emission factor for nitrogen leaching and runoff")
Name Common_SourceData.Common_SourceData_EFleach_Unit: _xlfn.LAMBDA("(kg N2O-N / kg N")
Name Common_SourceData.Common_SourceData_EFleach_Variation: _xlfn.LAMBDA((""))
Name Common_SourceData.Common_SourceData_EFN2O_NIRReference: _xlfn.LAMBDA("")
Name Common_SourceData.Common_SourceData_EFN2O_Source: _xlfn.LAMBDA("VEERG 2026: Table A.2.2.1")
Name Common_SourceData.Common_SourceData_EFN2O_Title: _xlfn.LAMBDA("Nitrous oxide emission factors for inorganic fertiliser application")
Name Common_SourceData.Common_SourceData_EFN2O_Unit: _xlfn.LAMBDA("(kg N2O-N / kg N")
Name Common_SourceData.Common_SourceData_EFPastureRangeAndPaddock_Data: _xlfn.LAMBDA(_xlfn.MAKEARRAY(3, 2, _xlfn.LAMBDA(_xlpm.r,_xlpm.c, INDEX({"Climate zone","EFPRP";"Wet climate zone",0.006;"Dry climate zone",0.002}, _xlpm.r, _xlpm.c))))
Name Common_SourceData.Common_SourceData_EFPastureRangeAndPaddock_NIRReference: _xlfn.LAMBDA("")
Name Common_SourceData.Common_SourceData_EFPastureRangeAndPaddock_Source: _xlfn.LAMBDA("VEERG 2026: Table A.2.2.2")

Sheet Home
A1: Home

Sheet Results
A1: #VALUE! | C1: 4.2 Manure management: Pasture Beef: Results
A3: =HYPERLINK("#'Home'!A1", "Home") -> Home
A4: =HYPERLINK("#'Results'!A1", "Results") -> Results | D4: Emissions breakdown
A6: INPUTS | D6: Scope 1 source | E6: GHG emissions method 1 | F6: GHG emissions method 2 | G6: GHG Unit | H6: CO2-e emissions method 1 | I6: CO2-e emissions method 2 | J6: CO2-e unit
A7: =HYPERLINK("#'Input - Site'!A1", "Site") -> Site | D7: 4.2.1.1-2 Manure methane | E7: ='4.2.1.1-2 Methane'!$E$244 -> 2.3956066 | F7: ='4.2.1.1-2 Methane'!X276 -> 2.1745073 | G7: t CH4 | H7: ='4.2.1.1-2 Methane'!$E$249 -> 67.076985 | I7: ='4.2.1.1-2 Methane'!$X$281 -> 60.886206 | J7: t CO2e
A8: =HYPERLINK("#'Input - Pasture Beef'!A1", "Pasture Beef") -> Pasture Beef | D8: 4.2.1.3-4 Soil direct N2O | E8: ='4.2.1.3-4 Soil direct N20'!$E$229 -> 0.21126044 | F8: ='4.2.1.3-4 Soil direct N20'!$V$267 -> 0.18859599 | G8: t N2O | H8: ='4.2.1.3-4 Soil direct N20'!$E$234 -> 55.984016 | I8: ='4.2.1.3-4 Soil direct N20'!$V$272 -> 49.977938 | J8: t CO2e
D9: 4.2.1.5-6 Soil atmospheric deposition | E9: ='4.2.1.5-6 Soil Atmos Dep'!$E$35 -> 0.039928223 | F9: ='4.2.1.5-6 Soil Atmos Dep'!$M$35 -> 0.035644643 | G9: ='4.2.1.5-6 Soil Atmos Dep'!$F$35 -> t N2O | H9: ='4.2.1.5-6 Soil Atmos Dep'!$E$40 -> 10.580979 | I9: ='4.2.1.5-6 Soil Atmos Dep'!$M$40 -> 9.4458304 | J9: t CO2e
A10: CALCULATIONS | D10: 4.2.1.7-8 Soil leaching and runoff | E10: ='4.2.1.7-8 Soil leach runoff'!$E$36 -> 0 | F10: ='4.2.1.7-8 Soil leach runoff'!$L$36 -> 0 | G10: ='4.2.1.7-8 Soil leach runoff'!$F$36 -> t N2O | H10: ='4.2.1.7-8 Soil leach runoff'!$E$41 -> 0 | I10: ='4.2.1.7-8 Soil leach runoff'!$L$41 -> 0 | J10: t CO2e
A11: =HYPERLINK("#'4.2.1.1-2 Methane'!A1", "4.2.1.1-2 Methane") -> 4.2.1.1-2 Methane | D11: Total | H11: =SUM(H7:H10) -> 133.64198 | I11: =SUM(I7:I10) -> 120.30997 | J11: t CO2e
A12: =HYPERLINK("#'4.2.1.3-4 Soil direct N2O'!A1", "4.2.1.3-4 Soil direct N2O") -> 4.2.1.3-4 Soil direct N2O
A13: =HYPERLINK("#'4.2.1.5-6 Soil Atmos Dep'!A1", "4.2.1.5-6 Soil atm. deposition") -> 4.2.1.5-6 Soil atm. deposition
A14: =HYPERLINK("#'4.2.1.7-8 Soil leach runoff'!A1", "4.2.1.7-8 Soil leach & runoff") -> 4.2.1.7-8 Soil leach & runoff
A16: APPENDICES
A17: =HYPERLINK("#'Constants - Pasture Beef'!A1", "Constants - Pasture Beef") -> Constants - Pasture Beef
A18: =HYPERLINK("#'Constants - Livestock'!A1", "Constants - Livestock") -> Constants - Livestock
A19: =HYPERLINK("#'Constants - Common'!A1", "Constants - Common") -> Constants - Common
A20: =HYPERLINK("#'Acknowledgements'!A1", "Acknowledgements") -> Acknowledgements

Sheet Input - Site
A1: #VALUE! | C1: Input - Site
A3: =HYPERLINK("#'Home'!A1", "Home") -> Home
A4: =HYPERLINK("#'Results'!A1", "Results") -> Results
D5: Your business
A6: INPUTS
A7: =HYPERLINK("#'Input - Site'!A1", "Site") -> Site | D7: Farm name | E7: Test Farms
A8: =HYPERLINK("#'Input - Pasture Beef'!A1", "Pasture Beef") -> Pasture Beef | D8: Reporting entity name | E8: Test Farms Pty Ltd
A10: CALCULATIONS | D10: 💡An 'Emissions accounting period' is a 12 month period where the business can report on the emissions, and is typically the same as the business' financial accounting period.
A11: =HYPERLINK("#'4.2.1.1-2 Methane'!A1", "4.2.1.1-2 Methane") -> 4.2.1.1-2 Methane
A12: =HYPERLINK("#'4.2.1.3-4 Soil direct N2O'!A1", "4.2.1.3-4 Soil direct N2O") -> 4.2.1.3-4 Soil direct N2O | D12: Emissions calculation period start date | E12: 45292 | F12: ← DD/MM/YYYY or DD Month YYYY
A13: =HYPERLINK("#'4.2.1.5-6 Soil Atmos Dep'!A1", "4.2.1.5-6 Soil atm. deposition") -> 4.2.1.5-6 Soil atm. deposition | D13: Emissions calculation period end date | E13: =DATE(YEAR(E12)+1,MONTH(E12),DAY(E12))-1 -> 45657 | F13: ← Automatically calculated, 12 months after start date
A14: =HYPERLINK("#'4.2.1.7-8 Soil leach runoff'!A1", "4.2.1.7-8 Soil leach & runoff") -> 4.2.1.7-8 Soil leach & runoff
A16: APPENDICES | D16: Location and climate
A17: =HYPERLINK("#'Constants - Pasture Beef'!A1", "Constants - Pasture Beef") -> Constants - Pasture Beef
A18: =HYPERLINK("#'Constants - Livestock'!A1", "Constants - Livestock") -> Constants - Livestock | D18: Location information is used to reference some region and climate-specific emission factors
A19: =HYPERLINK("#'Constants - Common'!A1", "Constants - Common") -> Constants - Common | D19: Tip: Use the web-based GAF Location Helper tool to easily get region and climate information. You will need an internet connection to use the GAF Location Helper.
A20: =HYPERLINK("#'Acknowledgements'!A1", "Acknowledgements") -> Acknowledgements
D21: State | E21: Western Australia | F21: ← Please select
D22: Region (ABS Statistical area level 4) if state is WA | E22: Western Australia - Outback (South) | F22: ← Please select
D23: Leaching zone | E23: NO - Not in leaching zone | F23: ← Please select
D24: Elevation | E24: 307.7 | F24: Meters
D25: Average temperature for reporting period | E25: 18 | F25: Degrees celsius
D26: Total rainfall for reporting period | E26: 601 | F26: Millimetres
D27: Potential evapotranspiration for reporting period | E27: 1326 | F27: Millimetres
D28: Number of frost days for reporting period | E28: 7 | F28: Days
D29: MAP:PET ratio | E29: =E26/E27 -> 0.45324284
D30: Rainfall zone | E30: =Common_InputFunctions.Utility_LookupItemFromMinMax(E26,Table_SourceData_RainfallZones[Min rainfall],Table_SourceData_RainfallZones[Max rainfall],Table_SourceData_RainfallZones[Rainfall Zone]) -> High rainfall
D31: Climate zone | E31: =Common_InputFunctions.Utility_GetClimateZone(E25,E26,E28,E24,E29,Table_SourceData_ClimateZones[Min temp],Table_SourceData_ClimateZones[Max temp],Table_SourceData_ClimateZones[Min rainfall],Table_SourceData_ClimateZones[Max rainfall],Table_SourceData_ClimateZones[Min frost days],Table_SourceData_ClimateZones[Max frost days],Table_SourceData_ClimateZones[Min elevation],Table_SourceData_ClimateZones[Max elevation],Table_SourceData_ClimateZones[Min MAP:PET],Table_SourceData_ClimateZones[Max MAP:PET],Table_SourceData_ClimateZones[Climate zone]) -> Warm temperate dry
D32: Wet or dry climate zone | E32: =Common_InputFunctions.Utility_LookupValueInTable($E$31,Table_SourceData_WetDryZones[Climate zone],Table_SourceData_WetDryZones[Wet or Dry Zone]) -> Dry climate zone
D33: Temperature zone | E33: =Common_InputFunctions.Utility_LookupItemFromMinMax(E25,Table_SourceData_TemperatureZones[Min MAT],Table_SourceData_TemperatureZones[Max MAT],Table_SourceData_TemperatureZones[Temperature Zone]) -> Temperate

Sheet Input - Pasture Beef
A1: #VALUE! | C1: Input -Pasture Beef
A3: =HYPERLINK("#'Home'!A1", "Home") -> Home
A4: =HYPERLINK("#'Results'!A1", "Results") -> Results
D5: Herd movement
A6: INPUTS
A7: =HYPERLINK("#'Input - Site'!A1", "Site") -> Site | D7: State | E7: ='Input - Site'!$E$21 -> Western Australia
A8: =HYPERLINK("#'Input - Pasture Beef'!A1", "Pasture Beef") -> Pasture Beef | D8: Livestock production region | E8: South West | F8: ← Please select
D9: Cattle breed | E9: Hereford or Shorthorn breeds | F9: ← Please select
A10: CALCULATIONS
A11: =HYPERLINK("#'4.2.1.1-2 Methane'!A1", "4.2.1.1-2 Methane") -> 4.2.1.1-2 Methane
A12: =HYPERLINK("#'4.2.1.3-4 Soil direct N2O'!A1", "4.2.1.3-4 Soil direct N2O") -> 4.2.1.3-4 Soil direct N2O | D12: NOTE: VEERG states that under method 2, time periods may be seasons, months or a custom time period. In this example, method 2 time periods are months.
A13: =HYPERLINK("#'4.2.1.5-6 Soil Atmos Dep'!A1", "4.2.1.5-6 Soil atm. deposition") -> 4.2.1.5-6 Soil atm. deposition
A14: =HYPERLINK("#'4.2.1.7-8 Soil leach runoff'!A1", "4.2.1.7-8 Soil leach & runoff") -> 4.2.1.7-8 Soil leach & runoff | D14: Duration on farm
D15: Method 1 default values (do not edit) | E15: Bulls < 1 year | F15: Bulls > 1 year | G15: Cows < 1 year | H15: Cows 1-2 years | I15: Cows 2-3 years | J15: Cows > 3 years | K15: Steers < 1 year | L15: Steers 1-2 years | M15: Steers 2-3 years | N15: Steers >3 years
A16: APPENDICES | D16: Spring | E16: 91.25 | F16: 91.25 | G16: 91.25 | H16: 91.25 | I16: 91.25 | J16: 91.25 | K16: 91.25 | L16: 91.25 | M16: 91.25 | N16: 91.25 | O16: Days
A17: =HYPERLINK("#'Constants - Pasture Beef'!A1", "Constants - Pasture Beef") -> Constants - Pasture Beef | D17: Summer | E17: 91.25 | F17: 91.25 | G17: 91.25 | H17: 91.25 | I17: 91.25 | J17: 91.25 | K17: 91.25 | L17: 91.25 | M17: 91.25 | N17: 91.25 | O17: Days
A18: =HYPERLINK("#'Constants - Livestock'!A1", "Constants - Livestock") -> Constants - Livestock | D18: Autumn | E18: 91.25 | F18: 91.25 | G18: 91.25 | H18: 91.25 | I18: 91.25 | J18: 91.25 | K18: 91.25 | L18: 91.25 | M18: 91.25 | N18: 91.25 | O18: Days
A19: =HYPERLINK("#'Constants - Common'!A1", "Constants - Common") -> Constants - Common | D19: Winter | E19: 91.25 | F19: 91.25 | G19: 91.25 | H19: 91.25 | I19: 91.25 | J19: 91.25 | K19: 91.25 | L19: 91.25 | M19: 91.25 | N19: 91.25 | O19: Days
A20: =HYPERLINK("#'Acknowledgements'!A1", "Acknowledgements") -> Acknowledgements
D21: Method 2 custom values (edit if known) | E21: Bulls < 1 year | F21: Bulls > 1 year | G21: Cows < 1 year | H21: Cows 1-2 years | I21: Cows 2-3 years | J21: Cows > 3 years | K21: Steers < 1 year | L21: Steers 1-2 years | M21: Steers 2-3 years | N21: Steers >3 years
D22: =TEXT('Input - Site'!$E$12, "mmmm yyyy") -> January 2024 | E22: =DAY(EOMONTH($D22,0)) -> 31 | F22: =DAY(EOMONTH($D22,0)) -> 31 | G22: =DAY(EOMONTH($D22,0)) -> 31 | H22: =DAY(EOMONTH($D22,0)) -> 31 | I22: =DAY(EOMONTH($D22,0)) -> 31 | J22: =DAY(EOMONTH($D22,0)) -> 31 | K22: =DAY(EOMONTH($D22,0)) -> 31 | L22: =DAY(EOMONTH($D22,0)) -> 31 | ... N22: =DAY(EOMONTH($D22,0)) -> 31 | O22: Days
D23: =TEXT(EDATE('Input - Site'!$E$12,1), "mmmm yyyy") -> February 2024 | E23: =DAY(EOMONTH($D23,0)) -> 29 | F23: =DAY(EOMONTH($D23,0)) -> 29 | G23: =DAY(EOMONTH($D23,0)) -> 29 | H23: =DAY(EOMONTH($D23,0)) -> 29 | I23: =DAY(EOMONTH($D23,0)) -> 29 | J23: =DAY(EOMONTH($D23,0)) -> 29 | K23: =DAY(EOMONTH($D23,0)) -> 29 | L23: =DAY(EOMONTH($D23,0)) -> 29 | ... N23: =DAY(EOMONTH($D23,0)) -> 29 | O23: Days
D24: =TEXT(EDATE('Input - Site'!$E$12,2), "mmmm yyyy") -> March 2024 | E24: =DAY(EOMONTH($D24,0)) -> 31 | F24: =DAY(EOMONTH($D24,0)) -> 31 | G24: =DAY(EOMONTH($D24,0)) -> 31 | H24: =DAY(EOMONTH($D24,0)) -> 31 | I24: =DAY(EOMONTH($D24,0)) -> 31 | J24: =DAY(EOMONTH($D24,0)) -> 31 | K24: =DAY(EOMONTH($D24,0)) -> 31 | L24: =DAY(EOMONTH($D24,0)) -> 31 | ... N24: =DAY(EOMONTH($D24,0)) -> 31 | O24: Days
D25: =TEXT(EDATE('Input - Site'!$E$12,3), "mmmm yyyy") -> April 2024 | E25: =DAY(EOMONTH($D25,0)) -> 30 | F25: =DAY(EOMONTH($D25,0)) -> 30 | G25: =DAY(EOMONTH($D25,0)) -> 30 | H25: =DAY(EOMONTH($D25,0)) -> 30 | I25: =DAY(EOMONTH($D25,0)) -> 30 | J25: =DAY(EOMONTH($D25,0)) -> 30 | K25: =DAY(EOMONTH($D25,0)) -> 30 | L25: =DAY(EOMONTH($D25,0)) -> 30 | ... N25: =DAY(EOMONTH($D25,0)) -> 30 | O25: Days
D26: =TEXT(EDATE('Input - Site'!$E$12,4), "mmmm yyyy") -> May 2024 | E26: =DAY(EOMONTH($D26,0)) -> 31 | F26: =DAY(EOMONTH($D26,0)) -> 31 | G26: =DAY(EOMONTH($D26,0)) -> 31 | H26: =DAY(EOMONTH($D26,0)) -> 31 | I26: =DAY(EOMONTH($D26,0)) -> 31 | J26: =DAY(EOMONTH($D26,0)) -> 31 | K26: =DAY(EOMONTH($D26,0)) -> 31 | L26: =DAY(EOMONTH($D26,0)) -> 31 | ... N26: =DAY(EOMONTH($D26,0)) -> 31 | O26: Days
D27: =TEXT(EDATE('Input - Site'!$E$12,5), "mmmm yyyy") -> June 2024 | E27: =DAY(EOMONTH($D27,0)) -> 30 | F27: =DAY(EOMONTH($D27,0)) -> 30 | G27: =DAY(EOMONTH($D27,0)) -> 30 | H27: =DAY(EOMONTH($D27,0)) -> 30 | I27: =DAY(EOMONTH($D27,0)) -> 30 | J27: =DAY(EOMONTH($D27,0)) -> 30 | K27: =DAY(EOMONTH($D27,0)) -> 30 | L27: =DAY(EOMONTH($D27,0)) -> 30 | ... N27: =DAY(EOMONTH($D27,0)) -> 30 | O27: Days
D28: =TEXT(EDATE('Input - Site'!$E$12,6), "mmmm yyyy") -> July 2024 | E28: =DAY(EOMONTH($D28,0)) -> 31 | F28: =DAY(EOMONTH($D28,0)) -> 31 | G28: =DAY(EOMONTH($D28,0)) -> 31 | H28: =DAY(EOMONTH($D28,0)) -> 31 | I28: =DAY(EOMONTH($D28,0)) -> 31 | J28: =DAY(EOMONTH($D28,0)) -> 31 | K28: =DAY(EOMONTH($D28,0)) -> 31 | L28: =DAY(EOMONTH($D28,0)) -> 31 | ... N28: =DAY(EOMONTH($D28,0)) -> 31 | O28: Days
D29: =TEXT(EDATE('Input - Site'!$E$12,7), "mmmm yyyy") -> August 2024 | E29: =DAY(EOMONTH($D29,0)) -> 31 | F29: =DAY(EOMONTH($D29,0)) -> 31 | G29: =DAY(EOMONTH($D29,0)) -> 31 | H29: =DAY(EOMONTH($D29,0)) -> 31 | I29: =DAY(EOMONTH($D29,0)) -> 31 | J29: =DAY(EOMONTH($D29,0)) -> 31 | K29: =DAY(EOMONTH($D29,0)) -> 31 | L29: =DAY(EOMONTH($D29,0)) -> 31 | ... N29: =DAY(EOMONTH($D29,0)) -> 31 | O29: Days
D30: =TEXT(EDATE('Input - Site'!$E$12,8), "mmmm yyyy") -> September 2024 | E30: =DAY(EOMONTH($D30,0)) -> 30 | F30: =DAY(EOMONTH($D30,0)) -> 30 | G30: =DAY(EOMONTH($D30,0)) -> 30 | H30: =DAY(EOMONTH($D30,0)) -> 30 | I30: =DAY(EOMONTH($D30,0)) -> 30 | J30: =DAY(EOMONTH($D30,0)) -> 30 | K30: =DAY(EOMONTH($D30,0)) -> 30 | L30: =DAY(EOMONTH($D30,0)) -> 30 | ... N30: =DAY(EOMONTH($D30,0)) -> 30 | O30: Days
D31: =TEXT(EDATE('Input - Site'!$E$12,9), "mmmm yyyy") -> October 2024 | E31: =DAY(EOMONTH($D31,0)) -> 31 | F31: =DAY(EOMONTH($D31,0)) -> 31 | G31: =DAY(EOMONTH($D31,0)) -> 31 | H31: =DAY(EOMONTH($D31,0)) -> 31 | I31: =DAY(EOMONTH($D31,0)) -> 31 | J31: =DAY(EOMONTH($D31,0)) -> 31 | K31: =DAY(EOMONTH($D31,0)) -> 31 | L31: =DAY(EOMONTH($D31,0)) -> 31 | ... N31: =DAY(EOMONTH($D31,0)) -> 31 | O31: Days
D32: =TEXT(EDATE('Input - Site'!$E$12,10), "mmmm yyyy") -> November 2024 | E32: =DAY(EOMONTH($D32,0)) -> 30 | F32: =DAY(EOMONTH($D32,0)) -> 30 | G32: =DAY(EOMONTH($D32,0)) -> 30 | H32: =DAY(EOMONTH($D32,0)) -> 30 | I32: =DAY(EOMONTH($D32,0)) -> 30 | J32: =DAY(EOMONTH($D32,0)) -> 30 | K32: =DAY(EOMONTH($D32,0)) -> 30 | L32: =DAY(EOMONTH($D32,0)) -> 30 | ... N32: =DAY(EOMONTH($D32,0)) -> 30 | O32: Days
D33: =TEXT(EDATE('Input - Site'!$E$12,11), "mmmm yyyy") -> December 2024 | E33: =DAY(EOMONTH($D33,0)) -> 31 | F33: =DAY(EOMONTH($D33,0)) -> 31 | G33: =DAY(EOMONTH($D33,0)) -> 31 | H33: =DAY(EOMONTH($D33,0)) -> 31 | I33: =DAY(EOMONTH($D33,0)) -> 31 | J33: =DAY(EOMONTH($D33,0)) -> 31 | K33: =DAY(EOMONTH($D33,0)) -> 31 | L33: =DAY(EOMONTH($D33,0)) -> 31 | ... N33: =DAY(EOMONTH($D33,0)) -> 31 | O33: Days
D36: Head
D37: Method 1 values | E37: Bulls < 1 year | F37: Bulls > 1 year | G37: Cows < 1 year | H37: Cows 1-2 years | I37: Cows 2-3 years | J37: Cows > 3 years | K37: Steers < 1 year | L37: Steers 1-2 years | M37: Steers 2-3 years | N37: Steers >3 years
D38: Spring | E38: 100 | F38: 100 | G38: 100 | H38: 100 | I38: 100 | J38: 100 | K38: 100 | L38: 100 | M38: 100 | N38: 100 | O38: Head
D39: Summer | E39: 100 | F39: 100 | G39: 100 | H39: 100 | I39: 100 | J39: 100 | K39: 100 | L39: 100 | M39: 100 | N39: 100 | O39: Head
D40: Autumn | E40: 200 | F40: 100 | G40: 200 | H40: 100 | I40: 100 | J40: 100 | K40: 200 | L40: 100 | M40: 100 | N40: 100 | O40: Head
D41: Winter | E41: 250 | F41: 100 | G41: 250 | H41: 100 | I41: 100 | J41: 100 | K41: 250 | L41: 100 | M41: 100 | N41: 100 | O41: Head
D43: Method 2 values | E43: Bulls < 1 year | F43: Bulls > 1 year | G43: Cows < 1 year | H43: Cows 1-2 years | I43: Cows 2-3 years | J43: Cows > 3 years | K43: Steers < 1 year | L43: Steers 1-2 years | M43: Steers 2-3 years | N43: Steers >3 years
D44: =TEXT('Input - Site'!$E$12, "mmmm yyyy") -> January 2024 | E44: 100 | F44: 100 | G44: 100 | H44: 100 | I44: 100 | J44: 100 | K44: 100 | L44: 100 | M44: 100 | N44: 100 | O44: Head
...

Sheet 4.2.1.1-2 Methane
A1: #VALUE! | C1: 4.2.1.1-2 Manure Methane
A3: =HYPERLINK("#'Home'!A1", "Home") -> Home | D3: Method 1 | W3: Method 2
A4: =HYPERLINK("#'Results'!A1", "Results") -> Results
D5: {=EntericMethane_PastureBeef_Equations.VEERG_3_2_1_1__4_AdditionalIntakeForMilkProduction_Title()} -> Additional intake for milk production in the season of calving and the season after calving
A6: INPUTS | D6: {=EntericMethane_PastureBeef_Equations.VEERG_3_2_1_1__4_AdditionalIntakeForMilkProduction_Source()} -> VEERG 2026: 3.2.1.1, Equation (4)
A7: =HYPERLINK("#'Input - Site'!A1", "Site") -> Site | D7: Function name | E7: EntericMethane_PastureBeef_Equations.VEERG_3_2_1_1__4_AdditionalIntakeForMilkProduction
A8: =HYPERLINK("#'Input - Pasture Beef'!A1", "Pasture Beef") -> Pasture Beef
A10: CALCULATIONS | D10: Variable | E10: {=EntericMethane_PastureBeef_Equations.VEERG_3_2_1_1__4_AdditionalIntakeForMilkProduction_Variable()} -> MA_jk45
A11: =HYPERLINK("#'4.2.1.1-2 Methane'!A1", "4.2.1.1-2 Methane") -> 4.2.1.1-2 Methane | D11: Unit | E11: {=EntericMethane_PastureBeef_Equations.VEERG_3_2_1_1__4_AdditionalIntakeForMilkProduction_Unit()} -> fraction
A12: =HYPERLINK("#'4.2.1.3-4 Soil direct N2O'!A1", "4.2.1.3-4 Soil direct N2O") -> 4.2.1.3-4 Soil direct N2O
A13: =HYPERLINK("#'4.2.1.5-6 Soil Atmos Dep'!A1", "4.2.1.5-6 Soil atm. deposition") -> 4.2.1.5-6 Soil atm. deposition | D13: {=_xlfn.CHOOSECOLS(EntericMethane_PastureBeef_Equations.VEERG_3_2_1_1__4_AdditionalIntakeForMilkProduction_ArgumentsVariation(), 1, 2)} -> LC_jk45 | E13: proportion of cows greater than 1 year in calf in the season of calving expressed as a fraction | H13: {=_xlfn.CHOOSECOLS(EntericMethane_PastureBeef_Equations.VEERG_3_2_1_1__4_AdditionalIntakeForMilkProduction_ArgumentsVariation(), 3,4)} -> fraction | I13: Input | J13: {=HYPERLINK(Common_InputFunctions.Utility_SourceHyperlink($D$19), $D$19)} -> M1_Table_LC_j_k-4-5
A14: =HYPERLINK("#'4.2.1.7-8 Soil leach runoff'!A1", "4.2.1.7-8 Soil leach & runoff") -> 4.2.1.7-8 Soil leach & runoff | D14: FA_jk45calv | E14: feed adjustment value for lactating cows in the season of calving expressed as a fraction | H14: fraction | I14: Constant | J14: {=_xlfn.XLOOKUP(1, (Table_SourceData_PastureBeef_FeedIntakeAdjustment_Variation[Breed]=$J$16)*(Table_SourceData_PastureBeef_FeedIntakeAdjustment_Variation[Season]=+"Calving season"),Table_SourceData_PastureBeef_FeedIntakeAdjustment_Variation[Feed adjustment])} -> 1.3
D15: FA_jk45after | E15: feed adjustment value for lactating cows in the season immediately after calving expressed as a fraction | H15: fraction | I15: Constant | J15: {=_xlfn.XLOOKUP(1, (Table_SourceData_PastureBeef_FeedIntakeAdjustment_Variation[Breed]=$J$16)*(Table_SourceData_PastureBeef_FeedIntakeAdjustment_Variation[Season]=+"Season after calving"),Table_SourceData_PastureBeef_FeedIntakeAdjustment_Variation[Feed adjustment])} -> 1.1
A16: APPENDICES | D16: b | E16: breed of cattle | I16: Input | J16: ='Input - Pasture Beef'!$E$9 -> Hereford or Shorthorn breeds
A17: =HYPERLINK("#'Constants - Pasture Beef'!A1", "Constants - Pasture Beef") -> Constants - Pasture Beef
A18: =HYPERLINK("#'Constants - Livestock'!A1", "Constants - Livestock") -> Constants - Livestock
A19: =HYPERLINK("#'Constants - Common'!A1", "Constants - Common") -> Constants - Common | D19: M1_Table_LC_j_k-4-5 | W19: M2_Table_LC_j_k-4-5
A20: =HYPERLINK("#'Acknowledgements'!A1", "Acknowledgements") -> Acknowledgements | D20: Proportion of cows in calf during season (Method 1) | W20: Proportion of cows in calf during season (Method 2)
D21: Season | E21: Calving season | F21: Cows 1-2 years | G21: Cows 2-3 years | H21: Cows > 3 years | W21: Month | X21: Cows 1-2 years | Y21: Cows 2-3 years | Z21: Cows > 3 years
D22: Spring | E22: ='Input - Pasture Beef'!$E111 -> Yes | F22: ='Input - Pasture Beef'!$F111 -> 0.1 | G22: ='Input - Pasture Beef'!$G111 -> 0.4 | H22: ='Input - Pasture Beef'!$H111 -> 0.4 | I22: Fraction | W22: =TEXT(EDATE('Input - Pasture Beef'!$D$124,0), "mmmm") & ", " & TEXT(EDATE('Input - Pasture Beef'!$D$125,0), "mmmm") & ", " & TEXT(EDATE('Input - Pasture Beef'!$D$126,0), "mmmm") -> August, September, October | X22: ='Input - Pasture Beef'!$E$127 -> 0.75 | Y22: ='Input - Pasture Beef'!$F$127 -> 0.75 | Z22: ='Input - Pasture Beef'!$G$127 -> 0.75 | AA22: Fraction
D23: Summer | E23: ='Input - Pasture Beef'!$E112 -> Yes | F23: ='Input - Pasture Beef'!$F112 -> 0.1 | G23: ='Input - Pasture Beef'!$G112 -> 0 | H23: ='Input - Pasture Beef'!$H112 -> 0 | W23: =TEXT(EDATE('Input - Pasture Beef'!$D$126,1), "mmmm") & ", " & TEXT(EDATE('Input - Pasture Beef'!$D$126,2), "mmmm") & ", " & TEXT(EDATE('Input - Pasture Beef'!$D$126,3), "mmmm") -> November, December, January
D24: Autumn | E24: ='Input - Pasture Beef'!$E113 -> No | F24: ='Input - Pasture Beef'!$F113 -> 0 | G24: ='Input - Pasture Beef'!$G113 -> 0 | H24: ='Input - Pasture Beef'!$H113 -> 0
D25: Winter | E25: ='Input - Pasture Beef'!$E111 -> Yes | F25: ='Input - Pasture Beef'!$F$110 -> 0.7 | G25: ='Input - Pasture Beef'!$G$110 -> 0.5 | H25: ='Input - Pasture Beef'!$H$110 -> 0.5 | W25: M2_Table_MA_j_k-4-5
W26: Additional intake for milk production in calving and post-calving seasons (Method 2)
D27: M1_Table_MA_j_k-4-5 | W27: Month | X27: Calving season | Y27: FAjk=4,5 | Z27: Bulls < 1 year | AA27: Bulls > 1 year | AB27: Cows < 1 year | AC27: Cows 1-2 years | AD27: Cows 2-3 years | AE27: Cows > 3 years | AF27: Steers < 1 year | AG27: Steers 1-2 years | AH27: Steers 2-3 years
D28: Additional intake for milk production in calving and post-calving seasons (Method 1) | W28: =TEXT('Input - Site'!$E$12,"mmmm") -> January | X28: {=IFERROR(_xlfn.IFS(SUMPRODUCT(ISNUMBER(SEARCH(TRIM(_xlfn.TEXTSPLIT($W$22,",")),W28))*1)>0,"Calving season",SUMPRODUCT(ISNUMBER(SEARCH(TRIM(_xlfn.TEXTSPLIT($W$23,",")),W28))*1)>0,"Season after calving"), "")} -> Season after calving | Y28: {=_xlfn.IFS(X28="Calving season", $J$14, X28="Season after calving", $J$15, X28="", "")} -> 1.1 | Z28: 1 | AA28: 1 | AB28: 1 | AC28: {=IFERROR(EntericMethane_PastureBeef_Equations.VEERG_3_2_1_1__4_AdditionalIntakeForMilkProduction(X$22,$Y28), 1)} -> 1.075 | AD28: {=IFERROR(EntericMethane_PastureBeef_Equations.VEERG_3_2_1_1__4_AdditionalIntakeForMilkProduction(Y$22,$Y28), 1)} -> 1.075 | AE28: {=IFERROR(EntericMethane_PastureBeef_Equations.VEERG_3_2_1_1__4_AdditionalIntakeForMilkProduction(Z$22,$Y28), 1)} -> 1.075 | AF28: 1 | AG28: 1 | AH28: 1
D29: Season | E29: Calving season | F29: Season after calving | G29: FAjk=4,5 | H29: FAjk=4,5 | I29: Bulls < 1 year | J29: Bulls > 1 year | K29: Cows < 1 year | L29: Cows 1-2 years | M29: Cows 2-3 years | N29: Cows > 3 years | O29: Steers < 1 year | P29: Steers 1-2 years | Q29: Steers 2-3 years | R29: Steers >3 years | W29: =TEXT(EDATE('Input - Site'!$E$12,1), "mmmm") -> February | X29: {=IFERROR(_xlfn.IFS(SUMPRODUCT(ISNUMBER(SEARCH(TRIM(_xlfn.TEXTSPLIT($W$22,",")),W29))*1)>0,"Calving season",SUMPRODUCT(ISNUMBER(SEARCH(TRIM(_xlfn.TEXTSPLIT($W$23,",")),W29))*1)>0,"Season after calving"), "")} | Y29: {=_xlfn.IFS(X29="Calving season", $J$14, X29="Season after calving", $J$15, X29="", "")} | Z29: 1 | AA29: 1 | AB29: 1 | AC29: {=IFERROR(EntericMethane_PastureBeef_Equations.VEERG_3_2_1_1__4_AdditionalIntakeForMilkProduction(X$22,$Y29), 1)} -> 1 | AD29: {=IFERROR(EntericMethane_PastureBeef_Equations.VEERG_3_2_1_1__4_AdditionalIntakeForMilkProduction(Y$22,$Y29), 1)} -> 1 | AE29: {=IFERROR(EntericMethane_PastureBeef_Equations.VEERG_3_2_1_1__4_AdditionalIntakeForMilkProduction(Z$22,$Y29), 1)} -> 1 | AF29: 1 | AG29: 1 | AH29: 1 | AI29: Steers >3 years
D30: Spring | E30: =IF('Input - Pasture Beef'!E111="Yes", "Calving season", "") -> Calving season | F30: =IF('Input - Pasture Beef'!E110="Yes", "Season after calving","") -> Season after calving | G30: =IF(E30="Calving season", $J$14, 1) -> 1.3 | H30: =IF(F30="Season after calving", $J$15, 1) -> 1.1 | I30: 1 | J30: 1 | K30: 1 | L30: {=EntericMethane_PastureBeef_Equations.VEERG_3_2_1_1__4_AdditionalIntakeForMilkProductionVariation(F22,F25,$G30,$H30)} -> 1.1 | M30: {=EntericMethane_PastureBeef_Equations.VEERG_3_2_1_1__4_AdditionalIntakeForMilkProductionVariation(G22,G25,$G30,$H30)} -> 1.17 | N30: {=EntericMethane_PastureBeef_Equations.VEERG_3_2_1_1__4_AdditionalIntakeForMilkProductionVariation(H22,H25,$G30,$H30)} -> 1.17 | O30: 1 | P30: 1 | Q30: 1 | R30: 1 | S30: =$E$11 -> fraction | W30: =TEXT(EDATE('Input - Site'!$E$12,2), "mmmm") -> March | X30: {=IFERROR(_xlfn.IFS(SUMPRODUCT(ISNUMBER(SEARCH(TRIM(_xlfn.TEXTSPLIT($W$22,",")),W30))*1)>0,"Calving season",SUMPRODUCT(ISNUMBER(SEARCH(TRIM(_xlfn.TEXTSPLIT($W$23,",")),W30))*1)>0,"Season after calving"), "")} | Y30: {=_xlfn.IFS(X30="Calving season", $J$14, X30="Season after calving", $J$15, X30="", "")} | Z30: 1 | AA30: 1 | AB30: 1 | AC30: {=IFERROR(EntericMethane_PastureBeef_Equations.VEERG_3_2_1_1__4_AdditionalIntakeForMilkProduction(X$22,$Y30), 1)} -> 1 | AD30: {=IFERROR(EntericMethane_PastureBeef_Equations.VEERG_3_2_1_1__4_AdditionalIntakeForMilkProduction(Y$22,$Y30), 1)} -> 1 | AE30: {=IFERROR(EntericMethane_PastureBeef_Equations.VEERG_3_2_1_1__4_AdditionalIntakeForMilkProduction(Z$22,$Y30), 1)} -> 1 | AF30: 1 | AG30: 1 | AH30: 1 | AI30: 1 | AJ30: =$E$11 -> fraction
D31: Summer | E31: =IF('Input - Pasture Beef'!E112="Yes", "Calving season", "") -> Calving season | F31: =IF('Input - Pasture Beef'!E111="Yes", "Season after calving","") -> Season after calving | G31: =IF(E31="Calving season", $J$14, 1) -> 1.3 | H31: =IF(F31="Season after calving", $J$15, 1) -> 1.1 | I31: 1 | J31: 1 | K31: 1 | L31: {=EntericMethane_PastureBeef_Equations.VEERG_3_2_1_1__4_AdditionalIntakeForMilkProductionVariation(F23,F22,$G31,$H31)} -> 1.04 | M31: {=EntericMethane_PastureBeef_Equations.VEERG_3_2_1_1__4_AdditionalIntakeForMilkProductionVariation(G23,G22,$G31,$H31)} -> 1.04 | N31: {=EntericMethane_PastureBeef_Equations.VEERG_3_2_1_1__4_AdditionalIntakeForMilkProductionVariation(H23,H22,$G31,$H31)} -> 1.04 | O31: 1 | P31: 1 | Q31: 1 | R31: 1 | S31: =$E$11 -> fraction | W31: =TEXT(EDATE('Input - Site'!$E$12,3), "mmmm") -> April | X31: {=IFERROR(_xlfn.IFS(SUMPRODUCT(ISNUMBER(SEARCH(TRIM(_xlfn.TEXTSPLIT($W$22,",")),W31))*1)>0,"Calving season",SUMPRODUCT(ISNUMBER(SEARCH(TRIM(_xlfn.TEXTSPLIT($W$23,",")),W31))*1)>0,"Season after calving"), "")} | Y31: {=_xlfn.IFS(X31="Calving season", $J$14, X31="Season after calving", $J$15, X31="", "")} | Z31: 1 | AA31: 1 | AB31: 1 | AC31: {=IFERROR(EntericMethane_PastureBeef_Equations.VEERG_3_2_1_1__4_AdditionalIntakeForMilkProduction(X$22,$Y31), 1)} -> 1 | AD31: {=IFERROR(EntericMethane_PastureBeef_Equations.VEERG_3_2_1_1__4_AdditionalIntakeForMilkProduction(Y$22,$Y31), 1)} -> 1 | AE31: {=IFERROR(EntericMethane_PastureBeef_Equations.VEERG_3_2_1_1__4_AdditionalIntakeForMilkProduction(Z$22,$Y31), 1)} -> 1 | AF31: 1 | AG31: 1 | AH31: 1 | AI31: 1 | AJ31: =$E$11 -> fraction
D32: Autumn | E32: =IF('Input - Pasture Beef'!E113="Yes", "Calving season", "") | F32: =IF('Input - Pasture Beef'!E112="Yes", "Season after calving","") -> Season after calving | G32: =IF(E32="Calving season", $J$14, 1) -> 1 | H32: =IF(F32="Season after calving", $J$15, 1) -> 1.1 | I32: 1 | J32: 1 | K32: 1 | L32: {=EntericMethane_PastureBeef_Equations.VEERG_3_2_1_1__4_AdditionalIntakeForMilkProductionVariation(F24,F23,$G32,$H32)} -> 1.01 | M32: {=EntericMethane_PastureBeef_Equations.VEERG_3_2_1_1__4_AdditionalIntakeForMilkProductionVariation(G24,G23,$G32,$H32)} -> 1 | N32: {=EntericMethane_PastureBeef_Equations.VEERG_3_2_1_1__4_AdditionalIntakeForMilkProductionVariation(H24,H23,$G32,$H32)} -> 1 | O32: 1 | P32: 1 | Q32: 1 | R32: 1 | S32: =$E$11 -> fraction | W32: =TEXT(EDATE('Input - Site'!$E$12,4), "mmmm") -> May | X32: {=IFERROR(_xlfn.IFS(SUMPRODUCT(ISNUMBER(SEARCH(TRIM(_xlfn.TEXTSPLIT($W$22,",")),W32))*1)>0,"Calving season",SUMPRODUCT(ISNUMBER(SEARCH(TRIM(_xlfn.TEXTSPLIT($W$23,",")),W32))*1)>0,"Season after calving"), "")} | Y32: {=_xlfn.IFS(X32="Calving season", $J$14, X32="Season after calving", $J$15, X32="", "")} | Z32: 1 | AA32: 1 | AB32: 1 | AC32: {=IFERROR(EntericMethane_PastureBeef_Equations.VEERG_3_2_1_1__4_AdditionalIntakeForMilkProduction(X$22,$Y32), 1)} -> 1 | AD32: {=IFERROR(EntericMethane_PastureBeef_Equations.VEERG_3_2_1_1__4_AdditionalIntakeForMilkProduction(Y$22,$Y32), 1)} -> 1 | AE32: {=IFERROR(EntericMethane_PastureBeef_Equations.VEERG_3_2_1_1__4_AdditionalIntakeForMilkProduction(Z$22,$Y32), 1)} -> 1 | AF32: 1 | AG32: 1 | AH32: 1 | AI32: 1 | AJ32: =$E$11 -> fraction
D33: Winter | E33: =IF('Input - Pasture Beef'!E110="Yes", "Calving season", "") -> Calving season | F33: =IF('Input - Pasture Beef'!E113="Yes", "Season after calving","") | G33: =IF(E33="Calving season", $J$14, 1) -> 1.3 | H33: =IF(F33="Season after calving", $J$15, 1) -> 1 | I33: 1 | J33: 1 | K33: 1 | L33: {=EntericMethane_PastureBeef_Equations.VEERG_3_2_1_1__4_AdditionalIntakeForMilkProductionVariation(F25,F24,$G33,$H33)} -> 1.21 | M33: {=EntericMethane_PastureBeef_Equations.VEERG_3_2_1_1__4_AdditionalIntakeForMilkProductionVariation(G25,G24,$G33,$H33)} -> 1.15 | N33: {=EntericMethane_PastureBeef_Equations.VEERG_3_2_1_1__4_AdditionalIntakeForMilkProductionVariation(H25,H24,$G33,$H33)} -> 1.15 | O33: 1 | P33: 1 | Q33: 1 | R33: 1 | S33: =$E$11 -> fraction | W33: =TEXT(EDATE('Input - Site'!$E$12,5), "mmmm") -> June | X33: {=IFERROR(_xlfn.IFS(SUMPRODUCT(ISNUMBER(SEARCH(TRIM(_xlfn.TEXTSPLIT($W$22,",")),W33))*1)>0,"Calving season",SUMPRODUCT(ISNUMBER(SEARCH(TRIM(_xlfn.TEXTSPLIT($W$23,",")),W33))*1)>0,"Season after calving"), "")} | Y33: {=_xlfn.IFS(X33="Calving season", $J$14, X33="Season after calving", $J$15, X33="", "")} | Z33: 1 | AA33: 1 | AB33: 1 | AC33: {=IFERROR(EntericMethane_PastureBeef_Equations.VEERG_3_2_1_1__4_AdditionalIntakeForMilkProduction(X$22,$Y33), 1)} -> 1 | AD33: {=IFERROR(EntericMethane_PastureBeef_Equations.VEERG_3_2_1_1__4_AdditionalIntakeForMilkProduction(Y$22,$Y33), 1)} -> 1 | AE33: {=IFERROR(EntericMethane_PastureBeef_Equations.VEERG_3_2_1_1__4_AdditionalIntakeForMilkProduction(Z$22,$Y33), 1)} -> 1 | AF33: 1 | AG33: 1 | AH33: 1 | AI33: 1 | AJ33: =$E$11 -> fraction
W34: =TEXT(EDATE('Input - Site'!$E$12,6), "mmmm") -> July | X34: {=IFERROR(_xlfn.IFS(SUMPRODUCT(ISNUMBER(SEARCH(TRIM(_xlfn.TEXTSPLIT($W$22,",")),W34))*1)>0,"Calving season",SUMPRODUCT(ISNUMBER(SEARCH(TRIM(_xlfn.TEXTSPLIT($W$23,",")),W34))*1)>0,"Season after calving"), "")} | Y34: {=_xlfn.IFS(X34="Calving season", $J$14, X34="Season after calving", $J$15, X34="", "")} | Z34: 1 | AA34: 1 | AB34: 1 | AC34: {=IFERROR(EntericMethane_PastureBeef_Equations.VEERG_3_2_1_1__4_AdditionalIntakeForMilkProduction(X$22,$Y34), 1)} -> 1 | AD34: {=IFERROR(EntericMethane_PastureBeef_Equations.VEERG_3_2_1_1__4_AdditionalIntakeForMilkProduction(Y$22,$Y34), 1)} -> 1 | AE34: {=IFERROR(EntericMethane_PastureBeef_Equations.VEERG_3_2_1_1__4_AdditionalIntakeForMilkProduction(Z$22,$Y34), 1)} -> 1 | AF34: 1 | AG34: 1 | AH34: 1 | AI34: 1 | AJ34: =$E$11 -> fraction
W35: =TEXT(EDATE('Input - Site'!$E$12,7), "mmmm") -> August | X35: {=IFERROR(_xlfn.IFS(SUMPRODUCT(ISNUMBER(SEARCH(TRIM(_xlfn.TEXTSPLIT($W$22,",")),W35))*1)>0,"Calving season",SUMPRODUCT(ISNUMBER(SEARCH(TRIM(_xlfn.TEXTSPLIT($W$23,",")),W35))*1)>0,"Season after calving"), "")} -> Calving season | Y35: {=_xlfn.IFS(X35="Calving season", $J$14, X35="Season after calving", $J$15, X35="", "")} -> 1.3 | Z35: 1 | AA35: 1 | AB35: 1 | AC35: {=IFERROR(EntericMethane_PastureBeef_Equations.VEERG_3_2_1_1__4_AdditionalIntakeForMilkProduction(X$22,$Y35), 1)} -> 1.225 | AD35: {=IFERROR(EntericMethane_PastureBeef_Equations.VEERG_3_2_1_1__4_AdditionalIntakeForMilkProduction(Y$22,$Y35), 1)} -> 1.225 | AE35: {=IFERROR(EntericMethane_PastureBeef_Equations.VEERG_3_2_1_1__4_AdditionalIntakeForMilkProduction(Z$22,$Y35), 1)} -> 1.225 | AF35: 1 | AG35: 1 | AH35: 1 | AI35: 1 | AJ35: =$E$11 -> fraction
W36: =TEXT(EDATE('Input - Site'!$E$12,8), "mmmm") -> September | X36: {=IFERROR(_xlfn.IFS(SUMPRODUCT(ISNUMBER(SEARCH(TRIM(_xlfn.TEXTSPLIT($W$22,",")),W36))*1)>0,"Calving season",SUMPRODUCT(ISNUMBER(SEARCH(TRIM(_xlfn.TEXTSPLIT($W$23,",")),W36))*1)>0,"Season after calving"), "")} -> Calving season | Y36: {=_xlfn.IFS(X36="Calving season", $J$14, X36="Season after calving", $J$15, X36="", "")} -> 1.3 | Z36: 1 | AA36: 1 | AB36: 1 | AC36: {=IFERROR(EntericMethane_PastureBeef_Equations.VEERG_3_2_1_1__4_AdditionalIntakeForMilkProduction(X$22,$Y36), 1)} -> 1.225 | AD36: {=IFERROR(EntericMethane_PastureBeef_Equations.VEERG_3_2_1_1__4_AdditionalIntakeForMilkProduction(Y$22,$Y36), 1)} -> 1.225 | AE36: {=IFERROR(EntericMethane_PastureBeef_Equations.VEERG_3_2_1_1__4_AdditionalIntakeForMilkProduction(Z$22,$Y36), 1)} -> 1.225 | AF36: 1 | AG36: 1 | AH36: 1 | AI36: 1 | AJ36: =$E$11 -> fraction
D37: {=EntericMethane_PastureBeef_Equations.VEERG_3_2_1_1__3_FeedIntakeForGrazingBeef_Title()} -> Feed intake for grazing beef cattle | W37: =TEXT(EDATE('Input - Site'!$E$12,9), "mmmm") -> October | X37: {=IFERROR(_xlfn.IFS(SUMPRODUCT(ISNUMBER(SEARCH(TRIM(_xlfn.TEXTSPLIT($W$22,",")),W37))*1)>0,"Calving season",SUMPRODUCT(ISNUMBER(SEARCH(TRIM(_xlfn.TEXTSPLIT($W$23,",")),W37))*1)>0,"Season after calving"), "")} -> Calving season | Y37: {=_xlfn.IFS(X37="Calving season", $J$14, X37="Season after calving", $J$15, X37="", "")} -> 1.3 | Z37: 1 | AA37: 1 | AB37: 1 | AC37: {=IFERROR(EntericMethane_PastureBeef_Equations.VEERG_3_2_1_1__4_AdditionalIntakeForMilkProduction(X$22,$Y37), 1)} -> 1.225 | AD37: {=IFERROR(EntericMethane_PastureBeef_Equations.VEERG_3_2_1_1__4_AdditionalIntakeForMilkProduction(Y$22,$Y37), 1)} -> 1.225 | AE37: {=IFERROR(EntericMethane_PastureBeef_Equations.VEERG_3_2_1_1__4_AdditionalIntakeForMilkProduction(Z$22,$Y37), 1)} -> 1.225 | AF37: 1 | AG37: 1 | AH37: 1 | AI37: 1 | AJ37: =$E$11 -> fraction
D38: {=EntericMethane_PastureBeef_Equations.VEERG_3_2_1_1__3_FeedIntakeForGrazingBeef_Source()} -> VEERG 2026: 3.2.1.1, Equation (3) | K38: Cows < 3 months | L38: Cows 3-6 months | M38: Cows 6 months-1 year | W38: =TEXT(EDATE('Input - Site'!$E$12,10), "mmmm") -> November | X38: {=IFERROR(_xlfn.IFS(SUMPRODUCT(ISNUMBER(SEARCH(TRIM(_xlfn.TEXTSPLIT($W$22,",")),W38))*1)>0,"Calving season",SUMPRODUCT(ISNUMBER(SEARCH(TRIM(_xlfn.TEXTSPLIT($W$23,",")),W38))*1)>0,"Season after calving"), "")} -> Season after calving | Y38: {=_xlfn.IFS(X38="Calving season", $J$14, X38="Season after calving", $J$15, X38="", "")} -> 1.1 | Z38: 1 | AA38: 1 | AB38: 1 | AC38: {=IFERROR(EntericMethane_PastureBeef_Equations.VEERG_3_2_1_1__4_AdditionalIntakeForMilkProduction(X$22,$Y38), 1)} -> 1.075 | AD38: {=IFERROR(EntericMethane_PastureBeef_Equations.VEERG_3_2_1_1__4_AdditionalIntakeForMilkProduction(Y$22,$Y38), 1)} -> 1.075 | AE38: {=IFERROR(EntericMethane_PastureBeef_Equations.VEERG_3_2_1_1__4_AdditionalIntakeForMilkProduction(Z$22,$Y38), 1)} -> 1.075 | AF38: 1 | AG38: 1 | AH38: 1 | AI38: 1 | AJ38: =$E$11 -> fraction
D39: Function name | E39: {=Common_InputFunctions.Utility_DisplayFunctionName($E$84)} -> =EntericMethane_PastureBeef_Equations.VEERG_3_2_1_1__3_FeedIntakeForGrazingBeef | W39: =TEXT(EDATE('Input - Site'!$E$12,11), "mmmm") -> December | X39: {=IFERROR(_xlfn.IFS(SUMPRODUCT(ISNUMBER(SEARCH(TRIM(_xlfn.TEXTSPLIT($W$22,",")),W39))*1)>0,"Calving season",SUMPRODUCT(ISNUMBER(SEARCH(TRIM(_xlfn.TEXTSPLIT($W$23,",")),W39))*1)>0,"Season after calving"), "")} -> Season after calving | Y39: {=_xlfn.IFS(X39="Calving season", $J$14, X39="Season after calving", $J$15, X39="", "")} -> 1.1 | Z39: 1 | AA39: 1 | AB39: 1 | AC39: {=IFERROR(EntericMethane_PastureBeef_Equations.VEERG_3_2_1_1__4_AdditionalIntakeForMilkProduction(X$22,$Y39), 1)} -> 1.075 | AD39: {=IFERROR(EntericMethane_PastureBeef_Equations.VEERG_3_2_1_1__4_AdditionalIntakeForMilkProduction(Y$22,$Y39), 1)} -> 1.075 | AE39: {=IFERROR(EntericMethane_PastureBeef_Equations.VEERG_3_2_1_1__4_AdditionalIntakeForMilkProduction(Z$22,$Y39), 1)} -> 1.075 | AF39: 1 | AG39: 1 | AH39: 1 | AI39: 1 | AJ39: =$E$11 -> fraction
AI40: 1 | AJ40: =$E$11 -> fraction
W41: M2_Table_W_j_k_l | AI41: 1 | AJ41: =$E$11 -> fraction
D42: Variable | E42: {=EntericMethane_PastureBeef_Equations.VEERG_3_2_1_1__3_FeedIntakeForGrazingBeef_Variable()} -> I_jkl | W42: Liveweight (Method 2)
...

Sheet 4.2.1.3-4 Soil direct N20
A1: #VALUE! | C1: 4.2.1.3-4 Manure Direct N2O
A3: =HYPERLINK("#'Home'!A1", "Home") -> Home | D3: Method 1 | U3: Method 2
A4: =HYPERLINK("#'Results'!A1", "Results") -> Results
D5: {=MMS_PastureBeef_Soil_N2ODirect_Equations.VEERG_4_2_1_3__7_RelativeSize_Title()} -> Relative size of the cattle
A6: INPUTS | D6: {=MMS_PastureBeef_Soil_N2ODirect_Equations.VEERG_4_2_1_3__7_RelativeSize_Source()} -> VEERG 2026: 4.2.1.3, Equation (7)
A7: =HYPERLINK("#'Input - Site'!A1", "Site") -> Site | D7: Function name | E7: {=Common_InputFunctions.Utility_DisplayFunctionName(E33)} -> =MMS_PastureBeef_Soil_N2ODirect_Equations.VEERG_4_2_1_3__7_RelativeSize
A8: =HYPERLINK("#'Input - Pasture Beef'!A1", "Pasture Beef") -> Pasture Beef
A10: CALCULATIONS | D10: Variable | E10: {=MMS_PastureBeef_Soil_N2ODirect_Equations.VEERG_4_2_1_3__7_RelativeSize_Variable()} -> Z_jkl
A11: =HYPERLINK("#'4.2.1.1-2 Methane'!A1", "4.2.1.1-2 Methane") -> 4.2.1.1-2 Methane | D11: Unit | E11: {=MMS_PastureBeef_Soil_N2ODirect_Equations.VEERG_4_2_1_3__7_RelativeSize_Unit()} -> ratio
A12: =HYPERLINK("#'4.2.1.3-4 Soil direct N2O'!A1", "4.2.1.3-4 Soil direct N2O") -> 4.2.1.3-4 Soil direct N2O
A13: =HYPERLINK("#'4.2.1.5-6 Soil Atmos Dep'!A1", "4.2.1.5-6 Soil atm. deposition") -> 4.2.1.5-6 Soil atm. deposition | D13: {=MMS_PastureBeef_Soil_N2ODirect_Equations.VEERG_4_2_1_3__7_RelativeSize_Arguments()} -> W_jkl | E13: liveweight (kg) | F13: ="See " & D17 -> See M1_Table_W_j_k_l
A14: =HYPERLINK("#'4.2.1.7-8 Soil leach runoff'!A1", "4.2.1.7-8 Soil leach & runoff") -> 4.2.1.7-8 Soil leach & runoff | D14: SRW_k | E14: standard reference weight (kg) | F14: ="See " & D25 -> See Table_SRW_k
D15: i | E15: state | F15: ='Input - Pasture Beef'!$E$7 -> Western Australia
A16: APPENDICES
A17: =HYPERLINK("#'Constants - Pasture Beef'!A1", "Constants - Pasture Beef") -> Constants - Pasture Beef | D17: M1_Table_W_j_k_l | U17: M2_Table_LW_j_k_l
A18: =HYPERLINK("#'Constants - Livestock'!A1", "Constants - Livestock") -> Constants - Livestock | D18: Liveweight (Method 1) | U18: Liveweight (Method 2)
A19: =HYPERLINK("#'Constants - Common'!A1", "Constants - Common") -> Constants - Common | D19: Season | E19: Bulls < 1 year | F19: Bulls > 1 year | G19: Cows < 1 year | H19: Cows 1-2 years | I19: Cows 2-3 years | J19: Cows > 3 years | K19: Steers < 1 year | L19: Steers 1-2 years | M19: Steers 2-3 years | N19: Steers >3 years | U19: Month | V19: Bulls < 1 year | W19: Bulls > 1 year | X19: Cows < 1 year | Y19: Cows 1-2 years | Z19: Cows 2-3 years | AA19: Cows > 3 years | AB19: Steers < 1 year | AC19: Steers 1-2 years | AD19: Steers 2-3 years | AE19: Steers >3 years
A20: =HYPERLINK("#'Acknowledgements'!A1", "Acknowledgements") -> Acknowledgements | D20: ='Input - Pasture Beef'!D60 -> Spring | E20: ='Input - Pasture Beef'!E60 -> 340 | F20: ='Input - Pasture Beef'!F60 -> 800 | G20: ='Input - Pasture Beef'!G60 -> 260 | H20: ='Input - Pasture Beef'!H60 -> 420 | I20: ='Input - Pasture Beef'!I60 -> 550 | J20: ='Input - Pasture Beef'!J60 -> 550 | K20: ='Input - Pasture Beef'!K60 -> 300 | ... N20: ='Input - Pasture Beef'!N60 -> 480 | O20: kg/head | U20: =TEXT('Input - Site'!$E$12, "mmmm yyyy") -> January 2024 | V20: ='Input - Pasture Beef'!E66 -> 380 | W20: ='Input - Pasture Beef'!F66 -> 780 | X20: ='Input - Pasture Beef'!G66 -> 300 | Y20: ='Input - Pasture Beef'!H66 -> 450 | Z20: ='Input - Pasture Beef'!I66 -> 530 | AA20: ='Input - Pasture Beef'!J66 -> 530 | AB20: ='Input - Pasture Beef'!K66 -> 340 | AC20: ='Input - Pasture Beef'!L66 -> 470 | ... AE20: ='Input - Pasture Beef'!N66 -> 470 | AF20: kg/head
D21: ='Input - Pasture Beef'!D61 -> Summer | E21: ='Input - Pasture Beef'!E61 -> 380 | F21: ='Input - Pasture Beef'!F61 -> 780 | G21: ='Input - Pasture Beef'!G61 -> 300 | H21: ='Input - Pasture Beef'!H61 -> 450 | I21: ='Input - Pasture Beef'!I61 -> 530 | J21: ='Input - Pasture Beef'!J61 -> 530 | K21: ='Input - Pasture Beef'!K61 -> 340 | ... N21: ='Input - Pasture Beef'!N61 -> 470 | O21: kg/head | U21: =TEXT(EDATE('Input - Site'!$E$12,1), "mmmm yyyy") -> February 2024 | V21: ='Input - Pasture Beef'!E67 -> 380 | W21: ='Input - Pasture Beef'!F67 -> 780 | X21: ='Input - Pasture Beef'!G67 -> 300 | Y21: ='Input - Pasture Beef'!H67 -> 450 | Z21: ='Input - Pasture Beef'!I67 -> 530 | AA21: ='Input - Pasture Beef'!J67 -> 530 | AB21: ='Input - Pasture Beef'!K67 -> 340 | AC21: ='Input - Pasture Beef'!L67 -> 470 | ... AE21: ='Input - Pasture Beef'!N67 -> 470 | AF21: kg/head
D22: ='Input - Pasture Beef'!D62 -> Autumn | E22: ='Input - Pasture Beef'!E62 -> 100 | F22: ='Input - Pasture Beef'!F62 -> 680 | G22: ='Input - Pasture Beef'!G62 -> 80 | H22: ='Input - Pasture Beef'!H62 -> 320 | I22: ='Input - Pasture Beef'!I62 -> 480 | J22: ='Input - Pasture Beef'!J62 -> 480 | K22: ='Input - Pasture Beef'!K62 -> 100 | ... N22: ='Input - Pasture Beef'!N62 -> 340 | O22: kg/head | U22: =TEXT(EDATE('Input - Site'!$E$12,2), "mmmm yyyy") -> March 2024 | V22: ='Input - Pasture Beef'!E68 -> 100 | W22: ='Input - Pasture Beef'!F68 -> 680 | X22: ='Input - Pasture Beef'!G68 -> 80 | Y22: ='Input - Pasture Beef'!H68 -> 320 | Z22: ='Input - Pasture Beef'!I68 -> 480 | AA22: ='Input - Pasture Beef'!J68 -> 480 | AB22: ='Input - Pasture Beef'!K68 -> 100 | AC22: ='Input - Pasture Beef'!L68 -> 340 | ... AE22: ='Input - Pasture Beef'!N68 -> 340 | AF22: kg/head
D23: ='Input - Pasture Beef'!D63 -> Winter | E23: ='Input - Pasture Beef'!E63 -> 190 | F23: ='Input - Pasture Beef'!F63 -> 700 | G23: ='Input - Pasture Beef'!G63 -> 150 | H23: ='Input - Pasture Beef'!H63 -> 330 | I23: ='Input - Pasture Beef'!I63 -> 490 | J23: ='Input - Pasture Beef'!J63 -> 490 | K23: ='Input - Pasture Beef'!K63 -> 170 | ... N23: ='Input - Pasture Beef'!N63 -> 360 | O23: kg/head | U23: =TEXT(EDATE('Input - Site'!$E$12,3), "mmmm yyyy") -> April 2024 | V23: ='Input - Pasture Beef'!E69 -> 100 | W23: ='Input - Pasture Beef'!F69 -> 680 | X23: ='Input - Pasture Beef'!G69 -> 80 | Y23: ='Input - Pasture Beef'!H69 -> 320 | Z23: ='Input - Pasture Beef'!I69 -> 480 | AA23: ='Input - Pasture Beef'!J69 -> 480 | AB23: ='Input - Pasture Beef'!K69 -> 100 | AC23: ='Input - Pasture Beef'!L69 -> 340 | ... AE23: ='Input - Pasture Beef'!N69 -> 340 | AF23: kg/head
U24: =TEXT(EDATE('Input - Site'!$E$12,4), "mmmm yyyy") -> May 2024 | V24: ='Input - Pasture Beef'!E70 -> 100 | W24: ='Input - Pasture Beef'!F70 -> 680 | X24: ='Input - Pasture Beef'!G70 -> 80 | Y24: ='Input - Pasture Beef'!H70 -> 320 | Z24: ='Input - Pasture Beef'!I70 -> 480 | AA24: ='Input - Pasture Beef'!J70 -> 480 | AB24: ='Input - Pasture Beef'!K70 -> 100 | AC24: ='Input - Pasture Beef'!L70 -> 340 | ... AE24: ='Input - Pasture Beef'!N70 -> 340 | AF24: kg/head
D25: Table_SRW_k | U25: =TEXT(EDATE('Input - Site'!$E$12,5), "mmmm yyyy") -> June 2024 | V25: ='Input - Pasture Beef'!E71 -> 190 | W25: ='Input - Pasture Beef'!F71 -> 700 | X25: ='Input - Pasture Beef'!G71 -> 150 | Y25: ='Input - Pasture Beef'!H71 -> 330 | Z25: ='Input - Pasture Beef'!I71 -> 490 | AA25: ='Input - Pasture Beef'!J71 -> 490 | AB25: ='Input - Pasture Beef'!K71 -> 170 | AC25: ='Input - Pasture Beef'!L71 -> 360 | ... AE25: ='Input - Pasture Beef'!N71 -> 360 | AF25: kg/head
D26: Standard reference weight | U26: =TEXT(EDATE('Input - Site'!$E$12,6), "mmmm yyyy") -> July 2024 | V26: ='Input - Pasture Beef'!E72 -> 190 | W26: ='Input - Pasture Beef'!F72 -> 700 | X26: ='Input - Pasture Beef'!G72 -> 150 | Y26: ='Input - Pasture Beef'!H72 -> 330 | Z26: ='Input - Pasture Beef'!I72 -> 490 | AA26: ='Input - Pasture Beef'!J72 -> 490 | AB26: ='Input - Pasture Beef'!K72 -> 170 | AC26: ='Input - Pasture Beef'!L72 -> 360 | ... AE26: ='Input - Pasture Beef'!N72 -> 360 | AF26: kg/head
D27: Bulls < 1 year | E27: Bulls > 1 year | F27: Cows < 1 year | G27: Cows 1-2 years | H27: Cows 2-3 years | I27: Cows > 3 years | J27: Steers < 1 year | K27: Steers 1-2 years | L27: Steers 2-3 years | M27: Steers >3 years | U27: =TEXT(EDATE('Input - Site'!$E$12,7), "mmmm yyyy") -> August 2024 | V27: ='Input - Pasture Beef'!E73 -> 190 | W27: ='Input - Pasture Beef'!F73 -> 700 | X27: ='Input - Pasture Beef'!G73 -> 150 | Y27: ='Input - Pasture Beef'!H73 -> 330 | Z27: ='Input - Pasture Beef'!I73 -> 490 | AA27: ='Input - Pasture Beef'!J73 -> 490 | AB27: ='Input - Pasture Beef'!K73 -> 170 | AC27: ='Input - Pasture Beef'!L73 -> 360 | ... AE27: ='Input - Pasture Beef'!N73 -> 360 | AF27: kg/head
D28: =Common_InputFunctions.Utility_LookupValueInTableOneColumnAndHeader(Common_InputFunctions.Utility_ConvertStateCommonNameToAbbreviation($F$15,Table_AustralianStates[Common Name],Table_AustralianStates[Abbreviation]),D27,Table_SourceData_PastureBeef_StandardReferenceWeightsExpanded[State abbreviation],Table_SourceData_PastureBeef_StandardReferenceWeightsExpanded[#Headers],Table_SourceData_PastureBeef_StandardReferenceWeightsExpanded[]) -> 770 | E28: =Common_InputFunctions.Utility_LookupValueInTableOneColumnAndHeader(Common_InputFunctions.Utility_ConvertStateCommonNameToAbbreviation($F$15,Table_AustralianStates[Common Name],Table_AustralianStates[Abbreviation]),E27,Table_SourceData_PastureBeef_StandardReferenceWeightsExpanded[State abbreviation],Table_SourceData_PastureBeef_StandardReferenceWeightsExpanded[#Headers],Table_SourceData_PastureBeef_StandardReferenceWeightsExpanded[]) -> 770 | F28: =Common_InputFunctions.Utility_LookupValueInTableOneColumnAndHeader(Common_InputFunctions.Utility_ConvertStateCommonNameToAbbreviation($F$15,Table_AustralianStates[Common Name],Table_AustralianStates[Abbreviation]),F27,Table_SourceData_PastureBeef_StandardReferenceWeightsExpanded[State abbreviation],Table_SourceData_PastureBeef_StandardReferenceWeightsExpanded[#Headers],Table_SourceData_PastureBeef_StandardReferenceWeightsExpanded[]) -> 550 | G28: =Common_InputFunctions.Utility_LookupValueInTableOneColumnAndHeader(Common_InputFunctions.Utility_ConvertStateCommonNameToAbbreviation($F$15,Table_AustralianStates[Common Name],Table_AustralianStates[Abbreviation]),G27,Table_SourceData_PastureBeef_StandardReferenceWeightsExpanded[State abbreviation],Table_SourceData_PastureBeef_StandardReferenceWeightsExpanded[#Headers],Table_SourceData_PastureBeef_StandardReferenceWeightsExpanded[]) -> 550 | H28: =Common_InputFunctions.Utility_LookupValueInTableOneColumnAndHeader(Common_InputFunctions.Utility_ConvertStateCommonNameToAbbreviation($F$15,Table_AustralianStates[Common Name],Table_AustralianStates[Abbreviation]),H27,Table_SourceData_PastureBeef_StandardReferenceWeightsExpanded[State abbreviation],Table_SourceData_PastureBeef_StandardReferenceWeightsExpanded[#Headers],Table_SourceData_PastureBeef_StandardReferenceWeightsExpanded[]) -> 550 | I28: =Common_InputFunctions.Utility_LookupValueInTableOneColumnAndHeader(Common_InputFunctions.Utility_ConvertStateCommonNameToAbbreviation($F$15,Table_AustralianStates[Common Name],Table_AustralianStates[Abbreviation]),I27,Table_SourceData_PastureBeef_StandardReferenceWeightsExpanded[State abbreviation],Table_SourceData_PastureBeef_StandardReferenceWeightsExpanded[#Headers],Table_SourceData_PastureBeef_StandardReferenceWeightsExpanded[]) -> 550 | J28: =Common_InputFunctions.Utility_LookupValueInTableOneColumnAndHeader(Common_InputFunctions.Utility_ConvertStateCommonNameToAbbreviation($F$15,Table_AustralianStates[Common Name],Table_AustralianStates[Abbreviation]),J27,Table_SourceData_PastureBeef_StandardReferenceWeightsExpanded[State abbreviation],Table_SourceData_PastureBeef_StandardReferenceWeightsExpanded[#Headers],Table_SourceData_PastureBeef_StandardReferenceWeightsExpanded[]) -> 660 | K28: =Common_InputFunctions.Utility_LookupValueInTableOneColumnAndHeader(Common_InputFunctions.Utility_ConvertStateCommonNameToAbbreviation($F$15,Table_AustralianStates[Common Name],Table_AustralianStates[Abbreviation]),K27,Table_SourceData_PastureBeef_StandardReferenceWeightsExpanded[State abbreviation],Table_SourceData_PastureBeef_StandardReferenceWeightsExpanded[#Headers],Table_SourceData_PastureBeef_StandardReferenceWeightsExpanded[]) -> 660 | ... M28: =Common_InputFunctions.Utility_LookupValueInTableOneColumnAndHeader(Common_InputFunctions.Utility_ConvertStateCommonNameToAbbreviation($F$15,Table_AustralianStates[Common Name],Table_AustralianStates[Abbreviation]),M27,Table_SourceData_PastureBeef_StandardReferenceWeightsExpanded[State abbreviation],Table_SourceData_PastureBeef_StandardReferenceWeightsExpanded[#Headers],Table_SourceData_PastureBeef_StandardReferenceWeightsExpanded[]) -> 660 | N28: kg/head | U28: =TEXT(EDATE('Input - Site'!$E$12,8), "mmmm yyyy") -> September 2024 | V28: ='Input - Pasture Beef'!E74 -> 340 | W28: ='Input - Pasture Beef'!F74 -> 800 | X28: ='Input - Pasture Beef'!G74 -> 260 | Y28: ='Input - Pasture Beef'!H74 -> 420 | Z28: ='Input - Pasture Beef'!I74 -> 550 | AA28: ='Input - Pasture Beef'!J74 -> 550 | AB28: ='Input - Pasture Beef'!K74 -> 300 | AC28: ='Input - Pasture Beef'!L74 -> 480 | ... AE28: ='Input - Pasture Beef'!N74 -> 480 | AF28: kg/head
U29: =TEXT(EDATE('Input - Site'!$E$12,9), "mmmm yyyy") -> October 2024 | V29: ='Input - Pasture Beef'!E75 -> 340 | W29: ='Input - Pasture Beef'!F75 -> 800 | X29: ='Input - Pasture Beef'!G75 -> 260 | Y29: ='Input - Pasture Beef'!H75 -> 420 | Z29: ='Input - Pasture Beef'!I75 -> 550 | AA29: ='Input - Pasture Beef'!J75 -> 550 | AB29: ='Input - Pasture Beef'!K75 -> 300 | AC29: ='Input - Pasture Beef'!L75 -> 480 | ... AE29: ='Input - Pasture Beef'!N75 -> 480 | AF29: kg/head
D30: M1_Table_Z_j_k_l | U30: =TEXT(EDATE('Input - Site'!$E$12,10), "mmmm yyyy") -> November 2024 | V30: ='Input - Pasture Beef'!E76 -> 340 | W30: ='Input - Pasture Beef'!F76 -> 800 | X30: ='Input - Pasture Beef'!G76 -> 260 | Y30: ='Input - Pasture Beef'!H76 -> 420 | Z30: ='Input - Pasture Beef'!I76 -> 550 | AA30: ='Input - Pasture Beef'!J76 -> 550 | AB30: ='Input - Pasture Beef'!K76 -> 300 | AC30: ='Input - Pasture Beef'!L76 -> 480 | ... AE30: ='Input - Pasture Beef'!N76 -> 480 | AF30: kg/head
D31: Relative size (Method 1) | U31: =TEXT(EDATE('Input - Site'!$E$12,11), "mmmm yyyy") -> December 2024 | V31: ='Input - Pasture Beef'!E77 -> 380 | W31: ='Input - Pasture Beef'!F77 -> 780 | X31: ='Input - Pasture Beef'!G77 -> 300 | Y31: ='Input - Pasture Beef'!H77 -> 450 | Z31: ='Input - Pasture Beef'!I77 -> 530 | AA31: ='Input - Pasture Beef'!J77 -> 530 | AB31: ='Input - Pasture Beef'!K77 -> 340 | AC31: ='Input - Pasture Beef'!L77 -> 470 | ... AE31: ='Input - Pasture Beef'!N77 -> 470 | AF31: kg/head
D32: Season | E32: Bulls < 1 year | F32: Bulls > 1 year | G32: Cows < 1 year | H32: Cows 1-2 years | I32: Cows 2-3 years | J32: Cows > 3 years | K32: Steers < 1 year | L32: Steers 1-2 years | M32: Steers 2-3 years | N32: Steers >3 years
D33: ='Input - Pasture Beef'!D60 -> Spring | E33: {=MMS_PastureBeef_Soil_N2ODirect_Equations.VEERG_4_2_1_3__7_RelativeSize(E20,D$28)} -> 0.44155844 | F33: {=MMS_PastureBeef_Soil_N2ODirect_Equations.VEERG_4_2_1_3__7_RelativeSize(F20,E$28)} -> 1.038961 | G33: {=MMS_PastureBeef_Soil_N2ODirect_Equations.VEERG_4_2_1_3__7_RelativeSize(G20,F$28)} -> 0.47272727 | H33: {=MMS_PastureBeef_Soil_N2ODirect_Equations.VEERG_4_2_1_3__7_RelativeSize(H20,G$28)} -> 0.76363636 | I33: {=MMS_PastureBeef_Soil_N2ODirect_Equations.VEERG_4_2_1_3__7_RelativeSize(I20,H$28)} -> 1 | J33: {=MMS_PastureBeef_Soil_N2ODirect_Equations.VEERG_4_2_1_3__7_RelativeSize(J20,I$28)} -> 1 | K33: {=MMS_PastureBeef_Soil_N2ODirect_Equations.VEERG_4_2_1_3__7_RelativeSize(K20,J$28)} -> 0.45454545 | L33: {=MMS_PastureBeef_Soil_N2ODirect_Equations.VEERG_4_2_1_3__7_RelativeSize(L20,K$28)} -> 0.72727273 | ... N33: {=MMS_PastureBeef_Soil_N2ODirect_Equations.VEERG_4_2_1_3__7_RelativeSize(N20,M$28)} -> 0.72727273 | O33: =$E$11 -> ratio | U33: M2_Table_Z_j_k_l
D34: ='Input - Pasture Beef'!D61 -> Summer | E34: {=MMS_PastureBeef_Soil_N2ODirect_Equations.VEERG_4_2_1_3__7_RelativeSize(E21,D$28)} -> 0.49350649 | F34: {=MMS_PastureBeef_Soil_N2ODirect_Equations.VEERG_4_2_1_3__7_RelativeSize(F21,E$28)} -> 1.012987 | G34: {=MMS_PastureBeef_Soil_N2ODirect_Equations.VEERG_4_2_1_3__7_RelativeSize(G21,F$28)} -> 0.54545455 | H34: {=MMS_PastureBeef_Soil_N2ODirect_Equations.VEERG_4_2_1_3__7_RelativeSize(H21,G$28)} -> 0.81818182 | I34: {=MMS_PastureBeef_Soil_N2ODirect_Equations.VEERG_4_2_1_3__7_RelativeSize(I21,H$28)} -> 0.96363636 | J34: {=MMS_PastureBeef_Soil_N2ODirect_Equations.VEERG_4_2_1_3__7_RelativeSize(J21,I$28)} -> 0.96363636 | K34: {=MMS_PastureBeef_Soil_N2ODirect_Equations.VEERG_4_2_1_3__7_RelativeSize(K21,J$28)} -> 0.51515152 | L34: {=MMS_PastureBeef_Soil_N2ODirect_Equations.VEERG_4_2_1_3__7_RelativeSize(L21,K$28)} -> 0.71212121 | ... N34: {=MMS_PastureBeef_Soil_N2ODirect_Equations.VEERG_4_2_1_3__7_RelativeSize(N21,M$28)} -> 0.71212121 | O34: =$E$11 -> ratio | U34: Relative size (Method 2)
