Workbook
Name Common_Equations.Common_ConvertCH4ToCO2e: _xlfn.LAMBDA(_xlpm.E_CH4,_xlpm.GWP_CH4, _xlpm.E_CH4 * _xlpm.GWP_CH4)
Name Common_Equations.Common_ConvertCH4ToCO2e_Arguments: _xlfn.LAMBDA(_xlfn.MAKEARRAY(2, 2, _xlfn.LAMBDA(_xlpm.r,_xlpm.c, INDEX({"ECH4","Methane emissions (t CH4)";"GWPCH4","Global warming potential for methane (t CO2-e / t CH4)"}, _xlpm.r, _xlpm.c))))
Name Common_Equations.Common_ConvertCH4ToCO2e_LatexEquation: _xlfn.LAMBDA("CO2_e = E_{CH4} \times GWP_{CH4}")
Name Common_Equations.Common_ConvertCH4ToCO2e_NIRReference: _xlfn.LAMBDA("")
Name Common_Equations.Common_ConvertCH4ToCO2e_Title: _xlfn.LAMBDA("Convert methane emissions to carbon dioxide equivalent emissions")
Name Common_Equations.Common_ConvertCH4ToCO2e_Unit: _xlfn.LAMBDA("t CO2e")
Name Common_Equations.Common_ConvertCH4ToCO2e_Variable: _xlfn.LAMBDA("ECH4 CO2e")
Name Common_Equations.Common_ConvertN2OToCO2e: _xlfn.LAMBDA(_xlpm.E_N2O,_xlpm.GWP_N2O, _xlpm.E_N2O * _xlpm.GWP_N2O)
Name Common_Equations.Common_ConvertN2OToCO2e_LatexEquation: _xlfn.LAMBDA("CO2_e = E_{N2O} \times GWP_{N2O}")
Name Common_Equations.Common_ConvertN2OToCO2e_NIRReference: _xlfn.LAMBDA("")
Name Common_Equations.Common_ConvertN2OToCO2e_Title: _xlfn.LAMBDA("Convert nitrous oxide emissions to carbon dioxide equivalent emissions")
Name Common_Equations.Common_ConvertN2OToCO2e_Unit: _xlfn.LAMBDA("t CO2e")
Name Common_Equations.Common_ConvertN2OToCO2e_Variable: _xlfn.LAMBDA("EN2O CO2e")
Name Common_InputFunctions.Utility_ConvertStateCommonNameToAbbreviation: _xlfn.LAMBDA(_xlpm.StateCommonName,_xlpm.StateCommonNameArray,_xlpm.StateAbbreviationArray, _xlfn.XLOOKUP(_xlpm.StateCommonName, _xlpm.StateCommonNameArray, _xlpm.StateAbbreviationArray, ""))
Name Common_InputFunctions.Utility_DisplayArguments_1_2: _xlfn.LAMBDA(_xlpm.ArgumentsArray, _xlfn.CHOOSECOLS(_xlpm.ArgumentsArray, 1, 2))
Name Common_InputFunctions.Utility_DisplayArguments_3_4: _xlfn.LAMBDA(_xlpm.ArgumentsArray, _xlfn.CHOOSECOLS(_xlpm.ArgumentsArray, 3, 4))
Name Common_InputFunctions.Utility_DisplayFunctionName: _xlfn.LAMBDA(_xlpm.Function, _xlfn.TEXTBEFORE(_xlfn.FORMULATEXT(_xlpm.Function), "("))
Name Common_InputFunctions.Utility_GetArrayTableColumnStartNumber: _xlfn.LAMBDA(_xlpm.TableHeaderCell, COLUMN(_xlpm.TableHeaderCell))
Name Common_InputFunctions.Utility_GetArrayTableRowStartNumber: _xlfn.LAMBDA(_xlpm.TableheaderCell,_xlpm.RowsBetweenHeaderandArray, ROW(_xlpm.TableheaderCell) + _xlpm.RowsBetweenHeaderandArray - 1)
Name Common_InputFunctions.Utility_LookupValueInTable: _xlfn.LAMBDA(_xlpm.LookupValue,_xlpm.LookupArray,_xlpm.ReturnArray, _xlfn.XLOOKUP(_xlpm.LookupValue, _xlpm.LookupArray, _xlpm.ReturnArray, ""))
Name Common_InputFunctions.Utility_SourceHyperlink: _xlfn.LAMBDA(_xlpm.TargetCell, _xlfn.LET(_xlpm.sh, _xlfn.TEXTAFTER(CELL("filename", _xlpm.TargetCell), "]"), _xlpm.addr, CELL("address", _xlpm.TargetCell), "#'" & _xlpm.sh & "'!" & _xlpm.addr))
Name Common_SourceData.Common_SourceData_AustralianStatesTerritories_Source: _xlfn.LAMBDA("")
Name Common_SourceData.Common_SourceData_AustralianStatesTerritories_Title: _xlfn.LAMBDA("Australian states and territories")
Name Common_SourceData.Common_SourceData_AustralianStatesTerritories_Unit: _xlfn.LAMBDA("")
Name Common_SourceData.Common_SourceData_AustralianStatesTerritories_Variable: _xlfn.LAMBDA("")
Name Common_SourceData.Common_SourceData_ClimateZones_Source: _xlfn.LAMBDA("VEERG 2026: Table 1.3: Climate and Rainfall zone classifications and definitions")
Name Common_SourceData.Common_SourceData_ClimateZones_Title: _xlfn.LAMBDA("VEERG Australian climate zones")
Name Common_SourceData.Common_SourceData_ClimateZones_Unit: _xlfn.LAMBDA("")
Name Common_SourceData.Common_SourceData_ClimateZones_Variable: _xlfn.LAMBDA("")
Name Common_SourceData.Common_SourceData_ConvertGasElementalToMolecular_Source: _xlfn.LAMBDA("XXXXXXX")
Name Common_SourceData.Common_SourceData_ConvertGasElementalToMolecular_Title: _xlfn.LAMBDA("Factor to convert elemental mass of gas to molecular mass")
Name Common_SourceData.Common_SourceData_ConvertGasElementalToMolecular_Unit: _xlfn.LAMBDA("factor")
Name Common_SourceData.Common_SourceData_ConvertGasElementalToMolecular_Variable: _xlfn.LAMBDA("Cg")
Name Common_SourceData.Common_SourceData_ConvertN2oElementalToMolecularCg_Data: _xlfn.LAMBDA(44 / 28)
Name Common_SourceData.Common_SourceData_ConvertN2oElementalToMolecularCg_Source: _xlfn.LAMBDA("National Inventory Report 2023 Volume 1")
Name Common_SourceData.Common_SourceData_ConvertN2oElementalToMolecularCg_Title: _xlfn.LAMBDA("Factor to convert elemental mass of N2O to molecular mass")
Name Common_SourceData.Common_SourceData_ConvertN2oElementalToMolecularCg_Unit: _xlfn.LAMBDA("factor")
Name Common_SourceData.Common_SourceData_ConvertN2oElementalToMolecularCg_Variable: _xlfn.LAMBDA("CgN2O")
Name Common_SourceData.Common_SourceData_DataScores_Scope3_Source: _xlfn.LAMBDA("VEERG 2026: XXXXXXXX")
Name Common_SourceData.Common_SourceData_DataScores_Scope3_Title: _xlfn.LAMBDA("Australian data scores for scope 3")
Name Common_SourceData.Common_SourceData_DataScores_Scope3_Unit: _xlfn.LAMBDA("")
Name Common_SourceData.Common_SourceData_DataScores_Scope3_Variable: _xlfn.LAMBDA("")
Name Common_SourceData.Common_SourceData_DataScores_Scope3_Variation: _xlfn.LAMBDA("")
Name Common_SourceData.Common_SourceData_DensityOfMethane_Data: _xlfn.LAMBDA(0.6784)
Name Common_SourceData.Common_SourceData_DensityOfMethane_Source: _xlfn.LAMBDA("National Inventory Report 2023 Volume 1: Equations 3.B.1a_2, 3.B.1c_2, 3.B.3_1, 3.B.4g_2")
Name Common_SourceData.Common_SourceData_DensityOfMethane_Title: _xlfn.LAMBDA("p = density of methane")
Name Common_SourceData.Common_SourceData_DensityOfMethane_Unit: _xlfn.LAMBDA("kg/m3")
Name Common_SourceData.Common_SourceData_EFleach_Data: _xlfn.LAMBDA(_xlfn.MAKEARRAY(1, 2, _xlfn.LAMBDA(_xlpm.r,_xlpm.c, INDEX({"EFleach",0.011}, _xlpm.r, _xlpm.c))))
Name Common_SourceData.Common_SourceData_EFleach_NIRReference: _xlfn.LAMBDA("National Inventory Report Volume 1: Equation 3.D.B_10")
Name Common_SourceData.Common_SourceData_EFleach_Source: _xlfn.LAMBDA("VEERG 2026:5.5.2.3 Constant Parameters")
Name Common_SourceData.Common_SourceData_EFleach_Title: _xlfn.LAMBDA("Emission factor for nitrogen leaching and runoff")
Name Common_SourceData.Common_SourceData_EFleach_Unit: _xlfn.LAMBDA("(kg N2O-N / kg N")
Name Common_SourceData.Common_SourceData_EFleach_Variation: _xlfn.LAMBDA((""))
Name Common_SourceData.Common_SourceData_EFN2O_NIRReference: _xlfn.LAMBDA("")
Name Common_SourceData.Common_SourceData_EFN2O_Source: _xlfn.LAMBDA("VEERG 2026: Table A.2.2.1")
Name Common_SourceData.Common_SourceData_EFN2O_Title: _xlfn.LAMBDA("Nitrous oxide emission factors for inorganic fertiliser application")
Name Common_SourceData.Common_SourceData_EFN2O_Unit: _xlfn.LAMBDA("(kg N2O-N / kg N")
Name Common_SourceData.Common_SourceData_EFPastureRangeAndPaddock_Data: _xlfn.LAMBDA(_xlfn.MAKEARRAY(3, 2, _xlfn.LAMBDA(_xlpm.r,_xlpm.c, INDEX({"Climate zone","EFPRP";"Wet climate zone",0.006;"Dry climate zone",0.002}, _xlpm.r, _xlpm.c))))
Name Common_SourceData.Common_SourceData_EFPastureRangeAndPaddock_NIRReference: _xlfn.LAMBDA("")
Name Common_SourceData.Common_SourceData_EFPastureRangeAndPaddock_Source: _xlfn.LAMBDA("VEERG 2026: Table A.2.2.2")

Sheet Home
A1: Home

Sheet Overview
A1: #VALUE! | C1: 4.3: Manure Management: Dairy: Overview
A3: =HYPERLINK("#'Home'!A1", "Home") -> Home
A4: =HYPERLINK("#'Overview'!A1", "Overview") -> Overview
A5: =HYPERLINK("#'Results'!A1", "Results") -> Results | D5: 💡 Below is a diagram that maps the equations used to calculate emissions, how they interact with each other and how they align with dairy manure management processes.
D6: Click on a box to go to the corresponding calculation.
A7: INPUTS
A8: =HYPERLINK("#'Input - Site'!A1", "Site") -> Site
A9: =HYPERLINK("#'Input - Dairy'!A1", "Dairy") -> Dairy
A11: CALCULATIONS
A12: =HYPERLINK("#'4.3.1.1-2 Methane'!A1", "4.3.1.1-2 Methane") -> 4.3.1.1-2 Methane
A13: =HYPERLINK("#'4.3.1.3-4 Direct N20'!A1", "4.3.1.3-4 Direct N2O") -> 4.3.1.3-4 Direct N2O
A14: =HYPERLINK("#'4.3.1.5 Atmos Deposition'!A1", "4.3.1.5 Atmospheric deposition") -> 4.3.1.5 Atmospheric deposition
A15: =HYPERLINK("#'4.3.1.6-7 Leaching and runoff'!A1", "4.3.1.6-7 Leaching and runoff") -> 4.3.1.6-7 Leaching and runoff
A16: =HYPERLINK("#'4.3.1.8 Manure applied to soils'!A1", "4.3.1.8 Manure applied to soils") -> 4.3.1.8 Manure applied to soils
A17: =HYPERLINK("#'4.3.1.9 Soil direct N2O'!A1", "4.3.1.9 Soil direct N2O") -> 4.3.1.9 Soil direct N2O
A18: =HYPERLINK("#'4.3.1.10-11 Soil Atmos Dep'!A1", "4.3.1.10-11 Soil atm. deposition") -> 4.3.1.10-11 Soil atm. deposition
A19: =HYPERLINK("#'4.3.1.12-13 Soil leach runoff'!A1", "4.3.1.12-13 Soil leach & runoff") -> 4.3.1.12-13 Soil leach & runoff
A21: APPENDICES
A22: =HYPERLINK("#'Constants - Dairy'!A1", "Constants - Dairy") -> Constants - Dairy
A23: =HYPERLINK("#'Constants - Livestock'!A1", "Constants - Livestock") -> Constants - Livestock
A24: =HYPERLINK("#'Constants - Common'!A1", "Constants - Common") -> Constants - Common
A25: =HYPERLINK("#'Acknowledgements'!A1", "Acknowledgements") -> Acknowledgements

Sheet Results
A1: #VALUE! | C1: 4.3 Manure management: Dairy: Results
A3: =HYPERLINK("#'Home'!A1", "Home") -> Home
A4: =HYPERLINK("#'Overview'!A1", "Overview") -> Overview | D4: Emissions breakdown
A5: =HYPERLINK("#'Results'!A1", "Results") -> Results
D6: Scope 1 source | E6: GHG emissions method 1 | F6: GHG emissions method 2 | G6: GHG Unit | H6: CO2-e emissions method 1 | I6: CO2-e emissions method 2 | J6: CO2-e unit
A7: INPUTS | D7: 4.3.1.1-2 Manure methane | E7: ='4.3.1.1-2 Methane'!$E$270 -> 8.675539 | F7: ='4.3.1.1-2 Methane'!$P$270 -> 8.9300276 | G7: ='4.3.1.1-2 Methane'!$F$270 -> t CH4 | H7: ='4.3.1.1-2 Methane'!$E$275 -> 242.91509 | I7: ='4.3.1.1-2 Methane'!$P$275 -> 250.04077 | J7: ='4.3.1.1-2 Methane'!$F$275 -> t CO2e
A8: =HYPERLINK("#'Input - Site'!A1", "Site") -> Site | D8: 4.3.1.3-4 Manure direct N2O | E8: ='4.3.1.3-4 Direct N20'!$E$280 -> 0.017559969 | F8: ='4.3.1.3-4 Direct N20'!$O$280 -> 0.017559969 | G8: ='4.3.1.3-4 Direct N20'!$F$280 -> t N2O | H8: ='4.3.1.3-4 Direct N20'!$E$285 -> 4.6533917 | I8: ='4.3.1.3-4 Direct N20'!$O$285 -> 4.6533917 | J8: ='4.3.1.3-4 Direct N20'!$F$285 -> t CO2e
A9: =HYPERLINK("#'Input - Dairy'!A1", "Dairy") -> Dairy | D9: 4.3.1.5 Manure atmospheric deposition | E9: ='4.3.1.5 Atmos deposition'!$E$68 -> 0.038269028 | F9: ='4.3.1.5 Atmos deposition'!$P$68 -> 0.038269028 | G9: ='4.3.1.5 Atmos deposition'!$F$68 -> t N2O | H9: ='4.3.1.5 Atmos deposition'!$E$73 -> 10.141292 | I9: ='4.3.1.5 Atmos deposition'!$P$73 -> 10.141292 | J9: ='4.3.1.5 Atmos deposition'!$F$73 -> t CO2e
D10: 4.3.1.6-7 Manure leaching and runoff | E10: ='4.3.1.6-7 Leaching and runoff'!$E$52 -> 0.0020994899 | F10: ='4.3.1.6-7 Leaching and runoff'!$P$52 -> 0.0020994899 | G10: ='4.3.1.6-7 Leaching and runoff'!$F$52 -> t N2O | H10: ='4.3.1.6-7 Leaching and runoff'!$E$57 -> 0.55636482 | I10: ='4.3.1.6-7 Leaching and runoff'!$P$57 -> 0.55636482 | J10: ='4.3.1.6-7 Leaching and runoff'!$F$57 -> t CO2e
A11: CALCULATIONS | D11: 4.3.1.9 Soil direct N2O | E11: ='4.3.1.9 Soil direct N2O'!$E$53 -> 0.060451181 | F11: ='4.3.1.9 Soil direct N2O'!$P$53 -> 0.060451181 | G11: ='4.3.1.9 Soil direct N2O'!$F$53 -> t N2O | H11: ='4.3.1.9 Soil direct N2O'!$E$58 -> 16.019563 | I11: ='4.3.1.9 Soil direct N2O'!$P$58 -> 16.019563 | J11: ='4.3.1.9 Soil direct N2O'!$F$58 -> t CO2e
A12: =HYPERLINK("#'4.3.1.1-2 Methane'!A1", "4.3.1.1-2 Methane") -> 4.3.1.1-2 Methane | D12: 4.3.1.10-11 Soil atmospheric deposition | E12: ='4.3.1.10-11 Soil Atmos Dep'!$E$45 -> 0.037449507 | F12: ='4.3.1.10-11 Soil Atmos Dep'!$P$45 -> 0.037449507 | G12: ='4.3.1.10-11 Soil Atmos Dep'!$F$45 -> t N2O | H12: ='4.3.1.10-11 Soil Atmos Dep'!$E$50 -> 9.9241193 | I12: ='4.3.1.10-11 Soil Atmos Dep'!$P$50 -> 9.9241193 | J12: ='4.3.1.10-11 Soil Atmos Dep'!$F$50 -> t CO2e
A13: =HYPERLINK("#'4.3.1.3-4 Direct N20'!A1", "4.3.1.3-4 Direct N2O") -> 4.3.1.3-4 Direct N2O | D13: 4.3.1.12-13 Soil leaching and runoff | E13: ='4.3.1.12-13 Soil leach runoff'!$E$47 -> 0.0066496299 | F13: ='4.3.1.12-13 Soil leach runoff'!$P$47 -> 0.0066496299 | G13: ='4.3.1.12-13 Soil leach runoff'!$F$47 -> t N2O | H13: ='4.3.1.12-13 Soil leach runoff'!$E$52 -> 1.7621519 | I13: ='4.3.1.12-13 Soil leach runoff'!$P$52 -> 1.7621519 | J13: ='4.3.1.12-13 Soil leach runoff'!$F$52 -> t CO2e
A14: =HYPERLINK("#'4.3.1.5 Atmos Deposition'!A1", "4.3.1.5 Atmospheric deposition") -> 4.3.1.5 Atmospheric deposition | D14: Total | H14: =SUM(H7:H13) -> 285.97198 | I14: =SUM(I7:I13) -> 293.09766 | J14: t CO2e
A15: =HYPERLINK("#'4.3.1.6-7 Leaching and runoff'!A1", "4.3.1.6-7 Leaching and runoff") -> 4.3.1.6-7 Leaching and runoff
A16: =HYPERLINK("#'4.3.1.8 Manure applied to soils'!A1", "4.3.1.8 Manure applied to soils") -> 4.3.1.8 Manure applied to soils | D16: 4.3.1.8 Manure applied to soils
A17: =HYPERLINK("#'4.3.1.9 Soil direct N2O'!A1", "4.3.1.9 Soil direct N2O") -> 4.3.1.9 Soil direct N2O | D17: WARNING: Manure nitrogen that was applied to soils must be accounted for
A18: =HYPERLINK("#'4.3.1.10-11 Soil Atmos Dep'!A1", "4.3.1.10-11 Soil atm. deposition") -> 4.3.1.10-11 Soil atm. deposition | D18: See the table below for how to account for manure applied to soils for scope 1 and 3.
A19: =HYPERLINK("#'4.3.1.12-13 Soil leach runoff'!A1", "4.3.1.12-13 Soil leach & runoff") -> 4.3.1.12-13 Soil leach & runoff | D19: Manure nitrogen use | E19: Amount of N in manure | F19: N unit | G19: Emissions allocated to | H19: VEERG Calculation method
D20: Manure nitrogen deposited on farm soils (including use as fertiliser for other enterprises on own farm eg crops) | E20: ='4.3.1.8 Manure applied to soils'!$E$85 -> 9379.2609 | F20: kg N | G20: Scope 1 - This dairy | H20: 5.2.2.1 (1), 5.4.1.3 (1, 2), 5.5.1.1 (1, 3)
A21: APPENDICES | D21: Manure nitrogen deposited on farm soils as fertiliser for other farm enterpsies (eg crops) | E21: ='4.3.1.8 Manure applied to soils'!$E$148 -> 3126.4203 | F21: kg N | G21: Scope 1 - This dairy | H21: 5.2.2.1 (1), 5.4.1.3 (1, 2), 5.5.1.1 (1, 3)
A22: =HYPERLINK("#'Constants - Dairy'!A1", "Constants - Dairy") -> Constants - Dairy | D22: Manure nitrogen sold | E22: ='4.3.1.8 Manure applied to soils'!$E$115 -> 3126.4203 | F22: kg N | G22: Scope 3 (downstream) | H22: 15.13.1.1 (1), 5.2.2.1 (1), 5.4.1.3 (1, 2), 5.5.1.1 (1, 3)
A23: =HYPERLINK("#'Constants - Livestock'!A1", "Constants - Livestock") -> Constants - Livestock
A24: =HYPERLINK("#'Constants - Common'!A1", "Constants - Common") -> Constants - Common
A25: =HYPERLINK("#'Acknowledgements'!A1", "Acknowledgements") -> Acknowledgements

Sheet Input - Site
A1: #VALUE! | C1: Input - Site
A3: =HYPERLINK("#'Home'!A1", "Home") -> Home
A4: =HYPERLINK("#'Overview'!A1", "Overview") -> Overview
A5: =HYPERLINK("#'Results'!A1", "Results") -> Results | D5: Your business
A7: INPUTS | D7: Farm name | E7: Test Farms
A8: =HYPERLINK("#'Input - Site'!A1", "Site") -> Site | D8: Reporting entity name | E8: Test Farms Pty Ltd
A9: =HYPERLINK("#'Input - Dairy'!A1", "Dairy") -> Dairy
D10: 💡An 'Emissions accounting period' is a 12 month period where the business can report on the emissions, and is typically the same as the business' financial accounting period.
A11: CALCULATIONS
A12: =HYPERLINK("#'4.3.1.1-2 Methane'!A1", "4.3.1.1-2 Methane") -> 4.3.1.1-2 Methane | D12: Emissions calculation period start date | E12: 45292 | F12: ← DD/MM/YYYY or DD Month YYYY
A13: =HYPERLINK("#'4.3.1.3-4 Direct N20'!A1", "4.3.1.3-4 Direct N2O") -> 4.3.1.3-4 Direct N2O | D13: Emissions calculation period end date | E13: =DATE(YEAR(E12)+1,MONTH(E12),DAY(E12))-1 -> 45657 | F13: ← Automatically calculated, 12 months after start date
A14: =HYPERLINK("#'4.3.1.5 Atmos Deposition'!A1", "4.3.1.5 Atmospheric deposition") -> 4.3.1.5 Atmospheric deposition
A15: =HYPERLINK("#'4.3.1.6-7 Leaching and runoff'!A1", "4.3.1.6-7 Leaching and runoff") -> 4.3.1.6-7 Leaching and runoff
A16: =HYPERLINK("#'4.3.1.8 Manure applied to soils'!A1", "4.3.1.8 Manure applied to soils") -> 4.3.1.8 Manure applied to soils | D16: Location and climate
A17: =HYPERLINK("#'4.3.1.9 Soil direct N2O'!A1", "4.3.1.9 Soil direct N2O") -> 4.3.1.9 Soil direct N2O
A18: =HYPERLINK("#'4.3.1.10-11 Soil Atmos Dep'!A1", "4.3.1.10-11 Soil atm. deposition") -> 4.3.1.10-11 Soil atm. deposition | D18: Location information is used to reference some region and climate-specific emission factors
A19: =HYPERLINK("#'4.3.1.12-13 Soil leach runoff'!A1", "4.3.1.12-13 Soil leach & runoff") -> 4.3.1.12-13 Soil leach & runoff | D19: Tip: Use the web-based GAF Location Helper tool to easily get region and climate information. You will need an internet connection to use the GAF Location Helper.
A21: APPENDICES | D21: State | E21: New South Wales | F21: ← Please select
A22: =HYPERLINK("#'Constants - Dairy'!A1", "Constants - Dairy") -> Constants - Dairy | D22: Region (ABS Statistical area level 4) if state is WA | E22: Western Australia - Outback (South) | F22: ← Please select
A23: =HYPERLINK("#'Constants - Livestock'!A1", "Constants - Livestock") -> Constants - Livestock | D23: Leaching zone | E23: NO - Not in leaching zone | F23: ← Please select
A24: =HYPERLINK("#'Constants - Common'!A1", "Constants - Common") -> Constants - Common | D24: Elevation | E24: 307.7 | F24: Meters
A25: =HYPERLINK("#'Acknowledgements'!A1", "Acknowledgements") -> Acknowledgements | D25: Average temperature for reporting period | E25: 18 | F25: Degrees celsius
D26: Total rainfall for reporting period | E26: 601 | F26: Millimetres
D27: Potential evapotranspiration for reporting period | E27: 1326 | F27: Millimetres
D28: Number of frost days for reporting period | E28: 7 | F28: Days
D29: MAP:PET ratio | E29: =E26/E27 -> 0.45324284
D30: Rainfall zone | E30: =Common_InputFunctions.Utility_LookupItemFromMinMax(E26,Table_SourceData_RainfallZones[Min rainfall],Table_SourceData_RainfallZones[Max rainfall],Table_SourceData_RainfallZones[Rainfall Zone]) -> High rainfall
D31: Climate zone | E31: =Common_InputFunctions.Utility_GetClimateZone(E25,E26,E28,E24,E29,Table_SourceData_ClimateZones[Min temp],Table_SourceData_ClimateZones[Max temp],Table_SourceData_ClimateZones[Min rainfall],Table_SourceData_ClimateZones[Max rainfall],Table_SourceData_ClimateZones[Min frost days],Table_SourceData_ClimateZones[Max frost days],Table_SourceData_ClimateZones[Min elevation],Table_SourceData_ClimateZones[Max elevation],Table_SourceData_ClimateZones[Min MAP:PET],Table_SourceData_ClimateZones[Max MAP:PET],Table_SourceData_ClimateZones[Climate zone]) -> Warm temperate dry
D32: Wet or dry climate zone | E32: =Common_InputFunctions.Utility_LookupValueInTable($E$31,Table_SourceData_WetDryZones[Climate zone],Table_SourceData_WetDryZones[Wet or Dry Zone]) -> Dry climate zone
D33: Temperature zone | E33: =Common_InputFunctions.Utility_LookupItemFromMinMax(E25,Table_SourceData_TemperatureZones[Min MAT],Table_SourceData_TemperatureZones[Max MAT],Table_SourceData_TemperatureZones[Temperature Zone]) -> Temperate

Sheet Input - Dairy
A1: #VALUE! | C1: Input -Dairy
A3: =HYPERLINK("#'Home'!A1", "Home") -> Home
A4: =HYPERLINK("#'Overview'!A1", "Overview") -> Overview
A5: =HYPERLINK("#'Results'!A1", "Results") -> Results | D5: Herd movement
A7: INPUTS | D7: Breed | E7: Medium Friesian | F7: ← Please select
A8: =HYPERLINK("#'Input - Site'!A1", "Site") -> Site
A9: =HYPERLINK("#'Input - Dairy'!A1", "Dairy") -> Dairy | E9: Milking cows | F9: Heifers > 1 year | G9: Heifers < 1 year | H9: Bulls > 1 year | I9: Bulls < 1 year
D10: ="Average number of head between " & TEXT('Input - Site'!$E$12, "dd mmm yy") & " and " & TEXT('Input - Site'!$E$13, "dd mmm yy") -> Average number of head between 01 Jan 24 and 31 Dec 24 | E10: 100 | F10: 100 | G10: 100 | H10: 100 | I10: 100 | J10: head
A11: CALCULATIONS
A12: =HYPERLINK("#'4.3.1.1-2 Methane'!A1", "4.3.1.1-2 Methane") -> 4.3.1.1-2 Methane | D12: Liveweight
A13: =HYPERLINK("#'4.3.1.3-4 Direct N20'!A1", "4.3.1.3-4 Direct N2O") -> 4.3.1.3-4 Direct N2O | D13: Method 1 default values (Do not edit) | E13: Milking cows | F13: Heifers > 1 year | G13: Heifers < 1 year | H13: Bulls > 1 year | I13: Bulls < 1 year
A14: =HYPERLINK("#'4.3.1.5 Atmos Deposition'!A1", "4.3.1.5 Atmospheric deposition") -> 4.3.1.5 Atmospheric deposition | D14: Average liveweight | E14: {=Common_InputFunctions.Utility_LookupValueInTableNumber($E$7, Table_SourceData_Dairy_WjCowsHeifers[Breed],Table_SourceData_Dairy_WjCowsHeifers[Milking cows])} -> 550 | F14: {=Common_InputFunctions.Utility_LookupValueInTableNumber($E$7, Table_SourceData_Dairy_WjCowsHeifers[Breed],Table_SourceData_Dairy_WjCowsHeifers[Heifers > 1])} -> 380 | G14: {=Common_InputFunctions.Utility_LookupValueInTableNumber($E$7, Table_SourceData_Dairy_WjCowsHeifers[Breed],Table_SourceData_Dairy_WjCowsHeifers[Heifers < 1 (weaned)])} -> 155 | H14: {=Table_SourceData_Dairy_WjBulls[Bulls > 1]} -> 600 | I14: {=Table_SourceData_Dairy_WjBulls[Bulls < 1 (weaned)]} -> 225 | J14: kg/head
A15: =HYPERLINK("#'4.3.1.6-7 Leaching and runoff'!A1", "4.3.1.6-7 Leaching and runoff") -> 4.3.1.6-7 Leaching and runoff | D15: Average liveweight gain | E15: {=Table_SourceData_Dairy_LWGj[Milking cows]} -> 0.016 | F15: {=Table_SourceData_Dairy_LWGj[Heifers > 1]} -> 0.6 | G15: {=Table_SourceData_Dairy_LWGj[Heifers < 1 (weaned)]} -> 0.57 | H15: {=Table_SourceData_Dairy_LWGj[Bulls > 1]} -> 0.1 | I15: {=Table_SourceData_Dairy_LWGj[Bulls < 1 (weaned)]} -> 0.8 | J15: kg/head/day
A16: =HYPERLINK("#'4.3.1.8 Manure applied to soils'!A1", "4.3.1.8 Manure applied to soils") -> 4.3.1.8 Manure applied to soils
A17: =HYPERLINK("#'4.3.1.9 Soil direct N2O'!A1", "4.3.1.9 Soil direct N2O") -> 4.3.1.9 Soil direct N2O | D17: Method 2 custom values (Edit if known) | E17: Milking cows | F17: Heifers > 1 year | G17: Heifers < 1 year | H17: Bulls > 1 year | I17: Bulls < 1 year
A18: =HYPERLINK("#'4.3.1.10-11 Soil Atmos Dep'!A1", "4.3.1.10-11 Soil atm. deposition") -> 4.3.1.10-11 Soil atm. deposition | D18: Average liveweight | E18: {=Common_InputFunctions.Utility_LookupValueInTableNumber($E$7, Table_SourceData_Dairy_WjCowsHeifers[Breed],Table_SourceData_Dairy_WjCowsHeifers[Milking cows])} -> 550 | F18: {=Common_InputFunctions.Utility_LookupValueInTableNumber($E$7, Table_SourceData_Dairy_WjCowsHeifers[Breed],Table_SourceData_Dairy_WjCowsHeifers[Heifers > 1])} -> 380 | G18: {=Common_InputFunctions.Utility_LookupValueInTableNumber($E$7, Table_SourceData_Dairy_WjCowsHeifers[Breed],Table_SourceData_Dairy_WjCowsHeifers[Heifers < 1 (weaned)])} -> 155 | H18: {=Table_SourceData_Dairy_WjBulls[Bulls > 1]} -> 600 | I18: {=Table_SourceData_Dairy_WjBulls[Bulls < 1 (weaned)]} -> 225 | J18: kg/head
A19: =HYPERLINK("#'4.3.1.12-13 Soil leach runoff'!A1", "4.3.1.12-13 Soil leach & runoff") -> 4.3.1.12-13 Soil leach & runoff | D19: Average liveweight gain | E19: {=Table_SourceData_Dairy_LWGj[Milking cows]} -> 0.016 | F19: {=Table_SourceData_Dairy_LWGj[Heifers > 1]} -> 0.6 | G19: {=Table_SourceData_Dairy_LWGj[Heifers < 1 (weaned)]} -> 0.57 | H19: {=Table_SourceData_Dairy_LWGj[Bulls > 1]} -> 0.1 | I19: {=Table_SourceData_Dairy_LWGj[Bulls < 1 (weaned)]} -> 0.8 | J19: kg/head/day
A21: APPENDICES | D21: Duration of stay
A22: =HYPERLINK("#'Constants - Dairy'!A1", "Constants - Dairy") -> Constants - Dairy
A23: =HYPERLINK("#'Constants - Livestock'!A1", "Constants - Livestock") -> Constants - Livestock | D23: Method 1 default values (Do not edit) | E23: Milking cows | F23: Heifers > 1 year | G23: Heifers < 1 year | H23: Bulls > 1 year | I23: Bulls < 1 year
A24: =HYPERLINK("#'Constants - Common'!A1", "Constants - Common") -> Constants - Common | D24: ="Average duration of stay between " & TEXT('Input - Site'!$E$12, "dd mmm yy") & " and " & TEXT('Input - Site'!$E$13, "dd mmm yy") & " weaned livestock" -> Average duration of stay between 01 Jan 24 and 31 Dec 24 weaned livestock | E24: {=Common_InputFunctions.Utility_LookupValueInTableNumber(E23,Table_SourceData_Dairy_Duration[Animal class j],Table_SourceData_Dairy_Duration[Duration (weaned)])} -> 365 | F24: {=Common_InputFunctions.Utility_LookupValueInTableNumber(F23,Table_SourceData_Dairy_Duration[Animal class j],Table_SourceData_Dairy_Duration[Duration (weaned)])} -> 365 | G24: {=Common_InputFunctions.Utility_LookupValueInTableNumber(G23,Table_SourceData_Dairy_Duration[Animal class j],Table_SourceData_Dairy_Duration[Duration (weaned)])} -> 281 | H24: {=Common_InputFunctions.Utility_LookupValueInTableNumber(H23,Table_SourceData_Dairy_Duration[Animal class j],Table_SourceData_Dairy_Duration[Duration (weaned)])} -> 365 | I24: {=Common_InputFunctions.Utility_LookupValueInTableNumber(I23,Table_SourceData_Dairy_Duration[Animal class j],Table_SourceData_Dairy_Duration[Duration (weaned)])} -> 281 | J24: Days
A25: =HYPERLINK("#'Acknowledgements'!A1", "Acknowledgements") -> Acknowledgements | D25: ="Average duration of stay between " & TEXT('Input - Site'!$E$12, "dd mmm yy") & " and " & TEXT('Input - Site'!$E$13, "dd mmm yy") & " pre-weaned livestock" -> Average duration of stay between 01 Jan 24 and 31 Dec 24 pre-weaned livestock | E25: {=Common_InputFunctions.Utility_LookupValueInTableNumber(E23,Table_SourceData_Dairy_Duration[Animal class j],Table_SourceData_Dairy_Duration[Duration (pre-weaned)])} -> 0 | F25: {=Common_InputFunctions.Utility_LookupValueInTableNumber(F23,Table_SourceData_Dairy_Duration[Animal class j],Table_SourceData_Dairy_Duration[Duration (pre-weaned)])} -> 0 | G25: {=Common_InputFunctions.Utility_LookupValueInTableNumber(G23,Table_SourceData_Dairy_Duration[Animal class j],Table_SourceData_Dairy_Duration[Duration (pre-weaned)])} -> 84 | H25: {=Common_InputFunctions.Utility_LookupValueInTableNumber(H23,Table_SourceData_Dairy_Duration[Animal class j],Table_SourceData_Dairy_Duration[Duration (pre-weaned)])} -> 0 | I25: {=Common_InputFunctions.Utility_LookupValueInTableNumber(I23,Table_SourceData_Dairy_Duration[Animal class j],Table_SourceData_Dairy_Duration[Duration (pre-weaned)])} -> 84 | J25: Days
D27: Method 2 custom values (Edit if known) | E27: Milking cows | F27: Heifers > 1 year | G27: Heifers < 1 year | H27: Bulls > 1 year | I27: Bulls < 1 year
D28: ="Average duration of stay between " & TEXT('Input - Site'!$E$12, "dd mmm yy") & " and " & TEXT('Input - Site'!$E$13, "dd mmm yy") & " weaned livestock" -> Average duration of stay between 01 Jan 24 and 31 Dec 24 weaned livestock | E28: {=Common_InputFunctions.Utility_LookupValueInTableNumber(E27,Table_SourceData_Dairy_Duration[Animal class j],Table_SourceData_Dairy_Duration[Duration (weaned)])} -> 365 | F28: {=Common_InputFunctions.Utility_LookupValueInTableNumber(F27,Table_SourceData_Dairy_Duration[Animal class j],Table_SourceData_Dairy_Duration[Duration (weaned)])} -> 365 | G28: {=Common_InputFunctions.Utility_LookupValueInTableNumber(G27,Table_SourceData_Dairy_Duration[Animal class j],Table_SourceData_Dairy_Duration[Duration (weaned)])} -> 281 | H28: {=Common_InputFunctions.Utility_LookupValueInTableNumber(H27,Table_SourceData_Dairy_Duration[Animal class j],Table_SourceData_Dairy_Duration[Duration (weaned)])} -> 365 | I28: {=Common_InputFunctions.Utility_LookupValueInTableNumber(I27,Table_SourceData_Dairy_Duration[Animal class j],Table_SourceData_Dairy_Duration[Duration (weaned)])} -> 281 | J28: Days
D29: ="Average duration of stay between " & TEXT('Input - Site'!$E$12, "dd mmm yy") & " and " & TEXT('Input - Site'!$E$13, "dd mmm yy") & " pre-weaned livestock" -> Average duration of stay between 01 Jan 24 and 31 Dec 24 pre-weaned livestock | E29: =365-E28 -> 0 | F29: =365-F28 -> 0 | G29: =365-G28 -> 84 | H29: =365-H28 -> 0 | I29: =365-I28 -> 84 | J29: Days
D33: Diet
D35: Method 1 default values (Do not edit) | E35: Milking cows | F35: Heifers > 1 year | G35: Heifers < 1 year | H35: Bulls > 1 year | I35: Bulls < 1 year
D36: Dry matter intake | E36: {=Common_InputFunctions.Utility_LookupValueInTableNumber(E35,Table_SourceData_Dairy_Duration[Animal class j],Table_SourceData_Dairy_Duration[Duration (weaned)])} -> 365 | F36: {=Common_InputFunctions.Utility_LookupValueInTableNumber(F35,Table_SourceData_Dairy_Duration[Animal class j],Table_SourceData_Dairy_Duration[Duration (weaned)])} -> 365 | G36: {=Common_InputFunctions.Utility_LookupValueInTableNumber(G35,Table_SourceData_Dairy_Duration[Animal class j],Table_SourceData_Dairy_Duration[Duration (weaned)])} -> 281 | H36: {=Common_InputFunctions.Utility_LookupValueInTableNumber(H35,Table_SourceData_Dairy_Duration[Animal class j],Table_SourceData_Dairy_Duration[Duration (weaned)])} -> 365 | I36: {=Common_InputFunctions.Utility_LookupValueInTableNumber(I35,Table_SourceData_Dairy_Duration[Animal class j],Table_SourceData_Dairy_Duration[Duration (weaned)])} -> 281 | J36: kgDM/head/day
D37: Dry matter digestibility | E37: ='Constants - Dairy'!$D$160 -> 0.75 | F37: ='Constants - Dairy'!$D$160 -> 0.75 | G37: ='Constants - Dairy'!$D$160 -> 0.75 | H37: ='Constants - Dairy'!$D$160 -> 0.75 | I37: ='Constants - Dairy'!$D$160 -> 0.75 | J37: Fraction
D38: Crude protein | E38: ='Constants - Dairy'!$D$153 -> 0.2 | F38: ='Constants - Dairy'!$D$153 -> 0.2 | G38: ='Constants - Dairy'!$D$153 -> 0.2 | H38: ='Constants - Dairy'!$D$153 -> 0.2 | I38: ='Constants - Dairy'!$D$153 -> 0.2 | J38: Fraction
D40: Method 2 custom values (Edit if known) | E40: Milking cows | F40: Heifers > 1 year | G40: Heifers < 1 year | H40: Bulls > 1 year | I40: Bulls < 1 year
D41: Dry matter intake | E41: {=Common_InputFunctions.Utility_LookupValueInTableNumber(E40,Table_SourceData_Dairy_Duration[Animal class j],Table_SourceData_Dairy_Duration[Duration (weaned)])} -> 365 | F41: {=Common_InputFunctions.Utility_LookupValueInTableNumber(F40,Table_SourceData_Dairy_Duration[Animal class j],Table_SourceData_Dairy_Duration[Duration (weaned)])} -> 365 | G41: {=Common_InputFunctions.Utility_LookupValueInTableNumber(G40,Table_SourceData_Dairy_Duration[Animal class j],Table_SourceData_Dairy_Duration[Duration (weaned)])} -> 281 | H41: {=Common_InputFunctions.Utility_LookupValueInTableNumber(H40,Table_SourceData_Dairy_Duration[Animal class j],Table_SourceData_Dairy_Duration[Duration (weaned)])} -> 365 | I41: {=Common_InputFunctions.Utility_LookupValueInTableNumber(I40,Table_SourceData_Dairy_Duration[Animal class j],Table_SourceData_Dairy_Duration[Duration (weaned)])} -> 281 | J41: kgDM/head/day
D42: Dry matter digestibility | E42: 0.75 | F42: 0.75 | G42: 0.75 | H42: 0.75 | I42: 0.75 | J42: Fraction
D43: Crude protein | E43: 0.2 | F43: 0.2 | G43: 0.2 | H43: 0.2 | I43: 0.2 | J43: Fraction
D47: Milk production
E48: Milking cows
D49: Average daily milk production | E49: 44 | F49: litres/head/day
D53: Production systems
D54: Time spent in production systems
D55: Production system template | E55: System 3: Pasture-grazed 3-9 months/year | F55: ← Please select
...

Sheet 4.3.1.1-2 Methane
A1: #VALUE! | C1: 4.3.1.1-2 Manure Methane
A3: =HYPERLINK("#'Home'!A1", "Home") -> Home | D3: Method 1 | O3: Method 2
A4: =HYPERLINK("#'Overview'!A1", "Overview") -> Overview
A5: =HYPERLINK("#'Results'!A1", "Results") -> Results | D5: {=EntericMethane_Dairy_Equations.VEERG_3_3_1_1__6_MetabolisabilityOfDiet_Title()} -> Metabolisability of diet
D6: {=EntericMethane_Dairy_Equations.VEERG_3_3_1_1__6_MetabolisabilityOfDiet_Source()} -> VEERG 2026: 3.3.1.1, Equation (6)
A7: INPUTS | D7: Function name | E7: {=Common_InputFunctions.Utility_DisplayFunctionName(D23)} -> =EntericMethane_Dairy_Equations.VEERG_3_3_1_1__6_MetabolisabilityOfDiet
A8: =HYPERLINK("#'Input - Site'!A1", "Site") -> Site
A9: =HYPERLINK("#'Input - Dairy'!A1", "Dairy") -> Dairy
D10: Variable | E10: {=EntericMethane_Dairy_Equations.VEERG_3_3_1_1__6_MetabolisabilityOfDiet_Variable()} -> qm_j
A11: CALCULATIONS | D11: Unit | E11: {=EntericMethane_Dairy_Equations.VEERG_3_3_1_1__6_MetabolisabilityOfDiet_Unit()} -> fraction
A12: =HYPERLINK("#'4.3.1.1-2 Methane'!A1", "4.3.1.1-2 Methane") -> 4.3.1.1-2 Methane
A13: =HYPERLINK("#'4.3.1.3-4 Direct N20'!A1", "4.3.1.3-4 Direct N2O") -> 4.3.1.3-4 Direct N2O | D13: {=_xlfn.CHOOSECOLS(EntericMethane_Dairy_Equations.VEERG_3_3_1_1__6_MetabolisabilityOfDiet_Arguments(), 1,2)} -> DMD_j | E13: dry matter digestibility expressed as a fraction | G13: {=_xlfn.CHOOSECOLS(EntericMethane_Dairy_Equations.VEERG_3_3_1_1__6_MetabolisabilityOfDiet_Arguments(), 3,4)} -> fraction | H13: Input | I13: ="See " & D15 -> See M1_Table_DMD_j
A14: =HYPERLINK("#'4.3.1.5 Atmos Deposition'!A1", "4.3.1.5 Atmospheric deposition") -> 4.3.1.5 Atmospheric deposition
A15: =HYPERLINK("#'4.3.1.6-7 Leaching and runoff'!A1", "4.3.1.6-7 Leaching and runoff") -> 4.3.1.6-7 Leaching and runoff | D15: M1_Table_DMD_j | O15: M2_Table_DMD_j
A16: =HYPERLINK("#'4.3.1.8 Manure applied to soils'!A1", "4.3.1.8 Manure applied to soils") -> 4.3.1.8 Manure applied to soils | D16: Dry matter digestibility (Method 1) | O16: Dry matter digestibility (Method 2)
A17: =HYPERLINK("#'4.3.1.9 Soil direct N2O'!A1", "4.3.1.9 Soil direct N2O") -> 4.3.1.9 Soil direct N2O | D17: Milking cows | E17: Heifers > 1 year | F17: Heifers < 1 year | G17: Bulls > 1 year | H17: Bulls < 1 year | O17: Milking cows | P17: Heifers > 1 year | Q17: Heifers < 1 year | R17: Bulls > 1 year | S17: Bulls < 1 year
A18: =HYPERLINK("#'4.3.1.10-11 Soil Atmos Dep'!A1", "4.3.1.10-11 Soil atm. deposition") -> 4.3.1.10-11 Soil atm. deposition | D18: ='Input - Dairy'!$E$37 -> 0.75 | E18: ='Input - Dairy'!$F$37 -> 0.75 | F18: ='Input - Dairy'!$G$37 -> 0.75 | G18: ='Input - Dairy'!$H$37 -> 0.75 | H18: ='Input - Dairy'!$I$37 -> 0.75 | I18: fraction | O18: ='Input - Dairy'!$E$42 -> 0.75 | P18: ='Input - Dairy'!$F$42 -> 0.75 | Q18: ='Input - Dairy'!$G$42 -> 0.75 | R18: ='Input - Dairy'!$H$42 -> 0.75 | S18: ='Input - Dairy'!$I$42 -> 0.75 | T18: fraction
A19: =HYPERLINK("#'4.3.1.12-13 Soil leach runoff'!A1", "4.3.1.12-13 Soil leach & runoff") -> 4.3.1.12-13 Soil leach & runoff
D20: M1_Table_qm_j | O20: M2_Table_qm_j
A21: APPENDICES | D21: Metabolisability of diet (Method 1) | O21: Metabolisability of diet (Method 2)
A22: =HYPERLINK("#'Constants - Dairy'!A1", "Constants - Dairy") -> Constants - Dairy | D22: Milking cows | E22: Heifers > 1 year | F22: Heifers < 1 year | G22: Bulls > 1 year | H22: Bulls < 1 year | O22: Milking cows | P22: Heifers > 1 year | Q22: Heifers < 1 year | R22: Bulls > 1 year | S22: Bulls < 1 year
A23: =HYPERLINK("#'Constants - Livestock'!A1", "Constants - Livestock") -> Constants - Livestock | D23: {=EntericMethane_Dairy_Equations.VEERG_3_3_1_1__6_MetabolisabilityOfDiet(D18)} -> 59.6236 | E23: {=EntericMethane_Dairy_Equations.VEERG_3_3_1_1__6_MetabolisabilityOfDiet(E18)} -> 59.6236 | F23: {=EntericMethane_Dairy_Equations.VEERG_3_3_1_1__6_MetabolisabilityOfDiet(F18)} -> 59.6236 | G23: {=EntericMethane_Dairy_Equations.VEERG_3_3_1_1__6_MetabolisabilityOfDiet(G18)} -> 59.6236 | H23: {=EntericMethane_Dairy_Equations.VEERG_3_3_1_1__6_MetabolisabilityOfDiet(H18)} -> 59.6236 | I23: =$E$11 -> fraction | O23: {=EntericMethane_Dairy_Equations.VEERG_3_3_1_1__6_MetabolisabilityOfDiet(O18)} -> 59.6236 | P23: {=EntericMethane_Dairy_Equations.VEERG_3_3_1_1__6_MetabolisabilityOfDiet(P18)} -> 59.6236 | Q23: {=EntericMethane_Dairy_Equations.VEERG_3_3_1_1__6_MetabolisabilityOfDiet(Q18)} -> 59.6236 | R23: {=EntericMethane_Dairy_Equations.VEERG_3_3_1_1__6_MetabolisabilityOfDiet(R18)} -> 59.6236 | S23: {=EntericMethane_Dairy_Equations.VEERG_3_3_1_1__6_MetabolisabilityOfDiet(S18)} -> 59.6236 | T23: =$E$11 -> fraction
A24: =HYPERLINK("#'Constants - Common'!A1", "Constants - Common") -> Constants - Common
A25: =HYPERLINK("#'Acknowledgements'!A1", "Acknowledgements") -> Acknowledgements
D27: {=EntericMethane_Dairy_Equations.VEERG_3_3_1_1__4_AdditionalIntakeForMilkProduction_Title()} -> Additional intake required for milk production
D28: {=EntericMethane_Dairy_Equations.VEERG_3_3_1_1__4_AdditionalIntakeForMilkProduction_Source()} -> VEERG 2026: 3.3.1.1, Equation (4)
D29: Function name | E29: {=Common_InputFunctions.Utility_DisplayFunctionName(D49)} -> =EntericMethane_Dairy_Equations.VEERG_3_3_1_1__4_AdditionalIntakeForMilkProduction
D32: Variable | E32: {=EntericMethane_Dairy_Equations.VEERG_3_3_1_1__4_AdditionalIntakeForMilkProduction_Variable()} -> MI_j
D33: Unit | E33: {=EntericMethane_Dairy_Equations.VEERG_3_3_1_1__4_AdditionalIntakeForMilkProduction_Unit()} -> kg DM/head/day
D35: {=_xlfn.CHOOSECOLS(EntericMethane_Dairy_Equations.VEERG_3_3_1_1__4_AdditionalIntakeForMilkProduction_Arguments(), 1,2)} -> MP_j | E35: milk production | G35: {=_xlfn.CHOOSECOLS(EntericMethane_Dairy_Equations.VEERG_3_3_1_1__4_AdditionalIntakeForMilkProduction_Arguments(), 3,4)} -> L/head/day | H35: Input | I35: {=HYPERLINK(Common_InputFunctions.Utility_SourceHyperlink($D$41), $D$41)} -> Table_MP_j
D36: NE | E36: net energy | G36: MJ net energy/kg milk | H36: Constant | I36: ='Constants - Dairy'!$D$167 -> 3.054
D37: GEC | E37: gross energy content | G37: MJ/kgDM | H37: Constant | I37: ='Constants - Dairy'!$D$174 -> 18.4
D38: k | E38: efficiency of metabolizable energy use for milk production | G38: fraction | H38: Constant | I38: ='Constants - Dairy'!$D$181 -> 0.6
D39: qm_j | E39: metabolisability of the diet | G39: fraction | H39: Calculated from 3.3.1.1 (6) | I39: {=HYPERLINK(Common_InputFunctions.Utility_SourceHyperlink($D$20), $D$20)} -> M1_Table_qm_j
D41: Table_MP_j
D42: Milk production
D43: Milking cows | E43: Heifers > 1 year | F43: Heifers < 1 year | G43: Bulls > 1 year | H43: Bulls < 1 year
D44: ='Input - Dairy'!$E$49 -> 44 | E44: 0 | F44: 0 | G44: 0 | H44: 0 | I44: L/head/day
D46: M1_Table_MI_j | O46: M2_Table_MI_j
D47: Additional intake for milk production (Method 1) | O47: Additional intake for milk production (Method 2)
...

Sheet 4.3.1.3-4 Direct N20
A1: #VALUE! | C1: 4.3.1.3-4 Manure Direct N2O
A3: =HYPERLINK("#'Home'!A1", "Home") -> Home | D3: Method 1 | N3: Method 2
A4: =HYPERLINK("#'Overview'!A1", "Overview") -> Overview
A5: =HYPERLINK("#'Results'!A1", "Results") -> Results | D5: {=MMS_Dairy_N2ODirect_Equations.VEERG_4_3_1_3__8_RelativeSize_Title()} -> Relative size
D6: {=MMS_Dairy_N2ODirect_Equations.VEERG_4_3_1_3__8_RelativeSize_Source()} -> VEERG 2026: 4.3.1.3, Equation (8)
A7: INPUTS | D7: Function name | E7: {=Common_InputFunctions.Utility_DisplayFunctionName(D29)} -> =MMS_Dairy_N2ODirect_Equations.VEERG_4_3_1_3__8_RelativeSize
A8: =HYPERLINK("#'Input - Site'!A1", "Site") -> Site
A9: =HYPERLINK("#'Input - Dairy'!A1", "Dairy") -> Dairy
D10: Variable | E10: {=MMS_Dairy_N2ODirect_Equations.VEERG_4_3_1_3__8_RelativeSize_Variable()} -> Z_j
A11: CALCULATIONS | D11: Unit | E11: {=MMS_Dairy_N2ODirect_Equations.VEERG_4_3_1_3__8_RelativeSize_Unit()} -> ratio
A12: =HYPERLINK("#'4.3.1.1-2 Methane'!A1", "4.3.1.1-2 Methane") -> 4.3.1.1-2 Methane
A13: =HYPERLINK("#'4.3.1.3-4 Direct N20'!A1", "4.3.1.3-4 Direct N2O") -> 4.3.1.3-4 Direct N2O | D13: {=_xlfn.CHOOSECOLS(MMS_Dairy_N2ODirect_Equations.VEERG_4_3_1_3__8_RelativeSize_Arguments(),1,2)} -> W_j | E13: liveweight | F13: {=_xlfn.CHOOSECOLS(MMS_Dairy_N2ODirect_Equations.VEERG_4_3_1_3__8_RelativeSize_Arguments(),3,4)} -> kg/head | G13: Input | H13: {=HYPERLINK(Common_InputFunctions.Utility_SourceHyperlink($D$16),$D$16)} -> M1_Table_W_j
A14: =HYPERLINK("#'4.3.1.5 Atmos Deposition'!A1", "4.3.1.5 Atmospheric deposition") -> 4.3.1.5 Atmospheric deposition | D14: WR_j | E14: reference weight | F14: kg/head | G14: Constant | H14: {=HYPERLINK(Common_InputFunctions.Utility_SourceHyperlink($D$21),$D$21)} -> Table_WR_j
A15: =HYPERLINK("#'4.3.1.6-7 Leaching and runoff'!A1", "4.3.1.6-7 Leaching and runoff") -> 4.3.1.6-7 Leaching and runoff
A16: =HYPERLINK("#'4.3.1.8 Manure applied to soils'!A1", "4.3.1.8 Manure applied to soils") -> 4.3.1.8 Manure applied to soils | D16: M1_Table_W_j | N16: M2_Table_W_j
A17: =HYPERLINK("#'4.3.1.9 Soil direct N2O'!A1", "4.3.1.9 Soil direct N2O") -> 4.3.1.9 Soil direct N2O | D17: Liveweight for each animal class j (Method 1) | N17: Liveweight for each animal class j (Method 2)
A18: =HYPERLINK("#'4.3.1.10-11 Soil Atmos Dep'!A1", "4.3.1.10-11 Soil atm. deposition") -> 4.3.1.10-11 Soil atm. deposition | D18: Milking cows | E18: Heifers > 1 year | F18: Heifers < 1 year | G18: Bulls > 1 year | H18: Bulls < 1 year | N18: Milking cows | O18: Heifers > 1 year | P18: Heifers < 1 year | Q18: Bulls > 1 year | R18: Bulls < 1 year
A19: =HYPERLINK("#'4.3.1.12-13 Soil leach runoff'!A1", "4.3.1.12-13 Soil leach & runoff") -> 4.3.1.12-13 Soil leach & runoff | D19: ='Input - Dairy'!$E$14 -> 550 | E19: ='Input - Dairy'!$F$14 -> 380 | F19: ='Input - Dairy'!$G$14 -> 155 | G19: ='Input - Dairy'!$H$14 -> 600 | H19: ='Input - Dairy'!$I$14 -> 225 | I19: kg/head | N19: ='Input - Dairy'!$E$18 -> 550 | O19: ='Input - Dairy'!$F$18 -> 380 | P19: ='Input - Dairy'!$G$18 -> 155 | Q19: ='Input - Dairy'!$H$18 -> 600 | R19: ='Input - Dairy'!$I$18 -> 225 | S19: kg/head
A21: APPENDICES | D21: Table_WR_j
A22: =HYPERLINK("#'Constants - Dairy'!A1", "Constants - Dairy") -> Constants - Dairy | D22: Reference weight for each animal class
A23: =HYPERLINK("#'Constants - Livestock'!A1", "Constants - Livestock") -> Constants - Livestock | D23: Milking cows | E23: Heifers > 1 year | F23: Heifers < 1 year | G23: Bulls > 1 year | H23: Bulls < 1 year
A24: =HYPERLINK("#'Constants - Common'!A1", "Constants - Common") -> Constants - Common | D24: {=Table_SourceData_Dairy_WRj[Milking cows]} -> 590 | E24: {=Table_SourceData_Dairy_WRj[Heifers > 1]} -> 590 | F24: {=Table_SourceData_Dairy_WRj[Heifers < 1 (weaned)]} -> 590 | G24: {=Table_SourceData_Dairy_WRj[Bulls > 1]} -> 770 | H24: {=Table_SourceData_Dairy_WRj[Bulls < 1 (weaned)]} -> 770 | I24: kg/head
A25: =HYPERLINK("#'Acknowledgements'!A1", "Acknowledgements") -> Acknowledgements
D26: M1_Table_Z_j | N26: M1_Table_Z_j
D27: Relative size for each animal class (Method 1) | N27: Relative size for each animal class (Method 1)
D28: Milking cows | E28: Heifers > 1 year | F28: Heifers < 1 year | G28: Bulls > 1 year | H28: Bulls < 1 year | N28: Milking cows | O28: Heifers > 1 year | P28: Heifers < 1 year | Q28: Bulls > 1 year | R28: Bulls < 1 year
D29: {=MMS_Dairy_N2ODirect_Equations.VEERG_4_3_1_3__8_RelativeSize(D19,D24)} -> 0.93220339 | E29: {=MMS_Dairy_N2ODirect_Equations.VEERG_4_3_1_3__8_RelativeSize(E19,E24)} -> 0.6440678 | F29: {=MMS_Dairy_N2ODirect_Equations.VEERG_4_3_1_3__8_RelativeSize(F19,F24)} -> 0.26271186 | G29: {=MMS_Dairy_N2ODirect_Equations.VEERG_4_3_1_3__8_RelativeSize(G19,G24)} -> 0.77922078 | H29: {=MMS_Dairy_N2ODirect_Equations.VEERG_4_3_1_3__8_RelativeSize(H19,H24)} -> 0.29220779 | I29: =$E$11 -> ratio | N29: {=MMS_Dairy_N2ODirect_Equations.VEERG_4_3_1_3__8_RelativeSize(N19,D24)} -> 0.93220339 | O29: {=MMS_Dairy_N2ODirect_Equations.VEERG_4_3_1_3__8_RelativeSize(O19,E24)} -> 0.6440678 | P29: {=MMS_Dairy_N2ODirect_Equations.VEERG_4_3_1_3__8_RelativeSize(P19,F24)} -> 0.26271186 | Q29: {=MMS_Dairy_N2ODirect_Equations.VEERG_4_3_1_3__8_RelativeSize(Q19,G24)} -> 0.77922078 | R29: {=MMS_Dairy_N2ODirect_Equations.VEERG_4_3_1_3__8_RelativeSize(R19,H24)} -> 0.29220779 | S29: =$E$11 -> ratio
D33: {=MMS_Dairy_N2ODirect_Equations.VEERG_4_3_1_3__7_IntakeRelativeToMaintenance_Title()} -> Intake relative to maintenance
D34: {=MMS_Dairy_N2ODirect_Equations.VEERG_4_3_1_3__7_IntakeRelativeToMaintenance_Source()} -> VEERG 2026: 4.3.1.3, Equation (7)
D35: Function name | E35: {=Common_InputFunctions.Utility_DisplayFunctionName(D65)} -> =MMS_Dairy_N2ODirect_Equations.VEERG_4_3_1_3__7_IntakeRelativeToMaintenance
D39: Variable | E39: {=MMS_Dairy_N2ODirect_Equations.VEERG_4_3_1_3__7_IntakeRelativeToMaintenance_Variable()} -> L_j
D40: Unit | E40: {=MMS_Dairy_N2ODirect_Equations.VEERG_4_3_1_3__7_IntakeRelativeToMaintenance_Unit()} -> ratio
D42: {=_xlfn.CHOOSECOLS(MMS_Dairy_N2ODirect_Equations.VEERG_4_3_1_3__7_IntakeRelativeToMaintenance_Arguments(),1,2)} -> I_j | E42: dry matter intake | G42: {=_xlfn.CHOOSECOLS(MMS_Dairy_N2ODirect_Equations.VEERG_4_3_1_3__7_IntakeRelativeToMaintenance_Arguments(),3,4)} -> kgDM/head/day | H42: Calculated from 3.3.1.1 (3) | I42: {=HYPERLINK(Common_InputFunctions.Utility_SourceHyperlink($D$47),$D$47)} -> M1_Table_I_j
D43: W_j | E43: liveweight | G43: kg/head | H43: Input | I43: {=HYPERLINK(Common_InputFunctions.Utility_SourceHyperlink($D$16),$D$16)} -> M1_Table_W_j
D44: MR_j | E44: increase in metabolic rate when producing milk | H44: Constant | I44: {=HYPERLINK(Common_InputFunctions.Utility_SourceHyperlink($D$52),$D$52)} -> Table_MR_j
D45: MI_j | E45: additional intake required for milk production | G45: kgDM/head/day | H45: Calculated from 3.3.1.1 (4) | I45: {=HYPERLINK(Common_InputFunctions.Utility_SourceHyperlink($D$57),$D$57)} -> M1_Table_MI_j
D47: M1_Table_I_j | N47: M2_Table_I_j
D48: Feed intake (Method 1) | N48: Feed intake (Method 2)
D49: Milking cows | E49: Heifers > 1 year | F49: Heifers < 1 year | G49: Bulls > 1 year | H49: Bulls < 1 year | N49: Milking cows | O49: Heifers > 1 year | P49: Heifers < 1 year | Q49: Bulls > 1 year | R49: Bulls < 1 year
D50: ='4.3.1.1-2 Methane'!D84 -> 9.4647128 | E50: ='4.3.1.1-2 Methane'!E84 -> 7.4188685 | F50: ='4.3.1.1-2 Methane'!F84 -> 4.0231735 | G50: ='4.3.1.1-2 Methane'!G84 -> 9.0270202 | H50: ='4.3.1.1-2 Methane'!H84 -> 5.4143473 | I50: =G42 -> kgDM/head/day | N50: ='4.3.1.1-2 Methane'!O84 -> 9.4647128 | O50: ='4.3.1.1-2 Methane'!P84 -> 7.4188685 | P50: ='4.3.1.1-2 Methane'!Q84 -> 4.0231735 | Q50: ='4.3.1.1-2 Methane'!R84 -> 9.0270202 | R50: ='4.3.1.1-2 Methane'!S84 -> 5.4143473 | S50: ='4.3.1.1-2 Methane'!T84 -> kg DM/head/day
...

Sheet 4.3.1.5 Atmos deposition
A1: #VALUE! | C1: 4.3.1.5 Manure Atmospheric Deposition
A3: =HYPERLINK("#'Home'!A1", "Home") -> Home | D3: Method 1 | O3: Method 2
A4: =HYPERLINK("#'Overview'!A1", "Overview") -> Overview
A5: =HYPERLINK("#'Results'!A1", "Results") -> Results | D5: {=MMS_Dairy_AtmosphericDeposition_Equations.VEERG_4_3_1_5__2_TotalNitrogenVolatilisedFromMMS_Title()} -> Total nitrogen volatilised from MMS
D6: {=MMS_Dairy_AtmosphericDeposition_Equations.VEERG_4_3_1_5__2_TotalNitrogenVolatilisedFromMMS_Source()} -> VEERG 2026: 4.3.1.5, Equation (2)
A7: INPUTS | D7: Function name | E7: {=Common_InputFunctions.Utility_DisplayFunctionName(F40)} -> =MMS_Dairy_AtmosphericDeposition_Equations.VEERG_4_3_1_5__2_TotalNitrogenVolatilisedFromMMS
A8: =HYPERLINK("#'Input - Site'!A1", "Site") -> Site
A9: =HYPERLINK("#'Input - Dairy'!A1", "Dairy") -> Dairy
D10: Variable | E10: {=MMS_Dairy_AtmosphericDeposition_Equations.VEERG_4_3_1_5__2_TotalNitrogenVolatilisedFromMMS_Variable()} -> MN_ATMOS
A11: CALCULATIONS | D11: Unit | E11: {=MMS_Dairy_AtmosphericDeposition_Equations.VEERG_4_3_1_5__2_TotalNitrogenVolatilisedFromMMS_Unit()} -> kg N
A12: =HYPERLINK("#'4.3.1.1-2 Methane'!A1", "4.3.1.1-2 Methane") -> 4.3.1.1-2 Methane
A13: =HYPERLINK("#'4.3.1.3-4 Direct N20'!A1", "4.3.1.3-4 Direct N2O") -> 4.3.1.3-4 Direct N2O | D13: {=_xlfn.CHOOSECOLS(MMS_Dairy_AtmosphericDeposition_Equations.VEERG_4_3_1_5__2_TotalNitrogenVolatilisedFromMMS_Arguments(),1,2)} -> MN_jm | E13: total nitrogen in each MMS for dairy cattle classes | G13: {=_xlfn.CHOOSECOLS(MMS_Dairy_AtmosphericDeposition_Equations.VEERG_4_3_1_5__2_TotalNitrogenVolatilisedFromMMS_Arguments(),3,4)} -> kg N | H13: Calculated from 4.3.1.3 (2) | I13: {=HYPERLINK(Common_InputFunctions.Utility_SourceHyperlink(D$16),D$16)} -> M1_Table_MN_j_m
A14: =HYPERLINK("#'4.3.1.5 Atmos Deposition'!A1", "4.3.1.5 Atmospheric deposition") -> 4.3.1.5 Atmospheric deposition | D14: FracGASM_m | E14: fraction of N volatilised from MMS | G14: fraction | H14: Constant | I14: {=HYPERLINK(Common_InputFunctions.Utility_SourceHyperlink($D$28),$D$28)} -> Table_FracGASM_m
A15: =HYPERLINK("#'4.3.1.6-7 Leaching and runoff'!A1", "4.3.1.6-7 Leaching and runoff") -> 4.3.1.6-7 Leaching and runoff
A16: =HYPERLINK("#'4.3.1.8 Manure applied to soils'!A1", "4.3.1.8 Manure applied to soils") -> 4.3.1.8 Manure applied to soils | D16: M1_Table_MN_j_m | O16: M2_Table_MN_j_m
A17: =HYPERLINK("#'4.3.1.9 Soil direct N2O'!A1", "4.3.1.9 Soil direct N2O") -> 4.3.1.9 Soil direct N2O | D17: Total nitrogen in each MMS (Method 1) | O17: Total nitrogen in each MMS (Method 2)
A18: =HYPERLINK("#'4.3.1.10-11 Soil Atmos Dep'!A1", "4.3.1.10-11 Soil atm. deposition") -> 4.3.1.10-11 Soil atm. deposition | D18: Production system | E18: MMS | F18: Milking cows | G18: Heifers > 1 year | H18: Heifers < 1 year | I18: Bulls > 1 year | J18: Bulls < 1 year | O18: Production system | P18: MMS | Q18: Milking cows | R18: Heifers > 1 year | S18: Heifers < 1 year | T18: Bulls > 1 year | U18: Bulls < 1 year
A19: =HYPERLINK("#'4.3.1.12-13 Soil leach runoff'!A1", "4.3.1.12-13 Soil leach & runoff") -> 4.3.1.12-13 Soil leach & runoff | D19: ='Input - Dairy'!$D$59 -> Milking shed | E19: ='Input - Dairy'!$D$78 -> Anaerobic lagoon | F19: ='4.3.1.3-4 Direct N20'!$F$236 -> 212.24813 | G19: ='4.3.1.3-4 Direct N20'!$G$236 -> 182.3579 | H19: ='4.3.1.3-4 Direct N20'!$H$236 -> 72.631224 | I19: ='4.3.1.3-4 Direct N20'!$I$236 -> 229.2311 | J19: ='4.3.1.3-4 Direct N20'!$J$236 -> 95.962857 | K19: =$G$13 -> kg N | O19: ='Input - Dairy'!$D$59 -> Milking shed | P19: ='Input - Dairy'!$D$78 -> Anaerobic lagoon | Q19: ='4.3.1.3-4 Direct N20'!$P$236 -> 212.24813 | R19: ='4.3.1.3-4 Direct N20'!$Q$236 -> 182.3579 | S19: ='4.3.1.3-4 Direct N20'!$R$236 -> 72.631224 | T19: ='4.3.1.3-4 Direct N20'!$S$236 -> 229.2311 | U19: ='4.3.1.3-4 Direct N20'!$T$236 -> 95.962857 | V19: =$G$13 -> kg N
D20: ='Input - Dairy'!$D$59 -> Milking shed | E20: ='Input - Dairy'!$D$79 -> Sump and dispersal system | F20: ='4.3.1.3-4 Direct N20'!$F$237 -> 212.24813 | G20: ='4.3.1.3-4 Direct N20'!$G$237 -> 182.3579 | H20: ='4.3.1.3-4 Direct N20'!$H$237 -> 72.631224 | I20: ='4.3.1.3-4 Direct N20'!$I$237 -> 229.2311 | J20: ='4.3.1.3-4 Direct N20'!$J$237 -> 95.962857 | O20: ='Input - Dairy'!$D$59 -> Milking shed | P20: ='Input - Dairy'!$D$79 -> Sump and dispersal system | Q20: ='4.3.1.3-4 Direct N20'!$P$237 -> 212.24813 | R20: ='4.3.1.3-4 Direct N20'!$Q$237 -> 182.3579 | S20: ='4.3.1.3-4 Direct N20'!$R$237 -> 72.631224 | T20: ='4.3.1.3-4 Direct N20'!$S$237 -> 229.2311 | U20: ='4.3.1.3-4 Direct N20'!$T$237 -> 95.962857
A21: APPENDICES | D21: ='Input - Dairy'!$D$59 -> Milking shed | E21: ='Input - Dairy'!$D$80 -> Drains to paddock | F21: ='4.3.1.3-4 Direct N20'!$F$238 -> 212.24813 | G21: ='4.3.1.3-4 Direct N20'!$G$238 -> 182.3579 | H21: ='4.3.1.3-4 Direct N20'!$H$238 -> 72.631224 | I21: ='4.3.1.3-4 Direct N20'!$I$238 -> 229.2311 | J21: ='4.3.1.3-4 Direct N20'!$J$238 -> 95.962857 | O21: ='Input - Dairy'!$D$59 -> Milking shed | P21: ='Input - Dairy'!$D$80 -> Drains to paddock | Q21: ='4.3.1.3-4 Direct N20'!$P$238 -> 212.24813 | R21: ='4.3.1.3-4 Direct N20'!$Q$238 -> 182.3579 | S21: ='4.3.1.3-4 Direct N20'!$R$238 -> 72.631224 | T21: ='4.3.1.3-4 Direct N20'!$S$238 -> 229.2311 | U21: ='4.3.1.3-4 Direct N20'!$T$238 -> 95.962857
A22: =HYPERLINK("#'Constants - Dairy'!A1", "Constants - Dairy") -> Constants - Dairy | D22: ='Input - Dairy'!$D$59 -> Milking shed | E22: Solid storage | F22: ='4.3.1.3-4 Direct N20'!$F$239 -> 424.49627 | G22: ='4.3.1.3-4 Direct N20'!$G$239 -> 364.71581 | H22: ='4.3.1.3-4 Direct N20'!$H$239 -> 145.26245 | I22: ='4.3.1.3-4 Direct N20'!$I$239 -> 458.46219 | J22: ='4.3.1.3-4 Direct N20'!$J$239 -> 191.92571 | O22: ='Input - Dairy'!$D$59 -> Milking shed | P22: Solid storage | Q22: ='4.3.1.3-4 Direct N20'!$P$239 -> 424.49627 | R22: ='4.3.1.3-4 Direct N20'!$Q$239 -> 364.71581 | S22: ='4.3.1.3-4 Direct N20'!$R$239 -> 145.26245 | T22: ='4.3.1.3-4 Direct N20'!$S$239 -> 458.46219 | U22: ='4.3.1.3-4 Direct N20'!$T$239 -> 191.92571
A23: =HYPERLINK("#'Constants - Livestock'!A1", "Constants - Livestock") -> Constants - Livestock | D23: ='Input - Dairy'!$D$60 -> Feed pad | E23: ='Input - Dairy'!$D$94 -> Anaerobic lagoon | F23: ='4.3.1.3-4 Direct N20'!$F$240 -> 858.64017 | G23: ='4.3.1.3-4 Direct N20'!$G$240 -> 737.72061 | H23: ='4.3.1.3-4 Direct N20'!$H$240 -> 293.82632 | I23: ='4.3.1.3-4 Direct N20'!$I$240 -> 927.34398 | J23: ='4.3.1.3-4 Direct N20'!$J$240 -> 388.21338 | O23: ='Input - Dairy'!$D$60 -> Feed pad | P23: ='Input - Dairy'!$D$94 -> Anaerobic lagoon | Q23: ='4.3.1.3-4 Direct N20'!$P$240 -> 858.64017 | R23: ='4.3.1.3-4 Direct N20'!$Q$240 -> 737.72061 | S23: ='4.3.1.3-4 Direct N20'!$R$240 -> 293.82632 | T23: ='4.3.1.3-4 Direct N20'!$S$240 -> 927.34398 | U23: ='4.3.1.3-4 Direct N20'!$T$240 -> 388.21338
A24: =HYPERLINK("#'Constants - Common'!A1", "Constants - Common") -> Constants - Common | D24: ='Input - Dairy'!$D$60 -> Feed pad | E24: ='Input - Dairy'!$D$95 -> Sump and dispersal system | F24: ='4.3.1.3-4 Direct N20'!$F$241 -> 686.91214 | G24: ='4.3.1.3-4 Direct N20'!$G$241 -> 590.17649 | H24: ='4.3.1.3-4 Direct N20'!$H$241 -> 235.06105 | I24: ='4.3.1.3-4 Direct N20'!$I$241 -> 741.87518 | J24: ='4.3.1.3-4 Direct N20'!$J$241 -> 310.5707 | O24: ='Input - Dairy'!$D$60 -> Feed pad | P24: ='Input - Dairy'!$D$95 -> Sump and dispersal system | Q24: ='4.3.1.3-4 Direct N20'!$P$241 -> 686.91214 | R24: ='4.3.1.3-4 Direct N20'!$Q$241 -> 590.17649 | S24: ='4.3.1.3-4 Direct N20'!$R$241 -> 235.06105 | T24: ='4.3.1.3-4 Direct N20'!$S$241 -> 741.87518 | U24: ='4.3.1.3-4 Direct N20'!$T$241 -> 310.5707
A25: =HYPERLINK("#'Acknowledgements'!A1", "Acknowledgements") -> Acknowledgements | D25: ='Input - Dairy'!$D$60 -> Feed pad | E25: ='Input - Dairy'!$D$96 -> Drains to paddock | F25: ='4.3.1.3-4 Direct N20'!$F$242 -> 686.91214 | G25: ='4.3.1.3-4 Direct N20'!$G$242 -> 590.17649 | H25: ='4.3.1.3-4 Direct N20'!$H$242 -> 235.06105 | I25: ='4.3.1.3-4 Direct N20'!$I$242 -> 741.87518 | J25: ='4.3.1.3-4 Direct N20'!$J$242 -> 310.5707 | O25: ='Input - Dairy'!$D$60 -> Feed pad | P25: ='Input - Dairy'!$D$96 -> Drains to paddock | Q25: ='4.3.1.3-4 Direct N20'!$P$242 -> 686.91214 | R25: ='4.3.1.3-4 Direct N20'!$Q$242 -> 590.17649 | S25: ='4.3.1.3-4 Direct N20'!$R$242 -> 235.06105 | T25: ='4.3.1.3-4 Direct N20'!$S$242 -> 741.87518 | U25: ='4.3.1.3-4 Direct N20'!$T$242 -> 310.5707
D26: ='Input - Dairy'!$D$60 -> Feed pad | E26: Solid storage | F26: ='4.3.1.3-4 Direct N20'!$F$243 -> 1202.0962 | G26: ='4.3.1.3-4 Direct N20'!$G$243 -> 1032.8088 | H26: ='4.3.1.3-4 Direct N20'!$H$243 -> 411.35684 | I26: ='4.3.1.3-4 Direct N20'!$I$243 -> 1298.2816 | J26: ='4.3.1.3-4 Direct N20'!$J$243 -> 543.49873 | O26: ='Input - Dairy'!$D$60 -> Feed pad | P26: Solid storage | Q26: ='4.3.1.3-4 Direct N20'!$P$243 -> 1202.0962 | R26: ='4.3.1.3-4 Direct N20'!$Q$243 -> 1032.8088 | S26: ='4.3.1.3-4 Direct N20'!$R$243 -> 411.35684 | T26: ='4.3.1.3-4 Direct N20'!$S$243 -> 1298.2816 | U26: ='4.3.1.3-4 Direct N20'!$T$243 -> 543.49873
D28: Table_FracGASM_m
D29: Fraction N volatilised from each MS
D30: MMS | E30: FracGASMm
D31: {=Table_SourceData_Dairy_EFmFracGASM[NIR reference]} -> Pasture range and paddock | E31: {=Table_SourceData_Dairy_EFmFracGASM[FracGASMm]} -> 0 | F31: =G14 -> fraction
D32: Anaerobic lagoon | E32: 0.35
D33: Sump and dispersal system | E33: 0.07
D34: Drains to paddock | E34: 0.2
D35: Solid storage | E35: 0.3
D37: M1_Table_MN_atmos | O37: M2_Table_MN_atmos
D38: Total nitrogen volatilised from each MMS (Method 1) | O38: Total nitrogen volatilised from each MMS (Method 2)
D39: Production system | E39: MMS | F39: Milking cows | G39: Heifers > 1 year | H39: Heifers < 1 year | I39: Bulls > 1 year | J39: Bulls < 1 year | O39: Production system | P39: MMS | Q39: Milking cows | R39: Heifers > 1 year | S39: Heifers < 1 year | T39: Bulls > 1 year | U39: Bulls < 1 year
D40: ='Input - Dairy'!$D$59 -> Milking shed | E40: ='Input - Dairy'!$D$78 -> Anaerobic lagoon | F40: {=MMS_Dairy_AtmosphericDeposition_Equations.VEERG_4_3_1_5__2_TotalNitrogenVolatilisedFromMMS(F19,$E32)} -> 74.286847 | G40: {=MMS_Dairy_AtmosphericDeposition_Equations.VEERG_4_3_1_5__2_TotalNitrogenVolatilisedFromMMS(G19,$E32)} -> 63.825266 | H40: {=MMS_Dairy_AtmosphericDeposition_Equations.VEERG_4_3_1_5__2_TotalNitrogenVolatilisedFromMMS(H19,$E32)} -> 25.420928 | I40: {=MMS_Dairy_AtmosphericDeposition_Equations.VEERG_4_3_1_5__2_TotalNitrogenVolatilisedFromMMS(I19,$E32)} -> 80.230884 | J40: {=MMS_Dairy_AtmosphericDeposition_Equations.VEERG_4_3_1_5__2_TotalNitrogenVolatilisedFromMMS(J19,$E32)} -> 33.587 | K40: =$E$11 -> kg N | O40: ='Input - Dairy'!$D$59 -> Milking shed | P40: ='Input - Dairy'!$D$78 -> Anaerobic lagoon | Q40: {=MMS_Dairy_AtmosphericDeposition_Equations.VEERG_4_3_1_5__2_TotalNitrogenVolatilisedFromMMS(Q19,$E32)} -> 74.286847 | R40: {=MMS_Dairy_AtmosphericDeposition_Equations.VEERG_4_3_1_5__2_TotalNitrogenVolatilisedFromMMS(R19,$E32)} -> 63.825266 | S40: {=MMS_Dairy_AtmosphericDeposition_Equations.VEERG_4_3_1_5__2_TotalNitrogenVolatilisedFromMMS(S19,$E32)} -> 25.420928 | T40: {=MMS_Dairy_AtmosphericDeposition_Equations.VEERG_4_3_1_5__2_TotalNitrogenVolatilisedFromMMS(T19,$E32)} -> 80.230884 | U40: {=MMS_Dairy_AtmosphericDeposition_Equations.VEERG_4_3_1_5__2_TotalNitrogenVolatilisedFromMMS(U19,$E32)} -> 33.587 | V40: =$E$11 -> kg N
D41: ='Input - Dairy'!$D$59 -> Milking shed | E41: ='Input - Dairy'!$D$79 -> Sump and dispersal system | F41: {=MMS_Dairy_AtmosphericDeposition_Equations.VEERG_4_3_1_5__2_TotalNitrogenVolatilisedFromMMS(F20,$E33)} -> 14.857369 | G41: {=MMS_Dairy_AtmosphericDeposition_Equations.VEERG_4_3_1_5__2_TotalNitrogenVolatilisedFromMMS(G20,$E33)} -> 12.765053 | H41: {=MMS_Dairy_AtmosphericDeposition_Equations.VEERG_4_3_1_5__2_TotalNitrogenVolatilisedFromMMS(H20,$E33)} -> 5.0841857 | I41: {=MMS_Dairy_AtmosphericDeposition_Equations.VEERG_4_3_1_5__2_TotalNitrogenVolatilisedFromMMS(I20,$E33)} -> 16.046177 | J41: {=MMS_Dairy_AtmosphericDeposition_Equations.VEERG_4_3_1_5__2_TotalNitrogenVolatilisedFromMMS(J20,$E33)} -> 6.7174 | O41: ='Input - Dairy'!$D$59 -> Milking shed | P41: ='Input - Dairy'!$D$79 -> Sump and dispersal system | Q41: {=MMS_Dairy_AtmosphericDeposition_Equations.VEERG_4_3_1_5__2_TotalNitrogenVolatilisedFromMMS(Q20,$E33)} -> 14.857369 | R41: {=MMS_Dairy_AtmosphericDeposition_Equations.VEERG_4_3_1_5__2_TotalNitrogenVolatilisedFromMMS(R20,$E33)} -> 12.765053 | S41: {=MMS_Dairy_AtmosphericDeposition_Equations.VEERG_4_3_1_5__2_TotalNitrogenVolatilisedFromMMS(S20,$E33)} -> 5.0841857 | T41: {=MMS_Dairy_AtmosphericDeposition_Equations.VEERG_4_3_1_5__2_TotalNitrogenVolatilisedFromMMS(T20,$E33)} -> 16.046177 | U41: {=MMS_Dairy_AtmosphericDeposition_Equations.VEERG_4_3_1_5__2_TotalNitrogenVolatilisedFromMMS(U20,$E33)} -> 6.7174
D42: ='Input - Dairy'!$D$59 -> Milking shed | E42: ='Input - Dairy'!$D$80 -> Drains to paddock | F42: {=MMS_Dairy_AtmosphericDeposition_Equations.VEERG_4_3_1_5__2_TotalNitrogenVolatilisedFromMMS(F21,$E34)} -> 42.449627 | G42: {=MMS_Dairy_AtmosphericDeposition_Equations.VEERG_4_3_1_5__2_TotalNitrogenVolatilisedFromMMS(G21,$E34)} -> 36.471581 | H42: {=MMS_Dairy_AtmosphericDeposition_Equations.VEERG_4_3_1_5__2_TotalNitrogenVolatilisedFromMMS(H21,$E34)} -> 14.526245 | I42: {=MMS_Dairy_AtmosphericDeposition_Equations.VEERG_4_3_1_5__2_TotalNitrogenVolatilisedFromMMS(I21,$E34)} -> 45.846219 | J42: {=MMS_Dairy_AtmosphericDeposition_Equations.VEERG_4_3_1_5__2_TotalNitrogenVolatilisedFromMMS(J21,$E34)} -> 19.192571 | O42: ='Input - Dairy'!$D$59 -> Milking shed | P42: ='Input - Dairy'!$D$80 -> Drains to paddock | Q42: {=MMS_Dairy_AtmosphericDeposition_Equations.VEERG_4_3_1_5__2_TotalNitrogenVolatilisedFromMMS(Q21,$E34)} -> 42.449627 | R42: {=MMS_Dairy_AtmosphericDeposition_Equations.VEERG_4_3_1_5__2_TotalNitrogenVolatilisedFromMMS(R21,$E34)} -> 36.471581 | S42: {=MMS_Dairy_AtmosphericDeposition_Equations.VEERG_4_3_1_5__2_TotalNitrogenVolatilisedFromMMS(S21,$E34)} -> 14.526245 | T42: {=MMS_Dairy_AtmosphericDeposition_Equations.VEERG_4_3_1_5__2_TotalNitrogenVolatilisedFromMMS(T21,$E34)} -> 45.846219 | U42: {=MMS_Dairy_AtmosphericDeposition_Equations.VEERG_4_3_1_5__2_TotalNitrogenVolatilisedFromMMS(U21,$E34)} -> 19.192571
