Workbook
Name Common_Equations.Common_ConvertCH4ToCO2e: _xlfn.LAMBDA(_xlpm.E_CH4,_xlpm.GWP_CH4, _xlpm.E_CH4 * _xlpm.GWP_CH4)
Name Common_Equations.Common_ConvertCH4ToCO2e_Arguments: _xlfn.LAMBDA(_xlfn.MAKEARRAY(2, 2, _xlfn.LAMBDA(_xlpm.r,_xlpm.c, INDEX({"ECH4","Methane emissions (t CH4)";"GWPCH4","Global warming potential for methane (t CO2-e / t CH4)"}, _xlpm.r, _xlpm.c))))
Name Common_Equations.Common_ConvertCH4ToCO2e_LatexEquation: _xlfn.LAMBDA("CO2_e = E_{CH4} \times GWP_{CH4}")
Name Common_Equations.Common_ConvertCH4ToCO2e_NIRReference: _xlfn.LAMBDA("")
Name Common_Equations.Common_ConvertCH4ToCO2e_Title: _xlfn.LAMBDA("Convert methane emissions to carbon dioxide equivalent emissions")
Name Common_Equations.Common_ConvertCH4ToCO2e_Unit: _xlfn.LAMBDA("t CO2e")
Name Common_Equations.Common_ConvertCH4ToCO2e_Variable: _xlfn.LAMBDA("ECH4 CO2e")
Name Common_Equations.Common_ConvertN2OToCO2e: _xlfn.LAMBDA(_xlpm.E_N2O,_xlpm.GWP_N2O, _xlpm.E_N2O * _xlpm.GWP_N2O)
Name Common_Equations.Common_ConvertN2OToCO2e_LatexEquation: _xlfn.LAMBDA("CO2_e = E_{N2O} \times GWP_{N2O}")
Name Common_Equations.Common_ConvertN2OToCO2e_NIRReference: _xlfn.LAMBDA("")
Name Common_Equations.Common_ConvertN2OToCO2e_Title: _xlfn.LAMBDA("Convert nitrous oxide emissions to carbon dioxide equivalent emissions")
Name Common_Equations.Common_ConvertN2OToCO2e_Unit: _xlfn.LAMBDA("t CO2e")
Name Common_Equations.Common_ConvertN2OToCO2e_Variable: _xlfn.LAMBDA("EN2O CO2e")
Name Common_InputFunctions.Utility_ConvertStateCommonNameToAbbreviation: _xlfn.LAMBDA(_xlpm.StateCommonName,_xlpm.StateCommonNameArray,_xlpm.StateAbbreviationArray, _xlfn.XLOOKUP(_xlpm.StateCommonName, _xlpm.StateCommonNameArray, _xlpm.StateAbbreviationArray, ""))
Name Common_InputFunctions.Utility_DisplayArguments_1_2: _xlfn.LAMBDA(_xlpm.ArgumentsArray, _xlfn.CHOOSECOLS(_xlpm.ArgumentsArray, 1, 2))
Name Common_InputFunctions.Utility_DisplayArguments_3_4: _xlfn.LAMBDA(_xlpm.ArgumentsArray, _xlfn.CHOOSECOLS(_xlpm.ArgumentsArray, 3, 4))
Name Common_InputFunctions.Utility_DisplayFunctionName: _xlfn.LAMBDA(_xlpm.Function, _xlfn.TEXTBEFORE(_xlfn.FORMULATEXT(_xlpm.Function), "("))
Name Common_InputFunctions.Utility_GetArrayTableColumnStartNumber: _xlfn.LAMBDA(_xlpm.TableHeaderCell, COLUMN(_xlpm.TableHeaderCell))
Name Common_InputFunctions.Utility_GetArrayTableRowStartNumber: _xlfn.LAMBDA(_xlpm.TableheaderCell,_xlpm.RowsBetweenHeaderandArray, ROW(_xlpm.TableheaderCell) + _xlpm.RowsBetweenHeaderandArray - 1)
Name Common_InputFunctions.Utility_LookupValueInTable: _xlfn.LAMBDA(_xlpm.LookupValue,_xlpm.LookupArray,_xlpm.ReturnArray, _xlfn.XLOOKUP(_xlpm.LookupValue, _xlpm.LookupArray, _xlpm.ReturnArray, ""))
Name Common_InputFunctions.Utility_SourceHyperlink: _xlfn.LAMBDA(_xlpm.TargetCell, _xlfn.LET(_xlpm.sh, _xlfn.TEXTAFTER(CELL("filename", _xlpm.TargetCell), "]"), _xlpm.addr, CELL("address", _xlpm.TargetCell), "#'" & _xlpm.sh & "'!" & _xlpm.addr))
Name Common_SourceData.Common_SourceData_AustralianStatesTerritories_Source: _xlfn.LAMBDA("")
Name Common_SourceData.Common_SourceData_AustralianStatesTerritories_Title: _xlfn.LAMBDA("Australian states and territories")
Name Common_SourceData.Common_SourceData_AustralianStatesTerritories_Unit: _xlfn.LAMBDA("")
Name Common_SourceData.Common_SourceData_AustralianStatesTerritories_Variable: _xlfn.LAMBDA("")
Name Common_SourceData.Common_SourceData_ClimateZones_Source: _xlfn.LAMBDA("VEERG 2026: Table 1.3: Climate and Rainfall zone classifications and definitions")
Name Common_SourceData.Common_SourceData_ClimateZones_Title: _xlfn.LAMBDA("VEERG Australian climate zones")
Name Common_SourceData.Common_SourceData_ClimateZones_Unit: _xlfn.LAMBDA("")
Name Common_SourceData.Common_SourceData_ClimateZones_Variable: _xlfn.LAMBDA("")
Name Common_SourceData.Common_SourceData_ConvertGasElementalToMolecular_Source: _xlfn.LAMBDA("XXXXXXX")
Name Common_SourceData.Common_SourceData_ConvertGasElementalToMolecular_Title: _xlfn.LAMBDA("Factor to convert elemental mass of gas to molecular mass")
Name Common_SourceData.Common_SourceData_ConvertGasElementalToMolecular_Unit: _xlfn.LAMBDA("factor")
Name Common_SourceData.Common_SourceData_ConvertGasElementalToMolecular_Variable: _xlfn.LAMBDA("Cg")
Name Common_SourceData.Common_SourceData_ConvertN2oElementalToMolecularCg_Data: _xlfn.LAMBDA(44 / 28)
Name Common_SourceData.Common_SourceData_ConvertN2oElementalToMolecularCg_Source: _xlfn.LAMBDA("National Inventory Report 2023 Volume 1")
Name Common_SourceData.Common_SourceData_ConvertN2oElementalToMolecularCg_Title: _xlfn.LAMBDA("Factor to convert elemental mass of N2O to molecular mass")
Name Common_SourceData.Common_SourceData_ConvertN2oElementalToMolecularCg_Unit: _xlfn.LAMBDA("factor")
Name Common_SourceData.Common_SourceData_ConvertN2oElementalToMolecularCg_Variable: _xlfn.LAMBDA("CgN2O")
Name Common_SourceData.Common_SourceData_DataScores_Scope3_Source: _xlfn.LAMBDA("VEERG 2026: XXXXXXXX")
Name Common_SourceData.Common_SourceData_DataScores_Scope3_Title: _xlfn.LAMBDA("Australian data scores for scope 3")
Name Common_SourceData.Common_SourceData_DataScores_Scope3_Unit: _xlfn.LAMBDA("")
Name Common_SourceData.Common_SourceData_DataScores_Scope3_Variable: _xlfn.LAMBDA("")
Name Common_SourceData.Common_SourceData_DataScores_Scope3_Variation: _xlfn.LAMBDA("")
Name Common_SourceData.Common_SourceData_DensityOfMethane_Data: _xlfn.LAMBDA(0.6784)
Name Common_SourceData.Common_SourceData_DensityOfMethane_Source: _xlfn.LAMBDA("National Inventory Report 2023 Volume 1: Equations 3.B.1a_2, 3.B.1c_2, 3.B.3_1, 3.B.4g_2")
Name Common_SourceData.Common_SourceData_DensityOfMethane_Title: _xlfn.LAMBDA("p = density of methane")
Name Common_SourceData.Common_SourceData_DensityOfMethane_Unit: _xlfn.LAMBDA("kg/m3")
Name Common_SourceData.Common_SourceData_EFleach_Data: _xlfn.LAMBDA(_xlfn.MAKEARRAY(1, 2, _xlfn.LAMBDA(_xlpm.r,_xlpm.c, INDEX({"EFleach",0.011}, _xlpm.r, _xlpm.c))))
Name Common_SourceData.Common_SourceData_EFleach_NIRReference: _xlfn.LAMBDA("National Inventory Report Volume 1: Equation 3.D.B_10")
Name Common_SourceData.Common_SourceData_EFleach_Source: _xlfn.LAMBDA("VEERG 2026:5.5.2.3 Constant Parameters")
Name Common_SourceData.Common_SourceData_EFleach_Title: _xlfn.LAMBDA("Emission factor for nitrogen leaching and runoff")
Name Common_SourceData.Common_SourceData_EFleach_Unit: _xlfn.LAMBDA("(kg N2O-N / kg N")
Name Common_SourceData.Common_SourceData_EFleach_Variation: _xlfn.LAMBDA((""))
Name Common_SourceData.Common_SourceData_EFN2O_NIRReference: _xlfn.LAMBDA("")
Name Common_SourceData.Common_SourceData_EFN2O_Source: _xlfn.LAMBDA("VEERG 2026: Table A.2.2.1")
Name Common_SourceData.Common_SourceData_EFN2O_Title: _xlfn.LAMBDA("Nitrous oxide emission factors for inorganic fertiliser application")
Name Common_SourceData.Common_SourceData_EFN2O_Unit: _xlfn.LAMBDA("(kg N2O-N / kg N")
Name Common_SourceData.Common_SourceData_EFPastureRangeAndPaddock_Data: _xlfn.LAMBDA(_xlfn.MAKEARRAY(3, 2, _xlfn.LAMBDA(_xlpm.r,_xlpm.c, INDEX({"Climate zone","EFPRP";"Wet climate zone",0.006;"Dry climate zone",0.002}, _xlpm.r, _xlpm.c))))
Name Common_SourceData.Common_SourceData_EFPastureRangeAndPaddock_NIRReference: _xlfn.LAMBDA("")
Name Common_SourceData.Common_SourceData_EFPastureRangeAndPaddock_Source: _xlfn.LAMBDA("VEERG 2026: Table A.2.2.2")

Sheet Home
A1: Home

Sheet Overview

Sheet Results
A1: #VALUE! | C1: 4.5 Manure management: Swine: Results
A3: =HYPERLINK("#'Home'!A1", "Home") -> Home
A4: =HYPERLINK("#'Overview'!A1", "Overview") -> Overview | D4: Emissions breakdown
A5: =HYPERLINK("#'Results'!A1", "Results") -> Results
D6: Scope 1 source | E6: GHG emissions method 1 | F6: GHG emissions method 2 | G6: GHG Unit | H6: CO2-e emissions method 1 | I6: CO2-e emissions method 2 | J6: CO2-e unit
A7: INPUTS | D7: 4.5.1.1-2 Manure methane | E7: ='4.5.1.1-2 Methane'!E261 -> 2.3840372 | F7: ='4.5.1.1-2 Methane'!O261 -> 2.4087426 | G7: t CH4 | H7: ='4.5.1.1-2 Methane'!E266 -> 66.753043 | I7: ='4.5.1.1-2 Methane'!O266 -> 67.444792 | J7: t CO2e
A8: =HYPERLINK("#'Input - Site'!A1", "Site") -> Site | D8: 4.5.1.3-4 Direct N2O | E8: ='4.5.1.3-4 Direct N2O'!E297 -> 0.074343141 | F8: ='4.5.1.3-4 Direct N2O'!O297 -> 0.074343141 | G8: t N2O | H8: ='4.5.1.3-4 Direct N2O'!E302 -> 19.700932 | I8: ='4.5.1.3-4 Direct N2O'!O302 -> 19.700932 | J8: t CO2e
A9: =HYPERLINK("#'Input - Swine'!A1", "Swine") -> Swine | D9: 4.5.1.5-6 Atmospheric deposition | E9: ='4.5.1.5-6 Atmos Dep'!E125 -> 0.024944402 | F9: ='4.5.1.5-6 Atmos Dep'!O125 -> 0.024944402 | G9: t N2O | H9: ='4.5.1.5-6 Atmos Dep'!E130 -> 6.6102665 | I9: ='4.5.1.5-6 Atmos Dep'!O130 -> 6.6102665 | J9: t CO2e
D10: 4.2.1.7-8 Leaching and runoff | E10: ='4.5.1.7-8 Leaching and runoff'!E49 -> 0.00026075016 | F10: ='4.5.1.7-8 Leaching and runoff'!N49 -> 0.00026075016 | G10: t N2O | H10: ='4.5.1.7-8 Leaching and runoff'!E54 -> 0.069098792 | I10: ='4.5.1.7-8 Leaching and runoff'!N54 -> 0.069098792 | J10: t CO2e
A11: CALCULATIONS | D11: Total | H11: =SUM(H7:H10) -> 93.13334 | I11: =SUM(I7:I10) -> 93.82509 | J11: t CO2e
A12: =HYPERLINK("#'4.5.1.1-2 Methane'!A1", "4.5.1.1-2 Methane") -> 4.5.1.1-2 Methane
A13: =HYPERLINK("#'4.5.1.3-4 Direct N2O'!A1", "4.5.1.3-4 Direct N2O") -> 4.5.1.3-4 Direct N2O | D13: 4.5.1.9 Manure applied to soils
A14: =HYPERLINK("#'4.5.1.5-6 Atmos Dep'!A1", "4.5.1.5-6 Soil atm. deposition") -> 4.5.1.5-6 Soil atm. deposition | D14: WARNING: Manure nitrogen that was applied to soils must be accounted for
A15: =HYPERLINK("#'4.5.1.7-8 Leaching and runoff'!A1", "4.5.1.7-8 Leaching & runoff") -> 4.5.1.7-8 Leaching & runoff | D15: See the table below for how to account for manure applied to soils for scope 1 and 3.
A16: =HYPERLINK("#'4.5.1.9 Manure applied to soils'!A1", "4.5.1.9 Manure applied to soils") -> 4.5.1.9 Manure applied to soils | D16: Manure nitrogen use | E16: Amount of N in manure | F16: N unit | G16: Emissions allocated to | H16: VEERG Calculation method
D17: Manure nitrogen deposited on farm soils (including use as fertiliser for other enterprises on own farm eg crops) | E17: ='4.5.1.9 Manure applied to soils'!E161 -> 3256.7705 | F17: ='4.5.1.9 Manure applied to soils'!F161 -> kg N | G17: Scope 1 - This piggery | H17: 5.2.2.1 (1), 5.4.1.3 (1, 2), 5.5.1.1 (1, 3)
A18: APPENDICES | D18: Manure nitrogen deposited on farm soils as fertiliser for other farm enterpsies (eg crops) | E18: ='4.5.1.9 Manure applied to soils'!E278 -> 653.20846 | F18: ='4.5.1.9 Manure applied to soils'!F278 -> kg N | G18: Scope 1 - This piggery | H18: 5.2.2.1 (1), 5.4.1.3 (1, 2), 5.5.1.1 (1, 3)
A19: =HYPERLINK("#'Constants - Swine'!A1", "Constants - Swine") -> Constants - Swine | D19: Manure nitrogen sold | E19: ='4.5.1.9 Manure applied to soils'!E209 -> 653.20846 | F19: ='4.5.1.9 Manure applied to soils'!F209 -> kg N | G19: Scope 3 (downstream) | H19: 15.13.1.1 (1), 5.2.2.1 (1), 5.4.1.3 (1, 2), 5.5.1.1 (1, 3)
A20: =HYPERLINK("#'Constants - Livestock'!A1", "Constants - Livestock") -> Constants - Livestock
A21: =HYPERLINK("#'Constants - Common'!A1", "Constants - Common") -> Constants - Common
A22: =HYPERLINK("#'Acknowledgements'!A1", "Acknowledgements") -> Acknowledgements

Sheet Input - Site
A1: #VALUE! | C1: Input - Site
A3: =HYPERLINK("#'Home'!A1", "Home") -> Home
A4: =HYPERLINK("#'Overview'!A1", "Overview") -> Overview
A5: =HYPERLINK("#'Results'!A1", "Results") -> Results | D5: Your business
A7: INPUTS | D7: Farm name | E7: Test Farms
A8: =HYPERLINK("#'Input - Site'!A1", "Site") -> Site | D8: Reporting entity name | E8: Test Farms Pty Ltd
A9: =HYPERLINK("#'Input - Swine'!A1", "Swine") -> Swine
D10: 💡An 'Emissions accounting period' is a 12 month period where the business can report on the emissions, and is typically the same as the business' financial accounting period.
A11: CALCULATIONS
A12: =HYPERLINK("#'4.5.1.1-2 Methane'!A1", "4.5.1.1-2 Methane") -> 4.5.1.1-2 Methane | D12: Emissions calculation period start date | E12: 45292 | F12: ← DD/MM/YYYY or DD Month YYYY
A13: =HYPERLINK("#'4.5.1.3-4 Direct N2O'!A1", "4.5.1.3-4 Direct N2O") -> 4.5.1.3-4 Direct N2O | D13: Emissions calculation period end date | E13: =DATE(YEAR(E12)+1,MONTH(E12),DAY(E12))-1 -> 45657 | F13: ← Automatically calculated, 12 months after start date
A14: =HYPERLINK("#'4.5.1.5-6 Atmos Dep'!A1", "4.5.1.5-6 Soil atm. deposition") -> 4.5.1.5-6 Soil atm. deposition
A15: =HYPERLINK("#'4.5.1.7-8 Leaching and runoff'!A1", "4.5.1.7-8 Leaching & runoff") -> 4.5.1.7-8 Leaching & runoff
A16: =HYPERLINK("#'4.5.1.9 Manure applied to soils'!A1", "4.5.1.9 Manure applied to soils") -> 4.5.1.9 Manure applied to soils | D16: Location and climate
A18: APPENDICES | D18: Location information is used to reference some region and climate-specific emission factors
A19: =HYPERLINK("#'Constants - Swine'!A1", "Constants - Swine") -> Constants - Swine | D19: Tip: Use the web-based GAF Location Helper tool to easily get region and climate information. You will need an internet connection to use the GAF Location Helper.
A20: =HYPERLINK("#'Constants - Livestock'!A1", "Constants - Livestock") -> Constants - Livestock
A21: =HYPERLINK("#'Constants - Common'!A1", "Constants - Common") -> Constants - Common | D21: State | E21: Western Australia | F21: ← Please select
A22: =HYPERLINK("#'Acknowledgements'!A1", "Acknowledgements") -> Acknowledgements | D22: Region (ABS Statistical area level 4) if state is WA | E22: Western Australia - Outback (South) | F22: ← Please select
D23: Leaching zone | E23: NO - Not in leaching zone | F23: ← Please select
D24: Elevation | E24: 307.7 | F24: Meters
D25: Average temperature for reporting period | E25: 18 | F25: Degrees celsius
D26: Total rainfall for reporting period | E26: 601 | F26: Millimetres
D27: Potential evapotranspiration for reporting period | E27: 1326 | F27: Millimetres
D28: Number of frost days for reporting period | E28: 7 | F28: Days
D29: MAP:PET ratio | E29: =E26/E27 -> 0.45324284
D30: Rainfall zone | E30: =Common_InputFunctions.Utility_LookupItemFromMinMax(E26,Table_SourceData_RainfallZones[Min rainfall],Table_SourceData_RainfallZones[Max rainfall],Table_SourceData_RainfallZones[Rainfall Zone]) -> High rainfall
D31: Climate zone | E31: =Common_InputFunctions.Utility_GetClimateZone(E25,E26,E28,E24,E29,Table_SourceData_ClimateZones[Min temp],Table_SourceData_ClimateZones[Max temp],Table_SourceData_ClimateZones[Min rainfall],Table_SourceData_ClimateZones[Max rainfall],Table_SourceData_ClimateZones[Min frost days],Table_SourceData_ClimateZones[Max frost days],Table_SourceData_ClimateZones[Min elevation],Table_SourceData_ClimateZones[Max elevation],Table_SourceData_ClimateZones[Min MAP:PET],Table_SourceData_ClimateZones[Max MAP:PET],Table_SourceData_ClimateZones[Climate zone]) -> Warm temperate dry
D32: Wet or dry climate zone | E32: =Common_InputFunctions.Utility_LookupValueInTable($E$31,Table_SourceData_WetDryZones[Climate zone],Table_SourceData_WetDryZones[Wet or Dry Zone]) -> Dry climate zone
D33: Temperature zone | E33: =Common_InputFunctions.Utility_LookupItemFromMinMax(E25,Table_SourceData_TemperatureZones[Min MAT],Table_SourceData_TemperatureZones[Max MAT],Table_SourceData_TemperatureZones[Temperature Zone]) -> Temperate

Sheet Input - Swine
A1: #VALUE! | C1: Input -Swine
A3: =HYPERLINK("#'Home'!A1", "Home") -> Home
A4: =HYPERLINK("#'Overview'!A1", "Overview") -> Overview
A5: =HYPERLINK("#'Results'!A1", "Results") -> Results | D5: This tool demostrates inputs for one production system.
D6: Because the type of production system is not relevant in emissions calculations, you can select any kind.
A7: INPUTS
A8: =HYPERLINK("#'Input - Site'!A1", "Site") -> Site
A9: =HYPERLINK("#'Input - Swine'!A1", "Swine") -> Swine | E9: Boars | F9: Sows | G9: Gilts | H9: Others
D10: ="Average duration of stay between " & TEXT('Input - Site'!$E$12, "dd mmm yy") & " and " & TEXT('Input - Site'!$E$13, "dd mmm yy") -> Average duration of stay between 01 Jan 24 and 31 Dec 24 | E10: 365 | F10: 365 | G10: 365 | H10: 365 | I10: Days
A11: CALCULATIONS | D11: ="Average number of head between " & TEXT('Input - Site'!$E$12, "dd mmm yy") & " and " & TEXT('Input - Site'!$E$13, "dd mmm yy") -> Average number of head between 01 Jan 24 and 31 Dec 24 | E11: 100 | F11: 100 | G11: 100 | H11: 100 | I11: Head
A12: =HYPERLINK("#'4.5.1.1-2 Methane'!A1", "4.5.1.1-2 Methane") -> 4.5.1.1-2 Methane
A13: =HYPERLINK("#'4.5.1.3-4 Direct N2O'!A1", "4.5.1.3-4 Direct N2O") -> 4.5.1.3-4 Direct N2O | D13: Manure production
A14: =HYPERLINK("#'4.5.1.5-6 Atmos Dep'!A1", "4.5.1.5-6 Soil atm. deposition") -> 4.5.1.5-6 Soil atm. deposition
A15: =HYPERLINK("#'4.5.1.7-8 Leaching and runoff'!A1", "4.5.1.7-8 Leaching & runoff") -> 4.5.1.7-8 Leaching & runoff | D15: Method 1 default values (Do not edit) | E15: Boars | F15: Sows | G15: Gilts | H15: Others
A16: =HYPERLINK("#'4.5.1.9 Manure applied to soils'!A1", "4.5.1.9 Manure applied to soils") -> 4.5.1.9 Manure applied to soils | D16: Volatile solids produced per head per day | E16: {=Common_InputFunctions.Utility_LookupValueInTableNumber(E15, Table_SourceData_Swine_VolatileSolids[Class], Table_SourceData_Swine_VolatileSolids[VSj])} -> 0.4 | F16: {=Common_InputFunctions.Utility_LookupValueInTableNumber(F15, Table_SourceData_Swine_VolatileSolids[Class], Table_SourceData_Swine_VolatileSolids[VSj])} -> 0.46 | G16: {=Common_InputFunctions.Utility_LookupValueInTableNumber(G15, Table_SourceData_Swine_VolatileSolids[Class], Table_SourceData_Swine_VolatileSolids[VSj])} -> 0.55 | H16: {=Common_InputFunctions.Utility_LookupValueInTableNumber(H15, Table_SourceData_Swine_VolatileSolids[Class], Table_SourceData_Swine_VolatileSolids[VSj])} -> 0.39 | I16: kg/head/day
D17: Nitrogen produced in swine waste per head per day | E17: {=Common_InputFunctions.Utility_LookupValueInTableNumber(E15, Table_SourceData_Swine_NitrogenInWaste[Class name], Table_SourceData_Swine_NitrogenInWaste[NWj Daily])} -> 0.046 | F17: {=Common_InputFunctions.Utility_LookupValueInTableNumber(F15, Table_SourceData_Swine_NitrogenInWaste[Class name], Table_SourceData_Swine_NitrogenInWaste[NWj Daily])} -> 0.049 | G17: {=Common_InputFunctions.Utility_LookupValueInTableNumber(G15, Table_SourceData_Swine_NitrogenInWaste[Class name], Table_SourceData_Swine_NitrogenInWaste[NWj Daily])} -> 0.046 | H17: {=Common_InputFunctions.Utility_LookupValueInTableNumber(H15, Table_SourceData_Swine_NitrogenInWaste[Class name], Table_SourceData_Swine_NitrogenInWaste[NWj Daily])} -> 0.0312 | I17: kg N/head/day
A18: APPENDICES
A19: =HYPERLINK("#'Constants - Swine'!A1", "Constants - Swine") -> Constants - Swine | D19: Method 2 custom values (Edit if known) | E19: Boars | F19: Sows | G19: Gilts | H19: Others
A20: =HYPERLINK("#'Constants - Livestock'!A1", "Constants - Livestock") -> Constants - Livestock | D20: Volatile solids produced per head per day | E20: {=Common_InputFunctions.Utility_LookupValueInTableNumber(E19, Table_SourceData_Swine_VolatileSolids[Class], Table_SourceData_Swine_VolatileSolids[VSj])} -> 0.4 | F20: {=Common_InputFunctions.Utility_LookupValueInTableNumber(F19, Table_SourceData_Swine_VolatileSolids[Class], Table_SourceData_Swine_VolatileSolids[VSj])} -> 0.46 | G20: {=Common_InputFunctions.Utility_LookupValueInTableNumber(G19, Table_SourceData_Swine_VolatileSolids[Class], Table_SourceData_Swine_VolatileSolids[VSj])} -> 0.55 | H20: {=Common_InputFunctions.Utility_LookupValueInTableNumber(H19, Table_SourceData_Swine_VolatileSolids[Class], Table_SourceData_Swine_VolatileSolids[VSj])} -> 0.39 | I20: kg/head/day
A21: =HYPERLINK("#'Constants - Common'!A1", "Constants - Common") -> Constants - Common | D21: Nitrogen produced in swine waste per head per day | E21: {=Common_InputFunctions.Utility_LookupValueInTableNumber(E19, Table_SourceData_Swine_NitrogenInWaste[Class name], Table_SourceData_Swine_NitrogenInWaste[NWj Daily])} -> 0.046 | F21: {=Common_InputFunctions.Utility_LookupValueInTableNumber(F19, Table_SourceData_Swine_NitrogenInWaste[Class name], Table_SourceData_Swine_NitrogenInWaste[NWj Daily])} -> 0.049 | G21: {=Common_InputFunctions.Utility_LookupValueInTableNumber(G19, Table_SourceData_Swine_NitrogenInWaste[Class name], Table_SourceData_Swine_NitrogenInWaste[NWj Daily])} -> 0.046 | H21: {=Common_InputFunctions.Utility_LookupValueInTableNumber(H19, Table_SourceData_Swine_NitrogenInWaste[Class name], Table_SourceData_Swine_NitrogenInWaste[NWj Daily])} -> 0.0312 | I21: kg N/head/day
A22: =HYPERLINK("#'Acknowledgements'!A1", "Acknowledgements") -> Acknowledgements
D24: Manure management systems
D26: Production system | E26: Outdoor/free range | F26: ← Please select
E27: =IF(E26="Outdoor/free range", "In an outdoor/free range system the only likely stage 1 MMS is 'Drylot (feed pad)'", "") -> In an outdoor/free range system the only likely stage 1 MMS is 'Drylot (feed pad)'
D28: Stage 1 MMS | E28: Boars | F28: Sows | G28: Gilts | H28: Others
D29: ='Constants - Swine'!$G$41 -> Anaerobic lagoon | E29: 0.15 | F29: 0.15 | G29: 0.15 | H29: 0.15 | I29: Percent
D30: ='Constants - Swine'!$G$42 -> Drylot (feed pad) | E30: 0.15 | F30: 0.15 | G30: 0.15 | H30: 0.15 | I30: Percent
D31: ='Constants - Swine'!$G$43 -> Digester / covered lagoons | E31: 0.15 | F31: 0.15 | G31: 0.15 | H31: 0.15 | I31: Percent
D32: ='Constants - Swine'!$G$44 -> Deep litter | E32: 0.15 | F32: 0.15 | G32: 0.15 | H32: 0.15 | I32: Percent
D33: ='Constants - Swine'!$G$45 -> Pit storage | E33: 0.15 | F33: 0.15 | G33: 0.15 | H33: 0.15 | I33: Percent
D34: ='Constants - Swine'!$D$42 -> Solid storage | E34: 0.25 | F34: 0.25 | G34: 0.25 | H34: 0.25 | I34: Percent
D35: Total sent to all MMS (Must equal 100%) | E35: =SUM(E29,E30,E31,E32,E33,E34) -> 1 | F35: =SUM(F29,F30,F31,F32,F33,F34) -> 1 | G35: =SUM(G29,G30,G31,G32,G33,G34) -> 1 | H35: =SUM(H29,H30,H31,H32,H33,H34) -> 1
D37: ▼
D38: Solid separation from stage 1 MMS | E38: Were solids separated? (select) | F38: Percent separated (Method 1) | G38: Percent separated (Method 2)
D39: ="Solids separated from " & $D$29 -> Solids separated from Anaerobic lagoon | E39: Yes | F39: 0.2 | G39: 0.2
D40: ="Solids separated from " & $D$30 -> Solids separated from Drylot (feed pad) | E40: Yes | F40: 0.2 | G40: 0.2
D41: ="Solids separated from " & $D$31 -> Solids separated from Digester / covered lagoons | E41: Yes | F41: 0.2 | G41: 0.2
D42: ="Solids separated from " & $D$32 -> Solids separated from Deep litter | E42: Yes | F42: 0.2 | G42: 0.2
D43: ="Solids separated from " & $D$33 -> Solids separated from Pit storage | E43: Yes | F43: 0.2 | G43: 0.2
D45: ▼
...

Sheet 4.5.1.1-2 Methane
A1: #VALUE! | C1: 4.5.1.1-2 Manure Methane
A3: =HYPERLINK("#'Home'!A1", "Home") -> Home | D3: Method 1 | N3: Method 2
A4: =HYPERLINK("#'Overview'!A1", "Overview") -> Overview
A5: =HYPERLINK("#'Results'!A1", "Results") -> Results | D5: {=MMS_Swine_Methane_Equations.VEERG_4_5_1_1__4_FractionVolatileSolidsPrimarySystem_Title()} -> Fraction of volatile solids in each primary system other than solid storage
D6: {=MMS_Swine_Methane_Equations.VEERG_4_5_1_1__4_FractionVolatileSolidsPrimarySystem_Source()} -> VEERG 2026: 4.5.1.1, Equation (4)
A7: INPUTS | D7: Function name | E7: {=Common_InputFunctions.Utility_DisplayFunctionName($E$37)} -> =MMS_Swine_Methane_Equations.VEERG_4_5_1_1__4_FractionVolatileSolidsPrimarySystem
A8: =HYPERLINK("#'Input - Site'!A1", "Site") -> Site
A9: =HYPERLINK("#'Input - Swine'!A1", "Swine") -> Swine
D10: Variable | E10: {=MMS_Swine_Methane_Equations.VEERG_4_5_1_1__4_FractionVolatileSolidsPrimarySystem_Variable()} -> FVSjmT1
A11: CALCULATIONS | D11: Unit | E11: {=MMS_Swine_Methane_Equations.VEERG_4_5_1_1__4_FractionVolatileSolidsPrimarySystem_Unit()} -> fraction
A12: =HYPERLINK("#'4.5.1.1-2 Methane'!A1", "4.5.1.1-2 Methane") -> 4.5.1.1-2 Methane
A13: =HYPERLINK("#'4.5.1.3-4 Direct N2O'!A1", "4.5.1.3-4 Direct N2O") -> 4.5.1.3-4 Direct N2O | D13: {=Common_InputFunctions.Utility_DisplayArguments_1_2(MMS_Swine_Methane_Equations.VEERG_4_5_1_1__4_FractionVolatileSolidsPrimarySystem_Arguments())} -> MMSjmT1 | E13: fraction of manure to each primary MMS for each class prior to solid separation | G13: {=Common_InputFunctions.Utility_DisplayArguments_3_4(MMS_Swine_Methane_Equations.VEERG_4_5_1_1__4_FractionVolatileSolidsPrimarySystem_Arguments())} -> fraction | H13: Input | I13: {=HYPERLINK(Common_InputFunctions.Utility_SourceHyperlink($D$16), $D$16)} -> Table_MMS_j_m_T-1
A14: =HYPERLINK("#'4.5.1.5-6 Atmos Dep'!A1", "4.5.1.5-6 Soil atm. deposition") -> 4.5.1.5-6 Soil atm. deposition | D14: SSm | E14: fraction of volatile solids separated to solid storage for each MMS | G14: fraction | H14: Input | I14: {=HYPERLINK(Common_InputFunctions.Utility_SourceHyperlink($D$25), $D$25)} -> M1_Table_SS_m
A15: =HYPERLINK("#'4.5.1.7-8 Leaching and runoff'!A1", "4.5.1.7-8 Leaching & runoff") -> 4.5.1.7-8 Leaching & runoff
A16: =HYPERLINK("#'4.5.1.9 Manure applied to soils'!A1", "4.5.1.9 Manure applied to soils") -> 4.5.1.9 Manure applied to soils | D16: Table_MMS_j_m_T-1
D17: Fraction VS sent to MMS other than solid storage in stage 1
A18: APPENDICES | D18: Stage 1 management | E18: Boars | F18: Sows | G18: Gilts | H18: Others
A19: =HYPERLINK("#'Constants - Swine'!A1", "Constants - Swine") -> Constants - Swine | D19: ='Input - Swine'!$D$29 -> Anaerobic lagoon | E19: ='Input - Swine'!E29 -> 0.15 | F19: ='Input - Swine'!F29 -> 0.15 | G19: ='Input - Swine'!G29 -> 0.15 | H19: ='Input - Swine'!H29 -> 0.15 | I19: =G13 -> fraction
A20: =HYPERLINK("#'Constants - Livestock'!A1", "Constants - Livestock") -> Constants - Livestock | D20: ='Input - Swine'!$D$30 -> Drylot (feed pad) | E20: ='Input - Swine'!E30 -> 0.15 | F20: ='Input - Swine'!F30 -> 0.15 | G20: ='Input - Swine'!G30 -> 0.15 | H20: ='Input - Swine'!H30 -> 0.15
A21: =HYPERLINK("#'Constants - Common'!A1", "Constants - Common") -> Constants - Common | D21: ='Input - Swine'!$D$31 -> Digester / covered lagoons | E21: ='Input - Swine'!E31 -> 0.15 | F21: ='Input - Swine'!F31 -> 0.15 | G21: ='Input - Swine'!G31 -> 0.15 | H21: ='Input - Swine'!H31 -> 0.15
A22: =HYPERLINK("#'Acknowledgements'!A1", "Acknowledgements") -> Acknowledgements | D22: ='Input - Swine'!$D$32 -> Deep litter | E22: ='Input - Swine'!E32 -> 0.15 | F22: ='Input - Swine'!F32 -> 0.15 | G22: ='Input - Swine'!G32 -> 0.15 | H22: ='Input - Swine'!H32 -> 0.15
D23: ='Input - Swine'!$D$33 -> Pit storage | E23: ='Input - Swine'!E33 -> 0.15 | F23: ='Input - Swine'!F33 -> 0.15 | G23: ='Input - Swine'!G33 -> 0.15 | H23: ='Input - Swine'!H33 -> 0.15
D25: M1_Table_SS_m | N25: M2_Table_SS_m-1-7-9
D26: Fraction separated solids sent from MMS other than solid storage to solid storage in stage 1 (Method 1) | N26: Fraction separated solids sent from MMS other than solid storage to solid storage in stage 1 (Method 2)
D27: Stage 1 management | E27: Boars | F27: Sows | G27: Gilts | H27: Others | N27: Stage 1 management | O27: Boars | P27: Sows | Q27: Gilts | R27: Others
D28: ='Input - Swine'!$D$29 -> Anaerobic lagoon | E28: ='Input - Swine'!$F$39 -> 0.2 | F28: ='Input - Swine'!$F$39 -> 0.2 | G28: ='Input - Swine'!$F$39 -> 0.2 | H28: ='Input - Swine'!$F$39 -> 0.2 | I28: =G14 -> fraction | N28: ='Input - Swine'!$D$29 -> Anaerobic lagoon | O28: ='Input - Swine'!$G$39 -> 0.2 | P28: ='Input - Swine'!$G$39 -> 0.2 | Q28: ='Input - Swine'!$G$39 -> 0.2 | R28: ='Input - Swine'!$G$39 -> 0.2 | S28: =G14 -> fraction
D29: ='Input - Swine'!$D$30 -> Drylot (feed pad) | E29: ='Input - Swine'!$F$40 -> 0.2 | F29: ='Input - Swine'!$F$40 -> 0.2 | G29: ='Input - Swine'!$F$40 -> 0.2 | H29: ='Input - Swine'!$F$40 -> 0.2 | N29: ='Input - Swine'!$D$30 -> Drylot (feed pad) | O29: ='Input - Swine'!$G$40 -> 0.2 | P29: ='Input - Swine'!$G$40 -> 0.2 | Q29: ='Input - Swine'!$G$40 -> 0.2 | R29: ='Input - Swine'!$G$40 -> 0.2
D30: ='Input - Swine'!$D$31 -> Digester / covered lagoons | E30: ='Input - Swine'!$F$41 -> 0.2 | F30: ='Input - Swine'!$F$41 -> 0.2 | G30: ='Input - Swine'!$F$41 -> 0.2 | H30: ='Input - Swine'!$F$41 -> 0.2 | N30: ='Input - Swine'!$D$31 -> Digester / covered lagoons | O30: ='Input - Swine'!$G$41 -> 0.2 | P30: ='Input - Swine'!$G$41 -> 0.2 | Q30: ='Input - Swine'!$G$41 -> 0.2 | R30: ='Input - Swine'!$G$41 -> 0.2
D31: ='Input - Swine'!$D$32 -> Deep litter | E31: ='Input - Swine'!$F$42 -> 0.2 | F31: ='Input - Swine'!$F$42 -> 0.2 | G31: ='Input - Swine'!$F$42 -> 0.2 | H31: ='Input - Swine'!$F$42 -> 0.2 | N31: ='Input - Swine'!$D$32 -> Deep litter | O31: ='Input - Swine'!$G$42 -> 0.2 | P31: ='Input - Swine'!$G$42 -> 0.2 | Q31: ='Input - Swine'!$G$42 -> 0.2 | R31: ='Input - Swine'!$G$42 -> 0.2
D32: ='Input - Swine'!$D$33 -> Pit storage | E32: ='Input - Swine'!$F$43 -> 0.2 | F32: ='Input - Swine'!$F$43 -> 0.2 | G32: ='Input - Swine'!$F$43 -> 0.2 | H32: ='Input - Swine'!$F$43 -> 0.2 | N32: ='Input - Swine'!$D$33 -> Pit storage | O32: ='Input - Swine'!$G$43 -> 0.2 | P32: ='Input - Swine'!$G$43 -> 0.2 | Q32: ='Input - Swine'!$G$43 -> 0.2 | R32: ='Input - Swine'!$G$43 -> 0.2
D34: M1_Table_FVS_j_m_T-1 | N34: M2_Table_FVS_j_m_T-1
D35: Fraction VS in MMS other than solid storage in stage 1 (Method 1) | N35: Fraction VS in MMS other than solid storage in stage 1 (Method 2)
D36: Stage 1 management | E36: Boars | F36: Sows | G36: Gilts | H36: Others | N36: Stage 1 management | O36: Boars | P36: Sows | Q36: Gilts | R36: Others
D37: ='Input - Swine'!$D$29 -> Anaerobic lagoon | E37: {=MMS_Swine_Methane_Equations.VEERG_4_5_1_1__4_FractionVolatileSolidsPrimarySystem(E19,E28)} -> 0.12 | F37: {=MMS_Swine_Methane_Equations.VEERG_4_5_1_1__4_FractionVolatileSolidsPrimarySystem(F19,F28)} -> 0.12 | G37: {=MMS_Swine_Methane_Equations.VEERG_4_5_1_1__4_FractionVolatileSolidsPrimarySystem(G19,G28)} -> 0.12 | H37: {=MMS_Swine_Methane_Equations.VEERG_4_5_1_1__4_FractionVolatileSolidsPrimarySystem(H19,H28)} -> 0.12 | I37: =$E$11 -> fraction | N37: ='Input - Swine'!$D$29 -> Anaerobic lagoon | O37: {=MMS_Swine_Methane_Equations.VEERG_4_5_1_1__4_FractionVolatileSolidsPrimarySystem(E19,O28)} -> 0.12 | P37: {=MMS_Swine_Methane_Equations.VEERG_4_5_1_1__4_FractionVolatileSolidsPrimarySystem(F19,P28)} -> 0.12 | Q37: {=MMS_Swine_Methane_Equations.VEERG_4_5_1_1__4_FractionVolatileSolidsPrimarySystem(G19,Q28)} -> 0.12 | R37: {=MMS_Swine_Methane_Equations.VEERG_4_5_1_1__4_FractionVolatileSolidsPrimarySystem(H19,R28)} -> 0.12 | S37: =$E$11 -> fraction
D38: ='Input - Swine'!$D$30 -> Drylot (feed pad) | E38: {=MMS_Swine_Methane_Equations.VEERG_4_5_1_1__4_FractionVolatileSolidsPrimarySystem(E20,E29)} -> 0.12 | F38: {=MMS_Swine_Methane_Equations.VEERG_4_5_1_1__4_FractionVolatileSolidsPrimarySystem(F20,F29)} -> 0.12 | G38: {=MMS_Swine_Methane_Equations.VEERG_4_5_1_1__4_FractionVolatileSolidsPrimarySystem(G20,G29)} -> 0.12 | H38: {=MMS_Swine_Methane_Equations.VEERG_4_5_1_1__4_FractionVolatileSolidsPrimarySystem(H20,H29)} -> 0.12 | N38: ='Input - Swine'!$D$30 -> Drylot (feed pad) | O38: {=MMS_Swine_Methane_Equations.VEERG_4_5_1_1__4_FractionVolatileSolidsPrimarySystem(E20,O29)} -> 0.12 | P38: {=MMS_Swine_Methane_Equations.VEERG_4_5_1_1__4_FractionVolatileSolidsPrimarySystem(F20,P29)} -> 0.12 | Q38: {=MMS_Swine_Methane_Equations.VEERG_4_5_1_1__4_FractionVolatileSolidsPrimarySystem(G20,Q29)} -> 0.12 | R38: {=MMS_Swine_Methane_Equations.VEERG_4_5_1_1__4_FractionVolatileSolidsPrimarySystem(H20,R29)} -> 0.12
D39: ='Input - Swine'!$D$31 -> Digester / covered lagoons | E39: {=MMS_Swine_Methane_Equations.VEERG_4_5_1_1__4_FractionVolatileSolidsPrimarySystem(E21,E30)} -> 0.12 | F39: {=MMS_Swine_Methane_Equations.VEERG_4_5_1_1__4_FractionVolatileSolidsPrimarySystem(F21,F30)} -> 0.12 | G39: {=MMS_Swine_Methane_Equations.VEERG_4_5_1_1__4_FractionVolatileSolidsPrimarySystem(G21,G30)} -> 0.12 | H39: {=MMS_Swine_Methane_Equations.VEERG_4_5_1_1__4_FractionVolatileSolidsPrimarySystem(H21,H30)} -> 0.12 | N39: ='Input - Swine'!$D$31 -> Digester / covered lagoons | O39: {=MMS_Swine_Methane_Equations.VEERG_4_5_1_1__4_FractionVolatileSolidsPrimarySystem(E21,O30)} -> 0.12 | P39: {=MMS_Swine_Methane_Equations.VEERG_4_5_1_1__4_FractionVolatileSolidsPrimarySystem(F21,P30)} -> 0.12 | Q39: {=MMS_Swine_Methane_Equations.VEERG_4_5_1_1__4_FractionVolatileSolidsPrimarySystem(G21,Q30)} -> 0.12 | R39: {=MMS_Swine_Methane_Equations.VEERG_4_5_1_1__4_FractionVolatileSolidsPrimarySystem(H21,R30)} -> 0.12
D40: ='Input - Swine'!$D$32 -> Deep litter | E40: {=MMS_Swine_Methane_Equations.VEERG_4_5_1_1__4_FractionVolatileSolidsPrimarySystem(E22,E31)} -> 0.12 | F40: {=MMS_Swine_Methane_Equations.VEERG_4_5_1_1__4_FractionVolatileSolidsPrimarySystem(F22,F31)} -> 0.12 | G40: {=MMS_Swine_Methane_Equations.VEERG_4_5_1_1__4_FractionVolatileSolidsPrimarySystem(G22,G31)} -> 0.12 | H40: {=MMS_Swine_Methane_Equations.VEERG_4_5_1_1__4_FractionVolatileSolidsPrimarySystem(H22,H31)} -> 0.12 | N40: ='Input - Swine'!$D$32 -> Deep litter | O40: {=MMS_Swine_Methane_Equations.VEERG_4_5_1_1__4_FractionVolatileSolidsPrimarySystem(E22,O31)} -> 0.12 | P40: {=MMS_Swine_Methane_Equations.VEERG_4_5_1_1__4_FractionVolatileSolidsPrimarySystem(F22,P31)} -> 0.12 | Q40: {=MMS_Swine_Methane_Equations.VEERG_4_5_1_1__4_FractionVolatileSolidsPrimarySystem(G22,Q31)} -> 0.12 | R40: {=MMS_Swine_Methane_Equations.VEERG_4_5_1_1__4_FractionVolatileSolidsPrimarySystem(H22,R31)} -> 0.12
D41: ='Input - Swine'!$D$33 -> Pit storage | E41: {=MMS_Swine_Methane_Equations.VEERG_4_5_1_1__4_FractionVolatileSolidsPrimarySystem(E23,E32)} -> 0.12 | F41: {=MMS_Swine_Methane_Equations.VEERG_4_5_1_1__4_FractionVolatileSolidsPrimarySystem(F23,F32)} -> 0.12 | G41: {=MMS_Swine_Methane_Equations.VEERG_4_5_1_1__4_FractionVolatileSolidsPrimarySystem(G23,G32)} -> 0.12 | H41: {=MMS_Swine_Methane_Equations.VEERG_4_5_1_1__4_FractionVolatileSolidsPrimarySystem(H23,H32)} -> 0.12 | N41: ='Input - Swine'!$D$33 -> Pit storage | O41: {=MMS_Swine_Methane_Equations.VEERG_4_5_1_1__4_FractionVolatileSolidsPrimarySystem(E23,O32)} -> 0.12 | P41: {=MMS_Swine_Methane_Equations.VEERG_4_5_1_1__4_FractionVolatileSolidsPrimarySystem(F23,P32)} -> 0.12 | Q41: {=MMS_Swine_Methane_Equations.VEERG_4_5_1_1__4_FractionVolatileSolidsPrimarySystem(G23,Q32)} -> 0.12 | R41: {=MMS_Swine_Methane_Equations.VEERG_4_5_1_1__4_FractionVolatileSolidsPrimarySystem(H23,R32)} -> 0.12
D45: {=MMS_Swine_Methane_Equations.VEERG_4_5_1_1__5_FractionVolatileSolidsSolidStorage_Title()} -> Fraction of volatile solids in solid storage
D46: {=MMS_Swine_Methane_Equations.VEERG_4_5_1_1__5_FractionVolatileSolidsSolidStorage_Source()} -> VEERG 2026: 4.5.1.1, Equation (5)
...

Sheet 4.5.1.3-4 Direct N2O
A1: #VALUE! | C1: 4.5.1.3-4 Manure Direct N2O
A3: =HYPERLINK("#'Home'!A1", "Home") -> Home | D3: Method 1 | N3: Method 2
A4: =HYPERLINK("#'Overview'!A1", "Overview") -> Overview
A5: =HYPERLINK("#'Results'!A1", "Results") -> Results | D5: {=MMS_Swine_N2ODirect_Equations.VEERG_4_5_1_3__5_AnnualNitrogenExcretion_Title()} -> Annual nitrogen excretion from each swine group
D6: {=MMS_Swine_N2ODirect_Equations.VEERG_4_5_1_3__5_AnnualNitrogenExcretion_Source()} -> VEERG 2026: 4.5.1.3, Equation (5)
A7: INPUTS | D7: Function name | E7: {=Common_InputFunctions.Utility_DisplayFunctionName($E$35)} -> =MMS_Swine_N2ODirect_Equations.VEERG_4_5_1_3__5_AnnualNitrogenExcretion
A8: =HYPERLINK("#'Input - Site'!A1", "Site") -> Site
A9: =HYPERLINK("#'Input - Swine'!A1", "Swine") -> Swine
D10: Variable | E10: {=MMS_Swine_N2ODirect_Equations.VEERG_4_5_1_3__5_AnnualNitrogenExcretion_Variable()} -> AE_j
A11: CALCULATIONS | D11: Unit | E11: {=MMS_Swine_N2ODirect_Equations.VEERG_4_5_1_3__5_AnnualNitrogenExcretion_Unit()} -> kg N
A12: =HYPERLINK("#'4.5.1.1-2 Methane'!A1", "4.5.1.1-2 Methane") -> 4.5.1.1-2 Methane
A13: =HYPERLINK("#'4.5.1.3-4 Direct N2O'!A1", "4.5.1.3-4 Direct N2O") -> 4.5.1.3-4 Direct N2O | D13: {=Common_InputFunctions.Utility_DisplayArguments_1_2(MMS_Swine_N2ODirect_Equations.VEERG_4_5_1_3__5_AnnualNitrogenExcretion_Arguments())} -> N_j | E13: number of swine in each group | G13: {=Common_InputFunctions.Utility_DisplayArguments_3_4(MMS_Swine_N2ODirect_Equations.VEERG_4_5_1_3__5_AnnualNitrogenExcretion_Arguments())} -> head | H13: Input | I13: {=HYPERLINK(Common_InputFunctions.Utility_SourceHyperlink(D17), D17)} -> Table_N_j
A14: =HYPERLINK("#'4.5.1.5-6 Atmos Dep'!A1", "4.5.1.5-6 Soil atm. deposition") -> 4.5.1.5-6 Soil atm. deposition | D14: NW_j | E14: nitrogen produced in swine manure and waste feed in each class | G14: kg N/head/day | H14: Input | I14: {=HYPERLINK(Common_InputFunctions.Utility_SourceHyperlink(D22), D22)} -> M1_Table_NW_j
A15: =HYPERLINK("#'4.5.1.7-8 Leaching and runoff'!A1", "4.5.1.7-8 Leaching & runoff") -> 4.5.1.7-8 Leaching & runoff | D15: D_j | E15: duration of stay of swine group | G15: days | H15: Input | I15: {=HYPERLINK(Common_InputFunctions.Utility_SourceHyperlink(D27), D27)} -> Table_D_j
A16: =HYPERLINK("#'4.5.1.9 Manure applied to soils'!A1", "4.5.1.9 Manure applied to soils") -> 4.5.1.9 Manure applied to soils
D17: Table_N_j
A18: APPENDICES | D18: Number of head for each swine class
A19: =HYPERLINK("#'Constants - Swine'!A1", "Constants - Swine") -> Constants - Swine | D19: Boars | E19: Sows | F19: Gilts | G19: Others
A20: =HYPERLINK("#'Constants - Livestock'!A1", "Constants - Livestock") -> Constants - Livestock | D20: ='Input - Swine'!$E$11 -> 100 | E20: ='Input - Swine'!$F$11 -> 100 | F20: ='Input - Swine'!$G$11 -> 100 | G20: ='Input - Swine'!$H$11 -> 100 | H20: =G13 -> head
A21: =HYPERLINK("#'Constants - Common'!A1", "Constants - Common") -> Constants - Common
A22: =HYPERLINK("#'Acknowledgements'!A1", "Acknowledgements") -> Acknowledgements | D22: M1_Table_NW_j | N22: M2_Table_NW_j
D23: Nitrogen produced per class (Method 1) | N23: Nitrogen produced per class (Method 2)
D24: Boars | E24: Sows | F24: Gilts | G24: Others | N24: Boars | O24: Sows | P24: Gilts | Q24: Others
D25: ='Input - Swine'!E17 -> 0.046 | E25: ='Input - Swine'!F17 -> 0.049 | F25: ='Input - Swine'!G17 -> 0.046 | G25: ='Input - Swine'!H17 -> 0.0312 | H25: =G14 -> kg N/head/day | N25: ='Input - Swine'!E21 -> 0.046 | O25: ='Input - Swine'!F21 -> 0.049 | P25: ='Input - Swine'!G21 -> 0.046 | Q25: ='Input - Swine'!H21 -> 0.0312 | R25: =G14 -> kg N/head/day
D27: Table_D_j
D28: Duration of stay for each swine class
D29: Boars | E29: Sows | F29: Gilts | G29: Others
D30: ='Input - Swine'!E10 -> 365 | E30: ='Input - Swine'!F10 -> 365 | F30: ='Input - Swine'!G10 -> 365 | G30: ='Input - Swine'!H10 -> 365 | H30: =G15 -> days
D32: M1_Table_AE_j | N32: M2_Table_AE_j
D33: Annual nitrogen excretion (Method 1) | N33: Annual nitrogen excretion (Method 2)
D34: Boars | E34: Sows | F34: Gilts | G34: Others | N34: Boars | O34: Sows | P34: Gilts | Q34: Others
D35: {=MMS_Swine_N2ODirect_Equations.VEERG_4_5_1_3__5_AnnualNitrogenExcretion(D20,D25,D30)} -> 1679 | E35: {=MMS_Swine_N2ODirect_Equations.VEERG_4_5_1_3__5_AnnualNitrogenExcretion(E20,E25,E30)} -> 1788.5 | F35: {=MMS_Swine_N2ODirect_Equations.VEERG_4_5_1_3__5_AnnualNitrogenExcretion(F20,F25,F30)} -> 1679 | G35: {=MMS_Swine_N2ODirect_Equations.VEERG_4_5_1_3__5_AnnualNitrogenExcretion(G20,G25,G30)} -> 1138.8 | H35: =$E$11 -> kg N | N35: {=MMS_Swine_N2ODirect_Equations.VEERG_4_5_1_3__5_AnnualNitrogenExcretion(D20,N25,D30)} -> 1679 | O35: {=MMS_Swine_N2ODirect_Equations.VEERG_4_5_1_3__5_AnnualNitrogenExcretion(E20,O25,E30)} -> 1788.5 | P35: {=MMS_Swine_N2ODirect_Equations.VEERG_4_5_1_3__5_AnnualNitrogenExcretion(F20,P25,F30)} -> 1679 | Q35: {=MMS_Swine_N2ODirect_Equations.VEERG_4_5_1_3__5_AnnualNitrogenExcretion(G20,Q25,G30)} -> 1138.8 | R35: =$E$11 -> kg N
D39: {=MMS_Swine_N2ODirect_Equations.VEERG_4_5_1_3__3_FractionOfNitrogenInPrimaryMMS_Title()} -> Fraction of nitrogen in each primary MMS (excluding solid storage)
D40: {=MMS_Swine_N2ODirect_Equations.VEERG_4_5_1_3__3_FractionOfNitrogenInPrimaryMMS_Source()} -> VEERG 2026: 4.5.1.3, Equation (3)
D41: Function name | E41: {=Common_InputFunctions.Utility_DisplayFunctionName($E$71)} -> =MMS_Swine_N2ODirect_Equations.VEERG_4_5_1_3__3_FractionOfNitrogenInPrimaryMMS
D44: Variable | E44: {=MMS_Swine_N2ODirect_Equations.VEERG_4_5_1_3__3_FractionOfNitrogenInPrimaryMMS_Variable()} -> FN_jmT1
D45: Unit | E45: {=MMS_Swine_N2ODirect_Equations.VEERG_4_5_1_3__3_FractionOfNitrogenInPrimaryMMS_Unit()} -> fraction
D47: {=Common_InputFunctions.Utility_DisplayArguments_1_2(MMS_Swine_N2ODirect_Equations.VEERG_4_5_1_3__3_FractionOfNitrogenInPrimaryMMS_Arguments())} -> MMS_jmT1 | E47: fraction of manure in primary MMS | G47: {=Common_InputFunctions.Utility_DisplayArguments_3_4(MMS_Swine_N2ODirect_Equations.VEERG_4_5_1_3__3_FractionOfNitrogenInPrimaryMMS_Arguments())} -> fraction | H47: Input | I47: {=HYPERLINK(Common_InputFunctions.Utility_SourceHyperlink(D50), D50)} -> Table_MMS_j_m-1-7-9-8_T-1
D48: SN_m | E48: fraction of nitrogen separated to solid storage for each MMS | G48: fraction | H48: Input | I48: {=HYPERLINK(Common_InputFunctions.Utility_SourceHyperlink(D59), D59)} -> M1_Table_SN_m-1-7-9
D50: Table_MMS_j_m-1-7-9-8_T-1
...

Sheet 4.5.1.5-6 Atmos Dep
A1: #VALUE! | C1: 4.5.1.5-6 Atmospheric deposition N2O
A3: =HYPERLINK("#'Home'!A1", "Home") -> Home | D3: Method 1 | N3: Method 2
A4: =HYPERLINK("#'Overview'!A1", "Overview") -> Overview
A5: =HYPERLINK("#'Results'!A1", "Results") -> Results | D5: {=MMS_Swine_AtmosphericDeposition_Equations.VEERG_4_5_1_5__2_TotalNitrogenVolatilisedFromMMS_Title()} -> Total nitrogen volatilised from MMS
D6: {=MMS_Swine_AtmosphericDeposition_Equations.VEERG_4_5_1_5__2_TotalNitrogenVolatilisedFromMMS_Source()} -> VEERG 2026: 4.5.1.1, Equation (2)
A7: INPUTS | D7: Function name | E7: {=Common_InputFunctions.Utility_DisplayFunctionName(F73)} -> =MMS_Swine_AtmosphericDeposition_Equations.VEERG_4_5_1_5__2_TotalNitrogenVolatilisedFromMMS
A8: =HYPERLINK("#'Input - Site'!A1", "Site") -> Site
A9: =HYPERLINK("#'Input - Swine'!A1", "Swine") -> Swine
D10: Variable | E10: {=MMS_Swine_AtmosphericDeposition_Equations.VEERG_4_5_1_5__2_TotalNitrogenVolatilisedFromMMS_Variable()} -> MMS_ATMOS
A11: CALCULATIONS | D11: Unit | E11: {=MMS_Swine_AtmosphericDeposition_Equations.VEERG_4_5_1_5__2_TotalNitrogenVolatilisedFromMMS_Unit()} -> kg N
A12: =HYPERLINK("#'4.5.1.1-2 Methane'!A1", "4.5.1.1-2 Methane") -> 4.5.1.1-2 Methane
A13: =HYPERLINK("#'4.5.1.3-4 Direct N2O'!A1", "4.5.1.3-4 Direct N2O") -> 4.5.1.3-4 Direct N2O | D13: {=Common_InputFunctions.Utility_DisplayArguments_1_2(MMS_Swine_AtmosphericDeposition_Equations.VEERG_4_5_1_5__2_TotalNitrogenVolatilisedFromMMS_Arguments())} -> MN_jmT | E13: nitrogen per swine class, MMS and treatment stage | G13: {=Common_InputFunctions.Utility_DisplayArguments_3_4(MMS_Swine_AtmosphericDeposition_Equations.VEERG_4_5_1_5__2_TotalNitrogenVolatilisedFromMMS_Arguments())} -> kg N | H13: Calculated from 4.5.1.3 (2)(6) | I13: {=HYPERLINK(Common_InputFunctions.Utility_SourceHyperlink(D19), D19)} -> M1_Table_MN_j_m_T-1 | J13: {=HYPERLINK(Common_InputFunctions.Utility_SourceHyperlink(D29), D29)} -> M1_Table_MN_j_m_T-2
A14: =HYPERLINK("#'4.5.1.5-6 Atmos Dep'!A1", "4.5.1.5-6 Soil atm. deposition") -> 4.5.1.5-6 Soil atm. deposition | D14: FracGASMmT | E14: fraction of N volatilised in each MMS | G14: (kg NH3-N + NOx-N)/kg N | H14: Constant | I14: {=HYPERLINK(Common_InputFunctions.Utility_SourceHyperlink(D59), D59)} -> Table_FracGASM_m_t
A15: =HYPERLINK("#'4.5.1.7-8 Leaching and runoff'!A1", "4.5.1.7-8 Leaching & runoff") -> 4.5.1.7-8 Leaching & runoff
A16: =HYPERLINK("#'4.5.1.9 Manure applied to soils'!A1", "4.5.1.9 Manure applied to soils") -> 4.5.1.9 Manure applied to soils | D16: Note: Manure that is directly applied to soil after stage 1 is not included in Atmospheric Deposition calculations
D17: and instead is handled in 'Manure applied to soils'.
A18: APPENDICES
A19: =HYPERLINK("#'Constants - Swine'!A1", "Constants - Swine") -> Constants - Swine | D19: M1_Table_MN_j_m_T-1 | N19: M1_Table_MN_j_m_T-1
A20: =HYPERLINK("#'Constants - Livestock'!A1", "Constants - Livestock") -> Constants - Livestock | D20: Nitrogen in treatment stage 1 MMS (Method 1) | N20: Nitrogen in treatment stage 1 MMS (Method 1)
A21: =HYPERLINK("#'Constants - Common'!A1", "Constants - Common") -> Constants - Common | D21: Stage 1 management | E21: Boars | F21: Sows | G21: Gilts | H21: Others | N21: Stage 1 management | O21: Boars | P21: Sows | Q21: Gilts | R21: Others
A22: =HYPERLINK("#'Acknowledgements'!A1", "Acknowledgements") -> Acknowledgements | D22: ='Input - Swine'!$D$29 -> Anaerobic lagoon | E22: ='4.5.1.3-4 Direct N2O'!E118 -> 201.48 | F22: ='4.5.1.3-4 Direct N2O'!F118 -> 214.62 | G22: ='4.5.1.3-4 Direct N2O'!G118 -> 201.48 | H22: ='4.5.1.3-4 Direct N2O'!H118 -> 136.656 | I22: =$G$13 -> kg N | N22: ='Input - Swine'!$D$29 -> Anaerobic lagoon | O22: ='4.5.1.3-4 Direct N2O'!O118 -> 201.48 | P22: ='4.5.1.3-4 Direct N2O'!P118 -> 214.62 | Q22: ='4.5.1.3-4 Direct N2O'!Q118 -> 201.48 | R22: ='4.5.1.3-4 Direct N2O'!R118 -> 136.656 | S22: =$G$13 -> kg N
D23: ='Input - Swine'!$D$30 -> Drylot (feed pad) | E23: ='4.5.1.3-4 Direct N2O'!E119 -> 201.48 | F23: ='4.5.1.3-4 Direct N2O'!F119 -> 214.62 | G23: ='4.5.1.3-4 Direct N2O'!G119 -> 201.48 | H23: ='4.5.1.3-4 Direct N2O'!H119 -> 136.656 | N23: ='Input - Swine'!$D$30 -> Drylot (feed pad) | O23: ='4.5.1.3-4 Direct N2O'!O119 -> 201.48 | P23: ='4.5.1.3-4 Direct N2O'!P119 -> 214.62 | Q23: ='4.5.1.3-4 Direct N2O'!Q119 -> 201.48 | R23: ='4.5.1.3-4 Direct N2O'!R119 -> 136.656
D24: ='Input - Swine'!$D$31 -> Digester / covered lagoons | E24: ='4.5.1.3-4 Direct N2O'!E120 -> 201.48 | F24: ='4.5.1.3-4 Direct N2O'!F120 -> 214.62 | G24: ='4.5.1.3-4 Direct N2O'!G120 -> 201.48 | H24: ='4.5.1.3-4 Direct N2O'!H120 -> 136.656 | N24: ='Input - Swine'!$D$31 -> Digester / covered lagoons | O24: ='4.5.1.3-4 Direct N2O'!O120 -> 201.48 | P24: ='4.5.1.3-4 Direct N2O'!P120 -> 214.62 | Q24: ='4.5.1.3-4 Direct N2O'!Q120 -> 201.48 | R24: ='4.5.1.3-4 Direct N2O'!R120 -> 136.656
D25: ='Input - Swine'!$D$32 -> Deep litter | E25: ='4.5.1.3-4 Direct N2O'!E121 -> 201.48 | F25: ='4.5.1.3-4 Direct N2O'!F121 -> 214.62 | G25: ='4.5.1.3-4 Direct N2O'!G121 -> 201.48 | H25: ='4.5.1.3-4 Direct N2O'!H121 -> 136.656 | N25: ='Input - Swine'!$D$32 -> Deep litter | O25: ='4.5.1.3-4 Direct N2O'!O121 -> 201.48 | P25: ='4.5.1.3-4 Direct N2O'!P121 -> 214.62 | Q25: ='4.5.1.3-4 Direct N2O'!Q121 -> 201.48 | R25: ='4.5.1.3-4 Direct N2O'!R121 -> 136.656
D26: ='Input - Swine'!$D$33 -> Pit storage | E26: ='4.5.1.3-4 Direct N2O'!E122 -> 201.48 | F26: ='4.5.1.3-4 Direct N2O'!F122 -> 214.62 | G26: ='4.5.1.3-4 Direct N2O'!G122 -> 201.48 | H26: ='4.5.1.3-4 Direct N2O'!H122 -> 136.656 | N26: ='Input - Swine'!$D$33 -> Pit storage | O26: ='4.5.1.3-4 Direct N2O'!O122 -> 201.48 | P26: ='4.5.1.3-4 Direct N2O'!P122 -> 214.62 | Q26: ='4.5.1.3-4 Direct N2O'!Q122 -> 201.48 | R26: ='4.5.1.3-4 Direct N2O'!R122 -> 136.656
D27: ='Input - Swine'!$D$34 -> Solid storage | E27: ='4.5.1.3-4 Direct N2O'!E123 -> 671.6 | F27: ='4.5.1.3-4 Direct N2O'!F123 -> 715.4 | G27: ='4.5.1.3-4 Direct N2O'!G123 -> 671.6 | H27: ='4.5.1.3-4 Direct N2O'!H123 -> 455.52 | N27: ='Input - Swine'!$D$34 -> Solid storage | O27: ='4.5.1.3-4 Direct N2O'!O123 -> 671.6 | P27: ='4.5.1.3-4 Direct N2O'!P123 -> 715.4 | Q27: ='4.5.1.3-4 Direct N2O'!Q123 -> 671.6 | R27: ='4.5.1.3-4 Direct N2O'!R123 -> 455.52
D29: M1_Table_MN_j_m_T-2 | N29: M1_Table_MN_j_m_T-2
D30: Nitrogen in stage 2 MMS (Method 1) | N30: Nitrogen in stage 2 MMS (Method 1)
D31: Stage 1 management | E31: Stage 2 management | F31: Boars | G31: Sows | H31: Gilts | I31: Others | N31: Stage 1 management | O31: Stage 2 management | P31: Boars | Q31: Sows | R31: Gilts | S31: Others
D32: ='Input - Swine'!$D$29 -> Anaerobic lagoon | E32: ='Input - Swine'!$D$48 -> Digester / covered lagoons | F32: ='4.5.1.3-4 Direct N2O'!F217 -> 18.1332 | G32: ='4.5.1.3-4 Direct N2O'!G217 -> 24.14475 | H32: ='4.5.1.3-4 Direct N2O'!H217 -> 22.6665 | I32: ='4.5.1.3-4 Direct N2O'!I217 -> 15.3738 | J32: =$G$13 -> kg N | N32: ='Input - Swine'!$D$29 -> Anaerobic lagoon | O32: ='Input - Swine'!$D$48 -> Digester / covered lagoons | P32: ='4.5.1.3-4 Direct N2O'!P217 -> 18.1332 | Q32: ='4.5.1.3-4 Direct N2O'!Q217 -> 24.14475 | R32: ='4.5.1.3-4 Direct N2O'!R217 -> 22.6665 | S32: ='4.5.1.3-4 Direct N2O'!S217 -> 15.3738 | T32: =$G$13 -> kg N
E33: ='Input - Swine'!$D$49 -> Deep litter | F33: ='4.5.1.3-4 Direct N2O'!F218 -> 18.1332 | G33: ='4.5.1.3-4 Direct N2O'!G218 -> 24.14475 | H33: ='4.5.1.3-4 Direct N2O'!H218 -> 22.6665 | I33: ='4.5.1.3-4 Direct N2O'!I218 -> 15.3738 | O33: ='Input - Swine'!$D$49 -> Deep litter | P33: ='4.5.1.3-4 Direct N2O'!P218 -> 18.1332 | Q33: ='4.5.1.3-4 Direct N2O'!Q218 -> 24.14475 | R33: ='4.5.1.3-4 Direct N2O'!R218 -> 22.6665 | S33: ='4.5.1.3-4 Direct N2O'!S218 -> 15.3738
E34: ='Input - Swine'!$D$50 -> Pit storage | F34: ='4.5.1.3-4 Direct N2O'!F219 -> 18.1332 | G34: ='4.5.1.3-4 Direct N2O'!G219 -> 24.14475 | H34: ='4.5.1.3-4 Direct N2O'!H219 -> 22.6665 | I34: ='4.5.1.3-4 Direct N2O'!I219 -> 15.3738 | O34: ='Input - Swine'!$D$50 -> Pit storage | P34: ='4.5.1.3-4 Direct N2O'!P219 -> 18.1332 | Q34: ='4.5.1.3-4 Direct N2O'!Q219 -> 24.14475 | R34: ='4.5.1.3-4 Direct N2O'!R219 -> 22.6665 | S34: ='4.5.1.3-4 Direct N2O'!S219 -> 15.3738
E35: ='Input - Swine'!$D$51 -> Direct application | F35: ='4.5.1.3-4 Direct N2O'!F220 -> 36.2664 | G35: ='4.5.1.3-4 Direct N2O'!G220 -> 24.14475 | H35: ='4.5.1.3-4 Direct N2O'!H220 -> 22.6665 | I35: ='4.5.1.3-4 Direct N2O'!I220 -> 15.3738 | O35: ='Input - Swine'!$D$51 -> Direct application | P35: ='4.5.1.3-4 Direct N2O'!P220 -> 36.2664 | Q35: ='4.5.1.3-4 Direct N2O'!Q220 -> 24.14475 | R35: ='4.5.1.3-4 Direct N2O'!R220 -> 22.6665 | S35: ='4.5.1.3-4 Direct N2O'!S220 -> 15.3738
D36: ='Input - Swine'!$D$30 -> Drylot (feed pad) | E36: ='Input - Swine'!$D$55 -> Anaerobic lagoon | F36: ='4.5.1.3-4 Direct N2O'!F221 -> 27.40128 | G36: ='4.5.1.3-4 Direct N2O'!G221 -> 36.4854 | H36: ='4.5.1.3-4 Direct N2O'!H221 -> 34.2516 | I36: ='4.5.1.3-4 Direct N2O'!I221 -> 23.23152 | N36: ='Input - Swine'!$D$30 -> Drylot (feed pad) | O36: ='Input - Swine'!$D$55 -> Anaerobic lagoon | P36: ='4.5.1.3-4 Direct N2O'!P221 -> 27.40128 | Q36: ='4.5.1.3-4 Direct N2O'!Q221 -> 36.4854 | R36: ='4.5.1.3-4 Direct N2O'!R221 -> 34.2516 | S36: ='4.5.1.3-4 Direct N2O'!S221 -> 23.23152
E37: ='Input - Swine'!$D$56 -> Digester / covered lagoons | F37: ='4.5.1.3-4 Direct N2O'!F222 -> 27.40128 | G37: ='4.5.1.3-4 Direct N2O'!G222 -> 36.4854 | H37: ='4.5.1.3-4 Direct N2O'!H222 -> 34.2516 | I37: ='4.5.1.3-4 Direct N2O'!I222 -> 23.23152 | O37: ='Input - Swine'!$D$56 -> Digester / covered lagoons | P37: ='4.5.1.3-4 Direct N2O'!P222 -> 27.40128 | Q37: ='4.5.1.3-4 Direct N2O'!Q222 -> 36.4854 | R37: ='4.5.1.3-4 Direct N2O'!R222 -> 34.2516 | S37: ='4.5.1.3-4 Direct N2O'!S222 -> 23.23152
E38: ='Input - Swine'!$D$57 -> Deep litter | F38: ='4.5.1.3-4 Direct N2O'!F223 -> 27.40128 | G38: ='4.5.1.3-4 Direct N2O'!G223 -> 36.4854 | H38: ='4.5.1.3-4 Direct N2O'!H223 -> 34.2516 | I38: ='4.5.1.3-4 Direct N2O'!I223 -> 23.23152 | O38: ='Input - Swine'!$D$57 -> Deep litter | P38: ='4.5.1.3-4 Direct N2O'!P223 -> 27.40128 | Q38: ='4.5.1.3-4 Direct N2O'!Q223 -> 36.4854 | R38: ='4.5.1.3-4 Direct N2O'!R223 -> 34.2516 | S38: ='4.5.1.3-4 Direct N2O'!S223 -> 23.23152
E39: ='Input - Swine'!$D$58 -> Pit storage | F39: ='4.5.1.3-4 Direct N2O'!F224 -> 27.40128 | G39: ='4.5.1.3-4 Direct N2O'!G224 -> 36.4854 | H39: ='4.5.1.3-4 Direct N2O'!H224 -> 34.2516 | I39: ='4.5.1.3-4 Direct N2O'!I224 -> 23.23152 | O39: ='Input - Swine'!$D$58 -> Pit storage | P39: ='4.5.1.3-4 Direct N2O'!P224 -> 27.40128 | Q39: ='4.5.1.3-4 Direct N2O'!Q224 -> 36.4854 | R39: ='4.5.1.3-4 Direct N2O'!R224 -> 34.2516 | S39: ='4.5.1.3-4 Direct N2O'!S224 -> 23.23152
E40: ='Input - Swine'!$D$59 -> Direct application | F40: ='4.5.1.3-4 Direct N2O'!F225 -> 27.40128 | G40: ='4.5.1.3-4 Direct N2O'!G225 -> 0 | H40: ='4.5.1.3-4 Direct N2O'!H225 -> 0 | I40: ='4.5.1.3-4 Direct N2O'!I225 -> 0 | O40: ='Input - Swine'!$D$59 -> Direct application | P40: ='4.5.1.3-4 Direct N2O'!P225 -> 27.40128 | Q40: ='4.5.1.3-4 Direct N2O'!Q225 -> 0 | R40: ='4.5.1.3-4 Direct N2O'!R225 -> 0 | S40: ='4.5.1.3-4 Direct N2O'!S225 -> 0
D41: ='Input - Swine'!$D$31 -> Digester / covered lagoons | E41: ='Input - Swine'!$D$63 -> Anaerobic lagoon | F41: ='4.5.1.3-4 Direct N2O'!F226 -> 40.296 | G41: ='4.5.1.3-4 Direct N2O'!G226 -> 53.655 | H41: ='4.5.1.3-4 Direct N2O'!H226 -> 50.37 | I41: ='4.5.1.3-4 Direct N2O'!I226 -> 34.164 | N41: ='Input - Swine'!$D$31 -> Digester / covered lagoons | O41: ='Input - Swine'!$D$63 -> Anaerobic lagoon | P41: ='4.5.1.3-4 Direct N2O'!P226 -> 40.296 | Q41: ='4.5.1.3-4 Direct N2O'!Q226 -> 53.655 | R41: ='4.5.1.3-4 Direct N2O'!R226 -> 50.37 | S41: ='4.5.1.3-4 Direct N2O'!S226 -> 34.164
E42: ='Input - Swine'!$D$64 -> Deep litter | F42: ='4.5.1.3-4 Direct N2O'!F227 -> 40.296 | G42: ='4.5.1.3-4 Direct N2O'!G227 -> 53.655 | H42: ='4.5.1.3-4 Direct N2O'!H227 -> 50.37 | I42: ='4.5.1.3-4 Direct N2O'!I227 -> 34.164 | O42: ='Input - Swine'!$D$64 -> Deep litter | P42: ='4.5.1.3-4 Direct N2O'!P227 -> 40.296 | Q42: ='4.5.1.3-4 Direct N2O'!Q227 -> 53.655 | R42: ='4.5.1.3-4 Direct N2O'!R227 -> 50.37 | S42: ='4.5.1.3-4 Direct N2O'!S227 -> 34.164
...

Sheet 4.5.1.7-8 Leaching and runoff
A1: #VALUE! | C1: 4.5.1.7-8 Leaching and runoff
A3: =HYPERLINK("#'Home'!A1", "Home") -> Home | D3: Method 1 | M3: Method 2
A4: =HYPERLINK("#'Overview'!A1", "Overview") -> Overview
A5: =HYPERLINK("#'Results'!A1", "Results") -> Results | D5: {=MMS_Swine_LeachingAndRunoff_Equations.VEERG_4_5_1_7__2_MassOfNitrogenLostToLeachingAndRunoffFromDrylotMMS_Title()} -> Mass of nitrogen lost to leaching and runoff from drylot MMS
D6: {=MMS_Swine_LeachingAndRunoff_Equations.VEERG_4_5_1_7__2_MassOfNitrogenLostToLeachingAndRunoffFromDrylotMMS_Source()} -> VEERG 2026: 4.5.1.7, Equation (2)
A7: INPUTS | D7: Function name | E7: {=Common_InputFunctions.Utility_DisplayFunctionName($E$28)} -> =MMS_Swine_LeachingAndRunoff_Equations.VEERG_4_5_1_7__2_MassOfNitrogenLostToLeachingAndRunoffFromDrylotMMS
A8: =HYPERLINK("#'Input - Site'!A1", "Site") -> Site
A9: =HYPERLINK("#'Input - Swine'!A1", "Swine") -> Swine
D10: Variable | E10: {=MMS_Swine_LeachingAndRunoff_Equations.VEERG_4_5_1_7__2_MassOfNitrogenLostToLeachingAndRunoffFromDrylotMMS_Variable()} -> MNLeach_jm5 | F10: This infers that drylot is not a stage 2 MMS option
A11: CALCULATIONS | D11: Unit | E11: {=MMS_Swine_LeachingAndRunoff_Equations.VEERG_4_5_1_7__2_MassOfNitrogenLostToLeachingAndRunoffFromDrylotMMS_Unit()} -> kg N | F11: Doc has typo - refers to 'solid storage'
A12: =HYPERLINK("#'4.5.1.1-2 Methane'!A1", "4.5.1.1-2 Methane") -> 4.5.1.1-2 Methane
A13: =HYPERLINK("#'4.5.1.3-4 Direct N2O'!A1", "4.5.1.3-4 Direct N2O") -> 4.5.1.3-4 Direct N2O | D13: {=Common_InputFunctions.Utility_DisplayArguments_1_2(MMS_Swine_LeachingAndRunoff_Equations.VEERG_4_5_1_7__2_MassOfNitrogenLostToLeachingAndRunoffFromDrylotMMS_Arguments())} -> MN_jm5T1 | E13: nitrogen in treatment stage 1 drylot MMS | G13: {=Common_InputFunctions.Utility_DisplayArguments_3_4(MMS_Swine_LeachingAndRunoff_Equations.VEERG_4_5_1_7__2_MassOfNitrogenLostToLeachingAndRunoffFromDrylotMMS_Arguments())} -> kg N | H13: Calculated from 4.5.1.3 (2) | I13: {=HYPERLINK(Common_InputFunctions.Utility_SourceHyperlink(D20), D20)} -> M1_Table_MN_j_m-5_T-1
A14: =HYPERLINK("#'4.5.1.5-6 Atmos Dep'!A1", "4.5.1.5-6 Soil atm. deposition") -> 4.5.1.5-6 Soil atm. deposition | D14: FracWET | E14: fraction of N available for leaching and runoff | G14: fraction | H14: Constant | I14: =Common_InputFunctions.CommonCropping_GetFracWET(I16,I18,#REF!,#REF!,Table_SourceData_FracWETIrrigation[Irrigation type i],Table_SourceData_FracWETIrrigation[FracWET]) -> 1
A15: =HYPERLINK("#'4.5.1.7-8 Leaching and runoff'!A1", "4.5.1.7-8 Leaching & runoff") -> 4.5.1.7-8 Leaching & runoff | D15: FracLEACH_MS | E15: fraction of N lost through leaching and runoff | G15: fraction | H15: Constant | I15: ='Constants - Swine'!$E$17 -> 0.02
A16: =HYPERLINK("#'4.5.1.9 Manure applied to soils'!A1", "4.5.1.9 Manure applied to soils") -> 4.5.1.9 Manure applied to soils | D16: z | E16: location in leaching zone | H16: Input | I16: ='Input - Site'!$E$23 -> NO - Not in leaching zone
D17: j | E17: production system | H17: Input | I17: ='Input - Swine'!$E$91 -> Crop
A18: APPENDICES | D18: ir | E18: irrigation method | H18: Input | I18: ='Input - Swine'!$E$92 -> Sprinkler irrigation
A19: =HYPERLINK("#'Constants - Swine'!A1", "Constants - Swine") -> Constants - Swine
A20: =HYPERLINK("#'Constants - Livestock'!A1", "Constants - Livestock") -> Constants - Livestock | D20: M1_Table_MN_j_m-5_T-1 | M20: M2_Table_MN_j_m-5_T-1
A21: =HYPERLINK("#'Constants - Common'!A1", "Constants - Common") -> Constants - Common | D21: Nitrogen in stage 1 drylot (Method 1) | M21: Nitrogen in stage 1 drylot (Method 2)
A22: =HYPERLINK("#'Acknowledgements'!A1", "Acknowledgements") -> Acknowledgements | D22: Stage 1 management | E22: Boars | F22: Sows | G22: Gilts | H22: Others | M22: Stage 1 management | N22: Boars | O22: Sows | P22: Gilts | Q22: Others
D23: ='Input - Swine'!$D$30 -> Drylot (feed pad) | E23: ='4.5.1.3-4 Direct N2O'!E119 -> 201.48 | F23: ='4.5.1.3-4 Direct N2O'!F119 -> 214.62 | G23: ='4.5.1.3-4 Direct N2O'!G119 -> 201.48 | H23: ='4.5.1.3-4 Direct N2O'!H119 -> 136.656 | I23: =$G$13 -> kg N | M23: ='Input - Swine'!$D$30 -> Drylot (feed pad) | N23: ='4.5.1.3-4 Direct N2O'!O119 -> 201.48 | O23: ='4.5.1.3-4 Direct N2O'!P119 -> 214.62 | P23: ='4.5.1.3-4 Direct N2O'!Q119 -> 201.48 | Q23: ='4.5.1.3-4 Direct N2O'!R119 -> 136.656 | R23: =$G$13 -> kg N
D25: M1_Table_MN_leach_j_m-5 | M25: M1_Table_MN_leach_j_m-5
D26: Mass of nitrogen lost to leaching (Method 1) | M26: Mass of nitrogen lost to leaching (Method 1)
D27: Stage 1 management | E27: Boars | F27: Sows | G27: Gilts | H27: Others | M27: Stage 1 management | N27: Boars | O27: Sows | P27: Gilts | Q27: Others
D28: ='Input - Swine'!$D$30 -> Drylot (feed pad) | E28: {=MMS_Swine_LeachingAndRunoff_Equations.VEERG_4_5_1_7__2_MassOfNitrogenLostToLeachingAndRunoffFromDrylotMMS(E23,$I$14,$I$15)} -> 4.0296 | F28: {=MMS_Swine_LeachingAndRunoff_Equations.VEERG_4_5_1_7__2_MassOfNitrogenLostToLeachingAndRunoffFromDrylotMMS(F23,$I$14,$I$15)} -> 4.2924 | G28: {=MMS_Swine_LeachingAndRunoff_Equations.VEERG_4_5_1_7__2_MassOfNitrogenLostToLeachingAndRunoffFromDrylotMMS(G23,$I$14,$I$15)} -> 4.0296 | H28: {=MMS_Swine_LeachingAndRunoff_Equations.VEERG_4_5_1_7__2_MassOfNitrogenLostToLeachingAndRunoffFromDrylotMMS(H23,$I$14,$I$15)} -> 2.73312 | I28: =$E$11 -> kg N | M28: ='Input - Swine'!$D$30 -> Drylot (feed pad) | N28: {=MMS_Swine_LeachingAndRunoff_Equations.VEERG_4_5_1_7__2_MassOfNitrogenLostToLeachingAndRunoffFromDrylotMMS(N23,$I$14,$I$15)} -> 4.0296 | O28: {=MMS_Swine_LeachingAndRunoff_Equations.VEERG_4_5_1_7__2_MassOfNitrogenLostToLeachingAndRunoffFromDrylotMMS(O23,$I$14,$I$15)} -> 4.2924 | P28: {=MMS_Swine_LeachingAndRunoff_Equations.VEERG_4_5_1_7__2_MassOfNitrogenLostToLeachingAndRunoffFromDrylotMMS(P23,$I$14,$I$15)} -> 4.0296 | Q28: {=MMS_Swine_LeachingAndRunoff_Equations.VEERG_4_5_1_7__2_MassOfNitrogenLostToLeachingAndRunoffFromDrylotMMS(Q23,$I$14,$I$15)} -> 2.73312 | R28: =$E$11 -> kg N
D32: {=MMS_Swine_LeachingAndRunoff_Equations.VEERG_4_5_1_7__1_AnnualEmissionsFromLeachingAndRunoffFromMMS_Title()} -> Annual emissions from leaching and runoff from each MMS
D33: {=MMS_Swine_LeachingAndRunoff_Equations.VEERG_4_5_1_7__1_AnnualEmissionsFromLeachingAndRunoffFromMMS_Source()} -> VEERG 2026: 4.5.1.7, Equation (1)
D34: Function name | E34: {=Common_InputFunctions.Utility_DisplayFunctionName($E$47)} -> =MMS_Swine_LeachingAndRunoff_Equations.VEERG_4_5_1_7__1_AnnualEmissionsFromLeachingAndRunoffFromMMS
D37: Variable | E37: {=MMS_Swine_LeachingAndRunoff_Equations.VEERG_4_5_1_7__1_AnnualEmissionsFromLeachingAndRunoffFromMMS_Variable()} -> E_N2Oleach
D38: Unit | E38: {=MMS_Swine_LeachingAndRunoff_Equations.VEERG_4_5_1_7__1_AnnualEmissionsFromLeachingAndRunoffFromMMS_Unit()} -> t N2O
