Workbook
Name Common_Equations.Common_ConvertCH4ToCO2e: _xlfn.LAMBDA(_xlpm.E_CH4,_xlpm.GWP_CH4, _xlpm.E_CH4 * _xlpm.GWP_CH4)
Name Common_Equations.Common_ConvertCH4ToCO2e_Arguments: _xlfn.LAMBDA(_xlfn.MAKEARRAY(2, 2, _xlfn.LAMBDA(_xlpm.r,_xlpm.c, INDEX({"ECH4","Methane emissions (t CH4)";"GWPCH4","Global warming potential for methane (t CO2-e / t CH4)"}, _xlpm.r, _xlpm.c))))
Name Common_Equations.Common_ConvertCH4ToCO2e_LatexEquation: _xlfn.LAMBDA("CO2_e = E_{CH4} \times GWP_{CH4}")
Name Common_Equations.Common_ConvertCH4ToCO2e_NIRReference: _xlfn.LAMBDA("")
Name Common_Equations.Common_ConvertCH4ToCO2e_Title: _xlfn.LAMBDA("Convert methane emissions to carbon dioxide equivalent emissions")
Name Common_Equations.Common_ConvertCH4ToCO2e_Unit: _xlfn.LAMBDA("t CO2e")
Name Common_Equations.Common_ConvertCH4ToCO2e_Variable: _xlfn.LAMBDA("ECH4 CO2e")
Name Common_Equations.Common_ConvertN2OToCO2e: _xlfn.LAMBDA(_xlpm.E_N2O,_xlpm.GWP_N2O, _xlpm.E_N2O * _xlpm.GWP_N2O)
Name Common_Equations.Common_ConvertN2OToCO2e_LatexEquation: _xlfn.LAMBDA("CO2_e = E_{N2O} \times GWP_{N2O}")
Name Common_Equations.Common_ConvertN2OToCO2e_NIRReference: _xlfn.LAMBDA("")
Name Common_Equations.Common_ConvertN2OToCO2e_Title: _xlfn.LAMBDA("Convert nitrous oxide emissions to carbon dioxide equivalent emissions")
Name Common_Equations.Common_ConvertN2OToCO2e_Unit: _xlfn.LAMBDA("t CO2e")
Name Common_Equations.Common_ConvertN2OToCO2e_Variable: _xlfn.LAMBDA("EN2O CO2e")
Name Common_InputFunctions.Utility_ConvertStateCommonNameToAbbreviation: _xlfn.LAMBDA(_xlpm.StateCommonName,_xlpm.StateCommonNameArray,_xlpm.StateAbbreviationArray, _xlfn.XLOOKUP(_xlpm.StateCommonName, _xlpm.StateCommonNameArray, _xlpm.StateAbbreviationArray, ""))
Name Common_InputFunctions.Utility_DisplayFunctionName: _xlfn.LAMBDA(_xlpm.Function, _xlfn.TEXTBEFORE(_xlfn.FORMULATEXT(_xlpm.Function), "("))
Name Common_InputFunctions.Utility_GetArrayTableColumnStartNumber: _xlfn.LAMBDA(_xlpm.TableHeaderCell, COLUMN(_xlpm.TableHeaderCell))
Name Common_InputFunctions.Utility_GetArrayTableRowStartNumber: _xlfn.LAMBDA(_xlpm.TableheaderCell,_xlpm.RowsBetweenHeaderandArray, ROW(_xlpm.TableheaderCell) + _xlpm.RowsBetweenHeaderandArray - 1)
Name Common_InputFunctions.Utility_LookupValueInTable: _xlfn.LAMBDA(_xlpm.LookupValue,_xlpm.LookupArray,_xlpm.ReturnArray, _xlfn.XLOOKUP(_xlpm.LookupValue, _xlpm.LookupArray, _xlpm.ReturnArray, ""))
Name Common_SourceData.Common_SourceData_AustralianStatesTerritories_Source: _xlfn.LAMBDA("")
Name Common_SourceData.Common_SourceData_AustralianStatesTerritories_Title: _xlfn.LAMBDA("Australian states and territories")
Name Common_SourceData.Common_SourceData_AustralianStatesTerritories_Unit: _xlfn.LAMBDA("")
Name Common_SourceData.Common_SourceData_AustralianStatesTerritories_Variable: _xlfn.LAMBDA("")
Name Common_SourceData.Common_SourceData_ClimateZones_Source: _xlfn.LAMBDA("VEERG 2026: Table 1.3: Climate and Rainfall zone classifications and definitions")
Name Common_SourceData.Common_SourceData_ClimateZones_Title: _xlfn.LAMBDA("VEERG Australian climate zones")
Name Common_SourceData.Common_SourceData_ClimateZones_Unit: _xlfn.LAMBDA("")
Name Common_SourceData.Common_SourceData_ClimateZones_Variable: _xlfn.LAMBDA("")
Name Common_SourceData.Common_SourceData_ConvertGasElementalToMolecular_Source: _xlfn.LAMBDA("XXXXXXX")
Name Common_SourceData.Common_SourceData_ConvertGasElementalToMolecular_Title: _xlfn.LAMBDA("Factor to convert elemental mass of gas to molecular mass")
Name Common_SourceData.Common_SourceData_ConvertGasElementalToMolecular_Unit: _xlfn.LAMBDA("factor")
Name Common_SourceData.Common_SourceData_ConvertGasElementalToMolecular_Variable: _xlfn.LAMBDA("Cg")
Name Common_SourceData.Common_SourceData_ConvertN2oElementalToMolecularCg_Data: _xlfn.LAMBDA(44 / 28)
Name Common_SourceData.Common_SourceData_ConvertN2oElementalToMolecularCg_Source: _xlfn.LAMBDA("National Inventory Report 2023 Volume 1")
Name Common_SourceData.Common_SourceData_ConvertN2oElementalToMolecularCg_Title: _xlfn.LAMBDA("Factor to convert elemental mass of N2O to molecular mass")
Name Common_SourceData.Common_SourceData_ConvertN2oElementalToMolecularCg_Unit: _xlfn.LAMBDA("factor")
Name Common_SourceData.Common_SourceData_ConvertN2oElementalToMolecularCg_Variable: _xlfn.LAMBDA("CgN2O")
Name Common_SourceData.Common_SourceData_DataScores_Scope3_Source: _xlfn.LAMBDA("VEERG 2026: XXXXXXXX")
Name Common_SourceData.Common_SourceData_DataScores_Scope3_Title: _xlfn.LAMBDA("Australian data scores for scope 3")
Name Common_SourceData.Common_SourceData_DataScores_Scope3_Unit: _xlfn.LAMBDA("")
Name Common_SourceData.Common_SourceData_DataScores_Scope3_Variable: _xlfn.LAMBDA("")
Name Common_SourceData.Common_SourceData_DataScores_Scope3_Variation: _xlfn.LAMBDA("")
Name Common_SourceData.Common_SourceData_DensityOfMethane_Data: _xlfn.LAMBDA(0.6784)
Name Common_SourceData.Common_SourceData_DensityOfMethane_Source: _xlfn.LAMBDA("National Inventory Report 2023 Volume 1: Equations 3.B.1a_2, 3.B.1c_2, 3.B.3_1, 3.B.4g_2")
Name Common_SourceData.Common_SourceData_DensityOfMethane_Title: _xlfn.LAMBDA("p = density of methane")
Name Common_SourceData.Common_SourceData_DensityOfMethane_Unit: _xlfn.LAMBDA("kg/m3")
Name Common_SourceData.Common_SourceData_EFleach_Data: _xlfn.LAMBDA(_xlfn.MAKEARRAY(1, 2, _xlfn.LAMBDA(_xlpm.r,_xlpm.c, INDEX({"EFleach",0.011}, _xlpm.r, _xlpm.c))))
Name Common_SourceData.Common_SourceData_EFleach_NIRReference: _xlfn.LAMBDA("National Inventory Report Volume 1: Equation 3.D.B_10")
Name Common_SourceData.Common_SourceData_EFleach_Source: _xlfn.LAMBDA("VEERG 2026:5.5.2.3 Constant Parameters")
Name Common_SourceData.Common_SourceData_EFleach_Title: _xlfn.LAMBDA("Emission factor for nitrogen leaching and runoff")
Name Common_SourceData.Common_SourceData_EFleach_Unit: _xlfn.LAMBDA("(kg N2O-N / kg N")
Name Common_SourceData.Common_SourceData_EFleach_Variation: _xlfn.LAMBDA((""))
Name Common_SourceData.Common_SourceData_EFN2O_NIRReference: _xlfn.LAMBDA("")
Name Common_SourceData.Common_SourceData_EFN2O_Source: _xlfn.LAMBDA("VEERG 2026: Table A.2.2.1")
Name Common_SourceData.Common_SourceData_EFN2O_Title: _xlfn.LAMBDA("Nitrous oxide emission factors for inorganic fertiliser application")
Name Common_SourceData.Common_SourceData_EFN2O_Unit: _xlfn.LAMBDA("(kg N2O-N / kg N")
Name Common_SourceData.Common_SourceData_EFPastureRangeAndPaddock_Data: _xlfn.LAMBDA(_xlfn.MAKEARRAY(3, 2, _xlfn.LAMBDA(_xlpm.r,_xlpm.c, INDEX({"Climate zone","EFPRP";"Wet climate zone",0.006;"Dry climate zone",0.002}, _xlpm.r, _xlpm.c))))
Name Common_SourceData.Common_SourceData_EFPastureRangeAndPaddock_NIRReference: _xlfn.LAMBDA("")
Name Common_SourceData.Common_SourceData_EFPastureRangeAndPaddock_Source: _xlfn.LAMBDA("VEERG 2026: Table A.2.2.2")
Name Common_SourceData.Common_SourceData_EFPastureRangeAndPaddock_Title: _xlfn.LAMBDA("Emission factor for urine and dung deposited on pasture, range or paddock")
Name Common_SourceData.Common_SourceData_EFPastureRangeAndPaddock_Unit: _xlfn.LAMBDA("kg N2O - N / kg N")
Name Common_SourceData.Common_SourceData_EFPastureRangeAndPaddock_Variation: _xlfn.LAMBDA("VARIATION FROM SOURCE DATA: Changed 'Dry climate zones' to singular 'Dry climate zone' to aid lookup.")

Sheet Home
A1: Home

Sheet Results
A1: #VALUE! | C1: 4.5 Manure management: Swine: Results
A3: =HYPERLINK("#'Home'!A1", "Home") -> Home
A4: =HYPERLINK("#'Results'!A1", "Results") -> Results | D4: Emissions breakdown
A6: INPUTS | D6: Scope 1 source | E6: GHG emissions method 1 | F6: GHG emissions method 2 | G6: GHG Unit | H6: CO2-e emissions method 1 | I6: CO2-e emissions method 2 | J6: CO2-e unit
A7: =HYPERLINK("#'Input - Site'!A1", "Site") -> Site | D7: 4.2.1.1-2 Manure methane | E7: ='4.5.1.1-2 Methane'!$D$276 -> 365 | F7: ='4.5.1.1-2 Methane'!U276 -> 0 | G7: t CH4 | H7: ='4.5.1.1-2 Methane'!#REF! -> #REF! | I7: ='4.5.1.1-2 Methane'!$U$281 -> 0 | J7: t CO2e
A8: =HYPERLINK("#'Input - Swine'!A1", "Swine") -> Swine | D8: 4.2.1.3-4 Soil direct N2O | E8: ='4.2.1.3-4 Soil direct N20'!$E$227 -> #REF! | F8: ='4.2.1.3-4 Soil direct N20'!$U$259 -> #REF! | G8: t N2O | H8: ='4.2.1.3-4 Soil direct N20'!$E$232 -> #REF! | I8: ='4.2.1.3-4 Soil direct N20'!$U$264 -> #REF! | J8: t CO2e
D9: 4.2.1.5-6 Soil atmospheric deposition | E9: ='4.2.1.5-6 Soil Atmos Dep'!$E$35 -> #REF! | F9: ='4.2.1.5-6 Soil Atmos Dep'!$M$35 -> #REF! | G9: ='4.2.1.5-6 Soil Atmos Dep'!$F$35 -> t N2O | H9: ='4.2.1.5-6 Soil Atmos Dep'!$E$40 -> #REF! | I9: ='4.2.1.5-6 Soil Atmos Dep'!$M$40 -> #REF! | J9: t CO2e
A10: CALCULATIONS | D10: 4.2.1.7-8 Soil leaching and runoff | E10: ='4.2.1.7-8 Soil leach runoff'!$E$36 -> #REF! | F10: ='4.2.1.7-8 Soil leach runoff'!$L$36 -> #REF! | G10: ='4.2.1.7-8 Soil leach runoff'!$F$36 -> t N2O | H10: ='4.2.1.7-8 Soil leach runoff'!$E$41 -> #REF! | I10: ='4.2.1.7-8 Soil leach runoff'!$L$41 -> #REF! | J10: t CO2e
A11: =HYPERLINK("#'4.2.1.1-2 Methane'!A1", "4.2.1.1-2 Methane") -> 4.2.1.1-2 Methane | D11: Total | H11: =SUM(H7:H10) -> #REF! | I11: =SUM(I7:I10) -> #REF! | J11: t CO2e
A12: =HYPERLINK("#'4.2.1.3-4 Soil direct N2O'!A1", "4.2.1.3-4 Soil direct N2O") -> 4.2.1.3-4 Soil direct N2O
A13: =HYPERLINK("#'4.2.1.5-6 Soil Atmos Dep'!A1", "4.2.1.5-6 Soil atm. deposition") -> 4.2.1.5-6 Soil atm. deposition
A14: =HYPERLINK("#'4.2.1.7-8 Soil leach runoff'!A1", "4.2.1.7-8 Soil leach & runoff") -> 4.2.1.7-8 Soil leach & runoff
A16: APPENDICES
A17: =HYPERLINK("#'Constants - Swine'!A1", "Constants - Swine") -> Constants - Swine
A18: =HYPERLINK("#'Constants - Livestock'!A1", "Constants - Livestock") -> Constants - Livestock
A19: =HYPERLINK("#'Constants - Common'!A1", "Constants - Common") -> Constants - Common
A20: =HYPERLINK("#'Acknowledgements'!A1", "Acknowledgements") -> Acknowledgements

Sheet Input - Site
A1: #VALUE! | C1: Input - Site
A3: =HYPERLINK("#'Home'!A1", "Home") -> Home
A4: =HYPERLINK("#'Results'!A1", "Results") -> Results
D5: Your business
A6: INPUTS
A7: =HYPERLINK("#'Input - Site'!A1", "Site") -> Site | D7: Farm name | E7: Test Farms
A8: =HYPERLINK("#'Input - Swine'!A1", "Swine") -> Swine | D8: Reporting entity name | E8: Test Farms Pty Ltd
A10: CALCULATIONS | D10: 💡An 'Emissions accounting period' is a 12 month period where the business can report on the emissions, and is typically the same as the business' financial accounting period.
A11: =HYPERLINK("#'4.2.1.1-2 Methane'!A1", "4.2.1.1-2 Methane") -> 4.2.1.1-2 Methane
A12: =HYPERLINK("#'4.2.1.3-4 Soil direct N2O'!A1", "4.2.1.3-4 Soil direct N2O") -> 4.2.1.3-4 Soil direct N2O | D12: Emissions calculation period start date | E12: 45292 | F12: ← DD/MM/YYYY or DD Month YYYY
A13: =HYPERLINK("#'4.2.1.5-6 Soil Atmos Dep'!A1", "4.2.1.5-6 Soil atm. deposition") -> 4.2.1.5-6 Soil atm. deposition | D13: Emissions calculation period end date | E13: =DATE(YEAR(E12)+1,MONTH(E12),DAY(E12))-1 -> 45657 | F13: ← Automatically calculated, 12 months after start date
A14: =HYPERLINK("#'4.2.1.7-8 Soil leach runoff'!A1", "4.2.1.7-8 Soil leach & runoff") -> 4.2.1.7-8 Soil leach & runoff
A16: APPENDICES | D16: Location and climate
A17: =HYPERLINK("#'Constants - Swine'!A1", "Constants - Swine") -> Constants - Swine
A18: =HYPERLINK("#'Constants - Livestock'!A1", "Constants - Livestock") -> Constants - Livestock | D18: Location information is used to reference some region and climate-specific emission factors
A19: =HYPERLINK("#'Constants - Common'!A1", "Constants - Common") -> Constants - Common | D19: Tip: Use the web-based GAF Location Helper tool to easily get region and climate information. You will need an internet connection to use the GAF Location Helper.
A20: =HYPERLINK("#'Acknowledgements'!A1", "Acknowledgements") -> Acknowledgements
D21: State | E21: Western Australia | F21: ← Please select
D22: Region (ABS Statistical area level 4) if state is WA | E22: Western Australia - Outback (South) | F22: ← Please select
D23: Leaching zone | E23: NO - Not in leaching zone | F23: ← Please select
D24: Elevation | E24: 307.7 | F24: Meters
D25: Average temperature for reporting period | E25: 18 | F25: Degrees celsius
D26: Total rainfall for reporting period | E26: 601 | F26: Millimetres
D27: Potential evapotranspiration for reporting period | E27: 1326 | F27: Millimetres
D28: Number of frost days for reporting period | E28: 7 | F28: Days
D29: MAP:PET ratio | E29: =E26/E27 -> 0.45324284
D30: Rainfall zone | E30: =Common_InputFunctions.Utility_LookupItemFromMinMax(E26,Table_SourceData_RainfallZones[Min rainfall],Table_SourceData_RainfallZones[Max rainfall],Table_SourceData_RainfallZones[Rainfall Zone]) -> High rainfall
D31: Climate zone | E31: =Common_InputFunctions.Utility_GetClimateZone(E25,E26,E28,E24,E29,Table_SourceData_ClimateZones[Min temp],Table_SourceData_ClimateZones[Max temp],Table_SourceData_ClimateZones[Min rainfall],Table_SourceData_ClimateZones[Max rainfall],Table_SourceData_ClimateZones[Min frost days],Table_SourceData_ClimateZones[Max frost days],Table_SourceData_ClimateZones[Min elevation],Table_SourceData_ClimateZones[Max elevation],Table_SourceData_ClimateZones[Min MAP:PET],Table_SourceData_ClimateZones[Max MAP:PET],Table_SourceData_ClimateZones[Climate zone]) -> Warm temperate dry
D32: Wet or dry climate zone | E32: =Common_InputFunctions.Utility_LookupValueInTable($E$31,Table_SourceData_WetDryZones[Climate zone],Table_SourceData_WetDryZones[Wet or Dry Zone]) -> Dry climate zone
D33: Temperature zone | E33: =Common_InputFunctions.Utility_LookupItemFromMinMax(E25,Table_SourceData_TemperatureZones[Min MAT],Table_SourceData_TemperatureZones[Max MAT],Table_SourceData_TemperatureZones[Temperature Zone]) -> Temperate

Sheet Input - Swine
A1: #VALUE! | C1: Input -Swine
A3: =HYPERLINK("#'Home'!A1", "Home") -> Home
A4: =HYPERLINK("#'Results'!A1", "Results") -> Results
D5: This tool demostrates inputs for one production system.
A6: INPUTS | D6: Because the type of production system is not relevant in emissions calculations, you can select any kind.
A7: =HYPERLINK("#'Input - Site'!A1", "Site") -> Site
A8: =HYPERLINK("#'Input - Swine'!A1", "Swine") -> Swine
E9: Boars | F9: Sows | G9: Gilts | H9: Suckers | I9: Weaners | J9: Growers | K9: Slaughter pigs
A10: CALCULATIONS | D10: ="Average duration of stay between " & TEXT('Input - Site'!$E$12, "dd mmm yy") & " and " & TEXT('Input - Site'!$E$13, "dd mmm yy") -> Average duration of stay between 01 Jan 24 and 31 Dec 24 | E10: 365 | F10: 365 | G10: 365 | H10: 365 | I10: 365 | J10: 365 | K10: 365 | L10: Days
A11: =HYPERLINK("#'4.2.1.1-2 Methane'!A1", "4.2.1.1-2 Methane") -> 4.2.1.1-2 Methane | D11: ="Average number of head between " & TEXT('Input - Site'!$E$12, "dd mmm yy") & " and " & TEXT('Input - Site'!$E$13, "dd mmm yy") -> Average number of head between 01 Jan 24 and 31 Dec 24 | E11: 100 | F11: 100 | G11: 100 | H11: 100 | I11: 100 | J11: 100 | K11: 100 | L11: Head
A12: =HYPERLINK("#'4.2.1.3-4 Soil direct N2O'!A1", "4.2.1.3-4 Soil direct N2O") -> 4.2.1.3-4 Soil direct N2O
A13: =HYPERLINK("#'4.2.1.5-6 Soil Atmos Dep'!A1", "4.2.1.5-6 Soil atm. deposition") -> 4.2.1.5-6 Soil atm. deposition | D13: Manure production
A14: =HYPERLINK("#'4.2.1.7-8 Soil leach runoff'!A1", "4.2.1.7-8 Soil leach & runoff") -> 4.2.1.7-8 Soil leach & runoff
D15: Method 1 default values (Do not edit) | E15: Boars | F15: Sows | G15: Gilts | H15: Suckers | I15: Weaners | J15: Growers | K15: Slaughter pigs
A16: APPENDICES | D16: Volatile solids produced per head per day | E16: {=Common_InputFunctions.Utility_LookupValueInTableNumber(E15, Table_SourceData_Swine_VolatileSolids[Class], Table_SourceData_Swine_VolatileSolids[VSj])} -> 0.4 | F16: {=Common_InputFunctions.Utility_LookupValueInTableNumber(F15, Table_SourceData_Swine_VolatileSolids[Class], Table_SourceData_Swine_VolatileSolids[VSj])} -> 0.46 | G16: {=Common_InputFunctions.Utility_LookupValueInTableNumber(G15, Table_SourceData_Swine_VolatileSolids[Class], Table_SourceData_Swine_VolatileSolids[VSj])} -> 0.55 | H16: {=Common_InputFunctions.Utility_LookupValueInTableNumber(H15, Table_SourceData_Swine_VolatileSolids[Class], Table_SourceData_Swine_VolatileSolids[VSj])} -> 0.39 | I16: {=Common_InputFunctions.Utility_LookupValueInTableNumber(I15, Table_SourceData_Swine_VolatileSolids[Class], Table_SourceData_Swine_VolatileSolids[VSj])} -> 0.39 | J16: {=Common_InputFunctions.Utility_LookupValueInTableNumber(J15, Table_SourceData_Swine_VolatileSolids[Class], Table_SourceData_Swine_VolatileSolids[VSj])} -> 0.39 | K16: {=Common_InputFunctions.Utility_LookupValueInTableNumber(K15, Table_SourceData_Swine_VolatileSolids[Class], Table_SourceData_Swine_VolatileSolids[VSj])} -> 0.39 | L16: kg/head/day
A17: =HYPERLINK("#'Constants - Swine'!A1", "Constants - Swine") -> Constants - Swine | D17: Nitrogen produced in swine waste per head per day | L17: kg N/head/day
A18: =HYPERLINK("#'Constants - Livestock'!A1", "Constants - Livestock") -> Constants - Livestock
A19: =HYPERLINK("#'Constants - Common'!A1", "Constants - Common") -> Constants - Common | D19: Method 2 custom values (Edit if known) | E19: Boars | F19: Sows | G19: Gilts | H19: Suckers | I19: Weaners | J19: Growers | K19: Slaughter pigs
A20: =HYPERLINK("#'Acknowledgements'!A1", "Acknowledgements") -> Acknowledgements | D20: Volatile solids produced per head per day | E20: {=Common_InputFunctions.Utility_LookupValueInTableNumber(E19, Table_SourceData_Swine_VolatileSolids[Class], Table_SourceData_Swine_VolatileSolids[VSj])} -> 0.4 | F20: {=Common_InputFunctions.Utility_LookupValueInTableNumber(F19, Table_SourceData_Swine_VolatileSolids[Class], Table_SourceData_Swine_VolatileSolids[VSj])} -> 0.46 | G20: {=Common_InputFunctions.Utility_LookupValueInTableNumber(G19, Table_SourceData_Swine_VolatileSolids[Class], Table_SourceData_Swine_VolatileSolids[VSj])} -> 0.55 | H20: {=Common_InputFunctions.Utility_LookupValueInTableNumber(H19, Table_SourceData_Swine_VolatileSolids[Class], Table_SourceData_Swine_VolatileSolids[VSj])} -> 0.39 | I20: {=Common_InputFunctions.Utility_LookupValueInTableNumber(I19, Table_SourceData_Swine_VolatileSolids[Class], Table_SourceData_Swine_VolatileSolids[VSj])} -> 0.39 | J20: {=Common_InputFunctions.Utility_LookupValueInTableNumber(J19, Table_SourceData_Swine_VolatileSolids[Class], Table_SourceData_Swine_VolatileSolids[VSj])} -> 0.39 | K20: {=Common_InputFunctions.Utility_LookupValueInTableNumber(K19, Table_SourceData_Swine_VolatileSolids[Class], Table_SourceData_Swine_VolatileSolids[VSj])} -> 0.39 | L20: kg/head/day
D21: Nitrogen produced in swine waste per head per day | L21: kg N/head/day
D24: Manure management systems
D26: Production system | E26: Conventional housing | F26: ← Please select
D28: Stage 1 MMS | E28: Boars | F28: Sows | G28: Gilts | H28: Suckers | I28: Weaners | J28: Growers | K28: Slaughter pigs
D29: ='Constants - Swine'!$G$41 -> Anaerobic lagoon | E29: 0.15 | F29: 0.15 | G29: 0.15 | H29: 0.15 | I29: 0.15 | J29: 0.15 | K29: 0.15 | L29: Percent
D30: ='Constants - Swine'!$G$42 -> Drylot (feed pad) | E30: 0.15 | F30: 0.15 | G30: 0.15 | H30: 0.15 | I30: 0.15 | J30: 0.15 | K30: 0.15 | L30: Percent
D31: ='Constants - Swine'!$G$43 -> Digester / covered lagoons | E31: 0.15 | F31: 0.15 | G31: 0.15 | H31: 0.15 | I31: 0.15 | J31: 0.15 | K31: 0.15 | L31: Percent
D32: ='Constants - Swine'!$G$44 -> Deep litter | E32: 0.15 | F32: 0.15 | G32: 0.15 | H32: 0.15 | I32: 0.15 | J32: 0.15 | K32: 0.15 | L32: Percent
D33: ='Constants - Swine'!$G$45 -> Pit storage | E33: 0.15 | F33: 0.15 | G33: 0.15 | H33: 0.15 | I33: 0.15 | J33: 0.15 | K33: 0.15 | L33: Percent
D34: Solid storage | E34: 0.25 | F34: 0.25 | G34: 0.25 | H34: 0.25 | I34: 0.25 | J34: 0.25 | K34: 0.25 | L34: Percent
D35: Total sent to all MMS (Must equal 100%) | E35: =SUM(E29,E30,E31,E32,E33,E34) -> 1 | F35: =SUM(F29,F30,F31,F32,F33,F34) -> 1 | G35: =SUM(G29,G30,G31,G32,G33,G34) -> 1 | H35: =SUM(H29,H30,H31,H32,H33,H34) -> 1 | I35: =SUM(I29,I30,I31,I32,I33,I34) -> 1 | J35: =SUM(J29,J30,J31,J32,J33,J34) -> 1 | K35: =SUM(K29,K30,K31,K32,K33,K34) -> 1
D37: ▼
D38: Solid separation from stage 1 MMS | E38: Were solids separated? (select) | F38: Percent separated (Method 1) | G38: Percent separated (Method 2)
D39: ="Solids separated from " & $D$29 -> Solids separated from Anaerobic lagoon | E39: Yes | F39: 0.2 | G39: 0.2
D40: ="Solids separated from " & $D$30 -> Solids separated from Drylot (feed pad) | E40: Yes | F40: 0.2 | G40: 0.2
D41: ="Solids separated from " & $D$31 -> Solids separated from Digester / covered lagoons | E41: Yes | F41: 0.2 | G41: 0.2
D42: ="Solids separated from " & $D$32 -> Solids separated from Deep litter | E42: Yes | F42: 0.2 | G42: 0.2
D43: ="Solids separated from " & $D$33 -> Solids separated from Pit storage | E43: Yes | F43: 0.2 | G43: 0.2
D45: ▼
D46: Stage 2 MMS | E46: Boars | F46: Sows | G46: Gilts | H46: Suckers | I46: Weaners | J46: Growers | K46: Slaughter pigs | L46: ► | M46: Destination after stage 2 MMS (Percent)
D47: ="Stage 2 MMS From " & $D$29 -> Stage 2 MMS From Anaerobic lagoon | E47: =IF(SUM(E29:K29)>0,"Manure was sent to this MMS, please complete this section.","No manure was sent to this MMS. Leave this section blank.") -> Manure was sent to this MMS, please complete this section. | M47: Sold | N47: Fert for own farm (eg crop) | O47: Direct application to soil
...

Sheet 4.5.1.1-2 Methane
A1: #VALUE! | C1: 4.5.1.1-2 Manure Methane
A3: =HYPERLINK("#'Home'!A1", "Home") -> Home | D3: Method 1 | T3: Method 2
A4: =HYPERLINK("#'Results'!A1", "Results") -> Results
D5: {=ManureManagement_Swine_Methane.VEERG_4_5_1_1__4_FractionVolatileSolidsPrimarySystem_Title()} -> Fraction of volatile solids in each primary system other than solid storage
A6: INPUTS | D6: {=ManureManagement_Swine_Methane.VEERG_4_5_1_1__4_FractionVolatileSolidsPrimarySystem_Source()} -> VEERG 2026: 4.5.1.1, Equation (4)
A7: =HYPERLINK("#'Input - Site'!A1", "Site") -> Site | D7: Function name | E7: {=Common_InputFunctions.Utility_DisplayFunctionName($E$40)} -> =ManureManagement_Swine_Methane.VEERG_4_5_1_1__4_FractionVolatileSolidsPrimarySystem
A8: =HYPERLINK("#'Input - Swine'!A1", "Swine") -> Swine
A10: CALCULATIONS | D10: Variable | E10: {=ManureManagement_Swine_Methane.VEERG_4_5_1_1__4_FractionVolatileSolidsPrimarySystem_Variable()} -> FVSjmT1 | G10: Inconsistencies - 'primary system' vs 'stage 1'
A11: =HYPERLINK("#'4.2.1.1-2 Methane'!A1", "4.2.1.1-2 Methane") -> 4.2.1.1-2 Methane | D11: Unit | E11: {=ManureManagement_Swine_Methane.VEERG_4_5_1_1__4_FractionVolatileSolidsPrimarySystem_Unit()} -> fraction
A12: =HYPERLINK("#'4.2.1.3-4 Soil direct N2O'!A1", "4.2.1.3-4 Soil direct N2O") -> 4.2.1.3-4 Soil direct N2O
A13: =HYPERLINK("#'4.2.1.5-6 Soil Atmos Dep'!A1", "4.2.1.5-6 Soil atm. deposition") -> 4.2.1.5-6 Soil atm. deposition | D13: {=ManureManagement_Swine_Methane.VEERG_4_5_1_1__4_FractionVolatileSolidsPrimarySystem_Arguments()} -> MMSjmT1 | E13: fraction of manure to each primary MMS for each class prior to solid separation : fraction | H13: ="See " & $D$16 -> See Table_MMS_j_m-1-7-9-8_T-1 | I13: If this is directly related to equation 5, the mms numbers should be the same eg 1,7,9 (and probably 8,)
A14: =HYPERLINK("#'4.2.1.7-8 Soil leach runoff'!A1", "4.2.1.7-8 Soil leach & runoff") -> 4.2.1.7-8 Soil leach & runoff | D14: SSm | E14: fraction of volatile solids separated to solid storage for each MMS : fraction | H14: ="See " & $D$26 -> See M1_Table_SS_m-1-7-9 | I14: SSm should be SSjm
A16: APPENDICES | D16: Table_MMS_j_m-1-7-9-8_T-1
A17: =HYPERLINK("#'Constants - Swine'!A1", "Constants - Swine") -> Constants - Swine | D17: Fraction VS sent to MMS other than solid storage in stage 1
A18: =HYPERLINK("#'Constants - Livestock'!A1", "Constants - Livestock") -> Constants - Livestock | E18: Boars | F18: Sows | G18: Gilts | H18: Suckers | I18: Weaners | J18: Growers | K18: Slaughter pigs
A19: =HYPERLINK("#'Constants - Common'!A1", "Constants - Common") -> Constants - Common | D19: Stage 1 management | E19: MMSj=1,m=1,7,9,8,13,T=1 | F19: MMSj=2,m=1,7,9,8,13,T=1 | G19: MMSj=3,m=1,7,9,8,13,T=1 | H19: MMSj=4,m=1,7,9,8,13,T=1 | I19: MMSj=4,m=1,7,9,8,13,T=1 | J19: MMSj=4,m=1,7,9,8,13,T=1 | K19: MMSj=4,m=1,7,9,8,13,T=1
A20: =HYPERLINK("#'Acknowledgements'!A1", "Acknowledgements") -> Acknowledgements | D20: ='Input - Swine'!$D$29 -> Anaerobic lagoon | E20: ='Input - Swine'!E29 -> 0.15 | F20: ='Input - Swine'!F29 -> 0.15 | G20: ='Input - Swine'!G29 -> 0.15 | H20: ='Input - Swine'!H29 -> 0.15 | I20: ='Input - Swine'!I29 -> 0.15 | J20: ='Input - Swine'!J29 -> 0.15 | K20: ='Input - Swine'!K29 -> 0.15 | L20: Fraction
D21: ='Input - Swine'!$D$30 -> Drylot (feed pad) | E21: ='Input - Swine'!E30 -> 0.15 | F21: ='Input - Swine'!F30 -> 0.15 | G21: ='Input - Swine'!G30 -> 0.15 | H21: ='Input - Swine'!H30 -> 0.15 | I21: ='Input - Swine'!I30 -> 0.15 | J21: ='Input - Swine'!J30 -> 0.15 | K21: ='Input - Swine'!K30 -> 0.15 | L21: Fraction
D22: ='Input - Swine'!$D$31 -> Digester / covered lagoons | E22: ='Input - Swine'!E31 -> 0.15 | F22: ='Input - Swine'!F31 -> 0.15 | G22: ='Input - Swine'!G31 -> 0.15 | H22: ='Input - Swine'!H31 -> 0.15 | I22: ='Input - Swine'!I31 -> 0.15 | J22: ='Input - Swine'!J31 -> 0.15 | K22: ='Input - Swine'!K31 -> 0.15 | L22: Fraction
D23: ='Input - Swine'!$D$32 -> Deep litter | E23: ='Input - Swine'!E32 -> 0.15 | F23: ='Input - Swine'!F32 -> 0.15 | G23: ='Input - Swine'!G32 -> 0.15 | H23: ='Input - Swine'!H32 -> 0.15 | I23: ='Input - Swine'!I32 -> 0.15 | J23: ='Input - Swine'!J32 -> 0.15 | K23: ='Input - Swine'!K32 -> 0.15 | L23: Fraction
D24: ='Input - Swine'!$D$33 -> Pit storage | E24: ='Input - Swine'!E33 -> 0.15 | F24: ='Input - Swine'!F33 -> 0.15 | G24: ='Input - Swine'!G33 -> 0.15 | H24: ='Input - Swine'!H33 -> 0.15 | I24: ='Input - Swine'!I33 -> 0.15 | J24: ='Input - Swine'!J33 -> 0.15 | K24: ='Input - Swine'!K33 -> 0.15 | L24: Fraction
D26: M1_Table_SS_m-1-7-9
D27: Fraction separated solids sent from MMS other than solid storage to solid storage in stage 1 (Method 1)
E28: Boars | F28: Sows | G28: Gilts | H28: Suckers | I28: Weaners | J28: Growers | K28: Slaughter pigs
D29: Stage 1 management | E29: SSj=1m=1,7,9 | F29: SSj=2m=1,7,9 | G29: SSj=3m=1,7,9 | H29: SSj=4m=1,7,9 | I29: SSj=4m=1,7,9 | J29: SSj=4m=1,7,9 | K29: SSj=4m=1,7,9
D30: ='Input - Swine'!$D$29 -> Anaerobic lagoon | E30: ='Input - Swine'!$F$39 -> 0.2 | F30: ='Input - Swine'!$F$39 -> 0.2 | G30: ='Input - Swine'!$F$39 -> 0.2 | H30: ='Input - Swine'!$F$39 -> 0.2 | I30: ='Input - Swine'!$F$39 -> 0.2 | J30: ='Input - Swine'!$F$39 -> 0.2 | K30: ='Input - Swine'!$F$39 -> 0.2 | L30: Fraction
D31: ='Input - Swine'!$D$30 -> Drylot (feed pad) | E31: ='Input - Swine'!$F$40 -> 0.2 | F31: ='Input - Swine'!$F$40 -> 0.2 | G31: ='Input - Swine'!$F$40 -> 0.2 | H31: ='Input - Swine'!$F$40 -> 0.2 | I31: ='Input - Swine'!$F$40 -> 0.2 | J31: ='Input - Swine'!$F$40 -> 0.2 | K31: ='Input - Swine'!$F$40 -> 0.2 | L31: Fraction
D32: ='Input - Swine'!$D$31 -> Digester / covered lagoons | E32: ='Input - Swine'!$F$41 -> 0.2 | F32: ='Input - Swine'!$F$41 -> 0.2 | G32: ='Input - Swine'!$F$41 -> 0.2 | H32: ='Input - Swine'!$F$41 -> 0.2 | I32: ='Input - Swine'!$F$41 -> 0.2 | J32: ='Input - Swine'!$F$41 -> 0.2 | K32: ='Input - Swine'!$F$41 -> 0.2 | L32: Fraction
D33: ='Input - Swine'!$D$32 -> Deep litter | E33: ='Input - Swine'!$F$42 -> 0.2 | F33: ='Input - Swine'!$F$42 -> 0.2 | G33: ='Input - Swine'!$F$42 -> 0.2 | H33: ='Input - Swine'!$F$42 -> 0.2 | I33: ='Input - Swine'!$F$42 -> 0.2 | J33: ='Input - Swine'!$F$42 -> 0.2 | K33: ='Input - Swine'!$F$42 -> 0.2 | L33: Fraction
D34: ='Input - Swine'!$D$33 -> Pit storage | E34: ='Input - Swine'!$F$43 -> 0.2 | F34: ='Input - Swine'!$F$43 -> 0.2 | G34: ='Input - Swine'!$F$43 -> 0.2 | H34: ='Input - Swine'!$F$43 -> 0.2 | I34: ='Input - Swine'!$F$43 -> 0.2 | J34: ='Input - Swine'!$F$43 -> 0.2 | K34: ='Input - Swine'!$F$43 -> 0.2 | L34: Fraction
D36: M1_Table_FVS_j_m-1-7-9_T-1
D37: Fraction VS in MMS other than solid storage in stage 1 (Method 1)
E38: Boars | F38: Sows | G38: Gilts | H38: Suckers | I38: Weaners | J38: Growers | K38: Slaughter pigs
D39: Stage 1 management | E39: FVSj,m=1,7,9,T=1 | F39: FVSj,m=1,7,9,T=1 | G39: FVSj,m=1,7,9,T=1 | H39: FVSj,m=1,7,9,T=1 | I39: FVSj,m=1,7,9,T=1 | J39: FVSj,m=1,7,9,T=1 | K39: FVSj,m=1,7,9,T=1
D40: ='Input - Swine'!$D$29 -> Anaerobic lagoon | E40: {=ManureManagement_Swine_Methane.VEERG_4_5_1_1__4_FractionVolatileSolidsPrimarySystem(E20,E30)} -> 0.12 | F40: {=ManureManagement_Swine_Methane.VEERG_4_5_1_1__4_FractionVolatileSolidsPrimarySystem(F20,F30)} -> 0.12 | G40: {=ManureManagement_Swine_Methane.VEERG_4_5_1_1__4_FractionVolatileSolidsPrimarySystem(G20,G30)} -> 0.12 | H40: {=ManureManagement_Swine_Methane.VEERG_4_5_1_1__4_FractionVolatileSolidsPrimarySystem(H20,H30)} -> 0.12 | I40: {=ManureManagement_Swine_Methane.VEERG_4_5_1_1__4_FractionVolatileSolidsPrimarySystem(I20,I30)} -> 0.12 | J40: {=ManureManagement_Swine_Methane.VEERG_4_5_1_1__4_FractionVolatileSolidsPrimarySystem(J20,J30)} -> 0.12 | K40: {=ManureManagement_Swine_Methane.VEERG_4_5_1_1__4_FractionVolatileSolidsPrimarySystem(K20,K30)} -> 0.12 | L40: =$E$11 -> fraction
D41: ='Input - Swine'!$D$30 -> Drylot (feed pad) | E41: {=ManureManagement_Swine_Methane.VEERG_4_5_1_1__4_FractionVolatileSolidsPrimarySystem(E21,E31)} -> 0.12 | F41: {=ManureManagement_Swine_Methane.VEERG_4_5_1_1__4_FractionVolatileSolidsPrimarySystem(F21,F31)} -> 0.12 | G41: {=ManureManagement_Swine_Methane.VEERG_4_5_1_1__4_FractionVolatileSolidsPrimarySystem(G21,G31)} -> 0.12 | H41: {=ManureManagement_Swine_Methane.VEERG_4_5_1_1__4_FractionVolatileSolidsPrimarySystem(H21,H31)} -> 0.12 | I41: {=ManureManagement_Swine_Methane.VEERG_4_5_1_1__4_FractionVolatileSolidsPrimarySystem(I21,I31)} -> 0.12 | J41: {=ManureManagement_Swine_Methane.VEERG_4_5_1_1__4_FractionVolatileSolidsPrimarySystem(J21,J31)} -> 0.12 | K41: {=ManureManagement_Swine_Methane.VEERG_4_5_1_1__4_FractionVolatileSolidsPrimarySystem(K21,K31)} -> 0.12 | L41: =$E$11 -> fraction
D42: ='Input - Swine'!$D$31 -> Digester / covered lagoons | E42: {=ManureManagement_Swine_Methane.VEERG_4_5_1_1__4_FractionVolatileSolidsPrimarySystem(E22,E32)} -> 0.12 | F42: {=ManureManagement_Swine_Methane.VEERG_4_5_1_1__4_FractionVolatileSolidsPrimarySystem(F22,F32)} -> 0.12 | G42: {=ManureManagement_Swine_Methane.VEERG_4_5_1_1__4_FractionVolatileSolidsPrimarySystem(G22,G32)} -> 0.12 | H42: {=ManureManagement_Swine_Methane.VEERG_4_5_1_1__4_FractionVolatileSolidsPrimarySystem(H22,H32)} -> 0.12 | I42: {=ManureManagement_Swine_Methane.VEERG_4_5_1_1__4_FractionVolatileSolidsPrimarySystem(I22,I32)} -> 0.12 | J42: {=ManureManagement_Swine_Methane.VEERG_4_5_1_1__4_FractionVolatileSolidsPrimarySystem(J22,J32)} -> 0.12 | K42: {=ManureManagement_Swine_Methane.VEERG_4_5_1_1__4_FractionVolatileSolidsPrimarySystem(K22,K32)} -> 0.12 | L42: =$E$11 -> fraction
D43: ='Input - Swine'!$D$32 -> Deep litter | E43: {=ManureManagement_Swine_Methane.VEERG_4_5_1_1__4_FractionVolatileSolidsPrimarySystem(E23,E33)} -> 0.12 | F43: {=ManureManagement_Swine_Methane.VEERG_4_5_1_1__4_FractionVolatileSolidsPrimarySystem(F23,F33)} -> 0.12 | G43: {=ManureManagement_Swine_Methane.VEERG_4_5_1_1__4_FractionVolatileSolidsPrimarySystem(G23,G33)} -> 0.12 | H43: {=ManureManagement_Swine_Methane.VEERG_4_5_1_1__4_FractionVolatileSolidsPrimarySystem(H23,H33)} -> 0.12 | I43: {=ManureManagement_Swine_Methane.VEERG_4_5_1_1__4_FractionVolatileSolidsPrimarySystem(I23,I33)} -> 0.12 | J43: {=ManureManagement_Swine_Methane.VEERG_4_5_1_1__4_FractionVolatileSolidsPrimarySystem(J23,J33)} -> 0.12 | K43: {=ManureManagement_Swine_Methane.VEERG_4_5_1_1__4_FractionVolatileSolidsPrimarySystem(K23,K33)} -> 0.12 | L43: =$E$11 -> fraction
D44: ='Input - Swine'!$D$33 -> Pit storage | E44: {=ManureManagement_Swine_Methane.VEERG_4_5_1_1__4_FractionVolatileSolidsPrimarySystem(E24,E34)} -> 0.12 | F44: {=ManureManagement_Swine_Methane.VEERG_4_5_1_1__4_FractionVolatileSolidsPrimarySystem(F24,F34)} -> 0.12 | G44: {=ManureManagement_Swine_Methane.VEERG_4_5_1_1__4_FractionVolatileSolidsPrimarySystem(G24,G34)} -> 0.12 | H44: {=ManureManagement_Swine_Methane.VEERG_4_5_1_1__4_FractionVolatileSolidsPrimarySystem(H24,H34)} -> 0.12 | I44: {=ManureManagement_Swine_Methane.VEERG_4_5_1_1__4_FractionVolatileSolidsPrimarySystem(I24,I34)} -> 0.12 | J44: {=ManureManagement_Swine_Methane.VEERG_4_5_1_1__4_FractionVolatileSolidsPrimarySystem(J24,J34)} -> 0.12 | K44: {=ManureManagement_Swine_Methane.VEERG_4_5_1_1__4_FractionVolatileSolidsPrimarySystem(K24,K34)} -> 0.12 | L44: =$E$11 -> fraction
D48: {=ManureManagement_Swine_Methane.VEERG_4_5_1_1__5_FractionVolatileSolidsSolidStorage_Title()} -> Fraction of volatile solids in solid storage | F48: Rename to 'Fraction of volatile solids in primary system in solid storage'
...

Sheet 4.2.1.3-4 Soil direct N20
A1: #VALUE! | C1: 4.2.1.3-4 Manure Direct N2O
A3: =HYPERLINK("#'Home'!A1", "Home") -> Home | D3: Method 1 | T3: Method 2
A4: =HYPERLINK("#'Results'!A1", "Results") -> Results
D5: {=MMS_PastureBeef_Soil_N2ODirect_Equations.VEERG_4_2_1_3__7_RelativeSize_Title()} -> Relative size of the cattle
A6: INPUTS | D6: {=MMS_PastureBeef_Soil_N2ODirect_Equations.VEERG_4_2_1_3__7_RelativeSize_Source()} -> VEERG 2026: 4.2.1.3, Equation (7)
A7: =HYPERLINK("#'Input - Site'!A1", "Site") -> Site | D7: Function name | E7: {=Common_InputFunctions.Utility_DisplayFunctionName(E33)} -> =MMS_PastureBeef_Soil_N2ODirect_Equations.VEERG_4_2_1_3__7_RelativeSize
A8: =HYPERLINK("#'Input - Swine'!A1", "Swine") -> Swine
A10: CALCULATIONS | D10: Variable | E10: {=MMS_PastureBeef_Soil_N2ODirect_Equations.VEERG_4_2_1_3__7_RelativeSize_Variable()} -> Z_jkl
A11: =HYPERLINK("#'4.2.1.1-2 Methane'!A1", "4.2.1.1-2 Methane") -> 4.2.1.1-2 Methane | D11: Unit | E11: {=MMS_PastureBeef_Soil_N2ODirect_Equations.VEERG_4_2_1_3__7_RelativeSize_Unit()} -> ratio
A12: =HYPERLINK("#'4.2.1.3-4 Soil direct N2O'!A1", "4.2.1.3-4 Soil direct N2O") -> 4.2.1.3-4 Soil direct N2O
A13: =HYPERLINK("#'4.2.1.5-6 Soil Atmos Dep'!A1", "4.2.1.5-6 Soil atm. deposition") -> 4.2.1.5-6 Soil atm. deposition | D13: {=MMS_PastureBeef_Soil_N2ODirect_Equations.VEERG_4_2_1_3__7_RelativeSize_Arguments()} -> W_jkl | E13: liveweight (kg) | F13: ="See " & D17 -> See M1_Table_W_j_k_l | G13: Variable is LW in Methane
A14: =HYPERLINK("#'4.2.1.7-8 Soil leach runoff'!A1", "4.2.1.7-8 Soil leach & runoff") -> 4.2.1.7-8 Soil leach & runoff | D14: SRW_k | E14: standard reference weight (kg) | F14: ="See " & D25 -> See Table_SRW_k
D15: i | E15: state | F15: ='Input - Swine'!$E$7 -> 0
A16: APPENDICES
A17: =HYPERLINK("#'Constants - Swine'!A1", "Constants - Swine") -> Constants - Swine | D17: M1_Table_W_j_k_l | T17: M2_Table_LW_j_k_l
A18: =HYPERLINK("#'Constants - Livestock'!A1", "Constants - Livestock") -> Constants - Livestock | D18: Liveweight (Method 1) | T18: Liveweight (Method 2)
A19: =HYPERLINK("#'Constants - Common'!A1", "Constants - Common") -> Constants - Common | D19: Season | E19: Bulls < 1 year | F19: Bulls > 1 year | G19: Cows < 1 year | H19: Cows 1-2 years | I19: Cows 2-3 years | J19: Cows > 3 years | K19: Steers < 1 year | L19: Steers 1-2 years | M19: Steers 2-3 years | N19: Steers >3 years | T19: Month | U19: Bulls < 1 year | V19: Bulls > 1 year | W19: Cows < 1 year | X19: Cows 1-2 years | Y19: Cows 2-3 years | Z19: Cows > 3 years | AA19: Steers < 1 year | AB19: Steers 1-2 years | AC19: Steers 2-3 years | AD19: Steers >3 years
A20: =HYPERLINK("#'Acknowledgements'!A1", "Acknowledgements") -> Acknowledgements | D20: ='Input - Swine'!D138 -> 0 | E20: ='Input - Swine'!E138 -> 0 | F20: ='Input - Swine'!F138 -> 0 | G20: ='Input - Swine'!G138 -> 0 | H20: ='Input - Swine'!H138 -> 0 | I20: ='Input - Swine'!I138 -> 0 | J20: ='Input - Swine'!J138 -> 0 | K20: ='Input - Swine'!K138 -> 0 | ... M20: ='Input - Swine'!M138 -> 0 | N20: ='Input - Swine'!N118 -> 0 | O20: kg/head | T20: =TEXT('Input - Site'!$E$12, "mmmm yyyy") -> January 2024 | U20: ='Input - Swine'!E144 -> 0 | V20: ='Input - Swine'!F144 -> 0 | W20: ='Input - Swine'!G144 -> 0 | X20: ='Input - Swine'!H144 -> 0 | Y20: ='Input - Swine'!I144 -> 0 | Z20: ='Input - Swine'!J144 -> 0 | AA20: ='Input - Swine'!K144 -> 0 | AB20: ='Input - Swine'!L144 -> 0 | AC20: ='Input - Swine'!M144 -> 0 | AD20: ='Input - Swine'!N124 -> 0 | AE20: kg/head
D21: ='Input - Swine'!D139 -> 0 | E21: ='Input - Swine'!E139 -> 0 | F21: ='Input - Swine'!F139 -> 0 | G21: ='Input - Swine'!G139 -> 0 | H21: ='Input - Swine'!H139 -> 0 | I21: ='Input - Swine'!I139 -> 0 | J21: ='Input - Swine'!J139 -> 0 | K21: ='Input - Swine'!K139 -> 0 | ... M21: ='Input - Swine'!M139 -> 0 | N21: ='Input - Swine'!N119 -> 0 | O21: kg/head | T21: =TEXT(EDATE('Input - Site'!$E$12,1), "mmmm yyyy") -> February 2024 | U21: ='Input - Swine'!E145 -> 0 | V21: ='Input - Swine'!F145 -> 0 | W21: ='Input - Swine'!G145 -> 0 | X21: ='Input - Swine'!H145 -> 0 | Y21: ='Input - Swine'!I145 -> 0 | Z21: ='Input - Swine'!J145 -> 0 | AA21: ='Input - Swine'!K145 -> 0 | AB21: ='Input - Swine'!L145 -> 0 | AC21: ='Input - Swine'!M145 -> 0 | AD21: ='Input - Swine'!N125 -> 0 | AE21: kg/head
D22: ='Input - Swine'!D140 -> 0 | E22: ='Input - Swine'!E140 -> 0 | F22: ='Input - Swine'!F140 -> 0 | G22: ='Input - Swine'!G140 -> 0 | H22: ='Input - Swine'!H140 -> 0 | I22: ='Input - Swine'!I140 -> 0 | J22: ='Input - Swine'!J140 -> 0 | K22: ='Input - Swine'!K140 -> 0 | ... M22: ='Input - Swine'!M140 -> 0 | N22: ='Input - Swine'!N120 -> 0 | O22: kg/head | T22: =TEXT(EDATE('Input - Site'!$E$12,2), "mmmm yyyy") -> March 2024 | U22: ='Input - Swine'!E146 -> 0 | V22: ='Input - Swine'!F146 -> 0 | W22: ='Input - Swine'!G146 -> 0 | X22: ='Input - Swine'!H146 -> 0 | Y22: ='Input - Swine'!I146 -> 0 | Z22: ='Input - Swine'!J146 -> 0 | AA22: ='Input - Swine'!K146 -> 0 | AB22: ='Input - Swine'!L146 -> 0 | AC22: ='Input - Swine'!M146 -> 0 | AD22: ='Input - Swine'!N126 -> 0 | AE22: kg/head
D23: ='Input - Swine'!D141 -> 0 | E23: ='Input - Swine'!E141 -> 0 | F23: ='Input - Swine'!F141 -> 0 | G23: ='Input - Swine'!G141 -> 0 | H23: ='Input - Swine'!H141 -> 0 | I23: ='Input - Swine'!I141 -> 0 | J23: ='Input - Swine'!J141 -> 0 | K23: ='Input - Swine'!K141 -> 0 | ... M23: ='Input - Swine'!M141 -> 0 | N23: ='Input - Swine'!N121 -> 0 | O23: kg/head | T23: =TEXT(EDATE('Input - Site'!$E$12,3), "mmmm yyyy") -> April 2024 | U23: ='Input - Swine'!E147 -> 0 | V23: ='Input - Swine'!F147 -> 0 | W23: ='Input - Swine'!G147 -> 0 | X23: ='Input - Swine'!H147 -> 0 | Y23: ='Input - Swine'!I147 -> 0 | Z23: ='Input - Swine'!J147 -> 0 | AA23: ='Input - Swine'!K147 -> 0 | AB23: ='Input - Swine'!L147 -> 0 | AC23: ='Input - Swine'!M147 -> 0 | AD23: ='Input - Swine'!N127 -> 0 | AE23: kg/head
T24: =TEXT(EDATE('Input - Site'!$E$12,4), "mmmm yyyy") -> May 2024 | U24: ='Input - Swine'!E148 -> 0 | V24: ='Input - Swine'!F148 -> 0 | W24: ='Input - Swine'!G148 -> 0 | X24: ='Input - Swine'!H148 -> 0 | Y24: ='Input - Swine'!I148 -> 0 | Z24: ='Input - Swine'!J148 -> 0 | AA24: ='Input - Swine'!K148 -> 0 | AB24: ='Input - Swine'!L148 -> 0 | AC24: ='Input - Swine'!M148 -> 0 | AD24: ='Input - Swine'!N128 -> 0 | AE24: kg/head
D25: Table_SRW_k | T25: =TEXT(EDATE('Input - Site'!$E$12,5), "mmmm yyyy") -> June 2024 | U25: ='Input - Swine'!E149 -> 0 | V25: ='Input - Swine'!F149 -> 0 | W25: ='Input - Swine'!G149 -> 0 | X25: ='Input - Swine'!H149 -> 0 | Y25: ='Input - Swine'!I149 -> 0 | Z25: ='Input - Swine'!J149 -> 0 | AA25: ='Input - Swine'!K149 -> 0 | AB25: ='Input - Swine'!L149 -> 0 | AC25: ='Input - Swine'!M149 -> 0 | AD25: ='Input - Swine'!N129 -> 0 | AE25: kg/head
D26: Standard reference weight | T26: =TEXT(EDATE('Input - Site'!$E$12,6), "mmmm yyyy") -> July 2024 | U26: ='Input - Swine'!E150 -> 0 | V26: ='Input - Swine'!F150 -> 0 | W26: ='Input - Swine'!G150 -> 0 | X26: ='Input - Swine'!H150 -> 0 | Y26: ='Input - Swine'!I150 -> 0 | Z26: ='Input - Swine'!J150 -> 0 | AA26: ='Input - Swine'!K150 -> 0 | AB26: ='Input - Swine'!L150 -> 0 | AC26: ='Input - Swine'!M150 -> 0 | AD26: ='Input - Swine'!N130 -> 0 | AE26: kg/head
D27: Bulls < 1 year | E27: Bulls > 1 year | F27: Cows < 1 year | G27: Cows 1-2 years | H27: Cows 2-3 years | I27: Cows > 3 years | J27: Steers < 1 year | K27: Steers 1-2 years | L27: Steers 2-3 years | M27: Steers >3 years | T27: =TEXT(EDATE('Input - Site'!$E$12,7), "mmmm yyyy") -> August 2024 | U27: ='Input - Swine'!E151 -> 0 | V27: ='Input - Swine'!F151 -> 0 | W27: ='Input - Swine'!G151 -> 0 | X27: ='Input - Swine'!H151 -> 0 | Y27: ='Input - Swine'!I151 -> 0 | Z27: ='Input - Swine'!J151 -> 0 | AA27: ='Input - Swine'!K151 -> 0 | AB27: ='Input - Swine'!L151 -> 0 | AC27: ='Input - Swine'!M151 -> 0 | AD27: ='Input - Swine'!N131 -> 0 | AE27: kg/head
D28: =Common_InputFunctions.Utility_LookupValueInTableOneColumnAndHeader(Common_InputFunctions.Utility_ConvertStateCommonNameToAbbreviation($F$15,Table_AustralianStates[Common Name],Table_AustralianStates[Abbreviation]),D27,#REF!,#REF!,#REF!) -> #REF! | E28: =Common_InputFunctions.Utility_LookupValueInTableOneColumnAndHeader(Common_InputFunctions.Utility_ConvertStateCommonNameToAbbreviation($F$15,Table_AustralianStates[Common Name],Table_AustralianStates[Abbreviation]),E27,#REF!,#REF!,#REF!) -> #REF! | F28: =Common_InputFunctions.Utility_LookupValueInTableOneColumnAndHeader(Common_InputFunctions.Utility_ConvertStateCommonNameToAbbreviation($F$15,Table_AustralianStates[Common Name],Table_AustralianStates[Abbreviation]),F27,#REF!,#REF!,#REF!) -> #REF! | G28: =Common_InputFunctions.Utility_LookupValueInTableOneColumnAndHeader(Common_InputFunctions.Utility_ConvertStateCommonNameToAbbreviation($F$15,Table_AustralianStates[Common Name],Table_AustralianStates[Abbreviation]),G27,#REF!,#REF!,#REF!) -> #REF! | H28: =Common_InputFunctions.Utility_LookupValueInTableOneColumnAndHeader(Common_InputFunctions.Utility_ConvertStateCommonNameToAbbreviation($F$15,Table_AustralianStates[Common Name],Table_AustralianStates[Abbreviation]),H27,#REF!,#REF!,#REF!) -> #REF! | I28: =Common_InputFunctions.Utility_LookupValueInTableOneColumnAndHeader(Common_InputFunctions.Utility_ConvertStateCommonNameToAbbreviation($F$15,Table_AustralianStates[Common Name],Table_AustralianStates[Abbreviation]),I27,#REF!,#REF!,#REF!) -> #REF! | J28: =Common_InputFunctions.Utility_LookupValueInTableOneColumnAndHeader(Common_InputFunctions.Utility_ConvertStateCommonNameToAbbreviation($F$15,Table_AustralianStates[Common Name],Table_AustralianStates[Abbreviation]),J27,#REF!,#REF!,#REF!) -> #REF! | K28: =Common_InputFunctions.Utility_LookupValueInTableOneColumnAndHeader(Common_InputFunctions.Utility_ConvertStateCommonNameToAbbreviation($F$15,Table_AustralianStates[Common Name],Table_AustralianStates[Abbreviation]),K27,#REF!,#REF!,#REF!) -> #REF! | ... M28: =Common_InputFunctions.Utility_LookupValueInTableOneColumnAndHeader(Common_InputFunctions.Utility_ConvertStateCommonNameToAbbreviation($F$15,Table_AustralianStates[Common Name],Table_AustralianStates[Abbreviation]),M27,#REF!,#REF!,#REF!) -> #REF! | N28: kg/head | T28: =TEXT(EDATE('Input - Site'!$E$12,8), "mmmm yyyy") -> September 2024 | U28: ='Input - Swine'!E152 -> 0 | V28: ='Input - Swine'!F152 -> 0 | W28: ='Input - Swine'!G152 -> 0 | X28: ='Input - Swine'!H152 -> 0 | Y28: ='Input - Swine'!I152 -> 0 | Z28: ='Input - Swine'!J152 -> 0 | AA28: ='Input - Swine'!K152 -> 0 | AB28: ='Input - Swine'!L152 -> 0 | AC28: ='Input - Swine'!M152 -> 0 | AD28: ='Input - Swine'!N132 -> 0 | AE28: kg/head
T29: =TEXT(EDATE('Input - Site'!$E$12,9), "mmmm yyyy") -> October 2024 | U29: ='Input - Swine'!E153 -> 0 | V29: ='Input - Swine'!F153 -> 0 | W29: ='Input - Swine'!G153 -> 0 | X29: ='Input - Swine'!H153 -> 0 | Y29: ='Input - Swine'!I153 -> 0 | Z29: ='Input - Swine'!J153 -> 0 | AA29: ='Input - Swine'!K153 -> 0 | AB29: ='Input - Swine'!L153 -> 0 | AC29: ='Input - Swine'!M153 -> 0 | AD29: ='Input - Swine'!N133 -> 0 | AE29: kg/head
D30: M1_Table_Z_j_k_l | T30: =TEXT(EDATE('Input - Site'!$E$12,10), "mmmm yyyy") -> November 2024 | U30: ='Input - Swine'!E154 -> 0 | V30: ='Input - Swine'!F154 -> 0 | W30: ='Input - Swine'!G154 -> 0 | X30: ='Input - Swine'!H154 -> 0 | Y30: ='Input - Swine'!I154 -> 0 | Z30: ='Input - Swine'!J154 -> 0 | AA30: ='Input - Swine'!K154 -> 0 | AB30: ='Input - Swine'!L154 -> 0 | AC30: ='Input - Swine'!M154 -> 0 | AD30: ='Input - Swine'!N134 -> 0 | AE30: kg/head
D31: Relative size (Method 1) | T31: =TEXT(EDATE('Input - Site'!$E$12,11), "mmmm yyyy") -> December 2024 | U31: ='Input - Swine'!E155 -> 0 | V31: ='Input - Swine'!F155 -> 0 | W31: ='Input - Swine'!G155 -> 0 | X31: ='Input - Swine'!H155 -> 0 | Y31: ='Input - Swine'!I155 -> 0 | Z31: ='Input - Swine'!J155 -> 0 | AA31: ='Input - Swine'!K155 -> 0 | AB31: ='Input - Swine'!L155 -> 0 | AC31: ='Input - Swine'!M155 -> 0 | AD31: ='Input - Swine'!N135 -> 0 | AE31: kg/head
D32: Season | E32: Bulls < 1 year | F32: Bulls > 1 year | G32: Cows < 1 year | H32: Cows 1-2 years | I32: Cows 2-3 years | J32: Cows > 3 years | K32: Steers < 1 year | L32: Steers 1-2 years | M32: Steers 2-3 years | N32: Steers >3 years
D33: ='Input - Swine'!D138 -> 0 | E33: {=MMS_PastureBeef_Soil_N2ODirect_Equations.VEERG_4_2_1_3__7_RelativeSize(E20,D$28)} -> #REF! | F33: {=MMS_PastureBeef_Soil_N2ODirect_Equations.VEERG_4_2_1_3__7_RelativeSize(F20,E$28)} -> #REF! | G33: {=MMS_PastureBeef_Soil_N2ODirect_Equations.VEERG_4_2_1_3__7_RelativeSize(G20,F$28)} -> #REF! | H33: {=MMS_PastureBeef_Soil_N2ODirect_Equations.VEERG_4_2_1_3__7_RelativeSize(H20,G$28)} -> #REF! | I33: {=MMS_PastureBeef_Soil_N2ODirect_Equations.VEERG_4_2_1_3__7_RelativeSize(I20,H$28)} -> #REF! | J33: {=MMS_PastureBeef_Soil_N2ODirect_Equations.VEERG_4_2_1_3__7_RelativeSize(J20,I$28)} -> #REF! | K33: {=MMS_PastureBeef_Soil_N2ODirect_Equations.VEERG_4_2_1_3__7_RelativeSize(K20,J$28)} -> #REF! | L33: {=MMS_PastureBeef_Soil_N2ODirect_Equations.VEERG_4_2_1_3__7_RelativeSize(L20,K$28)} -> #REF! | ... N33: {=MMS_PastureBeef_Soil_N2ODirect_Equations.VEERG_4_2_1_3__7_RelativeSize(N20,M$28)} -> #REF! | O33: =$E$11 -> ratio | T33: M2_Table_Z_j_k_l
D34: ='Input - Swine'!D139 -> 0 | E34: {=MMS_PastureBeef_Soil_N2ODirect_Equations.VEERG_4_2_1_3__7_RelativeSize(E21,D$28)} -> #REF! | F34: {=MMS_PastureBeef_Soil_N2ODirect_Equations.VEERG_4_2_1_3__7_RelativeSize(F21,E$28)} -> #REF! | G34: {=MMS_PastureBeef_Soil_N2ODirect_Equations.VEERG_4_2_1_3__7_RelativeSize(G21,F$28)} -> #REF! | H34: {=MMS_PastureBeef_Soil_N2ODirect_Equations.VEERG_4_2_1_3__7_RelativeSize(H21,G$28)} -> #REF! | I34: {=MMS_PastureBeef_Soil_N2ODirect_Equations.VEERG_4_2_1_3__7_RelativeSize(I21,H$28)} -> #REF! | J34: {=MMS_PastureBeef_Soil_N2ODirect_Equations.VEERG_4_2_1_3__7_RelativeSize(J21,I$28)} -> #REF! | K34: {=MMS_PastureBeef_Soil_N2ODirect_Equations.VEERG_4_2_1_3__7_RelativeSize(K21,J$28)} -> #REF! | L34: {=MMS_PastureBeef_Soil_N2ODirect_Equations.VEERG_4_2_1_3__7_RelativeSize(L21,K$28)} -> #REF! | ... N34: {=MMS_PastureBeef_Soil_N2ODirect_Equations.VEERG_4_2_1_3__7_RelativeSize(N21,M$28)} -> #REF! | O34: =$E$11 -> ratio | T34: Relative size (Method 2)
D35: ='Input - Swine'!D140 -> 0 | E35: {=MMS_PastureBeef_Soil_N2ODirect_Equations.VEERG_4_2_1_3__7_RelativeSize(E22,D$28)} -> #REF! | F35: {=MMS_PastureBeef_Soil_N2ODirect_Equations.VEERG_4_2_1_3__7_RelativeSize(F22,E$28)} -> #REF! | G35: {=MMS_PastureBeef_Soil_N2ODirect_Equations.VEERG_4_2_1_3__7_RelativeSize(G22,F$28)} -> #REF! | H35: {=MMS_PastureBeef_Soil_N2ODirect_Equations.VEERG_4_2_1_3__7_RelativeSize(H22,G$28)} -> #REF! | I35: {=MMS_PastureBeef_Soil_N2ODirect_Equations.VEERG_4_2_1_3__7_RelativeSize(I22,H$28)} -> #REF! | J35: {=MMS_PastureBeef_Soil_N2ODirect_Equations.VEERG_4_2_1_3__7_RelativeSize(J22,I$28)} -> #REF! | K35: {=MMS_PastureBeef_Soil_N2ODirect_Equations.VEERG_4_2_1_3__7_RelativeSize(K22,J$28)} -> #REF! | L35: {=MMS_PastureBeef_Soil_N2ODirect_Equations.VEERG_4_2_1_3__7_RelativeSize(L22,K$28)} -> #REF! | ... N35: {=MMS_PastureBeef_Soil_N2ODirect_Equations.VEERG_4_2_1_3__7_RelativeSize(N22,M$28)} -> #REF! | O35: =$E$11 -> ratio | T35: Month | U35: Bulls < 1 year | V35: Bulls > 1 year | W35: Cows < 1 year | X35: Cows 1-2 years | Y35: Cows 2-3 years | Z35: Cows > 3 years | AA35: Steers < 1 year | AB35: Steers 1-2 years | AC35: Steers 2-3 years | AD35: Steers >3 years
D36: ='Input - Swine'!D141 -> 0 | E36: {=MMS_PastureBeef_Soil_N2ODirect_Equations.VEERG_4_2_1_3__7_RelativeSize(E23,D$28)} -> #REF! | F36: {=MMS_PastureBeef_Soil_N2ODirect_Equations.VEERG_4_2_1_3__7_RelativeSize(F23,E$28)} -> #REF! | G36: {=MMS_PastureBeef_Soil_N2ODirect_Equations.VEERG_4_2_1_3__7_RelativeSize(G23,F$28)} -> #REF! | H36: {=MMS_PastureBeef_Soil_N2ODirect_Equations.VEERG_4_2_1_3__7_RelativeSize(H23,G$28)} -> #REF! | I36: {=MMS_PastureBeef_Soil_N2ODirect_Equations.VEERG_4_2_1_3__7_RelativeSize(I23,H$28)} -> #REF! | J36: {=MMS_PastureBeef_Soil_N2ODirect_Equations.VEERG_4_2_1_3__7_RelativeSize(J23,I$28)} -> #REF! | K36: {=MMS_PastureBeef_Soil_N2ODirect_Equations.VEERG_4_2_1_3__7_RelativeSize(K23,J$28)} -> #REF! | L36: {=MMS_PastureBeef_Soil_N2ODirect_Equations.VEERG_4_2_1_3__7_RelativeSize(L23,K$28)} -> #REF! | ... N36: {=MMS_PastureBeef_Soil_N2ODirect_Equations.VEERG_4_2_1_3__7_RelativeSize(N23,M$28)} -> #REF! | O36: =$E$11 -> ratio | T36: =TEXT('Input - Site'!$E$12, "mmmm yyyy") -> January 2024 | U36: {=MMS_PastureBeef_Soil_N2ODirect_Equations.VEERG_4_2_1_3__7_RelativeSize(U20,D$28)} -> #REF! | V36: {=MMS_PastureBeef_Soil_N2ODirect_Equations.VEERG_4_2_1_3__7_RelativeSize(V20,E$28)} -> #REF! | W36: {=MMS_PastureBeef_Soil_N2ODirect_Equations.VEERG_4_2_1_3__7_RelativeSize(W20,F$28)} -> #REF! | X36: {=MMS_PastureBeef_Soil_N2ODirect_Equations.VEERG_4_2_1_3__7_RelativeSize(X20,G$28)} -> #REF! | Y36: {=MMS_PastureBeef_Soil_N2ODirect_Equations.VEERG_4_2_1_3__7_RelativeSize(Y20,H$28)} -> #REF! | Z36: {=MMS_PastureBeef_Soil_N2ODirect_Equations.VEERG_4_2_1_3__7_RelativeSize(Z20,I$28)} -> #REF! | AA36: {=MMS_PastureBeef_Soil_N2ODirect_Equations.VEERG_4_2_1_3__7_RelativeSize(AA20,J$28)} -> #REF! | AB36: {=MMS_PastureBeef_Soil_N2ODirect_Equations.VEERG_4_2_1_3__7_RelativeSize(AB20,K$28)} -> #REF! | ... AD36: {=MMS_PastureBeef_Soil_N2ODirect_Equations.VEERG_4_2_1_3__7_RelativeSize(AD20,M$28)} -> #REF! | AE36: =$E$11 -> ratio
T37: =TEXT(EDATE('Input - Site'!$E$12,1), "mmmm yyyy") -> February 2024 | U37: {=MMS_PastureBeef_Soil_N2ODirect_Equations.VEERG_4_2_1_3__7_RelativeSize(U21,D$28)} -> #REF! | V37: {=MMS_PastureBeef_Soil_N2ODirect_Equations.VEERG_4_2_1_3__7_RelativeSize(V21,E$28)} -> #REF! | W37: {=MMS_PastureBeef_Soil_N2ODirect_Equations.VEERG_4_2_1_3__7_RelativeSize(W21,F$28)} -> #REF! | X37: {=MMS_PastureBeef_Soil_N2ODirect_Equations.VEERG_4_2_1_3__7_RelativeSize(X21,G$28)} -> #REF! | Y37: {=MMS_PastureBeef_Soil_N2ODirect_Equations.VEERG_4_2_1_3__7_RelativeSize(Y21,H$28)} -> #REF! | Z37: {=MMS_PastureBeef_Soil_N2ODirect_Equations.VEERG_4_2_1_3__7_RelativeSize(Z21,I$28)} -> #REF! | AA37: {=MMS_PastureBeef_Soil_N2ODirect_Equations.VEERG_4_2_1_3__7_RelativeSize(AA21,J$28)} -> #REF! | AB37: {=MMS_PastureBeef_Soil_N2ODirect_Equations.VEERG_4_2_1_3__7_RelativeSize(AB21,K$28)} -> #REF! | ... AD37: {=MMS_PastureBeef_Soil_N2ODirect_Equations.VEERG_4_2_1_3__7_RelativeSize(AD21,M$28)} -> #REF! | AE37: =$E$11 -> ratio
T38: =TEXT(EDATE('Input - Site'!$E$12,2), "mmmm yyyy") -> March 2024 | U38: {=MMS_PastureBeef_Soil_N2ODirect_Equations.VEERG_4_2_1_3__7_RelativeSize(U22,D$28)} -> #REF! | V38: {=MMS_PastureBeef_Soil_N2ODirect_Equations.VEERG_4_2_1_3__7_RelativeSize(V22,E$28)} -> #REF! | W38: {=MMS_PastureBeef_Soil_N2ODirect_Equations.VEERG_4_2_1_3__7_RelativeSize(W22,F$28)} -> #REF! | X38: {=MMS_PastureBeef_Soil_N2ODirect_Equations.VEERG_4_2_1_3__7_RelativeSize(X22,G$28)} -> #REF! | Y38: {=MMS_PastureBeef_Soil_N2ODirect_Equations.VEERG_4_2_1_3__7_RelativeSize(Y22,H$28)} -> #REF! | Z38: {=MMS_PastureBeef_Soil_N2ODirect_Equations.VEERG_4_2_1_3__7_RelativeSize(Z22,I$28)} -> #REF! | AA38: {=MMS_PastureBeef_Soil_N2ODirect_Equations.VEERG_4_2_1_3__7_RelativeSize(AA22,J$28)} -> #REF! | AB38: {=MMS_PastureBeef_Soil_N2ODirect_Equations.VEERG_4_2_1_3__7_RelativeSize(AB22,K$28)} -> #REF! | ... AD38: {=MMS_PastureBeef_Soil_N2ODirect_Equations.VEERG_4_2_1_3__7_RelativeSize(AD22,M$28)} -> #REF! | AE38: =$E$11 -> ratio
T39: =TEXT(EDATE('Input - Site'!$E$12,3), "mmmm yyyy") -> April 2024 | U39: {=MMS_PastureBeef_Soil_N2ODirect_Equations.VEERG_4_2_1_3__7_RelativeSize(U23,D$28)} -> #REF! | V39: {=MMS_PastureBeef_Soil_N2ODirect_Equations.VEERG_4_2_1_3__7_RelativeSize(V23,E$28)} -> #REF! | W39: {=MMS_PastureBeef_Soil_N2ODirect_Equations.VEERG_4_2_1_3__7_RelativeSize(W23,F$28)} -> #REF! | X39: {=MMS_PastureBeef_Soil_N2ODirect_Equations.VEERG_4_2_1_3__7_RelativeSize(X23,G$28)} -> #REF! | Y39: {=MMS_PastureBeef_Soil_N2ODirect_Equations.VEERG_4_2_1_3__7_RelativeSize(Y23,H$28)} -> #REF! | Z39: {=MMS_PastureBeef_Soil_N2ODirect_Equations.VEERG_4_2_1_3__7_RelativeSize(Z23,I$28)} -> #REF! | AA39: {=MMS_PastureBeef_Soil_N2ODirect_Equations.VEERG_4_2_1_3__7_RelativeSize(AA23,J$28)} -> #REF! | AB39: {=MMS_PastureBeef_Soil_N2ODirect_Equations.VEERG_4_2_1_3__7_RelativeSize(AB23,K$28)} -> #REF! | ... AD39: {=MMS_PastureBeef_Soil_N2ODirect_Equations.VEERG_4_2_1_3__7_RelativeSize(AD23,M$28)} -> #REF! | AE39: =$E$11 -> ratio
D40: {=MMS_PastureBeef_Soil_N2ODirect_Equations.VEERG_4_2_1_3__6_IntakeRelativeToMaintenance_Title()} -> Intake relative to that needed for maintenance | T40: =TEXT(EDATE('Input - Site'!$E$12,4), "mmmm yyyy") -> May 2024 | U40: {=MMS_PastureBeef_Soil_N2ODirect_Equations.VEERG_4_2_1_3__7_RelativeSize(U24,D$28)} -> #REF! | V40: {=MMS_PastureBeef_Soil_N2ODirect_Equations.VEERG_4_2_1_3__7_RelativeSize(V24,E$28)} -> #REF! | W40: {=MMS_PastureBeef_Soil_N2ODirect_Equations.VEERG_4_2_1_3__7_RelativeSize(W24,F$28)} -> #REF! | X40: {=MMS_PastureBeef_Soil_N2ODirect_Equations.VEERG_4_2_1_3__7_RelativeSize(X24,G$28)} -> #REF! | Y40: {=MMS_PastureBeef_Soil_N2ODirect_Equations.VEERG_4_2_1_3__7_RelativeSize(Y24,H$28)} -> #REF! | Z40: {=MMS_PastureBeef_Soil_N2ODirect_Equations.VEERG_4_2_1_3__7_RelativeSize(Z24,I$28)} -> #REF! | AA40: {=MMS_PastureBeef_Soil_N2ODirect_Equations.VEERG_4_2_1_3__7_RelativeSize(AA24,J$28)} -> #REF! | AB40: {=MMS_PastureBeef_Soil_N2ODirect_Equations.VEERG_4_2_1_3__7_RelativeSize(AB24,K$28)} -> #REF! | ... AD40: {=MMS_PastureBeef_Soil_N2ODirect_Equations.VEERG_4_2_1_3__7_RelativeSize(AD24,M$28)} -> #REF! | AE40: =$E$11 -> ratio
D41: {=MMS_PastureBeef_Soil_N2ODirect_Equations.VEERG_4_2_1_3__6_IntakeRelativeToMaintenance_Source()} -> VEERG 2026: 4.2.1.3, Equation (6) | T41: =TEXT(EDATE('Input - Site'!$E$12,5), "mmmm yyyy") -> June 2024 | U41: {=MMS_PastureBeef_Soil_N2ODirect_Equations.VEERG_4_2_1_3__7_RelativeSize(U25,D$28)} -> #REF! | V41: {=MMS_PastureBeef_Soil_N2ODirect_Equations.VEERG_4_2_1_3__7_RelativeSize(V25,E$28)} -> #REF! | W41: {=MMS_PastureBeef_Soil_N2ODirect_Equations.VEERG_4_2_1_3__7_RelativeSize(W25,F$28)} -> #REF! | X41: {=MMS_PastureBeef_Soil_N2ODirect_Equations.VEERG_4_2_1_3__7_RelativeSize(X25,G$28)} -> #REF! | Y41: {=MMS_PastureBeef_Soil_N2ODirect_Equations.VEERG_4_2_1_3__7_RelativeSize(Y25,H$28)} -> #REF! | Z41: {=MMS_PastureBeef_Soil_N2ODirect_Equations.VEERG_4_2_1_3__7_RelativeSize(Z25,I$28)} -> #REF! | AA41: {=MMS_PastureBeef_Soil_N2ODirect_Equations.VEERG_4_2_1_3__7_RelativeSize(AA25,J$28)} -> #REF! | AB41: {=MMS_PastureBeef_Soil_N2ODirect_Equations.VEERG_4_2_1_3__7_RelativeSize(AB25,K$28)} -> #REF! | ... AD41: {=MMS_PastureBeef_Soil_N2ODirect_Equations.VEERG_4_2_1_3__7_RelativeSize(AD25,M$28)} -> #REF! | AE41: =$E$11 -> ratio
D42: Function name | E42: {=Common_InputFunctions.Utility_DisplayFunctionName(E62)} -> =MMS_PastureBeef_Soil_N2ODirect_Equations.VEERG_4_2_1_3__6_IntakeRelativeToMaintenance | T42: =TEXT(EDATE('Input - Site'!$E$12,6), "mmmm yyyy") -> July 2024 | U42: {=MMS_PastureBeef_Soil_N2ODirect_Equations.VEERG_4_2_1_3__7_RelativeSize(U26,D$28)} -> #REF! | V42: {=MMS_PastureBeef_Soil_N2ODirect_Equations.VEERG_4_2_1_3__7_RelativeSize(V26,E$28)} -> #REF! | W42: {=MMS_PastureBeef_Soil_N2ODirect_Equations.VEERG_4_2_1_3__7_RelativeSize(W26,F$28)} -> #REF! | X42: {=MMS_PastureBeef_Soil_N2ODirect_Equations.VEERG_4_2_1_3__7_RelativeSize(X26,G$28)} -> #REF! | Y42: {=MMS_PastureBeef_Soil_N2ODirect_Equations.VEERG_4_2_1_3__7_RelativeSize(Y26,H$28)} -> #REF! | Z42: {=MMS_PastureBeef_Soil_N2ODirect_Equations.VEERG_4_2_1_3__7_RelativeSize(Z26,I$28)} -> #REF! | AA42: {=MMS_PastureBeef_Soil_N2ODirect_Equations.VEERG_4_2_1_3__7_RelativeSize(AA26,J$28)} -> #REF! | AB42: {=MMS_PastureBeef_Soil_N2ODirect_Equations.VEERG_4_2_1_3__7_RelativeSize(AB26,K$28)} -> #REF! | ... AD42: {=MMS_PastureBeef_Soil_N2ODirect_Equations.VEERG_4_2_1_3__7_RelativeSize(AD26,M$28)} -> #REF! | AE42: =$E$11 -> ratio
...

Sheet 4.2.1.5-6 Soil Atmos Dep
A1: #VALUE! | C1: 4.2.1.5-6 Soil atmospheric deposition N2O
A3: =HYPERLINK("#'Home'!A1", "Home") -> Home | D3: Method 1 | L3: Method 2
A4: =HYPERLINK("#'Results'!A1", "Results") -> Results
D5: {=MMS_PastureBeef_Soil_AtmosphericDeposition_Equations.VEERG_4_2_1_5__2_MassOfNitrogenVolatilisedOnPasture_Title()} -> Mass of nitrogen volatilised
A6: INPUTS | D6: {=MMS_PastureBeef_Soil_AtmosphericDeposition_Equations.VEERG_4_2_1_5__2_MassOfNitrogenVolatilisedOnPasture_Source()} -> VEERG 2026: 4.2.1.5, Equation (2)
A7: =HYPERLINK("#'Input - Site'!A1", "Site") -> Site | D7: Function name | E7: {=Common_InputFunctions.Utility_DisplayFunctionName(E16)} -> =MMS_PastureBeef_Soil_AtmosphericDeposition_Equations.VEERG_4_2_1_5__2_MassOfNitrogenVolatilisedOnPasture
A8: =HYPERLINK("#'Input - Swine'!A1", "Swine") -> Swine
A10: CALCULATIONS | D10: Variable | E10: {=MMS_PastureBeef_Soil_AtmosphericDeposition_Equations.VEERG_4_2_1_5__2_MassOfNitrogenVolatilisedOnPasture_Variable()} -> M_vol
A11: =HYPERLINK("#'4.2.1.1-2 Methane'!A1", "4.2.1.1-2 Methane") -> 4.2.1.1-2 Methane | D11: Unit | E11: {=MMS_PastureBeef_Soil_AtmosphericDeposition_Equations.VEERG_4_2_1_5__2_MassOfNitrogenVolatilisedOnPasture_Unit()} -> kg N
A12: =HYPERLINK("#'4.2.1.3-4 Soil direct N2O'!A1", "4.2.1.3-4 Soil direct N2O") -> 4.2.1.3-4 Soil direct N2O
A13: =HYPERLINK("#'4.2.1.5-6 Soil Atmos Dep'!A1", "4.2.1.5-6 Soil atm. deposition") -> 4.2.1.5-6 Soil atm. deposition | D13: {=MMS_PastureBeef_Soil_AtmosphericDeposition_Equations.VEERG_4_2_1_5__2_MassOfNitrogenVolatilisedOnPasture_Arguments()} -> AE | E13: total mass of nitrogen excreted on PRP for beef cattle (kg N) | H13: ='4.2.1.3-4 Soil direct N20'!$E$210 -> #REF! | L13: {=MMS_PastureBeef_Soil_AtmosphericDeposition_Equations.VEERG_4_2_1_5__2_MassOfNitrogenVolatilisedOnPasture_Arguments()} -> AE | M13: total mass of nitrogen excreted on PRP for beef cattle (kg N) | P13: ='4.2.1.3-4 Soil direct N20'!$U$253 -> #REF!
A14: =HYPERLINK("#'4.2.1.7-8 Soil leach runoff'!A1", "4.2.1.7-8 Soil leach & runoff") -> 4.2.1.7-8 Soil leach & runoff | D14: FracGASMsoil | E14: fraction of nitrogen volatilised from urine and faeces deposited on pasture ((kg NH3-N + NOx-N)/kg N) | H14: ='Constants - Swine'!$D$432 -> 0 | L14: FracGASMsoil | M14: fraction of nitrogen volatilised from urine and faeces deposited on pasture ((kg NH3-N + NOx-N)/kg N)
A16: APPENDICES | D16: Mvol | E16: {=MMS_PastureBeef_Soil_AtmosphericDeposition_Equations.VEERG_4_2_1_5__2_MassOfNitrogenVolatilisedOnPasture(H13,H14)} -> #REF! | F16: =E11 -> kg N | L16: Mvol | M16: {=MMS_PastureBeef_Soil_AtmosphericDeposition_Equations.VEERG_4_2_1_5__2_MassOfNitrogenVolatilisedOnPasture(P13,$H$14)} -> #REF! | N16: =M11 -> 0
A17: =HYPERLINK("#'Constants - Swine'!A1", "Constants - Swine") -> Constants - Swine
A18: =HYPERLINK("#'Constants - Livestock'!A1", "Constants - Livestock") -> Constants - Livestock
A19: =HYPERLINK("#'Constants - Common'!A1", "Constants - Common") -> Constants - Common
A20: =HYPERLINK("#'Acknowledgements'!A1", "Acknowledgements") -> Acknowledgements | D20: {=MMS_PastureBeef_Soil_AtmosphericDeposition_Equations.VEERG_4_2_1_5__1_AtmosphericDepositionEmissionsFromUrineAndDungOnPasture_Title()} -> Atmospheric deposition emissions from urine and dung deposited on pasture
D21: {=MMS_PastureBeef_Soil_AtmosphericDeposition_Equations.VEERG_4_2_1_5__1_AtmosphericDepositionEmissionsFromUrineAndDungOnPasture_Source()} -> VEERG 2026: 4.2.1.5, Equation (1)
