Workbook
Name Common_Equations.Common_ConvertCH4ToCO2e: _xlfn.LAMBDA(_xlpm.E_CH4,_xlpm.GWP_CH4, _xlpm.E_CH4 * _xlpm.GWP_CH4)
Name Common_Equations.Common_ConvertCH4ToCO2e_Arguments: _xlfn.LAMBDA(_xlfn.MAKEARRAY(2, 2, _xlfn.LAMBDA(_xlpm.r,_xlpm.c, INDEX({"ECH4","Methane emissions (t CH4)";"GWPCH4","Global warming potential for methane (t CO2-e / t CH4)"}, _xlpm.r, _xlpm.c))))
Name Common_Equations.Common_ConvertCH4ToCO2e_LatexEquation: _xlfn.LAMBDA("CO2_e = E_{CH4} \times GWP_{CH4}")
Name Common_Equations.Common_ConvertCH4ToCO2e_NIRReference: _xlfn.LAMBDA("")
Name Common_Equations.Common_ConvertCH4ToCO2e_Title: _xlfn.LAMBDA("Convert methane emissions to carbon dioxide equivalent emissions")
Name Common_Equations.Common_ConvertCH4ToCO2e_Unit: _xlfn.LAMBDA("t CO2e")
Name Common_Equations.Common_ConvertCH4ToCO2e_Variable: _xlfn.LAMBDA("ECH4 CO2e")
Name Common_Equations.Common_ConvertN2OToCO2e: _xlfn.LAMBDA(_xlpm.E_N2O,_xlpm.GWP_N2O, _xlpm.E_N2O * _xlpm.GWP_N2O)
Name Common_Equations.Common_ConvertN2OToCO2e_LatexEquation: _xlfn.LAMBDA("CO2_e = E_{N2O} \times GWP_{N2O}")
Name Common_Equations.Common_ConvertN2OToCO2e_NIRReference: _xlfn.LAMBDA("")
Name Common_Equations.Common_ConvertN2OToCO2e_Title: _xlfn.LAMBDA("Convert nitrous oxide emissions to carbon dioxide equivalent emissions")
Name Common_Equations.Common_ConvertN2OToCO2e_Unit: _xlfn.LAMBDA("t CO2e")
Name Common_Equations.Common_ConvertN2OToCO2e_Variable: _xlfn.LAMBDA("EN2O CO2e")
Name Common_InputFunctions.Utility_ConvertStateCommonNameToAbbreviation: _xlfn.LAMBDA(_xlpm.StateCommonName,_xlpm.StateCommonNameArray,_xlpm.StateAbbreviationArray, _xlfn.XLOOKUP(_xlpm.StateCommonName, _xlpm.StateCommonNameArray, _xlpm.StateAbbreviationArray, ""))
Name Common_InputFunctions.Utility_DisplayFunctionName: _xlfn.LAMBDA(_xlpm.Function, _xlfn.TEXTBEFORE(_xlfn.FORMULATEXT(_xlpm.Function), "("))
Name Common_InputFunctions.Utility_GetArrayTableColumnStartNumber: _xlfn.LAMBDA(_xlpm.TableHeaderCell, COLUMN(_xlpm.TableHeaderCell))
Name Common_InputFunctions.Utility_GetArrayTableRowStartNumber: _xlfn.LAMBDA(_xlpm.TableheaderCell,_xlpm.RowsBetweenHeaderandArray, ROW(_xlpm.TableheaderCell) + _xlpm.RowsBetweenHeaderandArray - 1)
Name Common_InputFunctions.Utility_LookupValueInTable: _xlfn.LAMBDA(_xlpm.LookupValue,_xlpm.LookupArray,_xlpm.ReturnArray, _xlfn.XLOOKUP(_xlpm.LookupValue, _xlpm.LookupArray, _xlpm.ReturnArray, ""))
Name Common_SourceData.Common_SourceData_AustralianStatesTerritories_Source: _xlfn.LAMBDA("")
Name Common_SourceData.Common_SourceData_AustralianStatesTerritories_Title: _xlfn.LAMBDA("Australian states and territories")
Name Common_SourceData.Common_SourceData_AustralianStatesTerritories_Unit: _xlfn.LAMBDA("")
Name Common_SourceData.Common_SourceData_AustralianStatesTerritories_Variable: _xlfn.LAMBDA("")
Name Common_SourceData.Common_SourceData_ClimateZones_Source: _xlfn.LAMBDA("VEERG 2026: Table 1.3: Climate and Rainfall zone classifications and definitions")
Name Common_SourceData.Common_SourceData_ClimateZones_Title: _xlfn.LAMBDA("VEERG Australian climate zones")
Name Common_SourceData.Common_SourceData_ClimateZones_Unit: _xlfn.LAMBDA("")
Name Common_SourceData.Common_SourceData_ClimateZones_Variable: _xlfn.LAMBDA("")
Name Common_SourceData.Common_SourceData_ConvertGasElementalToMolecular_Source: _xlfn.LAMBDA("XXXXXXX")
Name Common_SourceData.Common_SourceData_ConvertGasElementalToMolecular_Title: _xlfn.LAMBDA("Factor to convert elemental mass of gas to molecular mass")
Name Common_SourceData.Common_SourceData_ConvertGasElementalToMolecular_Unit: _xlfn.LAMBDA("factor")
Name Common_SourceData.Common_SourceData_ConvertGasElementalToMolecular_Variable: _xlfn.LAMBDA("Cg")
Name Common_SourceData.Common_SourceData_ConvertN2oElementalToMolecularCg_Data: _xlfn.LAMBDA(44 / 28)
Name Common_SourceData.Common_SourceData_ConvertN2oElementalToMolecularCg_Source: _xlfn.LAMBDA("National Inventory Report 2023 Volume 1")
Name Common_SourceData.Common_SourceData_ConvertN2oElementalToMolecularCg_Title: _xlfn.LAMBDA("Factor to convert elemental mass of N2O to molecular mass")
Name Common_SourceData.Common_SourceData_ConvertN2oElementalToMolecularCg_Unit: _xlfn.LAMBDA("factor")
Name Common_SourceData.Common_SourceData_ConvertN2oElementalToMolecularCg_Variable: _xlfn.LAMBDA("CgN2O")
Name Common_SourceData.Common_SourceData_DataScores_Scope3_Source: _xlfn.LAMBDA("VEERG 2026: XXXXXXXX")
Name Common_SourceData.Common_SourceData_DataScores_Scope3_Title: _xlfn.LAMBDA("Australian data scores for scope 3")
Name Common_SourceData.Common_SourceData_DataScores_Scope3_Unit: _xlfn.LAMBDA("")
Name Common_SourceData.Common_SourceData_DataScores_Scope3_Variable: _xlfn.LAMBDA("")
Name Common_SourceData.Common_SourceData_DataScores_Scope3_Variation: _xlfn.LAMBDA("")
Name Common_SourceData.Common_SourceData_DensityOfMethane_Data: _xlfn.LAMBDA(0.6784)
Name Common_SourceData.Common_SourceData_DensityOfMethane_Source: _xlfn.LAMBDA("National Inventory Report 2023 Volume 1: Equations 3.B.1a_2, 3.B.1c_2, 3.B.3_1, 3.B.4g_2")
Name Common_SourceData.Common_SourceData_DensityOfMethane_Title: _xlfn.LAMBDA("p = density of methane")
Name Common_SourceData.Common_SourceData_DensityOfMethane_Unit: _xlfn.LAMBDA("kg/m3")
Name Common_SourceData.Common_SourceData_EFleach_Data: _xlfn.LAMBDA(_xlfn.MAKEARRAY(1, 2, _xlfn.LAMBDA(_xlpm.r,_xlpm.c, INDEX({"EFleach",0.011}, _xlpm.r, _xlpm.c))))
Name Common_SourceData.Common_SourceData_EFleach_NIRReference: _xlfn.LAMBDA("National Inventory Report Volume 1: Equation 3.D.B_10")
Name Common_SourceData.Common_SourceData_EFleach_Source: _xlfn.LAMBDA("VEERG 2026:5.5.2.3 Constant Parameters")
Name Common_SourceData.Common_SourceData_EFleach_Title: _xlfn.LAMBDA("Emission factor for nitrogen leaching and runoff")
Name Common_SourceData.Common_SourceData_EFleach_Unit: _xlfn.LAMBDA("(kg N2O-N / kg N")
Name Common_SourceData.Common_SourceData_EFleach_Variation: _xlfn.LAMBDA((""))
Name Common_SourceData.Common_SourceData_EFN2O_NIRReference: _xlfn.LAMBDA("")
Name Common_SourceData.Common_SourceData_EFN2O_Source: _xlfn.LAMBDA("VEERG 2026: Table A.2.2.1")
Name Common_SourceData.Common_SourceData_EFN2O_Title: _xlfn.LAMBDA("Nitrous oxide emission factors for inorganic fertiliser application")
Name Common_SourceData.Common_SourceData_EFN2O_Unit: _xlfn.LAMBDA("(kg N2O-N / kg N")
Name Common_SourceData.Common_SourceData_EFPastureRangeAndPaddock_Data: _xlfn.LAMBDA(_xlfn.MAKEARRAY(3, 2, _xlfn.LAMBDA(_xlpm.r,_xlpm.c, INDEX({"Climate zone","EFPRP";"Wet climate zone",0.006;"Dry climate zone",0.002}, _xlpm.r, _xlpm.c))))
Name Common_SourceData.Common_SourceData_EFPastureRangeAndPaddock_NIRReference: _xlfn.LAMBDA("")
Name Common_SourceData.Common_SourceData_EFPastureRangeAndPaddock_Source: _xlfn.LAMBDA("VEERG 2026: Table A.2.2.2")
Name Common_SourceData.Common_SourceData_EFPastureRangeAndPaddock_Title: _xlfn.LAMBDA("Emission factor for urine and dung deposited on pasture, range or paddock")
Name Common_SourceData.Common_SourceData_EFPastureRangeAndPaddock_Unit: _xlfn.LAMBDA("kg N2O - N / kg N")
Name Common_SourceData.Common_SourceData_EFPastureRangeAndPaddock_Variation: _xlfn.LAMBDA("VARIATION FROM SOURCE DATA: Changed 'Dry climate zones' to singular 'Dry climate zone' to aid lookup.")

Sheet Home
A1: Home

Sheet Results
A1: #VALUE! | C1: 4.6 Manure management: Poultry: Results
A3: =HYPERLINK("#'Home'!A1", "Home") -> Home
A4: =HYPERLINK("#'Results'!A1", "Results") -> Results | D4: Emissions breakdown
A6: INPUTS | D6: Scope 1 source | E6: GHG emissions method 1 | F6: GHG emissions method 2 | G6: GHG Unit | H6: CO2-e emissions method 1 | I6: CO2-e emissions method 2 | J6: CO2-e unit
A7: =HYPERLINK("#'Input - Site'!A1", "Site") -> Site | D7: 4.5.1.1-2 Manure methane | E7: ='4.6.1.1-2 Methane'!E280 -> 0 | F7: ='4.6.1.1-2 Methane'!O280 -> 0 | G7: t CH4 | H7: ='4.6.1.1-2 Methane'!E285 -> 0 | I7: ='4.6.1.1-2 Methane'!O285 -> 0 | J7: t CO2e
A8: =HYPERLINK("#'Input - Swine'!A1", "Swine") -> Swine | D8: 4.5.1.3-4 Direct N2O | E8: ='4.6.1.3-4 Direct N20'!E274 -> 0 | F8: ='4.6.1.3-4 Direct N20'!O274 -> 0 | G8: t N2O | H8: ='4.6.1.3-4 Direct N20'!E279 -> 0 | I8: ='4.6.1.3-4 Direct N20'!O279 -> 0 | J8: t CO2e
D9: 4.5.1.5-6 Atmospheric deposition | E9: ='4.5.1.5-6 Atmos Dep'!E109 -> #REF! | F9: ='4.5.1.5-6 Atmos Dep'!O109 -> #REF! | G9: t N2O | H9: ='4.5.1.5-6 Atmos Dep'!E114 -> #REF! | I9: ='4.5.1.5-6 Atmos Dep'!O114 -> #REF! | J9: t CO2e
A10: CALCULATIONS | D10: 4.2.1.7-8 Leaching and runoff | E10: ='4.5.1.7-8 Leaching and runoff'!$E$36 -> 0 | F10: ='4.5.1.7-8 Leaching and runoff'!$N$36 -> 0 | G10: t N2O | H10: ='4.5.1.7-8 Leaching and runoff'!E54 -> 0 | I10: ='4.5.1.7-8 Leaching and runoff'!N54 -> 0 | J10: t CO2e
A11: =HYPERLINK("#'4.5.1.1-2 Methane'!A1", "4.5.1.1-2 Methane") -> 4.5.1.1-2 Methane | D11: Total | H11: =SUM(H7:H10) -> #REF! | I11: =SUM(I7:I10) -> #REF! | J11: t CO2e
A12: =HYPERLINK("#'4.5.1.3-4 Direct N20'!A1", "4.5.1.3-4 Direct N2O") -> 4.5.1.3-4 Direct N2O
A13: =HYPERLINK("#'4.5.1.5-6 Atmos Dep'!A1", "4.5.1.5-6 Soil atm. deposition") -> 4.5.1.5-6 Soil atm. deposition | D13: WARNING: Manure nitrogen that was applied to soils must be accounted for
A14: =HYPERLINK("#'4.5.1.7-8 Leaching and runoff'!A1", "4.5.1.7-8 Leaching & runoff") -> 4.5.1.7-8 Leaching & runoff | D14: See the table below for how to account for manure applied to soils for scope 1 and 3.
A15: =HYPERLINK("#'4.5.1.9 Manure applied to soils'!A1", "4.5.1.9 Manure applied to soils") -> 4.5.1.9 Manure applied to soils
D16: Manure nitrogen use | E16: Amount of N in manure | F16: N unit | G16: Emissions allocated to | H16: VEERG Calculation method
A17: APPENDICES | D17: Manure nitrogen deposited on farm soils (including use as fertiliser for other enterprises on own farm eg crops) | E17: ='4.5.1.9 Manure applied to soils'!E136 -> #N/A | F17: ='4.5.1.9 Manure applied to soils'!F136 -> kg N | G17: Scope 1 - This piggery | H17: 5.2.2.1 (1), 5.4.1.3 (1, 2), 5.5.1.1 (1, 3)
A18: =HYPERLINK("#'Constants - Swine'!A1", "Constants - Swine") -> Constants - Swine | D18: Manure nitrogen deposited on farm soils as fertiliser for other farm enterpsies (eg crops) | E18: ='4.5.1.9 Manure applied to soils'!E235 -> #N/A | F18: ='4.5.1.9 Manure applied to soils'!F235 -> kg N | G18: Scope 1 - This piggery | H18: 5.2.2.1 (1), 5.4.1.3 (1, 2), 5.5.1.1 (1, 3)
A19: =HYPERLINK("#'Constants - Livestock'!A1", "Constants - Livestock") -> Constants - Livestock | D19: Manure nitrogen sold | E19: ='4.5.1.9 Manure applied to soils'!E178 -> #N/A | F19: ='4.5.1.9 Manure applied to soils'!F178 -> kg N | G19: Scope 3 (downstream) | H19: 15.13.1.1 (1), 5.2.2.1 (1), 5.4.1.3 (1, 2), 5.5.1.1 (1, 3)
A20: =HYPERLINK("#'Constants - Common'!A1", "Constants - Common") -> Constants - Common
A21: =HYPERLINK("#'Acknowledgements'!A1", "Acknowledgements") -> Acknowledgements

Sheet Input - Site
A1: #VALUE! | C1: Input - Site
A3: =HYPERLINK("#'Home'!A1", "Home") -> Home
A4: =HYPERLINK("#'Results'!A1", "Results") -> Results
D5: Your business
A6: INPUTS
A7: =HYPERLINK("#'Input - Site'!A1", "Site") -> Site | D7: Farm name | E7: Test Farms
A8: =HYPERLINK("#'Input - Swine'!A1", "Swine") -> Swine | D8: Reporting entity name | E8: Test Farms Pty Ltd
A10: CALCULATIONS | D10: 💡An 'Emissions accounting period' is a 12 month period where the business can report on the emissions, and is typically the same as the business' financial accounting period.
A11: =HYPERLINK("#'4.5.1.1-2 Methane'!A1", "4.5.1.1-2 Methane") -> 4.5.1.1-2 Methane
A12: =HYPERLINK("#'4.5.1.3-4 Direct N20'!A1", "4.5.1.3-4 Direct N2O") -> 4.5.1.3-4 Direct N2O | D12: Emissions calculation period start date | E12: 45292 | F12: ← DD/MM/YYYY or DD Month YYYY
A13: =HYPERLINK("#'4.5.1.5-6 Atmos Dep'!A1", "4.5.1.5-6 Soil atm. deposition") -> 4.5.1.5-6 Soil atm. deposition | D13: Emissions calculation period end date | E13: =DATE(YEAR(E12)+1,MONTH(E12),DAY(E12))-1 -> 45657 | F13: ← Automatically calculated, 12 months after start date
A14: =HYPERLINK("#'4.5.1.7-8 Leaching and runoff'!A1", "4.5.1.7-8 Leaching & runoff") -> 4.5.1.7-8 Leaching & runoff
A15: =HYPERLINK("#'4.5.1.9 Manure applied to soils'!A1", "4.5.1.9 Manure applied to soils") -> 4.5.1.9 Manure applied to soils
D16: Location and climate
A17: APPENDICES
A18: =HYPERLINK("#'Constants - Swine'!A1", "Constants - Swine") -> Constants - Swine | D18: Location information is used to reference some region and climate-specific emission factors
A19: =HYPERLINK("#'Constants - Livestock'!A1", "Constants - Livestock") -> Constants - Livestock | D19: Tip: Use the web-based GAF Location Helper tool to easily get region and climate information. You will need an internet connection to use the GAF Location Helper.
A20: =HYPERLINK("#'Constants - Common'!A1", "Constants - Common") -> Constants - Common
A21: =HYPERLINK("#'Acknowledgements'!A1", "Acknowledgements") -> Acknowledgements | D21: State | E21: Western Australia | F21: ← Please select
D22: Region (ABS Statistical area level 4) if state is WA | E22: Western Australia - Outback (South) | F22: ← Please select
D23: Leaching zone | E23: NO - Not in leaching zone | F23: ← Please select
D24: Elevation | E24: 307.7 | F24: Meters
D25: Average temperature for reporting period | E25: 18 | F25: Degrees celsius
D26: Total rainfall for reporting period | E26: 601 | F26: Millimetres
D27: Potential evapotranspiration for reporting period | E27: 1326 | F27: Millimetres
D28: Number of frost days for reporting period | E28: 7 | F28: Days
D29: MAP:PET ratio | E29: =E26/E27 -> 0.45324284
D30: Rainfall zone | E30: =Common_InputFunctions.Utility_LookupItemFromMinMax(E26,Table_SourceData_RainfallZones[Min rainfall],Table_SourceData_RainfallZones[Max rainfall],Table_SourceData_RainfallZones[Rainfall Zone]) -> High rainfall
D31: Climate zone | E31: =Common_InputFunctions.Utility_GetClimateZone(E25,E26,E28,E24,E29,Table_SourceData_ClimateZones[Min temp],Table_SourceData_ClimateZones[Max temp],Table_SourceData_ClimateZones[Min rainfall],Table_SourceData_ClimateZones[Max rainfall],Table_SourceData_ClimateZones[Min frost days],Table_SourceData_ClimateZones[Max frost days],Table_SourceData_ClimateZones[Min elevation],Table_SourceData_ClimateZones[Max elevation],Table_SourceData_ClimateZones[Min MAP:PET],Table_SourceData_ClimateZones[Max MAP:PET],Table_SourceData_ClimateZones[Climate zone]) -> Warm temperate dry
D32: Wet or dry climate zone | E32: =Common_InputFunctions.Utility_LookupValueInTable($E$31,Table_SourceData_WetDryZones[Climate zone],Table_SourceData_WetDryZones[Wet or Dry Zone]) -> Dry climate zone
D33: Temperature zone | E33: =Common_InputFunctions.Utility_LookupItemFromMinMax(E25,Table_SourceData_TemperatureZones[Min MAT],Table_SourceData_TemperatureZones[Max MAT],Table_SourceData_TemperatureZones[Temperature Zone]) -> Temperate

Sheet Input - Poultry
A1: #VALUE! | C1: Input -Poultry
A3: =HYPERLINK("#'Home'!A1", "Home") -> Home
A4: =HYPERLINK("#'Results'!A1", "Results") -> Results
D5: This tool demostrates inputs for one production system.
A6: INPUTS
A7: =HYPERLINK("#'Input - Site'!A1", "Site") -> Site
A8: =HYPERLINK("#'Input - Swine'!A1", "Swine") -> Swine
E9: Layers | F9: Meat chicken growers | G9: Meat chicken breeders | H9: Other
A10: CALCULATIONS | D10: ="Average duration of stay between " & TEXT('Input - Site'!$E$12, "dd mmm yy") & " and " & TEXT('Input - Site'!$E$13, "dd mmm yy") -> Average duration of stay between 01 Jan 24 and 31 Dec 24 | E10: 365 | F10: 365 | G10: 365 | H10: 365 | I10: Days
A11: =HYPERLINK("#'4.5.1.1-2 Methane'!A1", "4.5.1.1-2 Methane") -> 4.5.1.1-2 Methane | D11: ="Average number of birds between " & TEXT('Input - Site'!$E$12, "dd mmm yy") & " and " & TEXT('Input - Site'!$E$13, "dd mmm yy") -> Average number of birds between 01 Jan 24 and 31 Dec 24 | E11: 100 | F11: 100 | G11: 100 | H11: 100 | I11: Head
A12: =HYPERLINK("#'4.5.1.3-4 Direct N20'!A1", "4.5.1.3-4 Direct N2O") -> 4.5.1.3-4 Direct N2O
A13: =HYPERLINK("#'4.5.1.5-6 Atmos Dep'!A1", "4.5.1.5-6 Soil atm. deposition") -> 4.5.1.5-6 Soil atm. deposition | D13: Manure production
A14: =HYPERLINK("#'4.5.1.7-8 Leaching and runoff'!A1", "4.5.1.7-8 Leaching & runoff") -> 4.5.1.7-8 Leaching & runoff
A15: =HYPERLINK("#'4.5.1.9 Manure applied to soils'!A1", "4.5.1.9 Manure applied to soils") -> 4.5.1.9 Manure applied to soils | D15: Method 1 default values (Do not edit) | E15: Layers | F15: Meat chicken growers | G15: Meat chicken breeders | H15: Other
D16: Dry matter intake | E16: ='Constants - Poultry'!E9 -> 0.086 | F16: ='Constants - Poultry'!F9 -> 0.093 | G16: ='Constants - Poultry'!G9 -> 0.103 | H16: ='Constants - Poultry'!H9 -> 0.093 | I16: kg/DM/bird/day
A17: APPENDICES | D17: Dry matter digestibility (DMD) | E17: ='Constants - Poultry'!E10 -> 0.8 | F17: ='Constants - Poultry'!F10 -> 0.8 | G17: ='Constants - Poultry'!G10 -> 0.8 | H17: ='Constants - Poultry'!H10 -> 0.8 | I17: fraction
A18: =HYPERLINK("#'Constants - Swine'!A1", "Constants - Swine") -> Constants - Swine | D18: Crude protein (CP) | E18: ='Constants - Poultry'!E11 -> 0.19 | F18: ='Constants - Poultry'!F11 -> 0.23 | G18: ='Constants - Poultry'!G11 -> 0.19 | H18: ='Constants - Poultry'!H11 -> 0.23 | I18: fraction
A19: =HYPERLINK("#'Constants - Livestock'!A1", "Constants - Livestock") -> Constants - Livestock
A20: =HYPERLINK("#'Constants - Common'!A1", "Constants - Common") -> Constants - Common | D20: Method 2 custom values (Edit if known) | E20: Layers | F20: Meat chicken growers | G20: Meat chicken breeders | H20: Other
A21: =HYPERLINK("#'Acknowledgements'!A1", "Acknowledgements") -> Acknowledgements | D21: Dry matter intake | E21: ='Constants - Poultry'!E9 -> 0.086 | F21: ='Constants - Poultry'!F9 -> 0.093 | G21: ='Constants - Poultry'!G9 -> 0.103 | H21: ='Constants - Poultry'!H9 -> 0.093 | I21: kg/DM/bird/day
D22: Dry matter digestibility (DMD) | E22: ='Constants - Poultry'!E10 -> 0.8 | F22: ='Constants - Poultry'!F10 -> 0.8 | G22: ='Constants - Poultry'!G10 -> 0.8 | H22: ='Constants - Poultry'!H10 -> 0.8 | I22: fraction
D23: Crude protein (CP) | E23: ='Constants - Poultry'!E11 -> 0.19 | F23: ='Constants - Poultry'!F11 -> 0.23 | G23: ='Constants - Poultry'!G11 -> 0.19 | H23: ='Constants - Poultry'!H11 -> 0.23 | I23: fraction
D25: Manure management systems
D27: Production system | E27: Free range | F27: ← Please select
D29: Stage 1 MMS | E29: Layers | F29: Meat chicken growers | G29: Meat chicken breeders | H29: Other
D30: =Table_SourceData_PoultryMMSSTage1[[#This Row],[MMS]] -> Belt manure removal | E30: 0.3 | F30: 0.15 | G30: 0.15 | H30: 0.15 | I30: Percent
D31: =Table_SourceData_PoultryMMSSTage1[[#This Row],[MMS]] -> Manure stored in house | E31: 0.3 | F31: 0.15 | G31: 0.15 | H31: 0.15 | I31: Percent
D32: =Table_SourceData_PoultryMMSSTage1[[#This Row],[MMS]] -> Pasture range and paddock | E32: 0.3 | F32: 0.15 | G32: 0.15 | H32: 0.15 | I32: Percent
D33: =Table_SourceData_PoultryMMSSTage1[[#This Row],[MMS]] -> No MMS | E33: 0.1 | F33: 0.1 | G33: 0.1 | H33: 0.1 | I33: Percent
D34: Total sent to all MMS (Must equal 100%) | E34: =SUM(E30,E31,E32,E33) -> 1 | F34: =SUM(F30,F31,F32,F33) -> 0.55 | G34: =SUM(G30,G31,G32,G33) -> 0.55 | H34: =SUM(H30,H31,H32,H33) -> 0.55
D35: ▼
D36: Stage 2 MMS | E36: Layers | F36: Meat chicken growers | G36: Meat chicken breeders | H36: Other | I36: ► | J36: Destination after stage 2 MMS (Percent)
D37: ="Stage 2 MMS From " & $D$30 -> Stage 2 MMS From Belt manure removal | E37: =IF(SUM(E30:K30)>0,"Manure was sent to this MMS, please complete this section.","No manure was sent to this MMS. Leave this section blank.") -> Manure was sent to this MMS, please complete this section. | J37: Sold | K37: Fert for own farm (eg crop) | L37: Direct application to soil
D38: ='Constants - Poultry'!$J$29 -> Solid storage | E38: 0.2 | F38: 0.2 | G38: 0.2 | H38: 0.2 | I38: Percent | J38: 0.25 | K38: 0.25 | L38: =1-SUM(J38:K38) -> 0.5
D39: ='Constants - Poultry'!$J$30 -> Composting (passive windrow) | E39: 0.2 | F39: 0.2 | G39: 0.2 | H39: 0.2 | I39: Percent | J39: 0.25 | K39: 0.25 | L39: =1-SUM(J39:K39) -> 0.5
D40: ='Constants - Poultry'!$J$31 -> Digester / covered lagoons | E40: 0.2 | F40: 0.2 | G40: 0.2 | H40: 0.2 | I40: Percent | J40: 0.25 | K40: 0.25 | L40: =1-SUM(J40:K40) -> 0.5
D41: ='Constants - Poultry'!$J$32 -> Direct processing | E41: 0.2 | F41: 0.2 | G41: 0.2 | H41: 0.2 | I41: Percent | J41: 0.25 | K41: 0.25 | L41: =1-SUM(J41:K41) -> 0.5
D42: Direct application to soil | E42: =1-SUM(E38:E41) -> 0.2 | F42: =1-SUM(F38:F41) -> 0.2 | G42: =1-SUM(G38:G41) -> 0.2 | H42: =1-SUM(H38:H41) -> 0.2 | I42: Percent
D44: ="Stage 2 MMS From " & $D$31 -> Stage 2 MMS From Manure stored in house | E44: =IF(SUM(E31:K31)>0,"Manure was sent to this MMS, please complete this section.","No manure was sent to this MMS. Leave this section blank.") -> Manure was sent to this MMS, please complete this section. | J44: Sold | K44: Fert for own farm (eg crop) | L44: Direct application to soil
D45: ='Constants - Poultry'!$J$29 -> Solid storage | E45: 0.2 | F45: 0.2 | G45: 0.2 | H45: 0.2 | I45: Percent | J45: 0.25 | K45: 0.25 | L45: =1-SUM(J45:K45) -> 0.5
...

Sheet 4.6.1.1-2 Methane
A1: #VALUE! | C1: 4.6.1.1-2 Manure Methane
A3: =HYPERLINK("#'Home'!A1", "Home") -> Home | D3: Method 1 | N3: Method 2
A4: =HYPERLINK("#'Results'!A1", "Results") -> Results
D5: {=MMS_poultry_Methane_Equations.VEERG_4_6_1_1__5_VolatileSolidProduction_Title()} -> Volatile solid production poultry classes
A6: INPUTS | D6: {=MMS_poultry_Methane_Equations.VEERG_4_6_1_1__5_VolatileSolidProduction_Source()} -> VEERG 2026: 4.4.1.1, Equation (5)
A7: =HYPERLINK("#'Input - Site'!A1", "Site") -> Site | D7: Function name | E7: {=Common_InputFunctions.Utility_DisplayFunctionName(D35)} -> =MMS_poultry_Methane_Equations.VEERG_4_6_1_1__5_VolatileSolidProduction
A8: =HYPERLINK("#'Input - Swine'!A1", "Swine") -> Swine
A10: CALCULATIONS | D10: Variable | E10: {=MMS_poultry_Methane_Equations.VEERG_4_6_1_1__5_VolatileSolidProduction_Variable()} -> VS_jk
A11: =HYPERLINK("#'4.5.1.1-2 Methane'!A1", "4.5.1.1-2 Methane") -> 4.5.1.1-2 Methane | D11: Unit | E11: {=MMS_poultry_Methane_Equations.VEERG_4_6_1_1__5_VolatileSolidProduction_Unit()} -> kg VS/bird/day
A12: =HYPERLINK("#'4.5.1.3-4 Direct N20'!A1", "4.5.1.3-4 Direct N2O") -> 4.5.1.3-4 Direct N2O
A13: =HYPERLINK("#'4.5.1.5-6 Atmos Dep'!A1", "4.5.1.5-6 Soil atm. deposition") -> 4.5.1.5-6 Soil atm. deposition | D13: {=MMS_poultry_Methane_Equations.VEERG_4_6_1_1__5_VolatileSolidProduction_Arguments()} -> I_jk | E13: dry matter intake for each class and subclass : kg DM/bird/day | G13: ="See " & D17 -> See M1_Table_I_j_k
A14: =HYPERLINK("#'4.5.1.7-8 Leaching and runoff'!A1", "4.5.1.7-8 Leaching & runoff") -> 4.5.1.7-8 Leaching & runoff | D14: DMD_jk | E14: dry matter digestibility for each class and subclass : fraction | G14: ="See " & D22 -> See M1_Table_DMD_j_k
A15: =HYPERLINK("#'4.5.1.9 Manure applied to soils'!A1", "4.5.1.9 Manure applied to soils") -> 4.5.1.9 Manure applied to soils | D15: A_j | E15: ash content of manure for each class and subclass : fraction | G15: ="See " & D32 -> See M1_Table_VS_j_k
A17: APPENDICES | D17: M1_Table_I_j_k | N17: M2_Table_I_j_k
A18: =HYPERLINK("#'Constants - Swine'!A1", "Constants - Swine") -> Constants - Swine | D18: Dry matter intake (Method 1) | N18: Dry matter intake (Method 2)
A19: =HYPERLINK("#'Constants - Livestock'!A1", "Constants - Livestock") -> Constants - Livestock | D19: Layers | E19: Meat chicken growers | F19: Meat chicken breeders | G19: Other | N19: Layers | O19: Meat chicken growers | P19: Meat chicken breeders | Q19: Other
A20: =HYPERLINK("#'Constants - Common'!A1", "Constants - Common") -> Constants - Common | D20: ='Input - Poultry'!E16 -> 0.086 | E20: ='Input - Poultry'!F16 -> 0.093 | F20: ='Input - Poultry'!G16 -> 0.103 | G20: ='Input - Poultry'!H16 -> 0.093 | H20: kg/DM/bird/day | N20: ='Input - Poultry'!E21 -> 0.086 | O20: ='Input - Poultry'!F21 -> 0.093 | P20: ='Input - Poultry'!G21 -> 0.103 | Q20: ='Input - Poultry'!H21 -> 0.093 | R20: kg/DM/bird/day
A21: =HYPERLINK("#'Acknowledgements'!A1", "Acknowledgements") -> Acknowledgements
D22: M1_Table_DMD_j_k | N22: M1_Table_DMD_j_k
D23: Dry matter digestibility (Method 1) | N23: Dry matter digestibility (Method 1)
D24: Layers | E24: Meat chicken growers | F24: Meat chicken breeders | G24: Other | N24: Layers | O24: Meat chicken growers | P24: Meat chicken breeders | Q24: Other
D25: ='Input - Poultry'!E17 -> 0.8 | E25: ='Input - Poultry'!F17 -> 0.8 | F25: ='Input - Poultry'!G17 -> 0.8 | G25: ='Input - Poultry'!H17 -> 0.8 | H25: fraction | N25: ='Input - Poultry'!E22 -> 0.8 | O25: ='Input - Poultry'!F22 -> 0.8 | P25: ='Input - Poultry'!G22 -> 0.8 | Q25: ='Input - Poultry'!H22 -> 0.8 | R25: fraction
D27: Table_A_j
D28: Ash content of manure
D29: Layers | E29: Meat chicken growers | F29: Meat chicken breeders | G29: Other
D30: ='Constants - Poultry'!E13 -> 0.18 | E30: ='Constants - Poultry'!F13 -> 0.15 | F30: ='Constants - Poultry'!G13 -> 0.18 | G30: ='Constants - Poultry'!H13 -> 0.15 | H30: fraction
D32: M1_Table_VS_j_k | N32: M2_Table_VS_j_k
D33: Volatile solid production (Method 1) | N33: Volatile solid production (Method 2)
D34: Layers | E34: Meat chicken growers | F34: Meat chicken breeders | G34: Other | N34: Layers | O34: Meat chicken growers | P34: Meat chicken breeders | Q34: Other
D35: {=MMS_poultry_Methane_Equations.VEERG_4_6_1_1__5_VolatileSolidProduction(D20,D25,D30)} -> 0.014104 | E35: {=MMS_poultry_Methane_Equations.VEERG_4_6_1_1__5_VolatileSolidProduction(E20,E25,E30)} -> 0.01581 | F35: {=MMS_poultry_Methane_Equations.VEERG_4_6_1_1__5_VolatileSolidProduction(F20,F25,F30)} -> 0.016892 | G35: {=MMS_poultry_Methane_Equations.VEERG_4_6_1_1__5_VolatileSolidProduction(G20,G25,G30)} -> 0.01581 | H35: =$E$11 -> kg VS/bird/day | N35: {=MMS_poultry_Methane_Equations.VEERG_4_6_1_1__5_VolatileSolidProduction(N20,N25,D30)} -> 0.014104 | O35: {=MMS_poultry_Methane_Equations.VEERG_4_6_1_1__5_VolatileSolidProduction(O20,O25,E30)} -> 0.01581 | P35: {=MMS_poultry_Methane_Equations.VEERG_4_6_1_1__5_VolatileSolidProduction(P20,P25,F30)} -> 0.016892 | Q35: {=MMS_poultry_Methane_Equations.VEERG_4_6_1_1__5_VolatileSolidProduction(Q20,Q25,G30)} -> 0.01581 | R35: =$E$11 -> kg VS/bird/day
D39: {=MMS_poultry_Methane_Equations.VEERG_4_6_1_1__2_Stage1MethaneProduction_Title()} -> Production of methane in treatment stage 1 MMS
D40: {=MMS_poultry_Methane_Equations.VEERG_4_6_1_1__2_Stage1MethaneProduction_Source()} -> VEERG 2026: 4.4.1.1, Equation (2)
D41: Function name | E41: {=Common_InputFunctions.Utility_DisplayFunctionName(E83)} -> =MMS_poultry_Methane_Equations.VEERG_4_6_1_1__2_Stage1MethaneProduction
D44: Variable | E44: {=MMS_poultry_Methane_Equations.VEERG_4_6_1_1__2_Stage1MethaneProduction_Variable()} -> M_jkmT1
D45: Unit | E45: {=MMS_poultry_Methane_Equations.VEERG_4_6_1_1__2_Stage1MethaneProduction_Unit()} -> kg CH4/bird/day
D47: {=MMS_poultry_Methane_Equations.VEERG_4_6_1_1__2_Stage1MethaneProduction_Arguments()} -> VS_jk | E47: volatile solid production poultry classes : kg VS/bird/day | G47: ="See " & D32 -> See M1_Table_VS_j_k
D48: BO_j | E48: emissions potential per class : m3 CH4/kg VS | G48: ="See " & D62 -> See Table_B_0_j
D49: MMS_jmT1 | E49: fraction of manure in each primary system : fraction | G49: ="See " & D54 -> See Table_MMS_j_m_T-1
D50: MCF_im | E50: methane conversion factor for temperature zone and MMS : fraction | G50: ="See " & D67 -> See Table_MCF_i_m
D51: rho | E51: density of methane : kg/m3 | G51: ='Constants - Common'!$D$175 -> 0.6784
...

Sheet 4.6.1.3-4 Direct N20
A1: #VALUE! | C1: 4.6.1.3-4 Manure Direct N2O
A3: =HYPERLINK("#'Home'!A1", "Home") -> Home | D3: Method 1 | N3: Method 2
A4: =HYPERLINK("#'Results'!A1", "Results") -> Results
D5: {=MMS_Poultry_N2ODirect_Equations.VEERG_4_6_1_3__5_NitrogenIntake_Title()} -> Nitrogen intake of poultry
A6: INPUTS | D6: {=MMS_Poultry_N2ODirect_Equations.VEERG_4_6_1_3__5_NitrogenIntake_Source()} -> VEERG 2026: 4.6.1.3, Equation (5)
A7: =HYPERLINK("#'Input - Site'!A1", "Site") -> Site | D7: Function name | E7: {=Common_InputFunctions.Utility_DisplayFunctionName()} -> #VALUE!
A8: =HYPERLINK("#'Input - Swine'!A1", "Swine") -> Swine
A10: CALCULATIONS | D10: Variable | E10: {=MMS_Poultry_N2ODirect_Equations.VEERG_4_6_1_3__5_NitrogenIntake_Variable()} -> NI_jk
A11: =HYPERLINK("#'4.5.1.1-2 Methane'!A1", "4.5.1.1-2 Methane") -> 4.5.1.1-2 Methane | D11: Unit | E11: {=MMS_Poultry_N2ODirect_Equations.VEERG_4_6_1_3__5_NitrogenIntake_Unit()} -> kg N/bird/day
A12: =HYPERLINK("#'4.5.1.3-4 Direct N20'!A1", "4.5.1.3-4 Direct N2O") -> 4.5.1.3-4 Direct N2O
A13: =HYPERLINK("#'4.5.1.5-6 Atmos Dep'!A1", "4.5.1.5-6 Soil atm. deposition") -> 4.5.1.5-6 Soil atm. deposition | D13: {=MMS_Poultry_N2ODirect_Equations.VEERG_4_6_1_3__5_NitrogenIntake_Arguments()} -> I_jk | E13: dry matter intake for each class and subclass : kg DM/bird/day
A14: =HYPERLINK("#'4.5.1.7-8 Leaching and runoff'!A1", "4.5.1.7-8 Leaching & runoff") -> 4.5.1.7-8 Leaching & runoff | D14: CP_jk | E14: crude protein content of feed : fraction
A15: =HYPERLINK("#'4.5.1.9 Manure applied to soils'!A1", "4.5.1.9 Manure applied to soils") -> 4.5.1.9 Manure applied to soils | D15: 6.25 | E15: factor for converting crude protein into nitrogen : ratio
A17: APPENDICES | D17: M1_Table_I_j_k
A18: =HYPERLINK("#'Constants - Swine'!A1", "Constants - Swine") -> Constants - Swine | D18: Dry matter intake (Method 1)
A19: =HYPERLINK("#'Constants - Livestock'!A1", "Constants - Livestock") -> Constants - Livestock | D19: Layers | E19: Meat chicken growers | F19: Meat chicken breeders | G19: Other
A20: =HYPERLINK("#'Constants - Common'!A1", "Constants - Common") -> Constants - Common | D20: ='Input - Poultry'!E16 -> 0.086 | E20: ='Constants - Poultry'!E13 -> 0.18 | F20: ='Constants - Poultry'!F13 -> 0.15 | G20: ='Constants - Poultry'!G13 -> 0.18 | H20: kg/DM/bird/day
A21: =HYPERLINK("#'Acknowledgements'!A1", "Acknowledgements") -> Acknowledgements
D22: M1_Table_CP_j_k
D23: Crude protein content of feed (Method 1)
D24: Layers | E24: Meat chicken growers | F24: Meat chicken breeders | G24: Other
D25: ='Input - Poultry'!E18 -> 0.19 | E25: ='Input - Poultry'!F18 -> 0.23 | F25: ='Input - Poultry'!G18 -> 0.19 | G25: ='Input - Poultry'!H18 -> 0.23 | H25: fraction

Sheet 4.5.1.5-6 Atmos Dep
A1: #VALUE! | C1: 4.5.1.5-6 Atmospheric deposition N2O
A3: =HYPERLINK("#'Home'!A1", "Home") -> Home | D3: Method 1 | N3: Method 2
A4: =HYPERLINK("#'Results'!A1", "Results") -> Results
D5: {=MMS_Swine_AtmosphericDeposition_Equations.VEERG_4_5_1_5__2_TotalNitrogenVolatilisedFromMMS_Title()} -> Total nitrogen volatilised from MMS
A6: INPUTS | D6: {=MMS_Swine_AtmosphericDeposition_Equations.VEERG_4_5_1_5__2_TotalNitrogenVolatilisedFromMMS_Source()} -> VEERG 2026: 4.5.1.1, Equation (2)
A7: =HYPERLINK("#'Input - Site'!A1", "Site") -> Site | D7: Function name | E7: {=Common_InputFunctions.Utility_DisplayFunctionName(F63)} -> =MMS_Swine_AtmosphericDeposition_Equations.VEERG_4_5_1_5__2_TotalNitrogenVolatilisedFromMMS
A8: =HYPERLINK("#'Input - Swine'!A1", "Swine") -> Swine
A10: CALCULATIONS | D10: Variable | E10: {=MMS_Swine_AtmosphericDeposition_Equations.VEERG_4_5_1_5__2_TotalNitrogenVolatilisedFromMMS_Variable()} -> MMS_ATMOS
A11: =HYPERLINK("#'4.5.1.1-2 Methane'!A1", "4.5.1.1-2 Methane") -> 4.5.1.1-2 Methane | D11: Unit | E11: {=MMS_Swine_AtmosphericDeposition_Equations.VEERG_4_5_1_5__2_TotalNitrogenVolatilisedFromMMS_Unit()} -> kg N
A12: =HYPERLINK("#'4.5.1.3-4 Direct N20'!A1", "4.5.1.3-4 Direct N2O") -> 4.5.1.3-4 Direct N2O
A13: =HYPERLINK("#'4.5.1.5-6 Atmos Dep'!A1", "4.5.1.5-6 Soil atm. deposition") -> 4.5.1.5-6 Soil atm. deposition | D13: {=MMS_Swine_AtmosphericDeposition_Equations.VEERG_4_5_1_5__2_TotalNitrogenVolatilisedFromMMS_Arguments()} -> MN_jmT | E13: nitrogen per swine class, MMS and treatment stage (kg N) | G13: ="See " & D16 & " and " & D26 -> See M1_Table_MN_j_m_T-1 and M1_Table_MN_j_m_T-2
A14: =HYPERLINK("#'4.5.1.7-8 Leaching and runoff'!A1", "4.5.1.7-8 Leaching & runoff") -> 4.5.1.7-8 Leaching & runoff | D14: FracGASMmT | E14: fraction of N volatilised in each MMS ((kg NH3-N + NOx-N)/kg N) | G14: ="See " & D50 -> See Table_FracGASM_m_t
A15: =HYPERLINK("#'4.5.1.9 Manure applied to soils'!A1", "4.5.1.9 Manure applied to soils") -> 4.5.1.9 Manure applied to soils
D16: M1_Table_MN_j_m_T-1 | N16: M1_Table_MN_j_m_T-1
A17: APPENDICES | D17: Nitrogen in treatment stage 1 MMS (Method 1) | N17: Nitrogen in treatment stage 1 MMS (Method 1)
A18: =HYPERLINK("#'Constants - Swine'!A1", "Constants - Swine") -> Constants - Swine | D18: Stage 1 management | E18: Boars | F18: Sows | G18: Gilts | H18: Others | N18: Stage 1 management | O18: Boars | P18: Sows | Q18: Gilts | R18: Others
A19: =HYPERLINK("#'Constants - Livestock'!A1", "Constants - Livestock") -> Constants - Livestock | D19: ='Input - Poultry'!$D$30 -> Belt manure removal | E19: ='4.6.1.3-4 Direct N20'!E118 -> 0 | F19: ='4.6.1.3-4 Direct N20'!F118 -> 0 | G19: ='4.6.1.3-4 Direct N20'!G118 -> 0 | H19: ='4.6.1.3-4 Direct N20'!H118 -> 0 | I19: ='4.6.1.3-4 Direct N20'!I118 -> 0 | N19: ='Input - Poultry'!$D$30 -> Belt manure removal | O19: ='4.6.1.3-4 Direct N20'!O118 -> 0 | P19: ='4.6.1.3-4 Direct N20'!P118 -> 0 | Q19: ='4.6.1.3-4 Direct N20'!Q118 -> 0 | R19: ='4.6.1.3-4 Direct N20'!R118 -> 0 | S19: ='4.6.1.3-4 Direct N20'!S118 -> 0
A20: =HYPERLINK("#'Constants - Common'!A1", "Constants - Common") -> Constants - Common | D20: ='Input - Poultry'!$D$31 -> Manure stored in house | E20: ='4.6.1.3-4 Direct N20'!E119 -> 0 | F20: ='4.6.1.3-4 Direct N20'!F119 -> 0 | G20: ='4.6.1.3-4 Direct N20'!G119 -> 0 | H20: ='4.6.1.3-4 Direct N20'!H119 -> 0 | I20: ='4.6.1.3-4 Direct N20'!I119 -> 0 | N20: ='Input - Poultry'!$D$31 -> Manure stored in house | O20: ='4.6.1.3-4 Direct N20'!O119 -> 0 | P20: ='4.6.1.3-4 Direct N20'!P119 -> 0 | Q20: ='4.6.1.3-4 Direct N20'!Q119 -> 0 | R20: ='4.6.1.3-4 Direct N20'!R119 -> 0 | S20: ='4.6.1.3-4 Direct N20'!S119 -> 0
A21: =HYPERLINK("#'Acknowledgements'!A1", "Acknowledgements") -> Acknowledgements | D21: ='Input - Poultry'!$D$32 -> Pasture range and paddock | E21: ='4.6.1.3-4 Direct N20'!E120 -> 0 | F21: ='4.6.1.3-4 Direct N20'!F120 -> 0 | G21: ='4.6.1.3-4 Direct N20'!G120 -> 0 | H21: ='4.6.1.3-4 Direct N20'!H120 -> 0 | I21: ='4.6.1.3-4 Direct N20'!I120 -> 0 | N21: ='Input - Poultry'!$D$32 -> Pasture range and paddock | O21: ='4.6.1.3-4 Direct N20'!O120 -> 0 | P21: ='4.6.1.3-4 Direct N20'!P120 -> 0 | Q21: ='4.6.1.3-4 Direct N20'!Q120 -> 0 | R21: ='4.6.1.3-4 Direct N20'!R120 -> 0 | S21: ='4.6.1.3-4 Direct N20'!S120 -> 0
D22: ='Input - Poultry'!$D$33 -> No MMS | E22: ='4.6.1.3-4 Direct N20'!E121 -> 0 | F22: ='4.6.1.3-4 Direct N20'!F121 -> 0 | G22: ='4.6.1.3-4 Direct N20'!G121 -> 0 | H22: ='4.6.1.3-4 Direct N20'!H121 -> 0 | I22: ='4.6.1.3-4 Direct N20'!I121 -> 0 | N22: ='Input - Poultry'!$D$33 -> No MMS | O22: ='4.6.1.3-4 Direct N20'!O121 -> 0 | P22: ='4.6.1.3-4 Direct N20'!P121 -> 0 | Q22: ='4.6.1.3-4 Direct N20'!Q121 -> 0 | R22: ='4.6.1.3-4 Direct N20'!R121 -> 0 | S22: ='4.6.1.3-4 Direct N20'!S121 -> 0
D23: ='Input - Poultry'!#REF! -> #REF! | E23: ='4.6.1.3-4 Direct N20'!E122 -> 0 | F23: ='4.6.1.3-4 Direct N20'!F122 -> 0 | G23: ='4.6.1.3-4 Direct N20'!G122 -> 0 | H23: ='4.6.1.3-4 Direct N20'!H122 -> 0 | I23: ='4.6.1.3-4 Direct N20'!I122 -> 0 | N23: ='Input - Poultry'!#REF! -> #REF! | O23: ='4.6.1.3-4 Direct N20'!O122 -> 0 | P23: ='4.6.1.3-4 Direct N20'!P122 -> 0 | Q23: ='4.6.1.3-4 Direct N20'!Q122 -> 0 | R23: ='4.6.1.3-4 Direct N20'!R122 -> 0 | S23: ='4.6.1.3-4 Direct N20'!S122 -> 0
D24: ='Input - Poultry'!#REF! -> #REF! | E24: ='4.6.1.3-4 Direct N20'!E123 -> 0 | F24: ='4.6.1.3-4 Direct N20'!F123 -> 0 | G24: ='4.6.1.3-4 Direct N20'!G123 -> 0 | H24: ='4.6.1.3-4 Direct N20'!H123 -> 0 | I24: ='4.6.1.3-4 Direct N20'!I123 -> 0 | N24: ='Input - Poultry'!#REF! -> #REF! | O24: ='4.6.1.3-4 Direct N20'!O123 -> 0 | P24: ='4.6.1.3-4 Direct N20'!P123 -> 0 | Q24: ='4.6.1.3-4 Direct N20'!Q123 -> 0 | R24: ='4.6.1.3-4 Direct N20'!R123 -> 0 | S24: ='4.6.1.3-4 Direct N20'!S123 -> 0
D26: M1_Table_MN_j_m_T-2 | N26: M1_Table_MN_j_m_T-2
D27: Nitrogen in stage 2 MMS (Method 1) | N27: Nitrogen in stage 2 MMS (Method 1)
D28: Stage 1 management | E28: Stage 2 management | F28: Boars | G28: Sows | H28: Gilts | I28: Others | N28: Stage 1 management | O28: Stage 2 management | P28: Boars | Q28: Sows | R28: Gilts | S28: Others
D29: ='Input - Poultry'!$D$30 -> Belt manure removal | E29: ='Input - Poultry'!$D$38 -> Solid storage | F29: ='4.6.1.3-4 Direct N20'!F209 -> 0 | G29: ='4.6.1.3-4 Direct N20'!G209 -> 0 | H29: ='4.6.1.3-4 Direct N20'!H209 -> 0 | I29: ='4.6.1.3-4 Direct N20'!I209 -> 0 | J29: ='4.6.1.3-4 Direct N20'!J209 -> 0 | N29: ='Input - Poultry'!$D$30 -> Belt manure removal | O29: ='Input - Poultry'!$D$38 -> Solid storage | P29: ='4.6.1.3-4 Direct N20'!P209 -> 0 | Q29: ='4.6.1.3-4 Direct N20'!Q209 -> 0 | R29: ='4.6.1.3-4 Direct N20'!R209 -> 0 | S29: ='4.6.1.3-4 Direct N20'!S209 -> 0 | T29: ='4.6.1.3-4 Direct N20'!T209 -> 0
E30: ='Input - Poultry'!$D$39 -> Composting (passive windrow) | F30: ='4.6.1.3-4 Direct N20'!F210 -> 0 | G30: ='4.6.1.3-4 Direct N20'!G210 -> 0 | H30: ='4.6.1.3-4 Direct N20'!H210 -> 0 | I30: ='4.6.1.3-4 Direct N20'!I210 -> 0 | J30: ='4.6.1.3-4 Direct N20'!J210 -> 0 | O30: ='Input - Poultry'!$D$39 -> Composting (passive windrow) | P30: ='4.6.1.3-4 Direct N20'!P210 -> 0 | Q30: ='4.6.1.3-4 Direct N20'!Q210 -> 0 | R30: ='4.6.1.3-4 Direct N20'!R210 -> 0 | S30: ='4.6.1.3-4 Direct N20'!S210 -> 0 | T30: ='4.6.1.3-4 Direct N20'!T210 -> 0
E31: ='Input - Poultry'!$D$40 -> Digester / covered lagoons | F31: ='4.6.1.3-4 Direct N20'!F211 -> 0 | G31: ='4.6.1.3-4 Direct N20'!G211 -> 0 | H31: ='4.6.1.3-4 Direct N20'!H211 -> 0 | I31: ='4.6.1.3-4 Direct N20'!I211 -> 0 | J31: ='4.6.1.3-4 Direct N20'!J211 -> 0 | O31: ='Input - Poultry'!$D$40 -> Digester / covered lagoons | P31: ='4.6.1.3-4 Direct N20'!P211 -> 0 | Q31: ='4.6.1.3-4 Direct N20'!Q211 -> 0 | R31: ='4.6.1.3-4 Direct N20'!R211 -> 0 | S31: ='4.6.1.3-4 Direct N20'!S211 -> 0 | T31: ='4.6.1.3-4 Direct N20'!T211 -> 0
D32: ='Input - Poultry'!$D$31 -> Manure stored in house | E32: ='Input - Poultry'!$D$45 -> Solid storage | F32: ='4.6.1.3-4 Direct N20'!F212 -> 0 | G32: ='4.6.1.3-4 Direct N20'!G212 -> 0 | H32: ='4.6.1.3-4 Direct N20'!H212 -> 0 | I32: ='4.6.1.3-4 Direct N20'!I212 -> 0 | J32: ='4.6.1.3-4 Direct N20'!J212 -> 0 | N32: ='Input - Poultry'!$D$31 -> Manure stored in house | O32: ='Input - Poultry'!$D$45 -> Solid storage | P32: ='4.6.1.3-4 Direct N20'!P212 -> 0 | Q32: ='4.6.1.3-4 Direct N20'!Q212 -> 0 | R32: ='4.6.1.3-4 Direct N20'!R212 -> 0 | S32: ='4.6.1.3-4 Direct N20'!S212 -> 0 | T32: ='4.6.1.3-4 Direct N20'!T212 -> 0
E33: ='Input - Poultry'!$D$46 -> Composting (passive windrow) | F33: ='4.6.1.3-4 Direct N20'!F213 -> 0 | G33: ='4.6.1.3-4 Direct N20'!G213 -> 0 | H33: ='4.6.1.3-4 Direct N20'!H213 -> 0 | I33: ='4.6.1.3-4 Direct N20'!I213 -> 0 | J33: ='4.6.1.3-4 Direct N20'!J213 -> 0 | O33: ='Input - Poultry'!$D$46 -> Composting (passive windrow) | P33: ='4.6.1.3-4 Direct N20'!P213 -> 0 | Q33: ='4.6.1.3-4 Direct N20'!Q213 -> 0 | R33: ='4.6.1.3-4 Direct N20'!R213 -> 0 | S33: ='4.6.1.3-4 Direct N20'!S213 -> 0 | T33: ='4.6.1.3-4 Direct N20'!T213 -> 0
E34: ='Input - Poultry'!$D$47 -> Digester / covered lagoons | F34: ='4.6.1.3-4 Direct N20'!F214 -> 0 | G34: ='4.6.1.3-4 Direct N20'!G214 -> 0 | H34: ='4.6.1.3-4 Direct N20'!H214 -> 0 | I34: ='4.6.1.3-4 Direct N20'!I214 -> 0 | J34: ='4.6.1.3-4 Direct N20'!J214 -> 0 | O34: ='Input - Poultry'!$D$47 -> Digester / covered lagoons | P34: ='4.6.1.3-4 Direct N20'!P214 -> 0 | Q34: ='4.6.1.3-4 Direct N20'!Q214 -> 0 | R34: ='4.6.1.3-4 Direct N20'!R214 -> 0 | S34: ='4.6.1.3-4 Direct N20'!S214 -> 0 | T34: ='4.6.1.3-4 Direct N20'!T214 -> 0
E35: ='Input - Poultry'!$D$48 -> Direct processing | F35: ='4.6.1.3-4 Direct N20'!F215 -> 0 | G35: ='4.6.1.3-4 Direct N20'!G215 -> 0 | H35: ='4.6.1.3-4 Direct N20'!H215 -> 0 | I35: ='4.6.1.3-4 Direct N20'!I215 -> 0 | J35: ='4.6.1.3-4 Direct N20'!J215 -> 0 | O35: ='Input - Poultry'!$D$48 -> Direct processing | P35: ='4.6.1.3-4 Direct N20'!P215 -> 0 | Q35: ='4.6.1.3-4 Direct N20'!Q215 -> 0 | R35: ='4.6.1.3-4 Direct N20'!R215 -> 0 | S35: ='4.6.1.3-4 Direct N20'!S215 -> 0 | T35: ='4.6.1.3-4 Direct N20'!T215 -> 0
D36: ='Input - Poultry'!$D$32 -> Pasture range and paddock | E36: ='Input - Poultry'!$D$52 -> Solid storage | F36: ='4.6.1.3-4 Direct N20'!F216 -> 0 | G36: ='4.6.1.3-4 Direct N20'!G216 -> 0 | H36: ='4.6.1.3-4 Direct N20'!H216 -> 0 | I36: ='4.6.1.3-4 Direct N20'!I216 -> 0 | J36: ='4.6.1.3-4 Direct N20'!J216 -> 0 | N36: ='Input - Poultry'!$D$32 -> Pasture range and paddock | O36: ='Input - Poultry'!$D$52 -> Solid storage | P36: ='4.6.1.3-4 Direct N20'!P216 -> 0 | Q36: ='4.6.1.3-4 Direct N20'!Q216 -> 0 | R36: ='4.6.1.3-4 Direct N20'!R216 -> 0 | S36: ='4.6.1.3-4 Direct N20'!S216 -> 0 | T36: ='4.6.1.3-4 Direct N20'!T216 -> 0
E37: ='Input - Poultry'!$D$53 -> Composting (passive windrow) | F37: ='4.6.1.3-4 Direct N20'!F217 -> 0 | G37: ='4.6.1.3-4 Direct N20'!G217 -> 0 | H37: ='4.6.1.3-4 Direct N20'!H217 -> 0 | I37: ='4.6.1.3-4 Direct N20'!I217 -> 0 | J37: ='4.6.1.3-4 Direct N20'!J217 -> 0 | O37: ='Input - Poultry'!$D$53 -> Composting (passive windrow) | P37: ='4.6.1.3-4 Direct N20'!P217 -> 0 | Q37: ='4.6.1.3-4 Direct N20'!Q217 -> 0 | R37: ='4.6.1.3-4 Direct N20'!R217 -> 0 | S37: ='4.6.1.3-4 Direct N20'!S217 -> 0 | T37: ='4.6.1.3-4 Direct N20'!T217 -> 0
E38: ='Input - Poultry'!$D$54 -> Digester / covered lagoons | F38: ='4.6.1.3-4 Direct N20'!F218 -> 0 | G38: ='4.6.1.3-4 Direct N20'!G218 -> 0 | H38: ='4.6.1.3-4 Direct N20'!H218 -> 0 | I38: ='4.6.1.3-4 Direct N20'!I218 -> 0 | J38: ='4.6.1.3-4 Direct N20'!J218 -> 0 | O38: ='Input - Poultry'!$D$54 -> Digester / covered lagoons | P38: ='4.6.1.3-4 Direct N20'!P218 -> 0 | Q38: ='4.6.1.3-4 Direct N20'!Q218 -> 0 | R38: ='4.6.1.3-4 Direct N20'!R218 -> 0 | S38: ='4.6.1.3-4 Direct N20'!S218 -> 0 | T38: ='4.6.1.3-4 Direct N20'!T218 -> 0
D39: ='Input - Poultry'!$D$33 -> No MMS | E39: ='Input - Poultry'!#REF! -> #REF! | F39: ='4.6.1.3-4 Direct N20'!F219 -> 0 | G39: ='4.6.1.3-4 Direct N20'!G219 -> 0 | H39: ='4.6.1.3-4 Direct N20'!H219 -> 0 | I39: ='4.6.1.3-4 Direct N20'!I219 -> 0 | J39: ='4.6.1.3-4 Direct N20'!J219 -> 0 | N39: ='Input - Poultry'!$D$33 -> No MMS | O39: ='Input - Poultry'!#REF! -> #REF! | P39: ='4.6.1.3-4 Direct N20'!P219 -> 0 | Q39: ='4.6.1.3-4 Direct N20'!Q219 -> 0 | R39: ='4.6.1.3-4 Direct N20'!R219 -> 0 | S39: ='4.6.1.3-4 Direct N20'!S219 -> 0 | T39: ='4.6.1.3-4 Direct N20'!T219 -> 0
E40: ='Input - Poultry'!$D$71 -> 0 | F40: ='4.6.1.3-4 Direct N20'!F220 -> 0 | G40: ='4.6.1.3-4 Direct N20'!G220 -> 0 | H40: ='4.6.1.3-4 Direct N20'!H220 -> 0 | I40: ='4.6.1.3-4 Direct N20'!I220 -> 0 | J40: ='4.6.1.3-4 Direct N20'!J220 -> 0 | O40: ='Input - Poultry'!$D$71 -> 0 | P40: ='4.6.1.3-4 Direct N20'!P220 -> 0 | Q40: ='4.6.1.3-4 Direct N20'!Q220 -> 0 | R40: ='4.6.1.3-4 Direct N20'!R220 -> 0 | S40: ='4.6.1.3-4 Direct N20'!S220 -> 0 | T40: ='4.6.1.3-4 Direct N20'!T220 -> 0
E41: ='Input - Poultry'!$D$72 -> 0 | F41: ='4.6.1.3-4 Direct N20'!F221 -> 0 | G41: ='4.6.1.3-4 Direct N20'!G221 -> 0 | H41: ='4.6.1.3-4 Direct N20'!H221 -> 0 | I41: ='4.6.1.3-4 Direct N20'!I221 -> 0 | J41: ='4.6.1.3-4 Direct N20'!J221 -> 0 | O41: ='Input - Poultry'!$D$72 -> 0 | P41: ='4.6.1.3-4 Direct N20'!P221 -> 0 | Q41: ='4.6.1.3-4 Direct N20'!Q221 -> 0 | R41: ='4.6.1.3-4 Direct N20'!R221 -> 0 | S41: ='4.6.1.3-4 Direct N20'!S221 -> 0 | T41: ='4.6.1.3-4 Direct N20'!T221 -> 0
D42: ='Input - Poultry'!#REF! -> #REF! | E42: ='Input - Poultry'!$D$77 -> 0 | F42: ='4.6.1.3-4 Direct N20'!F222 -> 0 | G42: ='4.6.1.3-4 Direct N20'!G222 -> 0 | H42: ='4.6.1.3-4 Direct N20'!H222 -> 0 | I42: ='4.6.1.3-4 Direct N20'!I222 -> 0 | J42: ='4.6.1.3-4 Direct N20'!J222 -> 0 | N42: ='Input - Poultry'!#REF! -> #REF! | O42: ='Input - Poultry'!$D$77 -> 0 | P42: ='4.6.1.3-4 Direct N20'!P222 -> 0 | Q42: ='4.6.1.3-4 Direct N20'!Q222 -> 0 | R42: ='4.6.1.3-4 Direct N20'!R222 -> 0 | S42: ='4.6.1.3-4 Direct N20'!S222 -> 0 | T42: ='4.6.1.3-4 Direct N20'!T222 -> 0
E43: ='Input - Poultry'!$D$78 -> 0 | F43: ='4.6.1.3-4 Direct N20'!F223 -> 0 | G43: ='4.6.1.3-4 Direct N20'!G223 -> 0 | H43: ='4.6.1.3-4 Direct N20'!H223 -> 0 | I43: ='4.6.1.3-4 Direct N20'!I223 -> 0 | J43: ='4.6.1.3-4 Direct N20'!J223 -> 0 | O43: ='Input - Poultry'!$D$78 -> 0 | P43: ='4.6.1.3-4 Direct N20'!P223 -> 0 | Q43: ='4.6.1.3-4 Direct N20'!Q223 -> 0 | R43: ='4.6.1.3-4 Direct N20'!R223 -> 0 | S43: ='4.6.1.3-4 Direct N20'!S223 -> 0 | T43: ='4.6.1.3-4 Direct N20'!T223 -> 0
...

Sheet 4.5.1.7-8 Leaching and runoff
A1: #VALUE! | C1: 4.5.1.7-8 Leaching and runoff
A3: =HYPERLINK("#'Home'!A1", "Home") -> Home | D3: Method 1 | M3: Method 2
A4: =HYPERLINK("#'Results'!A1", "Results") -> Results
D5: {=MMS_Swine_LeachingAndRunoff_Equations.VEERG_4_5_1_7__2_MassOfNitrogenLostToLeachingAndRunoffFromDrylotMMS_Title()} -> Mass of nitrogen lost to leaching and runoff from drylot MMS
A6: INPUTS | D6: {=MMS_Swine_LeachingAndRunoff_Equations.VEERG_4_5_1_7__2_MassOfNitrogenLostToLeachingAndRunoffFromDrylotMMS_Source()} -> VEERG 2026: 4.5.1.7, Equation (2)
A7: =HYPERLINK("#'Input - Site'!A1", "Site") -> Site | D7: Function name | E7: {=Common_InputFunctions.Utility_DisplayFunctionName($E$28)} -> =MMS_Swine_LeachingAndRunoff_Equations.VEERG_4_5_1_7__2_MassOfNitrogenLostToLeachingAndRunoffFromDrylotMMS
A8: =HYPERLINK("#'Input - Swine'!A1", "Swine") -> Swine
A10: CALCULATIONS | D10: Variable | E10: {=MMS_Swine_LeachingAndRunoff_Equations.VEERG_4_5_1_7__2_MassOfNitrogenLostToLeachingAndRunoffFromDrylotMMS_Variable()} -> MNLeach_jm5 | F10: This infers that drylot is not a stage 2 MMS option
A11: =HYPERLINK("#'4.5.1.1-2 Methane'!A1", "4.5.1.1-2 Methane") -> 4.5.1.1-2 Methane | D11: Unit | E11: {=MMS_Swine_LeachingAndRunoff_Equations.VEERG_4_5_1_7__2_MassOfNitrogenLostToLeachingAndRunoffFromDrylotMMS_Unit()} -> kg N | F11: Doc has typo - refers to 'solid storage'
A12: =HYPERLINK("#'4.5.1.3-4 Direct N20'!A1", "4.5.1.3-4 Direct N2O") -> 4.5.1.3-4 Direct N2O
A13: =HYPERLINK("#'4.5.1.5-6 Atmos Dep'!A1", "4.5.1.5-6 Soil atm. deposition") -> 4.5.1.5-6 Soil atm. deposition | D13: {=MMS_Swine_LeachingAndRunoff_Equations.VEERG_4_5_1_7__2_MassOfNitrogenLostToLeachingAndRunoffFromDrylotMMS_Arguments()} -> MN_jm5T1 | E13: nitrogen in treatment stage 1 drylot MMS (kg N) | G13: ="See " & D20 -> See M1_Table_MN_j_m-5_T-1
A14: =HYPERLINK("#'4.5.1.7-8 Leaching and runoff'!A1", "4.5.1.7-8 Leaching & runoff") -> 4.5.1.7-8 Leaching & runoff | D14: FracWET | E14: fraction of N available for leaching and runoff | G14: =Common_InputFunctions.CommonCropping_GetFracWET(G16,G18,Table_SourceData_FracWET[Is in leaching zone],Table_SourceData_FracWET[FracWET],Table_SourceData_FracWETIrrigation[Irrigation type i],Table_SourceData_FracWETIrrigation[FracWET]) -> 1
A15: =HYPERLINK("#'4.5.1.9 Manure applied to soils'!A1", "4.5.1.9 Manure applied to soils") -> 4.5.1.9 Manure applied to soils | D15: FracLEACH_MS | E15: fraction of N lost through leaching and runoff | G15: ='Constants - Poultry'!$E$17 -> 0
D16: z | E16: location in leaching zone | G16: ='Input - Site'!$E$23 -> NO - Not in leaching zone
A17: APPENDICES | D17: j | E17: production system | G17: ='Input - Poultry'!$E$59 -> Crop
A18: =HYPERLINK("#'Constants - Swine'!A1", "Constants - Swine") -> Constants - Swine | D18: ir | E18: irrigation method | G18: ='Input - Poultry'!$E$60 -> Sprinkler irrigation
A19: =HYPERLINK("#'Constants - Livestock'!A1", "Constants - Livestock") -> Constants - Livestock
A20: =HYPERLINK("#'Constants - Common'!A1", "Constants - Common") -> Constants - Common | D20: M1_Table_MN_j_m-5_T-1 | M20: M2_Table_MN_j_m-5_T-1
A21: =HYPERLINK("#'Acknowledgements'!A1", "Acknowledgements") -> Acknowledgements | D21: Nitrogen in stage 1 drylot (Method 1) | M21: Nitrogen in stage 1 drylot (Method 2)
D22: Stage 1 management | E22: Boars | F22: Sows | G22: Gilts | H22: Others | M22: Stage 1 management | N22: Boars | O22: Sows | P22: Gilts | Q22: Others
D23: ='Input - Poultry'!$D$31 -> Manure stored in house | E23: ='4.6.1.3-4 Direct N20'!E119 -> 0 | F23: ='4.6.1.3-4 Direct N20'!F119 -> 0 | G23: ='4.6.1.3-4 Direct N20'!G119 -> 0 | H23: ='4.6.1.3-4 Direct N20'!H119 -> 0 | I23: kg N | M23: ='Input - Poultry'!$D$31 -> Manure stored in house | N23: ='4.6.1.3-4 Direct N20'!O119 -> 0 | O23: ='4.6.1.3-4 Direct N20'!P119 -> 0 | P23: ='4.6.1.3-4 Direct N20'!Q119 -> 0 | Q23: ='4.6.1.3-4 Direct N20'!R119 -> 0 | R23: kg N
D25: M1_Table_MN_leach_j_m-5 | M25: M1_Table_MN_leach_j_m-5
D26: Mass of nitrogen lost to leaching (Method 1) | M26: Mass of nitrogen lost to leaching (Method 1)
D27: Stage 1 management | E27: Boars | F27: Sows | G27: Gilts | H27: Others | M27: Stage 1 management | N27: Boars | O27: Sows | P27: Gilts | Q27: Others
D28: ='Input - Poultry'!$D$31 -> Manure stored in house | E28: {=MMS_Swine_LeachingAndRunoff_Equations.VEERG_4_5_1_7__2_MassOfNitrogenLostToLeachingAndRunoffFromDrylotMMS(E23,$G$14,$G$15)} -> 0 | F28: {=MMS_Swine_LeachingAndRunoff_Equations.VEERG_4_5_1_7__2_MassOfNitrogenLostToLeachingAndRunoffFromDrylotMMS(F23,$G$14,$G$15)} -> 0 | G28: {=MMS_Swine_LeachingAndRunoff_Equations.VEERG_4_5_1_7__2_MassOfNitrogenLostToLeachingAndRunoffFromDrylotMMS(G23,$G$14,$G$15)} -> 0 | H28: {=MMS_Swine_LeachingAndRunoff_Equations.VEERG_4_5_1_7__2_MassOfNitrogenLostToLeachingAndRunoffFromDrylotMMS(H23,$G$14,$G$15)} -> 0 | I28: =$E$11 -> kg N | M28: ='Input - Poultry'!$D$31 -> Manure stored in house | N28: {=MMS_Swine_LeachingAndRunoff_Equations.VEERG_4_5_1_7__2_MassOfNitrogenLostToLeachingAndRunoffFromDrylotMMS(N23,$G$14,$G$15)} -> 0 | O28: {=MMS_Swine_LeachingAndRunoff_Equations.VEERG_4_5_1_7__2_MassOfNitrogenLostToLeachingAndRunoffFromDrylotMMS(O23,$G$14,$G$15)} -> 0 | P28: {=MMS_Swine_LeachingAndRunoff_Equations.VEERG_4_5_1_7__2_MassOfNitrogenLostToLeachingAndRunoffFromDrylotMMS(P23,$G$14,$G$15)} -> 0 | Q28: {=MMS_Swine_LeachingAndRunoff_Equations.VEERG_4_5_1_7__2_MassOfNitrogenLostToLeachingAndRunoffFromDrylotMMS(Q23,$G$14,$G$15)} -> 0 | R28: =$E$11 -> kg N
D32: {=MMS_Swine_LeachingAndRunoff_Equations.VEERG_4_5_1_7__1_AnnualEmissionsFromLeachingAndRunoffFromMMS_Title()} -> Annual emissions from leaching and runoff from each MMS
D33: {=MMS_Swine_LeachingAndRunoff_Equations.VEERG_4_5_1_7__1_AnnualEmissionsFromLeachingAndRunoffFromMMS_Source()} -> VEERG 2026: 4.5.1.7, Equation (1)
D34: Function name | E34: {=Common_InputFunctions.Utility_DisplayFunctionName($E$47)} -> =MMS_Swine_LeachingAndRunoff_Equations.VEERG_4_5_1_7__1_AnnualEmissionsFromLeachingAndRunoffFromMMS
D37: Variable | E37: {=MMS_Swine_LeachingAndRunoff_Equations.VEERG_4_5_1_7__1_AnnualEmissionsFromLeachingAndRunoffFromMMS_Variable()} -> E_N2Oleach
D38: Unit | E38: {=MMS_Swine_LeachingAndRunoff_Equations.VEERG_4_5_1_7__1_AnnualEmissionsFromLeachingAndRunoffFromMMS_Unit()} -> t N2O
D40: {=MMS_Swine_LeachingAndRunoff_Equations.VEERG_4_5_1_7__1_AnnualEmissionsFromLeachingAndRunoffFromMMS_Arguments()} -> MNLeach_jm5 | E40: mass of N lost through leaching and runoff from drylot MMS (kg N) | G40: ="See " & D25 -> See M1_Table_MN_leach_j_m-5
D41: EF_leach | E41: emission factor for leaching and runoff (kg N2O-N/kg N) | G41: ='Constants - Common'!$E$170 -> 0.011
D42: C_N2O | E42: factor to convert elemental mass of N2O to molecular mass | G42: =Common_InputFunctions.Utility_LookupValueInTableNumber("N2O",Table_GasToMolecularConversionFactor[Gas],Table_GasToMolecularConversionFactor[Conversion factor combined]) -> 1.5714286
D44: M1_Table_E_N2O_leach | M44: M2_Table_E_N2O_leach
D45: Annual emissions from leaching and runoff (Method 1) | M45: Annual emissions from leaching and runoff (Method 2)
D46: Stage 1 management | E46: Boars | F46: Sows | G46: Gilts | H46: Others | M46: Stage 1 management | N46: Boars | O46: Sows | P46: Gilts | Q46: Others
D47: ='Input - Poultry'!$D$31 -> Manure stored in house | E47: {=MMS_Swine_LeachingAndRunoff_Equations.VEERG_4_5_1_7__1_AnnualEmissionsFromLeachingAndRunoffFromMMS(E28,$G$41,$G$42)} -> 0 | F47: {=MMS_Swine_LeachingAndRunoff_Equations.VEERG_4_5_1_7__1_AnnualEmissionsFromLeachingAndRunoffFromMMS(F28,$G$41,$G$42)} -> 0 | G47: {=MMS_Swine_LeachingAndRunoff_Equations.VEERG_4_5_1_7__1_AnnualEmissionsFromLeachingAndRunoffFromMMS(G28,$G$41,$G$42)} -> 0 | H47: {=MMS_Swine_LeachingAndRunoff_Equations.VEERG_4_5_1_7__1_AnnualEmissionsFromLeachingAndRunoffFromMMS(H28,$G$41,$G$42)} -> 0 | I47: =$E$38 -> t N2O | M47: ='Input - Poultry'!$D$31 -> Manure stored in house | N47: {=MMS_Swine_LeachingAndRunoff_Equations.VEERG_4_5_1_7__1_AnnualEmissionsFromLeachingAndRunoffFromMMS(N28,$G$41,$G$42)} -> 0 | O47: {=MMS_Swine_LeachingAndRunoff_Equations.VEERG_4_5_1_7__1_AnnualEmissionsFromLeachingAndRunoffFromMMS(O28,$G$41,$G$42)} -> 0 | P47: {=MMS_Swine_LeachingAndRunoff_Equations.VEERG_4_5_1_7__1_AnnualEmissionsFromLeachingAndRunoffFromMMS(P28,$G$41,$G$42)} -> 0 | Q47: {=MMS_Swine_LeachingAndRunoff_Equations.VEERG_4_5_1_7__1_AnnualEmissionsFromLeachingAndRunoffFromMMS(Q28,$G$41,$G$42)} -> 0 | R47: =$E$38 -> t N2O
D49: EN2O,leach | E49: =SUM(E47:H47) -> 0 | F49: =$E$38 -> t N2O | M49: EN2O,leach | N49: =SUM(N47:Q47) -> 0 | O49: =$E$38 -> t N2O
D51: {=Common_Equations.Common_ConvertN2OToCO2e_Arguments()} -> EN2O | E51: Nitrous oxide emissions (t N2O) | G51: =E49 -> 0 | M51: {=Common_Equations.Common_ConvertN2OToCO2e_Arguments()} -> EN2O | N51: Nitrous oxide emissions (t N2O) | P51: =N49 -> 0
D52: GWPN2O | E52: Global warming potential for nitrous oxide (t CO2-e / t N2O) | G52: =Common_InputFunctions.Utility_LookupValueInTableNumber("N2O",[2]!Table_GWPData[Gas],[2]!Table_GWPData[CO2-e factor]) -> 265 | M52: GWPN2O | N52: Global warming potential for nitrous oxide (t CO2-e / t N2O) | P52: =Common_InputFunctions.Utility_LookupValueInTableNumber("N2O",[2]!Table_GWPData[Gas],[2]!Table_GWPData[CO2-e factor]) -> 265
...

Sheet 4.5.1.9 Manure applied to soils
A1: #VALUE! | C1: 4.5.1.9 Manure applied to soils
A3: =HYPERLINK("#'Home'!A1", "Home") -> Home | D3: Method 1 | N3: Method 2
A4: =HYPERLINK("#'Results'!A1", "Results") -> Results
D5: {=MMS_Swine_ManureAppliedToSoils_Equations.VEERG_4_5_1_9__1_MassOfNitrogenAppliedToSoilsScope1_Title()} -> Mass of nitrogen applied to soils for scope 1 emissions
A6: INPUTS | D6: {=MMS_Swine_ManureAppliedToSoils_Equations.VEERG_4_5_1_9__1_MassOfNitrogenAppliedToSoilsScope1_Source()} -> VEERG 2026: 4.5.1.9, Equation (1)
A7: =HYPERLINK("#'Input - Site'!A1", "Site") -> Site | D7: Function name | E7: {=Common_InputFunctions.Utility_DisplayFunctionName(F115)} -> =MMS_Swine_ManureAppliedToSoils_Equations.VEERG_4_5_1_9__1_MassOfNitrogenAppliedToSoilsScope1
A8: =HYPERLINK("#'Input - Swine'!A1", "Swine") -> Swine
G9: MNleachjm=5 infers stage 1 and 2 drylot MMS
A10: CALCULATIONS | D10: Variable | E10: {=MMS_Swine_ManureAppliedToSoils_Equations.VEERG_4_5_1_9__1_MassOfNitrogenAppliedToSoilsScope1_Variable()} -> MNSoil_scope1 | G10: but 4.5.1.7, Equation (2) says MNleachjm=5 only comes from stage 1 MMS
A11: =HYPERLINK("#'4.5.1.1-2 Methane'!A1", "4.5.1.1-2 Methane") -> 4.5.1.1-2 Methane | D11: Unit | E11: {=MMS_Swine_ManureAppliedToSoils_Equations.VEERG_4_5_1_9__1_MassOfNitrogenAppliedToSoilsScope1_Unit()} -> kg N
A12: =HYPERLINK("#'4.5.1.3-4 Direct N20'!A1", "4.5.1.3-4 Direct N2O") -> 4.5.1.3-4 Direct N2O
A13: =HYPERLINK("#'4.5.1.5-6 Atmos Dep'!A1", "4.5.1.5-6 Soil atm. deposition") -> 4.5.1.5-6 Soil atm. deposition | D13: {=MMS_Swine_ManureAppliedToSoils_Equations.VEERG_4_5_1_9__1_MassOfNitrogenAppliedToSoilsScope1_Arguments()} -> MN_jmT2 | E13: mass of N in MMS at treatment stage 2 : kg N | H13: ="See " & D19 -> See M1_Table_MN_j_m_T-2
A14: =HYPERLINK("#'4.5.1.7-8 Leaching and runoff'!A1", "4.5.1.7-8 Leaching & runoff") -> 4.5.1.7-8 Leaching & runoff | D14: EF_mT2 | E14: nitrous oxide emission factor for each MMS at treatment stage 2 : kg N2O-N/kg N | H14: ="See " & D102 -> See Table_EF_m_T
A15: =HYPERLINK("#'4.5.1.9 Manure applied to soils'!A1", "4.5.1.9 Manure applied to soils") -> 4.5.1.9 Manure applied to soils | D15: FracGASM_mT2 | E15: fraction of animal waste N volatilised in each MMS at treatment stage 2 : (kg NH3-N + NOx-N)/kg N | H15: ="See " & D92 -> See Table_FracGASM_m_t
D16: MNLeach_jm5 | E16: mass of N lost to leaching and runoff from drylot MMS : kg N | H16: ="See " & D44 -> See M1_Table_MN_leach_j_m-5
A17: APPENDICES | D17: PF | E17: fraction of manure applied to soil within the piggery boundary : fraction | H17: ="See " & D68 -> See M1_Table_PF
A18: =HYPERLINK("#'Constants - Swine'!A1", "Constants - Swine") -> Constants - Swine
A19: =HYPERLINK("#'Constants - Livestock'!A1", "Constants - Livestock") -> Constants - Livestock | D19: M1_Table_MN_j_m_T-2 | N19: M2_Table_MN_j_m_T-2
A20: =HYPERLINK("#'Constants - Common'!A1", "Constants - Common") -> Constants - Common | D20: Nitrogen in stage 2 MMS (Method 1) | N20: Nitrogen in stage 2 MMS (Method 2)
A21: =HYPERLINK("#'Acknowledgements'!A1", "Acknowledgements") -> Acknowledgements | D21: Stage 1 management | E21: Stage 2 management | F21: Boars | G21: Sows | H21: Gilts | I21: Others | N21: Stage 1 management | O21: Stage 2 management | P21: Boars | Q21: Sows | R21: Gilts | S21: Others
D22: ='Input - Poultry'!$D$30 -> Belt manure removal | E22: ='Input - Poultry'!$D$38 -> Solid storage | F22: ='4.6.1.3-4 Direct N20'!F209 -> 0 | G22: ='4.6.1.3-4 Direct N20'!G209 -> 0 | H22: ='4.6.1.3-4 Direct N20'!H209 -> 0 | I22: ='4.6.1.3-4 Direct N20'!I209 -> 0 | J22: fraction | N22: ='Input - Poultry'!$D$30 -> Belt manure removal | O22: ='Input - Poultry'!$D$38 -> Solid storage | P22: ='4.6.1.3-4 Direct N20'!P209 -> 0 | Q22: ='4.6.1.3-4 Direct N20'!Q209 -> 0 | R22: ='4.6.1.3-4 Direct N20'!R209 -> 0 | S22: ='4.6.1.3-4 Direct N20'!S209 -> 0 | T22: fraction
E23: ='Input - Poultry'!$D$39 -> Composting (passive windrow) | F23: ='4.6.1.3-4 Direct N20'!F210 -> 0 | G23: ='4.6.1.3-4 Direct N20'!G210 -> 0 | H23: ='4.6.1.3-4 Direct N20'!H210 -> 0 | I23: ='4.6.1.3-4 Direct N20'!I210 -> 0 | J23: fraction | O23: ='Input - Poultry'!$D$39 -> Composting (passive windrow) | P23: ='4.6.1.3-4 Direct N20'!P210 -> 0 | Q23: ='4.6.1.3-4 Direct N20'!Q210 -> 0 | R23: ='4.6.1.3-4 Direct N20'!R210 -> 0 | S23: ='4.6.1.3-4 Direct N20'!S210 -> 0 | T23: fraction
E24: ='Input - Poultry'!$D$40 -> Digester / covered lagoons | F24: ='4.6.1.3-4 Direct N20'!F211 -> 0 | G24: ='4.6.1.3-4 Direct N20'!G211 -> 0 | H24: ='4.6.1.3-4 Direct N20'!H211 -> 0 | I24: ='4.6.1.3-4 Direct N20'!I211 -> 0 | J24: fraction | O24: ='Input - Poultry'!$D$40 -> Digester / covered lagoons | P24: ='4.6.1.3-4 Direct N20'!P211 -> 0 | Q24: ='4.6.1.3-4 Direct N20'!Q211 -> 0 | R24: ='4.6.1.3-4 Direct N20'!R211 -> 0 | S24: ='4.6.1.3-4 Direct N20'!S211 -> 0 | T24: fraction
D25: ='Input - Poultry'!$D$31 -> Manure stored in house | E25: ='Input - Poultry'!$D$45 -> Solid storage | F25: ='4.6.1.3-4 Direct N20'!F212 -> 0 | G25: ='4.6.1.3-4 Direct N20'!G212 -> 0 | H25: ='4.6.1.3-4 Direct N20'!H212 -> 0 | I25: ='4.6.1.3-4 Direct N20'!I212 -> 0 | J25: fraction | N25: ='Input - Poultry'!$D$31 -> Manure stored in house | O25: ='Input - Poultry'!$D$45 -> Solid storage | P25: ='4.6.1.3-4 Direct N20'!P212 -> 0 | Q25: ='4.6.1.3-4 Direct N20'!Q212 -> 0 | R25: ='4.6.1.3-4 Direct N20'!R212 -> 0 | S25: ='4.6.1.3-4 Direct N20'!S212 -> 0 | T25: fraction
E26: ='Input - Poultry'!$D$46 -> Composting (passive windrow) | F26: ='4.6.1.3-4 Direct N20'!F213 -> 0 | G26: ='4.6.1.3-4 Direct N20'!G213 -> 0 | H26: ='4.6.1.3-4 Direct N20'!H213 -> 0 | I26: ='4.6.1.3-4 Direct N20'!I213 -> 0 | J26: fraction | O26: ='Input - Poultry'!$D$46 -> Composting (passive windrow) | P26: ='4.6.1.3-4 Direct N20'!P213 -> 0 | Q26: ='4.6.1.3-4 Direct N20'!Q213 -> 0 | R26: ='4.6.1.3-4 Direct N20'!R213 -> 0 | S26: ='4.6.1.3-4 Direct N20'!S213 -> 0 | T26: fraction
