Workbook
Name Common_Equations.Common_ConvertCH4ToCO2e: _xlfn.LAMBDA(_xlpm.E_CH4,_xlpm.GWP_CH4, _xlpm.E_CH4 * _xlpm.GWP_CH4)
Name Common_Equations.Common_ConvertCH4ToCO2e_Arguments: _xlfn.LAMBDA(_xlfn.MAKEARRAY(2, 2, _xlfn.LAMBDA(_xlpm.r,_xlpm.c, INDEX({"ECH4","Methane emissions (t CH4)";"GWPCH4","Global warming potential for methane (t CO2-e / t CH4)"}, _xlpm.r, _xlpm.c))))
Name Common_Equations.Common_ConvertCH4ToCO2e_LatexEquation: _xlfn.LAMBDA("CO2_e = E_{CH4} \times GWP_{CH4}")
Name Common_Equations.Common_ConvertCH4ToCO2e_NIRReference: _xlfn.LAMBDA("")
Name Common_Equations.Common_ConvertCH4ToCO2e_Title: _xlfn.LAMBDA("Convert methane emissions to carbon dioxide equivalent emissions")
Name Common_Equations.Common_ConvertCH4ToCO2e_Unit: _xlfn.LAMBDA("t CO2e")
Name Common_Equations.Common_ConvertCH4ToCO2e_Variable: _xlfn.LAMBDA("ECH4 CO2e")
Name Common_Equations.Common_ConvertN2OToCO2e: _xlfn.LAMBDA(_xlpm.E_N2O,_xlpm.GWP_N2O, _xlpm.E_N2O * _xlpm.GWP_N2O)
Name Common_Equations.Common_ConvertN2OToCO2e_LatexEquation: _xlfn.LAMBDA("CO2_e = E_{N2O} \times GWP_{N2O}")
Name Common_Equations.Common_ConvertN2OToCO2e_NIRReference: _xlfn.LAMBDA("")
Name Common_Equations.Common_ConvertN2OToCO2e_Title: _xlfn.LAMBDA("Convert nitrous oxide emissions to carbon dioxide equivalent emissions")
Name Common_Equations.Common_ConvertN2OToCO2e_Unit: _xlfn.LAMBDA("t CO2e")
Name Common_Equations.Common_ConvertN2OToCO2e_Variable: _xlfn.LAMBDA("EN2O CO2e")
Name Common_InputFunctions.Utility_ConvertStateCommonNameToAbbreviation: _xlfn.LAMBDA(_xlpm.StateCommonName,_xlpm.StateCommonNameArray,_xlpm.StateAbbreviationArray, _xlfn.XLOOKUP(_xlpm.StateCommonName, _xlpm.StateCommonNameArray, _xlpm.StateAbbreviationArray, ""))
Name Common_InputFunctions.Utility_DisplayArguments_1_2: _xlfn.LAMBDA(_xlpm.ArgumentsArray, _xlfn.CHOOSECOLS(_xlpm.ArgumentsArray, 1, 2))
Name Common_InputFunctions.Utility_DisplayArguments_3_4: _xlfn.LAMBDA(_xlpm.ArgumentsArray, _xlfn.CHOOSECOLS(_xlpm.ArgumentsArray, 3, 4))
Name Common_InputFunctions.Utility_DisplayFunctionName: _xlfn.LAMBDA(_xlpm.Function, _xlfn.TEXTBEFORE(_xlfn.FORMULATEXT(_xlpm.Function), "("))
Name Common_InputFunctions.Utility_GetArrayTableColumnStartNumber: _xlfn.LAMBDA(_xlpm.TableHeaderCell, COLUMN(_xlpm.TableHeaderCell))
Name Common_InputFunctions.Utility_GetArrayTableRowStartNumber: _xlfn.LAMBDA(_xlpm.TableheaderCell,_xlpm.RowsBetweenHeaderandArray, ROW(_xlpm.TableheaderCell) + _xlpm.RowsBetweenHeaderandArray - 1)
Name Common_InputFunctions.Utility_LookupValueInTable: _xlfn.LAMBDA(_xlpm.LookupValue,_xlpm.LookupArray,_xlpm.ReturnArray, _xlfn.XLOOKUP(_xlpm.LookupValue, _xlpm.LookupArray, _xlpm.ReturnArray, ""))
Name Common_InputFunctions.Utility_SourceHyperlink: _xlfn.LAMBDA(_xlpm.TargetCell, _xlfn.LET(_xlpm.sh, _xlfn.TEXTAFTER(CELL("filename", _xlpm.TargetCell), "]"), _xlpm.addr, CELL("address", _xlpm.TargetCell), "#'" & _xlpm.sh & "'!" & _xlpm.addr))
Name Common_SourceData.Common_SourceData_AustralianStatesTerritories_Source: _xlfn.LAMBDA("")
Name Common_SourceData.Common_SourceData_AustralianStatesTerritories_Title: _xlfn.LAMBDA("Australian states and territories")
Name Common_SourceData.Common_SourceData_AustralianStatesTerritories_Unit: _xlfn.LAMBDA("")
Name Common_SourceData.Common_SourceData_AustralianStatesTerritories_Variable: _xlfn.LAMBDA("")
Name Common_SourceData.Common_SourceData_ClimateZones_Source: _xlfn.LAMBDA("VEERG 2026: Table 1.3: Climate and Rainfall zone classifications and definitions")
Name Common_SourceData.Common_SourceData_ClimateZones_Title: _xlfn.LAMBDA("VEERG Australian climate zones")
Name Common_SourceData.Common_SourceData_ClimateZones_Unit: _xlfn.LAMBDA("")
Name Common_SourceData.Common_SourceData_ClimateZones_Variable: _xlfn.LAMBDA("")
Name Common_SourceData.Common_SourceData_ConvertGasElementalToMolecular_Source: _xlfn.LAMBDA("XXXXXXX")
Name Common_SourceData.Common_SourceData_ConvertGasElementalToMolecular_Title: _xlfn.LAMBDA("Factor to convert elemental mass of gas to molecular mass")
Name Common_SourceData.Common_SourceData_ConvertGasElementalToMolecular_Unit: _xlfn.LAMBDA("factor")
Name Common_SourceData.Common_SourceData_ConvertGasElementalToMolecular_Variable: _xlfn.LAMBDA("Cg")
Name Common_SourceData.Common_SourceData_ConvertN2oElementalToMolecularCg_Data: _xlfn.LAMBDA(44 / 28)
Name Common_SourceData.Common_SourceData_ConvertN2oElementalToMolecularCg_Source: _xlfn.LAMBDA("National Inventory Report 2023 Volume 1")
Name Common_SourceData.Common_SourceData_ConvertN2oElementalToMolecularCg_Title: _xlfn.LAMBDA("Factor to convert elemental mass of N2O to molecular mass")
Name Common_SourceData.Common_SourceData_ConvertN2oElementalToMolecularCg_Unit: _xlfn.LAMBDA("factor")
Name Common_SourceData.Common_SourceData_ConvertN2oElementalToMolecularCg_Variable: _xlfn.LAMBDA("CgN2O")
Name Common_SourceData.Common_SourceData_DataScores_Scope3_Source: _xlfn.LAMBDA("VEERG 2026: XXXXXXXX")
Name Common_SourceData.Common_SourceData_DataScores_Scope3_Title: _xlfn.LAMBDA("Australian data scores for scope 3")
Name Common_SourceData.Common_SourceData_DataScores_Scope3_Unit: _xlfn.LAMBDA("")
Name Common_SourceData.Common_SourceData_DataScores_Scope3_Variable: _xlfn.LAMBDA("")
Name Common_SourceData.Common_SourceData_DataScores_Scope3_Variation: _xlfn.LAMBDA("")
Name Common_SourceData.Common_SourceData_DensityOfMethane_Data: _xlfn.LAMBDA(0.6784)
Name Common_SourceData.Common_SourceData_DensityOfMethane_Source: _xlfn.LAMBDA("National Inventory Report 2023 Volume 1: Equations 3.B.1a_2, 3.B.1c_2, 3.B.3_1, 3.B.4g_2")
Name Common_SourceData.Common_SourceData_DensityOfMethane_Title: _xlfn.LAMBDA("p = density of methane")
Name Common_SourceData.Common_SourceData_DensityOfMethane_Unit: _xlfn.LAMBDA("kg/m3")
Name Common_SourceData.Common_SourceData_EFleach_Data: _xlfn.LAMBDA(_xlfn.MAKEARRAY(1, 2, _xlfn.LAMBDA(_xlpm.r,_xlpm.c, INDEX({"EFleach",0.011}, _xlpm.r, _xlpm.c))))
Name Common_SourceData.Common_SourceData_EFleach_NIRReference: _xlfn.LAMBDA("National Inventory Report Volume 1: Equation 3.D.B_10")
Name Common_SourceData.Common_SourceData_EFleach_Source: _xlfn.LAMBDA("VEERG 2026:5.5.2.3 Constant Parameters")
Name Common_SourceData.Common_SourceData_EFleach_Title: _xlfn.LAMBDA("Emission factor for nitrogen leaching and runoff")
Name Common_SourceData.Common_SourceData_EFleach_Unit: _xlfn.LAMBDA("(kg N2O-N / kg N")
Name Common_SourceData.Common_SourceData_EFleach_Variation: _xlfn.LAMBDA((""))
Name Common_SourceData.Common_SourceData_EFN2O_NIRReference: _xlfn.LAMBDA("")
Name Common_SourceData.Common_SourceData_EFN2O_Source: _xlfn.LAMBDA("VEERG 2026: Table A.2.2.1")
Name Common_SourceData.Common_SourceData_EFN2O_Title: _xlfn.LAMBDA("Nitrous oxide emission factors for inorganic fertiliser application")
Name Common_SourceData.Common_SourceData_EFN2O_Unit: _xlfn.LAMBDA("(kg N2O-N / kg N")
Name Common_SourceData.Common_SourceData_EFOrganicFertiliserAndCropResidues_Data: _xlfn.LAMBDA(_xlfn.MAKEARRAY(3, 2, _xlfn.LAMBDA(_xlpm.r,_xlpm.c, INDEX({"Climate zone","EFNi & EFN2O";"Wet climate zone",0.006;"Dry climate zone",0.005}, _xlpm.r, _xlpm.c))))
Name Common_SourceData.Common_SourceData_EFOrganicFertiliserAndCropResidues_NIRReference: _xlfn.LAMBDA("")
Name Common_SourceData.Common_SourceData_EFOrganicFertiliserAndCropResidues_Source: _xlfn.LAMBDA("VEERG 2026: Table A.2.1.4")

Sheet Home
A1: Home

Sheet Overview
A1: #VALUE! | C1: 4.7 Manure management: Other Livestock: Overview
A3: =HYPERLINK("#'Home'!A1", "Home") -> Home
A4: =HYPERLINK("#'Overview'!A1", "Overview") -> Overview
A5: =HYPERLINK("#'Results'!A1", "Results") -> Results | D5: 💡 Below is a diagram that maps the equations used to calculate emissions, how they interact with each other and how they align with dairy manure management processes.
D6: Click on a box to go to the corresponding calculation.
A7: INPUTS
A8: =HYPERLINK("#'Input - Site'!A1", "Site") -> Site
A9: =HYPERLINK("#'Input - Other Livestock'!A1", "Other Livestock") -> Other Livestock
A11: CALCULATIONS
A12: =HYPERLINK("#'4.7.1.1-2 Manure Methane'!A1", "4.7.1.1-2 Methane") -> 4.7.1.1-2 Methane
A13: =HYPERLINK("#'4.7.1.3-4 Soil Direct N2O'!A1", "4.7.1.3-4 Soil Direct N2O") -> 4.7.1.3-4 Soil Direct N2O
A14: =HYPERLINK("#'4.7.1.5-6 Soil Atmos Deposition'!A1", "4.7.1.5-6 Soil Atmos deposition") -> 4.7.1.5-6 Soil Atmos deposition
A15: =HYPERLINK("#'4.7.1.7-8 Soil Leaching Runoff'!A1", "4.7.1.8-9 Soil Leaching & Runoff") -> 4.7.1.8-9 Soil Leaching & Runoff
A17: APPENDICES
A18: =HYPERLINK("#'Constants - Other Livestock'!A1", "Constants - Other Livestock") -> Constants - Other Livestock
A19: =HYPERLINK("#'Constants - Livestock'!A1", "Constants - Livestock") -> Constants - Livestock
A20: =HYPERLINK("#'Constants - Common'!A1", "Constants - Common") -> Constants - Common
A21: =HYPERLINK("#'Acknowledgements'!A1", "Acknowledgements") -> Acknowledgements

Sheet Results
A1: #VALUE! | C1: 4.7 Manure management: Other Livestock: Results
A3: =HYPERLINK("#'Home'!A1", "Home") -> Home
A4: =HYPERLINK("#'Overview'!A1", "Overview") -> Overview | D4: Emissions breakdown
A5: =HYPERLINK("#'Results'!A1", "Results") -> Results
D6: Scope 1 source | E6: GHG emissions method 1 | F6: GHG emissions method 2 | G6: GHG Unit | H6: CO2-e emissions method 1 | I6: CO2-e emissions method 2 | J6: CO2-e unit
A7: INPUTS | D7: 4.7.1.1-2 Method 1 Manure methane | E7: ='4.7.1.1-2 Manure Methane'!E113 -> 11.990348 | F7: ='4.7.1.1-2 Manure Methane'!O113 -> 12.103058 | G7: ='4.7.1.1-2 Manure Methane'!F113 -> t CH4 | H7: ='4.7.1.1-2 Manure Methane'!E118 -> 335.72975 | I7: ='4.7.1.1-2 Manure Methane'!O118 -> 338.88561 | J7: t CO2e
A8: =HYPERLINK("#'Input - Site'!A1", "Site") -> Site | D8: 4.7.1.3-4 Method 1 Soil direct N2O | E8: ='4.7.1.3-4 Soil Direct N2O'!E70 -> 519.12803 | F8: =E8 -> 519.12803 | G8: t N2O | H8: ='4.7.1.3-4 Soil Direct N2O'!E75 -> 137568.93 | I8: =H8 -> 137568.93 | J8: t CO2e
A9: =HYPERLINK("#'Input - Other Livestock'!A1", "Other Livestock") -> Other Livestock | D9: 4.7.1.5-6 Method 1 Soil atmospheric deposition | E9: ='4.7.1.5-6 Soil Atmos Deposition'!E81 -> 186.11705 | F9: =E9 -> 186.11705 | G9: t N2O | H9: ='4.7.1.5-6 Soil Atmos Deposition'!E86 -> 49321.019 | I9: =H9 -> 49321.019 | J9: t CO2e
D10: 4.7.1.7-8 Method 1 Soil atmospheric deposition | E10: ='4.7.1.7-8 Soil Leaching Runoff'!E72 -> 3.0587417 | F10: =E10 -> 3.0587417 | G10: t N2O | H10: ='4.7.1.7-8 Soil Leaching Runoff'!E77 -> 810.56655 | I10: =H10 -> 810.56655 | J10: t CO2e
A11: CALCULATIONS | D11: Total | H11: =SUM(H7:H10) -> 188036.24 | I11: =SUM(I7:I10) -> 188039.4 | J11: t CO2e
A12: =HYPERLINK("#'4.7.1.1-2 Manure Methane'!A1", "4.7.1.1-2 Methane") -> 4.7.1.1-2 Methane
A13: =HYPERLINK("#'4.7.1.3-4 Soil Direct N2O'!A1", "4.7.1.3-4 Soil Direct N2O") -> 4.7.1.3-4 Soil Direct N2O
A14: =HYPERLINK("#'4.7.1.5-6 Soil Atmos Deposition'!A1", "4.7.1.5-6 Soil Atmos deposition") -> 4.7.1.5-6 Soil Atmos deposition
A15: =HYPERLINK("#'4.7.1.7-8 Soil Leaching Runoff'!A1", "4.7.1.8-9 Soil Leaching & Runoff") -> 4.7.1.8-9 Soil Leaching & Runoff
A17: APPENDICES
A18: =HYPERLINK("#'Constants - Other Livestock'!A1", "Constants - Other Livestock") -> Constants - Other Livestock
A19: =HYPERLINK("#'Constants - Livestock'!A1", "Constants - Livestock") -> Constants - Livestock
A20: =HYPERLINK("#'Constants - Common'!A1", "Constants - Common") -> Constants - Common
A21: =HYPERLINK("#'Acknowledgements'!A1", "Acknowledgements") -> Acknowledgements

Sheet Input - Site
A1: #VALUE! | C1: Input - Site
A3: =HYPERLINK("#'Home'!A1", "Home") -> Home
A4: =HYPERLINK("#'Overview'!A1", "Overview") -> Overview
A5: =HYPERLINK("#'Results'!A1", "Results") -> Results | D5: Your business
A7: INPUTS | D7: Farm name | E7: Test Farms
A8: =HYPERLINK("#'Input - Site'!A1", "Site") -> Site | D8: Reporting entity name | E8: Test Farms Pty Ltd
A9: =HYPERLINK("#'Input - Other Livestock'!A1", "Other Livestock") -> Other Livestock
D10: 💡An 'Emissions accounting period' is a 12 month period where the business can report on the emissions, and is typically the same as the business' financial accounting period.
A11: CALCULATIONS
A12: =HYPERLINK("#'4.7.1.1-2 Manure Methane'!A1", "4.7.1.1-2 Methane") -> 4.7.1.1-2 Methane | D12: Emissions calculation period start date | E12: 45292 | F12: ← DD/MM/YYYY or DD Month YYYY
A13: =HYPERLINK("#'4.7.1.3-4 Soil Direct N2O'!A1", "4.7.1.3-4 Soil Direct N2O") -> 4.7.1.3-4 Soil Direct N2O | D13: Emissions calculation period end date | E13: =DATE(YEAR(E12)+1,MONTH(E12),DAY(E12))-1 -> 45657 | F13: ← Automatically calculated, 12 months after start date
A14: =HYPERLINK("#'4.7.1.5-6 Soil Atmos Deposition'!A1", "4.7.1.5-6 Soil Atmos deposition") -> 4.7.1.5-6 Soil Atmos deposition
A15: =HYPERLINK("#'4.7.1.7-8 Soil Leaching Runoff'!A1", "4.7.1.8-9 Soil Leaching & Runoff") -> 4.7.1.8-9 Soil Leaching & Runoff
D16: Location and climate
A17: APPENDICES
A18: =HYPERLINK("#'Constants - Other Livestock'!A1", "Constants - Other Livestock") -> Constants - Other Livestock | D18: Location information is used to reference some region and climate-specific emission factors
A19: =HYPERLINK("#'Constants - Livestock'!A1", "Constants - Livestock") -> Constants - Livestock | D19: Tip: Use the web-based GAF Location Helper tool to easily get region and climate information. You will need an internet connection to use the GAF Location Helper.
A20: =HYPERLINK("#'Constants - Common'!A1", "Constants - Common") -> Constants - Common
A21: =HYPERLINK("#'Acknowledgements'!A1", "Acknowledgements") -> Acknowledgements | D21: State | E21: New South Wales | F21: ← Please select
D22: Region (ABS Statistical area level 4) if state is WA | E22: Western Australia - Outback (South) | F22: ← Please select
D23: Leaching zone | E23: NO - Not in leaching zone | F23: ← Please select
D24: Elevation | E24: 307.7 | F24: Meters
D25: Average temperature for reporting period | E25: 18 | F25: Degrees celsius
D26: Total rainfall for reporting period | E26: 601 | F26: Millimetres
D27: Potential evapotranspiration for reporting period | E27: 1326 | F27: Millimetres
D28: Number of frost days for reporting period | E28: 7 | F28: Days
D29: MAP:PET ratio | E29: =E26/E27 -> 0.45324284
D30: Rainfall zone | E30: =Common_InputFunctions.Utility_LookupItemFromMinMax(E26,Table_SourceData_RainfallZones[Min rainfall],Table_SourceData_RainfallZones[Max rainfall],Table_SourceData_RainfallZones[Rainfall Zone]) -> High rainfall
D31: Climate zone | E31: =Common_InputFunctions.Utility_GetClimateZone(E25,E26,E28,E24,E29,Table_SourceData_ClimateZones[Min temp],Table_SourceData_ClimateZones[Max temp],Table_SourceData_ClimateZones[Min rainfall],Table_SourceData_ClimateZones[Max rainfall],Table_SourceData_ClimateZones[Min frost days],Table_SourceData_ClimateZones[Max frost days],Table_SourceData_ClimateZones[Min elevation],Table_SourceData_ClimateZones[Max elevation],Table_SourceData_ClimateZones[Min MAP:PET],Table_SourceData_ClimateZones[Max MAP:PET],Table_SourceData_ClimateZones[Climate zone]) -> Warm temperate dry
D32: Wet or dry climate zone | E32: =Common_InputFunctions.Utility_LookupValueInTable($E$31,Table_SourceData_WetDryZones[Climate zone],Table_SourceData_WetDryZones[Wet or Dry Zone]) -> Dry climate zone
D33: Temperature zone | E33: =Common_InputFunctions.Utility_LookupItemFromMinMax(E25,Table_SourceData_TemperatureZones[Min MAT],Table_SourceData_TemperatureZones[Max MAT],Table_SourceData_TemperatureZones[Temperature Zone]) -> Temperate

Sheet Input - Other Livestock
A1: #VALUE! | C1: Input - MMS - Other Livestock
A3: =HYPERLINK("#'Home'!A1", "Home") -> Home
A4: =HYPERLINK("#'Overview'!A1", "Overview") -> Overview
A5: =HYPERLINK("#'Results'!A1", "Results") -> Results | D5: Buffalo
A7: INPUTS | E7: Bulls | F7: Cows | G7: Steers | H7: Calves
A8: =HYPERLINK("#'Input - Site'!A1", "Site") -> Site | D8: ="Average number of head between " & TEXT('Input - Site'!$E$12, "dd mmm yy") & " and " & TEXT('Input - Site'!$E$13, "dd mmm yy") -> Average number of head between 01 Jan 24 and 31 Dec 24 | E8: 4300 | F8: 100 | G8: 100 | H8: 100 | I8: head
A9: =HYPERLINK("#'Input - Other Livestock'!A1", "Other Livestock") -> Other Livestock
D10: Are all dams and natural water sources fenced off so buffalo cannot access them? | E10: No | F10: ← Please select
A11: CALCULATIONS
A12: =HYPERLINK("#'4.7.1.1-2 Manure Methane'!A1", "4.7.1.1-2 Methane") -> 4.7.1.1-2 Methane | D12: Manure management system | E12: Percent in MMS
A13: =HYPERLINK("#'4.7.1.3-4 Soil Direct N2O'!A1", "4.7.1.3-4 Soil Direct N2O") -> 4.7.1.3-4 Soil Direct N2O | D13: Pasture range and paddock | E13: =IF($E$10="Yes", 1, Common_InputFunctions.Utility_LookupValueInTableNumber(Common_InputFunctions.Utility_ConvertStateCommonNameToAbbreviation('Input - Site'!$E$21, Table_AustralianStates[Common Name], Table_AustralianStates[Abbreviation]),Table_SourceData_OtherLivestock_FractionWasteInMMS[Other livestock type],Table_SourceData_OtherLivestock_FractionWasteInMMS[Pasture range and paddock]))/100 -> 0.9966 | F13: Percent
A14: =HYPERLINK("#'4.7.1.5-6 Soil Atmos Deposition'!A1", "4.7.1.5-6 Soil Atmos deposition") -> 4.7.1.5-6 Soil Atmos deposition | D14: Anaerobic lagoon | E14: =IF($E$10="Yes", 0, Common_InputFunctions.Utility_LookupValueInTableNumber(Common_InputFunctions.Utility_ConvertStateCommonNameToAbbreviation('Input - Site'!$E$21, Table_AustralianStates[Common Name], Table_AustralianStates[Abbreviation]),Table_SourceData_OtherLivestock_FractionWasteInMMS[Other livestock type],Table_SourceData_OtherLivestock_FractionWasteInMMS[Uncovered anaerobic lagoon]))/100 -> 0.0034 | F14: Percent
A15: =HYPERLINK("#'4.7.1.7-8 Soil Leaching Runoff'!A1", "4.7.1.8-9 Soil Leaching & Runoff") -> 4.7.1.8-9 Soil Leaching & Runoff
D16: Where did the buffalo spend most of their time grazing? | E16: Pasture | F16: ← Please select
A17: APPENDICES | E17: Not irrigated | F17: ← Please select
A18: =HYPERLINK("#'Constants - Other Livestock'!A1", "Constants - Other Livestock") -> Constants - Other Livestock
A19: =HYPERLINK("#'Constants - Livestock'!A1", "Constants - Livestock") -> Constants - Livestock | D19: Goats
A20: =HYPERLINK("#'Constants - Common'!A1", "Constants - Common") -> Constants - Common
A21: =HYPERLINK("#'Acknowledgements'!A1", "Acknowledgements") -> Acknowledgements | E21: Bucks / billy | F21: Wethers | G21: Maiden breeding does / nannies | H21: Breeding does / nannies | I21: Other | J21: Kids
D22: ="Average number of head between " & TEXT('Input - Site'!$E$12, "dd mmm yy") & " and " & TEXT('Input - Site'!$E$13, "dd mmm yy") -> Average number of head between 01 Jan 24 and 31 Dec 24 | E22: 4300 | F22: 100 | G22: 100 | H22: 100 | I22: 100 | J22: 100 | K22: head
D24: Are all dams and natural water sources fenced off so goats cannot access them? | E24: No | F24: ← Please select
D26: Manure management system | E26: Percent in MMS
D27: Pasture range and paddock | E27: =IF($E$24="Yes", 1, Common_InputFunctions.Utility_LookupValueInTableNumber(Common_InputFunctions.Utility_ConvertStateCommonNameToAbbreviation('Input - Site'!$E$21, Table_AustralianStates[Common Name], Table_AustralianStates[Abbreviation]),Table_SourceData_OtherLivestock_FractionWasteInMMS[Other livestock type],Table_SourceData_OtherLivestock_FractionWasteInMMS[Pasture range and paddock]))/100 -> 0.9966 | F27: Percent
D28: Anaerobic lagoon | E28: =IF($E$24="Yes", 0, Common_InputFunctions.Utility_LookupValueInTableNumber(Common_InputFunctions.Utility_ConvertStateCommonNameToAbbreviation('Input - Site'!$E$21, Table_AustralianStates[Common Name], Table_AustralianStates[Abbreviation]),Table_SourceData_OtherLivestock_FractionWasteInMMS[Other livestock type],Table_SourceData_OtherLivestock_FractionWasteInMMS[Uncovered anaerobic lagoon]))/100 -> 0.0034 | F28: Percent
D30: Where did the goats spend most of their time grazing? | E30: Pasture | F30: ← Please select
E31: Not irrigated | F31: ← Please select
D33: Deer
E35: Bucks | F35: Breeding does | G35: Other does | H35: Fawn
D36: ="Average number of head between " & TEXT('Input - Site'!$E$12, "dd mmm yy") & " and " & TEXT('Input - Site'!$E$13, "dd mmm yy") -> Average number of head between 01 Jan 24 and 31 Dec 24 | E36: 4300 | F36: 100 | G36: 100 | H36: 100 | I36: head
D38: Are all dams and natural water sources fenced off so deer cannot access them? | E38: No | F38: ← Please select
D40: Manure management system | E40: Percent in MMS
D41: Pasture range and paddock | E41: =IF($E$38="Yes", 1, Common_InputFunctions.Utility_LookupValueInTableNumber(Common_InputFunctions.Utility_ConvertStateCommonNameToAbbreviation('Input - Site'!$E$21, Table_AustralianStates[Common Name], Table_AustralianStates[Abbreviation]),Table_SourceData_OtherLivestock_FractionWasteInMMS[Other livestock type],Table_SourceData_OtherLivestock_FractionWasteInMMS[Pasture range and paddock]))/100 -> 0.9966 | F41: Percent
D42: Anaerobic lagoon | E42: =IF($E$38="Yes", 0, Common_InputFunctions.Utility_LookupValueInTableNumber(Common_InputFunctions.Utility_ConvertStateCommonNameToAbbreviation('Input - Site'!$E$21, Table_AustralianStates[Common Name], Table_AustralianStates[Abbreviation]),Table_SourceData_OtherLivestock_FractionWasteInMMS[Other livestock type],Table_SourceData_OtherLivestock_FractionWasteInMMS[Uncovered anaerobic lagoon]))/100 -> 0.0034 | F42: Percent
D44: Where did the deer spend most of their time grazing? | E44: Pasture | F44: ← Please select
E45: Not irrigated | F45: ← Please select
D47: Others
E49: Camels | F49: Alpacas | G49: Horses | H49: Mules / asses | I49: Emus / ostriches
D50: ="Average number of head between " & TEXT('Input - Site'!$E$12, "dd mmm yy") & " and " & TEXT('Input - Site'!$E$13, "dd mmm yy") -> Average number of head between 01 Jan 24 and 31 Dec 24 | E50: 4300 | F50: 100 | G50: 100 | H50: 100 | I50: 100 | J50: head
D52: Are all dams and natural water sources fenced off so livestock cannot access them? | E52: No | F52: No | G52: No | H52: No | I52: No | J52: ← Please select
D54: Manure management system | E54: Camels | F54: Alpacas | G54: Horses | H54: Mules / asses | I54: Emus / ostriches
...

Sheet 4.7.1.1-2 Manure Methane
A1: #VALUE! | C1: 4.7.1.1-2 Manure Methane
A3: =HYPERLINK("#'Home'!A1", "Home") -> Home | D3: Method 1 | N3: Method 2
A4: =HYPERLINK("#'Overview'!A1", "Overview") -> Overview
A5: =HYPERLINK("#'Results'!A1", "Results") -> Results | D5: {=MMS_OtherLivestock_Methane_Equations.VEERG_4_7_1_1__2_AnnualMethaneProductionFromManureManagement_Title()} -> Annual methane production from manure management
D6: {=MMS_OtherLivestock_Methane_Equations.VEERG_4_7_1_1__2_AnnualMethaneProductionFromManureManagement_Source()} -> VEERG 2026: 4.7.1.1, Equation (2)
A7: INPUTS | D7: Function name | E7: {=Common_InputFunctions.Utility_DisplayFunctionName(E65)} -> =MMS_OtherLivestock_Methane_Equations.VEERG_4_7_1_1__2_AnnualMethaneProductionFromManureManagement
A8: =HYPERLINK("#'Input - Site'!A1", "Site") -> Site
A9: =HYPERLINK("#'Input - Other Livestock'!A1", "Other Livestock") -> Other Livestock
D10: Variable | E10: {=MMS_OtherLivestock_Methane_Equations.VEERG_4_7_1_1__2_AnnualMethaneProductionFromManureManagement_Variable()} -> M_jm
A11: CALCULATIONS | D11: Unit | E11: {=MMS_OtherLivestock_Methane_Equations.VEERG_4_7_1_1__2_AnnualMethaneProductionFromManureManagement_Unit()} -> kg CH4/head/day
A12: =HYPERLINK("#'4.7.1.1-2 Manure Methane'!A1", "4.7.1.1-2 Methane") -> 4.7.1.1-2 Methane
A13: =HYPERLINK("#'4.7.1.3-4 Soil Direct N2O'!A1", "4.7.1.3-4 Soil Direct N2O") -> 4.7.1.3-4 Soil Direct N2O | D13: {=_xlfn.CHOOSECOLS(MMS_OtherLivestock_Methane_Equations.VEERG_4_7_1_1__2_AnnualMethaneProductionFromManureManagement_Arguments(),1,2)} -> VS_j | E13: volatile solid production | H13: {=_xlfn.CHOOSECOLS(MMS_OtherLivestock_Methane_Equations.VEERG_4_7_1_1__2_AnnualMethaneProductionFromManureManagement_Arguments(),3,4)} -> kg/head/day | I13: Constant | J13: {=HYPERLINK(Common_InputFunctions.Utility_SourceHyperlink($D$20),$D$20)} -> Table_VS_j | N13: {=_xlfn.CHOOSECOLS(MMS_OtherLivestock_Methane_Equations.VEERG_4_7_1_1__2_AnnualMethaneProductionFromManureManagement_Arguments_Method2(),1,2)} -> VS_j | O13: volatile solid production | R13: {=_xlfn.CHOOSECOLS(MMS_OtherLivestock_Methane_Equations.VEERG_4_7_1_1__2_AnnualMethaneProductionFromManureManagement_Arguments_Method2(),3,4)} -> kg/head/day | S13: Constant
A14: =HYPERLINK("#'4.7.1.5-6 Soil Atmos Deposition'!A1", "4.7.1.5-6 Soil Atmos deposition") -> 4.7.1.5-6 Soil Atmos deposition | D14: B_O | E14: methane emissions potential | H14: m3 CH4/kg VS | I14: Constant | J14: {=HYPERLINK(Common_InputFunctions.Utility_SourceHyperlink($D$32),$D$32)} -> Table_B_O | N14: B_O | O14: methane emissions potential | R14: m3 CH4/kg VS | S14: Constant
A15: =HYPERLINK("#'4.7.1.7-8 Soil Leaching Runoff'!A1", "4.7.1.8-9 Soil Leaching & Runoff") -> 4.7.1.8-9 Soil Leaching & Runoff | D15: MMS_m | E15: fraction of waste in each manure management system | H15: fraction | I15: Constant | J15: {=HYPERLINK(Common_InputFunctions.Utility_SourceHyperlink($D$44),D44)} -> Table_MMS_m | N15: MMS_m | O15: fraction of waste in each manure management system | R15: fraction | S15: Constant
D16: MCF_im | E16: methane conversion factor for state and manure management system | H16: fraction | I16: Constant | J16: {=HYPERLINK(Common_InputFunctions.Utility_SourceHyperlink($D$56),$D$56)} -> M1_Table_MCF_i_m | N16: MCF_im | O16: methane conversion factor for temperature zone and manure management system | R16: fraction | S16: Constant | T16: {=HYPERLINK(Common_InputFunctions.Utility_SourceHyperlink($N$56),$N$56)} -> M2_Table_MCF_i_m
A17: APPENDICES | D17: rho | E17: density of methane | H17: kg/m3 | I17: Constant | J17: ='Constants - Common'!$D$175 -> 0.6784 | N17: rho | O17: density of methane | R17: kg/m3 | S17: Constant
A18: =HYPERLINK("#'Constants - Other Livestock'!A1", "Constants - Other Livestock") -> Constants - Other Livestock | D18: i | E18: state | I18: Input | J18: =Common_InputFunctions.Utility_ConvertStateCommonNameToAbbreviation(X_Cell_Site_State,Table_AustralianStates[Common Name],Table_AustralianStates[Abbreviation]) -> NSW | N18: i | O18: mean annual temperature | R18: degrees Celsius | S18: Input | T18: =X_Cell_Site_AverageTemperature -> 18
A19: =HYPERLINK("#'Constants - Livestock'!A1", "Constants - Livestock") -> Constants - Livestock
A20: =HYPERLINK("#'Constants - Common'!A1", "Constants - Common") -> Constants - Common | D20: Table_VS_j
A21: =HYPERLINK("#'Acknowledgements'!A1", "Acknowledgements") -> Acknowledgements | D21: Volatile solid production
D22: Livestock type | E22: VSj
D23: ='Constants - Other Livestock'!D25 -> Buffalo | E23: ='Constants - Other Livestock'!E25 -> 2.73 | F23: =H13 -> kg/head/day
D24: ='Constants - Other Livestock'!D26 -> Goats | E24: ='Constants - Other Livestock'!E26 -> 0.34
D25: ='Constants - Other Livestock'!D27 -> Deer | E25: ='Constants - Other Livestock'!E27 -> 0.91
D26: ='Constants - Other Livestock'!D28 -> Camels | E26: ='Constants - Other Livestock'!E28 -> 2.73
D27: ='Constants - Other Livestock'!D29 -> Alpacas | E27: ='Constants - Other Livestock'!E29 -> 0.34
D28: ='Constants - Other Livestock'!D30 -> Horses | E28: ='Constants - Other Livestock'!E30 -> 2.73
D29: ='Constants - Other Livestock'!D31 -> Mules/asses | E29: ='Constants - Other Livestock'!E31 -> 0.91
D30: ='Constants - Other Livestock'!D32 -> Emus/ostriches | E30: ='Constants - Other Livestock'!E32 -> 0.34
D32: Table_B_O
D33: Methane emissions potential
D34: Livestock type | E34: BO
D35: ='Constants - Other Livestock'!D103 -> Buffalo | E35: ='Constants - Other Livestock'!E103 -> 0.19 | F35: =$H$14 -> m3 CH4/kg VS
D36: ='Constants - Other Livestock'!D104 -> Goats | E36: ='Constants - Other Livestock'!E104 -> 0.24
D37: ='Constants - Other Livestock'!D105 -> Deer | E37: ='Constants - Other Livestock'!E105 -> 0.24
D38: ='Constants - Other Livestock'!D106 -> Camels | E38: ='Constants - Other Livestock'!E106 -> 0.24
D39: ='Constants - Other Livestock'!D107 -> Alpacas | E39: ='Constants - Other Livestock'!E107 -> 0.24
D40: ='Constants - Other Livestock'!D108 -> Horses | E40: ='Constants - Other Livestock'!E108 -> 0.19
D41: ='Constants - Other Livestock'!D109 -> Mules/asses | E41: ='Constants - Other Livestock'!E109 -> 0.24
D42: ='Constants - Other Livestock'!D110 -> Emus/ostriches | E42: ='Constants - Other Livestock'!E110 -> 0.36
...

Sheet 4.7.1.3-4 Soil Direct N2O
A1: #VALUE! | C1: 4.7.1.3-4 Manure Soil Direct N2O
A3: =HYPERLINK("#'Home'!A1", "Home") -> Home | D3: Method 1 | N3: Method 2
A4: =HYPERLINK("#'Overview'!A1", "Overview") -> Overview
A5: =HYPERLINK("#'Results'!A1", "Results") -> Results | D5: {=MMS_OtherLivestock_Soil_N2ODirect.VEERG_4_7_1_3__2_AnnualNitrogenExcretedToPasture_Title()} -> Annual nitrogen excreted by livestock to pasture, range and paddock
D6: {=MMS_OtherLivestock_Soil_N2ODirect.VEERG_4_7_1_3__2_AnnualNitrogenExcretedToPasture_Source()} -> VEERG 2026: 4.7.1.3, Equation (2)
A7: INPUTS | D7: Function name | E7: {=Common_InputFunctions.Utility_DisplayFunctionName(E44)} -> =MMS_OtherLivestock_Soil_N2ODirect.VEERG_4_7_1_3__2_AnnualNitrogenExcretedToPasture
A8: =HYPERLINK("#'Input - Site'!A1", "Site") -> Site
A9: =HYPERLINK("#'Input - Other Livestock'!A1", "Other Livestock") -> Other Livestock
D10: Variable | E10: {=MMS_OtherLivestock_Soil_N2ODirect.VEERG_4_7_1_3__2_AnnualNitrogenExcretedToPasture_Variable()} -> AE
A11: CALCULATIONS | D11: Unit | E11: {=MMS_OtherLivestock_Soil_N2ODirect.VEERG_4_7_1_3__2_AnnualNitrogenExcretedToPasture_Unit()} -> kg N/year
A12: =HYPERLINK("#'4.7.1.1-2 Manure Methane'!A1", "4.7.1.1-2 Methane") -> 4.7.1.1-2 Methane
A13: =HYPERLINK("#'4.7.1.3-4 Soil Direct N2O'!A1", "4.7.1.3-4 Soil Direct N2O") -> 4.7.1.3-4 Soil Direct N2O | D13: {=_xlfn.CHOOSECOLS(MMS_OtherLivestock_Soil_N2ODirect.VEERG_4_7_1_3__2_AnnualNitrogenExcretedToPasture_Arguments(),1,2)} -> N_j | E13: number of livestock of each livestock type j | G13: {=_xlfn.CHOOSECOLS(MMS_OtherLivestock_Soil_N2ODirect.VEERG_4_7_1_3__2_AnnualNitrogenExcretedToPasture_Arguments(),3,4)} -> head | H13: Input | I13: {=HYPERLINK(Common_InputFunctions.Utility_SourceHyperlink($D$17),$D$17)} -> Table_N_j
A14: =HYPERLINK("#'4.7.1.5-6 Soil Atmos Deposition'!A1", "4.7.1.5-6 Soil Atmos deposition") -> 4.7.1.5-6 Soil Atmos deposition | D14: NE_j | E14: nitrogen excreted by each livestock type j | G14: kg N/head/day | H14: Constant | I14: {=HYPERLINK(Common_InputFunctions.Utility_SourceHyperlink($D$29),$D$29)} -> Table_NE_j
A15: =HYPERLINK("#'4.7.1.7-8 Soil Leaching Runoff'!A1", "4.7.1.8-9 Soil Leaching & Runoff") -> 4.7.1.8-9 Soil Leaching & Runoff | D15: j | E15: livestock type | H15: Input | I15: {=HYPERLINK(Common_InputFunctions.Utility_SourceHyperlink($D$17),$D$17)} -> Table_N_j
A17: APPENDICES | D17: Table_N_j
A18: =HYPERLINK("#'Constants - Other Livestock'!A1", "Constants - Other Livestock") -> Constants - Other Livestock | D18: Number of livestock
A19: =HYPERLINK("#'Constants - Livestock'!A1", "Constants - Livestock") -> Constants - Livestock | D19: Livestock type | E19: Nj
A20: =HYPERLINK("#'Constants - Common'!A1", "Constants - Common") -> Constants - Common | D20: Buffalo | E20: =SUM(X_Table_OtherLivestock_Buffalo_Head) -> 4600 | F20: =G13 -> head
A21: =HYPERLINK("#'Acknowledgements'!A1", "Acknowledgements") -> Acknowledgements | D21: Goats | E21: =SUM(X_Table_OtherLivestock_Goats_Head) -> 4800
D22: Deer | E22: =SUM(X_Table_OtherLivestock_Deer_Head) -> 4600
D23: Camels | E23: =X_Cell_OtherLivestock_Others_Camels_Head -> 4300
D24: Alpacas | E24: =X_Cell_OtherLivestock_Others_Alpacas_Head -> 100
D25: Horses | E25: =X_Cell_OtherLivestock_Others_Horses_Head -> 100
D26: Mules/asses | E26: =X_Cell_OtherLivestock_Others_Mules_Head -> 100
D27: Emus/ostriches | E27: =X_Cell_OtherLivestock_Others_Emus_Head -> 100
D29: Table_NE_j
D30: Nitrogen extreted per day
D31: Livestock type | E31: NEj
D32: ='Constants - Other Livestock'!D103 -> Buffalo | E32: {=Common_InputFunctions.Utility_LookupValueInTableNumber(D32,Table_SourceData_OtherLivestock_NitrogenExcreted[Other livestock type],Table_SourceData_OtherLivestock_NitrogenExcreted[NEj])} -> 39.5 | F32: =$G$14 -> kg N/head/day
D33: ='Constants - Other Livestock'!D104 -> Goats | E33: {=Common_InputFunctions.Utility_LookupValueInTableNumber(D33,Table_SourceData_OtherLivestock_NitrogenExcreted[Other livestock type],Table_SourceData_OtherLivestock_NitrogenExcreted[NEj])} -> 7
D34: ='Constants - Other Livestock'!D105 -> Deer | E34: {=Common_InputFunctions.Utility_LookupValueInTableNumber(D34,Table_SourceData_OtherLivestock_NitrogenExcreted[Other livestock type],Table_SourceData_OtherLivestock_NitrogenExcreted[NEj])} -> 13.2
D35: ='Constants - Other Livestock'!D106 -> Camels | E35: {=Common_InputFunctions.Utility_LookupValueInTableNumber(D35,Table_SourceData_OtherLivestock_NitrogenExcreted[Other livestock type],Table_SourceData_OtherLivestock_NitrogenExcreted[NEj])} -> 39.5
D36: ='Constants - Other Livestock'!D107 -> Alpacas | E36: {=Common_InputFunctions.Utility_LookupValueInTableNumber(D36,Table_SourceData_OtherLivestock_NitrogenExcreted[Other livestock type],Table_SourceData_OtherLivestock_NitrogenExcreted[NEj])} -> 7
D37: ='Constants - Other Livestock'!D108 -> Horses | E37: {=Common_InputFunctions.Utility_LookupValueInTableNumber(D37,Table_SourceData_OtherLivestock_NitrogenExcreted[Other livestock type],Table_SourceData_OtherLivestock_NitrogenExcreted[NEj])} -> 39.5
D38: ='Constants - Other Livestock'!D109 -> Mules/asses | E38: {=Common_InputFunctions.Utility_LookupValueInTableNumber(D38,Table_SourceData_OtherLivestock_NitrogenExcreted[Other livestock type],Table_SourceData_OtherLivestock_NitrogenExcreted[NEj])} -> 13.2
D39: ='Constants - Other Livestock'!D110 -> Emus/ostriches | E39: {=Common_InputFunctions.Utility_LookupValueInTableNumber(D39,Table_SourceData_OtherLivestock_NitrogenExcreted[Other livestock type],Table_SourceData_OtherLivestock_NitrogenExcreted[NEj])} -> 7
D41: Table_AEj
D42: Annual nitrogen excretion
D43: Livestock type | E43: AEj
D44: Buffalo | E44: {=MMS_OtherLivestock_Soil_N2ODirect.VEERG_4_7_1_3__2_AnnualNitrogenExcretedToPasture(E20,E32)} -> 66320500 | F44: =$E$11 -> kg N/year
...

Sheet 4.7.1.5-6 Soil Atmos Deposition
A1: #VALUE! | C1: 4.7.1.4-5 Manure Soil Atmospheric Deposition
A3: =HYPERLINK("#'Home'!A1", "Home") -> Home | D3: Method 1 | N3: Method 2
A4: =HYPERLINK("#'Overview'!A1", "Overview") -> Overview
A5: =HYPERLINK("#'Results'!A1", "Results") -> Results | D5: {=MMS_OtherLivestock_Soil_AtmosphericDeposition.VEERG_4_7_1_5__2_MassOfNitrogenVolatilisedFromPasture_Title()} -> Mass of nitrogen volatilised from urine and faeces deposited on pasture
D6: {=MMS_OtherLivestock_Soil_AtmosphericDeposition.VEERG_4_7_1_5__2_MassOfNitrogenVolatilisedFromPasture_Source()} -> VEERG 2026: 4.7.1.5, Equation (2)
A7: INPUTS | D7: Function name | E7: {=Common_InputFunctions.Utility_DisplayFunctionName(E31)} -> =MMS_OtherLivestock_Soil_AtmosphericDeposition.VEERG_4_7_1_5__2_MassOfNitrogenVolatilisedFromPasture
A8: =HYPERLINK("#'Input - Site'!A1", "Site") -> Site
A9: =HYPERLINK("#'Input - Other Livestock'!A1", "Other Livestock") -> Other Livestock
D10: Variable | E10: {=MMS_OtherLivestock_Soil_AtmosphericDeposition.VEERG_4_7_1_5__2_MassOfNitrogenVolatilisedFromPasture_Variable()} -> M_vol
A11: CALCULATIONS | D11: Unit | E11: {=MMS_OtherLivestock_Soil_AtmosphericDeposition.VEERG_4_7_1_5__2_MassOfNitrogenVolatilisedFromPasture_Unit()} -> kg N
A12: =HYPERLINK("#'4.7.1.1-2 Manure Methane'!A1", "4.7.1.1-2 Methane") -> 4.7.1.1-2 Methane
A13: =HYPERLINK("#'4.7.1.3-4 Soil Direct N2O'!A1", "4.7.1.3-4 Soil Direct N2O") -> 4.7.1.3-4 Soil Direct N2O | D13: {=_xlfn.CHOOSECOLS(MMS_OtherLivestock_Soil_AtmosphericDeposition.VEERG_4_7_1_5__2_MassOfNitrogenVolatilisedFromPasture_Arguments(),1,2)} -> AE | E13: annual nitrogen excreted by each livestock type | G13: {=_xlfn.CHOOSECOLS(MMS_OtherLivestock_Soil_AtmosphericDeposition.VEERG_4_7_1_5__2_MassOfNitrogenVolatilisedFromPasture_Arguments(),3,4)} -> kg N/year | H13: Calculated by 4.7.1.3, (2) | I13: {=HYPERLINK(Common_InputFunctions.Utility_SourceHyperlink($D$16),$D$16)} -> Table_AEj
A14: =HYPERLINK("#'4.7.1.5-6 Soil Atmos Deposition'!A1", "4.7.1.5-6 Soil Atmos deposition") -> 4.7.1.5-6 Soil Atmos deposition | D14: FracGASMsoil | E14: fraction of nitrogen volatilised from urine and faeces deposited on pasture | G14: (kg NH3-N + NOx-N)/kg N | H14: Constant | I14: ='Constants - Other Livestock'!E115 -> 0.21
A15: =HYPERLINK("#'4.7.1.7-8 Soil Leaching Runoff'!A1", "4.7.1.8-9 Soil Leaching & Runoff") -> 4.7.1.8-9 Soil Leaching & Runoff
D16: Table_AEj
A17: APPENDICES | D17: Annual nitrogen excretion
A18: =HYPERLINK("#'Constants - Other Livestock'!A1", "Constants - Other Livestock") -> Constants - Other Livestock | D18: Livestock type | E18: AEj
A19: =HYPERLINK("#'Constants - Livestock'!A1", "Constants - Livestock") -> Constants - Livestock | D19: Buffalo | E19: =INDEX(Table_AEj,2,2) -> 66320500 | F19: ='4.7.1.3-4 Soil Direct N2O'!$F$44 -> kg N/year
A20: =HYPERLINK("#'Constants - Common'!A1", "Constants - Common") -> Constants - Common | D20: Goats | E20: =INDEX(Table_AEj,3,2) -> 12264000
A21: =HYPERLINK("#'Acknowledgements'!A1", "Acknowledgements") -> Acknowledgements | D21: Deer | E21: =INDEX(Table_AEj,4,2) -> 22162800
D22: Camels | E22: =INDEX(Table_AEj,5,2) -> 61995250
D23: Alpacas | E23: =INDEX(Table_AEj,6,2) -> 255500
D24: Horses | E24: =INDEX(Table_AEj,7,2) -> 1441750
D25: Mules/asses | E25: =INDEX(Table_AEj,8,2) -> 481800
D26: Emus/ostriches | E26: =INDEX(Table_AEj,9,2) -> 255500
D28: Table_M_vol
D29: Annual nitrogen excretion
D30: Livestock type | E30: Mvol
D31: Buffalo | E31: {=MMS_OtherLivestock_Soil_AtmosphericDeposition.VEERG_4_7_1_5__2_MassOfNitrogenVolatilisedFromPasture(E19,$I$14)} -> 13927305 | F31: ='4.7.1.3-4 Soil Direct N2O'!$F$44 -> kg N/year
D32: Goats | E32: {=MMS_OtherLivestock_Soil_AtmosphericDeposition.VEERG_4_7_1_5__2_MassOfNitrogenVolatilisedFromPasture(E20,$I$14)} -> 2575440
D33: Deer | E33: {=MMS_OtherLivestock_Soil_AtmosphericDeposition.VEERG_4_7_1_5__2_MassOfNitrogenVolatilisedFromPasture(E21,$I$14)} -> 4654188
D34: Camels | E34: {=MMS_OtherLivestock_Soil_AtmosphericDeposition.VEERG_4_7_1_5__2_MassOfNitrogenVolatilisedFromPasture(E22,$I$14)} -> 13019002
D35: Alpacas | E35: {=MMS_OtherLivestock_Soil_AtmosphericDeposition.VEERG_4_7_1_5__2_MassOfNitrogenVolatilisedFromPasture(E23,$I$14)} -> 53655
D36: Horses | E36: {=MMS_OtherLivestock_Soil_AtmosphericDeposition.VEERG_4_7_1_5__2_MassOfNitrogenVolatilisedFromPasture(E24,$I$14)} -> 302767.5
D37: Mules/asses | E37: {=MMS_OtherLivestock_Soil_AtmosphericDeposition.VEERG_4_7_1_5__2_MassOfNitrogenVolatilisedFromPasture(E25,$I$14)} -> 101178
D38: Emus/ostriches | E38: {=MMS_OtherLivestock_Soil_AtmosphericDeposition.VEERG_4_7_1_5__2_MassOfNitrogenVolatilisedFromPasture(E26,$I$14)} -> 53655
D42: {=MMS_OtherLivestock_Soil_AtmosphericDeposition.VEERG_4_7_1_5__1_AtmosphericDepositionEmissionsFromPasture_Title()} -> Atmospheric deposition emissions from urine and dung deposited on pasture
D43: {=MMS_OtherLivestock_Soil_AtmosphericDeposition.VEERG_4_7_1_5__1_AtmosphericDepositionEmissionsFromPasture_Source()} -> VEERG 2026: 4.7.1.5, Equation (1)
D44: Function name | E44: {=Common_InputFunctions.Utility_DisplayFunctionName(E72)} -> =MMS_OtherLivestock_Soil_AtmosphericDeposition.VEERG_4_7_1_5__1_AtmosphericDepositionEmissionsFromPasture
D47: Variable | E47: {=MMS_OtherLivestock_Soil_AtmosphericDeposition.VEERG_4_7_1_5__1_AtmosphericDepositionEmissionsFromPasture_Variable()} -> E_N2Oad
...

Sheet 4.7.1.7-8 Soil Leaching Runoff
A1: #VALUE! | C1: 4.7.1.7-8 Manure Soil Leaching and Runoff
A3: =HYPERLINK("#'Home'!A1", "Home") -> Home | D3: Method 1 | N3: Method 2
A4: =HYPERLINK("#'Overview'!A1", "Overview") -> Overview
A5: =HYPERLINK("#'Results'!A1", "Results") -> Results | D5: {=MMS_OtherLivestock_Soil_LeachingAndRunoff.VEERG_4_7_1_7__2_MassOfNitrogenLostToLeachingAndRunoff_Title()} -> Mass of nitrogen lost to leaching and runoff
D6: {=MMS_OtherLivestock_Soil_LeachingAndRunoff.VEERG_4_7_1_7__2_MassOfNitrogenLostToLeachingAndRunoff_Source()} -> VEERG 2026: 4.7.1.7, Equation (2)
A7: INPUTS | D7: Function name | E7: {=Common_InputFunctions.Utility_DisplayFunctionName(E47)} -> =MMS_OtherLivestock_Soil_LeachingAndRunoff.VEERG_4_7_1_7__2_MassOfNitrogenLostToLeachingAndRunoff
A8: =HYPERLINK("#'Input - Site'!A1", "Site") -> Site
A9: =HYPERLINK("#'Input - Other Livestock'!A1", "Other Livestock") -> Other Livestock
D10: Variable | E10: {=MMS_OtherLivestock_Soil_LeachingAndRunoff.VEERG_4_7_1_7__2_MassOfNitrogenLostToLeachingAndRunoff_Variable()} -> M_leach
A11: CALCULATIONS | D11: Unit | E11: {=MMS_OtherLivestock_Soil_LeachingAndRunoff.VEERG_4_7_1_7__2_MassOfNitrogenLostToLeachingAndRunoff_Unit()} -> kg N
A12: =HYPERLINK("#'4.7.1.1-2 Manure Methane'!A1", "4.7.1.1-2 Methane") -> 4.7.1.1-2 Methane
A13: =HYPERLINK("#'4.7.1.3-4 Soil Direct N2O'!A1", "4.7.1.3-4 Soil Direct N2O") -> 4.7.1.3-4 Soil Direct N2O | D13: {=_xlfn.CHOOSECOLS(MMS_OtherLivestock_Soil_LeachingAndRunoff.VEERG_4_7_1_7__2_MassOfNitrogenLostToLeachingAndRunoff_Arguments(),1,2)} -> AE | E13: annual nitrogen excreted by each livestock type | G13: {=_xlfn.CHOOSECOLS(MMS_OtherLivestock_Soil_LeachingAndRunoff.VEERG_4_7_1_7__2_MassOfNitrogenLostToLeachingAndRunoff_Arguments(),3,4)} -> kg N/year | H13: Calculated by 4.7.1.3, (2) | I13: {=HYPERLINK(Common_InputFunctions.Utility_SourceHyperlink($D$20),$D$20)} -> Table_AEj
A14: =HYPERLINK("#'4.7.1.5-6 Soil Atmos Deposition'!A1", "4.7.1.5-6 Soil Atmos deposition") -> 4.7.1.5-6 Soil Atmos deposition | D14: FracWet | E14: fraction of nitrogen available for leaching and runoff | H14: Constant | I14: {=HYPERLINK(Common_InputFunctions.Utility_SourceHyperlink($D$32),$D$32)} -> Table_Frac_Wet
A15: =HYPERLINK("#'4.7.1.7-8 Soil Leaching Runoff'!A1", "4.7.1.8-9 Soil Leaching & Runoff") -> 4.7.1.8-9 Soil Leaching & Runoff | D15: FracLEACH | E15: fraction of all nitrogen that is lost through leaching and runoff | H15: Constant | I15: ='Constants - Common'!$E$164 -> 0.24
D16: z | E16: location in leaching zone | H16: Input | I16: =X_Cell_Site_LeachingZone -> NO - Not in leaching zone
A17: APPENDICES | D17: j | E17: production system | H17: Input | I17: {=HYPERLINK(Common_InputFunctions.Utility_SourceHyperlink($D$32),$D$32)} -> Table_Frac_Wet
A18: =HYPERLINK("#'Constants - Other Livestock'!A1", "Constants - Other Livestock") -> Constants - Other Livestock | D18: ir | E18: irrigation method | H18: Input | I18: {=HYPERLINK(Common_InputFunctions.Utility_SourceHyperlink($D$32),$D$32)} -> Table_Frac_Wet
A19: =HYPERLINK("#'Constants - Livestock'!A1", "Constants - Livestock") -> Constants - Livestock
A20: =HYPERLINK("#'Constants - Common'!A1", "Constants - Common") -> Constants - Common | D20: Table_AEj
A21: =HYPERLINK("#'Acknowledgements'!A1", "Acknowledgements") -> Acknowledgements | D21: Annual nitrogen excretion
D22: Livestock type | E22: AEj
D23: Buffalo | E23: =INDEX(Table_AEj,2,2) -> 66320500 | F23: ='4.7.1.3-4 Soil Direct N2O'!$F$44 -> kg N/year
D24: Goats | E24: =INDEX(Table_AEj,3,2) -> 12264000
D25: Deer | E25: =INDEX(Table_AEj,4,2) -> 22162800
D26: Camels | E26: =INDEX(Table_AEj,5,2) -> 61995250
D27: Alpacas | E27: =INDEX(Table_AEj,6,2) -> 255500
D28: Horses | E28: =INDEX(Table_AEj,7,2) -> 1441750
D29: Mules/asses | E29: =INDEX(Table_AEj,8,2) -> 481800
D30: Emus/ostriches | E30: =INDEX(Table_AEj,9,2) -> 255500
D32: Table_Frac_Wet
D33: Fraction of nitrogen available for leaching and runoff
D34: Livestock type | E34: Production system | F34: Irrigation method | G34: FracWet
D35: Buffalo | E35: =X_Cell_OtherLivestock_Buffalo_GrazingProductionSystem -> Pasture | F35: =X_Cell_OtherLivestock_Buffalo_GrazingIrrigationMethod -> Not irrigated | G35: =Common_InputFunctions.CommonCropping_GetFracWET($I$16,F35,#REF!,#REF!,Table_SourceData_FracWETIrrigation[Irrigation type i],Table_SourceData_FracWETIrrigation[FracWET]) -> 0
D36: Goats | E36: =X_Cell_OtherLivestock_Goats_GrazingProductionSystem -> Pasture | F36: =X_Cell_OtherLivestock_Goats_GrazingIrrigationMethod -> Not irrigated | G36: =Common_InputFunctions.CommonCropping_GetFracWET($I$16,F36,#REF!,#REF!,Table_SourceData_FracWETIrrigation[Irrigation type i],Table_SourceData_FracWETIrrigation[FracWET]) -> 0
D37: Deer | E37: =X_Cell_OtherLivestock_Deer_GrazingProductionSystem -> Pasture | F37: =X_Cell_OtherLivestock_Deer_GrazingIrrigationMethod -> Not irrigated | G37: =Common_InputFunctions.CommonCropping_GetFracWET($I$16,F37,#REF!,#REF!,Table_SourceData_FracWETIrrigation[Irrigation type i],Table_SourceData_FracWETIrrigation[FracWET]) -> 0
D38: Camels | E38: =X_Cell_OtherLivestock_Others_Camels_GrazingProductionSystem -> Pasture | F38: =X_Cell_OtherLivestock_Others_Camels_GrazingIrrigationMethod -> Drip irrigation | G38: =Common_InputFunctions.CommonCropping_GetFracWET($I$16,F38,#REF!,#REF!,Table_SourceData_FracWETIrrigation[Irrigation type i],Table_SourceData_FracWETIrrigation[FracWET]) -> 0
D39: Alpacas | E39: =X_Cell_OtherLivestock_Others_Alpacas_GrazingProductionSystem -> Pasture | F39: =X_Cell_OtherLivestock_Others_Alpacas_GrazingIrrigationMethod -> Sprinkler irrigation | G39: =Common_InputFunctions.CommonCropping_GetFracWET($I$16,F39,#REF!,#REF!,Table_SourceData_FracWETIrrigation[Irrigation type i],Table_SourceData_FracWETIrrigation[FracWET]) -> 1
D40: Horses | E40: =X_Cell_OtherLivestock_Others_Horses_GrazingProductionSystem -> Crop | F40: =X_Cell_OtherLivestock_Others_Horses_GrazingIrrigationMethod -> Not irrigated | G40: =Common_InputFunctions.CommonCropping_GetFracWET($I$16,F40,#REF!,#REF!,Table_SourceData_FracWETIrrigation[Irrigation type i],Table_SourceData_FracWETIrrigation[FracWET]) -> 0
D41: Mules/asses | E41: =X_Cell_OtherLivestock_Others_Mules_GrazingProductionSystem -> Crop | F41: =X_Cell_OtherLivestock_Others_Mules_GrazingIrrigationMethod -> Surface irrigation | G41: =Common_InputFunctions.CommonCropping_GetFracWET($I$16,F41,#REF!,#REF!,Table_SourceData_FracWETIrrigation[Irrigation type i],Table_SourceData_FracWETIrrigation[FracWET]) -> 1
D42: Emus/ostriches | E42: =X_Cell_OtherLivestock_Others_Emus_GrazingProductionSystem -> Pasture | F42: =X_Cell_OtherLivestock_Others_Emus_GrazingIrrigationMethod -> Not irrigated | G42: =Common_InputFunctions.CommonCropping_GetFracWET($I$16,F42,#REF!,#REF!,Table_SourceData_FracWETIrrigation[Irrigation type i],Table_SourceData_FracWETIrrigation[FracWET]) -> 0
...

Sheet Constants - Other Livestock
A1: #VALUE! | C1: Source Data - Other Livestock
A3: =HYPERLINK("#'Home'!A1", "Home") -> Home
A4: =HYPERLINK("#'Overview'!A1", "Overview") -> Overview
A5: =HYPERLINK("#'Results'!A1", "Results") -> Results | D5: {=SourceData_OtherLivestock.SourceData_OtherLivestock_EntericFermentationEmissionFactor_Title()} -> Other Livestock - Enteric fermentation emission factor for each other livestock type
D6: {=SourceData_OtherLivestock.SourceData_OtherLivestock_EntericFermentationEmissionFactor_Source()} -> VEERG 2026: Table A.1.5.1
A7: INPUTS | D7: {=SourceData_OtherLivestock.SourceData_OtherLivestock_EntericFermentationEmissionFactor_Variable()} -> Mj
A8: =HYPERLINK("#'Input - Site'!A1", "Site") -> Site | D8: {=SourceData_OtherLivestock.SourceData_OtherLivestock_EntericFermentationEmissionFactor_Unit()} -> kg CH4 / head / year
A9: =HYPERLINK("#'Input - Other Livestock'!A1", "Other Livestock") -> Other Livestock | D9: Other livestock type | E9: Mj
D10: {=Common_InputFunctions.Utility_DisplayArrayInTable(SourceData_OtherLivestock.SourceData_OtherLivestock_EntericFermentationEmissionFactor_Data(),Table_SourceData_OtherLivestock_EntericEF[[#Headers],[Other livestock type]],0)} -> Buffalo | E10: {=Common_InputFunctions.Utility_DisplayArrayInTable(SourceData_OtherLivestock.SourceData_OtherLivestock_EntericFermentationEmissionFactor_Data(),Table_SourceData_OtherLivestock_EntericEF[[#Headers],[Other livestock type]],0)} -> 68
A11: CALCULATIONS | D11: {=Common_InputFunctions.Utility_DisplayArrayInTable(SourceData_OtherLivestock.SourceData_OtherLivestock_EntericFermentationEmissionFactor_Data(),Table_SourceData_OtherLivestock_EntericEF[[#Headers],[Other livestock type]],0)} -> Goats | E11: {=Common_InputFunctions.Utility_DisplayArrayInTable(SourceData_OtherLivestock.SourceData_OtherLivestock_EntericFermentationEmissionFactor_Data(),Table_SourceData_OtherLivestock_EntericEF[[#Headers],[Other livestock type]],0)} -> 5
A12: =HYPERLINK("#'4.7.1.1-2 Manure Methane'!A1", "4.7.1.1-2 Methane") -> 4.7.1.1-2 Methane | D12: {=Common_InputFunctions.Utility_DisplayArrayInTable(SourceData_OtherLivestock.SourceData_OtherLivestock_EntericFermentationEmissionFactor_Data(),Table_SourceData_OtherLivestock_EntericEF[[#Headers],[Other livestock type]],0)} -> Deer | E12: {=Common_InputFunctions.Utility_DisplayArrayInTable(SourceData_OtherLivestock.SourceData_OtherLivestock_EntericFermentationEmissionFactor_Data(),Table_SourceData_OtherLivestock_EntericEF[[#Headers],[Other livestock type]],0)} -> 20
A13: =HYPERLINK("#'4.7.1.3-4 Soil Direct N2O'!A1", "4.7.1.3-4 Soil Direct N2O") -> 4.7.1.3-4 Soil Direct N2O | D13: {=Common_InputFunctions.Utility_DisplayArrayInTable(SourceData_OtherLivestock.SourceData_OtherLivestock_EntericFermentationEmissionFactor_Data(),Table_SourceData_OtherLivestock_EntericEF[[#Headers],[Other livestock type]],0)} -> Camels | E13: {=Common_InputFunctions.Utility_DisplayArrayInTable(SourceData_OtherLivestock.SourceData_OtherLivestock_EntericFermentationEmissionFactor_Data(),Table_SourceData_OtherLivestock_EntericEF[[#Headers],[Other livestock type]],0)} -> 46
A14: =HYPERLINK("#'4.7.1.5-6 Soil Atmos Deposition'!A1", "4.7.1.5-6 Soil Atmos deposition") -> 4.7.1.5-6 Soil Atmos deposition | D14: {=Common_InputFunctions.Utility_DisplayArrayInTable(SourceData_OtherLivestock.SourceData_OtherLivestock_EntericFermentationEmissionFactor_Data(),Table_SourceData_OtherLivestock_EntericEF[[#Headers],[Other livestock type]],0)} -> Alpacas | E14: {=Common_InputFunctions.Utility_DisplayArrayInTable(SourceData_OtherLivestock.SourceData_OtherLivestock_EntericFermentationEmissionFactor_Data(),Table_SourceData_OtherLivestock_EntericEF[[#Headers],[Other livestock type]],0)} -> 8
A15: =HYPERLINK("#'4.7.1.7-8 Soil Leaching Runoff'!A1", "4.7.1.8-9 Soil Leaching & Runoff") -> 4.7.1.8-9 Soil Leaching & Runoff | D15: {=Common_InputFunctions.Utility_DisplayArrayInTable(SourceData_OtherLivestock.SourceData_OtherLivestock_EntericFermentationEmissionFactor_Data(),Table_SourceData_OtherLivestock_EntericEF[[#Headers],[Other livestock type]],0)} -> Horses | E15: {=Common_InputFunctions.Utility_DisplayArrayInTable(SourceData_OtherLivestock.SourceData_OtherLivestock_EntericFermentationEmissionFactor_Data(),Table_SourceData_OtherLivestock_EntericEF[[#Headers],[Other livestock type]],0)} -> 18
D16: {=Common_InputFunctions.Utility_DisplayArrayInTable(SourceData_OtherLivestock.SourceData_OtherLivestock_EntericFermentationEmissionFactor_Data(),Table_SourceData_OtherLivestock_EntericEF[[#Headers],[Other livestock type]],0)} -> Mules/asses | E16: {=Common_InputFunctions.Utility_DisplayArrayInTable(SourceData_OtherLivestock.SourceData_OtherLivestock_EntericFermentationEmissionFactor_Data(),Table_SourceData_OtherLivestock_EntericEF[[#Headers],[Other livestock type]],0)} -> 10
A17: APPENDICES | D17: {=Common_InputFunctions.Utility_DisplayArrayInTable(SourceData_OtherLivestock.SourceData_OtherLivestock_EntericFermentationEmissionFactor_Data(),Table_SourceData_OtherLivestock_EntericEF[[#Headers],[Other livestock type]],0)} -> Emus/ostriches | E17: {=Common_InputFunctions.Utility_DisplayArrayInTable(SourceData_OtherLivestock.SourceData_OtherLivestock_EntericFermentationEmissionFactor_Data(),Table_SourceData_OtherLivestock_EntericEF[[#Headers],[Other livestock type]],0)} -> 5
A18: =HYPERLINK("#'Constants - Other Livestock'!A1", "Constants - Other Livestock") -> Constants - Other Livestock
A19: =HYPERLINK("#'Constants - Livestock'!A1", "Constants - Livestock") -> Constants - Livestock
A20: =HYPERLINK("#'Constants - Common'!A1", "Constants - Common") -> Constants - Common | D20: {=SourceData_OtherLivestock.SourceData_OtherLivestock_VolatileSolidsProduced_Title()} -> Other Livestock - Volatile solids produced by each other livestock type
A21: =HYPERLINK("#'Acknowledgements'!A1", "Acknowledgements") -> Acknowledgements | D21: {=SourceData_OtherLivestock.SourceData_OtherLivestock_VolatileSolidsProduced_Source()} -> VEERG 2026: Table A.1.5.2
D22: {=SourceData_OtherLivestock.SourceData_OtherLivestock_VolatileSolidsProduced_Variable()} -> VSj
D23: {=SourceData_OtherLivestock.SourceData_OtherLivestock_VolatileSolidsProduced_Unit()} -> kg VS / head / day
D24: Other livestock type | E24: VSj
D25: {=Common_InputFunctions.Utility_DisplayArrayInTable(SourceData_OtherLivestock.SourceData_OtherLivestock_VolatileSolidsProduced_Data(),Table_SourceData_OtherLivestock_VolatileSolids[[#Headers],[Other livestock type]],0)} -> Buffalo | E25: {=Common_InputFunctions.Utility_DisplayArrayInTable(SourceData_OtherLivestock.SourceData_OtherLivestock_VolatileSolidsProduced_Data(),Table_SourceData_OtherLivestock_VolatileSolids[[#Headers],[Other livestock type]],0)} -> 2.73
D26: {=Common_InputFunctions.Utility_DisplayArrayInTable(SourceData_OtherLivestock.SourceData_OtherLivestock_VolatileSolidsProduced_Data(),Table_SourceData_OtherLivestock_VolatileSolids[[#Headers],[Other livestock type]],0)} -> Goats | E26: {=Common_InputFunctions.Utility_DisplayArrayInTable(SourceData_OtherLivestock.SourceData_OtherLivestock_VolatileSolidsProduced_Data(),Table_SourceData_OtherLivestock_VolatileSolids[[#Headers],[Other livestock type]],0)} -> 0.34
D27: {=Common_InputFunctions.Utility_DisplayArrayInTable(SourceData_OtherLivestock.SourceData_OtherLivestock_VolatileSolidsProduced_Data(),Table_SourceData_OtherLivestock_VolatileSolids[[#Headers],[Other livestock type]],0)} -> Deer | E27: {=Common_InputFunctions.Utility_DisplayArrayInTable(SourceData_OtherLivestock.SourceData_OtherLivestock_VolatileSolidsProduced_Data(),Table_SourceData_OtherLivestock_VolatileSolids[[#Headers],[Other livestock type]],0)} -> 0.91
D28: {=Common_InputFunctions.Utility_DisplayArrayInTable(SourceData_OtherLivestock.SourceData_OtherLivestock_VolatileSolidsProduced_Data(),Table_SourceData_OtherLivestock_VolatileSolids[[#Headers],[Other livestock type]],0)} -> Camels | E28: {=Common_InputFunctions.Utility_DisplayArrayInTable(SourceData_OtherLivestock.SourceData_OtherLivestock_VolatileSolidsProduced_Data(),Table_SourceData_OtherLivestock_VolatileSolids[[#Headers],[Other livestock type]],0)} -> 2.73
D29: {=Common_InputFunctions.Utility_DisplayArrayInTable(SourceData_OtherLivestock.SourceData_OtherLivestock_VolatileSolidsProduced_Data(),Table_SourceData_OtherLivestock_VolatileSolids[[#Headers],[Other livestock type]],0)} -> Alpacas | E29: {=Common_InputFunctions.Utility_DisplayArrayInTable(SourceData_OtherLivestock.SourceData_OtherLivestock_VolatileSolidsProduced_Data(),Table_SourceData_OtherLivestock_VolatileSolids[[#Headers],[Other livestock type]],0)} -> 0.34
D30: {=Common_InputFunctions.Utility_DisplayArrayInTable(SourceData_OtherLivestock.SourceData_OtherLivestock_VolatileSolidsProduced_Data(),Table_SourceData_OtherLivestock_VolatileSolids[[#Headers],[Other livestock type]],0)} -> Horses | E30: {=Common_InputFunctions.Utility_DisplayArrayInTable(SourceData_OtherLivestock.SourceData_OtherLivestock_VolatileSolidsProduced_Data(),Table_SourceData_OtherLivestock_VolatileSolids[[#Headers],[Other livestock type]],0)} -> 2.73
D31: {=Common_InputFunctions.Utility_DisplayArrayInTable(SourceData_OtherLivestock.SourceData_OtherLivestock_VolatileSolidsProduced_Data(),Table_SourceData_OtherLivestock_VolatileSolids[[#Headers],[Other livestock type]],0)} -> Mules/asses | E31: {=Common_InputFunctions.Utility_DisplayArrayInTable(SourceData_OtherLivestock.SourceData_OtherLivestock_VolatileSolidsProduced_Data(),Table_SourceData_OtherLivestock_VolatileSolids[[#Headers],[Other livestock type]],0)} -> 0.91
D32: {=Common_InputFunctions.Utility_DisplayArrayInTable(SourceData_OtherLivestock.SourceData_OtherLivestock_VolatileSolidsProduced_Data(),Table_SourceData_OtherLivestock_VolatileSolids[[#Headers],[Other livestock type]],0)} -> Emus/ostriches | E32: {=Common_InputFunctions.Utility_DisplayArrayInTable(SourceData_OtherLivestock.SourceData_OtherLivestock_VolatileSolidsProduced_Data(),Table_SourceData_OtherLivestock_VolatileSolids[[#Headers],[Other livestock type]],0)} -> 0.34
D35: {=SourceData_OtherLivestock.SourceData_OtherLivestock_NitrogenExcreted_Title()} -> Other Livestock - Nitrogen excreted per livestock type
D36: {=SourceData_OtherLivestock.SourceData_OtherLivestock_NitrogenExcreted_Source()} -> VEERG 2026: Table A.1.5.3
D37: {=SourceData_OtherLivestock.SourceData_OtherLivestock_NitrogenExcreted_Variable()} -> NEj
D38: {=SourceData_OtherLivestock.SourceData_OtherLivestock_NitrogenExcreted_Unit()} -> kg N2O / head / year
D39: Other livestock type | E39: NEj
D40: {=Common_InputFunctions.Utility_DisplayArrayInTable(SourceData_OtherLivestock.SourceData_OtherLivestock_NitrogenExcreted_Data(),Table_SourceData_OtherLivestock_NitrogenExcreted[[#Headers],[Other livestock type]],0)} -> Buffalo | E40: {=Common_InputFunctions.Utility_DisplayArrayInTable(SourceData_OtherLivestock.SourceData_OtherLivestock_NitrogenExcreted_Data(),Table_SourceData_OtherLivestock_NitrogenExcreted[[#Headers],[Other livestock type]],0)} -> 39.5
D41: {=Common_InputFunctions.Utility_DisplayArrayInTable(SourceData_OtherLivestock.SourceData_OtherLivestock_NitrogenExcreted_Data(),Table_SourceData_OtherLivestock_NitrogenExcreted[[#Headers],[Other livestock type]],0)} -> Goats | E41: {=Common_InputFunctions.Utility_DisplayArrayInTable(SourceData_OtherLivestock.SourceData_OtherLivestock_NitrogenExcreted_Data(),Table_SourceData_OtherLivestock_NitrogenExcreted[[#Headers],[Other livestock type]],0)} -> 7
D42: {=Common_InputFunctions.Utility_DisplayArrayInTable(SourceData_OtherLivestock.SourceData_OtherLivestock_NitrogenExcreted_Data(),Table_SourceData_OtherLivestock_NitrogenExcreted[[#Headers],[Other livestock type]],0)} -> Deer | E42: {=Common_InputFunctions.Utility_DisplayArrayInTable(SourceData_OtherLivestock.SourceData_OtherLivestock_NitrogenExcreted_Data(),Table_SourceData_OtherLivestock_NitrogenExcreted[[#Headers],[Other livestock type]],0)} -> 13.2
D43: {=Common_InputFunctions.Utility_DisplayArrayInTable(SourceData_OtherLivestock.SourceData_OtherLivestock_NitrogenExcreted_Data(),Table_SourceData_OtherLivestock_NitrogenExcreted[[#Headers],[Other livestock type]],0)} -> Camels | E43: {=Common_InputFunctions.Utility_DisplayArrayInTable(SourceData_OtherLivestock.SourceData_OtherLivestock_NitrogenExcreted_Data(),Table_SourceData_OtherLivestock_NitrogenExcreted[[#Headers],[Other livestock type]],0)} -> 39.5
...

Sheet Constants - Livestock
A1: #VALUE! | C1: Constants - Livestock
A3: =HYPERLINK("#'Home'!A1", "Home") -> Home
A4: =HYPERLINK("#'Overview'!A1", "Overview") -> Overview
A5: =HYPERLINK("#'Results'!A1", "Results") -> Results
D6: {=CommonLivestock_SourceData.SourceData_Livestock_Common_SymbolsMMS_Title()} -> Table 5.12 Additional symbols used in algorithms for manure related emissions
A7: INPUTS | D7: {=CommonLivestock_SourceData.SourceData_Livestock_Common_SymbolsMMS_Vairable()} -> MMS
A8: =HYPERLINK("#'Input - Site'!A1", "Site") -> Site | D8: {=CommonLivestock_SourceData.SourceData_Livestock_Common_SymbolsMMS_Source()} -> National Inventory Report 2023 Volume 1: Table 5.12
A9: =HYPERLINK("#'Input - Other Livestock'!A1", "Other Livestock") -> Other Livestock | D9: Symbol | E9: Manure management system | F9: Symbol and MMS
