Workbook
Name Common_Equations.Common_ConvertCH4ToCO2e: _xlfn.LAMBDA(_xlpm.E_CH4,_xlpm.GWP_CH4, _xlpm.E_CH4 * _xlpm.GWP_CH4)
Name Common_Equations.Common_ConvertCH4ToCO2e_Arguments: _xlfn.LAMBDA(_xlfn.MAKEARRAY(2, 2, _xlfn.LAMBDA(_xlpm.r,_xlpm.c, INDEX({"ECH4","Methane emissions (t CH4)";"GWPCH4","Global warming potential for methane (t CO2-e / t CH4)"}, _xlpm.r, _xlpm.c))))
Name Common_Equations.Common_ConvertCH4ToCO2e_LatexEquation: _xlfn.LAMBDA("CO2_e = E_{CH4} \times GWP_{CH4}")
Name Common_Equations.Common_ConvertCH4ToCO2e_NIRReference: _xlfn.LAMBDA("")
Name Common_Equations.Common_ConvertCH4ToCO2e_Title: _xlfn.LAMBDA("Convert methane emissions to carbon dioxide equivalent emissions")
Name Common_Equations.Common_ConvertCH4ToCO2e_Unit: _xlfn.LAMBDA("t CO2e")
Name Common_Equations.Common_ConvertCH4ToCO2e_Variable: _xlfn.LAMBDA("ECH4 CO2e")
Name Common_Equations.Common_ConvertN2OToCO2e: _xlfn.LAMBDA(_xlpm.E_N2O,_xlpm.GWP_N2O, _xlpm.E_N2O * _xlpm.GWP_N2O)
Name Common_Equations.Common_ConvertN2OToCO2e_LatexEquation: _xlfn.LAMBDA("CO2_e = E_{N2O} \times GWP_{N2O}")
Name Common_Equations.Common_ConvertN2OToCO2e_NIRReference: _xlfn.LAMBDA("")
Name Common_Equations.Common_ConvertN2OToCO2e_Title: _xlfn.LAMBDA("Convert nitrous oxide emissions to carbon dioxide equivalent emissions")
Name Common_Equations.Common_ConvertN2OToCO2e_Unit: _xlfn.LAMBDA("t CO2e")
Name Common_Equations.Common_ConvertN2OToCO2e_Variable: _xlfn.LAMBDA("EN2O CO2e")
Name Common_InputFunctions.Utility_ConvertStateCommonNameToAbbreviation: _xlfn.LAMBDA(_xlpm.StateCommonName,_xlpm.StateCommonNameArray,_xlpm.StateAbbreviationArray, _xlfn.XLOOKUP(_xlpm.StateCommonName, _xlpm.StateCommonNameArray, _xlpm.StateAbbreviationArray, ""))
Name Common_InputFunctions.Utility_DisplayFunctionName: _xlfn.LAMBDA(_xlpm.Function, _xlfn.TEXTBEFORE(_xlfn.FORMULATEXT(_xlpm.Function), "("))
Name Common_InputFunctions.Utility_GetArrayTableColumnStartNumber: _xlfn.LAMBDA(_xlpm.TableHeaderCell, COLUMN(_xlpm.TableHeaderCell))
Name Common_InputFunctions.Utility_GetArrayTableRowStartNumber: _xlfn.LAMBDA(_xlpm.TableheaderCell,_xlpm.RowsBetweenHeaderandArray, ROW(_xlpm.TableheaderCell) + _xlpm.RowsBetweenHeaderandArray - 1)
Name Common_InputFunctions.Utility_LookupValueInTable: _xlfn.LAMBDA(_xlpm.LookupValue,_xlpm.LookupArray,_xlpm.ReturnArray, _xlfn.XLOOKUP(_xlpm.LookupValue, _xlpm.LookupArray, _xlpm.ReturnArray, ""))
Name Common_SourceData.Common_SourceData_AustralianStatesTerritories_Source: _xlfn.LAMBDA("")
Name Common_SourceData.Common_SourceData_AustralianStatesTerritories_Title: _xlfn.LAMBDA("Australian states and territories")
Name Common_SourceData.Common_SourceData_AustralianStatesTerritories_Unit: _xlfn.LAMBDA("")
Name Common_SourceData.Common_SourceData_AustralianStatesTerritories_Variable: _xlfn.LAMBDA("")
Name Common_SourceData.Common_SourceData_ClimateZones_Source: _xlfn.LAMBDA("VEERG 2026: Table 1.3: Climate and Rainfall zone classifications and definitions")
Name Common_SourceData.Common_SourceData_ClimateZones_Title: _xlfn.LAMBDA("VEERG Australian climate zones")
Name Common_SourceData.Common_SourceData_ClimateZones_Unit: _xlfn.LAMBDA("")
Name Common_SourceData.Common_SourceData_ClimateZones_Variable: _xlfn.LAMBDA("")
Name Common_SourceData.Common_SourceData_ConvertGasElementalToMolecular_Source: _xlfn.LAMBDA("XXXXXXX")
Name Common_SourceData.Common_SourceData_ConvertGasElementalToMolecular_Title: _xlfn.LAMBDA("Factor to convert elemental mass of gas to molecular mass")
Name Common_SourceData.Common_SourceData_ConvertGasElementalToMolecular_Unit: _xlfn.LAMBDA("factor")
Name Common_SourceData.Common_SourceData_ConvertGasElementalToMolecular_Variable: _xlfn.LAMBDA("Cg")
Name Common_SourceData.Common_SourceData_ConvertN2oElementalToMolecularCg_Data: _xlfn.LAMBDA(44 / 28)
Name Common_SourceData.Common_SourceData_ConvertN2oElementalToMolecularCg_Source: _xlfn.LAMBDA("National Inventory Report 2023 Volume 1")
Name Common_SourceData.Common_SourceData_ConvertN2oElementalToMolecularCg_Title: _xlfn.LAMBDA("Factor to convert elemental mass of N2O to molecular mass")
Name Common_SourceData.Common_SourceData_ConvertN2oElementalToMolecularCg_Unit: _xlfn.LAMBDA("factor")
Name Common_SourceData.Common_SourceData_ConvertN2oElementalToMolecularCg_Variable: _xlfn.LAMBDA("CgN2O")
Name Common_SourceData.Common_SourceData_DataScores_Scope3_Source: _xlfn.LAMBDA("VEERG 2026: XXXXXXXX")
Name Common_SourceData.Common_SourceData_DataScores_Scope3_Title: _xlfn.LAMBDA("Australian data scores for scope 3")
Name Common_SourceData.Common_SourceData_DataScores_Scope3_Unit: _xlfn.LAMBDA("")
Name Common_SourceData.Common_SourceData_DataScores_Scope3_Variable: _xlfn.LAMBDA("")
Name Common_SourceData.Common_SourceData_DataScores_Scope3_Variation: _xlfn.LAMBDA("")
Name Common_SourceData.Common_SourceData_DensityOfMethane_Data: _xlfn.LAMBDA(0.6784)
Name Common_SourceData.Common_SourceData_DensityOfMethane_Source: _xlfn.LAMBDA("National Inventory Report 2023 Volume 1: Equations 3.B.1a_2, 3.B.1c_2, 3.B.3_1, 3.B.4g_2")
Name Common_SourceData.Common_SourceData_DensityOfMethane_Title: _xlfn.LAMBDA("p = density of methane")
Name Common_SourceData.Common_SourceData_DensityOfMethane_Unit: _xlfn.LAMBDA("kg/m3")
Name Common_SourceData.Common_SourceData_EFleach_Data: _xlfn.LAMBDA(_xlfn.MAKEARRAY(1, 2, _xlfn.LAMBDA(_xlpm.r,_xlpm.c, INDEX({"EFleach",0.011}, _xlpm.r, _xlpm.c))))
Name Common_SourceData.Common_SourceData_EFleach_NIRReference: _xlfn.LAMBDA("National Inventory Report Volume 1: Equation 3.D.B_10")
Name Common_SourceData.Common_SourceData_EFleach_Source: _xlfn.LAMBDA("VEERG 2026:5.5.2.3 Constant Parameters")
Name Common_SourceData.Common_SourceData_EFleach_Title: _xlfn.LAMBDA("Emission factor for nitrogen leaching and runoff")
Name Common_SourceData.Common_SourceData_EFleach_Unit: _xlfn.LAMBDA("(kg N2O-N / kg N")
Name Common_SourceData.Common_SourceData_EFleach_Variation: _xlfn.LAMBDA((""))
Name Common_SourceData.Common_SourceData_EFN2O_NIRReference: _xlfn.LAMBDA("")
Name Common_SourceData.Common_SourceData_EFN2O_Source: _xlfn.LAMBDA("VEERG 2026: Table A.2.2.1")
Name Common_SourceData.Common_SourceData_EFN2O_Title: _xlfn.LAMBDA("Nitrous oxide emission factors for inorganic fertiliser application")
Name Common_SourceData.Common_SourceData_EFN2O_Unit: _xlfn.LAMBDA("(kg N2O-N / kg N")
Name Common_SourceData.Common_SourceData_EFPastureRangeAndPaddock_Data: _xlfn.LAMBDA(_xlfn.MAKEARRAY(3, 2, _xlfn.LAMBDA(_xlpm.r,_xlpm.c, INDEX({"Climate zone","EFPRP";"Wet climate zone",0.006;"Dry climate zone",0.002}, _xlpm.r, _xlpm.c))))
Name Common_SourceData.Common_SourceData_EFPastureRangeAndPaddock_NIRReference: _xlfn.LAMBDA("")
Name Common_SourceData.Common_SourceData_EFPastureRangeAndPaddock_Source: _xlfn.LAMBDA("VEERG 2026: Table A.2.2.2")
Name Common_SourceData.Common_SourceData_EFPastureRangeAndPaddock_Title: _xlfn.LAMBDA("Emission factor for urine and dung deposited on pasture, range or paddock")
Name Common_SourceData.Common_SourceData_EFPastureRangeAndPaddock_Unit: _xlfn.LAMBDA("kg N2O - N / kg N")
Name Common_SourceData.Common_SourceData_EFPastureRangeAndPaddock_Variation: _xlfn.LAMBDA("VARIATION FROM SOURCE DATA: Changed 'Dry climate zones' to singular 'Dry climate zone' to aid lookup.")

Sheet Home
A1: Home

Sheet Results
A1: #VALUE! | C1: 5.1 Inorganic Fertiliser
A3: =HYPERLINK("#'Home'!A1", "Home") -> Home
A4: =HYPERLINK("#'Results'!A1", "Results") -> Results | D4: Emissions breakdown
A6: INPUTS | D6: Scope 1 source | E6: GHG emissions method 1 | F6: GHG emissions method 2 | G6: GHG Unit | H6: CO2-e emissions method 1 | I6: CO2-e emissions method 2 | J6: CO2-e unit
A7: =HYPERLINK("#'Input - Site'!A1", "Site") -> Site | D7: 4.6.1.1-2 Manure methane | E7: ='5.1.1.1-2 Inorganic fert N2O'!E209 -> 0 | F7: ='5.1.1.1-2 Inorganic fert N2O'!N209 -> 0 | G7: t CH4 | H7: ='5.1.1.1-2 Inorganic fert N2O'!E214 -> 0 | I7: ='5.1.1.1-2 Inorganic fert N2O'!N214 -> 0 | J7: t CO2e
A8: =HYPERLINK("#'Input - Poultry'!A1", "Poultry") -> Poultry | D8: 4.6.1.3-4 Direct N2O | E8: =#REF! -> #REF! | F8: =#REF! -> #REF! | G8: t N2O | H8: =#REF! -> #REF! | I8: =#REF! -> #REF! | J8: t CO2e
D9: 4.6.1.5-6 Atmospheric deposition | E9: =#REF! -> #REF! | F9: =#REF! -> #REF! | G9: t N2O | H9: =#REF! -> #REF! | I9: =#REF! -> #REF! | J9: t CO2e
A10: CALCULATIONS | D10: 4.6.1.7-8 Leaching and runoff | E10: =#REF! -> #REF! | F10: =#REF! -> #REF! | G10: t N2O | H10: =#REF! -> #REF! | I10: =#REF! -> #REF! | J10: t CO2e
A11: =HYPERLINK("#'4.6.1.1-2 Methane'!A1", "4.6.1.1-2 Methane") -> 4.6.1.1-2 Methane | D11: 4.6.1.10-11 Soil direct N2O | E11: =#REF! -> #REF! | F11: =#REF! -> #REF! | G11: t N2O | H11: =#REF! -> #REF! | I11: =#REF! -> #REF! | J11: t CO2e
A12: =HYPERLINK("#'4.6.1.3-4 Direct N20'!A1", "4.6.1.3-4 Direct N2O") -> 4.6.1.3-4 Direct N2O | D12: 4.6.1.12-13 Soil Atmospheric deposition | E12: =#REF! -> #REF! | F12: =#REF! -> #REF! | G12: t N2O | H12: =#REF! -> #REF! | I12: =#REF! -> #REF! | J12: t CO2e
A13: =HYPERLINK("#'4.6.1.5-6 Atmos Dep'!A1", "4.6.1.5-6 Atmospheric deposition") -> 4.6.1.5-6 Atmospheric deposition | D13: 4.6.1.14-15 Soil leaching and runoff | E13: =#REF! -> #REF! | F13: =#REF! -> #REF! | G13: t N2O | H13: =#REF! -> #REF! | I13: =#REF! -> #REF! | J13: t CO2e
A14: =HYPERLINK("#'4.6.1.7-8 Leaching and runoff'!A1", "4.6.1.7-8 Leaching & runoff") -> 4.6.1.7-8 Leaching & runoff | D14: Total | H14: =SUM(H7:H13) -> #REF! | I14: =SUM(I7:I13) -> #REF! | J14: t CO2e
A15: =HYPERLINK("#'4.6.1.9 Manure applied to soils'!A1", "4.6.1.9 Manure applied to soils") -> 4.6.1.9 Manure applied to soils
A16: =HYPERLINK("#'4.6.1.10-11 Soil direct N2O'!A1", "4.6.1.10-11 Soil direct N2O") -> 4.6.1.10-11 Soil direct N2O | D16: 4.6.1.9 Manure applied to soils
A17: =HYPERLINK("#'4.6.1.12-13 Soil atmos dep'!A1", "4.6.1.12-13 Soil Atm. deposition") -> 4.6.1.12-13 Soil Atm. deposition | D17: WARNING: Manure nitrogen that was applied to soils must be accounted for
A18: =HYPERLINK("#'4.6.1.14-15 Soil leach runoff'!A1", "4.6.1.14-15 Soil leach & runoff") -> 4.6.1.14-15 Soil leach & runoff | D18: See the table below for how to account for manure applied to soils for scope 1 and 3.
D19: Manure nitrogen use | E19: Amount of N in manure | F19: N unit | G19: Emissions allocated to | H19: VEERG Calculation method
A20: APPENDICES | D20: Manure nitrogen deposited on farm soils (including use as fertiliser for other enterprises on own farm eg crops) | E20: =#REF! -> #REF! | F20: kg N | G20: Scope 1 - This poultry enterprise | H20: 5.2.2.1 (1), 5.4.1.3 (1, 2), 5.5.1.1 (1, 3)
A21: =HYPERLINK("#'Constants - Poultry'!A1", "Constants - Poultry") -> Constants - Poultry | D21: Manure nitrogen deposited on farm soils as fertiliser for other farm enterpsies (eg crops) | E21: =#REF! -> #REF! | F21: kg N | G21: Scope 1 - This poultry enterprise | H21: 5.2.2.1 (1), 5.4.1.3 (1, 2), 5.5.1.1 (1, 3)
A22: =HYPERLINK("#'Constants - Livestock'!A1", "Constants - Livestock") -> Constants - Livestock | D22: Manure nitrogen sold | E22: =#REF! -> #REF! | F22: kg N | G22: Scope 3 (downstream) | H22: 15.13.1.1 (1), 5.2.2.1 (1), 5.4.1.3 (1, 2), 5.5.1.1 (1, 3)
A23: =HYPERLINK("#'Constants - Common'!A1", "Constants - Common") -> Constants - Common
A24: =HYPERLINK("#'Acknowledgements'!A1", "Acknowledgements") -> Acknowledgements

Sheet Input - Site
A1: #VALUE! | C1: Input - Site
A3: =HYPERLINK("#'Home'!A1", "Home") -> Home
A4: =HYPERLINK("#'Results'!A1", "Results") -> Results
D5: Your business
A6: INPUTS
A7: =HYPERLINK("#'Input - Site'!A1", "Site") -> Site | D7: Farm name | E7: Test Farms
A8: =HYPERLINK("#'Input - Poultry'!A1", "Poultry") -> Poultry | D8: Reporting entity name | E8: Test Farms Pty Ltd
A10: CALCULATIONS | D10: 💡An 'Emissions accounting period' is a 12 month period where the business can report on the emissions, and is typically the same as the business' financial accounting period.
A11: =HYPERLINK("#'4.6.1.1-2 Methane'!A1", "4.6.1.1-2 Methane") -> 4.6.1.1-2 Methane
A12: =HYPERLINK("#'4.6.1.3-4 Direct N20'!A1", "4.6.1.3-4 Direct N2O") -> 4.6.1.3-4 Direct N2O | D12: Emissions calculation period start date | E12: 45292 | F12: ← DD/MM/YYYY or DD Month YYYY
A13: =HYPERLINK("#'4.6.1.5-6 Atmos Dep'!A1", "4.6.1.5-6 Atmospheric deposition") -> 4.6.1.5-6 Atmospheric deposition | D13: Emissions calculation period end date | E13: =DATE(YEAR(E12)+1,MONTH(E12),DAY(E12))-1 -> 45657 | F13: ← Automatically calculated, 12 months after start date
A14: =HYPERLINK("#'4.6.1.7-8 Leaching and runoff'!A1", "4.6.1.7-8 Leaching & runoff") -> 4.6.1.7-8 Leaching & runoff
A15: =HYPERLINK("#'4.6.1.9 Manure applied to soils'!A1", "4.6.1.9 Manure applied to soils") -> 4.6.1.9 Manure applied to soils
A16: =HYPERLINK("#'4.6.1.10-11 Soil direct N2O'!A1", "4.6.1.10-11 Soil direct N2O") -> 4.6.1.10-11 Soil direct N2O | D16: Location and climate
A17: =HYPERLINK("#'4.6.1.12-13 Soil atmos dep'!A1", "4.6.1.12-13 Soil Atm. deposition") -> 4.6.1.12-13 Soil Atm. deposition
A18: =HYPERLINK("#'4.6.1.14-15 Soil leach runoff'!A1", "4.6.1.14-15 Soil leach & runoff") -> 4.6.1.14-15 Soil leach & runoff | D18: Location information is used to reference some region and climate-specific emission factors
D19: Tip: Use the web-based GAF Location Helper tool to easily get region and climate information. You will need an internet connection to use the GAF Location Helper.
A20: APPENDICES
A21: =HYPERLINK("#'Constants - Poultry'!A1", "Constants - Poultry") -> Constants - Poultry | D21: State | E21: Western Australia | F21: ← Please select
A22: =HYPERLINK("#'Constants - Livestock'!A1", "Constants - Livestock") -> Constants - Livestock | D22: Region (ABS Statistical area level 4) if state is WA | E22: Western Australia - Outback (South) | F22: ← Please select
A23: =HYPERLINK("#'Constants - Common'!A1", "Constants - Common") -> Constants - Common | D23: Leaching zone | E23: NO - Not in leaching zone | F23: ← Please select
A24: =HYPERLINK("#'Acknowledgements'!A1", "Acknowledgements") -> Acknowledgements | D24: Elevation | E24: 307.7 | F24: Meters
D25: Average temperature for reporting period | E25: 18 | F25: Degrees celsius
D26: Total rainfall for reporting period | E26: 601 | F26: Millimetres
D27: Potential evapotranspiration for reporting period | E27: 1326 | F27: Millimetres
D28: Number of frost days for reporting period | E28: 7 | F28: Days
D29: MAP:PET ratio | E29: =E26/E27 -> 0.45324284
D30: Rainfall zone | E30: =Common_InputFunctions.Utility_LookupItemFromMinMax(E26,Table_SourceData_RainfallZones[Min rainfall],Table_SourceData_RainfallZones[Max rainfall],Table_SourceData_RainfallZones[Rainfall Zone]) -> High rainfall
D31: Climate zone | E31: =Common_InputFunctions.Utility_GetClimateZone(E25,E26,E28,E24,E29,Table_SourceData_ClimateZones[Min temp],Table_SourceData_ClimateZones[Max temp],Table_SourceData_ClimateZones[Min rainfall],Table_SourceData_ClimateZones[Max rainfall],Table_SourceData_ClimateZones[Min frost days],Table_SourceData_ClimateZones[Max frost days],Table_SourceData_ClimateZones[Min elevation],Table_SourceData_ClimateZones[Max elevation],Table_SourceData_ClimateZones[Min MAP:PET],Table_SourceData_ClimateZones[Max MAP:PET],Table_SourceData_ClimateZones[Climate zone]) -> Warm temperate dry
D32: Wet or dry climate zone | E32: =Common_InputFunctions.Utility_LookupValueInTable($E$31,Table_SourceData_WetDryZones[Climate zone],Table_SourceData_WetDryZones[Wet or Dry Zone]) -> Dry climate zone
D33: Temperature zone | E33: =Common_InputFunctions.Utility_LookupItemFromMinMax(E25,Table_SourceData_TemperatureZones[Min MAT],Table_SourceData_TemperatureZones[Max MAT],Table_SourceData_TemperatureZones[Temperature Zone]) -> Temperate

Sheet Input - Inorganic fertiliser
A1: #VALUE! | C1: Input - Inorganic Fertiliser
D6: Production system | E6: Crop | F6: ← Please select
D7: Crop type | E7: Grains | F7: ← Please select
D8: Irrigation method | E8: Not irrigated | F8: ← Please select
D9: Area under cropping | E9: 100 | F9: hectares
D11: Inorganic fertiliser applied
D13: 💡You can add more rows to tables by right-clicking on the table and selecting "Insert > Table rows above/below".
D14: 💡The application area is the same as the area under pasture / cropping by default. You can edit it if the application area is different.
D16: Branded fertiliser products
D17: Product (select) | E17: Amount applied (kg / ha) | F17: Application area (ha) | G17: Total applied (kg) | H17: Ingredient 1 | I17: Ingredient 1 percent | J17: Ingredient 2 | K17: Ingredient 2 percent | L17: Ingredient 3 | M17: Ingredient 3 percent | N17: Ingredient 4 | O17: Ingredient 4 percent | P17: Ingredient 5 | Q17: Ingredient 5 percent | R17: Ingredient 6 | S17: Ingredient 6 percent | T17: N application rate (kg/ha)
D18: 80% Urea 20% MAP | E18: 200 | F18: =$E$9 -> 100 | G18: =Table_Input_InorganicFertiliser_Brands[[#This Row],[Amount applied (kg / ha)]]*Table_Input_InorganicFertiliser_Brands[[#This Row],[Application area (ha)]] -> 20000 | H18: {=Fertiliser_InputFunctions.Fertiliser_FertiliserProductLookup(Table_Input_InorganicFertiliser_Brands[[#This Row],[Product (select)]], Table_Input_InorganicFertiliser_Brands[[#Headers],[Ingredient 1]], FertiliserProducts[#Data], FertiliserProducts[Product], FertiliserProducts[#Headers])} -> Urea-Ammonium Nitrate (UAN) | I18: {=Fertiliser_InputFunctions.Fertiliser_FertiliserProductLookup(Table_Input_InorganicFertiliser_Brands[[#This Row],[Product (select)]], Table_Input_InorganicFertiliser_Brands[[#Headers],[Ingredient 1 percent]], FertiliserProducts[#Data], FertiliserProducts[Product], FertiliserProducts[#Headers])} -> 0.8 | J18: {=Fertiliser_InputFunctions.Fertiliser_FertiliserProductLookup(Table_Input_InorganicFertiliser_Brands[[#This Row],[Product (select)]], Table_Input_InorganicFertiliser_Brands[[#Headers],[Ingredient 2]], FertiliserProducts[#Data], FertiliserProducts[Product], FertiliserProducts[#Headers])} -> Monoammonium phosphate (MAP) | K18: {=Fertiliser_InputFunctions.Fertiliser_FertiliserProductLookup(Table_Input_InorganicFertiliser_Brands[[#This Row],[Product (select)]], Table_Input_InorganicFertiliser_Brands[[#Headers],[Ingredient 2 percent]], FertiliserProducts[#Data], FertiliserProducts[Product], FertiliserProducts[#Headers])} -> 0.2 | L18: {=Fertiliser_InputFunctions.Fertiliser_FertiliserProductLookup(Table_Input_InorganicFertiliser_Brands[[#This Row],[Product (select)]], Table_Input_InorganicFertiliser_Brands[[#Headers],[Ingredient 3]], FertiliserProducts[#Data], FertiliserProducts[Product], FertiliserProducts[#Headers])} | M18: {=Fertiliser_InputFunctions.Fertiliser_FertiliserProductLookup(Table_Input_InorganicFertiliser_Brands[[#This Row],[Product (select)]], Table_Input_InorganicFertiliser_Brands[[#Headers],[Ingredient 3 percent]], FertiliserProducts[#Data], FertiliserProducts[Product], FertiliserProducts[#Headers])} | N18: {=Fertiliser_InputFunctions.Fertiliser_FertiliserProductLookup(Table_Input_InorganicFertiliser_Brands[[#This Row],[Product (select)]], Table_Input_InorganicFertiliser_Brands[[#Headers],[Ingredient 4]], FertiliserProducts[#Data], FertiliserProducts[Product], FertiliserProducts[#Headers])} | O18: {=Fertiliser_InputFunctions.Fertiliser_FertiliserProductLookup(Table_Input_InorganicFertiliser_Brands[[#This Row],[Product (select)]], Table_Input_InorganicFertiliser_Brands[[#Headers],[Ingredient 4 percent]], FertiliserProducts[#Data], FertiliserProducts[Product], FertiliserProducts[#Headers])} | P18: {=Fertiliser_InputFunctions.Fertiliser_FertiliserProductLookup(Table_Input_InorganicFertiliser_Brands[[#This Row],[Product (select)]], Table_Input_InorganicFertiliser_Brands[[#Headers],[Ingredient 5]], FertiliserProducts[#Data], FertiliserProducts[Product], FertiliserProducts[#Headers])} | Q18: {=Fertiliser_InputFunctions.Fertiliser_FertiliserProductLookup(Table_Input_InorganicFertiliser_Brands[[#This Row],[Product (select)]], Table_Input_InorganicFertiliser_Brands[[#Headers],[Ingredient 5 percent]], FertiliserProducts[#Data], FertiliserProducts[Product], FertiliserProducts[#Headers])} | R18: {=Fertiliser_InputFunctions.Fertiliser_FertiliserProductLookup(Table_Input_InorganicFertiliser_Brands[[#This Row],[Product (select)]], Table_Input_InorganicFertiliser_Brands[[#Headers],[Ingredient 6]], FertiliserProducts[#Data], FertiliserProducts[Product], FertiliserProducts[#Headers])} | S18: {=Fertiliser_InputFunctions.Fertiliser_FertiliserProductLookup(Table_Input_InorganicFertiliser_Brands[[#This Row],[Product (select)]], Table_Input_InorganicFertiliser_Brands[[#Headers],[Ingredient 6 percent]], FertiliserProducts[#Data], FertiliserProducts[Product], FertiliserProducts[#Headers])} | T18: =Table_Input_InorganicFertiliser_Brands[[#This Row],[Amount applied (kg / ha)]]*(IFERROR((_xlfn.XLOOKUP(Table_Input_InorganicFertiliser_Brands[[#This Row],[Ingredient 1]], Table_Fertiliser_ChemicalCompounds[Fertiliser type f],Table_Fertiliser_ChemicalCompounds[FNinorganic f])*Table_Input_InorganicFertiliser_Brands[[#This Row],[Ingredient 1 percent]]), 0)+ IFERROR((_xlfn.XLOOKUP(Table_Input_InorganicFertiliser_Brands[[#This Row],[Ingredient 2]],Table_Fertiliser_ChemicalCompounds[Fertiliser type f],Table_Fertiliser_ChemicalCompounds[FNinorganic f])*Table_Input_InorganicFertiliser_Brands[[#This Row],[Ingredient 2 percent]]), 0)+ IFERROR((_xlfn.XLOOKUP(Table_Input_InorganicFertiliser_Brands[[#This Row],[Ingredient 3]],Table_Fertiliser_ChemicalCompounds[Fertiliser type f],Table_Fertiliser_ChemicalCompounds[FNinorganic f])*Table_Input_InorganicFertiliser_Brands[[#This Row],[Ingredient 3 percent]]), 0)+ IFERROR((_xlfn.XLOOKUP(Table_Input_InorganicFertiliser_Brands[[#This Row],[Ingredient 4]],Table_Fertiliser_ChemicalCompounds[Fertiliser type f],Table_Fertiliser_ChemicalCompounds[FNinorganic f])*Table_Input_InorganicFertiliser_Brands[[#This Row],[Ingredient 4 percent]]), 0)+ IFERROR((_xlfn.XLOOKUP(Table_Input_InorganicFertiliser_Brands[[#This Row],[Ingredient 5]],Table_Fertiliser_ChemicalCompounds[Fertiliser type f],Table_Fertiliser_ChemicalCompounds[FNinorganic f])*Table_Input_InorganicFertiliser_Brands[[#This Row],[Ingredient 5 percent]]), 0)+ IFERROR((_xlfn.XLOOKUP(Table_Input_InorganicFertiliser_Brands[[#This Row],[Ingredient 6]],Table_Fertiliser_ChemicalCompounds[Fertiliser type f],Table_Fertiliser_ChemicalCompounds[FNinorganic f])*Table_Input_InorganicFertiliser_Brands[[#This Row],[Ingredient 6 percent]]), 0)) -> 55.2
D21: Custom fertiliser blends
D22: Custom blend name | E22: Amount applied (kg / ha) | F22: Application area (ha) | G22: Total applied (kg) | H22: Ingredient 1 (select) | I22: Ingredient 1 percent | J22: Ingredient 2 | K22: Ingredient 2 percent | L22: Ingredient 3 | M22: Ingredient 3 percent | N22: Ingredient 4 | O22: Ingredient 4 percent | P22: N application rate (kg/ha)
D23: My first custom blend | E23: 200 | F23: =$E$9 -> 100 | G23: =Table_Input_InorganicFertiliser_Custom[[#This Row],[Amount applied (kg / ha)]]*Table_Input_InorganicFertiliser_Custom[[#This Row],[Application area (ha)]] -> 20000 | H23: Nitrogen - generic | I23: 0.45 | J23: Phosphorus - Generic | K23: 0.3 | L23: Potassium - Generic | M23: 0.1 | N23: Sulfur - Generic | O23: 0.05 | P23: =Table_Input_InorganicFertiliser_Custom[[#This Row],[Amount applied (kg / ha)]]* (IFERROR((_xlfn.XLOOKUP(Table_Input_InorganicFertiliser_Custom[[#This Row],[Ingredient 1 (select)]], Table_Fertiliser_ChemicalCompounds[Fertiliser type f],Table_Fertiliser_ChemicalCompounds[FNinorganic f])*Table_Input_InorganicFertiliser_Custom[[#This Row],[Ingredient 1 percent]]), 0) + IFERROR((_xlfn.XLOOKUP(Table_Input_InorganicFertiliser_Custom[[#This Row],[Ingredient 2]], Table_Fertiliser_ChemicalCompounds[Fertiliser type f],Table_Fertiliser_ChemicalCompounds[FNinorganic f])*Table_Input_InorganicFertiliser_Custom[[#This Row],[Ingredient 2 percent]]), 0) + IFERROR((_xlfn.XLOOKUP(Table_Input_InorganicFertiliser_Custom[[#This Row],[Ingredient 3]], Table_Fertiliser_ChemicalCompounds[Fertiliser type f],Table_Fertiliser_ChemicalCompounds[FNinorganic f])*Table_Input_InorganicFertiliser_Custom[[#This Row],[Ingredient 3 percent]]), 0) + IFERROR((_xlfn.XLOOKUP(Table_Input_InorganicFertiliser_Custom[[#This Row],[Ingredient 4]], Table_Fertiliser_ChemicalCompounds[Fertiliser type f],Table_Fertiliser_ChemicalCompounds[FNinorganic f])*Table_Input_InorganicFertiliser_Custom[[#This Row],[Ingredient 4 percent]]), 0) ) -> 90
D26: Soil amendments
D28: 💡 You can add more rows to the table by right-clicking on the table and selecting "Insert > Table rows above/below".
D29: 💡 'Lime' refers to calcium carbonate - CaCO3. 'Dolomite' refers to calcium magnesium carbonate - CaMg(CO3)2
D31: Product | E31: Amount applied (t/hectare) | F31: Application area (ha) | G31: Total amount applied (t) | H31: Percent Lime CaCO3 | I31: Percent Dolomite CaMg(CO3)2 | J31: Percent Lime Sand CaCO3 | K31: Percent Gypsum | L31: Percent Potash
D32: gfdgfdgd | E32: 10 | F32: ='[1]Input - Pasture'!$E$12 -> 100 | G32: =IFERROR(Table_Input_Lime[[#This Row],[Amount applied (t/hectare)]]*Table_Input_Lime[[#This Row],[Application area (ha)]], 0) -> 1000 | H32: 0.4 | I32: 0.3 | J32: 0.15 | K32: 0.1 | L32: 0.05
D35: Organic fertiliser applied
D37: 💡 You can add more rows to the table by right-clicking on the table and selecting "Insert > Table rows above/below".
D38: 💡The application area is the same as the area under pasture / cropping by default. You can edit it if the application area is different.
D40: Organic fertiliser type (select) | E40: Source (select) | F40: Percentage of N in fertiliser | G40: Amount applied (kg/hectare) | H40: Amount N applied (kg/hectare) | I40: Application area (ha) | J40: Total organic fertliser applied | K40: Total nitrogen applied (kg)
D41: Dairy Manure | E41: Location not specified | F41: 0.3 | G41: 10 | H41: =Table_Input_OrganicFertiliser[[#This Row],[Amount applied (kg/hectare)]]*Table_Input_OrganicFertiliser[[#This Row],[Percentage of N in fertiliser]] -> 3 | I41: ='[1]Input - Pasture'!$E$12 -> 100 | J41: =Table_Input_OrganicFertiliser[[#This Row],[Amount applied (kg/hectare)]]*Table_Input_OrganicFertiliser[[#This Row],[Application area (ha)]] -> 1000 | K41: =IFERROR(Table_Input_OrganicFertiliser[[#This Row],[Amount N applied (kg/hectare)]]*Table_Input_OrganicFertiliser[[#This Row],[Application area (ha)]], 0) -> 300

Sheet 5.1.1.1-2 Inorganic fert N2O
A1: #VALUE! | C1: 5.1.1.1-2 Inorganic fertiliser application N2O emissions
D3: Method 1 | M3: Method 2
D5: {=Fertiliser_Equations_InorganicN2O.VEERG_5_1_1_1__2_MassOfNitrogenInInorganicFertiliser_Title()} -> Mass of nitrogen in inorganic fertiliser applied to production system | M5: {=Fertiliser_Equations_InorganicN2O.VEERG_5_1_1_2__1_EmissionFactorIrrigatedMaize_Title()} -> Emission factor for nitrous oxide for irrigated maize
D6: {=Fertiliser_Equations_InorganicN2O.VEERG_5_1_1_1__2_MassOfNitrogenInInorganicFertiliser_Source()} -> VEERG 2026: 5.1.1.1, Equation (2) | M6: {=Fertiliser_Equations_InorganicN2O.VEERG_5_1_1_2__1_EmissionFactorIrrigatedMaize_Source()} -> VEERG 2026: 5.1.1.2, Equation (1)
D7: Function name | E7: {=Common_InputFunctions.Utility_DisplayFunctionName(G21)} -> =Fertiliser_Equations_InorganicN2O.VEERG_5_1_1_1__2_MassOfNitrogenInInorganicFertiliser
M9: Variable | N9: {=Fertiliser_Equations_InorganicN2O.VEERG_5_1_1_2__1_EmissionFactorIrrigatedMaize_Variable()} -> EF_fjIrrigatedMaizeN2O
D10: Variable | E10: {=Fertiliser_Equations_InorganicN2O.VEERG_5_1_1_1__2_MassOfNitrogenInInorganicFertiliser_Variable()} -> MN_jf | M10: Unit | N10: {=Fertiliser_Equations_InorganicN2O.VEERG_5_1_1_2__1_EmissionFactorIrrigatedMaize_Unit()} -> kg N2O-N/kg N applied
D11: Unit | E11: {=Fertiliser_Equations_InorganicN2O.VEERG_5_1_1_1__2_MassOfNitrogenInInorganicFertiliser_Unit()} -> kg N
M12: {=_xlfn.CHOOSECOLS(Fertiliser_Equations_InorganicN2O.VEERG_5_1_1_2__1_EmissionFactorIrrigatedMaize_Arguments(), 1, 2)} -> N_fjIrrigatedMaize | N12: application rate of inorganic fertiliser type f in the irrigated maize crop (kg N/ha) | Q12: ="See " & $M$41 -> See M2_Table_FertApplications | S12: {=_xlfn.CHOOSECOLS(Fertiliser_Equations_InorganicN2O.VEERG_5_1_1_2__1_EmissionFactorIrrigatedMaize_Arguments(), 3)} -> Input
D13: {=_xlfn.CHOOSECOLS(Fertiliser_Equations_InorganicN2O.VEERG_5_1_1_1__2_MassOfNitrogenInInorganicFertiliser_Arguments(), 1,2)} -> TM_jf | E13: total mass of inorganic fertiliser type f applied to production system j (kg) | G13: ="See " & $D$16 -> See Table_MN_j_f | H13: {=_xlfn.CHOOSECOLS(Fertiliser_Equations_InorganicN2O.VEERG_5_1_1_1__2_MassOfNitrogenInInorganicFertiliser_Arguments(), 3)} -> Input | M13: f | N13: Inorganic fertiliser type | Q13: Not used - application rate calculated per product blend application | S13: Constant
D14: FN_inorganicf | E14: fraction of nitrogen in inorganic fertiliser type f (kg N/kg) | G14: ="See " & $D$16 -> See Table_MN_j_f | H14: Constant
D16: Table_MN_j_f | M16: {=Fertiliser_Equations_InorganicN2O.VEERG_5_1_1_2__2_EmissionFactorNonIrrigatedGrainsHighRainfall_Title()} -> Emission factor for nitrous oxide for non-irrigated grains in high rainfall zone
D17: Mass of nitrogen applied | M17: {=Fertiliser_Equations_InorganicN2O.VEERG_5_1_1_2__2_EmissionFactorNonIrrigatedGrainsHighRainfall_Source()} -> VEERG 2026: 5.1.1.2, Equation (2)
E18: Input | F18: Constant | G18: Calculated
E19: kg | F19: fraction | G19: =$E$11 -> kg N
D20: Fertiliser type f | E20: TMjf | F20: FNinorganic,f | G20: MNjf | M20: Variable | N20: {=Fertiliser_Equations_InorganicN2O.VEERG_5_1_1_2__2_EmissionFactorNonIrrigatedGrainsHighRainfall_Variable()} -> EF_fjNonIrrigatedGrainsN2O
D21: {=Table_Fertiliser_ChemicalCompounds[Fertiliser type f]} -> Monoammonium phosphate (MAP) | E21: {=Fertiliser_InputFunctions.Fertiliser_TotalChemicalCompoundAppliedAllIngredients($D21,Table_Input_InorganicFertiliser_Brands[Total applied (kg)],Table_Input_InorganicFertiliser_Brands[Ingredient 1],Table_Input_InorganicFertiliser_Brands[Ingredient 1 percent],Table_Input_InorganicFertiliser_Brands[Ingredient 2],Table_Input_InorganicFertiliser_Brands[Ingredient 2 percent],Table_Input_InorganicFertiliser_Brands[Ingredient 3],Table_Input_InorganicFertiliser_Brands[Ingredient 3 percent],Table_Input_InorganicFertiliser_Brands[Ingredient 4],Table_Input_InorganicFertiliser_Brands[Ingredient 4 percent],Table_Input_InorganicFertiliser_Brands[Ingredient 5],Table_Input_InorganicFertiliser_Brands[Ingredient 5 percent],Table_Input_InorganicFertiliser_Brands[Ingredient 6],Table_Input_InorganicFertiliser_Brands[Ingredient 6 percent])+ Fertiliser_InputFunctions.Fertiliser_TotalChemicalCompoundAppliedAllIngredients($D21,Table_Input_InorganicFertiliser_Custom[Total applied (kg)],Table_Input_InorganicFertiliser_Custom[Ingredient 1 (select)],Table_Input_InorganicFertiliser_Custom[Ingredient 1 percent],Table_Input_InorganicFertiliser_Custom[Ingredient 2],Table_Input_InorganicFertiliser_Custom[Ingredient 2 percent],Table_Input_InorganicFertiliser_Custom[Ingredient 3],Table_Input_InorganicFertiliser_Custom[Ingredient 3 percent],Table_Input_InorganicFertiliser_Custom[Ingredient 4],Table_Input_InorganicFertiliser_Custom[Ingredient 4 percent])} -> 4000 | F21: {=Common_InputFunctions.Utility_LookupValueInTableNumber(D21,Table_Fertiliser_ChemicalCompounds[Fertiliser type f],Table_Fertiliser_ChemicalCompounds[FNinorganic f])} -> 0.1 | G21: {=Fertiliser_Equations_InorganicN2O.VEERG_5_1_1_1__2_MassOfNitrogenInInorganicFertiliser(E21,F21)} -> 400 | M21: Unit | N21: {=Fertiliser_Equations_InorganicN2O.VEERG_5_1_1_2__2_EmissionFactorNonIrrigatedGrainsHighRainfall_Unit()} -> kg N2O-N/kg N applied
D22: Diammonium phosphate (DAP) | E22: {=Fertiliser_InputFunctions.Fertiliser_TotalChemicalCompoundAppliedAllIngredients($D22,Table_Input_InorganicFertiliser_Brands[Total applied (kg)],Table_Input_InorganicFertiliser_Brands[Ingredient 1],Table_Input_InorganicFertiliser_Brands[Ingredient 1 percent],Table_Input_InorganicFertiliser_Brands[Ingredient 2],Table_Input_InorganicFertiliser_Brands[Ingredient 2 percent],Table_Input_InorganicFertiliser_Brands[Ingredient 3],Table_Input_InorganicFertiliser_Brands[Ingredient 3 percent],Table_Input_InorganicFertiliser_Brands[Ingredient 4],Table_Input_InorganicFertiliser_Brands[Ingredient 4 percent],Table_Input_InorganicFertiliser_Brands[Ingredient 5],Table_Input_InorganicFertiliser_Brands[Ingredient 5 percent],Table_Input_InorganicFertiliser_Brands[Ingredient 6],Table_Input_InorganicFertiliser_Brands[Ingredient 6 percent])+ Fertiliser_InputFunctions.Fertiliser_TotalChemicalCompoundAppliedAllIngredients($D22,Table_Input_InorganicFertiliser_Custom[Total applied (kg)],Table_Input_InorganicFertiliser_Custom[Ingredient 1 (select)],Table_Input_InorganicFertiliser_Custom[Ingredient 1 percent],Table_Input_InorganicFertiliser_Custom[Ingredient 2],Table_Input_InorganicFertiliser_Custom[Ingredient 2 percent],Table_Input_InorganicFertiliser_Custom[Ingredient 3],Table_Input_InorganicFertiliser_Custom[Ingredient 3 percent],Table_Input_InorganicFertiliser_Custom[Ingredient 4],Table_Input_InorganicFertiliser_Custom[Ingredient 4 percent])} -> 0 | F22: {=Common_InputFunctions.Utility_LookupValueInTableNumber(D22,Table_Fertiliser_ChemicalCompounds[Fertiliser type f],Table_Fertiliser_ChemicalCompounds[FNinorganic f])} -> 0.18 | G22: {=Fertiliser_Equations_InorganicN2O.VEERG_5_1_1_1__2_MassOfNitrogenInInorganicFertiliser(E22,F22)} -> 0
D23: Urea | E23: {=Fertiliser_InputFunctions.Fertiliser_TotalChemicalCompoundAppliedAllIngredients($D23,Table_Input_InorganicFertiliser_Brands[Total applied (kg)],Table_Input_InorganicFertiliser_Brands[Ingredient 1],Table_Input_InorganicFertiliser_Brands[Ingredient 1 percent],Table_Input_InorganicFertiliser_Brands[Ingredient 2],Table_Input_InorganicFertiliser_Brands[Ingredient 2 percent],Table_Input_InorganicFertiliser_Brands[Ingredient 3],Table_Input_InorganicFertiliser_Brands[Ingredient 3 percent],Table_Input_InorganicFertiliser_Brands[Ingredient 4],Table_Input_InorganicFertiliser_Brands[Ingredient 4 percent],Table_Input_InorganicFertiliser_Brands[Ingredient 5],Table_Input_InorganicFertiliser_Brands[Ingredient 5 percent],Table_Input_InorganicFertiliser_Brands[Ingredient 6],Table_Input_InorganicFertiliser_Brands[Ingredient 6 percent])+ Fertiliser_InputFunctions.Fertiliser_TotalChemicalCompoundAppliedAllIngredients($D23,Table_Input_InorganicFertiliser_Custom[Total applied (kg)],Table_Input_InorganicFertiliser_Custom[Ingredient 1 (select)],Table_Input_InorganicFertiliser_Custom[Ingredient 1 percent],Table_Input_InorganicFertiliser_Custom[Ingredient 2],Table_Input_InorganicFertiliser_Custom[Ingredient 2 percent],Table_Input_InorganicFertiliser_Custom[Ingredient 3],Table_Input_InorganicFertiliser_Custom[Ingredient 3 percent],Table_Input_InorganicFertiliser_Custom[Ingredient 4],Table_Input_InorganicFertiliser_Custom[Ingredient 4 percent])} -> 0 | F23: {=Common_InputFunctions.Utility_LookupValueInTableNumber(D23,Table_Fertiliser_ChemicalCompounds[Fertiliser type f],Table_Fertiliser_ChemicalCompounds[FNinorganic f])} -> 0.46 | G23: {=Fertiliser_Equations_InorganicN2O.VEERG_5_1_1_1__2_MassOfNitrogenInInorganicFertiliser(E23,F23)} -> 0 | M23: {=_xlfn.CHOOSECOLS(Fertiliser_Equations_InorganicN2O.VEERG_5_1_1_2__2_EmissionFactorNonIrrigatedGrainsHighRainfall_Arguments(), 1, 2)} -> N_fjNonIrrigatedGrains | N23: application rate of inorganic fertiliser type f in the grains crop (kg N/ha) | Q23: ="See " & $M$41 -> See M2_Table_FertApplications | S23: {=_xlfn.CHOOSECOLS(Fertiliser_Equations_InorganicN2O.VEERG_5_1_1_2__2_EmissionFactorNonIrrigatedGrainsHighRainfall_Arguments(), 3)} -> Input
D24: Sulphate of ammonia (SOA) | E24: {=Fertiliser_InputFunctions.Fertiliser_TotalChemicalCompoundAppliedAllIngredients($D24,Table_Input_InorganicFertiliser_Brands[Total applied (kg)],Table_Input_InorganicFertiliser_Brands[Ingredient 1],Table_Input_InorganicFertiliser_Brands[Ingredient 1 percent],Table_Input_InorganicFertiliser_Brands[Ingredient 2],Table_Input_InorganicFertiliser_Brands[Ingredient 2 percent],Table_Input_InorganicFertiliser_Brands[Ingredient 3],Table_Input_InorganicFertiliser_Brands[Ingredient 3 percent],Table_Input_InorganicFertiliser_Brands[Ingredient 4],Table_Input_InorganicFertiliser_Brands[Ingredient 4 percent],Table_Input_InorganicFertiliser_Brands[Ingredient 5],Table_Input_InorganicFertiliser_Brands[Ingredient 5 percent],Table_Input_InorganicFertiliser_Brands[Ingredient 6],Table_Input_InorganicFertiliser_Brands[Ingredient 6 percent])+ Fertiliser_InputFunctions.Fertiliser_TotalChemicalCompoundAppliedAllIngredients($D24,Table_Input_InorganicFertiliser_Custom[Total applied (kg)],Table_Input_InorganicFertiliser_Custom[Ingredient 1 (select)],Table_Input_InorganicFertiliser_Custom[Ingredient 1 percent],Table_Input_InorganicFertiliser_Custom[Ingredient 2],Table_Input_InorganicFertiliser_Custom[Ingredient 2 percent],Table_Input_InorganicFertiliser_Custom[Ingredient 3],Table_Input_InorganicFertiliser_Custom[Ingredient 3 percent],Table_Input_InorganicFertiliser_Custom[Ingredient 4],Table_Input_InorganicFertiliser_Custom[Ingredient 4 percent])} -> 0 | F24: {=Common_InputFunctions.Utility_LookupValueInTableNumber(D24,Table_Fertiliser_ChemicalCompounds[Fertiliser type f],Table_Fertiliser_ChemicalCompounds[FNinorganic f])} -> 0.21 | G24: {=Fertiliser_Equations_InorganicN2O.VEERG_5_1_1_1__2_MassOfNitrogenInInorganicFertiliser(E24,F24)} -> 0 | M24: f | N24: Inorganic fertiliser type | Q24: Not used - application rate calculated per product blend application | S24: Constant
D25: Urea-ammonium nitrate (UAN) | E25: {=Fertiliser_InputFunctions.Fertiliser_TotalChemicalCompoundAppliedAllIngredients($D25,Table_Input_InorganicFertiliser_Brands[Total applied (kg)],Table_Input_InorganicFertiliser_Brands[Ingredient 1],Table_Input_InorganicFertiliser_Brands[Ingredient 1 percent],Table_Input_InorganicFertiliser_Brands[Ingredient 2],Table_Input_InorganicFertiliser_Brands[Ingredient 2 percent],Table_Input_InorganicFertiliser_Brands[Ingredient 3],Table_Input_InorganicFertiliser_Brands[Ingredient 3 percent],Table_Input_InorganicFertiliser_Brands[Ingredient 4],Table_Input_InorganicFertiliser_Brands[Ingredient 4 percent],Table_Input_InorganicFertiliser_Brands[Ingredient 5],Table_Input_InorganicFertiliser_Brands[Ingredient 5 percent],Table_Input_InorganicFertiliser_Brands[Ingredient 6],Table_Input_InorganicFertiliser_Brands[Ingredient 6 percent])+ Fertiliser_InputFunctions.Fertiliser_TotalChemicalCompoundAppliedAllIngredients($D25,Table_Input_InorganicFertiliser_Custom[Total applied (kg)],Table_Input_InorganicFertiliser_Custom[Ingredient 1 (select)],Table_Input_InorganicFertiliser_Custom[Ingredient 1 percent],Table_Input_InorganicFertiliser_Custom[Ingredient 2],Table_Input_InorganicFertiliser_Custom[Ingredient 2 percent],Table_Input_InorganicFertiliser_Custom[Ingredient 3],Table_Input_InorganicFertiliser_Custom[Ingredient 3 percent],Table_Input_InorganicFertiliser_Custom[Ingredient 4],Table_Input_InorganicFertiliser_Custom[Ingredient 4 percent])} -> 16000 | F25: {=Common_InputFunctions.Utility_LookupValueInTableNumber(D25,Table_Fertiliser_ChemicalCompounds[Fertiliser type f],Table_Fertiliser_ChemicalCompounds[FNinorganic f])} -> 0.32 | G25: {=Fertiliser_Equations_InorganicN2O.VEERG_5_1_1_1__2_MassOfNitrogenInInorganicFertiliser(E25,F25)} -> 5120
D26: Ammonium nitrate (AN) | E26: {=Fertiliser_InputFunctions.Fertiliser_TotalChemicalCompoundAppliedAllIngredients($D26,Table_Input_InorganicFertiliser_Brands[Total applied (kg)],Table_Input_InorganicFertiliser_Brands[Ingredient 1],Table_Input_InorganicFertiliser_Brands[Ingredient 1 percent],Table_Input_InorganicFertiliser_Brands[Ingredient 2],Table_Input_InorganicFertiliser_Brands[Ingredient 2 percent],Table_Input_InorganicFertiliser_Brands[Ingredient 3],Table_Input_InorganicFertiliser_Brands[Ingredient 3 percent],Table_Input_InorganicFertiliser_Brands[Ingredient 4],Table_Input_InorganicFertiliser_Brands[Ingredient 4 percent],Table_Input_InorganicFertiliser_Brands[Ingredient 5],Table_Input_InorganicFertiliser_Brands[Ingredient 5 percent],Table_Input_InorganicFertiliser_Brands[Ingredient 6],Table_Input_InorganicFertiliser_Brands[Ingredient 6 percent])+ Fertiliser_InputFunctions.Fertiliser_TotalChemicalCompoundAppliedAllIngredients($D26,Table_Input_InorganicFertiliser_Custom[Total applied (kg)],Table_Input_InorganicFertiliser_Custom[Ingredient 1 (select)],Table_Input_InorganicFertiliser_Custom[Ingredient 1 percent],Table_Input_InorganicFertiliser_Custom[Ingredient 2],Table_Input_InorganicFertiliser_Custom[Ingredient 2 percent],Table_Input_InorganicFertiliser_Custom[Ingredient 3],Table_Input_InorganicFertiliser_Custom[Ingredient 3 percent],Table_Input_InorganicFertiliser_Custom[Ingredient 4],Table_Input_InorganicFertiliser_Custom[Ingredient 4 percent])} -> 0 | F26: {=Common_InputFunctions.Utility_LookupValueInTableNumber(D26,Table_Fertiliser_ChemicalCompounds[Fertiliser type f],Table_Fertiliser_ChemicalCompounds[FNinorganic f])} -> 0.337 | G26: {=Fertiliser_Equations_InorganicN2O.VEERG_5_1_1_1__2_MassOfNitrogenInInorganicFertiliser(E26,F26)} -> 0
D27: Calcium ammonium nitrate (CAN) | E27: {=Fertiliser_InputFunctions.Fertiliser_TotalChemicalCompoundAppliedAllIngredients($D27,Table_Input_InorganicFertiliser_Brands[Total applied (kg)],Table_Input_InorganicFertiliser_Brands[Ingredient 1],Table_Input_InorganicFertiliser_Brands[Ingredient 1 percent],Table_Input_InorganicFertiliser_Brands[Ingredient 2],Table_Input_InorganicFertiliser_Brands[Ingredient 2 percent],Table_Input_InorganicFertiliser_Brands[Ingredient 3],Table_Input_InorganicFertiliser_Brands[Ingredient 3 percent],Table_Input_InorganicFertiliser_Brands[Ingredient 4],Table_Input_InorganicFertiliser_Brands[Ingredient 4 percent],Table_Input_InorganicFertiliser_Brands[Ingredient 5],Table_Input_InorganicFertiliser_Brands[Ingredient 5 percent],Table_Input_InorganicFertiliser_Brands[Ingredient 6],Table_Input_InorganicFertiliser_Brands[Ingredient 6 percent])+ Fertiliser_InputFunctions.Fertiliser_TotalChemicalCompoundAppliedAllIngredients($D27,Table_Input_InorganicFertiliser_Custom[Total applied (kg)],Table_Input_InorganicFertiliser_Custom[Ingredient 1 (select)],Table_Input_InorganicFertiliser_Custom[Ingredient 1 percent],Table_Input_InorganicFertiliser_Custom[Ingredient 2],Table_Input_InorganicFertiliser_Custom[Ingredient 2 percent],Table_Input_InorganicFertiliser_Custom[Ingredient 3],Table_Input_InorganicFertiliser_Custom[Ingredient 3 percent],Table_Input_InorganicFertiliser_Custom[Ingredient 4],Table_Input_InorganicFertiliser_Custom[Ingredient 4 percent])} -> 0 | F27: {=Common_InputFunctions.Utility_LookupValueInTableNumber(D27,Table_Fertiliser_ChemicalCompounds[Fertiliser type f],Table_Fertiliser_ChemicalCompounds[FNinorganic f])} -> 0.27 | G27: {=Fertiliser_Equations_InorganicN2O.VEERG_5_1_1_1__2_MassOfNitrogenInInorganicFertiliser(E27,F27)} -> 0 | M27: {=Fertiliser_Equations_InorganicN2O.VEERG_5_1_1_2__3_EmissionFactorCotton_Title()} -> Emission factor for nitrous oxide for cotton
D28: Nitrogen - Ammoniacal | E28: {=Fertiliser_InputFunctions.Fertiliser_TotalChemicalCompoundAppliedAllIngredients($D28,Table_Input_InorganicFertiliser_Brands[Total applied (kg)],Table_Input_InorganicFertiliser_Brands[Ingredient 1],Table_Input_InorganicFertiliser_Brands[Ingredient 1 percent],Table_Input_InorganicFertiliser_Brands[Ingredient 2],Table_Input_InorganicFertiliser_Brands[Ingredient 2 percent],Table_Input_InorganicFertiliser_Brands[Ingredient 3],Table_Input_InorganicFertiliser_Brands[Ingredient 3 percent],Table_Input_InorganicFertiliser_Brands[Ingredient 4],Table_Input_InorganicFertiliser_Brands[Ingredient 4 percent],Table_Input_InorganicFertiliser_Brands[Ingredient 5],Table_Input_InorganicFertiliser_Brands[Ingredient 5 percent],Table_Input_InorganicFertiliser_Brands[Ingredient 6],Table_Input_InorganicFertiliser_Brands[Ingredient 6 percent])+ Fertiliser_InputFunctions.Fertiliser_TotalChemicalCompoundAppliedAllIngredients($D28,Table_Input_InorganicFertiliser_Custom[Total applied (kg)],Table_Input_InorganicFertiliser_Custom[Ingredient 1 (select)],Table_Input_InorganicFertiliser_Custom[Ingredient 1 percent],Table_Input_InorganicFertiliser_Custom[Ingredient 2],Table_Input_InorganicFertiliser_Custom[Ingredient 2 percent],Table_Input_InorganicFertiliser_Custom[Ingredient 3],Table_Input_InorganicFertiliser_Custom[Ingredient 3 percent],Table_Input_InorganicFertiliser_Custom[Ingredient 4],Table_Input_InorganicFertiliser_Custom[Ingredient 4 percent])} -> 0 | F28: {=Common_InputFunctions.Utility_LookupValueInTableNumber(D28,Table_Fertiliser_ChemicalCompounds[Fertiliser type f],Table_Fertiliser_ChemicalCompounds[FNinorganic f])} -> 1 | G28: {=Fertiliser_Equations_InorganicN2O.VEERG_5_1_1_1__2_MassOfNitrogenInInorganicFertiliser(E28,F28)} -> 0 | M28: {=Fertiliser_Equations_InorganicN2O.VEERG_5_1_1_2__3_EmissionFactorCotton_Source()} -> VEERG 2026: 5.1.1.2, Equation (3)
D29: Nitrogen - Nitrate | E29: {=Fertiliser_InputFunctions.Fertiliser_TotalChemicalCompoundAppliedAllIngredients($D29,Table_Input_InorganicFertiliser_Brands[Total applied (kg)],Table_Input_InorganicFertiliser_Brands[Ingredient 1],Table_Input_InorganicFertiliser_Brands[Ingredient 1 percent],Table_Input_InorganicFertiliser_Brands[Ingredient 2],Table_Input_InorganicFertiliser_Brands[Ingredient 2 percent],Table_Input_InorganicFertiliser_Brands[Ingredient 3],Table_Input_InorganicFertiliser_Brands[Ingredient 3 percent],Table_Input_InorganicFertiliser_Brands[Ingredient 4],Table_Input_InorganicFertiliser_Brands[Ingredient 4 percent],Table_Input_InorganicFertiliser_Brands[Ingredient 5],Table_Input_InorganicFertiliser_Brands[Ingredient 5 percent],Table_Input_InorganicFertiliser_Brands[Ingredient 6],Table_Input_InorganicFertiliser_Brands[Ingredient 6 percent])+ Fertiliser_InputFunctions.Fertiliser_TotalChemicalCompoundAppliedAllIngredients($D29,Table_Input_InorganicFertiliser_Custom[Total applied (kg)],Table_Input_InorganicFertiliser_Custom[Ingredient 1 (select)],Table_Input_InorganicFertiliser_Custom[Ingredient 1 percent],Table_Input_InorganicFertiliser_Custom[Ingredient 2],Table_Input_InorganicFertiliser_Custom[Ingredient 2 percent],Table_Input_InorganicFertiliser_Custom[Ingredient 3],Table_Input_InorganicFertiliser_Custom[Ingredient 3 percent],Table_Input_InorganicFertiliser_Custom[Ingredient 4],Table_Input_InorganicFertiliser_Custom[Ingredient 4 percent])} -> 0 | F29: {=Common_InputFunctions.Utility_LookupValueInTableNumber(D29,Table_Fertiliser_ChemicalCompounds[Fertiliser type f],Table_Fertiliser_ChemicalCompounds[FNinorganic f])} -> 1 | G29: {=Fertiliser_Equations_InorganicN2O.VEERG_5_1_1_1__2_MassOfNitrogenInInorganicFertiliser(E29,F29)} -> 0
D30: Nitrogen - generic | E30: {=Fertiliser_InputFunctions.Fertiliser_TotalChemicalCompoundAppliedAllIngredients($D30,Table_Input_InorganicFertiliser_Brands[Total applied (kg)],Table_Input_InorganicFertiliser_Brands[Ingredient 1],Table_Input_InorganicFertiliser_Brands[Ingredient 1 percent],Table_Input_InorganicFertiliser_Brands[Ingredient 2],Table_Input_InorganicFertiliser_Brands[Ingredient 2 percent],Table_Input_InorganicFertiliser_Brands[Ingredient 3],Table_Input_InorganicFertiliser_Brands[Ingredient 3 percent],Table_Input_InorganicFertiliser_Brands[Ingredient 4],Table_Input_InorganicFertiliser_Brands[Ingredient 4 percent],Table_Input_InorganicFertiliser_Brands[Ingredient 5],Table_Input_InorganicFertiliser_Brands[Ingredient 5 percent],Table_Input_InorganicFertiliser_Brands[Ingredient 6],Table_Input_InorganicFertiliser_Brands[Ingredient 6 percent])+ Fertiliser_InputFunctions.Fertiliser_TotalChemicalCompoundAppliedAllIngredients($D30,Table_Input_InorganicFertiliser_Custom[Total applied (kg)],Table_Input_InorganicFertiliser_Custom[Ingredient 1 (select)],Table_Input_InorganicFertiliser_Custom[Ingredient 1 percent],Table_Input_InorganicFertiliser_Custom[Ingredient 2],Table_Input_InorganicFertiliser_Custom[Ingredient 2 percent],Table_Input_InorganicFertiliser_Custom[Ingredient 3],Table_Input_InorganicFertiliser_Custom[Ingredient 3 percent],Table_Input_InorganicFertiliser_Custom[Ingredient 4],Table_Input_InorganicFertiliser_Custom[Ingredient 4 percent])} -> 9000 | F30: {=Common_InputFunctions.Utility_LookupValueInTableNumber(D30,Table_Fertiliser_ChemicalCompounds[Fertiliser type f],Table_Fertiliser_ChemicalCompounds[FNinorganic f])} -> 1 | G30: {=Fertiliser_Equations_InorganicN2O.VEERG_5_1_1_1__2_MassOfNitrogenInInorganicFertiliser(E30,F30)} -> 9000
D31: Phosphorus - generic | E31: {=Fertiliser_InputFunctions.Fertiliser_TotalChemicalCompoundAppliedAllIngredients($D31,Table_Input_InorganicFertiliser_Brands[Total applied (kg)],Table_Input_InorganicFertiliser_Brands[Ingredient 1],Table_Input_InorganicFertiliser_Brands[Ingredient 1 percent],Table_Input_InorganicFertiliser_Brands[Ingredient 2],Table_Input_InorganicFertiliser_Brands[Ingredient 2 percent],Table_Input_InorganicFertiliser_Brands[Ingredient 3],Table_Input_InorganicFertiliser_Brands[Ingredient 3 percent],Table_Input_InorganicFertiliser_Brands[Ingredient 4],Table_Input_InorganicFertiliser_Brands[Ingredient 4 percent],Table_Input_InorganicFertiliser_Brands[Ingredient 5],Table_Input_InorganicFertiliser_Brands[Ingredient 5 percent],Table_Input_InorganicFertiliser_Brands[Ingredient 6],Table_Input_InorganicFertiliser_Brands[Ingredient 6 percent])+ Fertiliser_InputFunctions.Fertiliser_TotalChemicalCompoundAppliedAllIngredients($D31,Table_Input_InorganicFertiliser_Custom[Total applied (kg)],Table_Input_InorganicFertiliser_Custom[Ingredient 1 (select)],Table_Input_InorganicFertiliser_Custom[Ingredient 1 percent],Table_Input_InorganicFertiliser_Custom[Ingredient 2],Table_Input_InorganicFertiliser_Custom[Ingredient 2 percent],Table_Input_InorganicFertiliser_Custom[Ingredient 3],Table_Input_InorganicFertiliser_Custom[Ingredient 3 percent],Table_Input_InorganicFertiliser_Custom[Ingredient 4],Table_Input_InorganicFertiliser_Custom[Ingredient 4 percent])} -> 6000 | F31: {=Common_InputFunctions.Utility_LookupValueInTableNumber(D31,Table_Fertiliser_ChemicalCompounds[Fertiliser type f],Table_Fertiliser_ChemicalCompounds[FNinorganic f])} -> 0 | G31: {=Fertiliser_Equations_InorganicN2O.VEERG_5_1_1_1__2_MassOfNitrogenInInorganicFertiliser(E31,F31)} -> 0
D32: Potassium - generic | E32: {=Fertiliser_InputFunctions.Fertiliser_TotalChemicalCompoundAppliedAllIngredients($D32,Table_Input_InorganicFertiliser_Brands[Total applied (kg)],Table_Input_InorganicFertiliser_Brands[Ingredient 1],Table_Input_InorganicFertiliser_Brands[Ingredient 1 percent],Table_Input_InorganicFertiliser_Brands[Ingredient 2],Table_Input_InorganicFertiliser_Brands[Ingredient 2 percent],Table_Input_InorganicFertiliser_Brands[Ingredient 3],Table_Input_InorganicFertiliser_Brands[Ingredient 3 percent],Table_Input_InorganicFertiliser_Brands[Ingredient 4],Table_Input_InorganicFertiliser_Brands[Ingredient 4 percent],Table_Input_InorganicFertiliser_Brands[Ingredient 5],Table_Input_InorganicFertiliser_Brands[Ingredient 5 percent],Table_Input_InorganicFertiliser_Brands[Ingredient 6],Table_Input_InorganicFertiliser_Brands[Ingredient 6 percent])+ Fertiliser_InputFunctions.Fertiliser_TotalChemicalCompoundAppliedAllIngredients($D32,Table_Input_InorganicFertiliser_Custom[Total applied (kg)],Table_Input_InorganicFertiliser_Custom[Ingredient 1 (select)],Table_Input_InorganicFertiliser_Custom[Ingredient 1 percent],Table_Input_InorganicFertiliser_Custom[Ingredient 2],Table_Input_InorganicFertiliser_Custom[Ingredient 2 percent],Table_Input_InorganicFertiliser_Custom[Ingredient 3],Table_Input_InorganicFertiliser_Custom[Ingredient 3 percent],Table_Input_InorganicFertiliser_Custom[Ingredient 4],Table_Input_InorganicFertiliser_Custom[Ingredient 4 percent])} -> 2000 | F32: {=Common_InputFunctions.Utility_LookupValueInTableNumber(D32,Table_Fertiliser_ChemicalCompounds[Fertiliser type f],Table_Fertiliser_ChemicalCompounds[FNinorganic f])} -> 0 | G32: {=Fertiliser_Equations_InorganicN2O.VEERG_5_1_1_1__2_MassOfNitrogenInInorganicFertiliser(E32,F32)} -> 0 | M32: Variable | N32: {=Fertiliser_Equations_InorganicN2O.VEERG_5_1_1_2__3_EmissionFactorCotton_Variable()} -> EF_fjCottonN2O
D33: Sulfur - generic | E33: {=Fertiliser_InputFunctions.Fertiliser_TotalChemicalCompoundAppliedAllIngredients($D33,Table_Input_InorganicFertiliser_Brands[Total applied (kg)],Table_Input_InorganicFertiliser_Brands[Ingredient 1],Table_Input_InorganicFertiliser_Brands[Ingredient 1 percent],Table_Input_InorganicFertiliser_Brands[Ingredient 2],Table_Input_InorganicFertiliser_Brands[Ingredient 2 percent],Table_Input_InorganicFertiliser_Brands[Ingredient 3],Table_Input_InorganicFertiliser_Brands[Ingredient 3 percent],Table_Input_InorganicFertiliser_Brands[Ingredient 4],Table_Input_InorganicFertiliser_Brands[Ingredient 4 percent],Table_Input_InorganicFertiliser_Brands[Ingredient 5],Table_Input_InorganicFertiliser_Brands[Ingredient 5 percent],Table_Input_InorganicFertiliser_Brands[Ingredient 6],Table_Input_InorganicFertiliser_Brands[Ingredient 6 percent])+ Fertiliser_InputFunctions.Fertiliser_TotalChemicalCompoundAppliedAllIngredients($D33,Table_Input_InorganicFertiliser_Custom[Total applied (kg)],Table_Input_InorganicFertiliser_Custom[Ingredient 1 (select)],Table_Input_InorganicFertiliser_Custom[Ingredient 1 percent],Table_Input_InorganicFertiliser_Custom[Ingredient 2],Table_Input_InorganicFertiliser_Custom[Ingredient 2 percent],Table_Input_InorganicFertiliser_Custom[Ingredient 3],Table_Input_InorganicFertiliser_Custom[Ingredient 3 percent],Table_Input_InorganicFertiliser_Custom[Ingredient 4],Table_Input_InorganicFertiliser_Custom[Ingredient 4 percent])} -> 1000 | F33: {=Common_InputFunctions.Utility_LookupValueInTableNumber(D33,Table_Fertiliser_ChemicalCompounds[Fertiliser type f],Table_Fertiliser_ChemicalCompounds[FNinorganic f])} -> 0 | G33: {=Fertiliser_Equations_InorganicN2O.VEERG_5_1_1_1__2_MassOfNitrogenInInorganicFertiliser(E33,F33)} -> 0 | M33: Unit | N33: {=Fertiliser_Equations_InorganicN2O.VEERG_5_1_1_2__3_EmissionFactorCotton_Unit()} -> kg N2O-N/kg N applied
D34: Zinc - generic | E34: {=Fertiliser_InputFunctions.Fertiliser_TotalChemicalCompoundAppliedAllIngredients($D34,Table_Input_InorganicFertiliser_Brands[Total applied (kg)],Table_Input_InorganicFertiliser_Brands[Ingredient 1],Table_Input_InorganicFertiliser_Brands[Ingredient 1 percent],Table_Input_InorganicFertiliser_Brands[Ingredient 2],Table_Input_InorganicFertiliser_Brands[Ingredient 2 percent],Table_Input_InorganicFertiliser_Brands[Ingredient 3],Table_Input_InorganicFertiliser_Brands[Ingredient 3 percent],Table_Input_InorganicFertiliser_Brands[Ingredient 4],Table_Input_InorganicFertiliser_Brands[Ingredient 4 percent],Table_Input_InorganicFertiliser_Brands[Ingredient 5],Table_Input_InorganicFertiliser_Brands[Ingredient 5 percent],Table_Input_InorganicFertiliser_Brands[Ingredient 6],Table_Input_InorganicFertiliser_Brands[Ingredient 6 percent])+ Fertiliser_InputFunctions.Fertiliser_TotalChemicalCompoundAppliedAllIngredients($D34,Table_Input_InorganicFertiliser_Custom[Total applied (kg)],Table_Input_InorganicFertiliser_Custom[Ingredient 1 (select)],Table_Input_InorganicFertiliser_Custom[Ingredient 1 percent],Table_Input_InorganicFertiliser_Custom[Ingredient 2],Table_Input_InorganicFertiliser_Custom[Ingredient 2 percent],Table_Input_InorganicFertiliser_Custom[Ingredient 3],Table_Input_InorganicFertiliser_Custom[Ingredient 3 percent],Table_Input_InorganicFertiliser_Custom[Ingredient 4],Table_Input_InorganicFertiliser_Custom[Ingredient 4 percent])} -> 0 | F34: {=Common_InputFunctions.Utility_LookupValueInTableNumber(D34,Table_Fertiliser_ChemicalCompounds[Fertiliser type f],Table_Fertiliser_ChemicalCompounds[FNinorganic f])} -> 0 | G34: {=Fertiliser_Equations_InorganicN2O.VEERG_5_1_1_1__2_MassOfNitrogenInInorganicFertiliser(E34,F34)} -> 0
D35: Muriate of potash (MOP) | E35: {=Fertiliser_InputFunctions.Fertiliser_TotalChemicalCompoundAppliedAllIngredients($D35,Table_Input_InorganicFertiliser_Brands[Total applied (kg)],Table_Input_InorganicFertiliser_Brands[Ingredient 1],Table_Input_InorganicFertiliser_Brands[Ingredient 1 percent],Table_Input_InorganicFertiliser_Brands[Ingredient 2],Table_Input_InorganicFertiliser_Brands[Ingredient 2 percent],Table_Input_InorganicFertiliser_Brands[Ingredient 3],Table_Input_InorganicFertiliser_Brands[Ingredient 3 percent],Table_Input_InorganicFertiliser_Brands[Ingredient 4],Table_Input_InorganicFertiliser_Brands[Ingredient 4 percent],Table_Input_InorganicFertiliser_Brands[Ingredient 5],Table_Input_InorganicFertiliser_Brands[Ingredient 5 percent],Table_Input_InorganicFertiliser_Brands[Ingredient 6],Table_Input_InorganicFertiliser_Brands[Ingredient 6 percent])+ Fertiliser_InputFunctions.Fertiliser_TotalChemicalCompoundAppliedAllIngredients($D35,Table_Input_InorganicFertiliser_Custom[Total applied (kg)],Table_Input_InorganicFertiliser_Custom[Ingredient 1 (select)],Table_Input_InorganicFertiliser_Custom[Ingredient 1 percent],Table_Input_InorganicFertiliser_Custom[Ingredient 2],Table_Input_InorganicFertiliser_Custom[Ingredient 2 percent],Table_Input_InorganicFertiliser_Custom[Ingredient 3],Table_Input_InorganicFertiliser_Custom[Ingredient 3 percent],Table_Input_InorganicFertiliser_Custom[Ingredient 4],Table_Input_InorganicFertiliser_Custom[Ingredient 4 percent])} -> 0 | F35: {=Common_InputFunctions.Utility_LookupValueInTableNumber(D35,Table_Fertiliser_ChemicalCompounds[Fertiliser type f],Table_Fertiliser_ChemicalCompounds[FNinorganic f])} -> 0 | G35: {=Fertiliser_Equations_InorganicN2O.VEERG_5_1_1_1__2_MassOfNitrogenInInorganicFertiliser(E35,F35)} -> 0 | M35: {=_xlfn.CHOOSECOLS(Fertiliser_Equations_InorganicN2O.VEERG_5_1_1_2__3_EmissionFactorCotton_Arguments(), 1, 2)} -> N_fjCotton | N35: application rate of inorganic fertiliser type f in the cotton crop (kg N/ha) | Q35: ="See " & $M$41 -> See M2_Table_FertApplications | S35: {=_xlfn.CHOOSECOLS(Fertiliser_Equations_InorganicN2O.VEERG_5_1_1_2__3_EmissionFactorCotton_Arguments(), 3)} -> Input
D36: Double superphosphate | E36: {=Fertiliser_InputFunctions.Fertiliser_TotalChemicalCompoundAppliedAllIngredients($D36,Table_Input_InorganicFertiliser_Brands[Total applied (kg)],Table_Input_InorganicFertiliser_Brands[Ingredient 1],Table_Input_InorganicFertiliser_Brands[Ingredient 1 percent],Table_Input_InorganicFertiliser_Brands[Ingredient 2],Table_Input_InorganicFertiliser_Brands[Ingredient 2 percent],Table_Input_InorganicFertiliser_Brands[Ingredient 3],Table_Input_InorganicFertiliser_Brands[Ingredient 3 percent],Table_Input_InorganicFertiliser_Brands[Ingredient 4],Table_Input_InorganicFertiliser_Brands[Ingredient 4 percent],Table_Input_InorganicFertiliser_Brands[Ingredient 5],Table_Input_InorganicFertiliser_Brands[Ingredient 5 percent],Table_Input_InorganicFertiliser_Brands[Ingredient 6],Table_Input_InorganicFertiliser_Brands[Ingredient 6 percent])+ Fertiliser_InputFunctions.Fertiliser_TotalChemicalCompoundAppliedAllIngredients($D36,Table_Input_InorganicFertiliser_Custom[Total applied (kg)],Table_Input_InorganicFertiliser_Custom[Ingredient 1 (select)],Table_Input_InorganicFertiliser_Custom[Ingredient 1 percent],Table_Input_InorganicFertiliser_Custom[Ingredient 2],Table_Input_InorganicFertiliser_Custom[Ingredient 2 percent],Table_Input_InorganicFertiliser_Custom[Ingredient 3],Table_Input_InorganicFertiliser_Custom[Ingredient 3 percent],Table_Input_InorganicFertiliser_Custom[Ingredient 4],Table_Input_InorganicFertiliser_Custom[Ingredient 4 percent])} -> 0 | F36: {=Common_InputFunctions.Utility_LookupValueInTableNumber(D36,Table_Fertiliser_ChemicalCompounds[Fertiliser type f],Table_Fertiliser_ChemicalCompounds[FNinorganic f])} -> 0 | G36: {=Fertiliser_Equations_InorganicN2O.VEERG_5_1_1_1__2_MassOfNitrogenInInorganicFertiliser(E36,F36)} -> 0 | M36: f | N36: Inorganic fertiliser type | Q36: Not used - application rate calculated per product blend application | S36: Constant
