Workbook
Name _Toc225350871: '5.4.1.1-4 Atmos deposition'!$C$1
Name _Toc225350871: '5.5.1.1-2 Leaching and runoff'!$C$1
Name Common_Equations.Common_ConvertCH4ToCO2e: _xlfn.LAMBDA(_xlpm.E_CH4,_xlpm.GWP_CH4, _xlpm.E_CH4 * _xlpm.GWP_CH4)
Name Common_Equations.Common_ConvertCH4ToCO2e_Arguments: _xlfn.LAMBDA(_xlfn.MAKEARRAY(2, 2, _xlfn.LAMBDA(_xlpm.r,_xlpm.c, INDEX({"ECH4","Methane emissions (t CH4)";"GWPCH4","Global warming potential for methane (t CO2-e / t CH4)"}, _xlpm.r, _xlpm.c))))
Name Common_Equations.Common_ConvertCH4ToCO2e_LatexEquation: _xlfn.LAMBDA("CO2_e = E_{CH4} \times GWP_{CH4}")
Name Common_Equations.Common_ConvertCH4ToCO2e_NIRReference: _xlfn.LAMBDA("")
Name Common_Equations.Common_ConvertCH4ToCO2e_Title: _xlfn.LAMBDA("Convert methane emissions to carbon dioxide equivalent emissions")
Name Common_Equations.Common_ConvertCH4ToCO2e_Unit: _xlfn.LAMBDA("t CO2e")
Name Common_Equations.Common_ConvertCH4ToCO2e_Variable: _xlfn.LAMBDA("ECH4 CO2e")
Name Common_Equations.Common_ConvertN2OToCO2e: _xlfn.LAMBDA(_xlpm.E_N2O,_xlpm.GWP_N2O, _xlpm.E_N2O * _xlpm.GWP_N2O)
Name Common_Equations.Common_ConvertN2OToCO2e_LatexEquation: _xlfn.LAMBDA("CO2_e = E_{N2O} \times GWP_{N2O}")
Name Common_Equations.Common_ConvertN2OToCO2e_NIRReference: _xlfn.LAMBDA("")
Name Common_Equations.Common_ConvertN2OToCO2e_Title: _xlfn.LAMBDA("Convert nitrous oxide emissions to carbon dioxide equivalent emissions")
Name Common_Equations.Common_ConvertN2OToCO2e_Unit: _xlfn.LAMBDA("t CO2e")
Name Common_Equations.Common_ConvertN2OToCO2e_Variable: _xlfn.LAMBDA("EN2O CO2e")
Name Common_InputFunctions.Utility_ConvertStateCommonNameToAbbreviation: _xlfn.LAMBDA(_xlpm.StateCommonName,_xlpm.StateCommonNameArray,_xlpm.StateAbbreviationArray, _xlfn.XLOOKUP(_xlpm.StateCommonName, _xlpm.StateCommonNameArray, _xlpm.StateAbbreviationArray, ""))
Name Common_InputFunctions.Utility_DisplayArguments_1_2: _xlfn.LAMBDA(_xlpm.ArgumentsArray, _xlfn.CHOOSECOLS(_xlpm.ArgumentsArray, 1, 2))
Name Common_InputFunctions.Utility_DisplayArguments_3_4: _xlfn.LAMBDA(_xlpm.ArgumentsArray, _xlfn.CHOOSECOLS(_xlpm.ArgumentsArray, 3, 4))
Name Common_InputFunctions.Utility_DisplayFunctionName: _xlfn.LAMBDA(_xlpm.Function, _xlfn.TEXTBEFORE(_xlfn.FORMULATEXT(_xlpm.Function), "("))
Name Common_InputFunctions.Utility_GetArrayTableColumnStartNumber: _xlfn.LAMBDA(_xlpm.TableHeaderCell, COLUMN(_xlpm.TableHeaderCell))
Name Common_InputFunctions.Utility_GetArrayTableRowStartNumber: _xlfn.LAMBDA(_xlpm.TableheaderCell,_xlpm.RowsBetweenHeaderandArray, ROW(_xlpm.TableheaderCell) + _xlpm.RowsBetweenHeaderandArray - 1)
Name Common_InputFunctions.Utility_LookupValueInTable: _xlfn.LAMBDA(_xlpm.LookupValue,_xlpm.LookupArray,_xlpm.ReturnArray, _xlfn.XLOOKUP(_xlpm.LookupValue, _xlpm.LookupArray, _xlpm.ReturnArray, ""))
Name Common_InputFunctions.Utility_SourceHyperlink: _xlfn.LAMBDA(_xlpm.TargetCell, _xlfn.LET(_xlpm.sh, _xlfn.TEXTAFTER(CELL("filename", _xlpm.TargetCell), "]"), _xlpm.addr, CELL("address", _xlpm.TargetCell), "#'" & _xlpm.sh & "'!" & _xlpm.addr))
Name Common_SourceData.Common_SourceData_AustralianStatesTerritories_Source: _xlfn.LAMBDA("")
Name Common_SourceData.Common_SourceData_AustralianStatesTerritories_Title: _xlfn.LAMBDA("Australian states and territories")
Name Common_SourceData.Common_SourceData_AustralianStatesTerritories_Unit: _xlfn.LAMBDA("")
Name Common_SourceData.Common_SourceData_AustralianStatesTerritories_Variable: _xlfn.LAMBDA("")
Name Common_SourceData.Common_SourceData_ClimateZones_Source: _xlfn.LAMBDA("VEERG 2026: Table 1.3: Climate and Rainfall zone classifications and definitions")
Name Common_SourceData.Common_SourceData_ClimateZones_Title: _xlfn.LAMBDA("VEERG Australian climate zones")
Name Common_SourceData.Common_SourceData_ClimateZones_Unit: _xlfn.LAMBDA("")
Name Common_SourceData.Common_SourceData_ClimateZones_Variable: _xlfn.LAMBDA("")
Name Common_SourceData.Common_SourceData_ConvertGasElementalToMolecular_Source: _xlfn.LAMBDA("XXXXXXX")
Name Common_SourceData.Common_SourceData_ConvertGasElementalToMolecular_Title: _xlfn.LAMBDA("Factor to convert elemental mass of gas to molecular mass")
Name Common_SourceData.Common_SourceData_ConvertGasElementalToMolecular_Unit: _xlfn.LAMBDA("factor")
Name Common_SourceData.Common_SourceData_ConvertGasElementalToMolecular_Variable: _xlfn.LAMBDA("Cg")
Name Common_SourceData.Common_SourceData_ConvertN2oElementalToMolecularCg_Data: _xlfn.LAMBDA(44 / 28)
Name Common_SourceData.Common_SourceData_ConvertN2oElementalToMolecularCg_Source: _xlfn.LAMBDA("National Inventory Report 2023 Volume 1")
Name Common_SourceData.Common_SourceData_ConvertN2oElementalToMolecularCg_Title: _xlfn.LAMBDA("Factor to convert elemental mass of N2O to molecular mass")
Name Common_SourceData.Common_SourceData_ConvertN2oElementalToMolecularCg_Unit: _xlfn.LAMBDA("factor")
Name Common_SourceData.Common_SourceData_ConvertN2oElementalToMolecularCg_Variable: _xlfn.LAMBDA("CgN2O")
Name Common_SourceData.Common_SourceData_DataScores_Scope3_Source: _xlfn.LAMBDA("VEERG 2026: XXXXXXXX")
Name Common_SourceData.Common_SourceData_DataScores_Scope3_Title: _xlfn.LAMBDA("Australian data scores for scope 3")
Name Common_SourceData.Common_SourceData_DataScores_Scope3_Unit: _xlfn.LAMBDA("")
Name Common_SourceData.Common_SourceData_DataScores_Scope3_Variable: _xlfn.LAMBDA("")
Name Common_SourceData.Common_SourceData_DataScores_Scope3_Variation: _xlfn.LAMBDA("")
Name Common_SourceData.Common_SourceData_DensityOfMethane_Data: _xlfn.LAMBDA(0.6784)
Name Common_SourceData.Common_SourceData_DensityOfMethane_Source: _xlfn.LAMBDA("National Inventory Report 2023 Volume 1: Equations 3.B.1a_2, 3.B.1c_2, 3.B.3_1, 3.B.4g_2")
Name Common_SourceData.Common_SourceData_DensityOfMethane_Title: _xlfn.LAMBDA("p = density of methane")
Name Common_SourceData.Common_SourceData_DensityOfMethane_Unit: _xlfn.LAMBDA("kg/m3")
Name Common_SourceData.Common_SourceData_EFleach_Data: _xlfn.LAMBDA(_xlfn.MAKEARRAY(1, 2, _xlfn.LAMBDA(_xlpm.r,_xlpm.c, INDEX({"EFleach",0.011}, _xlpm.r, _xlpm.c))))
Name Common_SourceData.Common_SourceData_EFleach_NIRReference: _xlfn.LAMBDA("National Inventory Report Volume 1: Equation 3.D.B_10")
Name Common_SourceData.Common_SourceData_EFleach_Source: _xlfn.LAMBDA("VEERG 2026:5.5.2.3 Constant Parameters")
Name Common_SourceData.Common_SourceData_EFleach_Title: _xlfn.LAMBDA("Emission factor for nitrogen leaching and runoff")
Name Common_SourceData.Common_SourceData_EFleach_Unit: _xlfn.LAMBDA("(kg N2O-N / kg N")
Name Common_SourceData.Common_SourceData_EFleach_Variation: _xlfn.LAMBDA((""))
Name Common_SourceData.Common_SourceData_EFN2O_NIRReference: _xlfn.LAMBDA("")
Name Common_SourceData.Common_SourceData_EFN2O_Source: _xlfn.LAMBDA("VEERG 2026: Table A.2.2.1")
Name Common_SourceData.Common_SourceData_EFN2O_Title: _xlfn.LAMBDA("Nitrous oxide emission factors for inorganic fertiliser application")
Name Common_SourceData.Common_SourceData_EFN2O_Unit: _xlfn.LAMBDA("(kg N2O-N / kg N")
Name Common_SourceData.Common_SourceData_EFOrganicFertiliserAndCropResidues_Data: _xlfn.LAMBDA(_xlfn.MAKEARRAY(3, 2, _xlfn.LAMBDA(_xlpm.r,_xlpm.c, INDEX({"Climate zone","EFNi & EFN2O";"Wet climate zone",0.006;"Dry climate zone",0.005}, _xlpm.r, _xlpm.c))))

Sheet Home
A1: Home

Sheet Overview
A1: #VALUE! | C1: 5: Fertiliser Use: Overview
A3: =HYPERLINK("#'Home'!A1", "Home") -> Home
A4: =HYPERLINK("#'Overview'!A1", "Overview") -> Overview
A5: =HYPERLINK("#'Results'!A1", "Results") -> Results | D5: 💡 Below is a diagram that maps the equations used to calculate emissions, and how they interact with each other.
D6: Click on a box to go to the corresponding calculation.
A7: INPUTS
A8: =HYPERLINK("#'Input - Site'!A1", "Site") -> Site
A9: =HYPERLINK("#'Input - Fertiliser'!A1", "Fertiliser") -> Fertiliser
A11: CALCULATIONS
A12: =HYPERLINK("#'5.1.1.1-2 Inorganic Fert N2O'!A1", "5.1.1.1-2 Inorganic Fert N2O") -> 5.1.1.1-2 Inorganic Fert N2O
A13: =HYPERLINK("#'5.1.1.3-4 Inorganic fert CO2'!A1", "5.1.1.3-4 Inorganic fert CO2") -> 5.1.1.3-4 Inorganic fert CO2
A14: =HYPERLINK("#'5.2.1.1-2 Organic Fert N2O'!A1", "5.2.1.1-2 Organic Fert N2O") -> 5.2.1.1-2 Organic Fert N2O
A15: =HYPERLINK("#'5.3.1.1-2 Lime CO2'!A1", "5.3.1.1-2 Lime CO2") -> 5.3.1.1-2 Lime CO2
A16: =HYPERLINK("#'5.4.1.1-4 Atmos deposition'!A1", "5.4.1.1-4 Atmos deposition") -> 5.4.1.1-4 Atmos deposition
A17: =HYPERLINK("#'5.5.1.1-2 Leaching and runoff'!A1", "5.5.1.1-2 Leaching and runoff") -> 5.5.1.1-2 Leaching and runoff
A19: APPENDICES
A20: =HYPERLINK("#'Constants - Fertiliser'!A1", "Constants - Fertiliser") -> Constants - Fertiliser
A21: =HYPERLINK("#'Constants - Common'!A1", "Constants - Common") -> Constants - Common
L37: `

Sheet Results
A1: #VALUE! | C1: 5: Fertiliser Use: Results
A3: =HYPERLINK("#'Home'!A1", "Home") -> Home
A4: =HYPERLINK("#'Overview'!A1", "Overview") -> Overview | D4: Emissions breakdown
A5: =HYPERLINK("#'Results'!A1", "Results") -> Results
D6: 💡 NOTE: When there is no Method 2, the Method 2 result are the same as Method 1
A7: INPUTS
A8: =HYPERLINK("#'Input - Site'!A1", "Site") -> Site | D8: Scope 1 source | E8: GHG emissions method 1 | F8: GHG emissions method 2 | G8: GHG Unit | H8: CO2-e emissions method 1 | I8: CO2-e emissions method 2 | J8: CO2-e unit
A9: =HYPERLINK("#'Input - Fertiliser'!A1", "Fertiliser") -> Fertiliser | D9: 5.1.1.1-2 Inorganic fertiliser N2O | E9: ='5.1.1.1-2 Inorganic fert N2O'!$E$80 -> 0.028771072 | F9: ='5.1.1.1-2 Inorganic fert N2O'!$N$88 -> 0.0268972 | G9: t N2O | H9: ='5.1.1.1-2 Inorganic fert N2O'!E85 -> 7.6243341 | I9: ='5.1.1.1-2 Inorganic fert N2O'!N93 -> 7.127758 | J9: t CO2e
D10: 5.1.1.3-4 Inorganic fertiliser CO2 | E10: ='5.1.1.3-4 Inorganic fert CO2'!$E$78 -> 0.3826087 | F10: =E10 -> 0.3826087 | G10: t CO2 | H10: ='5.1.1.3-4 Inorganic fert CO2'!$E$78 -> 0.3826087 | I10: =H10 -> 0.3826087 | J10: t CO2e
A11: CALCULATIONS | D11: 5.2.1.1-2 Organic fertiliser N2O | E11: ='5.2.1.1-2 Organic Fert N2O'!$E$50 -> 0.0043214286 | F11: =E11 -> 0.0043214286 | G11: t N2O | H11: ='5.2.1.1-2 Organic Fert N2O'!$E$55 -> 1.1451786 | I11: =H11 -> 1.1451786 | J11: t CO2e
A12: =HYPERLINK("#'5.1.1.1-2 Inorganic Fert N2O'!A1", "5.1.1.1-2 Inorganic Fert N2O") -> 5.1.1.1-2 Inorganic Fert N2O | D12: 5.3.1.1-3 Lime CO2 | E12: ='5.3.1.1-2 Lime CO2'!$E$31 -> 7.4708333 | F12: =E12 -> 7.4708333 | G12: t CO2 | H12: ='5.3.1.1-2 Lime CO2'!$E$31 -> 7.4708333 | I12: =H12 -> 7.4708333 | J12: t CO2e
A13: =HYPERLINK("#'5.1.1.3-4 Inorganic fert CO2'!A1", "5.1.1.3-4 Inorganic fert CO2") -> 5.1.1.3-4 Inorganic fert CO2 | D13: 5.4.1.1-5 Atmospheric deposition | E13: ='5.4.1.1-4 Atmos deposition'!$E$146 -> 0.0012705 | F13: =E13 -> 0.0012705 | G13: t N2O | H13: ='5.4.1.1-4 Atmos deposition'!$E$151 -> 0.3366825 | I13: =H13 -> 0.3366825 | J13: t CO2e
A14: =HYPERLINK("#'5.2.1.1-2 Organic Fert N2O'!A1", "5.2.1.1-2 Organic Fert N2O") -> 5.2.1.1-2 Organic Fert N2O | D14: 5.5.1.1-2 Leaching and runoff | E14: ='5.5.1.1-2 Leaching and runoff'!$E$94 -> 0 | F14: =E14 -> 0 | G14: t N2O | H14: ='5.5.1.1-2 Leaching and runoff'!$E$99 -> 0 | I14: =H14 -> 0 | J14: t CO2e
A15: =HYPERLINK("#'5.3.1.1-2 Lime CO2'!A1", "5.3.1.1-2 Lime CO2") -> 5.3.1.1-2 Lime CO2 | D15: Total | H15: =SUM(H9:H14) -> 16.959637 | I15: =SUM(I9:I14) -> 16.463061 | J15: t CO2e
A16: =HYPERLINK("#'5.4.1.1-4 Atmos deposition'!A1", "5.4.1.1-4 Atmos deposition") -> 5.4.1.1-4 Atmos deposition
A17: =HYPERLINK("#'5.5.1.1-2 Leaching and runoff'!A1", "5.5.1.1-2 Leaching and runoff") -> 5.5.1.1-2 Leaching and runoff
A19: APPENDICES
A20: =HYPERLINK("#'Constants - Fertiliser'!A1", "Constants - Fertiliser") -> Constants - Fertiliser
A21: =HYPERLINK("#'Constants - Common'!A1", "Constants - Common") -> Constants - Common

Sheet Input - Site
A1: #VALUE! | C1: Input - Site
A3: =HYPERLINK("#'Home'!A1", "Home") -> Home
A4: =HYPERLINK("#'Overview'!A1", "Overview") -> Overview
A5: =HYPERLINK("#'Results'!A1", "Results") -> Results | D5: Your business
A7: INPUTS | D7: Farm name | E7: Test Farms
A8: =HYPERLINK("#'Input - Site'!A1", "Site") -> Site | D8: Reporting entity name | E8: Test Farms Pty Ltd
A9: =HYPERLINK("#'Input - Fertiliser'!A1", "Fertiliser") -> Fertiliser
D10: 💡An 'Emissions accounting period' is a 12 month period where the business can report on the emissions, and is typically the same as the business' financial accounting period.
A11: CALCULATIONS
A12: =HYPERLINK("#'5.1.1.1-2 Inorganic Fert N2O'!A1", "5.1.1.1-2 Inorganic Fert N2O") -> 5.1.1.1-2 Inorganic Fert N2O | D12: Emissions calculation period start date | E12: 45292 | F12: ← DD/MM/YYYY or DD Month YYYY
A13: =HYPERLINK("#'5.1.1.3-4 Inorganic fert CO2'!A1", "5.1.1.3-4 Inorganic fert CO2") -> 5.1.1.3-4 Inorganic fert CO2 | D13: Emissions calculation period end date | E13: =DATE(YEAR(E12)+1,MONTH(E12),DAY(E12))-1 -> 45657 | F13: ← Automatically calculated, 12 months after start date
A14: =HYPERLINK("#'5.2.1.1-2 Organic Fert N2O'!A1", "5.2.1.1-2 Organic Fert N2O") -> 5.2.1.1-2 Organic Fert N2O
A15: =HYPERLINK("#'5.3.1.1-2 Lime CO2'!A1", "5.3.1.1-2 Lime CO2") -> 5.3.1.1-2 Lime CO2
A16: =HYPERLINK("#'5.4.1.1-4 Atmos deposition'!A1", "5.4.1.1-4 Atmos deposition") -> 5.4.1.1-4 Atmos deposition | D16: Location and climate
A17: =HYPERLINK("#'5.5.1.1-2 Leaching and runoff'!A1", "5.5.1.1-2 Leaching and runoff") -> 5.5.1.1-2 Leaching and runoff
D18: Location information is used to reference some region and climate-specific emission factors
A19: APPENDICES | D19: Tip: Use the web-based GAF Location Helper tool to easily get region and climate information. You will need an internet connection to use the GAF Location Helper.
A20: =HYPERLINK("#'Constants - Fertiliser'!A1", "Constants - Fertiliser") -> Constants - Fertiliser
A21: =HYPERLINK("#'Constants - Common'!A1", "Constants - Common") -> Constants - Common | D21: State | E21: Western Australia | F21: ← Please select
D22: Region (ABS Statistical area level 4) if state is WA | E22: Western Australia - Outback (South) | F22: ← Please select
D23: Leaching zone | E23: NO - Not in leaching zone | F23: ← Please select
D24: Elevation | E24: 307.7 | F24: Meters
D25: Average temperature for reporting period | E25: 18 | F25: Degrees celsius
D26: Total rainfall for reporting period | E26: 599 | F26: Millimetres
D27: Potential evapotranspiration for reporting period | E27: 1326 | F27: Millimetres
D28: Number of frost days for reporting period | E28: 7 | F28: Days
D29: MAP:PET ratio | E29: =E26/E27 -> 0.45173454
D30: Rainfall zone | E30: =Common_InputFunctions.Utility_LookupItemFromMinMax(E26,Table_SourceData_RainfallZones[Min rainfall],Table_SourceData_RainfallZones[Max rainfall],Table_SourceData_RainfallZones[Rainfall Zone]) -> Low rainfall
D31: Climate zone | E31: =Common_InputFunctions.Utility_GetClimateZone(E25,E26,E28,E24,E29,Table_SourceData_ClimateZones[Min temp],Table_SourceData_ClimateZones[Max temp],Table_SourceData_ClimateZones[Min rainfall],Table_SourceData_ClimateZones[Max rainfall],Table_SourceData_ClimateZones[Min frost days],Table_SourceData_ClimateZones[Max frost days],Table_SourceData_ClimateZones[Min elevation],Table_SourceData_ClimateZones[Max elevation],Table_SourceData_ClimateZones[Min MAP:PET],Table_SourceData_ClimateZones[Max MAP:PET],Table_SourceData_ClimateZones[Climate zone]) -> Warm temperate dry
D32: Wet or dry climate zone | E32: =Common_InputFunctions.Utility_LookupValueInTable($E$31,Table_SourceData_WetDryZones[Climate zone],Table_SourceData_WetDryZones[Wet or Dry Zone]) -> Dry climate zone
D33: Temperature zone | E33: =Common_InputFunctions.Utility_LookupItemFromMinMax(E25,Table_SourceData_TemperatureZones[Min MAT],Table_SourceData_TemperatureZones[Max MAT],Table_SourceData_TemperatureZones[Temperature Zone]) -> Temperate

Sheet Input - Fertiliser
A1: #VALUE! | C1: Input - Fertiliser
A3: =HYPERLINK("#'Home'!A1", "Home") -> Home
A4: =HYPERLINK("#'Overview'!A1", "Overview") -> Overview
A5: =HYPERLINK("#'Results'!A1", "Results") -> Results
D6: Production system | E6: Crop | F6: ← Please select
A7: INPUTS | D7: Crop type | E7: Grains | F7: ← Please select
A8: =HYPERLINK("#'Input - Site'!A1", "Site") -> Site | D8: Irrigation method | E8: Drip irrigation | F8: ← Please select
A9: =HYPERLINK("#'Input - Fertiliser'!A1", "Fertiliser") -> Fertiliser | D9: Area under cropping | E9: 100 | F9: hectares
A11: CALCULATIONS | D11: Inorganic fertiliser applied
A12: =HYPERLINK("#'5.1.1.1-2 Inorganic Fert N2O'!A1", "5.1.1.1-2 Inorganic Fert N2O") -> 5.1.1.1-2 Inorganic Fert N2O
A13: =HYPERLINK("#'5.1.1.3-4 Inorganic fert CO2'!A1", "5.1.1.3-4 Inorganic fert CO2") -> 5.1.1.3-4 Inorganic fert CO2 | D13: 💡You can add more rows to tables by right-clicking on the table and selecting "Insert > Table rows above/below".
A14: =HYPERLINK("#'5.2.1.1-2 Organic Fert N2O'!A1", "5.2.1.1-2 Organic Fert N2O") -> 5.2.1.1-2 Organic Fert N2O | D14: 💡The application area is the same as the area under pasture / cropping by default. You can edit it if the application area is different.
A15: =HYPERLINK("#'5.3.1.1-2 Lime CO2'!A1", "5.3.1.1-2 Lime CO2") -> 5.3.1.1-2 Lime CO2
A16: =HYPERLINK("#'5.4.1.1-4 Atmos deposition'!A1", "5.4.1.1-4 Atmos deposition") -> 5.4.1.1-4 Atmos deposition | D16: Branded fertiliser products
A17: =HYPERLINK("#'5.5.1.1-2 Leaching and runoff'!A1", "5.5.1.1-2 Leaching and runoff") -> 5.5.1.1-2 Leaching and runoff | D17: Product (select) | E17: Amount applied (kg / ha) | F17: Application unit | G17: Density | H17: Application area (ha) | I17: Total applied (kg) | J17: Ingredient 1 | K17: Ingredient 1 percent | L17: Ingredient 2 | M17: Ingredient 2 percent | N17: Ingredient 3 | O17: Ingredient 3 percent | P17: Ingredient 4 | Q17: Ingredient 4 percent | R17: Ingredient 5 | S17: Ingredient 5 percent | T17: Ingredient 6 | U17: Ingredient 6 percent | V17: N application rate (kg/ha) | W17: Urea source | X17: Ammonia source
D18: Aqua Finish | E18: 200 | F18: =_xlfn.XLOOKUP(Table_Input_InorganicFertiliser_Brands[[#This Row],[Product (select)]],FertiliserProducts[Product name],FertiliserProducts[Unit]) -> L | G18: =_xlfn.XLOOKUP(Table_Input_InorganicFertiliser_Brands[[#This Row],[Product (select)]],FertiliserProducts[Product name],FertiliserProducts[Density / gravity]) -> 1.26 | H18: =$E$9 -> 100 | I18: =(Table_Input_InorganicFertiliser_Brands[[#This Row],[Amount applied (kg / ha)]]*Table_Input_InorganicFertiliser_Brands[[#This Row],[Density]])*Table_Input_InorganicFertiliser_Brands[[#This Row],[Application area (ha)]] -> 25200 | J18: {=Fertiliser_InputFunctions.Fertiliser_FertiliserProductLookup(Table_Input_InorganicFertiliser_Brands[[#This Row],[Product (select)]], Table_Input_InorganicFertiliser_Brands[[#Headers],[Ingredient 1]], FertiliserProducts[#Data], FertiliserProducts[Product name], FertiliserProducts[#Headers])} -> Potassium - Generic | K18: {=Fertiliser_InputFunctions.Fertiliser_FertiliserProductLookup(Table_Input_InorganicFertiliser_Brands[[#This Row],[Product (select)]], Table_Input_InorganicFertiliser_Brands[[#Headers],[Ingredient 1 percent]], FertiliserProducts[#Data], FertiliserProducts[Product name], FertiliserProducts[#Headers])} -> 0.225 | L18: {=Fertiliser_InputFunctions.Fertiliser_FertiliserProductLookup(Table_Input_InorganicFertiliser_Brands[[#This Row],[Product (select)]], Table_Input_InorganicFertiliser_Brands[[#Headers],[Ingredient 2]], FertiliserProducts[#Data], FertiliserProducts[Product name], FertiliserProducts[#Headers])} -> Phosphorus - Generic | M18: {=Fertiliser_InputFunctions.Fertiliser_FertiliserProductLookup(Table_Input_InorganicFertiliser_Brands[[#This Row],[Product (select)]], Table_Input_InorganicFertiliser_Brands[[#Headers],[Ingredient 2 percent]], FertiliserProducts[#Data], FertiliserProducts[Product name], FertiliserProducts[#Headers])} -> 0.04 | N18: {=Fertiliser_InputFunctions.Fertiliser_FertiliserProductLookup(Table_Input_InorganicFertiliser_Brands[[#This Row],[Product (select)]], Table_Input_InorganicFertiliser_Brands[[#Headers],[Ingredient 3]], FertiliserProducts[#Data], FertiliserProducts[Product name], FertiliserProducts[#Headers])} -> Nitrogen - Generic | O18: {=Fertiliser_InputFunctions.Fertiliser_FertiliserProductLookup(Table_Input_InorganicFertiliser_Brands[[#This Row],[Product (select)]], Table_Input_InorganicFertiliser_Brands[[#Headers],[Ingredient 3 percent]], FertiliserProducts[#Data], FertiliserProducts[Product name], FertiliserProducts[#Headers])} -> 0.026 | P18: {=Fertiliser_InputFunctions.Fertiliser_FertiliserProductLookup(Table_Input_InorganicFertiliser_Brands[[#This Row],[Product (select)]], Table_Input_InorganicFertiliser_Brands[[#Headers],[Ingredient 4]], FertiliserProducts[#Data], FertiliserProducts[Product name], FertiliserProducts[#Headers])} | Q18: {=Fertiliser_InputFunctions.Fertiliser_FertiliserProductLookup(Table_Input_InorganicFertiliser_Brands[[#This Row],[Product (select)]], Table_Input_InorganicFertiliser_Brands[[#Headers],[Ingredient 4 percent]], FertiliserProducts[#Data], FertiliserProducts[Product name], FertiliserProducts[#Headers])} | R18: {=Fertiliser_InputFunctions.Fertiliser_FertiliserProductLookup(Table_Input_InorganicFertiliser_Brands[[#This Row],[Product (select)]], Table_Input_InorganicFertiliser_Brands[[#Headers],[Ingredient 5]], FertiliserProducts[#Data], FertiliserProducts[Product name], FertiliserProducts[#Headers])} | S18: {=Fertiliser_InputFunctions.Fertiliser_FertiliserProductLookup(Table_Input_InorganicFertiliser_Brands[[#This Row],[Product (select)]], Table_Input_InorganicFertiliser_Brands[[#Headers],[Ingredient 5 percent]], FertiliserProducts[#Data], FertiliserProducts[Product name], FertiliserProducts[#Headers])} | T18: {=Fertiliser_InputFunctions.Fertiliser_FertiliserProductLookup(Table_Input_InorganicFertiliser_Brands[[#This Row],[Product (select)]], Table_Input_InorganicFertiliser_Brands[[#Headers],[Ingredient 6]], FertiliserProducts[#Data], FertiliserProducts[Product name], FertiliserProducts[#Headers])} | U18: {=Fertiliser_InputFunctions.Fertiliser_FertiliserProductLookup(Table_Input_InorganicFertiliser_Brands[[#This Row],[Product (select)]], Table_Input_InorganicFertiliser_Brands[[#Headers],[Ingredient 6 percent]], FertiliserProducts[#Data], FertiliserProducts[Product name], FertiliserProducts[#Headers])} | V18: =(Table_Input_InorganicFertiliser_Brands[[#This Row],[Amount applied (kg / ha)]]*Table_Input_InorganicFertiliser_Brands[[#This Row],[Density]])*(IFERROR((_xlfn.XLOOKUP(Table_Input_InorganicFertiliser_Brands[[#This Row],[Ingredient 1]], Table_Fertiliser_ChemicalCompounds[Fertiliser type f],Table_Fertiliser_ChemicalCompounds[FNinorganic f])*Table_Input_InorganicFertiliser_Brands[[#This Row],[Ingredient 1 percent]]), 0)+ IFERROR((_xlfn.XLOOKUP(Table_Input_InorganicFertiliser_Brands[[#This Row],[Ingredient 2]],Table_Fertiliser_ChemicalCompounds[Fertiliser type f],Table_Fertiliser_ChemicalCompounds[FNinorganic f])*Table_Input_InorganicFertiliser_Brands[[#This Row],[Ingredient 2 percent]]), 0)+ IFERROR((_xlfn.XLOOKUP(Table_Input_InorganicFertiliser_Brands[[#This Row],[Ingredient 3]],Table_Fertiliser_ChemicalCompounds[Fertiliser type f],Table_Fertiliser_ChemicalCompounds[FNinorganic f])*Table_Input_InorganicFertiliser_Brands[[#This Row],[Ingredient 3 percent]]), 0)+ IFERROR((_xlfn.XLOOKUP(Table_Input_InorganicFertiliser_Brands[[#This Row],[Ingredient 4]],Table_Fertiliser_ChemicalCompounds[Fertiliser type f],Table_Fertiliser_ChemicalCompounds[FNinorganic f])*Table_Input_InorganicFertiliser_Brands[[#This Row],[Ingredient 4 percent]]), 0)+ IFERROR((_xlfn.XLOOKUP(Table_Input_InorganicFertiliser_Brands[[#This Row],[Ingredient 5]],Table_Fertiliser_ChemicalCompounds[Fertiliser type f],Table_Fertiliser_ChemicalCompounds[FNinorganic f])*Table_Input_InorganicFertiliser_Brands[[#This Row],[Ingredient 5 percent]]), 0)+ IFERROR((_xlfn.XLOOKUP(Table_Input_InorganicFertiliser_Brands[[#This Row],[Ingredient 6]],Table_Fertiliser_ChemicalCompounds[Fertiliser type f],Table_Fertiliser_ChemicalCompounds[FNinorganic f])*Table_Input_InorganicFertiliser_Brands[[#This Row],[Ingredient 6 percent]]), 0)) -> 6.552 | W18: =_xlfn.XLOOKUP(Table_Input_InorganicFertiliser_Brands[[#This Row],[Product (select)]],FertiliserProducts[Product name],FertiliserProducts[Urea source]) | X18: =_xlfn.XLOOKUP(Table_Input_InorganicFertiliser_Brands[[#This Row],[Product (select)]],FertiliserProducts[Product name],FertiliserProducts[Ammonia source])
A19: APPENDICES | D19: Boost-It | E19: 10 | F19: =_xlfn.XLOOKUP(Table_Input_InorganicFertiliser_Brands[[#This Row],[Product (select)]],FertiliserProducts[Product name],FertiliserProducts[Unit]) -> kg | G19: =_xlfn.XLOOKUP(Table_Input_InorganicFertiliser_Brands[[#This Row],[Product (select)]],FertiliserProducts[Product name],FertiliserProducts[Density / gravity]) -> 1 | H19: =$E$9 -> 100 | I19: =(Table_Input_InorganicFertiliser_Brands[[#This Row],[Amount applied (kg / ha)]]*Table_Input_InorganicFertiliser_Brands[[#This Row],[Density]])*Table_Input_InorganicFertiliser_Brands[[#This Row],[Application area (ha)]] -> 1000 | J19: {=Fertiliser_InputFunctions.Fertiliser_FertiliserProductLookup(Table_Input_InorganicFertiliser_Brands[[#This Row],[Product (select)]], Table_Input_InorganicFertiliser_Brands[[#Headers],[Ingredient 1]], FertiliserProducts[#Data], FertiliserProducts[Product name], FertiliserProducts[#Headers])} -> Urea | K19: {=Fertiliser_InputFunctions.Fertiliser_FertiliserProductLookup(Table_Input_InorganicFertiliser_Brands[[#This Row],[Product (select)]], Table_Input_InorganicFertiliser_Brands[[#Headers],[Ingredient 1 percent]], FertiliserProducts[#Data], FertiliserProducts[Product name], FertiliserProducts[#Headers])} -> 0.52173913 | L19: {=Fertiliser_InputFunctions.Fertiliser_FertiliserProductLookup(Table_Input_InorganicFertiliser_Brands[[#This Row],[Product (select)]], Table_Input_InorganicFertiliser_Brands[[#Headers],[Ingredient 2]], FertiliserProducts[#Data], FertiliserProducts[Product name], FertiliserProducts[#Headers])} -> Potassium - Generic | M19: {=Fertiliser_InputFunctions.Fertiliser_FertiliserProductLookup(Table_Input_InorganicFertiliser_Brands[[#This Row],[Product (select)]], Table_Input_InorganicFertiliser_Brands[[#Headers],[Ingredient 2 percent]], FertiliserProducts[#Data], FertiliserProducts[Product name], FertiliserProducts[#Headers])} -> 0.08 | N19: {=Fertiliser_InputFunctions.Fertiliser_FertiliserProductLookup(Table_Input_InorganicFertiliser_Brands[[#This Row],[Product (select)]], Table_Input_InorganicFertiliser_Brands[[#Headers],[Ingredient 3]], FertiliserProducts[#Data], FertiliserProducts[Product name], FertiliserProducts[#Headers])} -> Sulfur - Generic | O19: {=Fertiliser_InputFunctions.Fertiliser_FertiliserProductLookup(Table_Input_InorganicFertiliser_Brands[[#This Row],[Product (select)]], Table_Input_InorganicFertiliser_Brands[[#Headers],[Ingredient 3 percent]], FertiliserProducts[#Data], FertiliserProducts[Product name], FertiliserProducts[#Headers])} -> 0.053 | P19: {=Fertiliser_InputFunctions.Fertiliser_FertiliserProductLookup(Table_Input_InorganicFertiliser_Brands[[#This Row],[Product (select)]], Table_Input_InorganicFertiliser_Brands[[#Headers],[Ingredient 4]], FertiliserProducts[#Data], FertiliserProducts[Product name], FertiliserProducts[#Headers])} -> Phosphorus - Generic | Q19: {=Fertiliser_InputFunctions.Fertiliser_FertiliserProductLookup(Table_Input_InorganicFertiliser_Brands[[#This Row],[Product (select)]], Table_Input_InorganicFertiliser_Brands[[#Headers],[Ingredient 4 percent]], FertiliserProducts[#Data], FertiliserProducts[Product name], FertiliserProducts[#Headers])} -> 0.052 | R19: {=Fertiliser_InputFunctions.Fertiliser_FertiliserProductLookup(Table_Input_InorganicFertiliser_Brands[[#This Row],[Product (select)]], Table_Input_InorganicFertiliser_Brands[[#Headers],[Ingredient 5]], FertiliserProducts[#Data], FertiliserProducts[Product name], FertiliserProducts[#Headers])} -> Magnesium | S19: {=Fertiliser_InputFunctions.Fertiliser_FertiliserProductLookup(Table_Input_InorganicFertiliser_Brands[[#This Row],[Product (select)]], Table_Input_InorganicFertiliser_Brands[[#Headers],[Ingredient 5 percent]], FertiliserProducts[#Data], FertiliserProducts[Product name], FertiliserProducts[#Headers])} -> 0.013 | T19: {=Fertiliser_InputFunctions.Fertiliser_FertiliserProductLookup(Table_Input_InorganicFertiliser_Brands[[#This Row],[Product (select)]], Table_Input_InorganicFertiliser_Brands[[#Headers],[Ingredient 6]], FertiliserProducts[#Data], FertiliserProducts[Product name], FertiliserProducts[#Headers])} -> Zinc | U19: {=Fertiliser_InputFunctions.Fertiliser_FertiliserProductLookup(Table_Input_InorganicFertiliser_Brands[[#This Row],[Product (select)]], Table_Input_InorganicFertiliser_Brands[[#Headers],[Ingredient 6 percent]], FertiliserProducts[#Data], FertiliserProducts[Product name], FertiliserProducts[#Headers])} -> 0.002 | V19: =(Table_Input_InorganicFertiliser_Brands[[#This Row],[Amount applied (kg / ha)]]*Table_Input_InorganicFertiliser_Brands[[#This Row],[Density]])*(IFERROR((_xlfn.XLOOKUP(Table_Input_InorganicFertiliser_Brands[[#This Row],[Ingredient 1]], Table_Fertiliser_ChemicalCompounds[Fertiliser type f],Table_Fertiliser_ChemicalCompounds[FNinorganic f])*Table_Input_InorganicFertiliser_Brands[[#This Row],[Ingredient 1 percent]]), 0)+ IFERROR((_xlfn.XLOOKUP(Table_Input_InorganicFertiliser_Brands[[#This Row],[Ingredient 2]],Table_Fertiliser_ChemicalCompounds[Fertiliser type f],Table_Fertiliser_ChemicalCompounds[FNinorganic f])*Table_Input_InorganicFertiliser_Brands[[#This Row],[Ingredient 2 percent]]), 0)+ IFERROR((_xlfn.XLOOKUP(Table_Input_InorganicFertiliser_Brands[[#This Row],[Ingredient 3]],Table_Fertiliser_ChemicalCompounds[Fertiliser type f],Table_Fertiliser_ChemicalCompounds[FNinorganic f])*Table_Input_InorganicFertiliser_Brands[[#This Row],[Ingredient 3 percent]]), 0)+ IFERROR((_xlfn.XLOOKUP(Table_Input_InorganicFertiliser_Brands[[#This Row],[Ingredient 4]],Table_Fertiliser_ChemicalCompounds[Fertiliser type f],Table_Fertiliser_ChemicalCompounds[FNinorganic f])*Table_Input_InorganicFertiliser_Brands[[#This Row],[Ingredient 4 percent]]), 0)+ IFERROR((_xlfn.XLOOKUP(Table_Input_InorganicFertiliser_Brands[[#This Row],[Ingredient 5]],Table_Fertiliser_ChemicalCompounds[Fertiliser type f],Table_Fertiliser_ChemicalCompounds[FNinorganic f])*Table_Input_InorganicFertiliser_Brands[[#This Row],[Ingredient 5 percent]]), 0)+ IFERROR((_xlfn.XLOOKUP(Table_Input_InorganicFertiliser_Brands[[#This Row],[Ingredient 6]],Table_Fertiliser_ChemicalCompounds[Fertiliser type f],Table_Fertiliser_ChemicalCompounds[FNinorganic f])*Table_Input_InorganicFertiliser_Brands[[#This Row],[Ingredient 6 percent]]), 0)) -> 2.4
A20: =HYPERLINK("#'Constants - Fertiliser'!A1", "Constants - Fertiliser") -> Constants - Fertiliser
A21: =HYPERLINK("#'Constants - Common'!A1", "Constants - Common") -> Constants - Common | D21: Custom fertiliser blends
D22: Custom blend name | E22: Amount applied (kg / ha) | F22: Application area (ha) | G22: Total applied (kg) | H22: Ingredient 1 (select) | I22: Ingredient 1 percent | J22: Ingredient 2 | K22: Ingredient 2 percent | L22: Ingredient 3 | M22: Ingredient 3 percent | N22: Ingredient 4 | O22: Ingredient 4 percent | P22: N application rate (kg/ha) | Q22: Urea source (Select) | R22: Ammonia source (select)
D23: My first custom blend | E23: 100 | F23: =$E$9 -> 100 | G23: =Table_Input_InorganicFertiliser_Custom[[#This Row],[Amount applied (kg / ha)]]*Table_Input_InorganicFertiliser_Custom[[#This Row],[Application area (ha)]] -> 10000 | H23: Calcium nitrate | I23: 1 | J23: Zinc - Generic | K23: 0 | L23: Potassium - Generic | M23: 0 | N23: Sulfur - Generic | O23: 0 | P23: =Table_Input_InorganicFertiliser_Custom[[#This Row],[Amount applied (kg / ha)]]* (IFERROR((_xlfn.XLOOKUP(Table_Input_InorganicFertiliser_Custom[[#This Row],[Ingredient 1 (select)]], Table_Fertiliser_ChemicalCompounds[Fertiliser type f],Table_Fertiliser_ChemicalCompounds[FNinorganic f])*Table_Input_InorganicFertiliser_Custom[[#This Row],[Ingredient 1 percent]]), 0) + IFERROR((_xlfn.XLOOKUP(Table_Input_InorganicFertiliser_Custom[[#This Row],[Ingredient 2]], Table_Fertiliser_ChemicalCompounds[Fertiliser type f],Table_Fertiliser_ChemicalCompounds[FNinorganic f])*Table_Input_InorganicFertiliser_Custom[[#This Row],[Ingredient 2 percent]]), 0) + IFERROR((_xlfn.XLOOKUP(Table_Input_InorganicFertiliser_Custom[[#This Row],[Ingredient 3]], Table_Fertiliser_ChemicalCompounds[Fertiliser type f],Table_Fertiliser_ChemicalCompounds[FNinorganic f])*Table_Input_InorganicFertiliser_Custom[[#This Row],[Ingredient 3 percent]]), 0) + IFERROR((_xlfn.XLOOKUP(Table_Input_InorganicFertiliser_Custom[[#This Row],[Ingredient 4]], Table_Fertiliser_ChemicalCompounds[Fertiliser type f],Table_Fertiliser_ChemicalCompounds[FNinorganic f])*Table_Input_InorganicFertiliser_Custom[[#This Row],[Ingredient 4 percent]]), 0) ) -> 15.5 | Q23: Canada | R23: Global
F24: =$E$9 -> 100 | G24: =Table_Input_InorganicFertiliser_Custom[[#This Row],[Amount applied (kg / ha)]]*Table_Input_InorganicFertiliser_Custom[[#This Row],[Application area (ha)]] -> 0 | P24: =Table_Input_InorganicFertiliser_Custom[[#This Row],[Amount applied (kg / ha)]]* (IFERROR((_xlfn.XLOOKUP(Table_Input_InorganicFertiliser_Custom[[#This Row],[Ingredient 1 (select)]], Table_Fertiliser_ChemicalCompounds[Fertiliser type f],Table_Fertiliser_ChemicalCompounds[FNinorganic f])*Table_Input_InorganicFertiliser_Custom[[#This Row],[Ingredient 1 percent]]), 0) + IFERROR((_xlfn.XLOOKUP(Table_Input_InorganicFertiliser_Custom[[#This Row],[Ingredient 2]], Table_Fertiliser_ChemicalCompounds[Fertiliser type f],Table_Fertiliser_ChemicalCompounds[FNinorganic f])*Table_Input_InorganicFertiliser_Custom[[#This Row],[Ingredient 2 percent]]), 0) + IFERROR((_xlfn.XLOOKUP(Table_Input_InorganicFertiliser_Custom[[#This Row],[Ingredient 3]], Table_Fertiliser_ChemicalCompounds[Fertiliser type f],Table_Fertiliser_ChemicalCompounds[FNinorganic f])*Table_Input_InorganicFertiliser_Custom[[#This Row],[Ingredient 3 percent]]), 0) + IFERROR((_xlfn.XLOOKUP(Table_Input_InorganicFertiliser_Custom[[#This Row],[Ingredient 4]], Table_Fertiliser_ChemicalCompounds[Fertiliser type f],Table_Fertiliser_ChemicalCompounds[FNinorganic f])*Table_Input_InorganicFertiliser_Custom[[#This Row],[Ingredient 4 percent]]), 0) ) -> 0
D26: Soil amendments
D28: 💡 You can add more rows to the table by right-clicking on the table and selecting "Insert > Table rows above/below".
D29: 💡 'Lime' refers to calcium carbonate - CaCO3. 'Dolomite' refers to calcium magnesium carbonate - CaMg(CO3)2
D30: 💡The application area is the same as the area under pasture / cropping by default. You can edit it if the application area is different.
D31: =IF(MAX(Table_Input_Lime[Total]) > 1, "There can not be more than 100% ingredients in a product. Check the table below.", "")
D32: Product | E32: Amount applied (t/hectare) | F32: Application area (ha) | G32: Total amount applied (t) | H32: Percent Lime CaCO3 | I32: Percent Dolomite CaMg(CO3)2 | J32: Percent Gypsum | K32: Percent Potash | L32: Total
D33: Lime product 1 | E33: 100 | F33: =$E$9 -> 100 | G33: =IFERROR(Table_Input_Lime[[#This Row],[Amount applied (t/hectare)]]*Table_Input_Lime[[#This Row],[Application area (ha)]], 0) -> 10000 | H33: 0.4 | I33: 0.3 | J33: 0.25 | K33: 0.05 | L33: =SUM(Table_Input_Lime[[#This Row],[Percent Lime CaCO3]:[Percent Potash]]) -> 1
D34: Lime product 2 | E34: 100 | F34: =$E$9 -> 100 | G34: =IFERROR(Table_Input_Lime[[#This Row],[Amount applied (t/hectare)]]*Table_Input_Lime[[#This Row],[Application area (ha)]], 0) -> 10000 | I34: 1 | L34: =SUM(Table_Input_Lime[[#This Row],[Percent Lime CaCO3]:[Percent Potash]]) -> 1
D37: Organic fertiliser applied
D39: 💡 You can add more rows to the table by right-clicking on the table and selecting "Insert > Table rows above/below".
D40: 💡The application area is the same as the area under pasture / cropping by default. You can edit it if the application area is different.
D42: Organic fertiliser type (select) | E42: Percentage of N in fertiliser | F42: Amount applied (kg/hectare) | G42: Amount N applied (kg/hectare) | H42: Application area (ha) | I42: Total organic fertliser applied | J42: Total nitrogen applied (kg)
D43: Manure - Other | E43: 0.3 | F43: 10 | G43: =Table_Input_OrganicFertiliser[[#This Row],[Amount applied (kg/hectare)]]*Table_Input_OrganicFertiliser[[#This Row],[Percentage of N in fertiliser]] -> 3 | H43: =$E$9 -> 100 | I43: =Table_Input_OrganicFertiliser[[#This Row],[Amount applied (kg/hectare)]]*Table_Input_OrganicFertiliser[[#This Row],[Application area (ha)]] -> 1000 | J43: =IFERROR(Table_Input_OrganicFertiliser[[#This Row],[Amount N applied (kg/hectare)]]*Table_Input_OrganicFertiliser[[#This Row],[Application area (ha)]], 0) -> 300
A44: =HYPERLINK("#A1", "▲ Back to top") -> ▲ Back to top | D44: Manure - Poultry | E44: 0.25 | F44: 10 | G44: =Table_Input_OrganicFertiliser[[#This Row],[Amount applied (kg/hectare)]]*Table_Input_OrganicFertiliser[[#This Row],[Percentage of N in fertiliser]] -> 2.5 | H44: =$E$9 -> 100 | I44: =Table_Input_OrganicFertiliser[[#This Row],[Amount applied (kg/hectare)]]*Table_Input_OrganicFertiliser[[#This Row],[Application area (ha)]] -> 1000 | J44: =IFERROR(Table_Input_OrganicFertiliser[[#This Row],[Amount N applied (kg/hectare)]]*Table_Input_OrganicFertiliser[[#This Row],[Application area (ha)]], 0) -> 250

Sheet 5.1.1.1-2 Inorganic fert N2O
A1: #VALUE! | C1: 5.1.1.1-2 Inorganic fertiliser application N2O emissions
A3: =HYPERLINK("#'Home'!A1", "Home") -> Home | D3: Method 1 | M3: Method 2
A4: =HYPERLINK("#'Overview'!A1", "Overview") -> Overview
A5: =HYPERLINK("#'Results'!A1", "Results") -> Results | D5: {=Fertiliser_Equations_InorganicN2O.VEERG_5_1_1_1__2_MassOfNitrogenInInorganicFertiliser_Title()} -> Mass of nitrogen in inorganic fertiliser applied to production system | M5: {=Fertiliser_Equations_InorganicN2O.VEERG_5_1_1_2__1_EmissionFactorIrrigatedMaize_Title()} -> Emission factor for nitrous oxide for irrigated maize
D6: {=Fertiliser_Equations_InorganicN2O.VEERG_5_1_1_1__2_MassOfNitrogenInInorganicFertiliser_Source()} -> VEERG 2026: 5.1.1.1, Equation (2) | M6: {=Fertiliser_Equations_InorganicN2O.VEERG_5_1_1_2__1_EmissionFactorIrrigatedMaize_Source()} -> VEERG 2026: 5.1.1.2, Equation (1)
A7: INPUTS | D7: Function name | E7: {=Common_InputFunctions.Utility_DisplayFunctionName(G19)} -> =Fertiliser_Equations_InorganicN2O.VEERG_5_1_1_1__2_MassOfNitrogenInInorganicFertiliser
A8: =HYPERLINK("#'Input - Site'!A1", "Site") -> Site
A9: =HYPERLINK("#'Input - Fertiliser'!A1", "Fertiliser") -> Fertiliser | M9: Variable | N9: {=Fertiliser_Equations_InorganicN2O.VEERG_5_1_1_2__1_EmissionFactorIrrigatedMaize_Variable()} -> EF_fjIrrigatedMaizeN2O
D10: Variable | E10: {=Fertiliser_Equations_InorganicN2O.VEERG_5_1_1_1__2_MassOfNitrogenInInorganicFertiliser_Variable()} -> MN_jf | M10: Unit | N10: {=Fertiliser_Equations_InorganicN2O.VEERG_5_1_1_2__1_EmissionFactorIrrigatedMaize_Unit()} -> kg N2O-N/kg N applied
A11: CALCULATIONS | D11: Unit | E11: {=Fertiliser_Equations_InorganicN2O.VEERG_5_1_1_1__2_MassOfNitrogenInInorganicFertiliser_Unit()} -> kg N
A12: =HYPERLINK("#'5.1.1.1-2 Inorganic Fert N2O'!A1", "5.1.1.1-2 Inorganic Fert N2O") -> 5.1.1.1-2 Inorganic Fert N2O | M12: {=_xlfn.CHOOSECOLS(Fertiliser_Equations_InorganicN2O.VEERG_5_1_1_2__1_EmissionFactorIrrigatedMaize_Arguments(), 1, 2)} -> N_fjIrrigatedMaize | N12: application rate of inorganic fertiliser type f in the irrigated maize crop | P12: {=_xlfn.CHOOSECOLS(Fertiliser_Equations_InorganicN2O.VEERG_5_1_1_2__1_EmissionFactorIrrigatedMaize_Arguments(), 3,4)} -> kg N/ha | Q12: Input | R12: {=HYPERLINK(Common_InputFunctions.Utility_SourceHyperlink($M$41), $M$41)} -> M2_Table_FertApplications
A13: =HYPERLINK("#'5.1.1.3-4 Inorganic fert CO2'!A1", "5.1.1.3-4 Inorganic fert CO2") -> 5.1.1.3-4 Inorganic fert CO2 | D13: {=_xlfn.CHOOSECOLS(Fertiliser_Equations_InorganicN2O.VEERG_5_1_1_1__2_MassOfNitrogenInInorganicFertiliser_Arguments(), 1,2)} -> TM_jf | E13: total mass of inorganic fertiliser type f applied to production system j | G13: {=_xlfn.CHOOSECOLS(Fertiliser_Equations_InorganicN2O.VEERG_5_1_1_1__2_MassOfNitrogenInInorganicFertiliser_Arguments(), 3,4)} -> kg | H13: Input | I13: {=HYPERLINK(Common_InputFunctions.Utility_SourceHyperlink($D$16), $D$16)} -> Table_MN_j_f | M13: f | N13: Inorganic fertiliser type | Q13: Constant | R13: Not used - application rate calculated per product blend application
A14: =HYPERLINK("#'5.2.1.1-2 Organic Fert N2O'!A1", "5.2.1.1-2 Organic Fert N2O") -> 5.2.1.1-2 Organic Fert N2O | D14: FN_inorganicf | E14: fraction of nitrogen in inorganic fertiliser type f | G14: kg N/kg | H14: Constant | I14: {=HYPERLINK(Common_InputFunctions.Utility_SourceHyperlink($D$16), $D$16)} -> Table_MN_j_f
A15: =HYPERLINK("#'5.3.1.1-2 Lime CO2'!A1", "5.3.1.1-2 Lime CO2") -> 5.3.1.1-2 Lime CO2
A16: =HYPERLINK("#'5.4.1.1-4 Atmos deposition'!A1", "5.4.1.1-4 Atmos deposition") -> 5.4.1.1-4 Atmos deposition | D16: Table_MN_j_f | M16: {=Fertiliser_Equations_InorganicN2O.VEERG_5_1_1_2__2_EmissionFactorNonIrrigatedGrainsHighRainfall_Title()} -> Emission factor for nitrous oxide for non-irrigated grains in high rainfall zone
A17: =HYPERLINK("#'5.5.1.1-2 Leaching and runoff'!A1", "5.5.1.1-2 Leaching and runoff") -> 5.5.1.1-2 Leaching and runoff | D17: Mass of nitrogen applied | M17: {=Fertiliser_Equations_InorganicN2O.VEERG_5_1_1_2__2_EmissionFactorNonIrrigatedGrainsHighRainfall_Source()} -> VEERG 2026: 5.1.1.2, Equation (2)
D18: Fertiliser type f | E18: TMjf | F18: FNinorganic,f | G18: MNjf
A19: APPENDICES | D19: {=Table_Fertiliser_ChemicalCompounds[Fertiliser type f]} -> Monoammonium phosphate (MAP) | E19: {=Fertiliser_InputFunctions.Fertiliser_TotalChemicalCompoundAppliedAllIngredients($D19,(Table_Input_InorganicFertiliser_Brands[Total applied (kg)]*Table_Input_InorganicFertiliser_Brands[Density]),Table_Input_InorganicFertiliser_Brands[Ingredient 1],Table_Input_InorganicFertiliser_Brands[Ingredient 1 percent],Table_Input_InorganicFertiliser_Brands[Ingredient 2],Table_Input_InorganicFertiliser_Brands[Ingredient 2 percent],Table_Input_InorganicFertiliser_Brands[Ingredient 3],Table_Input_InorganicFertiliser_Brands[Ingredient 3 percent],Table_Input_InorganicFertiliser_Brands[Ingredient 4],Table_Input_InorganicFertiliser_Brands[Ingredient 4 percent],Table_Input_InorganicFertiliser_Brands[Ingredient 5],Table_Input_InorganicFertiliser_Brands[Ingredient 5 percent],Table_Input_InorganicFertiliser_Brands[Ingredient 6],Table_Input_InorganicFertiliser_Brands[Ingredient 6 percent])+ Fertiliser_InputFunctions.Fertiliser_TotalChemicalCompoundAppliedAllIngredients($D19,Table_Input_InorganicFertiliser_Custom[Total applied (kg)],Table_Input_InorganicFertiliser_Custom[Ingredient 1 (select)],Table_Input_InorganicFertiliser_Custom[Ingredient 1 percent],Table_Input_InorganicFertiliser_Custom[Ingredient 2],Table_Input_InorganicFertiliser_Custom[Ingredient 2 percent],Table_Input_InorganicFertiliser_Custom[Ingredient 3],Table_Input_InorganicFertiliser_Custom[Ingredient 3 percent],Table_Input_InorganicFertiliser_Custom[Ingredient 4],Table_Input_InorganicFertiliser_Custom[Ingredient 4 percent])} -> 0 | F19: {=Common_InputFunctions.Utility_LookupValueInTableNumber(D19,Table_Fertiliser_ChemicalCompounds[Fertiliser type f],Table_Fertiliser_ChemicalCompounds[FNinorganic f])} -> 0.1 | G19: {=Fertiliser_Equations_InorganicN2O.VEERG_5_1_1_1__2_MassOfNitrogenInInorganicFertiliser(E19,F19)} -> 0
A20: =HYPERLINK("#'Constants - Fertiliser'!A1", "Constants - Fertiliser") -> Constants - Fertiliser | D20: Diammonium phosphate (DAP) | E20: {=Fertiliser_InputFunctions.Fertiliser_TotalChemicalCompoundAppliedAllIngredients($D20,(Table_Input_InorganicFertiliser_Brands[Total applied (kg)]*Table_Input_InorganicFertiliser_Brands[Density]),Table_Input_InorganicFertiliser_Brands[Ingredient 1],Table_Input_InorganicFertiliser_Brands[Ingredient 1 percent],Table_Input_InorganicFertiliser_Brands[Ingredient 2],Table_Input_InorganicFertiliser_Brands[Ingredient 2 percent],Table_Input_InorganicFertiliser_Brands[Ingredient 3],Table_Input_InorganicFertiliser_Brands[Ingredient 3 percent],Table_Input_InorganicFertiliser_Brands[Ingredient 4],Table_Input_InorganicFertiliser_Brands[Ingredient 4 percent],Table_Input_InorganicFertiliser_Brands[Ingredient 5],Table_Input_InorganicFertiliser_Brands[Ingredient 5 percent],Table_Input_InorganicFertiliser_Brands[Ingredient 6],Table_Input_InorganicFertiliser_Brands[Ingredient 6 percent])+ Fertiliser_InputFunctions.Fertiliser_TotalChemicalCompoundAppliedAllIngredients($D20,Table_Input_InorganicFertiliser_Custom[Total applied (kg)],Table_Input_InorganicFertiliser_Custom[Ingredient 1 (select)],Table_Input_InorganicFertiliser_Custom[Ingredient 1 percent],Table_Input_InorganicFertiliser_Custom[Ingredient 2],Table_Input_InorganicFertiliser_Custom[Ingredient 2 percent],Table_Input_InorganicFertiliser_Custom[Ingredient 3],Table_Input_InorganicFertiliser_Custom[Ingredient 3 percent],Table_Input_InorganicFertiliser_Custom[Ingredient 4],Table_Input_InorganicFertiliser_Custom[Ingredient 4 percent])} -> 0 | F20: {=Common_InputFunctions.Utility_LookupValueInTableNumber(D20,Table_Fertiliser_ChemicalCompounds[Fertiliser type f],Table_Fertiliser_ChemicalCompounds[FNinorganic f])} -> 0.18 | G20: {=Fertiliser_Equations_InorganicN2O.VEERG_5_1_1_1__2_MassOfNitrogenInInorganicFertiliser(E20,F20)} -> 0 | M20: Variable | N20: {=Fertiliser_Equations_InorganicN2O.VEERG_5_1_1_2__2_EmissionFactorNonIrrigatedGrainsHighRainfall_Variable()} -> EF_fjNonIrrigatedGrainsN2O
A21: =HYPERLINK("#'Constants - Common'!A1", "Constants - Common") -> Constants - Common | D21: Urea | E21: {=Fertiliser_InputFunctions.Fertiliser_TotalChemicalCompoundAppliedAllIngredients($D21,(Table_Input_InorganicFertiliser_Brands[Total applied (kg)]*Table_Input_InorganicFertiliser_Brands[Density]),Table_Input_InorganicFertiliser_Brands[Ingredient 1],Table_Input_InorganicFertiliser_Brands[Ingredient 1 percent],Table_Input_InorganicFertiliser_Brands[Ingredient 2],Table_Input_InorganicFertiliser_Brands[Ingredient 2 percent],Table_Input_InorganicFertiliser_Brands[Ingredient 3],Table_Input_InorganicFertiliser_Brands[Ingredient 3 percent],Table_Input_InorganicFertiliser_Brands[Ingredient 4],Table_Input_InorganicFertiliser_Brands[Ingredient 4 percent],Table_Input_InorganicFertiliser_Brands[Ingredient 5],Table_Input_InorganicFertiliser_Brands[Ingredient 5 percent],Table_Input_InorganicFertiliser_Brands[Ingredient 6],Table_Input_InorganicFertiliser_Brands[Ingredient 6 percent])+ Fertiliser_InputFunctions.Fertiliser_TotalChemicalCompoundAppliedAllIngredients($D21,Table_Input_InorganicFertiliser_Custom[Total applied (kg)],Table_Input_InorganicFertiliser_Custom[Ingredient 1 (select)],Table_Input_InorganicFertiliser_Custom[Ingredient 1 percent],Table_Input_InorganicFertiliser_Custom[Ingredient 2],Table_Input_InorganicFertiliser_Custom[Ingredient 2 percent],Table_Input_InorganicFertiliser_Custom[Ingredient 3],Table_Input_InorganicFertiliser_Custom[Ingredient 3 percent],Table_Input_InorganicFertiliser_Custom[Ingredient 4],Table_Input_InorganicFertiliser_Custom[Ingredient 4 percent])} -> 521.73913 | F21: {=Common_InputFunctions.Utility_LookupValueInTableNumber(D21,Table_Fertiliser_ChemicalCompounds[Fertiliser type f],Table_Fertiliser_ChemicalCompounds[FNinorganic f])} -> 0.46 | G21: {=Fertiliser_Equations_InorganicN2O.VEERG_5_1_1_1__2_MassOfNitrogenInInorganicFertiliser(E21,F21)} -> 240 | M21: Unit | N21: {=Fertiliser_Equations_InorganicN2O.VEERG_5_1_1_2__2_EmissionFactorNonIrrigatedGrainsHighRainfall_Unit()} -> kg N2O-N/kg N applied
D22: Sulphate of ammonia (SOA) | E22: {=Fertiliser_InputFunctions.Fertiliser_TotalChemicalCompoundAppliedAllIngredients($D22,(Table_Input_InorganicFertiliser_Brands[Total applied (kg)]*Table_Input_InorganicFertiliser_Brands[Density]),Table_Input_InorganicFertiliser_Brands[Ingredient 1],Table_Input_InorganicFertiliser_Brands[Ingredient 1 percent],Table_Input_InorganicFertiliser_Brands[Ingredient 2],Table_Input_InorganicFertiliser_Brands[Ingredient 2 percent],Table_Input_InorganicFertiliser_Brands[Ingredient 3],Table_Input_InorganicFertiliser_Brands[Ingredient 3 percent],Table_Input_InorganicFertiliser_Brands[Ingredient 4],Table_Input_InorganicFertiliser_Brands[Ingredient 4 percent],Table_Input_InorganicFertiliser_Brands[Ingredient 5],Table_Input_InorganicFertiliser_Brands[Ingredient 5 percent],Table_Input_InorganicFertiliser_Brands[Ingredient 6],Table_Input_InorganicFertiliser_Brands[Ingredient 6 percent])+ Fertiliser_InputFunctions.Fertiliser_TotalChemicalCompoundAppliedAllIngredients($D22,Table_Input_InorganicFertiliser_Custom[Total applied (kg)],Table_Input_InorganicFertiliser_Custom[Ingredient 1 (select)],Table_Input_InorganicFertiliser_Custom[Ingredient 1 percent],Table_Input_InorganicFertiliser_Custom[Ingredient 2],Table_Input_InorganicFertiliser_Custom[Ingredient 2 percent],Table_Input_InorganicFertiliser_Custom[Ingredient 3],Table_Input_InorganicFertiliser_Custom[Ingredient 3 percent],Table_Input_InorganicFertiliser_Custom[Ingredient 4],Table_Input_InorganicFertiliser_Custom[Ingredient 4 percent])} -> 0 | F22: {=Common_InputFunctions.Utility_LookupValueInTableNumber(D22,Table_Fertiliser_ChemicalCompounds[Fertiliser type f],Table_Fertiliser_ChemicalCompounds[FNinorganic f])} -> 0.21 | G22: {=Fertiliser_Equations_InorganicN2O.VEERG_5_1_1_1__2_MassOfNitrogenInInorganicFertiliser(E22,F22)} -> 0
D23: Urea-ammonium nitrate (UAN) | E23: {=Fertiliser_InputFunctions.Fertiliser_TotalChemicalCompoundAppliedAllIngredients($D23,(Table_Input_InorganicFertiliser_Brands[Total applied (kg)]*Table_Input_InorganicFertiliser_Brands[Density]),Table_Input_InorganicFertiliser_Brands[Ingredient 1],Table_Input_InorganicFertiliser_Brands[Ingredient 1 percent],Table_Input_InorganicFertiliser_Brands[Ingredient 2],Table_Input_InorganicFertiliser_Brands[Ingredient 2 percent],Table_Input_InorganicFertiliser_Brands[Ingredient 3],Table_Input_InorganicFertiliser_Brands[Ingredient 3 percent],Table_Input_InorganicFertiliser_Brands[Ingredient 4],Table_Input_InorganicFertiliser_Brands[Ingredient 4 percent],Table_Input_InorganicFertiliser_Brands[Ingredient 5],Table_Input_InorganicFertiliser_Brands[Ingredient 5 percent],Table_Input_InorganicFertiliser_Brands[Ingredient 6],Table_Input_InorganicFertiliser_Brands[Ingredient 6 percent])+ Fertiliser_InputFunctions.Fertiliser_TotalChemicalCompoundAppliedAllIngredients($D23,Table_Input_InorganicFertiliser_Custom[Total applied (kg)],Table_Input_InorganicFertiliser_Custom[Ingredient 1 (select)],Table_Input_InorganicFertiliser_Custom[Ingredient 1 percent],Table_Input_InorganicFertiliser_Custom[Ingredient 2],Table_Input_InorganicFertiliser_Custom[Ingredient 2 percent],Table_Input_InorganicFertiliser_Custom[Ingredient 3],Table_Input_InorganicFertiliser_Custom[Ingredient 3 percent],Table_Input_InorganicFertiliser_Custom[Ingredient 4],Table_Input_InorganicFertiliser_Custom[Ingredient 4 percent])} -> 0 | F23: {=Common_InputFunctions.Utility_LookupValueInTableNumber(D23,Table_Fertiliser_ChemicalCompounds[Fertiliser type f],Table_Fertiliser_ChemicalCompounds[FNinorganic f])} -> 0.32 | G23: {=Fertiliser_Equations_InorganicN2O.VEERG_5_1_1_1__2_MassOfNitrogenInInorganicFertiliser(E23,F23)} -> 0 | M23: {=_xlfn.CHOOSECOLS(Fertiliser_Equations_InorganicN2O.VEERG_5_1_1_2__2_EmissionFactorNonIrrigatedGrainsHighRainfall_Arguments(), 1, 2)} -> N_fjNonIrrigatedGrains | N23: application rate of inorganic fertiliser type f in the grains crop | P23: {=_xlfn.CHOOSECOLS(Fertiliser_Equations_InorganicN2O.VEERG_5_1_1_2__2_EmissionFactorNonIrrigatedGrainsHighRainfall_Arguments(), 3,4)} -> kg N/ha | Q23: Input | R23: {=HYPERLINK(Common_InputFunctions.Utility_SourceHyperlink($M$41), $M$41)} -> M2_Table_FertApplications
D24: Ammonium nitrate (AN) | E24: {=Fertiliser_InputFunctions.Fertiliser_TotalChemicalCompoundAppliedAllIngredients($D24,(Table_Input_InorganicFertiliser_Brands[Total applied (kg)]*Table_Input_InorganicFertiliser_Brands[Density]),Table_Input_InorganicFertiliser_Brands[Ingredient 1],Table_Input_InorganicFertiliser_Brands[Ingredient 1 percent],Table_Input_InorganicFertiliser_Brands[Ingredient 2],Table_Input_InorganicFertiliser_Brands[Ingredient 2 percent],Table_Input_InorganicFertiliser_Brands[Ingredient 3],Table_Input_InorganicFertiliser_Brands[Ingredient 3 percent],Table_Input_InorganicFertiliser_Brands[Ingredient 4],Table_Input_InorganicFertiliser_Brands[Ingredient 4 percent],Table_Input_InorganicFertiliser_Brands[Ingredient 5],Table_Input_InorganicFertiliser_Brands[Ingredient 5 percent],Table_Input_InorganicFertiliser_Brands[Ingredient 6],Table_Input_InorganicFertiliser_Brands[Ingredient 6 percent])+ Fertiliser_InputFunctions.Fertiliser_TotalChemicalCompoundAppliedAllIngredients($D24,Table_Input_InorganicFertiliser_Custom[Total applied (kg)],Table_Input_InorganicFertiliser_Custom[Ingredient 1 (select)],Table_Input_InorganicFertiliser_Custom[Ingredient 1 percent],Table_Input_InorganicFertiliser_Custom[Ingredient 2],Table_Input_InorganicFertiliser_Custom[Ingredient 2 percent],Table_Input_InorganicFertiliser_Custom[Ingredient 3],Table_Input_InorganicFertiliser_Custom[Ingredient 3 percent],Table_Input_InorganicFertiliser_Custom[Ingredient 4],Table_Input_InorganicFertiliser_Custom[Ingredient 4 percent])} -> 0 | F24: {=Common_InputFunctions.Utility_LookupValueInTableNumber(D24,Table_Fertiliser_ChemicalCompounds[Fertiliser type f],Table_Fertiliser_ChemicalCompounds[FNinorganic f])} -> 0.337 | G24: {=Fertiliser_Equations_InorganicN2O.VEERG_5_1_1_1__2_MassOfNitrogenInInorganicFertiliser(E24,F24)} -> 0 | M24: f | N24: Inorganic fertiliser type | Q24: Constant | R24: Not used - application rate calculated per product blend application
D25: Calcium ammonium nitrate (CAN) | E25: {=Fertiliser_InputFunctions.Fertiliser_TotalChemicalCompoundAppliedAllIngredients($D25,(Table_Input_InorganicFertiliser_Brands[Total applied (kg)]*Table_Input_InorganicFertiliser_Brands[Density]),Table_Input_InorganicFertiliser_Brands[Ingredient 1],Table_Input_InorganicFertiliser_Brands[Ingredient 1 percent],Table_Input_InorganicFertiliser_Brands[Ingredient 2],Table_Input_InorganicFertiliser_Brands[Ingredient 2 percent],Table_Input_InorganicFertiliser_Brands[Ingredient 3],Table_Input_InorganicFertiliser_Brands[Ingredient 3 percent],Table_Input_InorganicFertiliser_Brands[Ingredient 4],Table_Input_InorganicFertiliser_Brands[Ingredient 4 percent],Table_Input_InorganicFertiliser_Brands[Ingredient 5],Table_Input_InorganicFertiliser_Brands[Ingredient 5 percent],Table_Input_InorganicFertiliser_Brands[Ingredient 6],Table_Input_InorganicFertiliser_Brands[Ingredient 6 percent])+ Fertiliser_InputFunctions.Fertiliser_TotalChemicalCompoundAppliedAllIngredients($D25,Table_Input_InorganicFertiliser_Custom[Total applied (kg)],Table_Input_InorganicFertiliser_Custom[Ingredient 1 (select)],Table_Input_InorganicFertiliser_Custom[Ingredient 1 percent],Table_Input_InorganicFertiliser_Custom[Ingredient 2],Table_Input_InorganicFertiliser_Custom[Ingredient 2 percent],Table_Input_InorganicFertiliser_Custom[Ingredient 3],Table_Input_InorganicFertiliser_Custom[Ingredient 3 percent],Table_Input_InorganicFertiliser_Custom[Ingredient 4],Table_Input_InorganicFertiliser_Custom[Ingredient 4 percent])} -> 0 | F25: {=Common_InputFunctions.Utility_LookupValueInTableNumber(D25,Table_Fertiliser_ChemicalCompounds[Fertiliser type f],Table_Fertiliser_ChemicalCompounds[FNinorganic f])} -> 0.27 | G25: {=Fertiliser_Equations_InorganicN2O.VEERG_5_1_1_1__2_MassOfNitrogenInInorganicFertiliser(E25,F25)} -> 0
D26: Nitrogen - Ammoniacal | E26: {=Fertiliser_InputFunctions.Fertiliser_TotalChemicalCompoundAppliedAllIngredients($D26,(Table_Input_InorganicFertiliser_Brands[Total applied (kg)]*Table_Input_InorganicFertiliser_Brands[Density]),Table_Input_InorganicFertiliser_Brands[Ingredient 1],Table_Input_InorganicFertiliser_Brands[Ingredient 1 percent],Table_Input_InorganicFertiliser_Brands[Ingredient 2],Table_Input_InorganicFertiliser_Brands[Ingredient 2 percent],Table_Input_InorganicFertiliser_Brands[Ingredient 3],Table_Input_InorganicFertiliser_Brands[Ingredient 3 percent],Table_Input_InorganicFertiliser_Brands[Ingredient 4],Table_Input_InorganicFertiliser_Brands[Ingredient 4 percent],Table_Input_InorganicFertiliser_Brands[Ingredient 5],Table_Input_InorganicFertiliser_Brands[Ingredient 5 percent],Table_Input_InorganicFertiliser_Brands[Ingredient 6],Table_Input_InorganicFertiliser_Brands[Ingredient 6 percent])+ Fertiliser_InputFunctions.Fertiliser_TotalChemicalCompoundAppliedAllIngredients($D26,Table_Input_InorganicFertiliser_Custom[Total applied (kg)],Table_Input_InorganicFertiliser_Custom[Ingredient 1 (select)],Table_Input_InorganicFertiliser_Custom[Ingredient 1 percent],Table_Input_InorganicFertiliser_Custom[Ingredient 2],Table_Input_InorganicFertiliser_Custom[Ingredient 2 percent],Table_Input_InorganicFertiliser_Custom[Ingredient 3],Table_Input_InorganicFertiliser_Custom[Ingredient 3 percent],Table_Input_InorganicFertiliser_Custom[Ingredient 4],Table_Input_InorganicFertiliser_Custom[Ingredient 4 percent])} -> 0 | F26: {=Common_InputFunctions.Utility_LookupValueInTableNumber(D26,Table_Fertiliser_ChemicalCompounds[Fertiliser type f],Table_Fertiliser_ChemicalCompounds[FNinorganic f])} -> 1 | G26: {=Fertiliser_Equations_InorganicN2O.VEERG_5_1_1_1__2_MassOfNitrogenInInorganicFertiliser(E26,F26)} -> 0
D27: Nitrogen - Nitrate | E27: {=Fertiliser_InputFunctions.Fertiliser_TotalChemicalCompoundAppliedAllIngredients($D27,(Table_Input_InorganicFertiliser_Brands[Total applied (kg)]*Table_Input_InorganicFertiliser_Brands[Density]),Table_Input_InorganicFertiliser_Brands[Ingredient 1],Table_Input_InorganicFertiliser_Brands[Ingredient 1 percent],Table_Input_InorganicFertiliser_Brands[Ingredient 2],Table_Input_InorganicFertiliser_Brands[Ingredient 2 percent],Table_Input_InorganicFertiliser_Brands[Ingredient 3],Table_Input_InorganicFertiliser_Brands[Ingredient 3 percent],Table_Input_InorganicFertiliser_Brands[Ingredient 4],Table_Input_InorganicFertiliser_Brands[Ingredient 4 percent],Table_Input_InorganicFertiliser_Brands[Ingredient 5],Table_Input_InorganicFertiliser_Brands[Ingredient 5 percent],Table_Input_InorganicFertiliser_Brands[Ingredient 6],Table_Input_InorganicFertiliser_Brands[Ingredient 6 percent])+ Fertiliser_InputFunctions.Fertiliser_TotalChemicalCompoundAppliedAllIngredients($D27,Table_Input_InorganicFertiliser_Custom[Total applied (kg)],Table_Input_InorganicFertiliser_Custom[Ingredient 1 (select)],Table_Input_InorganicFertiliser_Custom[Ingredient 1 percent],Table_Input_InorganicFertiliser_Custom[Ingredient 2],Table_Input_InorganicFertiliser_Custom[Ingredient 2 percent],Table_Input_InorganicFertiliser_Custom[Ingredient 3],Table_Input_InorganicFertiliser_Custom[Ingredient 3 percent],Table_Input_InorganicFertiliser_Custom[Ingredient 4],Table_Input_InorganicFertiliser_Custom[Ingredient 4 percent])} -> 0 | F27: {=Common_InputFunctions.Utility_LookupValueInTableNumber(D27,Table_Fertiliser_ChemicalCompounds[Fertiliser type f],Table_Fertiliser_ChemicalCompounds[FNinorganic f])} -> 1 | G27: {=Fertiliser_Equations_InorganicN2O.VEERG_5_1_1_1__2_MassOfNitrogenInInorganicFertiliser(E27,F27)} -> 0 | M27: {=Fertiliser_Equations_InorganicN2O.VEERG_5_1_1_2__3_EmissionFactorCotton_Title()} -> Emission factor for nitrous oxide for cotton
