Workbook
Name _Toc225350898: '6.2.1.1-2 Pasture residue N2O'!$C$1
Name AgResidue_Equations_CropResidue.VEERG_6_1_1_1__1__NitrousOxideEmissionsFromCropResidues: _xlfn.LAMBDA(_xlpm.M_c,_xlpm.EF_Ni,_xlpm.C_N2O, _xlpm.M_c * _xlpm.EF_Ni * _xlpm.C_N2O * 10 ^ (-3))
Name AgResidue_Equations_CropResidue.VEERG_6_1_1_1__1__NitrousOxideEmissionsFromCropResidues_FunctionName: _xlfn.LAMBDA("VEERG_6_1_1_1__1__NitrousOxideEmissionsFromCropResidues")
Name AgResidue_Equations_CropResidue.VEERG_6_1_1_1__1__NitrousOxideEmissionsFromCropResidues_LatexEquation: _xlfn.LAMBDA("E=\sum_{c}{M_{c}\times EF_{N}\times C_{g,N2O}\times 10^{-3}}")
Name AgResidue_Equations_CropResidue.VEERG_6_1_1_1__1__NitrousOxideEmissionsFromCropResidues_NIRReference: _xlfn.LAMBDA("")
Name AgResidue_Equations_CropResidue.VEERG_6_1_1_1__1__NitrousOxideEmissionsFromCropResidues_Source: _xlfn.LAMBDA("VEERG 2026: 6.1.1.1, Equation (1)")
Name AgResidue_Equations_CropResidue.VEERG_6_1_1_1__1__NitrousOxideEmissionsFromCropResidues_Title: _xlfn.LAMBDA("Nitrous oxide emissions from the return of crop residues across all crops c to the soil")
Name AgResidue_Equations_CropResidue.VEERG_6_1_1_1__1__NitrousOxideEmissionsFromCropResidues_Unit: _xlfn.LAMBDA("t N2O")
Name AgResidue_Equations_CropResidue.VEERG_6_1_1_1__1__NitrousOxideEmissionsFromCropResidues_Variable: _xlfn.LAMBDA("E")
Name AgResidue_Equations_CropResidue.VEERG_6_1_1_1__2__MassOfNitrogenInCropResidues_LatexEquation: _xlfn.LAMBDA("M_{c}=(P_{c}\times R_{AGc}\times(1-F_{c}-FFOD_{c})\times DM_{c}\times NC_{AGc})+(P_{c}\times R_{AGc}\times R_{BGc}\times DM_{c}\times NC_{BGc})")
Name AgResidue_Equations_CropResidue.VEERG_6_1_1_1__2__MassOfNitrogenInCropResidues_NIRReference: _xlfn.LAMBDA("")
Name AgResidue_Equations_CropResidue.VEERG_6_1_1_1__2__MassOfNitrogenInCropResidues_Source: _xlfn.LAMBDA("VEERG 2026: 6.1.1.1, Equation (2)")
Name AgResidue_Equations_CropResidue.VEERG_6_1_1_1__2__MassOfNitrogenInCropResidues_Title: _xlfn.LAMBDA("Mass of nitrogen in crop residues returned to the soil")
Name AgResidue_Equations_CropResidue.VEERG_6_1_1_1__2__MassOfNitrogenInCropResidues_Unit: _xlfn.LAMBDA("kg N")
Name AgResidue_Equations_CropResidue.VEERG_6_1_1_1__2__MassOfNitrogenInCropResidues_Variable: _xlfn.LAMBDA("M_c")
Name AgResidue_Equations_CropResidue.VEERG_6_1_1_2__1__FractionOfCropResidueRemovedBaled: _xlfn.LAMBDA(_xlpm.B,_xlpm.M_B,_xlpm.P_c,_xlpm.R_AGc, IFERROR((_xlpm.B * _xlpm.M_B) / (_xlpm.P_c * _xlpm.R_AGc), 0))
Name AgResidue_Equations_CropResidue.VEERG_6_1_1_2__1__FractionOfCropResidueRemovedBaled_LatexEquation: _xlfn.LAMBDA("FFOD_{c,baled}=\frac{B\times M_{B}}{P_{c}\times R_{AG,c}}")
Name AgResidue_Equations_CropResidue.VEERG_6_1_1_2__1__FractionOfCropResidueRemovedBaled_NIRReference: _xlfn.LAMBDA("")
Name AgResidue_Equations_CropResidue.VEERG_6_1_1_2__1__FractionOfCropResidueRemovedBaled_Source: _xlfn.LAMBDA("VEERG 2026: 6.1.1.2, Equation (1)")
Name AgResidue_Equations_CropResidue.VEERG_6_1_1_2__1__FractionOfCropResidueRemovedBaled_Title: _xlfn.LAMBDA("Fraction of crop residue that is removed for crop c, calculated where residues are baled")
Name AgResidue_Equations_CropResidue.VEERG_6_1_1_2__1__FractionOfCropResidueRemovedBaled_Unit: _xlfn.LAMBDA("dimensionless")
Name AgResidue_Equations_CropResidue.VEERG_6_1_1_2__1__FractionOfCropResidueRemovedBaled_Variable: _xlfn.LAMBDA("FFOD_cbaled")
Name AgResidue_Equations_CropResidue.VEERG_6_1_1_2__1__FractionOfCropResidueRemovedBaled_Variation: _xlfn.LAMBDA("VARIATION FROM SOURCE: Added 'baled' to variable subscript")
Name AgResidue_Equations_CropResidue.VEERG_6_1_1_2__1a__FractionOfCropResidueRemoved: _xlfn.LAMBDA(_xlpm.FFOD_cbaled,_xlpm.FFOD_cother, _xlpm.FFOD_cbaled + _xlpm.FFOD_cother)
Name AgResidue_Equations_CropResidue.VEERG_6_1_1_2__1a__FractionOfCropResidueRemoved_LatexEquation: _xlfn.LAMBDA("FFOD_{c} = FFOD_{c,baled} + FFOD_{c,other}")
Name AgResidue_Equations_CropResidue.VEERG_6_1_1_2__1a__FractionOfCropResidueRemoved_NIRReference: _xlfn.LAMBDA("")
Name AgResidue_Equations_CropResidue.VEERG_6_1_1_2__1a__FractionOfCropResidueRemoved_Source: _xlfn.LAMBDA("")
Name AgResidue_Equations_CropResidue.VEERG_6_1_1_2__1a__FractionOfCropResidueRemoved_Title: _xlfn.LAMBDA("Fraction of crop residue that is removed for crop c")
Name AgResidue_Equations_CropResidue.VEERG_6_1_1_2__1a__FractionOfCropResidueRemoved_Unit: _xlfn.LAMBDA("dimensionless")
Name AgResidue_Equations_CropResidue.VEERG_6_1_1_2__1a__FractionOfCropResidueRemoved_Variable: _xlfn.LAMBDA("FFOD_c")
Name AgResidue_Equations_CropResidue.VEERG_6_1_1_2__1a__FractionOfCropResidueRemoved_Variation: _xlfn.LAMBDA("VARIATION FROM SOURCE: Added this equation to accommodate user-defined residue removal other than baling.")
Name AgResidue_Equations_FieldBurning.VEERG_6_4_1_1__1__MethaneEmissionsFromBurningOfCropResidues: _xlfn.LAMBDA(_xlpm.Mburnc,_xlpm.CCc,_xlpm.EFCH4,_xlpm.C_CH4, _xlpm.Mburnc * _xlpm.CCc * _xlpm.EFCH4 * _xlpm.C_CH4 * 10 ^ (-3))
Name AgResidue_Equations_FieldBurning.VEERG_6_4_1_1__1__MethaneEmissionsFromBurningOfCropResidues_FunctionName: _xlfn.LAMBDA("VEERG_6_4_1_1__1__MethaneEmissionsFromBurningOfCropResidues")
Name AgResidue_Equations_FieldBurning.VEERG_6_4_1_1__1__MethaneEmissionsFromBurningOfCropResidues_LatexEquation: _xlfn.LAMBDA("E_{CH4}=\sum_{c}(M_{burn,c}\times CC_{c}\times EF_{CH4}\times C_{CH4}\times 10^{-3})")
Name AgResidue_Equations_FieldBurning.VEERG_6_4_1_1__1__MethaneEmissionsFromBurningOfCropResidues_NIRReference: _xlfn.LAMBDA("")
Name AgResidue_Equations_FieldBurning.VEERG_6_4_1_1__1__MethaneEmissionsFromBurningOfCropResidues_Source: _xlfn.LAMBDA("VEERG 2026: 6.4.1.1, Equation (1)")
Name AgResidue_Equations_FieldBurning.VEERG_6_4_1_1__1__MethaneEmissionsFromBurningOfCropResidues_Title: _xlfn.LAMBDA("Methane emissions from the burning of crop residues")
Name AgResidue_Equations_FieldBurning.VEERG_6_4_1_1__1__MethaneEmissionsFromBurningOfCropResidues_Unit: _xlfn.LAMBDA("t CH4")
Name AgResidue_Equations_FieldBurning.VEERG_6_4_1_1__1__MethaneEmissionsFromBurningOfCropResidues_Variable: _xlfn.LAMBDA("ECH4")
Name AgResidue_Equations_FieldBurning.VEERG_6_4_1_1__2__NitrousOxideEmissionsFromBurningOfCropResidues: _xlfn.LAMBDA(_xlpm.Mburnc,_xlpm.NCAGc,_xlpm.EFN2O,_xlpm.CN2O, _xlpm.Mburnc * _xlpm.NCAGc * _xlpm.EFN2O * _xlpm.CN2O * 10 ^ (-3))
Name AgResidue_Equations_FieldBurning.VEERG_6_4_1_1__2__NitrousOxideEmissionsFromBurningOfCropResidues_FunctionName: _xlfn.LAMBDA("VEERG_6_4_1_1__2__NitrousOxideEmissionsFromBurningOfCropResidues")
Name AgResidue_Equations_FieldBurning.VEERG_6_4_1_1__2__NitrousOxideEmissionsFromBurningOfCropResidues_LatexEquation: _xlfn.LAMBDA("E_{N2O}=\sum_{c}(M_{burn,c}\times NC_{AGc}\times EF_{N2O}\times C_{N2O}\times 10^{-3})")
Name AgResidue_Equations_FieldBurning.VEERG_6_4_1_1__2__NitrousOxideEmissionsFromBurningOfCropResidues_NIRReference: _xlfn.LAMBDA("")
Name AgResidue_Equations_FieldBurning.VEERG_6_4_1_1__2__NitrousOxideEmissionsFromBurningOfCropResidues_Source: _xlfn.LAMBDA("VEERG 2026: 6.4.1.1, Equation (2)")
Name AgResidue_Equations_FieldBurning.VEERG_6_4_1_1__2__NitrousOxideEmissionsFromBurningOfCropResidues_Title: _xlfn.LAMBDA("Nitrous oxide emissions from the burning of crop residues")
Name AgResidue_Equations_FieldBurning.VEERG_6_4_1_1__2__NitrousOxideEmissionsFromBurningOfCropResidues_Unit: _xlfn.LAMBDA("t N2O")
Name AgResidue_Equations_FieldBurning.VEERG_6_4_1_1__2__NitrousOxideEmissionsFromBurningOfCropResidues_Variable: _xlfn.LAMBDA("EN2O")
Name AgResidue_Equations_FieldBurning.VEERG_6_4_1_1__3__MassOfCropResidueBurnt: _xlfn.LAMBDA(_xlpm.Pc,_xlpm.RAGc,_xlpm.Sc,_xlpm.DMc,_xlpm.Zc,_xlpm.Fc, _xlpm.Pc * _xlpm.RAGc * _xlpm.Sc * _xlpm.DMc * _xlpm.Zc * _xlpm.Fc)
Name AgResidue_Equations_FieldBurning.VEERG_6_4_1_1__3__MassOfCropResidueBurnt_FunctionName: _xlfn.LAMBDA("VEERG_6_4_1_1__3__MassOfCropResidueBurnt")
Name AgResidue_Equations_FieldBurning.VEERG_6_4_1_1__3__MassOfCropResidueBurnt_LatexEquation: _xlfn.LAMBDA("M_{burn,c}=P_{c}\times R_{AGc}\times S_{c}\times DM_{c}\times Z_{c}\times F_{c}")
Name AgResidue_Equations_FieldBurning.VEERG_6_4_1_1__3__MassOfCropResidueBurnt_NIRReference: _xlfn.LAMBDA("")
Name AgResidue_Equations_FieldBurning.VEERG_6_4_1_1__3__MassOfCropResidueBurnt_Source: _xlfn.LAMBDA("VEERG 2026: 6.4.1.1, Equation (3)")
Name AgResidue_Equations_FieldBurning.VEERG_6_4_1_1__3__MassOfCropResidueBurnt_Title: _xlfn.LAMBDA("Mass of residue of crop c burnt")
Name AgResidue_Equations_FieldBurning.VEERG_6_4_1_1__3__MassOfCropResidueBurnt_Unit: _xlfn.LAMBDA("kg")
Name AgResidue_Equations_FieldBurning.VEERG_6_4_1_1__3__MassOfCropResidueBurnt_Variable: _xlfn.LAMBDA("Mburnc")
Name AgResidue_Equations_Leaching.VEERG_6_3_1_1__1__LeachingAndRunoffEmissionsCropAndPastureResidue: _xlfn.LAMBDA(_xlpm.Mleachcp,_xlpm.EFleach,_xlpm.CgN2O, _xlpm.Mleachcp * _xlpm.EFleach * _xlpm.CgN2O * 10 ^ (-3))
Name AgResidue_Equations_Leaching.VEERG_6_3_1_1__1__LeachingAndRunoffEmissionsCropAndPastureResidue_LatexEquation: _xlfn.LAMBDA("E_{N2O}=\sum_{c}\sum_{p}(M_{leach,cp}\times EF_{leach}\times Cg_{N2O}\times 10^{-3})")
Name AgResidue_Equations_Leaching.VEERG_6_3_1_1__1__LeachingAndRunoffEmissionsCropAndPastureResidue_NIRReference: _xlfn.LAMBDA("")
Name AgResidue_Equations_Leaching.VEERG_6_3_1_1__1__LeachingAndRunoffEmissionsCropAndPastureResidue_Source: _xlfn.LAMBDA("VEERG 2026: 6.3.1.1, Equation (1)")
Name AgResidue_Equations_Leaching.VEERG_6_3_1_1__1__LeachingAndRunoffEmissionsCropAndPastureResidue_Title: _xlfn.LAMBDA("Nitrous oxide leaching and runoff emissions from crop and pasture residues returned to the soil")

Sheet Home
A1: Home

Sheet Overview
A1: #VALUE! | C1: 6: Agricultural Residue Management: Overview
A3: =HYPERLINK("#'Home'!A1", "Home") -> Home
A4: =HYPERLINK("#'Overview'!A1", "Overview") -> Overview
A5: =HYPERLINK("#'Results'!A1", "Results") -> Results | D5: 💡 Below is a diagram that maps the equations used to calculate emissions, and how they interact with each other.
D6: Click on a box to go to the corresponding calculation.
A7: INPUTS
A8: =HYPERLINK("#'Input - Site'!A1", "Site") -> Site
A9: =HYPERLINK("#'Input - Fertiliser'!A1", "Fertiliser") -> Fertiliser
A11: CALCULATIONS
A12: =HYPERLINK("#'5.1.1.1-2 Inorganic Fert N2O'!A1", "5.1.1.1-2 Inorganic Fert N2O") -> 5.1.1.1-2 Inorganic Fert N2O
A13: =HYPERLINK("#'5.1.1.3-4 Inorganic fert CO2'!A1", "5.1.1.3-4 Inorganic fert CO2") -> 5.1.1.3-4 Inorganic fert CO2
A14: =HYPERLINK("#'5.2.1.1-2 Organic Fert N2O'!A1", "5.2.1.1-2 Organic Fert N2O") -> 5.2.1.1-2 Organic Fert N2O
A15: =HYPERLINK("#'5.3.1.1-2 Lime CO2'!A1", "5.3.1.1-2 Lime CO2") -> 5.3.1.1-2 Lime CO2
A16: =HYPERLINK("#'5.4.1.1-4 Atmos deposition'!A1", "5.4.1.1-4 Atmos deposition") -> 5.4.1.1-4 Atmos deposition
A17: =HYPERLINK("#'5.5.1.1-2 Leaching and runoff'!A1", "5.5.1.1-2 Leaching and runoff") -> 5.5.1.1-2 Leaching and runoff
A19: APPENDICES
A20: =HYPERLINK("#'Constants - Fertiliser'!A1", "Constants - Fertiliser") -> Constants - Fertiliser
A21: =HYPERLINK("#'Constants - Common'!A1", "Constants - Common") -> Constants - Common
L37: `

Sheet Results
A1: #VALUE! | C1: 6: Agricultural Residue Management: Results
A3: =HYPERLINK("#'Home'!A1", "Home") -> Home
A4: =HYPERLINK("#'Overview'!A1", "Overview") -> Overview | D4: Emissions breakdown
A5: =HYPERLINK("#'Results'!A1", "Results") -> Results
D6: 💡 NOTE: When there is no Method 2, the Method 2 result are the same as Method 1
A7: INPUTS
A8: =HYPERLINK("#'Input - Site'!A1", "Site") -> Site | D8: Scope 1 source | E8: GHG emissions method 1 | F8: GHG emissions method 2 | G8: GHG Unit | H8: CO2-e emissions method 1 | I8: CO2-e emissions method 2 | J8: CO2-e unit
A9: =HYPERLINK("#'Input - Fertiliser'!A1", "Fertiliser") -> Fertiliser | D9: 5.1.1.1-2 Inorganic fertiliser N2O | E9: ='6.1.1.1-2 Crop residue N2O'!$D$42 -> EN2O | F9: ='6.1.1.1-2 Crop residue N2O'!$N$88 -> 0 | G9: t N2O | H9: ='6.1.1.1-2 Crop residue N2O'!D47 -> ECO2e | I9: ='6.1.1.1-2 Crop residue N2O'!N93 -> 0 | J9: t CO2e
D10: 5.1.1.3-4 Inorganic fertiliser CO2 | E10: ='6.2.1.1-2 Pasture residue N2O'!$E$77 -> 0 | F10: =E10 -> 0 | G10: t CO2 | H10: ='6.2.1.1-2 Pasture residue N2O'!$E$77 -> 0 | I10: =H10 -> 0 | J10: t CO2e
A11: CALCULATIONS | D11: 5.2.1.1-2 Organic fertiliser N2O | E11: ='5.2.1.1-2 Organic Fert N2O'!$E$50 -> #REF! | F11: =E11 -> #REF! | G11: t N2O | H11: ='5.2.1.1-2 Organic Fert N2O'!$E$55 -> #REF! | I11: =H11 -> #REF! | J11: t CO2e
A12: =HYPERLINK("#'5.1.1.1-2 Inorganic Fert N2O'!A1", "5.1.1.1-2 Inorganic Fert N2O") -> 5.1.1.1-2 Inorganic Fert N2O | D12: 5.3.1.1-3 Lime CO2 | E12: ='5.3.1.1-2 Lime CO2'!$E$31 -> #REF! | F12: =E12 -> #REF! | G12: t CO2 | H12: ='5.3.1.1-2 Lime CO2'!$E$31 -> #REF! | I12: =H12 -> #REF! | J12: t CO2e
A13: =HYPERLINK("#'5.1.1.3-4 Inorganic fert CO2'!A1", "5.1.1.3-4 Inorganic fert CO2") -> 5.1.1.3-4 Inorganic fert CO2 | D13: 5.4.1.1-5 Atmospheric deposition | E13: ='5.4.1.1-4 Atmos deposition'!$E$144 -> #REF! | F13: =E13 -> #REF! | G13: t N2O | H13: ='5.4.1.1-4 Atmos deposition'!$E$149 -> #REF! | I13: =H13 -> #REF! | J13: t CO2e
A14: =HYPERLINK("#'5.2.1.1-2 Organic Fert N2O'!A1", "5.2.1.1-2 Organic Fert N2O") -> 5.2.1.1-2 Organic Fert N2O | D14: 5.5.1.1-2 Leaching and runoff | E14: ='5.5.1.1-2 Leaching and runoff'!$E$93 -> #VALUE! | F14: =E14 -> #VALUE! | G14: t N2O | H14: ='5.5.1.1-2 Leaching and runoff'!$E$98 -> #VALUE! | I14: =H14 -> #VALUE! | J14: t CO2e
A15: =HYPERLINK("#'5.3.1.1-2 Lime CO2'!A1", "5.3.1.1-2 Lime CO2") -> 5.3.1.1-2 Lime CO2 | D15: Total | H15: =SUM(H9:H14) -> #REF! | I15: =SUM(I9:I14) -> #REF! | J15: t CO2e
A16: =HYPERLINK("#'5.4.1.1-4 Atmos deposition'!A1", "5.4.1.1-4 Atmos deposition") -> 5.4.1.1-4 Atmos deposition
A17: =HYPERLINK("#'5.5.1.1-2 Leaching and runoff'!A1", "5.5.1.1-2 Leaching and runoff") -> 5.5.1.1-2 Leaching and runoff
A19: APPENDICES
A20: =HYPERLINK("#'Constants - Fertiliser'!A1", "Constants - Fertiliser") -> Constants - Fertiliser
A21: =HYPERLINK("#'Constants - Common'!A1", "Constants - Common") -> Constants - Common

Sheet Input - Site
A1: #VALUE! | C1: Input - Site
A3: =HYPERLINK("#'Home'!A1", "Home") -> Home
A4: =HYPERLINK("#'Overview'!A1", "Overview") -> Overview
A5: =HYPERLINK("#'Results'!A1", "Results") -> Results | D5: Your business
A7: INPUTS | D7: Farm name | E7: Test Farms
A8: =HYPERLINK("#'Input - Site'!A1", "Site") -> Site | D8: Reporting entity name | E8: Test Farms Pty Ltd
A9: =HYPERLINK("#'Input - Fertiliser'!A1", "Fertiliser") -> Fertiliser
D10: 💡An 'Emissions accounting period' is a 12 month period where the business can report on the emissions, and is typically the same as the business' financial accounting period.
A11: CALCULATIONS
A12: =HYPERLINK("#'5.1.1.1-2 Inorganic Fert N2O'!A1", "5.1.1.1-2 Inorganic Fert N2O") -> 5.1.1.1-2 Inorganic Fert N2O | D12: Emissions calculation period start date | E12: 45292 | F12: ← DD/MM/YYYY or DD Month YYYY
A13: =HYPERLINK("#'5.1.1.3-4 Inorganic fert CO2'!A1", "5.1.1.3-4 Inorganic fert CO2") -> 5.1.1.3-4 Inorganic fert CO2 | D13: Emissions calculation period end date | E13: =DATE(YEAR(E12)+1,MONTH(E12),DAY(E12))-1 -> 45657 | F13: ← Automatically calculated, 12 months after start date
A14: =HYPERLINK("#'5.2.1.1-2 Organic Fert N2O'!A1", "5.2.1.1-2 Organic Fert N2O") -> 5.2.1.1-2 Organic Fert N2O
A15: =HYPERLINK("#'5.3.1.1-2 Lime CO2'!A1", "5.3.1.1-2 Lime CO2") -> 5.3.1.1-2 Lime CO2
A16: =HYPERLINK("#'5.4.1.1-4 Atmos deposition'!A1", "5.4.1.1-4 Atmos deposition") -> 5.4.1.1-4 Atmos deposition | D16: Location and climate
A17: =HYPERLINK("#'5.5.1.1-2 Leaching and runoff'!A1", "5.5.1.1-2 Leaching and runoff") -> 5.5.1.1-2 Leaching and runoff
D18: Location information is used to reference some region and climate-specific emission factors
A19: APPENDICES | D19: Tip: Use the web-based GAF Location Helper tool to easily get region and climate information. You will need an internet connection to use the GAF Location Helper.
A20: =HYPERLINK("#'Constants - Fertiliser'!A1", "Constants - Fertiliser") -> Constants - Fertiliser
A21: =HYPERLINK("#'Constants - Common'!A1", "Constants - Common") -> Constants - Common | D21: State | E21: Western Australia | F21: ← Please select
D22: Region (ABS Statistical area level 4) if state is WA | E22: Western Australia - Outback (South) | F22: ← Please select
D23: Leaching zone | E23: NO - Not in leaching zone | F23: ← Please select
D24: Elevation | E24: 307.7 | F24: Meters
D25: Average temperature for reporting period | E25: 18 | F25: Degrees celsius
D26: Total rainfall for reporting period | E26: 599 | F26: Millimetres
D27: Potential evapotranspiration for reporting period | E27: 1326 | F27: Millimetres
D28: Number of frost days for reporting period | E28: 7 | F28: Days
D29: MAP:PET ratio | E29: =E26/E27 -> 0.45173454
D30: Rainfall zone | E30: =Common_InputFunctions.Utility_LookupItemFromMinMax(E26,Table_SourceData_RainfallZones[Min rainfall],Table_SourceData_RainfallZones[Max rainfall],Table_SourceData_RainfallZones[Rainfall Zone]) -> Low rainfall
D31: Climate zone | E31: =Common_InputFunctions.Utility_GetClimateZone(E25,E26,E28,E24,E29,Table_SourceData_ClimateZones[Min temp],Table_SourceData_ClimateZones[Max temp],Table_SourceData_ClimateZones[Min rainfall],Table_SourceData_ClimateZones[Max rainfall],Table_SourceData_ClimateZones[Min frost days],Table_SourceData_ClimateZones[Max frost days],Table_SourceData_ClimateZones[Min elevation],Table_SourceData_ClimateZones[Max elevation],Table_SourceData_ClimateZones[Min MAP:PET],Table_SourceData_ClimateZones[Max MAP:PET],Table_SourceData_ClimateZones[Climate zone]) -> Warm temperate dry
D32: Wet or dry climate zone | E32: =Common_InputFunctions.Utility_LookupValueInTable($E$31,Table_SourceData_WetDryZones[Climate zone],Table_SourceData_WetDryZones[Wet or Dry Zone]) -> Dry climate zone
D33: Temperature zone | E33: =Common_InputFunctions.Utility_LookupItemFromMinMax(E25,Table_SourceData_TemperatureZones[Min MAT],Table_SourceData_TemperatureZones[Max MAT],Table_SourceData_TemperatureZones[Temperature Zone]) -> Temperate

Sheet Input - Crop
A1: #VALUE! | C1: Input - Crop
A3: =HYPERLINK("#'Home'!A1", "Home") -> Home
A4: =HYPERLINK("#'Overview'!A1", "Overview") -> Overview
A5: =HYPERLINK("#'Results'!A1", "Results") -> Results | D5: Area
A7: INPUTS | D7: If multiple paddocks were managed in the same way at the same time, you can enter information for them all together.
A8: =HYPERLINK("#'Input - Site'!A1", "Site") -> Site
A9: =HYPERLINK("#'Input - Fertiliser'!A1", "Fertiliser") -> Fertiliser | D9: Crop type | E9: Wheat | F9: ← Please select
D10: Crop purpose | E10: Cover crop | F10: ← Please select | J10: Purpose | K10: Per hectare unit | L10: harvest term | M10: harvest endpoint | N10: Harvest uit
A11: CALCULATIONS | D11: Irrigation method | E11: Sprinkler irrigation | F11: ← Please select | J11: Cash grain crop | K11: grain | L11: yield | M11: harvest | N11: grain
A12: =HYPERLINK("#'5.1.1.1-2 Inorganic Fert N2O'!A1", "5.1.1.1-2 Inorganic Fert N2O") -> 5.1.1.1-2 Inorganic Fert N2O | J12: Cash crop for hay/silage | K12: above ground biomass | L12: yield | M12: harvest | N12: plant biomass
A13: =HYPERLINK("#'5.1.1.3-4 Inorganic fert CO2'!A1", "5.1.1.3-4 Inorganic fert CO2") -> 5.1.1.3-4 Inorganic fert CO2 | D13: Area under cropping | E13: 100 | F13: Hectares | J13: Cover crop | K13: above ground biomass | L13: mass | M13: end of crop cycle | N13: above ground biomass
A14: =HYPERLINK("#'5.2.1.1-2 Organic Fert N2O'!A1", "5.2.1.1-2 Organic Fert N2O") -> 5.2.1.1-2 Organic Fert N2O
A15: =HYPERLINK("#'5.3.1.1-2 Lime CO2'!A1", "5.3.1.1-2 Lime CO2") -> 5.3.1.1-2 Lime CO2 | D15: Yield
A16: =HYPERLINK("#'5.4.1.1-4 Atmos deposition'!A1", "5.4.1.1-4 Atmos deposition") -> 5.4.1.1-4 Atmos deposition
A17: =HYPERLINK("#'5.5.1.1-2 Leaching and runoff'!A1", "5.5.1.1-2 Leaching and runoff") -> 5.5.1.1-2 Leaching and runoff | D17: 💡 'Harvest index' is the ratio of harvested product weight to the total above-ground plant biomass.
D18: A default value is provided based on crop type. You can edit this if known.
A19: APPENDICES
A20: =HYPERLINK("#'Constants - Fertiliser'!A1", "Constants - Fertiliser") -> Constants - Fertiliser | D20: =E10 & " " & VLOOKUP(E10,J11:L13, 3) & " per hectare" -> Cover crop mass per hectare | E20: 10 | F20: ="Tonnes " & VLOOKUP(E10, J11:K13, 2, FALSE) & " per hectare" -> Tonnes above ground biomass per hectare
A21: =HYPERLINK("#'Constants - Common'!A1", "Constants - Common") -> Constants - Common | D21: Residue:crop ratio | E21: {=_xlfn.IFS(E10="Cash grain crop", Common_InputFunctions.Utility_LookupValueInTableNumber(E9, Table_SourceData_CropAttributes[Crop type],Table_SourceData_CropAttributes[Residue: Crop ratio]), E10="Cash crop for hay/silage", 0, E10="Cover crop", 1)} -> 1
D22: Crop residue biomass | E22: =E20*E21 -> 10 | F22: Tonnes per hectare
D23: Whole plant above ground biomass | E23: =E20+E22 -> 20 | F23: Tonnes per hectare
D25: Total production of crop | E25: =E20*E13 -> 1000 | F25: ="Tonnes " & VLOOKUP(E10, J11:N13, 5, FALSE) -> Tonnes above ground biomass
D28: Residue management
D30: ="Residue after " & VLOOKUP(E10,J11:M13, 4, FALSE) -> Residue after end of crop cycle | E30: =E22*E13 -> 1000 | F30: Tonnes
D32: Baled residue
D33: Percentage of residue that was baled | E33: 0.1 | F33: Percent
D34: Average weight per bale | E34: 60 | F34: Kilograms
D35: Number of bales | E35: =IFERROR((E36*10^3)/E34, 0) -> 1666.6667 | F35: Bales
D36: Total residue baled | E36: =E30*E33 -> 100 | F36: Tonnes
D38: Grazed residue
D39: Percentage of residue that was grazed | E39: 0.01 | F39: Percent
D40: Total residue grazed | E40: =E30*E39 -> 10 | F40: Tonnes
D42: Burned residue
D43: Percentage of residue that was burned | E43: 0.3 | F43: Percent
A44: =HYPERLINK("#A1", "▲ Back to top") -> ▲ Back to top | D44: Total residue burned | E44: =E30*E43 -> 300 | F44: Tonnes
D46: Residue retained on paddocks | E46: =E30-E36-E40-E44 -> 590 | F46: Tonnes

Sheet Input - Pasture
A1: #VALUE! | C1: Input - Pasture
D5: Area
D7: If multiple paddocks were managed in the same way at the same time, you can enter information for them all together.
D9: Pasture type | E9: Annual grass | F9: ← Please select
D10: Irrigation method | E10: Sprinkler irrigation | F10: ← Please select
D12: Area under pasture | E12: 100 | F12: Hectares
D14: Yield
D16: 💡 'Pasture yield' is the average amount of dry matter that is grazed.
D17: A default value is provided based on pasture type. You can edit this if known.
D19: Pasture yield | E19: {=Common_InputFunctions.Utility_LookupValueInTable(E9, [1]!Table_SourceData_PastureAttributes[Pasture type],[1]!Table_SourceData_PastureAttributes[Average Yield (t DM ha) Yp])} -> 4.41 | F19: Tonnes dry matter / hectare
D20: Total pasture yield | E20: =E12*E19 -> 441 | F20: Tonnes
D23: Residue management
D25: Area of pasture renewed or removed | E25: 50 | F25: Hectares

Sheet 6.1.1.1-2 Crop residue N2O
A1: #VALUE! | C1: 6.1.1.1-2 Crop residue N2O emissions
D3: Method 1 | M3: Method 2
D5: {=AgResidue_Equations_CropResidue.VEERG_6_1_1_1__2__MassOfNitrogenInCropResidues_Title()} -> Mass of nitrogen in crop residues returned to the soil | M5: {=AgResidue_Equations_CropResidue.VEERG_6_1_1_2__1__FractionOfCropResidueRemovedBaled_Title()} -> Fraction of crop residue that is removed for crop c, calculated where residues are baled
D6: {=AgResidue_Equations_CropResidue.VEERG_6_1_1_1__2__MassOfNitrogenInCropResidues_Source()} -> VEERG 2026: 6.1.1.1, Equation (2) | M6: {=AgResidue_Equations_CropResidue.VEERG_6_1_1_2__1__FractionOfCropResidueRemovedBaled_Source()} -> VEERG 2026: 6.1.1.2, Equation (1)
D7: Function name | E7: {=Common_InputFunctions.Utility_DisplayFunctionName(E24)} -> =AgResidue_Equations_CropResidue.VEERG_6_1_1_1__2__MassOfNitrogenInCropResidues | M7: {="⚠️" & AgResidue_Equations_CropResidue.VEERG_6_1_1_2__1__FractionOfCropResidueRemovedBaled_Variation()} -> ⚠️VARIATION FROM SOURCE: Added 'baled' to variable subscript
M8: Function name | N8: {=Common_InputFunctions.Utility_DisplayFunctionName(N21)} -> =AgResidue_Equations_CropResidue.VEERG_6_1_1_2__1__FractionOfCropResidueRemovedBaled
D10: Variable | E10: {=AgResidue_Equations_CropResidue.VEERG_6_1_1_1__2__MassOfNitrogenInCropResidues_Variable()} -> M_c
D11: Unit | E11: {=AgResidue_Equations_CropResidue.VEERG_6_1_1_1__2__MassOfNitrogenInCropResidues_Unit()} -> kg N
M12: Variable | N12: {=AgResidue_Equations_CropResidue.VEERG_6_1_1_2__1__FractionOfCropResidueRemovedBaled_Variable()} -> FFOD_cbaled
D13: {=_xlfn.CHOOSECOLS(AgResidue_Equations_CropResidue.VEERG_6_1_1_1__2__MassOfNitrogenInCropResidues_Arguments(), 1, 2)} -> P_c | E13: annual production of crop c | G13: {=_xlfn.CHOOSECOLS(AgResidue_Equations_CropResidue.VEERG_6_1_1_1__2__MassOfNitrogenInCropResidues_Arguments(), 3,4)} -> kg | H13: Input | I13: ='Input - Crop'!$E$20*10^3 -> 10000 | M13: Unit | N13: {=AgResidue_Equations_CropResidue.VEERG_6_1_1_2__1__FractionOfCropResidueRemovedBaled_Unit()} -> dimensionless
D14: R_AGc | E14: residue to crop ratio for crop c | G14: dimensionless | H14: Constant | I14: ='Input - Crop'!$E$21 -> 1
D15: R_BGc | E15: below ground-residue to above ground residue ratio for crop c | G15: dimensionless | H15: Constant | I15: {=Common_InputFunctions.Utility_LookupValueInTableNumber($I$21,Table_SourceData_CropAttributes[Crop type],Table_SourceData_CropAttributes[Below-ground: above-ground residue ratio])} -> 0.29 | M15: {=_xlfn.CHOOSECOLS(AgResidue_Equations_CropResidue.VEERG_6_1_1_2__1__FractionOfCropResidueRemovedBaled_Arguments(), 1, 2)} -> B | N15: number of bales generated | O15: {=_xlfn.CHOOSECOLS(AgResidue_Equations_CropResidue.VEERG_6_1_1_2__1__FractionOfCropResidueRemovedBaled_Arguments(), 3,4)} -> dimensionless | P15: Input | Q15: ='Input - Crop'!$E$35 -> 1666.6667
D16: F_c | E16: fraction of crop residue that is burnt for crop c | G16: dimensionless | H16: Input | I16: ='Input - Crop'!$E$43 -> 0.3 | M16: M_B | N16: mass of each bale | O16: kg | P16: Input | Q16: ='Input - Crop'!$E$34 -> 60
D17: FFOD_c | E17: fraction of the crop residue that is removed for crop c | G17: dimensionless | H17: Constant | I17: {=IF(ISNUMBER(_xlfn.XLOOKUP(1, (Table77[Crop type c]=$I$21)*(Table77[State]=$I$22),Table77[Fraction removed])), _xlfn.XLOOKUP(1, (Table77[Crop type c]=$I$21)*(Table77[State]=$I$22),Table77[Fraction removed]), 0)} -> 0.11 | M17: P_c | N17: annual production of crop c | O17: kg | P17: Input | Q17: ='Input - Crop'!$E$25*10^3 -> 1000000
D18: DM_c | E18: dry matter content of crop c | G18: kg dry weight/kg crop residue | H18: Constant | I18: {=Common_InputFunctions.Utility_LookupValueInTableNumber($I$21,Table_SourceData_CropAttributes[Crop type],Table_SourceData_CropAttributes[Dry matter content])} -> 0.88 | M18: R_AGc | N18: residue to crop ratio for crop c | O18: dimensionless | P18: Input | Q18: ='Input - Crop'!$E$21 -> 1
D19: NC_AGc | E19: nitrogen content of above-ground crop residue of crop c | G19: kg N/kg DM | H19: Constant | I19: {=Common_InputFunctions.Utility_LookupValueInTableNumber($I$21,Table_SourceData_CropAttributes[Crop type],Table_SourceData_CropAttributes[N content above-ground])} -> 0.006 | M19: c | N19: Crop type | P19: Input | Q19: ='[1]Input - Grains'!$E$9 -> Wheat
D20: NC_BGc | E20: nitrogen content of below-ground crop residue of crop c | G20: kg N/kg DM | H20: Constant | I20: {=Common_InputFunctions.Utility_LookupValueInTableNumber($I$21,Table_SourceData_CropAttributes[Crop type],Table_SourceData_CropAttributes[N content below-ground])} -> 0.01
D21: c | E21: Crop type | H21: Input | I21: ='Input - Crop'!$E$9 -> Wheat | M21: FFODc,baled | N21: {=AgResidue_Equations_CropResidue.VEERG_6_1_1_2__1__FractionOfCropResidueRemovedBaled(Q15,Q16,Q17,Q18)} -> 0.1
D22: State | E22: State or territory | H22: Input | I22: {=Common_InputFunctions.Utility_ConvertStateCommonNameToAbbreviation('Input - Site'!$E$21,Table_AustralianStates[Common Name],Table_AustralianStates[Abbreviation])} -> WA
D24: Mc | E24: {=AgResidue_Equations_CropResidue.VEERG_6_1_1_1__2__MassOfNitrogenInCropResidues(I13,I14,I16,I17,I18,I19,I15,I20)} -> 56.672 | F24: =$E$11 -> kg N | M24: {=AgResidue_Equations_CropResidue.VEERG_6_1_1_2__1a__FractionOfCropResidueRemoved_Title()} -> Fraction of crop residue that is removed for crop c
M25: {=AgResidue_Equations_CropResidue.VEERG_6_1_1_2__1a__FractionOfCropResidueRemoved_Source()}
M26: {="⚠️" & AgResidue_Equations_CropResidue.VEERG_6_1_1_2__1a__FractionOfCropResidueRemoved_Variation()} -> ⚠️VARIATION FROM SOURCE: Added this equation to accommodate user-defined residue removal other than baling.
D28: {=AgResidue_Equations_CropResidue.VEERG_6_1_1_1__1__NitrousOxideEmissionsFromCropResidues_Title()} -> Nitrous oxide emissions from the return of crop residues across all crops c to the soil
D29: {=AgResidue_Equations_CropResidue.VEERG_6_1_1_1__1__NitrousOxideEmissionsFromCropResidues_Source()} -> VEERG 2026: 6.1.1.1, Equation (1)
D30: Function name | E30: {=Common_InputFunctions.Utility_DisplayFunctionName(E42)} -> =AgResidue_Equations_CropResidue.VEERG_6_1_1_1__1__NitrousOxideEmissionsFromCropResidues | M30: Variable | N30: {=AgResidue_Equations_CropResidue.VEERG_6_1_1_2__1a__FractionOfCropResidueRemoved_Variable()} -> FFOD_c
M31: Unit | N31: {=AgResidue_Equations_CropResidue.VEERG_6_1_1_2__1a__FractionOfCropResidueRemoved_Unit()} -> dimensionless
D33: Variable | E33: {=AgResidue_Equations_CropResidue.VEERG_6_1_1_1__1__NitrousOxideEmissionsFromCropResidues_Variable()} -> E | M33: {=_xlfn.CHOOSECOLS(AgResidue_Equations_CropResidue.VEERG_6_1_1_2__1a__FractionOfCropResidueRemoved_Arguments(), 1, 2)} -> FFOD_cbaled | N33: Fraction of crop residue that is removed for crop c, calculated where residues are baled | Q33: {=_xlfn.CHOOSECOLS(AgResidue_Equations_CropResidue.VEERG_6_1_1_2__1a__FractionOfCropResidueRemoved_Arguments(), 3,4)} -> fraction | R33: Calculated from 6.1.1.2, (1) | S33: =$N$21 -> 0.1
D34: Unit | E34: {=AgResidue_Equations_CropResidue.VEERG_6_1_1_1__1__NitrousOxideEmissionsFromCropResidues_Unit()} -> t N2O | M34: FFOD_cother | N34: Fraction of crop residue that is removed for crop c, calculated where residues are removed by other means | Q34: fraction | R34: Input | S34: ='Input - Crop'!$E$39 -> 0.01
D36: {=_xlfn.CHOOSECOLS(AgResidue_Equations_CropResidue.VEERG_6_1_1_1__1__NitrousOxideEmissionsFromCropResidues_Arguments(), 1, 2)} -> M_c | E36: mass of nitrogen in crop c residues returned to the soil | G36: {=_xlfn.CHOOSECOLS(AgResidue_Equations_CropResidue.VEERG_6_1_1_1__1__NitrousOxideEmissionsFromCropResidues_Arguments(), 3,4)} -> kg N | H36: Calculated from 6.1.1.1 (2) | I36: =E24 -> 56.672 | M36: FFODc | N36: {=AgResidue_Equations_CropResidue.VEERG_6_1_1_2__1a__FractionOfCropResidueRemoved($S$33,$S$34)} -> 0.11
A37: =HYPERLINK("#A1", "▲ Back to top") -> ▲ Back to top | D37: EF_Ni | E37: emission factor for crop residues returned to the soil | G37: kg N2O-N/kg N | H37: Constant | I37: {=Common_InputFunctions.Utility_LookupValueInTableNumber(I40,Table_SourceData_N2OEFOrganicFert[Climate zone type i],Table_SourceData_N2OEFOrganicFert[EF i N2O])} -> 0.005
D38: C_N2O | E38: factor to convert elemental mass of nitrous oxide to molecular mass | G38: dimensionless | H38: Constant | I38: =Common_InputFunctions.Utility_LookupValueInTableNumber("N2O",Table_GasToMolecularConversionFactor[Gas],Table_GasToMolecularConversionFactor[Conversion factor combined]) -> 1.5714286
D39: c | E39: Crop type | H39: Input | I39: ='[1]Input - Grains'!$E$9 -> Wheat
D40: i | E40: Wet or dry climate zone | H40: Input | I40: ='Input - Site'!$E$32 -> Dry climate zone | M40: {=AgResidue_Equations_CropResidue.VEERG_6_1_1_1__2__MassOfNitrogenInCropResidues_Title()} -> Mass of nitrogen in crop residues returned to the soil
M41: {=AgResidue_Equations_CropResidue.VEERG_6_1_1_1__2__MassOfNitrogenInCropResidues_Source()} -> VEERG 2026: 6.1.1.1, Equation (2)
D42: EN2O | E42: {=AgResidue_Equations_CropResidue.VEERG_6_1_1_1__1__NitrousOxideEmissionsFromCropResidues(I36,I37,I38)} -> 0.00044528 | F42: =$E$34 -> t N2O | M42: Function name | N42: {=Common_InputFunctions.Utility_DisplayFunctionName(N59)} -> =AgResidue_Equations_CropResidue.VEERG_6_1_1_1__2__MassOfNitrogenInCropResidues
D44: {=Common_Equations.Common_ConvertN2OToCO2e_Arguments()} -> EN2O | E44: Nitrous oxide emissions (t N2O) | G44: =E42 -> 0.00044528
D45: GWPN2O | E45: Global warming potential for nitrous oxide (t CO2-e / t N2O) | G45: =Common_InputFunctions.Utility_LookupValueInTableNumber("N2O",Table_GWPData[Gas],Table_GWPData[CO2-e factor]) -> 265 | M45: Variable | N45: {=AgResidue_Equations_CropResidue.VEERG_6_1_1_1__2__MassOfNitrogenInCropResidues_Variable()} -> M_c
M46: Unit | N46: {=AgResidue_Equations_CropResidue.VEERG_6_1_1_1__2__MassOfNitrogenInCropResidues_Unit()} -> kg N
D47: ECO2e | E47: {=Common_Equations.Common_ConvertN2OToCO2e(G44,G45)} -> 0.1179992 | F47: {=Common_Equations.Common_ConvertN2OToCO2e_Unit()} -> t CO2e
M48: {=_xlfn.CHOOSECOLS(AgResidue_Equations_CropResidue.VEERG_6_1_1_1__2__MassOfNitrogenInCropResidues_Arguments_Method2(), 1, 2)} -> P_c | N48: annual production of crop c | P48: {=_xlfn.CHOOSECOLS(AgResidue_Equations_CropResidue.VEERG_6_1_1_1__2__MassOfNitrogenInCropResidues_Arguments_Method2(), 3,4)} -> kg | Q48: Input
...

Sheet 6.2.1.1-2 Pasture residue N2O
A1: #VALUE! | C1: 6.2.1.1-2 Return of pasture residue to soils
D3: Method 1 | O3: Method 2
D5: {=AgResidues_Equations_PastureResidues.VEERG_6_2_1_1__2__MassOfNitrogenInPastureResidues_Title()} -> Mass of nitrogen in pasture residues returned to the soil
D6: {=AgResidues_Equations_PastureResidues.VEERG_6_2_1_1__2__MassOfNitrogenInPastureResidues_Source()} -> VEERG 2026: 6.2.1.1, Equation (2)
D7: {=AgResidues_Equations_PastureResidues.VEERG_6_2_1_1__2__MassOfNitrogenInPastureResidues_NIRReference()}
D8: Function name | E8: {=Common_InputFunctions.Utility_DisplayFunctionName(E23)} -> =AgResidues_Equations_PastureResidues.VEERG_6_2_1_1__2__MassOfNitrogenInPastureResidues
D12: Variable | E12: {=AgResidues_Equations_PastureResidues.VEERG_6_2_1_1__2__MassOfNitrogenInPastureResidues_Variable()} -> Mp
D13: Unit | E13: {=AgResidues_Equations_PastureResidues.VEERG_6_2_1_1__2__MassOfNitrogenInPastureResidues_Unit()} -> kg N
D15: {=AgResidues_Equations_PastureResidues.VEERG_6_2_1_1__2__MassOfNitrogenInPastureResidues_Arguments()} -> Ap | E15: area of pasture renewed or removed (ha) | J15: ='Input - Pasture'!$E$25 -> 50
D16: Yp | E16: average yield of pasture crop (t DM/ha) | J16: ='Input - Pasture'!$E$19 -> 4.41
D17: NCAGp | E17: N content of above-ground pasture residue (kg N/kg DM) | J17: {=Common_InputFunctions.Utility_LookupValueInTableNumber($J$21,Table_SourceData_PastureAttributes[Pasture type],Table_SourceData_PastureAttributes[N content Above-ground NCAGp])} -> 0.015
D18: RBGp | E18: below-ground residue to above-ground residue ratio for pasture crop (dimensionless) | J18: {=Common_InputFunctions.Utility_LookupValueInTableNumber($J$21,Table_SourceData_PastureAttributes[Pasture type],Table_SourceData_PastureAttributes[Below-ground: above-ground residue ratio RBGp])} -> 0.4
D19: NCBGp | E19: N content of below-ground pasture crop residue (kg N/kg DM) | J19: {=Common_InputFunctions.Utility_LookupValueInTableNumber($J$21,Table_SourceData_PastureAttributes[Pasture type],Table_SourceData_PastureAttributes[N content Below-ground NCBGp])} -> 0.012
D20: FFODp | E20: fraction of pasture yield that is removed (dimensionless) | J20: {=Common_InputFunctions.Utility_LookupValueInTableNumber($J$21,Table_SourceData_PastureAttributes[Pasture type],Table_SourceData_PastureAttributes[Fraction of pasture yield that is removed FFODp])} -> 0.8
D21: p | E21: Pasture type | J21: ='Input - Pasture'!E9 -> Annual grass
D23: Mp | E23: {=AgResidues_Equations_PastureResidues.VEERG_6_2_1_1__2__MassOfNitrogenInPastureResidues(J15,J16,J20,J17,J18,J19)} -> 0.0017199 | F23: {=AgResidues_Equations_PastureResidues.VEERG_6_2_1_1__2__MassOfNitrogenInPastureResidues_Unit()} -> kg N
D27: {=AgResidues_Equations_PastureResidues.VEERG_6_2_1_1__1__NitrousOxideEmissionsFromPastureResidues_Title()} -> Nitrous oxide emissions from the return of pasture residues from all pasture types to the soil
D28: {=AgResidues_Equations_PastureResidues.VEERG_6_2_1_1__1__NitrousOxideEmissionsFromPastureResidues_Source()} -> VEERG 2026: 6.2.1.1, Equation (1)
D29: {=AgResidues_Equations_PastureResidues.VEERG_6_2_1_1__1__NitrousOxideEmissionsFromPastureResidues_NIRReference()}
D30: Function name | E30: {=Common_InputFunctions.Utility_DisplayFunctionName(E43)} -> =AgResidues_Equations_PastureResidues.VEERG_6_2_1_1__1__NitrousOxideEmissionsFromPastureResidues
D33: Variable | E33: {=AgResidues_Equations_PastureResidues.VEERG_6_2_1_1__1__NitrousOxideEmissionsFromPastureResidues_Variable()} -> EN2O
D34: Unit | E34: {=AgResidues_Equations_PastureResidues.VEERG_6_2_1_1__1__NitrousOxideEmissionsFromPastureResidues_Unit()} -> t N2O
D36: {=AgResidues_Equations_PastureResidues.VEERG_6_2_1_1__1__NitrousOxideEmissionsFromPastureResidues_Arguments()} -> Mp | E36: mass of nitrogen in pasture p residues returned to the soil (kg N) | J36: =E23 -> 0.0017199
D37: EFNi | E37: emission factor for crop residues returned to the soil in climate zone i (kg N2O-N/kg N) | J37: {=Common_InputFunctions.Utility_LookupValueInTableNumber(J40,Table_SourceData_N2OEFOrganicFert[Climate zone type i],Table_SourceData_N2OEFOrganicFert[EF i N2O])} -> 0.005
A38: =HYPERLINK("#A1", "▲ Back to top") -> ▲ Back to top | D38: CgN2O | E38: factor to convert elemental mass of nitrous oxide to molecular mass (dimensionless) | J38: =Common_InputFunctions.Utility_LookupValueInTableNumber("N2O",Table_GasToMolecularConversionFactor[Gas],Table_GasToMolecularConversionFactor[Conversion factor combined]) -> 1.5714286
D39: p | E39: Pasture type | J39: ='[1]Input - Pasture'!$E$9 -> Annual grass
D40: i | E40: Climate zone | J40: ='Input - Site'!$E$32 -> Dry climate zone
D43: EN2O | E43: {=AgResidues_Equations_PastureResidues.VEERG_6_2_1_1__1__NitrousOxideEmissionsFromPastureResidues(J36,J37,J38)} -> 1.35135e-08 | F43: {=AgResidues_Equations_PastureResidues.VEERG_6_2_1_1__1__NitrousOxideEmissionsFromPastureResidues_Unit()} -> t N2O
D45: {=Common_Equations.Common_ConvertN2OToCO2e_Arguments()} -> EN2O | E45: Nitrous oxide emissions (t N2O) | G45: =E43 -> 1.35135e-08
D46: GWPN2O | E46: Global warming potential for nitrous oxide (t CO2-e / t N2O) | G46: =Common_InputFunctions.Utility_LookupValueInTableNumber("N2O",Table_GWPData[Gas],Table_GWPData[CO2-e factor]) -> 265
D48: EN2O GWP | E48: {=Common_Equations.Common_ConvertN2OToCO2e(G45,G46)} -> 3.5810775e-06 | F48: {=Common_Equations.Common_ConvertN2OToCO2e_Unit()} -> t CO2e
A76: =HYPERLINK("#A1", "▲ Back to top") -> ▲ Back to top

Sheet 5.2.1.1-2 Organic Fert N2O
A1: #VALUE! | C1: 5.2.1.1 1-2 Organic fertiliser application N2O emissions
A3: =HYPERLINK("#'Home'!A1", "Home") -> Home | D3: Method 1 | O3: Method 2
A4: =HYPERLINK("#'Overview'!A1", "Overview") -> Overview
A5: =HYPERLINK("#'Results'!A1", "Results") -> Results | D5: {=Fertiliser_Equations_OrganicN2O.VEERG_5_2_1_1__2_MassOfNitrogenInOrganicFertiliser_Title()} -> Mass of nitrogen in purchased organic fertilisers applied to production system
D6: {=Fertiliser_Equations_OrganicN2O.VEERG_5_2_1_1__2_MassOfNitrogenInOrganicFertiliser_Source()} -> VEERG 2026: 5.2.1.1, Equation (2)
A7: INPUTS | D7: Function name | E7: {=Common_InputFunctions.Utility_DisplayFunctionName($I$20)} -> =Fertiliser_Equations_OrganicN2O.VEERG_5_2_1_1__2_MassOfNitrogenInOrganicFertiliser
A8: =HYPERLINK("#'Input - Site'!A1", "Site") -> Site
A9: =HYPERLINK("#'Input - Fertiliser'!A1", "Fertiliser") -> Fertiliser
D10: Variable | E10: {=Fertiliser_Equations_OrganicN2O.VEERG_5_2_1_1__2_MassOfNitrogenInOrganicFertiliser_Variable()} -> MNSoil_jf
A11: CALCULATIONS | D11: Unit | E11: {=Fertiliser_Equations_OrganicN2O.VEERG_5_2_1_1__2_MassOfNitrogenInOrganicFertiliser_Unit()} -> kg N
A12: =HYPERLINK("#'5.1.1.1-2 Inorganic Fert N2O'!A1", "5.1.1.1-2 Inorganic Fert N2O") -> 5.1.1.1-2 Inorganic Fert N2O
A13: =HYPERLINK("#'5.1.1.3-4 Inorganic fert CO2'!A1", "5.1.1.3-4 Inorganic fert CO2") -> 5.1.1.3-4 Inorganic fert CO2 | D13: {=_xlfn.CHOOSECOLS(Fertiliser_Equations_OrganicN2O.VEERG_5_2_1_1__2_MassOfNitrogenInOrganicFertiliser_Arguments(), 1, 2)} -> M_organicjf | E13: mass of organic fertiliser type f applied to production system j | G13: {=_xlfn.CHOOSECOLS(Fertiliser_Equations_OrganicN2O.VEERG_5_2_1_1__2_MassOfNitrogenInOrganicFertiliser_Arguments(), 3,4)} -> kg | H13: Input | I13: {=HYPERLINK(Common_InputFunctions.Utility_SourceHyperlink($D$17), $D$17)} -> Table_MNSoil_j_f
A14: =HYPERLINK("#'5.2.1.1-2 Organic Fert N2O'!A1", "5.2.1.1-2 Organic Fert N2O") -> 5.2.1.1-2 Organic Fert N2O | D14: FN_organicf | E14: nitrogen fraction of organic fertiliser type f | G14: kg N/kg | H14: Input | I14: {=HYPERLINK(Common_InputFunctions.Utility_SourceHyperlink($D$17), $D$17)} -> Table_MNSoil_j_f
A15: =HYPERLINK("#'5.3.1.1-2 Lime CO2'!A1", "5.3.1.1-2 Lime CO2") -> 5.3.1.1-2 Lime CO2 | D15: f | E15: Organic fertiliser type | H15: Input | I15: {=HYPERLINK(Common_InputFunctions.Utility_SourceHyperlink($D$17), $D$17)} -> Table_MNSoil_j_f
A16: =HYPERLINK("#'5.4.1.1-4 Atmos deposition'!A1", "5.4.1.1-4 Atmos deposition") -> 5.4.1.1-4 Atmos deposition
A17: =HYPERLINK("#'5.5.1.1-2 Leaching and runoff'!A1", "5.5.1.1-2 Leaching and runoff") -> 5.5.1.1-2 Leaching and runoff | D17: Table_MNSoil_j_f
D18: Mass of nitrogen in organic fertilisers
A19: APPENDICES | D19: Organic fertiliser type (f) | E19: Amount applied (kg/ha) | F19: Application area (ha) | G19: Morganicjf | H19: FNorganicf | I19: MNSoiljf
A20: =HYPERLINK("#'Constants - Fertiliser'!A1", "Constants - Fertiliser") -> Constants - Fertiliser | D20: {=#REF!} -> #REF! | E20: {=#REF!} -> #REF! | F20: {=#REF!} -> #REF! | G20: {=#REF!*#REF!} -> #REF! | H20: {=#REF!} -> #REF! | I20: {=Fertiliser_Equations_OrganicN2O.VEERG_5_2_1_1__2_MassOfNitrogenInOrganicFertiliser(G20,H20)} -> #REF!
A21: =HYPERLINK("#'Constants - Common'!A1", "Constants - Common") -> Constants - Common | I21: {=Fertiliser_Equations_Organic.VEERG_5_2_1_1__2_MassOfNitrogenInOrganicFertiliser(G21,H21)} -> 0
I22: {=Fertiliser_Equations_Organic.VEERG_5_2_1_1__2_MassOfNitrogenInOrganicFertiliser(G22,H22)} -> 0
I23: {=Fertiliser_Equations_Organic.VEERG_5_2_1_1__2_MassOfNitrogenInOrganicFertiliser(G23,H23)} -> 0
I24: {=Fertiliser_Equations_Organic.VEERG_5_2_1_1__2_MassOfNitrogenInOrganicFertiliser(G24,H24)} -> 0
I25: {=Fertiliser_Equations_Organic.VEERG_5_2_1_1__2_MassOfNitrogenInOrganicFertiliser(G25,H25)} -> 0
I26: {=Fertiliser_Equations_Organic.VEERG_5_2_1_1__2_MassOfNitrogenInOrganicFertiliser(G26,H26)} -> 0
I27: {=Fertiliser_Equations_Organic.VEERG_5_2_1_1__2_MassOfNitrogenInOrganicFertiliser(G27,H27)} -> 0
I28: {=Fertiliser_Equations_Organic.VEERG_5_2_1_1__2_MassOfNitrogenInOrganicFertiliser(G28,H28)} -> 0
I29: {=Fertiliser_Equations_Organic.VEERG_5_2_1_1__2_MassOfNitrogenInOrganicFertiliser(G29,H29)} -> 0
I30: {=Fertiliser_Equations_Organic.VEERG_5_2_1_1__2_MassOfNitrogenInOrganicFertiliser(G30,H30)} -> 0
D32: MNSoiljf | E32: =SUM(I20:I30) -> #REF! | F32: =$E$11 -> kg N
A34: =HYPERLINK("#A1", "▲ Back to top") -> ▲ Back to top
D36: {=Fertiliser_Equations_OrganicN2O.VEERG_5_2_1_1__1_OrganicFertiliserApplicationN2OEmissions_Title()} -> Nitrous oxide emissions from the application of all organic fertiliser types f to all production systems j
D37: {=Fertiliser_Equations_OrganicN2O.VEERG_5_2_1_1__1_OrganicFertiliserApplicationN2OEmissions_Source()} -> VEERG 2026: 5.2.1.1, Equation (1)
D38: Function name | E38: {=Common_InputFunctions.Utility_DisplayFunctionName($I$20)} -> =Fertiliser_Equations_OrganicN2O.VEERG_5_2_1_1__2_MassOfNitrogenInOrganicFertiliser
D41: Variable | E41: {=Fertiliser_Equations_OrganicN2O.VEERG_5_2_1_1__1_OrganicFertiliserApplicationN2OEmissions_Variable()} -> E_N2O
D42: Unit | E42: {=Fertiliser_Equations_OrganicN2O.VEERG_5_2_1_1__1_OrganicFertiliserApplicationN2OEmissions_Unit()} -> t N2O
D44: {=_xlfn.CHOOSECOLS(Fertiliser_Equations_OrganicN2O.VEERG_5_2_1_1__1_OrganicFertiliserApplicationN2OEmissions_Arguments(), 1, 2)} -> MNSoil_jf | E44: mass of nitrogen in organic fertiliser type f applied to production system j | I44: {=_xlfn.CHOOSECOLS(Fertiliser_Equations_OrganicN2O.VEERG_5_2_1_1__1_OrganicFertiliserApplicationN2OEmissions_Arguments(), 3,4)} -> kg N | J44: Calculated from 5.2.1.1 (2) | K44: =$E$32 -> #REF!
D45: EF_N2Oi | E45: emission factor for direct nitrous oxide emissions from organic fertiliser applied to soils and aquatic systems in climate zone i | I45: kg N2O-N/kg N | J45: Lookup | K45: {=Common_InputFunctions.Utility_LookupValueInTableNumber(K48, Table_SourceData_Common_EFOrganicFertCropResidues[Climate Zone],Table_SourceData_Common_EFOrganicFertCropResidues[EFNi & EFN2Oi])} -> 0.005
D46: C_N2O | E46: factor to convert elemental mass of nitrous oxide to molecular mass | J46: Constant | K46: =Common_InputFunctions.Utility_LookupValueInTableNumber("N2O",Table_GasToMolecularConversionFactor[Gas],Table_GasToMolecularConversionFactor[Conversion factor combined]) -> 1.5714286
D47: j | E47: Production system | J47: Input | K47: ='Input - Crop'!$E$6 -> 0
...

Sheet 5.3.1.1-2 Lime CO2
A1: #VALUE! | C1: 5.3.1.1 1-2 Lime application CO2
A3: =HYPERLINK("#'Home'!A1", "Home") -> Home | D3: Method 1 | O3: Method 2
A4: =HYPERLINK("#'Overview'!A1", "Overview") -> Overview
A5: =HYPERLINK("#'Results'!A1", "Results") -> Results | D5: {=Fertiliser_Equations_Lime.VEERG_5_3_1_1__1_LimeApplicationCO2Emissions_Title()} -> Emissions from the application of lime and dolomite to production systems
D6: {=Fertiliser_Equations_Lime.VEERG_5_3_1_1__1_LimeApplicationCO2Emissions_Source()} -> VEERG 2026: 5.3.1.1, Equation (1)
A7: INPUTS | D7: Function name | E7: {=Common_InputFunctions.Utility_DisplayFunctionName(H25)} -> =Fertiliser_Equations_Lime.VEERG_5_3_1_1__1_LimeApplicationCO2Emissions
A8: =HYPERLINK("#'Input - Site'!A1", "Site") -> Site
A9: =HYPERLINK("#'Input - Fertiliser'!A1", "Fertiliser") -> Fertiliser
D10: Variable | E10: {=Fertiliser_Equations_Lime.VEERG_5_3_1_1__1_LimeApplicationCO2Emissions_Variable()} -> E_lime
A11: CALCULATIONS | D11: Unit | E11: {=Fertiliser_Equations_Lime.VEERG_5_3_1_1__1_LimeApplicationCO2Emissions_Unit()} -> t CO2
A12: =HYPERLINK("#'5.1.1.1-2 Inorganic Fert N2O'!A1", "5.1.1.1-2 Inorganic Fert N2O") -> 5.1.1.1-2 Inorganic Fert N2O
A13: =HYPERLINK("#'5.1.1.3-4 Inorganic fert CO2'!A1", "5.1.1.3-4 Inorganic fert CO2") -> 5.1.1.3-4 Inorganic fert CO2 | D13: {=_xlfn.CHOOSECOLS(Fertiliser_Equations_Lime.VEERG_5_3_1_1__1_LimeApplicationCO2Emissions_Arguments(), 1, 2)} -> M_lime | E13: total mass of lime applied to production system | G13: {=_xlfn.CHOOSECOLS(Fertiliser_Equations_Lime.VEERG_5_3_1_1__1_LimeApplicationCO2Emissions_Arguments(), 3,4)} -> kg | H13: Input | I13: {=HYPERLINK(Common_InputFunctions.Utility_SourceHyperlink($D$22), $D$22)} -> Table_E_lime
A14: =HYPERLINK("#'5.2.1.1-2 Organic Fert N2O'!A1", "5.2.1.1-2 Organic Fert N2O") -> 5.2.1.1-2 Organic Fert N2O | D14: FracLime | E14: fraction of lime as limestone (CaCO3) | G14: fraction | H14: Input | I14: {=HYPERLINK(Common_InputFunctions.Utility_SourceHyperlink($D$22), $D$22)} -> Table_E_lime
A15: =HYPERLINK("#'5.3.1.1-2 Lime CO2'!A1", "5.3.1.1-2 Lime CO2") -> 5.3.1.1-2 Lime CO2 | D15: P_lime | E15: fractional purity of limestone | G15: fraction | H15: Constant | I15: ='Constants - Ag Residue'!$E$83 -> SA
A16: =HYPERLINK("#'5.4.1.1-4 Atmos deposition'!A1", "5.4.1.1-4 Atmos deposition") -> 5.4.1.1-4 Atmos deposition | D16: EF_lime | E16: emission factor for limestone fraction of lime | G16: kg C/kg | H16: Constant | I16: ='Constants - Ag Residue'!$F$83 -> 1
A17: =HYPERLINK("#'5.5.1.1-2 Leaching and runoff'!A1", "5.5.1.1-2 Leaching and runoff") -> 5.5.1.1-2 Leaching and runoff | D17: FracDol | E17: fraction of lime as dolomite | G17: fraction | H17: Input | I17: {=HYPERLINK(Common_InputFunctions.Utility_SourceHyperlink($D$22), $D$22)} -> Table_E_lime
D18: P_dol | E18: fractional purity of dolomite | G18: fraction | H18: Constant | I18: ='Constants - Ag Residue'!$E$84 -> WA
A19: APPENDICES | D19: EF_dol | E19: emission factor for dolomite fraction of lime | G19: kg C/kg | H19: Constant | I19: ='Constants - Ag Residue'!$F$84 -> 1
A20: =HYPERLINK("#'Constants - Fertiliser'!A1", "Constants - Fertiliser") -> Constants - Fertiliser | D20: C_CO2 | E20: factor to convert elemental mass of carbon dioxide to molecular mass | H20: Constant | I20: =Common_InputFunctions.Utility_LookupValueInTableNumber("CO2",Table_GasToMolecularConversionFactor[Gas], Table_GasToMolecularConversionFactor[Conversion factor combined]) -> 3.6666667
A21: =HYPERLINK("#'Constants - Common'!A1", "Constants - Common") -> Constants - Common
D22: Table_E_lime
D23: Lime applications
D24: Element | E24: M | F24: FracLime | G24: FracDol | H24: Elime
D25: {=#REF!} -> #REF! | E25: {=#REF!} -> #REF! | F25: {=#REF!+#REF!} -> #REF! | G25: {=#REF!} -> #REF! | H25: {=Fertiliser_Equations_Lime.VEERG_5_3_1_1__1_LimeApplicationCO2Emissions(E25,F25,$I$15,$I$16,G25,$I$18,$I$19,$I$20)} -> #REF!
H26: {=Fertiliser_Equations_Lime.VEERG_5_3_1_1__1_LimeApplicationCO2Emissions(E26,F26,$I$15,$I$16,G26,$I$18,$I$19,$I$20)} -> #VALUE!
H27: {=Fertiliser_Equations_Lime.VEERG_5_3_1_1__1_LimeApplicationCO2Emissions(E27,F27,$I$15,$I$16,G27,$I$18,$I$19,$I$20)} -> #VALUE!
H28: {=Fertiliser_Equations_Lime.VEERG_5_3_1_1__1_LimeApplicationCO2Emissions(E28,F28,$I$15,$I$16,G28,$I$18,$I$19,$I$20)} -> #VALUE!
H29: {=Fertiliser_Equations_Lime.VEERG_5_3_1_1__1_LimeApplicationCO2Emissions(E29,F29,$I$15,$I$16,G29,$I$18,$I$19,$I$20)} -> #VALUE!
D31: Elime | E31: =SUM(H25:H29) -> #REF! | F31: t CO2
A34: =HYPERLINK("#A1", "▲ Back to top") -> ▲ Back to top
A55: =HYPERLINK("#A1", "▲ Back to top") -> ▲ Back to top

Sheet 5.4.1.1-4 Atmos deposition
A1: #VALUE! | C1: 5.4.1.1-4 Atmospheric deposition resulting from fertiliser application
A3: =HYPERLINK("#'Home'!A1", "Home") -> Home | D3: Method 1 | O3: Method 2
A4: =HYPERLINK("#'Overview'!A1", "Overview") -> Overview
A5: =HYPERLINK("#'Results'!A1", "Results") -> Results | D5: {=Fertiliser_Equations_AtmosphericDeposition.VEERG_5_4_1_1__2_MassOfNitrogenVolatilisedFromInorganicFertiliser_Title()} -> Mass of nitrogen volatilised from inorganic fertiliser applied to production system
D6: {=Fertiliser_Equations_AtmosphericDeposition.VEERG_5_4_1_1__2_MassOfNitrogenVolatilisedFromInorganicFertiliser_Source()} -> VEERG 2026: 5.4.1.1, Equation (2)
A7: INPUTS | D7: Function name | E7: {=Common_InputFunctions.Utility_DisplayFunctionName(H19)} -> =Fertiliser_Equations_AtmosphericDeposition.VEERG_5_4_1_1__2_MassOfNitrogenVolatilisedFromInorganicFertiliser
A8: =HYPERLINK("#'Input - Site'!A1", "Site") -> Site
A9: =HYPERLINK("#'Input - Fertiliser'!A1", "Fertiliser") -> Fertiliser
D10: Variable | E10: {=Fertiliser_Equations_AtmosphericDeposition.VEERG_5_4_1_1__2_MassOfNitrogenVolatilisedFromInorganicFertiliser_Variable()} -> M_volinorganicjf
A11: CALCULATIONS | D11: Unit | E11: {=Fertiliser_Equations_AtmosphericDeposition.VEERG_5_4_1_1__2_MassOfNitrogenVolatilisedFromInorganicFertiliser_Unit()} -> kg N
A12: =HYPERLINK("#'5.1.1.1-2 Inorganic Fert N2O'!A1", "5.1.1.1-2 Inorganic Fert N2O") -> 5.1.1.1-2 Inorganic Fert N2O
A13: =HYPERLINK("#'5.1.1.3-4 Inorganic fert CO2'!A1", "5.1.1.3-4 Inorganic fert CO2") -> 5.1.1.3-4 Inorganic fert CO2 | D13: {=_xlfn.CHOOSECOLS(Fertiliser_Equations_AtmosphericDeposition.VEERG_5_4_1_1__2_MassOfNitrogenVolatilisedFromInorganicFertiliser_Arguments(), 1, 2)} -> MN_jf | E13: mass of nitrogen in inorganic fertiliser applied | G13: {=_xlfn.CHOOSECOLS(Fertiliser_Equations_AtmosphericDeposition.VEERG_5_4_1_1__2_MassOfNitrogenVolatilisedFromInorganicFertiliser_Arguments(), 3,4)} -> kg N | H13: Calculated from 5.1.1.1 (2) | I13: {=HYPERLINK(Common_InputFunctions.Utility_SourceHyperlink($D$16),$D$16)} -> Table_M_vol_inorganic_j_f
A14: =HYPERLINK("#'5.2.1.1-2 Organic Fert N2O'!A1", "5.2.1.1-2 Organic Fert N2O") -> 5.2.1.1-2 Organic Fert N2O | D14: FracGASF_f | E14: fraction of inorganic fertiliser that volatilises | G14: (kg NH3-N + NOx-N)/kg N | H14: Constant | I14: {=HYPERLINK(Common_InputFunctions.Utility_SourceHyperlink($D$16),$D$16)} -> Table_M_vol_inorganic_j_f
A15: =HYPERLINK("#'5.3.1.1-2 Lime CO2'!A1", "5.3.1.1-2 Lime CO2") -> 5.3.1.1-2 Lime CO2
A16: =HYPERLINK("#'5.4.1.1-4 Atmos deposition'!A1", "5.4.1.1-4 Atmos deposition") -> 5.4.1.1-4 Atmos deposition | D16: Table_M_vol_inorganic_j_f
A17: =HYPERLINK("#'5.5.1.1-2 Leaching and runoff'!A1", "5.5.1.1-2 Leaching and runoff") -> 5.5.1.1-2 Leaching and runoff | D17: Mass of nitrogen volatilised from inorganic fertiliser application
D18: Chemical compound | E18: MNjf | F18: Basis | G18: FracGASFf | H18: Mvolinorganicjf
A19: APPENDICES | D19: {=#REF!} -> #REF! | E19: ='6.1.1.1-2 Crop residue N2O'!O19 | F19: {=Common_InputFunctions.Utility_LookupValueInTable(D19, #REF!,#REF!)} -> #REF! | G19: {=Common_InputFunctions.Utility_LookupValueInTableNumber(F19, #REF!,#REF!)} -> 0 | H19: {=Fertiliser_Equations_AtmosphericDeposition.VEERG_5_4_1_1__2_MassOfNitrogenVolatilisedFromInorganicFertiliser(E19,G19)} -> #VALUE!
A20: =HYPERLINK("#'Constants - Fertiliser'!A1", "Constants - Fertiliser") -> Constants - Fertiliser | E20: ='6.1.1.1-2 Crop residue N2O'!O20 -> 0 | F20: {=Common_InputFunctions.Utility_LookupValueInTable(D20, #REF!,#REF!)} -> #REF! | G20: {=Common_InputFunctions.Utility_LookupValueInTableNumber(F20, #REF!,#REF!)} -> 0 | H20: {=Fertiliser_Equations_AtmosphericDeposition.VEERG_5_4_1_1__2_MassOfNitrogenVolatilisedFromInorganicFertiliser(E20,G20)} -> 0
A21: =HYPERLINK("#'Constants - Common'!A1", "Constants - Common") -> Constants - Common | E21: ='6.1.1.1-2 Crop residue N2O'!O21 -> 0 | F21: {=Common_InputFunctions.Utility_LookupValueInTable(D21, #REF!,#REF!)} -> #REF! | G21: {=Common_InputFunctions.Utility_LookupValueInTableNumber(F21, #REF!,#REF!)} -> 0 | H21: {=Fertiliser_Equations_AtmosphericDeposition.VEERG_5_4_1_1__2_MassOfNitrogenVolatilisedFromInorganicFertiliser(E21,G21)} -> 0
E22: ='6.1.1.1-2 Crop residue N2O'!O22 -> 0 | F22: {=Common_InputFunctions.Utility_LookupValueInTable(D22, #REF!,#REF!)} -> #REF! | G22: {=Common_InputFunctions.Utility_LookupValueInTableNumber(F22, #REF!,#REF!)} -> 0 | H22: {=Fertiliser_Equations_AtmosphericDeposition.VEERG_5_4_1_1__2_MassOfNitrogenVolatilisedFromInorganicFertiliser(E22,G22)} -> 0
E23: ='6.1.1.1-2 Crop residue N2O'!O23 -> 0 | F23: {=Common_InputFunctions.Utility_LookupValueInTable(D23, #REF!,#REF!)} -> #REF! | G23: {=Common_InputFunctions.Utility_LookupValueInTableNumber(F23, #REF!,#REF!)} -> 0 | H23: {=Fertiliser_Equations_AtmosphericDeposition.VEERG_5_4_1_1__2_MassOfNitrogenVolatilisedFromInorganicFertiliser(E23,G23)} -> 0
E24: ='6.1.1.1-2 Crop residue N2O'!O24 -> 0 | F24: {=Common_InputFunctions.Utility_LookupValueInTable(D24, #REF!,#REF!)} -> #REF! | G24: {=Common_InputFunctions.Utility_LookupValueInTableNumber(F24, #REF!,#REF!)} -> 0 | H24: {=Fertiliser_Equations_AtmosphericDeposition.VEERG_5_4_1_1__2_MassOfNitrogenVolatilisedFromInorganicFertiliser(E24,G24)} -> 0
E25: ='6.1.1.1-2 Crop residue N2O'!O25 -> 0 | F25: {=Common_InputFunctions.Utility_LookupValueInTable(D25, #REF!,#REF!)} -> #REF! | G25: {=Common_InputFunctions.Utility_LookupValueInTableNumber(F25, #REF!,#REF!)} -> 0 | H25: {=Fertiliser_Equations_AtmosphericDeposition.VEERG_5_4_1_1__2_MassOfNitrogenVolatilisedFromInorganicFertiliser(E25,G25)} -> 0
E26: ='6.1.1.1-2 Crop residue N2O'!O26 -> 0 | F26: {=Common_InputFunctions.Utility_LookupValueInTable(D26, #REF!,#REF!)} -> #REF! | G26: {=Common_InputFunctions.Utility_LookupValueInTableNumber(F26, #REF!,#REF!)} -> 0 | H26: {=Fertiliser_Equations_AtmosphericDeposition.VEERG_5_4_1_1__2_MassOfNitrogenVolatilisedFromInorganicFertiliser(E26,G26)} -> 0
E27: ='6.1.1.1-2 Crop residue N2O'!O27 -> 0 | F27: {=Common_InputFunctions.Utility_LookupValueInTable(D27, #REF!,#REF!)} -> #REF! | G27: {=Common_InputFunctions.Utility_LookupValueInTableNumber(F27, #REF!,#REF!)} -> 0 | H27: {=Fertiliser_Equations_AtmosphericDeposition.VEERG_5_4_1_1__2_MassOfNitrogenVolatilisedFromInorganicFertiliser(E27,G27)} -> 0
E28: ='6.1.1.1-2 Crop residue N2O'!O28 -> 0 | F28: {=Common_InputFunctions.Utility_LookupValueInTable(D28, #REF!,#REF!)} -> #REF! | G28: {=Common_InputFunctions.Utility_LookupValueInTableNumber(F28, #REF!,#REF!)} -> 0 | H28: {=Fertiliser_Equations_AtmosphericDeposition.VEERG_5_4_1_1__2_MassOfNitrogenVolatilisedFromInorganicFertiliser(E28,G28)} -> 0
E29: ='6.1.1.1-2 Crop residue N2O'!O29 -> 0 | F29: {=Common_InputFunctions.Utility_LookupValueInTable(D29, #REF!,#REF!)} -> #REF! | G29: {=Common_InputFunctions.Utility_LookupValueInTableNumber(F29, #REF!,#REF!)} -> 0 | H29: {=Fertiliser_Equations_AtmosphericDeposition.VEERG_5_4_1_1__2_MassOfNitrogenVolatilisedFromInorganicFertiliser(E29,G29)} -> 0
E30: ='6.1.1.1-2 Crop residue N2O'!O30 -> 0 | F30: {=Common_InputFunctions.Utility_LookupValueInTable(D30, #REF!,#REF!)} -> #REF! | G30: {=Common_InputFunctions.Utility_LookupValueInTableNumber(F30, #REF!,#REF!)} -> 0 | H30: {=Fertiliser_Equations_AtmosphericDeposition.VEERG_5_4_1_1__2_MassOfNitrogenVolatilisedFromInorganicFertiliser(E30,G30)} -> 0
E31: ='6.1.1.1-2 Crop residue N2O'!O31 -> 0 | F31: {=Common_InputFunctions.Utility_LookupValueInTable(D31, #REF!,#REF!)} -> #REF! | G31: {=Common_InputFunctions.Utility_LookupValueInTableNumber(F31, #REF!,#REF!)} -> 0 | H31: {=Fertiliser_Equations_AtmosphericDeposition.VEERG_5_4_1_1__2_MassOfNitrogenVolatilisedFromInorganicFertiliser(E31,G31)} -> 0
E32: ='6.1.1.1-2 Crop residue N2O'!O32 -> 0 | F32: {=Common_InputFunctions.Utility_LookupValueInTable(D32, #REF!,#REF!)} -> #REF! | G32: {=Common_InputFunctions.Utility_LookupValueInTableNumber(F32, #REF!,#REF!)} -> 0 | H32: {=Fertiliser_Equations_AtmosphericDeposition.VEERG_5_4_1_1__2_MassOfNitrogenVolatilisedFromInorganicFertiliser(E32,G32)} -> 0
E33: ='6.1.1.1-2 Crop residue N2O'!O33 -> 0 | F33: {=Common_InputFunctions.Utility_LookupValueInTable(D33, #REF!,#REF!)} -> #REF! | G33: {=Common_InputFunctions.Utility_LookupValueInTableNumber(F33, #REF!,#REF!)} -> 0 | H33: {=Fertiliser_Equations_AtmosphericDeposition.VEERG_5_4_1_1__2_MassOfNitrogenVolatilisedFromInorganicFertiliser(E33,G33)} -> 0
A34: =HYPERLINK("#A1", "▲ Back to top") -> ▲ Back to top | E34: ='6.1.1.1-2 Crop residue N2O'!O34 -> 0 | F34: {=Common_InputFunctions.Utility_LookupValueInTable(D34, #REF!,#REF!)} -> #REF! | G34: {=Common_InputFunctions.Utility_LookupValueInTableNumber(F34, #REF!,#REF!)} -> 0 | H34: {=Fertiliser_Equations_AtmosphericDeposition.VEERG_5_4_1_1__2_MassOfNitrogenVolatilisedFromInorganicFertiliser(E34,G34)} -> 0
E35: ='6.1.1.1-2 Crop residue N2O'!O35 -> 0 | F35: {=Common_InputFunctions.Utility_LookupValueInTable(D35, #REF!,#REF!)} -> #REF! | G35: {=Common_InputFunctions.Utility_LookupValueInTableNumber(F35, #REF!,#REF!)} -> 0 | H35: {=Fertiliser_Equations_AtmosphericDeposition.VEERG_5_4_1_1__2_MassOfNitrogenVolatilisedFromInorganicFertiliser(E35,G35)} -> 0
E36: ='6.1.1.1-2 Crop residue N2O'!O36 -> 0 | F36: {=Common_InputFunctions.Utility_LookupValueInTable(D36, #REF!,#REF!)} -> #REF! | G36: {=Common_InputFunctions.Utility_LookupValueInTableNumber(F36, #REF!,#REF!)} -> 0 | H36: {=Fertiliser_Equations_AtmosphericDeposition.VEERG_5_4_1_1__2_MassOfNitrogenVolatilisedFromInorganicFertiliser(E36,G36)} -> 0
D40: {=Fertiliser_Equations_AtmosphericDeposition.VEERG_5_4_1_1__1_InorganicFertiliserAtmosphericDepositionN2OEmissions_Title()} -> Nitrous oxide emissions from atmospheric deposition from all inorganic fertiliser types f and all production systems j
D41: {=Fertiliser_Equations_AtmosphericDeposition.VEERG_5_4_1_1__1_InorganicFertiliserAtmosphericDepositionN2OEmissions_Source()} -> VEERG 2026: 5.4.1.1, Equation (1)
D42: Function name | E42: {=Common_InputFunctions.Utility_DisplayFunctionName(F58)} -> =Fertiliser_Equations_AtmosphericDeposition.VEERG_5_4_1_1__1_InorganicFertiliserAtmosphericDepositionN2OEmissions
