Workbook
Name AgResidues_Equations_Leaching.VEERG_6_3_1_1__1__LeachingAndRunoffEmissionsCropAndPastureResidue: _xlfn.LAMBDA(_xlpm.Mleachcp,_xlpm.EFleach,_xlpm.CgN2O, _xlpm.Mleachcp * _xlpm.EFleach * _xlpm.CgN2O * 10 ^ (-3))
Name AgResidues_Equations_Leaching.VEERG_6_3_1_1__1__LeachingAndRunoffEmissionsCropAndPastureResidue_Source: _xlfn.LAMBDA("VEERG 2026: 6.3.1.1, Equation (1)")
Name AgResidues_Equations_Leaching.VEERG_6_3_1_1__1__LeachingAndRunoffEmissionsCropAndPastureResidue_Title: _xlfn.LAMBDA("Nitrous oxide leaching and runoff emissions from crop and pasture residues returned to the soil")
Name AgResidues_Equations_Leaching.VEERG_6_3_1_1__1__LeachingAndRunoffEmissionsCropAndPastureResidue_Unit: _xlfn.LAMBDA("t N2O")
Name AgResidues_Equations_Leaching.VEERG_6_3_1_1__1__LeachingAndRunoffEmissionsCropAndPastureResidue_Variable: _xlfn.LAMBDA("EN2O")
Name AgResidues_Equations_Leaching.VEERG_6_3_1_1__2__MassOfNitrogenLostThroughLeachingAndRunoff: _xlfn.LAMBDA(_xlpm.Mcp,_xlpm.FracWETzir,_xlpm.FracLEACH, _xlpm.Mcp * _xlpm.FracWETzir * _xlpm.FracLEACH)
Name AgResidues_Equations_Leaching.VEERG_6_3_1_1__2__MassOfNitrogenLostThroughLeachingAndRunoff_Source: _xlfn.LAMBDA("VEERG 2026: 6.3.1.1, Equation (2)")
Name AgResidues_Equations_Leaching.VEERG_6_3_1_1__2__MassOfNitrogenLostThroughLeachingAndRunoff_Title: _xlfn.LAMBDA("Mass of nitrogen lost through leaching and runoff")
Name AgResidues_Equations_Leaching.VEERG_6_3_1_1__2__MassOfNitrogenLostThroughLeachingAndRunoff_Unit: _xlfn.LAMBDA("kg N")
Name AgResidues_Equations_Leaching.VEERG_6_3_1_1__2__MassOfNitrogenLostThroughLeachingAndRunoff_Variable: _xlfn.LAMBDA("Mleachcp")
Name AgResidues_Equations_Leaching.VEERG_6_3_1_1__2__MassOfNitrogenLostThroughLeachingAndRunoff_Variation: _xlfn.LAMBDA("VARIATION FROM SOURCE: Added criteria for leaching zone z and irrigation type ir. Removed production system criteria j.")
Name AgResidues_SourceData.BurningOfAgriculturalResiduesEFs_Source: _xlfn.LAMBDA(("National Inventory Report 2023 volume 2: Table 5.31: Burning of agricultural residues - EFs"))
Name AgResidues_SourceData.BurningOfAgriculturalResiduesEFs_Title: _xlfn.LAMBDA(("Table 5.31 Burning of agricultural residues - EFs"))
Name Common_Equations.Common_ConvertCH4ToCO2e: _xlfn.LAMBDA(_xlpm.E_CH4,_xlpm.GWP_CH4, _xlpm.E_CH4 * _xlpm.GWP_CH4)
Name Common_Equations.Common_ConvertCH4ToCO2e_Arguments: _xlfn.LAMBDA(_xlfn.MAKEARRAY(2, 2, _xlfn.LAMBDA(_xlpm.r,_xlpm.c, INDEX({"ECH4","Methane emissions (t CH4)";"GWPCH4","Global warming potential for methane (t CO2-e / t CH4)"}, _xlpm.r, _xlpm.c))))
Name Common_Equations.Common_ConvertCH4ToCO2e_LatexEquation: _xlfn.LAMBDA("CO2_e = E_{CH4} \times GWP_{CH4}")
Name Common_Equations.Common_ConvertCH4ToCO2e_NIRReference: _xlfn.LAMBDA("")
Name Common_Equations.Common_ConvertCH4ToCO2e_Title: _xlfn.LAMBDA("Convert methane emissions to carbon dioxide equivalent emissions")
Name Common_Equations.Common_ConvertCH4ToCO2e_Unit: _xlfn.LAMBDA("t CO2e")
Name Common_Equations.Common_ConvertCH4ToCO2e_Variable: _xlfn.LAMBDA("ECH4 CO2e")
Name Common_Equations.Common_ConvertN2OToCO2e: _xlfn.LAMBDA(_xlpm.E_N2O,_xlpm.GWP_N2O, _xlpm.E_N2O * _xlpm.GWP_N2O)
Name Common_Equations.Common_ConvertN2OToCO2e_LatexEquation: _xlfn.LAMBDA("CO2_e = E_{N2O} \times GWP_{N2O}")
Name Common_Equations.Common_ConvertN2OToCO2e_NIRReference: _xlfn.LAMBDA("")
Name Common_Equations.Common_ConvertN2OToCO2e_Title: _xlfn.LAMBDA("Convert nitrous oxide emissions to carbon dioxide equivalent emissions")
Name Common_Equations.Common_ConvertN2OToCO2e_Unit: _xlfn.LAMBDA("t CO2e")
Name Common_Equations.Common_ConvertN2OToCO2e_Variable: _xlfn.LAMBDA("EN2O CO2e")
Name Common_InputFunctions.Utility_ConvertStateCommonNameToAbbreviation: _xlfn.LAMBDA(_xlpm.StateCommonName,_xlpm.StateCommonNameArray,_xlpm.StateAbbreviationArray, _xlfn.XLOOKUP(_xlpm.StateCommonName, _xlpm.StateCommonNameArray, _xlpm.StateAbbreviationArray, ""))
Name Common_InputFunctions.Utility_DisplayArguments_1_2: _xlfn.LAMBDA(_xlpm.ArgumentsArray, _xlfn.CHOOSECOLS(_xlpm.ArgumentsArray, 1, 2))
Name Common_InputFunctions.Utility_DisplayArguments_3_4: _xlfn.LAMBDA(_xlpm.ArgumentsArray, _xlfn.CHOOSECOLS(_xlpm.ArgumentsArray, 3, 4))
Name Common_InputFunctions.Utility_DisplayFunctionName: _xlfn.LAMBDA(_xlpm.Function, _xlfn.TEXTBEFORE(_xlfn.FORMULATEXT(_xlpm.Function), "("))
Name Common_InputFunctions.Utility_GetArrayTableColumnStartNumber: _xlfn.LAMBDA(_xlpm.TableHeaderCell, COLUMN(_xlpm.TableHeaderCell))
Name Common_InputFunctions.Utility_GetArrayTableRowStartNumber: _xlfn.LAMBDA(_xlpm.TableheaderCell,_xlpm.RowsBetweenHeaderandArray, ROW(_xlpm.TableheaderCell) + _xlpm.RowsBetweenHeaderandArray - 1)
Name Common_InputFunctions.Utility_LookupValueInTable: _xlfn.LAMBDA(_xlpm.LookupValue,_xlpm.LookupArray,_xlpm.ReturnArray, _xlfn.XLOOKUP(_xlpm.LookupValue, _xlpm.LookupArray, _xlpm.ReturnArray, ""))
Name Common_InputFunctions.Utility_ResultsItemFromEquationTitleAndSource: _xlfn.LAMBDA(_xlpm.TitleCell,_xlpm.SourceCell, SUBSTITUTE(LEFT(_xlpm.SourceCell, FIND(",", _xlpm.SourceCell) -1), "VEERG 2026: ", "") & " " & _xlpm.TitleCell )
Name Common_InputFunctions.Utility_SourceHyperlink: _xlfn.LAMBDA(_xlpm.TargetCell, _xlfn.LET(_xlpm.sh, _xlfn.TEXTAFTER(CELL("filename", _xlpm.TargetCell), "]"), _xlpm.addr, CELL("address", _xlpm.TargetCell), "#'" & _xlpm.sh & "'!" & _xlpm.addr))
Name Common_InputFunctions.Utility_SourceHyperlinkDifferentSheet: _xlfn.LAMBDA(_xlpm.TargetCell, _xlfn.LET( _xlpm.sh, _xlfn.TEXTAFTER(CELL("filename", _xlpm.TargetCell), "]"), _xlpm.addr, CELL("address", _xlpm.TargetCell), "#" & _xlpm.addr ) )
Name Common_SourceData.Common_SourceData_AustralianStatesTerritories_Source: _xlfn.LAMBDA("")
Name Common_SourceData.Common_SourceData_AustralianStatesTerritories_Title: _xlfn.LAMBDA("Australian states and territories")
Name Common_SourceData.Common_SourceData_AustralianStatesTerritories_Unit: _xlfn.LAMBDA("")
Name Common_SourceData.Common_SourceData_AustralianStatesTerritories_Variable: _xlfn.LAMBDA("")
Name Common_SourceData.Common_SourceData_ClimateZones_Source: _xlfn.LAMBDA("VEERG 2026: Table 1.3: Climate and Rainfall zone classifications and definitions")
Name Common_SourceData.Common_SourceData_ClimateZones_Title: _xlfn.LAMBDA("VEERG Australian climate zones")
Name Common_SourceData.Common_SourceData_ClimateZones_Unit: _xlfn.LAMBDA("")
Name Common_SourceData.Common_SourceData_ClimateZones_Variable: _xlfn.LAMBDA("")
Name Common_SourceData.Common_SourceData_ConvertGasElementalToMolecular_Source: _xlfn.LAMBDA("XXXXXXX")
Name Common_SourceData.Common_SourceData_ConvertGasElementalToMolecular_Title: _xlfn.LAMBDA("Factor to convert elemental mass of gas to molecular mass")
Name Common_SourceData.Common_SourceData_ConvertGasElementalToMolecular_Unit: _xlfn.LAMBDA("factor")
Name Common_SourceData.Common_SourceData_ConvertGasElementalToMolecular_Variable: _xlfn.LAMBDA("Cg")
Name Common_SourceData.Common_SourceData_ConvertN2oElementalToMolecularCg_Data: _xlfn.LAMBDA(44 / 28)
Name Common_SourceData.Common_SourceData_ConvertN2oElementalToMolecularCg_Source: _xlfn.LAMBDA("National Inventory Report 2023 Volume 1")
Name Common_SourceData.Common_SourceData_ConvertN2oElementalToMolecularCg_Title: _xlfn.LAMBDA("Factor to convert elemental mass of N2O to molecular mass")
Name Common_SourceData.Common_SourceData_ConvertN2oElementalToMolecularCg_Unit: _xlfn.LAMBDA("factor")
Name Common_SourceData.Common_SourceData_ConvertN2oElementalToMolecularCg_Variable: _xlfn.LAMBDA("CgN2O")
Name Common_SourceData.Common_SourceData_DataScores_Scope3_Source: _xlfn.LAMBDA("VEERG 2026: XXXXXXXX")
Name Common_SourceData.Common_SourceData_DataScores_Scope3_Title: _xlfn.LAMBDA("Australian data scores for scope 3")
Name Common_SourceData.Common_SourceData_DataScores_Scope3_Unit: _xlfn.LAMBDA("")
Name Common_SourceData.Common_SourceData_DataScores_Scope3_Variable: _xlfn.LAMBDA("")
Name Common_SourceData.Common_SourceData_DataScores_Scope3_Variation: _xlfn.LAMBDA("")
Name Common_SourceData.Common_SourceData_DensityOfMethane_Data: _xlfn.LAMBDA(0.6784)
Name Common_SourceData.Common_SourceData_DensityOfMethane_Source: _xlfn.LAMBDA("National Inventory Report 2023 Volume 1: Equations 3.B.1a_2, 3.B.1c_2, 3.B.3_1, 3.B.4g_2")

Sheet Home
A1: #VALUE!
A3: =HYPERLINK("#'Home'!A1", "Home") -> Home
A4: =HYPERLINK("#'Overview'!A1", "Overview") -> Overview
A5: =HYPERLINK("#'Results'!A1", "Results") -> Results
A8: INPUTS
A9: =HYPERLINK("#'Input - Site'!A1", "Site") -> Site
A10: =HYPERLINK("#'Input - Rice'!A1", "Rice") -> Rice
A13: CALCULATIONS
A14: =HYPERLINK("#'7.1.1-2 Rice cultivation'!A1", "7.1.1-2 Rice cultivation") -> 7.1.1-2 Rice cultivation
A17: APPENDICES
A18: =HYPERLINK("#'Constants - Rice cultivation'!A1", "Constants - Rice cultivation") -> Constants - Rice cultivation
A19: =HYPERLINK("#'Constants - Common'!A1", "Constants - Common") -> Constants - Common

Sheet Overview
A1: #VALUE! | C1: 7: Rice Cultivation: Overview
A3: =HYPERLINK("#'Home'!A1", "Home") -> Home
A4: =HYPERLINK("#'Overview'!A1", "Overview") -> Overview
A5: =HYPERLINK("#'Results'!A1", "Results") -> Results | D5: 💡 Below is a diagram that maps the equations used to calculate emissions, and how they interact with each other.
D6: Click on a box to go to the corresponding calculation.
A8: INPUTS
A9: =HYPERLINK("#'Input - Site'!A1", "Site") -> Site
A10: =HYPERLINK("#'Input - Rice'!A1", "Rice") -> Rice
A13: CALCULATIONS
A14: =HYPERLINK("#'7.1.1-2 Rice cultivation'!A1", "7.1.1-2 Rice cultivation") -> 7.1.1-2 Rice cultivation
A17: APPENDICES
A18: =HYPERLINK("#'Constants - Rice cultivation'!A1", "Constants - Rice cultivation") -> Constants - Rice cultivation
A19: =HYPERLINK("#'Constants - Common'!A1", "Constants - Common") -> Constants - Common
L37: `

Sheet Results
A1: #VALUE! | C1: 7: Rice Cultivation: Results
A3: =HYPERLINK("#'Home'!A1", "Home") -> Home
A4: =HYPERLINK("#'Overview'!A1", "Overview") -> Overview | D4: Emissions breakdown
A5: =HYPERLINK("#'Results'!A1", "Results") -> Results
D6: 💡 NOTE: When there is no Method 2, the Method 2 result are the same as Method 1
A8: INPUTS | D8: Scope 1 source | E8: GHG emissions method 1 | F8: GHG emissions method 2 | G8: GHG Unit | H8: CO2-e emissions method 1 | I8: CO2-e emissions method 2 | J8: CO2-e unit
A9: =HYPERLINK("#'Input - Site'!A1", "Site") -> Site | D9: 7.1.1-2 Rice cultivation | E9: =VEERG_7_1_1_1__1_MethaneEmissionsFromRiceCultivation_Result_Method1 -> 98.450769 | F9: =E9 -> 98.450769 | G9: t N2O | H9: ='7.1.1-2 Rice cultivation'!$E$107 -> 2756.6215 | I9: =H9 -> 2756.6215 | J9: t CO2e
A10: =HYPERLINK("#'Input - Rice'!A1", "Rice") -> Rice | D10: Total | H10: =SUM(H9:H9) -> 2756.6215 | I10: =SUM(I9:I9) -> 2756.6215 | J10: t CO2e
A13: CALCULATIONS
A14: =HYPERLINK("#'7.1.1-2 Rice cultivation'!A1", "7.1.1-2 Rice cultivation") -> 7.1.1-2 Rice cultivation
A17: APPENDICES
A18: =HYPERLINK("#'Constants - Rice cultivation'!A1", "Constants - Rice cultivation") -> Constants - Rice cultivation
A19: =HYPERLINK("#'Constants - Common'!A1", "Constants - Common") -> Constants - Common

Sheet Input - Site
A1: #VALUE! | C1: Input - Site
A3: =HYPERLINK("#'Home'!A1", "Home") -> Home
A4: =HYPERLINK("#'Overview'!A1", "Overview") -> Overview
A5: =HYPERLINK("#'Results'!A1", "Results") -> Results | D5: Your business
D7: Farm name | E7: Test Farms
A8: INPUTS | D8: Reporting entity name | E8: Test Farms Pty Ltd
A9: =HYPERLINK("#'Input - Site'!A1", "Site") -> Site
A10: =HYPERLINK("#'Input - Rice'!A1", "Rice") -> Rice | D10: 💡An 'Emissions accounting period' is a 12 month period where the business can report on the emissions, and is typically the same as the business' financial accounting period.
D12: Emissions calculation period start date | E12: 45292 | F12: ← DD/MM/YYYY or DD Month YYYY
A13: CALCULATIONS | D13: Emissions calculation period end date | E13: =DATE(YEAR(X_Cell_Site_StartDate)+1,MONTH(X_Cell_Site_StartDate),DAY(X_Cell_Site_StartDate))-1 -> 45657 | F13: ← Automatically calculated, 12 months after start date
A14: =HYPERLINK("#'7.1.1-2 Rice cultivation'!A1", "7.1.1-2 Rice cultivation") -> 7.1.1-2 Rice cultivation
A17: APPENDICES
A18: =HYPERLINK("#'Constants - Rice cultivation'!A1", "Constants - Rice cultivation") -> Constants - Rice cultivation
A19: =HYPERLINK("#'Constants - Common'!A1", "Constants - Common") -> Constants - Common

Sheet Input - Rice
A1: #VALUE! | C1: Input - Rice
A3: =HYPERLINK("#'Home'!A1", "Home") -> Home
A4: =HYPERLINK("#'Overview'!A1", "Overview") -> Overview
A5: =HYPERLINK("#'Results'!A1", "Results") -> Results | D5: Area
D7: If multiple paddocks were managed in the same way at the same time, you can enter information for them all together.
A8: INPUTS
A9: =HYPERLINK("#'Input - Site'!A1", "Site") -> Site
A10: =HYPERLINK("#'Input - Rice'!A1", "Rice") -> Rice | D10: ="Number of full growing seasons between "&TEXT(X_Cell_Site_StartDate,"d/m/yy")&" and " & TEXT(X_Cell_Site_EndDate,"d/m/yy") & " that are managed the same way" -> Number of full growing seasons between 1/1/24 and 31/12/24 that are managed the same way | E10: 2 | F10: growing seasons
D12: Amendments
A13: CALCULATIONS
A14: =HYPERLINK("#'7.1.1-2 Rice cultivation'!A1", "7.1.1-2 Rice cultivation") -> 7.1.1-2 Rice cultivation | D14: Amendment mix name | E14: Straw added < 30 days precultivation (t/ha) | F14: Straw added 30+ days pre cultivation (t/ha) | G14: Compost (t/ha) | H14: Farm yard manure (t/ha) | I14: Green manure (t/ha) | J14: Inorganic fertiliser (t/ha)
D15: Mix 1 | E15: 2 | F15: 0 | G15: 2 | H15: 0 | I15: 2 | J15: 0
D16: Mix 2 | E16: 0 | F16: 2 | G16: 0 | H16: 2 | I16: 0 | J16: 2
A17: APPENDICES
A18: =HYPERLINK("#'Constants - Rice cultivation'!A1", "Constants - Rice cultivation") -> Constants - Rice cultivation
A19: =HYPERLINK("#'Constants - Common'!A1", "Constants - Common") -> Constants - Common | D19: Regimes
D21: Regime name | E21: Area under cultivation (hectares) | F21: Pre-cultivation water regime (select) | G21: Water regime (select) | H21: Water regime sub-type (select) | I21: Amendment blend (select) | J21: Cultivation period (days)
D22: Regime 1 | E22: 100 | F22: Non flooded pre-season <180 days | G22: Rainfed and deep water | H22: Drought prone | I22: Mix 1 | J22: 100
D23: Regime 2 | E23: 100 | F23: Flooded pre-season >30 days | G23: Irrigated | H23: Single drainage period | I23: Mix 2 | J23: 100

Sheet 7.1.1-2 Rice cultivation
A1: #VALUE! | C1: 7.1.1-2 Rice cultivation CH4 emissions
A3: =HYPERLINK("#'Home'!A1", "Home") -> Home | D3: Method 1 | O3: Method 2
A4: =HYPERLINK("#'Overview'!A1", "Overview") -> Overview
A5: =HYPERLINK("#'Results'!A1", "Results") -> Results | D5: {=RiceCultivation_Equations.VEERG_7_1_1_1__3_OrganicAmendmentsScalingFactor_Title()} -> Organic amendments scaling factor
D6: {=RiceCultivation_Equations.VEERG_7_1_1_1__3_OrganicAmendmentsScalingFactor_Source()} -> VEERG 2026: 7.1.1.1, Equation (3)
D7: {=RiceCultivation_Equations.VEERG_7_1_1_1__3_OrganicAmendmentsScalingFactor_Variation()} -> VARIATION ON SOURCE:
A8: INPUTS | D8: Included inorganic fertiliser as amendment as per VEERG equation description:
A9: =HYPERLINK("#'Input - Site'!A1", "Site") -> Site | D9: Where inorganic fertiliser is applied to the rice fields rather than organic amendments, SF_o is set to 1.
A10: =HYPERLINK("#'Input - Rice'!A1", "Rice") -> Rice | D10: Declared each amendment separately to allow summing in Excel in one equation
D11: Function name | E11: {=Common_InputFunctions.Utility_DisplayFunctionName(E43)} -> =RiceCultivation_Equations.VEERG_7_1_1_1__3_OrganicAmendmentsScalingFactorVariation
A13: CALCULATIONS
A14: =HYPERLINK("#'7.1.1-2 Rice cultivation'!A1", "7.1.1-2 Rice cultivation") -> 7.1.1-2 Rice cultivation | D14: Variable | E14: {=RiceCultivation_Equations.VEERG_7_1_1_1__3_OrganicAmendmentsScalingFactor_Variable()} -> SF_o
D15: Unit | E15: {=RiceCultivation_Equations.VEERG_7_1_1_1__3_OrganicAmendmentsScalingFactor_Unit()} -> dimensionless
A17: APPENDICES | D17: {=_xlfn.CHOOSECOLS(RiceCultivation_Equations.VEERG_7_1_1_1__3_OrganicAmendmentsScalingFactor_Arguments(), 1, 2)} -> ROA_o | E17: application rate of organic amendment o | G17: {=_xlfn.CHOOSECOLS(RiceCultivation_Equations.VEERG_7_1_1_1__3_OrganicAmendmentsScalingFactor_Arguments(), 3,4)} -> tonnes/ha | H17: Input | I17: {=HYPERLINK(Common_InputFunctions.Utility_SourceHyperlink($D$21),$D$21)} -> Table_ROA_o
A18: =HYPERLINK("#'Constants - Rice cultivation'!A1", "Constants - Rice cultivation") -> Constants - Rice cultivation | D18: CFOA_o | E18: conversion factor of organic amendment o | G18: fraction | H18: Constant | I18: {=HYPERLINK(Common_InputFunctions.Utility_SourceHyperlink($D$30),$D$30)} -> Table_CFOA_o
A19: =HYPERLINK("#'Constants - Common'!A1", "Constants - Common") -> Constants - Common | D19: o | E19: organic amendment type | H19: Input | I19: {=HYPERLINK(Common_InputFunctions.Utility_SourceHyperlink($D$21),$D$21)} -> Table_ROA_o
D21: Table_ROA_o
D22: Application rate of organic amendment
D23: Amendment mix | E23: ='Constants - Rice cultivation'!D39 -> Straw incorporated shortly (<30 days) before cultivation | F23: ='Constants - Rice cultivation'!D40 -> Straw incorporated long (>30 days) before cultivation | G23: ='Constants - Rice cultivation'!D41 -> Compost | H23: ='Constants - Rice cultivation'!D42 -> Farm yard manure | I23: ='Constants - Rice cultivation'!D43 -> Green manure | J23: Inorganic fertiliser
D24: {=IFERROR(INDEX(Table_Input_AmendmentBlends[Amendment mix name], _xlfn.SEQUENCE(5)), "")} -> Mix 1 | E24: {=IFERROR(INDEX(Table_Input_AmendmentBlends[Straw added < 30 days precultivation (t/ha)], _xlfn.SEQUENCE(5)), 0)} -> 2 | F24: {=IFERROR(INDEX(Table_Input_AmendmentBlends[Straw added 30+ days pre cultivation (t/ha)], _xlfn.SEQUENCE(5)), 0)} -> 0 | G24: {=IFERROR(INDEX(Table_Input_AmendmentBlends[Compost (t/ha)], _xlfn.SEQUENCE(5)), 0)} -> 2 | H24: {=IFERROR(INDEX(Table_Input_AmendmentBlends[Farm yard manure (t/ha)], _xlfn.SEQUENCE(5)), 0)} -> 0 | I24: {=IFERROR(INDEX(Table_Input_AmendmentBlends[Green manure (t/ha)], _xlfn.SEQUENCE(5)), 0)} -> 2 | J24: {=IFERROR(INDEX(Table_Input_AmendmentBlends[Inorganic fertiliser (t/ha)], _xlfn.SEQUENCE(5)), 0)} -> 0 | K24: =G17 -> tonnes/ha
D25: Mix 2 | E25: 0 | F25: 2 | G25: 0 | H25: 2 | I25: 0 | J25: 2
E26: 0 | F26: 0 | G26: 0 | H26: 0 | I26: 0 | J26: 0
E27: 0 | F27: 0 | G27: 0 | H27: 0 | I27: 0 | J27: 0
E28: 0 | F28: 0 | G28: 0 | H28: 0 | I28: 0 | J28: 0
D30: Table_CFOA_o
D31: Conversion factor for organic amendment
D32: Amendment | E32: CFOAo
D33: ='Constants - Rice cultivation'!D39 -> Straw incorporated shortly (<30 days) before cultivation | E33: ='Constants - Rice cultivation'!E39 -> 1 | F33: =G18 -> fraction
D34: ='Constants - Rice cultivation'!D40 -> Straw incorporated long (>30 days) before cultivation | E34: ='Constants - Rice cultivation'!E40 -> 0.19
D35: ='Constants - Rice cultivation'!D41 -> Compost | E35: ='Constants - Rice cultivation'!E41 -> 0.17
D36: ='Constants - Rice cultivation'!D42 -> Farm yard manure | E36: ='Constants - Rice cultivation'!E42 -> 0.21
D37: ='Constants - Rice cultivation'!D43 -> Green manure | E37: ='Constants - Rice cultivation'!E43 -> 0.45
D38: ='Constants - Rice cultivation'!D44 -> Inorganic fertiliser | E38: ='Constants - Rice cultivation'!E44 -> 1
D40: Table_SF_o
D41: Organic amendments scaling factor
D42: Amendment mix | E42: SFo
D43: {=IFERROR(INDEX(Table_Input_AmendmentBlends[Amendment mix name], _xlfn.SEQUENCE(5)), "")} -> Mix 1 | E43: {=RiceCultivation_Equations.VEERG_7_1_1_1__3_OrganicAmendmentsScalingFactorVariation(E24, $E$33, F24, $E$34, G24, $E$35,H24,$E$36, I24,$E$37,J24,$E$38)} -> 2.3450162
D44: Mix 2 | E44: {=RiceCultivation_Equations.VEERG_7_1_1_1__3_OrganicAmendmentsScalingFactorVariation(E25, $E$33, F25, $E$34, G25, $E$35,H25,$E$36, I25,$E$37,J25,$E$38)} -> 2.1982259
E45: {=RiceCultivation_Equations.VEERG_7_1_1_1__3_OrganicAmendmentsScalingFactorVariation(E26, $E$33, F26, $E$34, G26, $E$35,H26,$E$36, I26,$E$37,J26,$E$38)} -> 1
E46: {=RiceCultivation_Equations.VEERG_7_1_1_1__3_OrganicAmendmentsScalingFactorVariation(E27, $E$33, F27, $E$34, G27, $E$35,H27,$E$36, I27,$E$37,J27,$E$38)} -> 1
...

Sheet Constants - Rice cultivation
A1: #VALUE! | C1: Constants - Rice cultivation
A3: =HYPERLINK("#'Home'!A1", "Home") -> Home
A4: =HYPERLINK("#'Overview'!A1", "Overview") -> Overview
A5: =HYPERLINK("#'Results'!A1", "Results") -> Results | D5: {=RiceCultivation_SourceData.SourceData_RiceCultivation_WaterScalingFactorGrowingSeason_Title()} -> Scaling factor based on the water regime employed during the growing season cultivation period
D6: {=RiceCultivation_SourceData.SourceData_RiceCultivation_WaterScalingFactorGrowingSeason_Source()} -> VEERG 2026: Table A.2.3.1
D7: {=RiceCultivation_SourceData.SourceData_RiceCultivation_WaterScalingFactorGrowingSeason_Variable()} -> SFw
A8: INPUTS | D8: {=RiceCultivation_SourceData.SourceData_RiceCultivation_WaterScalingFactorGrowingSeason_Unit()} -> fraction | H8: Table_WaterRegimeSubtypes_Upland | J8: Table_WaterRegimeSubtypes_Irrigated | L8: Table_WaterRegimeSubtypes_Rainfedanddeepwater
A9: =HYPERLINK("#'Input - Site'!A1", "Site") -> Site | D9: Water regime type | E9: Water regime sub-type | F9: SFw | H9: Sub type | J9: Sub type | L9: Sub type
A10: =HYPERLINK("#'Input - Rice'!A1", "Rice") -> Rice | D10: {=Common_InputFunctions.Utility_DisplayArrayInTable(RiceCultivation_SourceData.SourceData_RiceCultivation_WaterScalingFactorGrowingSeason_Data(),Table_SourceData_WaterScalingFactorGrowingSeason[[#Headers],[Water regime type]],0)} -> Upland | E10: {=Common_InputFunctions.Utility_DisplayArrayInTable(RiceCultivation_SourceData.SourceData_RiceCultivation_WaterScalingFactorGrowingSeason_Data(),Table_SourceData_WaterScalingFactorGrowingSeason[[#Headers],[Water regime type]],0)} -> Paddy rotation | F10: {=Common_InputFunctions.Utility_DisplayArrayInTable(RiceCultivation_SourceData.SourceData_RiceCultivation_WaterScalingFactorGrowingSeason_Data(),Table_SourceData_WaterScalingFactorGrowingSeason[[#Headers],[Water regime type]],0)} -> 0 | H10: =E10 -> Paddy rotation | J10: =E12 -> Continuously flooded | L10: =E15 -> Regular rainfed
D11: {=Common_InputFunctions.Utility_DisplayArrayInTable(RiceCultivation_SourceData.SourceData_RiceCultivation_WaterScalingFactorGrowingSeason_Data(),Table_SourceData_WaterScalingFactorGrowingSeason[[#Headers],[Water regime type]],0)} -> Upland | E11: {=Common_InputFunctions.Utility_DisplayArrayInTable(RiceCultivation_SourceData.SourceData_RiceCultivation_WaterScalingFactorGrowingSeason_Data(),Table_SourceData_WaterScalingFactorGrowingSeason[[#Headers],[Water regime type]],0)} -> Fallow without flooding in previous year | F11: {=Common_InputFunctions.Utility_DisplayArrayInTable(RiceCultivation_SourceData.SourceData_RiceCultivation_WaterScalingFactorGrowingSeason_Data(),Table_SourceData_WaterScalingFactorGrowingSeason[[#Headers],[Water regime type]],0)} -> 0 | H11: =E11 -> Fallow without flooding in previous year | J11: =E13 -> Single drainage period | L11: =E16 -> Drought prone
D12: {=Common_InputFunctions.Utility_DisplayArrayInTable(RiceCultivation_SourceData.SourceData_RiceCultivation_WaterScalingFactorGrowingSeason_Data(),Table_SourceData_WaterScalingFactorGrowingSeason[[#Headers],[Water regime type]],0)} -> Irrigated | E12: {=Common_InputFunctions.Utility_DisplayArrayInTable(RiceCultivation_SourceData.SourceData_RiceCultivation_WaterScalingFactorGrowingSeason_Data(),Table_SourceData_WaterScalingFactorGrowingSeason[[#Headers],[Water regime type]],0)} -> Continuously flooded | F12: {=Common_InputFunctions.Utility_DisplayArrayInTable(RiceCultivation_SourceData.SourceData_RiceCultivation_WaterScalingFactorGrowingSeason_Data(),Table_SourceData_WaterScalingFactorGrowingSeason[[#Headers],[Water regime type]],0)} -> 1 | J12: =E14 -> Multiple drainage periods | L12: =E17 -> Deep water
A13: CALCULATIONS | D13: {=Common_InputFunctions.Utility_DisplayArrayInTable(RiceCultivation_SourceData.SourceData_RiceCultivation_WaterScalingFactorGrowingSeason_Data(),Table_SourceData_WaterScalingFactorGrowingSeason[[#Headers],[Water regime type]],0)} -> Irrigated | E13: {=Common_InputFunctions.Utility_DisplayArrayInTable(RiceCultivation_SourceData.SourceData_RiceCultivation_WaterScalingFactorGrowingSeason_Data(),Table_SourceData_WaterScalingFactorGrowingSeason[[#Headers],[Water regime type]],0)} -> Single drainage period | F13: {=Common_InputFunctions.Utility_DisplayArrayInTable(RiceCultivation_SourceData.SourceData_RiceCultivation_WaterScalingFactorGrowingSeason_Data(),Table_SourceData_WaterScalingFactorGrowingSeason[[#Headers],[Water regime type]],0)} -> 0.71
A14: =HYPERLINK("#'7.1.1-2 Rice cultivation'!A1", "7.1.1-2 Rice cultivation") -> 7.1.1-2 Rice cultivation | D14: {=Common_InputFunctions.Utility_DisplayArrayInTable(RiceCultivation_SourceData.SourceData_RiceCultivation_WaterScalingFactorGrowingSeason_Data(),Table_SourceData_WaterScalingFactorGrowingSeason[[#Headers],[Water regime type]],0)} -> Irrigated | E14: {=Common_InputFunctions.Utility_DisplayArrayInTable(RiceCultivation_SourceData.SourceData_RiceCultivation_WaterScalingFactorGrowingSeason_Data(),Table_SourceData_WaterScalingFactorGrowingSeason[[#Headers],[Water regime type]],0)} -> Multiple drainage periods | F14: {=Common_InputFunctions.Utility_DisplayArrayInTable(RiceCultivation_SourceData.SourceData_RiceCultivation_WaterScalingFactorGrowingSeason_Data(),Table_SourceData_WaterScalingFactorGrowingSeason[[#Headers],[Water regime type]],0)} -> 0.55
D15: {=Common_InputFunctions.Utility_DisplayArrayInTable(RiceCultivation_SourceData.SourceData_RiceCultivation_WaterScalingFactorGrowingSeason_Data(),Table_SourceData_WaterScalingFactorGrowingSeason[[#Headers],[Water regime type]],0)} -> Rainfed and deep water | E15: {=Common_InputFunctions.Utility_DisplayArrayInTable(RiceCultivation_SourceData.SourceData_RiceCultivation_WaterScalingFactorGrowingSeason_Data(),Table_SourceData_WaterScalingFactorGrowingSeason[[#Headers],[Water regime type]],0)} -> Regular rainfed | F15: {=Common_InputFunctions.Utility_DisplayArrayInTable(RiceCultivation_SourceData.SourceData_RiceCultivation_WaterScalingFactorGrowingSeason_Data(),Table_SourceData_WaterScalingFactorGrowingSeason[[#Headers],[Water regime type]],0)} -> 0.54
D16: {=Common_InputFunctions.Utility_DisplayArrayInTable(RiceCultivation_SourceData.SourceData_RiceCultivation_WaterScalingFactorGrowingSeason_Data(),Table_SourceData_WaterScalingFactorGrowingSeason[[#Headers],[Water regime type]],0)} -> Rainfed and deep water | E16: {=Common_InputFunctions.Utility_DisplayArrayInTable(RiceCultivation_SourceData.SourceData_RiceCultivation_WaterScalingFactorGrowingSeason_Data(),Table_SourceData_WaterScalingFactorGrowingSeason[[#Headers],[Water regime type]],0)} -> Drought prone | F16: {=Common_InputFunctions.Utility_DisplayArrayInTable(RiceCultivation_SourceData.SourceData_RiceCultivation_WaterScalingFactorGrowingSeason_Data(),Table_SourceData_WaterScalingFactorGrowingSeason[[#Headers],[Water regime type]],0)} -> 0.16
A17: APPENDICES | D17: {=Common_InputFunctions.Utility_DisplayArrayInTable(RiceCultivation_SourceData.SourceData_RiceCultivation_WaterScalingFactorGrowingSeason_Data(),Table_SourceData_WaterScalingFactorGrowingSeason[[#Headers],[Water regime type]],0)} -> Rainfed and deep water | E17: {=Common_InputFunctions.Utility_DisplayArrayInTable(RiceCultivation_SourceData.SourceData_RiceCultivation_WaterScalingFactorGrowingSeason_Data(),Table_SourceData_WaterScalingFactorGrowingSeason[[#Headers],[Water regime type]],0)} -> Deep water | F17: {=Common_InputFunctions.Utility_DisplayArrayInTable(RiceCultivation_SourceData.SourceData_RiceCultivation_WaterScalingFactorGrowingSeason_Data(),Table_SourceData_WaterScalingFactorGrowingSeason[[#Headers],[Water regime type]],0)} -> 0.06
A18: =HYPERLINK("#'Constants - Rice cultivation'!A1", "Constants - Rice cultivation") -> Constants - Rice cultivation
A19: =HYPERLINK("#'Constants - Common'!A1", "Constants - Common") -> Constants - Common
D20: {=RiceCultivation_SourceData.SourceData_RiceCultivation_WaterScalingFactorPreSeason_Title()} -> Scaling factor based on the water regime employed in the pre - season before the growing period
D21: {=RiceCultivation_SourceData.SourceData_RiceCultivation_WaterScalingFactorPreSeason_Source()} -> VEERG 2026: Table A.2.3.2
D22: {=RiceCultivation_SourceData.SourceData_RiceCultivation_WaterScalingFactorPreSeason_Variable()} -> SFp
D23: {=RiceCultivation_SourceData.SourceData_RiceCultivation_WaterScalingFactorPreSeason_Unit()} -> fraction
D24: Water regime prior to cultivation | E24: SFp
D25: {=Common_InputFunctions.Utility_DisplayArrayInTable(RiceCultivation_SourceData.SourceData_RiceCultivation_WaterScalingFactorPreSeason_Data(),Table_SourceData_WaterScalingFactorPreSeason[[#Headers],[Water regime prior to cultivation]], 0)} -> Non flooded pre-season <180 days | E25: {=Common_InputFunctions.Utility_DisplayArrayInTable(RiceCultivation_SourceData.SourceData_RiceCultivation_WaterScalingFactorPreSeason_Data(),Table_SourceData_WaterScalingFactorPreSeason[[#Headers],[Water regime prior to cultivation]], 0)} -> 1
D26: {=Common_InputFunctions.Utility_DisplayArrayInTable(RiceCultivation_SourceData.SourceData_RiceCultivation_WaterScalingFactorPreSeason_Data(),Table_SourceData_WaterScalingFactorPreSeason[[#Headers],[Water regime prior to cultivation]], 0)} -> Non flooded pre-season >180 days | E26: {=Common_InputFunctions.Utility_DisplayArrayInTable(RiceCultivation_SourceData.SourceData_RiceCultivation_WaterScalingFactorPreSeason_Data(),Table_SourceData_WaterScalingFactorPreSeason[[#Headers],[Water regime prior to cultivation]], 0)} -> 0.89
D27: {=Common_InputFunctions.Utility_DisplayArrayInTable(RiceCultivation_SourceData.SourceData_RiceCultivation_WaterScalingFactorPreSeason_Data(),Table_SourceData_WaterScalingFactorPreSeason[[#Headers],[Water regime prior to cultivation]], 0)} -> Flooded pre-season >30 days | E27: {=Common_InputFunctions.Utility_DisplayArrayInTable(RiceCultivation_SourceData.SourceData_RiceCultivation_WaterScalingFactorPreSeason_Data(),Table_SourceData_WaterScalingFactorPreSeason[[#Headers],[Water regime prior to cultivation]], 0)} -> 2.41
D28: {=Common_InputFunctions.Utility_DisplayArrayInTable(RiceCultivation_SourceData.SourceData_RiceCultivation_WaterScalingFactorPreSeason_Data(),Table_SourceData_WaterScalingFactorPreSeason[[#Headers],[Water regime prior to cultivation]], 0)} -> Non-flooded pre-season >365 days | E28: {=Common_InputFunctions.Utility_DisplayArrayInTable(RiceCultivation_SourceData.SourceData_RiceCultivation_WaterScalingFactorPreSeason_Data(),Table_SourceData_WaterScalingFactorPreSeason[[#Headers],[Water regime prior to cultivation]], 0)} -> 0.59
D31: {=RiceCultivation_SourceData.SourceData_RiceCultivation_OrganicAmendmentConversionFactor_Title()} -> Conversion factor for organic amendment i
D32: {=RiceCultivation_SourceData.SourceData_RiceCultivation_OrganicAmendmentConversionFactor_Source()} -> VEERG 2026: Table A.2.3.3
D33: {=RiceCultivation_SourceData.SourceData_RiceCultivation_OrganicAmendmentConversionFactor_Variation()} -> VARIATION ON SOURCE:
D34: Included inorganic fertiliser as amendment as per VEERG equation description:
D35: Where inorganic fertiliser is applied to the rice fields rather than organic amendments, SF_o is set to 1.
D36: {=RiceCultivation_SourceData.SourceData_RiceCultivation_OrganicAmendmentConversionFactor_Variable()} -> CFOAi
D37: {=RiceCultivation_SourceData.SourceData_RiceCultivation_OrganicAmendmentConversionFactor_Unit()} -> fraction
D38: Organic amendment i | E38: CFOAi
D39: {=Common_InputFunctions.Utility_DisplayArrayInTable(RiceCultivation_SourceData.SourceData_RiceCultivation_OrganicAmendmentConversionFactor_Data(),Table15[[#Headers],[Organic amendment i]],0)} -> Straw incorporated shortly (<30 days) before cultivation | E39: {=Common_InputFunctions.Utility_DisplayArrayInTable(RiceCultivation_SourceData.SourceData_RiceCultivation_OrganicAmendmentConversionFactor_Data(),Table15[[#Headers],[Organic amendment i]],0)} -> 1
D40: {=Common_InputFunctions.Utility_DisplayArrayInTable(RiceCultivation_SourceData.SourceData_RiceCultivation_OrganicAmendmentConversionFactor_Data(),Table15[[#Headers],[Organic amendment i]],0)} -> Straw incorporated long (>30 days) before cultivation | E40: {=Common_InputFunctions.Utility_DisplayArrayInTable(RiceCultivation_SourceData.SourceData_RiceCultivation_OrganicAmendmentConversionFactor_Data(),Table15[[#Headers],[Organic amendment i]],0)} -> 0.19
D41: {=Common_InputFunctions.Utility_DisplayArrayInTable(RiceCultivation_SourceData.SourceData_RiceCultivation_OrganicAmendmentConversionFactor_Data(),Table15[[#Headers],[Organic amendment i]],0)} -> Compost | E41: {=Common_InputFunctions.Utility_DisplayArrayInTable(RiceCultivation_SourceData.SourceData_RiceCultivation_OrganicAmendmentConversionFactor_Data(),Table15[[#Headers],[Organic amendment i]],0)} -> 0.17
D42: {=Common_InputFunctions.Utility_DisplayArrayInTable(RiceCultivation_SourceData.SourceData_RiceCultivation_OrganicAmendmentConversionFactor_Data(),Table15[[#Headers],[Organic amendment i]],0)} -> Farm yard manure | E42: {=Common_InputFunctions.Utility_DisplayArrayInTable(RiceCultivation_SourceData.SourceData_RiceCultivation_OrganicAmendmentConversionFactor_Data(),Table15[[#Headers],[Organic amendment i]],0)} -> 0.21
D43: {=Common_InputFunctions.Utility_DisplayArrayInTable(RiceCultivation_SourceData.SourceData_RiceCultivation_OrganicAmendmentConversionFactor_Data(),Table15[[#Headers],[Organic amendment i]],0)} -> Green manure | E43: {=Common_InputFunctions.Utility_DisplayArrayInTable(RiceCultivation_SourceData.SourceData_RiceCultivation_OrganicAmendmentConversionFactor_Data(),Table15[[#Headers],[Organic amendment i]],0)} -> 0.45
...

Sheet Constants - Common
A1: #VALUE! | C1: Constants - Common
A3: =HYPERLINK("#'Home'!A1", "Home") -> Home
A4: =HYPERLINK("#'Overview'!A1", "Overview") -> Overview
A5: =HYPERLINK("#'Results'!A1", "Results") -> Results | D5: {=Common_SourceData.Common_SourceData_AustralianStatesTerritories_Title()} -> Australian states and territories
D6: State/Territory | E6: Common Name | F6: Abbreviation
D7: {=Common_InputFunctions.Utility_DisplayArrayInTable(Common_SourceData.Common_SourceData_AustralianStatesTerritories_Data(),Table_AustralianStates[[#Headers],[State/Territory]],0)} -> New South Wales | E7: {=Common_InputFunctions.Utility_DisplayArrayInTable(Common_SourceData.Common_SourceData_AustralianStatesTerritories_Data(),Table_AustralianStates[[#Headers],[State/Territory]],0)} -> New South Wales | F7: {=Common_InputFunctions.Utility_DisplayArrayInTable(Common_SourceData.Common_SourceData_AustralianStatesTerritories_Data(),Table_AustralianStates[[#Headers],[State/Territory]],0)} -> NSW
A8: INPUTS | D8: {=Common_InputFunctions.Utility_DisplayArrayInTable(Common_SourceData.Common_SourceData_AustralianStatesTerritories_Data(),Table_AustralianStates[[#Headers],[State/Territory]],0)} -> Australian Capital Territory | E8: {=Common_InputFunctions.Utility_DisplayArrayInTable(Common_SourceData.Common_SourceData_AustralianStatesTerritories_Data(),Table_AustralianStates[[#Headers],[State/Territory]],0)} -> ACT | F8: {=Common_InputFunctions.Utility_DisplayArrayInTable(Common_SourceData.Common_SourceData_AustralianStatesTerritories_Data(),Table_AustralianStates[[#Headers],[State/Territory]],0)} -> ACT
A9: =HYPERLINK("#'Input - Site'!A1", "Site") -> Site | D9: {=Common_InputFunctions.Utility_DisplayArrayInTable(Common_SourceData.Common_SourceData_AustralianStatesTerritories_Data(),Table_AustralianStates[[#Headers],[State/Territory]],0)} -> Victoria | E9: {=Common_InputFunctions.Utility_DisplayArrayInTable(Common_SourceData.Common_SourceData_AustralianStatesTerritories_Data(),Table_AustralianStates[[#Headers],[State/Territory]],0)} -> Victoria | F9: {=Common_InputFunctions.Utility_DisplayArrayInTable(Common_SourceData.Common_SourceData_AustralianStatesTerritories_Data(),Table_AustralianStates[[#Headers],[State/Territory]],0)} -> VIC
A10: =HYPERLINK("#'Input - Rice'!A1", "Rice") -> Rice | D10: {=Common_InputFunctions.Utility_DisplayArrayInTable(Common_SourceData.Common_SourceData_AustralianStatesTerritories_Data(),Table_AustralianStates[[#Headers],[State/Territory]],0)} -> Queensland | E10: {=Common_InputFunctions.Utility_DisplayArrayInTable(Common_SourceData.Common_SourceData_AustralianStatesTerritories_Data(),Table_AustralianStates[[#Headers],[State/Territory]],0)} -> Queensland | F10: {=Common_InputFunctions.Utility_DisplayArrayInTable(Common_SourceData.Common_SourceData_AustralianStatesTerritories_Data(),Table_AustralianStates[[#Headers],[State/Territory]],0)} -> QLD
D11: {=Common_InputFunctions.Utility_DisplayArrayInTable(Common_SourceData.Common_SourceData_AustralianStatesTerritories_Data(),Table_AustralianStates[[#Headers],[State/Territory]],0)} -> South Australia | E11: {=Common_InputFunctions.Utility_DisplayArrayInTable(Common_SourceData.Common_SourceData_AustralianStatesTerritories_Data(),Table_AustralianStates[[#Headers],[State/Territory]],0)} -> South Australia | F11: {=Common_InputFunctions.Utility_DisplayArrayInTable(Common_SourceData.Common_SourceData_AustralianStatesTerritories_Data(),Table_AustralianStates[[#Headers],[State/Territory]],0)} -> SA
D12: {=Common_InputFunctions.Utility_DisplayArrayInTable(Common_SourceData.Common_SourceData_AustralianStatesTerritories_Data(),Table_AustralianStates[[#Headers],[State/Territory]],0)} -> Western Australia | E12: {=Common_InputFunctions.Utility_DisplayArrayInTable(Common_SourceData.Common_SourceData_AustralianStatesTerritories_Data(),Table_AustralianStates[[#Headers],[State/Territory]],0)} -> Western Australia | F12: {=Common_InputFunctions.Utility_DisplayArrayInTable(Common_SourceData.Common_SourceData_AustralianStatesTerritories_Data(),Table_AustralianStates[[#Headers],[State/Territory]],0)} -> WA
A13: CALCULATIONS | D13: {=Common_InputFunctions.Utility_DisplayArrayInTable(Common_SourceData.Common_SourceData_AustralianStatesTerritories_Data(),Table_AustralianStates[[#Headers],[State/Territory]],0)} -> Tasmania | E13: {=Common_InputFunctions.Utility_DisplayArrayInTable(Common_SourceData.Common_SourceData_AustralianStatesTerritories_Data(),Table_AustralianStates[[#Headers],[State/Territory]],0)} -> Tasmania | F13: {=Common_InputFunctions.Utility_DisplayArrayInTable(Common_SourceData.Common_SourceData_AustralianStatesTerritories_Data(),Table_AustralianStates[[#Headers],[State/Territory]],0)} -> TAS
A14: =HYPERLINK("#'7.1.1-2 Rice cultivation'!A1", "7.1.1-2 Rice cultivation") -> 7.1.1-2 Rice cultivation | D14: {=Common_InputFunctions.Utility_DisplayArrayInTable(Common_SourceData.Common_SourceData_AustralianStatesTerritories_Data(),Table_AustralianStates[[#Headers],[State/Territory]],0)} -> Northern Territory | E14: {=Common_InputFunctions.Utility_DisplayArrayInTable(Common_SourceData.Common_SourceData_AustralianStatesTerritories_Data(),Table_AustralianStates[[#Headers],[State/Territory]],0)} -> Northern Territory | F14: {=Common_InputFunctions.Utility_DisplayArrayInTable(Common_SourceData.Common_SourceData_AustralianStatesTerritories_Data(),Table_AustralianStates[[#Headers],[State/Territory]],0)} -> NT
A17: APPENDICES
A18: =HYPERLINK("#'Constants - Rice cultivation'!A1", "Constants - Rice cultivation") -> Constants - Rice cultivation | D18: {=Common_SourceData.Common_SourceData_WASA4Areas_Title()} -> ABS Statistcal Areas Level 4 - Western Australia
A19: =HYPERLINK("#'Constants - Common'!A1", "Constants - Common") -> Constants - Common | D19: {=Common_SourceData.Common_SourceData_WASA4Areas_Source()} -> Australian Bureau of Statistics (ABS) - Statistical Areas Level 2 - 2021 - Shapefile
D20: SA 4 Name
D21: {=Common_InputFunctions.Utility_DisplayArrayInTable(Common_SourceData.Common_SourceData_WASA4Areas_Data(), Table_WASA4Areas[[#Headers],[SA 4 Name]], 0)} -> Bunbury
D22: {=Common_InputFunctions.Utility_DisplayArrayInTable(Common_SourceData.Common_SourceData_WASA4Areas_Data(), Table_WASA4Areas[[#Headers],[SA 4 Name]], 0)} -> Mandurah
D23: {=Common_InputFunctions.Utility_DisplayArrayInTable(Common_SourceData.Common_SourceData_WASA4Areas_Data(), Table_WASA4Areas[[#Headers],[SA 4 Name]], 0)} -> Perth - Inner
D24: {=Common_InputFunctions.Utility_DisplayArrayInTable(Common_SourceData.Common_SourceData_WASA4Areas_Data(), Table_WASA4Areas[[#Headers],[SA 4 Name]], 0)} -> Perth - North East
D25: {=Common_InputFunctions.Utility_DisplayArrayInTable(Common_SourceData.Common_SourceData_WASA4Areas_Data(), Table_WASA4Areas[[#Headers],[SA 4 Name]], 0)} -> Perth - North West
D26: {=Common_InputFunctions.Utility_DisplayArrayInTable(Common_SourceData.Common_SourceData_WASA4Areas_Data(), Table_WASA4Areas[[#Headers],[SA 4 Name]], 0)} -> Perth - South East
D27: {=Common_InputFunctions.Utility_DisplayArrayInTable(Common_SourceData.Common_SourceData_WASA4Areas_Data(), Table_WASA4Areas[[#Headers],[SA 4 Name]], 0)} -> Perth - South West
D28: {=Common_InputFunctions.Utility_DisplayArrayInTable(Common_SourceData.Common_SourceData_WASA4Areas_Data(), Table_WASA4Areas[[#Headers],[SA 4 Name]], 0)} -> Western Australia - Wheat Belt
D29: {=Common_InputFunctions.Utility_DisplayArrayInTable(Common_SourceData.Common_SourceData_WASA4Areas_Data(), Table_WASA4Areas[[#Headers],[SA 4 Name]], 0)} -> Western Australia - Outback (North)
D30: {=Common_InputFunctions.Utility_DisplayArrayInTable(Common_SourceData.Common_SourceData_WASA4Areas_Data(), Table_WASA4Areas[[#Headers],[SA 4 Name]], 0)} -> Western Australia - Outback (South)
D34: {=Common_SourceData.Common_SourceData_GWP_Title()} -> Global warming potential for greenhouse gases
D35: {=Common_SourceData.Common_SourceData_GWP_Source()} -> XXXXXXX
D36: Gas | E36: CO2-e factor
D37: {=Common_InputFunctions.Utility_DisplayArrayInTable(Common_SourceData.Common_SourceData_GWP_Data(), Table_GWPData[[#Headers],[Gas]], 0)} -> CO2 | E37: {=Common_InputFunctions.Utility_DisplayArrayInTable(Common_SourceData.Common_SourceData_GWP_Data(), Table_GWPData[[#Headers],[Gas]], 0)} -> 1
D38: {=Common_InputFunctions.Utility_DisplayArrayInTable(Common_SourceData.Common_SourceData_GWP_Data(), Table_GWPData[[#Headers],[Gas]], 0)} -> CH4 | E38: {=Common_InputFunctions.Utility_DisplayArrayInTable(Common_SourceData.Common_SourceData_GWP_Data(), Table_GWPData[[#Headers],[Gas]], 0)} -> 28
D39: {=Common_InputFunctions.Utility_DisplayArrayInTable(Common_SourceData.Common_SourceData_GWP_Data(), Table_GWPData[[#Headers],[Gas]], 0)} -> N2O | E39: {=Common_InputFunctions.Utility_DisplayArrayInTable(Common_SourceData.Common_SourceData_GWP_Data(), Table_GWPData[[#Headers],[Gas]], 0)} -> 265
D40: {=Common_InputFunctions.Utility_DisplayArrayInTable(Common_SourceData.Common_SourceData_GWP_Data(), Table_GWPData[[#Headers],[Gas]], 0)} -> CF4 | E40: {=Common_InputFunctions.Utility_DisplayArrayInTable(Common_SourceData.Common_SourceData_GWP_Data(), Table_GWPData[[#Headers],[Gas]], 0)} -> 6630
D41: {=Common_InputFunctions.Utility_DisplayArrayInTable(Common_SourceData.Common_SourceData_GWP_Data(), Table_GWPData[[#Headers],[Gas]], 0)} -> C2F6 | E41: {=Common_InputFunctions.Utility_DisplayArrayInTable(Common_SourceData.Common_SourceData_GWP_Data(), Table_GWPData[[#Headers],[Gas]], 0)} -> 12200
D42: {=Common_InputFunctions.Utility_DisplayArrayInTable(Common_SourceData.Common_SourceData_GWP_Data(), Table_GWPData[[#Headers],[Gas]], 0)} -> SF6 | E42: {=Common_InputFunctions.Utility_DisplayArrayInTable(Common_SourceData.Common_SourceData_GWP_Data(), Table_GWPData[[#Headers],[Gas]], 0)} -> 22800
D43: {=Common_InputFunctions.Utility_DisplayArrayInTable(Common_SourceData.Common_SourceData_GWP_Data(), Table_GWPData[[#Headers],[Gas]], 0)} -> NF3 | E43: {=Common_InputFunctions.Utility_DisplayArrayInTable(Common_SourceData.Common_SourceData_GWP_Data(), Table_GWPData[[#Headers],[Gas]], 0)} -> 17200
D45: {=Common_SourceData.Common_SourceData_ConvertGasElementalToMolecular_Title()} -> Factor to convert elemental mass of gas to molecular mass
D46: {=Common_SourceData.Common_SourceData_ConvertGasElementalToMolecular_Source()} -> XXXXXXX
D47: Gas | E47: Conversion factor | F47: Conversion factor 1 | G47: Conversion factor 2 | H47: Conversion factor combined
...
