Workbook
Name Common_Equations.Common_ConvertCH4ToCO2e: _xlfn.LAMBDA(_xlpm.E_CH4,_xlpm.GWP_CH4, _xlpm.E_CH4 * _xlpm.GWP_CH4)
Name Common_Equations.Common_ConvertCH4ToCO2e_Arguments: _xlfn.LAMBDA(_xlfn.MAKEARRAY(2, 2, _xlfn.LAMBDA(_xlpm.r,_xlpm.c, INDEX({"ECH4","Methane emissions (t CH4)";"GWPCH4","Global warming potential for methane (t CO2-e / t CH4)"}, _xlpm.r, _xlpm.c))))
Name Common_Equations.Common_ConvertCH4ToCO2e_LatexEquation: _xlfn.LAMBDA("CO2_e = E_{CH4} \times GWP_{CH4}")
Name Common_Equations.Common_ConvertCH4ToCO2e_NIRReference: _xlfn.LAMBDA("")
Name Common_Equations.Common_ConvertCH4ToCO2e_Title: _xlfn.LAMBDA("Convert methane emissions to carbon dioxide equivalent emissions")
Name Common_Equations.Common_ConvertCH4ToCO2e_Unit: _xlfn.LAMBDA("t CO2e")
Name Common_Equations.Common_ConvertCH4ToCO2e_Variable: _xlfn.LAMBDA("ECH4 CO2e")
Name Common_Equations.Common_ConvertN2OToCO2e: _xlfn.LAMBDA(_xlpm.E_N2O,_xlpm.GWP_N2O, _xlpm.E_N2O * _xlpm.GWP_N2O)
Name Common_Equations.Common_ConvertN2OToCO2e_LatexEquation: _xlfn.LAMBDA("CO2_e = E_{N2O} \times GWP_{N2O}")
Name Common_Equations.Common_ConvertN2OToCO2e_NIRReference: _xlfn.LAMBDA("")
Name Common_Equations.Common_ConvertN2OToCO2e_Title: _xlfn.LAMBDA("Convert nitrous oxide emissions to carbon dioxide equivalent emissions")
Name Common_Equations.Common_ConvertN2OToCO2e_Unit: _xlfn.LAMBDA("t CO2e")
Name Common_Equations.Common_ConvertN2OToCO2e_Variable: _xlfn.LAMBDA("EN2O CO2e")
Name Common_InputFunctions.Utility_ConvertStateCommonNameToAbbreviation: _xlfn.LAMBDA(_xlpm.StateCommonName,_xlpm.StateCommonNameArray,_xlpm.StateAbbreviationArray, _xlfn.XLOOKUP(_xlpm.StateCommonName, _xlpm.StateCommonNameArray, _xlpm.StateAbbreviationArray, ""))
Name Common_InputFunctions.Utility_DisplayArguments_1_2: _xlfn.LAMBDA(_xlpm.ArgumentsArray, _xlfn.CHOOSECOLS(_xlpm.ArgumentsArray, 1, 2))
Name Common_InputFunctions.Utility_DisplayArguments_3_4: _xlfn.LAMBDA(_xlpm.ArgumentsArray, _xlfn.CHOOSECOLS(_xlpm.ArgumentsArray, 3, 4))
Name Common_InputFunctions.Utility_DisplayFunctionName: _xlfn.LAMBDA(_xlpm.Function, _xlfn.TEXTBEFORE(_xlfn.FORMULATEXT(_xlpm.Function), "("))
Name Common_InputFunctions.Utility_GetArrayTableColumnStartNumber: _xlfn.LAMBDA(_xlpm.TableHeaderCell, COLUMN(_xlpm.TableHeaderCell))
Name Common_InputFunctions.Utility_GetArrayTableRowStartNumber: _xlfn.LAMBDA(_xlpm.TableheaderCell,_xlpm.RowsBetweenHeaderandArray, ROW(_xlpm.TableheaderCell) + _xlpm.RowsBetweenHeaderandArray - 1)
Name Common_InputFunctions.Utility_LookupValueInTable: _xlfn.LAMBDA(_xlpm.LookupValue,_xlpm.LookupArray,_xlpm.ReturnArray, _xlfn.XLOOKUP(_xlpm.LookupValue, _xlpm.LookupArray, _xlpm.ReturnArray, ""))
Name Common_InputFunctions.Utility_ResultsItemFromEquationTitleAndSource: _xlfn.LAMBDA(_xlpm.TitleCell,_xlpm.SourceCell, SUBSTITUTE(LEFT(_xlpm.SourceCell, FIND(",", _xlpm.SourceCell) -1), "VEERG 2026: ", "") & " " & _xlpm.TitleCell )
Name Common_InputFunctions.Utility_SourceHyperlink: _xlfn.LAMBDA(_xlpm.TargetCell, _xlfn.LET(_xlpm.sh, _xlfn.TEXTAFTER(CELL("filename", _xlpm.TargetCell), "]"), _xlpm.addr, CELL("address", _xlpm.TargetCell), "#'" & _xlpm.sh & "'!" & _xlpm.addr))
Name Common_InputFunctions.Utility_SourceHyperlinkDifferentSheet: _xlfn.LAMBDA(_xlpm.TargetCell, _xlfn.LET( _xlpm.sh, _xlfn.TEXTAFTER(CELL("filename", _xlpm.TargetCell), "]"), _xlpm.addr, CELL("address", _xlpm.TargetCell), "#" & _xlpm.addr ) )
Name Common_SourceData.Common_SourceData_AustralianStatesTerritories_Source: _xlfn.LAMBDA("")
Name Common_SourceData.Common_SourceData_AustralianStatesTerritories_Title: _xlfn.LAMBDA("Australian states and territories")
Name Common_SourceData.Common_SourceData_AustralianStatesTerritories_Unit: _xlfn.LAMBDA("")
Name Common_SourceData.Common_SourceData_AustralianStatesTerritories_Variable: _xlfn.LAMBDA("")
Name Common_SourceData.Common_SourceData_ClimateZones_Source: _xlfn.LAMBDA("VEERG 2026: Table 1.3: Climate and Rainfall zone classifications and definitions")
Name Common_SourceData.Common_SourceData_ClimateZones_Title: _xlfn.LAMBDA("VEERG Australian climate zones")
Name Common_SourceData.Common_SourceData_ClimateZones_Unit: _xlfn.LAMBDA("")
Name Common_SourceData.Common_SourceData_ClimateZones_Variable: _xlfn.LAMBDA("")
Name Common_SourceData.Common_SourceData_ConvertGasElementalToMolecular_Source: _xlfn.LAMBDA("XXXXXXX")
Name Common_SourceData.Common_SourceData_ConvertGasElementalToMolecular_Title: _xlfn.LAMBDA("Factor to convert elemental mass of gas to molecular mass")
Name Common_SourceData.Common_SourceData_ConvertGasElementalToMolecular_Unit: _xlfn.LAMBDA("factor")
Name Common_SourceData.Common_SourceData_ConvertGasElementalToMolecular_Variable: _xlfn.LAMBDA("Cg")
Name Common_SourceData.Common_SourceData_ConvertN2oElementalToMolecularCg_Data: _xlfn.LAMBDA(44 / 28)
Name Common_SourceData.Common_SourceData_ConvertN2oElementalToMolecularCg_Source: _xlfn.LAMBDA("National Inventory Report 2023 Volume 1")
Name Common_SourceData.Common_SourceData_ConvertN2oElementalToMolecularCg_Title: _xlfn.LAMBDA("Factor to convert elemental mass of N2O to molecular mass")
Name Common_SourceData.Common_SourceData_ConvertN2oElementalToMolecularCg_Unit: _xlfn.LAMBDA("factor")
Name Common_SourceData.Common_SourceData_ConvertN2oElementalToMolecularCg_Variable: _xlfn.LAMBDA("CgN2O")
Name Common_SourceData.Common_SourceData_DataScores_Scope3_Source: _xlfn.LAMBDA("VEERG 2026: XXXXXXXX")
Name Common_SourceData.Common_SourceData_DataScores_Scope3_Title: _xlfn.LAMBDA("Australian data scores for scope 3")
Name Common_SourceData.Common_SourceData_DataScores_Scope3_Unit: _xlfn.LAMBDA("")
Name Common_SourceData.Common_SourceData_DataScores_Scope3_Variable: _xlfn.LAMBDA("")
Name Common_SourceData.Common_SourceData_DataScores_Scope3_Variation: _xlfn.LAMBDA("")
Name Common_SourceData.Common_SourceData_DensityOfMethane_Data: _xlfn.LAMBDA(0.6784)
Name Common_SourceData.Common_SourceData_DensityOfMethane_Source: _xlfn.LAMBDA("National Inventory Report 2023 Volume 1: Equations 3.B.1a_2, 3.B.1c_2, 3.B.3_1, 3.B.4g_2")
Name Common_SourceData.Common_SourceData_DensityOfMethane_Title: _xlfn.LAMBDA("p = density of methane")
Name Common_SourceData.Common_SourceData_DensityOfMethane_Unit: _xlfn.LAMBDA("kg/m3")
Name Common_SourceData.Common_SourceData_EFleach_Data: _xlfn.LAMBDA(_xlfn.MAKEARRAY(1, 2, _xlfn.LAMBDA(_xlpm.r,_xlpm.c, INDEX({"EFleach",0.011}, _xlpm.r, _xlpm.c))))
Name Common_SourceData.Common_SourceData_EFleach_NIRReference: _xlfn.LAMBDA("National Inventory Report Volume 1: Equation 3.D.B_10")
Name Common_SourceData.Common_SourceData_EFleach_Source: _xlfn.LAMBDA("VEERG 2026:5.5.2.3 Constant Parameters")
Name Common_SourceData.Common_SourceData_EFleach_Title: _xlfn.LAMBDA("Emission factor for nitrogen leaching and runoff")
Name Common_SourceData.Common_SourceData_EFleach_Unit: _xlfn.LAMBDA("(kg N2O-N / kg N")
Name Common_SourceData.Common_SourceData_EFleach_Variation: _xlfn.LAMBDA((""))
Name Common_SourceData.Common_SourceData_EFN2O_NIRReference: _xlfn.LAMBDA("")
Name Common_SourceData.Common_SourceData_EFN2O_Source: _xlfn.LAMBDA("VEERG 2026: Table A.2.2.1")
Name Common_SourceData.Common_SourceData_EFN2O_Title: _xlfn.LAMBDA("Nitrous oxide emission factors for inorganic fertiliser application")
Name Common_SourceData.Common_SourceData_EFN2O_Unit: _xlfn.LAMBDA("(kg N2O-N / kg N")
Name Common_SourceData.Common_SourceData_EFOrganicFertiliserAndCropResidues_Data: _xlfn.LAMBDA(_xlfn.MAKEARRAY(3, 2, _xlfn.LAMBDA(_xlpm.r,_xlpm.c, INDEX({"Climate zone","EFNi & EFN2O";"Wet climate zone",0.006;"Dry climate zone",0.005}, _xlpm.r, _xlpm.c))))

Sheet Home
A1: #VALUE!
A3: =HYPERLINK("#'Home'!A1", "Home") -> Home
A4: =HYPERLINK("#'Overview'!A1", "Overview") -> Overview
A5: =HYPERLINK("#'Results'!A1", "Results") -> Results
A8: INPUTS
A9: =HYPERLINK("#'Input - Wastewater'!A1", "Wastewater") -> Wastewater
A12: CALCULATIONS
A13: =HYPERLINK("#'11.1.1-2 Wastewater CH4'!A1", "11.1.1-2 Wastewater CH4") -> 11.1.1-2 Wastewater CH4
A14: =HYPERLINK("#'11.1.3-4 Wastewater N2O'!A1", "11.1.3-4 Wastewater N2O") -> 11.1.3-4 Wastewater N2O
A17: APPENDICES
A18: =HYPERLINK("#'Constants - Wastewater'!A1", "Constants - Wastewater") -> Constants - Wastewater
A19: =HYPERLINK("#'Constants - Common'!A1", "Constants - Common") -> Constants - Common

Sheet Overview
A1: #VALUE! | C1: 14: Electricity use scope 2: Overview
A3: =HYPERLINK("#'Home'!A1", "Home") -> Home
A4: =HYPERLINK("#'Overview'!A1", "Overview") -> Overview
A5: =HYPERLINK("#'Results'!A1", "Results") -> Results | D5: 💡 Below is a diagram that maps the equations used to calculate emissions, and how they interact with each other.
D6: Click on a box to go to the corresponding calculation.
A8: INPUTS
A9: =HYPERLINK("#'Input - Wastewater'!A1", "Wastewater") -> Wastewater
A12: CALCULATIONS
A13: =HYPERLINK("#'11.1.1-2 Wastewater CH4'!A1", "11.1.1-2 Wastewater CH4") -> 11.1.1-2 Wastewater CH4
A14: =HYPERLINK("#'11.1.3-4 Wastewater N2O'!A1", "11.1.3-4 Wastewater N2O") -> 11.1.3-4 Wastewater N2O
A17: APPENDICES
A18: =HYPERLINK("#'Constants - Wastewater'!A1", "Constants - Wastewater") -> Constants - Wastewater
A19: =HYPERLINK("#'Constants - Common'!A1", "Constants - Common") -> Constants - Common
L37: `

Sheet Results
A1: #VALUE! | C1: 14: Electricity use scope 2: Results
A3: =HYPERLINK("#'Home'!A1", "Home") -> Home
A4: =HYPERLINK("#'Overview'!A1", "Overview") -> Overview | D4: Emissions breakdown
A5: =HYPERLINK("#'Results'!A1", "Results") -> Results
D6: 💡 NOTE: When there is no Method 2, the Method 2 result are the same as Method 1
A8: INPUTS | D8: Scope 1 source | E8: GHG emissions method 1 | F8: GHG emissions method 2 | G8: GHG Unit | H8: CO2-e emissions method 1 | I8: CO2-e emissions method 2 | J8: CO2-e unit
A9: =HYPERLINK("#'Input - Wastewater'!A1", "Wastewater") -> Wastewater | D9: 11.1.1-2 Wastewater CH4 | E9: =VEERG_11_1_1_1__1_MethaneEmissionsFromWastewaterTreatment_Result_Method1 -> 0.047159433 | F9: =E9 -> 0.047159433 | G9: t CH4 | H9: ='11.1.1-2 Wastewater CH4'!E35 -> 1.3204641 | I9: =H9 -> 1.3204641 | J9: t CO2e
D10: 11.1.3-4 Wastewater N2O | E10: =VEERG_11_1_3_1__1_NitrousOxideEmissionsFromFlaredBiogas_Result_Method1 -> 4.26764e-07 | F10: =E10 -> 4.26764e-07 | G10: t N2O | H10: ='11.1.3-4 Wastewater N2O'!E22 -> 0.00011309246 | I10: =H10 -> 0.00011309246 | J10: t CO2e
D11: Total | H11: =SUM(H9:H10) -> 1.3205772 | I11: =SUM(I9:I10) -> 1.3205772 | J11: t CO2e
A12: CALCULATIONS
A13: =HYPERLINK("#'11.1.1-2 Wastewater CH4'!A1", "11.1.1-2 Wastewater CH4") -> 11.1.1-2 Wastewater CH4
A14: =HYPERLINK("#'11.1.3-4 Wastewater N2O'!A1", "11.1.3-4 Wastewater N2O") -> 11.1.3-4 Wastewater N2O
A17: APPENDICES
A18: =HYPERLINK("#'Constants - Wastewater'!A1", "Constants - Wastewater") -> Constants - Wastewater
A19: =HYPERLINK("#'Constants - Common'!A1", "Constants - Common") -> Constants - Common

Sheet Input - Wastewater
A1: #VALUE! | C1: Input - Wastewater
A3: =HYPERLINK("#'Home'!A1", "Home") -> Home
A4: =HYPERLINK("#'Overview'!A1", "Overview") -> Overview
A5: =HYPERLINK("#'Results'!A1", "Results") -> Results | D5: Wastewater treatment
D7: Treatment facility type | F7: Unmanaged aerobic treatment | G7: ← Please select
A8: INPUTS | D8: Quantity of wastewater in cubic metres | F8: 1000 | G8: m3
A9: =HYPERLINK("#'Input - Wastewater'!A1", "Wastewater") -> Wastewater
D10: Chemical oxygen demand
A12: CALCULATIONS | D12: "Chemical oxygen demand" (COD) is an indicator of the amount of organic pollutants in wastewater
A13: =HYPERLINK("#'11.1.1-2 Wastewater CH4'!A1", "11.1.1-2 Wastewater CH4") -> 11.1.1-2 Wastewater CH4
A14: =HYPERLINK("#'11.1.3-4 Wastewater N2O'!A1", "11.1.3-4 Wastewater N2O") -> 11.1.3-4 Wastewater N2O | D14: Average inlet chemical oxygen demand (COD) | F14: 0.9 | G14: kg COD/m3
D15: Fraction of chemical oxygen demand removed from the treatment facility as sludge | F15: 0.5 | G15: fraction
D16: Fraction of chemical oxygen demand removed from the treatment facility and transferred for processing or to landfilll | F16: 0.2 | G16: fraction
A17: APPENDICES | D17: Average outlet chemical oxygen demand | F17: 0.1 | G17: kg COD/m3
A18: =HYPERLINK("#'Constants - Wastewater'!A1", "Constants - Wastewater") -> Constants - Wastewater
A19: =HYPERLINK("#'Constants - Common'!A1", "Constants - Common") -> Constants - Common
D20: Management of sludge biogas
D22: If you know the quantity of sludge biogas but not the amount of methane, assume that the methane content is 70% of the biogas amount.
D24: Quantity of methane in sludge biogas captured for combustion at the facility | F24: 100 | G24: m3 CH4
D25: Quantity of methane in sludge biogas flared by the treatment facility | F25: 100 | G25: m3 CH4
D26: Quantity of methane in sludge biogas transferred out of the treatment facility | F26: 100 | G26: m3 CH4
D54: Methane from treated wastewater - organic material in water
E55: EF is converted to from NGER CO2e to CH4
D56: COD that can emit during treatment is what's put in, less what's removed as sludge and what eventually leaves after treatment
D57: =F8*(F14*(1-F15)-F17) -> 350
E59: EF is converted to from NGER CO2e to CH4
D60: PLUS emissions from sludge that was removed from COD minus what sludge was sent offsite (becoming a scope 3 emission)
D62: Equals CH4
D65: MINUS "methane released from wastewater handling" | E65: does not convert to CO2e
D68: PLUS Emissions from methane in sludge that was flared
D70: Convert to CO2e later with GWP

Sheet 11.1.1-2 Wastewater CH4
A1: #VALUE! | C1: 11.1.1-2 Wastewater CH4
A3: =HYPERLINK("#'Home'!A1", "Home") -> Home | D3: Method 1
A4: =HYPERLINK("#'Overview'!A1", "Overview") -> Overview
A5: =HYPERLINK("#'Results'!A1", "Results") -> Results | D5: {=Wastewater_Methane_Equations.VEERG_11_1_1_1__1_MethaneEmissionsFromWastewaterTreatment_Title()} -> Methane emissions from wastewater treatment
D6: {=Wastewater_Methane_Equations.VEERG_11_1_1_1__1_MethaneEmissionsFromWastewaterTreatment_Source()} -> VEERG 2026: 11.1.1.1, Equation (1)
D7: {=Wastewater_Methane_Equations.VEERG_11_1_1_1__1_MethaneEmissionsFromWastewaterTreatment_Variation()} -> VARIATION ON SOURCE: Changed units of EF_ww, EF_Sludge and EF_flared from CO2e to CH4 to match data in Table
A8: INPUTS | D8: Function name | E8: {=Common_InputFunctions.Utility_DisplayFunctionName(E30)} -> =Wastewater_Methane_Equations.VEERG_11_1_1_1__1_MethaneEmissionsFromWastewaterTreatment
A9: =HYPERLINK("#'Input - Wastewater'!A1", "Wastewater") -> Wastewater
D11: Variable | E11: {=Wastewater_Methane_Equations.VEERG_11_1_1_1__1_MethaneEmissionsFromWastewaterTreatment_Variable()} -> E_CH4
A12: CALCULATIONS | D12: Unit | E12: {=Wastewater_Methane_Equations.VEERG_11_1_1_1__1_MethaneEmissionsFromWastewaterTreatment_Unit()} -> t CH4
A13: =HYPERLINK("#'11.1.1-2 Wastewater CH4'!A1", "11.1.1-2 Wastewater CH4") -> 11.1.1-2 Wastewater CH4
A14: =HYPERLINK("#'11.1.3-4 Wastewater N2O'!A1", "11.1.3-4 Wastewater N2O") -> 11.1.3-4 Wastewater N2O | D14: {=_xlfn.CHOOSECOLS(Wastewater_Methane_Equations.VEERG_11_1_1_1__1_MethaneEmissionsFromWastewaterTreatment_Arguments(),1,2)} -> W_t | E14: quantity of wastewater treated at facility type t | H14: {=_xlfn.CHOOSECOLS(Wastewater_Methane_Equations.VEERG_11_1_1_1__1_MethaneEmissionsFromWastewaterTreatment_Arguments(),3,4)} -> m3 | I14: Input | J14: =X_Cell_Wastewater_QuantityInM3 -> 1000
D15: COD_in | E15: average inlet Chemical Oxygen Demand concentration of wastewater | H15: kg COD/m3 | I15: Input | J15: =X_Cell_Wastewater_InletCOD -> 0.9
D16: F_sludge | E16: fraction of COD removed from wastewater as sludge | H16: fraction | I16: Input | J16: =X_Cell_Wastewater_FractionCODRemovedAsSludge -> 0.5
A17: APPENDICES | D17: COD_out | E17: average outlet COD concentration of wastewater | H17: kg COD/m3 | I17: Input | J17: =X_Cell_Wastewater_OutletCOD -> 0.1
A18: =HYPERLINK("#'Constants - Wastewater'!A1", "Constants - Wastewater") -> Constants - Wastewater | D18: CF_ww_t | E18: methane correction factor for facility type t used to treat wastewater | H18: fraction | I18: Constant | J18: {=Common_InputFunctions.Utility_LookupValueInTableNumber(J28,Table_SourceData_MCF_Wastewater[Facility type t],Table_SourceData_MCF_Wastewater[CFww,t])} -> 0.3
A19: =HYPERLINK("#'Constants - Common'!A1", "Constants - Common") -> Constants - Common | D19: EF_ww | E19: methane emission factor for wastewater | H19: kg CH4/kg COD | I19: Constant | J19: ='Constants - Wastewater'!$E$31 -> 0.25
D20: F_removed | E20: fraction of COD removed from the wastewater treatment facility and transferred elsewhere | H20: fraction | I20: Input | J20: =X_Cell_Wastewater_FractionCODRemovedAndTransferred -> 0.2
D21: CF_sludge_t | E21: methane correction factor for facility type t used to treat sludge | H21: fraction | I21: Constant | J21: {=Common_InputFunctions.Utility_LookupValueInTableNumber(J28,Table_SourceData_MCF_Sludge[Facility type t],Table_SourceData_MCF_Sludge[CFsludge,t])} -> 0.3
D22: EF_sludge | E22: methane emission factor for sludge | H22: kg CH4/kg COD | I22: Constant | J22: ='Constants - Wastewater'!$E$36 -> 0.25
D23: Q_cap | E23: quantity of methane in sludge biogas captured for combustion | H23: m3 CH4 | I23: Input | J23: =X_Cell_Wastewater_SludgeMethaneCapturedForCombustion -> 100
D24: Q_flared | E24: quantity of methane in sludge biogas flared by the treatment facility | H24: m3 CH4 | I24: Input | J24: =X_Cell_Wastewater_SludgeMethaneFlared -> 100
D25: Q_out | E25: quantity of methane in sludge biogas transferred out of the treatment facility | H25: m3 CH4 | I25: Input | J25: =X_Cell_Wastewater_SludgeMethaneTransferred -> 100
D26: EC_flared | E26: energy content factor of methane in sludge biogas flared | H26: GJ/m3 | I26: Constant | J26: ='Constants - Wastewater'!$E$41 -> 0.0377
D27: EF_flaredCH4 | E27: methane emission factor for sludge biogas flared | H27: kg CH4/GJ | I27: Constant | J27: ='Constants - Wastewater'!$E$46 -> 0.2289
D28: t | E28: treatment facility type | I28: Input | J28: =X_Cell_Wastewater_TreatmentFacilityType -> Unmanaged aerobic treatment
D30: ECH4 | E30: {=Wastewater_Methane_Equations.VEERG_11_1_1_1__1_MethaneEmissionsFromWastewaterTreatment(J14,J15,J16,J17,J18,J19,J20,J21,J22,J23,J24,J25,J26,J27)} -> 0.047159433 | F30: =$E$12 -> t CH4
D32: {=Common_Equations.Common_ConvertCH4ToCO2e_Arguments()} -> ECH4 | E32: Methane emissions (t CH4) | G32: =E30 -> 0.047159433
D33: GWPCH4 | E33: Global warming potential for methane (t CO2-e / t CH4) | G33: 28
D35: ECO2e | E35: {=Common_Equations.Common_ConvertN2OToCO2e(G32,G33)} -> 1.3204641 | F35: {=Common_Equations.Common_ConvertN2OToCO2e_Unit()} -> t CO2e

Sheet 11.1.3-4 Wastewater N2O
A1: #VALUE! | C1: 11.1.3-4 Wastewater N2O
A3: =HYPERLINK("#'Home'!A1", "Home") -> Home | D3: Method 1
A4: =HYPERLINK("#'Overview'!A1", "Overview") -> Overview
A5: =HYPERLINK("#'Results'!A1", "Results") -> Results | D5: {=Wastewater_N2O_Equations.VEERG_11_1_3_1__1_NitrousOxideEmissionsFromFlaredBiogas_Title()} -> Nitrous oxide emissions from flared biogas
D6: {=Wastewater_N2O_Equations.VEERG_11_1_3_1__1_NitrousOxideEmissionsFromFlaredBiogas_Source()} -> VEERG 2026: 11.1.3.1, Equation (1)
D7: Function name | E7: {=Common_InputFunctions.Utility_DisplayFunctionName(E17)} -> =Wastewater_N2O_Equations.VEERG_11_1_3_1__1_NitrousOxideEmissionsFromFlaredBiogas
A8: INPUTS
A9: =HYPERLINK("#'Input - Wastewater'!A1", "Wastewater") -> Wastewater
D10: Variable | E10: {=Wastewater_N2O_Equations.VEERG_11_1_3_1__1_NitrousOxideEmissionsFromFlaredBiogas_Variable()} -> E_N2O
D11: Unit | E11: {=Wastewater_N2O_Equations.VEERG_11_1_3_1__1_NitrousOxideEmissionsFromFlaredBiogas_Unit()} -> t N2O
A12: CALCULATIONS
A13: =HYPERLINK("#'11.1.1-2 Wastewater CH4'!A1", "11.1.1-2 Wastewater CH4") -> 11.1.1-2 Wastewater CH4 | D13: {=_xlfn.CHOOSECOLS(Wastewater_N2O_Equations.VEERG_11_1_3_1__1_NitrousOxideEmissionsFromFlaredBiogas_Arguments(),1,2)} -> Q_flared | E13: volume of biogas flared | G13: {=_xlfn.CHOOSECOLS(Wastewater_N2O_Equations.VEERG_11_1_3_1__1_NitrousOxideEmissionsFromFlaredBiogas_Arguments(),3,4)} -> m3 | H13: Input | I13: =X_Cell_Wastewater_SludgeMethaneFlared -> 100
A14: =HYPERLINK("#'11.1.3-4 Wastewater N2O'!A1", "11.1.3-4 Wastewater N2O") -> 11.1.3-4 Wastewater N2O | D14: EC_flared | E14: energy content factor of sludge biogas flared | G14: GJ/m3 | H14: Constant | I14: ='Constants - Wastewater'!E41 -> 0.0377
D15: EF_flaredN2O | E15: nitrous oxide emission factor for flared biogas | G15: kg N2O/GJ | H15: Constant | I15: ='Constants - Wastewater'!E51 -> 0.0001132
A17: APPENDICES | D17: ECH4 | E17: {=Wastewater_N2O_Equations.VEERG_11_1_3_1__1_NitrousOxideEmissionsFromFlaredBiogas(I13,I14,I15)} -> 4.26764e-07 | F17: =$E$11 -> t N2O
A18: =HYPERLINK("#'Constants - Wastewater'!A1", "Constants - Wastewater") -> Constants - Wastewater
A19: =HYPERLINK("#'Constants - Common'!A1", "Constants - Common") -> Constants - Common | D19: {=Common_Equations.Common_ConvertN2OToCO2e_Arguments()} -> EN2O | E19: Nitrous oxide emissions (t N2O) | G19: =E17 -> 4.26764e-07
D20: GWPN2O | E20: Global warming potential for nitrous oxide (t CO2-e / t N2O) | G20: 265
D22: ECO2e | E22: {=Common_Equations.Common_ConvertN2OToCO2e(G19,G20)} -> 0.00011309246 | F22: {=Common_Equations.Common_ConvertN2OToCO2e_Unit()} -> t CO2e

Sheet Constants - Wastewater
A1: #VALUE! | C1: Constants - Wastewater
A3: =HYPERLINK("#'Home'!A1", "Home") -> Home
A4: =HYPERLINK("#'Overview'!A1", "Overview") -> Overview
A5: =HYPERLINK("#'Results'!A1", "Results") -> Results | D5: {=Wastewater_SourceData.Waste_MethaneCorrectionFactorWastewater_Title()} -> Methane correction factor for treatment facility type t used to treat wastewater
D6: {=Wastewater_SourceData.Waste_MethaneCorrectionFactorWastewater_Source()} -> VEERG 2026: Table A.4.1.3
D7: {=Wastewater_SourceData.Waste_MethaneCorrectionFactorWastewater_Variable()} -> CFww,t
A8: INPUTS | D8: {=Wastewater_SourceData.Waste_MethaneCorrectionFactorWastewater_Unit()} -> fraction
A9: =HYPERLINK("#'Input - Wastewater'!A1", "Wastewater") -> Wastewater | D9: Facility type t | E9: CFww,t
D10: {=Common_InputFunctions.Utility_DisplayArrayInTable(Wastewater_SourceData.Waste_MethaneCorrectionFactorWastewater_Data(), Table_SourceData_MCF_Wastewater[[#Headers],[Facility type t]], 0)} -> Managed aerobic treatment | E10: {=Common_InputFunctions.Utility_DisplayArrayInTable(Wastewater_SourceData.Waste_MethaneCorrectionFactorWastewater_Data(), Table_SourceData_MCF_Wastewater[[#Headers],[Facility type t]], 0)} -> 0
D11: {=Common_InputFunctions.Utility_DisplayArrayInTable(Wastewater_SourceData.Waste_MethaneCorrectionFactorWastewater_Data(), Table_SourceData_MCF_Wastewater[[#Headers],[Facility type t]], 0)} -> Unmanaged aerobic treatment | E11: {=Common_InputFunctions.Utility_DisplayArrayInTable(Wastewater_SourceData.Waste_MethaneCorrectionFactorWastewater_Data(), Table_SourceData_MCF_Wastewater[[#Headers],[Facility type t]], 0)} -> 0.3
A12: CALCULATIONS | D12: {=Common_InputFunctions.Utility_DisplayArrayInTable(Wastewater_SourceData.Waste_MethaneCorrectionFactorWastewater_Data(), Table_SourceData_MCF_Wastewater[[#Headers],[Facility type t]], 0)} -> Anaerobic digestor/reactor | E12: {=Common_InputFunctions.Utility_DisplayArrayInTable(Wastewater_SourceData.Waste_MethaneCorrectionFactorWastewater_Data(), Table_SourceData_MCF_Wastewater[[#Headers],[Facility type t]], 0)} -> 0.8
A13: =HYPERLINK("#'11.1.1-2 Wastewater CH4'!A1", "11.1.1-2 Wastewater CH4") -> 11.1.1-2 Wastewater CH4 | D13: {=Common_InputFunctions.Utility_DisplayArrayInTable(Wastewater_SourceData.Waste_MethaneCorrectionFactorWastewater_Data(), Table_SourceData_MCF_Wastewater[[#Headers],[Facility type t]], 0)} -> Shallow anaerobic lagoon (≤ 2 m) | E13: {=Common_InputFunctions.Utility_DisplayArrayInTable(Wastewater_SourceData.Waste_MethaneCorrectionFactorWastewater_Data(), Table_SourceData_MCF_Wastewater[[#Headers],[Facility type t]], 0)} -> 0.2
A14: =HYPERLINK("#'11.1.3-4 Wastewater N2O'!A1", "11.1.3-4 Wastewater N2O") -> 11.1.3-4 Wastewater N2O | D14: {=Common_InputFunctions.Utility_DisplayArrayInTable(Wastewater_SourceData.Waste_MethaneCorrectionFactorWastewater_Data(), Table_SourceData_MCF_Wastewater[[#Headers],[Facility type t]], 0)} -> Deep anaerobic lagoon (> 2m) | E14: {=Common_InputFunctions.Utility_DisplayArrayInTable(Wastewater_SourceData.Waste_MethaneCorrectionFactorWastewater_Data(), Table_SourceData_MCF_Wastewater[[#Headers],[Facility type t]], 0)} -> 0.8
A17: APPENDICES | D17: {=Wastewater_SourceData.Waste_MethaneCorrectionFactorSludge_Title()} -> Methane correction factor for treatment facility type t used to treat sludge
A18: =HYPERLINK("#'Constants - Wastewater'!A1", "Constants - Wastewater") -> Constants - Wastewater | D18: {=Wastewater_SourceData.Waste_MethaneCorrectionFactorSludge_Source()} -> VEERG 2026: Table A.4.1.4
A19: =HYPERLINK("#'Constants - Common'!A1", "Constants - Common") -> Constants - Common | D19: {=Wastewater_SourceData.Waste_MethaneCorrectionFactorSludge_Variable()} -> CFsludge,t
D20: {=Wastewater_SourceData.Waste_MethaneCorrectionFactorSludge_Unit()} -> fraction
D21: Facility type t | E21: CFsludge,t
D22: {=Common_InputFunctions.Utility_DisplayArrayInTable(Wastewater_SourceData.Waste_MethaneCorrectionFactorSludge_Data(), Table_SourceData_MCF_Sludge[[#Headers],[Facility type t]], 0)} -> Managed aerobic treatment | E22: {=Common_InputFunctions.Utility_DisplayArrayInTable(Wastewater_SourceData.Waste_MethaneCorrectionFactorSludge_Data(), Table_SourceData_MCF_Sludge[[#Headers],[Facility type t]], 0)} -> 0
D23: {=Common_InputFunctions.Utility_DisplayArrayInTable(Wastewater_SourceData.Waste_MethaneCorrectionFactorSludge_Data(), Table_SourceData_MCF_Sludge[[#Headers],[Facility type t]], 0)} -> Unmanaged aerobic treatment | E23: {=Common_InputFunctions.Utility_DisplayArrayInTable(Wastewater_SourceData.Waste_MethaneCorrectionFactorSludge_Data(), Table_SourceData_MCF_Sludge[[#Headers],[Facility type t]], 0)} -> 0.3
D24: {=Common_InputFunctions.Utility_DisplayArrayInTable(Wastewater_SourceData.Waste_MethaneCorrectionFactorSludge_Data(), Table_SourceData_MCF_Sludge[[#Headers],[Facility type t]], 0)} -> Anaerobic digestor/reactor | E24: {=Common_InputFunctions.Utility_DisplayArrayInTable(Wastewater_SourceData.Waste_MethaneCorrectionFactorSludge_Data(), Table_SourceData_MCF_Sludge[[#Headers],[Facility type t]], 0)} -> 0.8
D25: {=Common_InputFunctions.Utility_DisplayArrayInTable(Wastewater_SourceData.Waste_MethaneCorrectionFactorSludge_Data(), Table_SourceData_MCF_Sludge[[#Headers],[Facility type t]], 0)} -> Shallow anaerobic lagoon (≤ 2 m) | E25: {=Common_InputFunctions.Utility_DisplayArrayInTable(Wastewater_SourceData.Waste_MethaneCorrectionFactorSludge_Data(), Table_SourceData_MCF_Sludge[[#Headers],[Facility type t]], 0)} -> 0.2
D26: {=Common_InputFunctions.Utility_DisplayArrayInTable(Wastewater_SourceData.Waste_MethaneCorrectionFactorSludge_Data(), Table_SourceData_MCF_Sludge[[#Headers],[Facility type t]], 0)} -> Deep anaerobic lagoon (> 2m) | E26: {=Common_InputFunctions.Utility_DisplayArrayInTable(Wastewater_SourceData.Waste_MethaneCorrectionFactorSludge_Data(), Table_SourceData_MCF_Sludge[[#Headers],[Facility type t]], 0)} -> 0.8
D29: {=Wastewater_SourceData.Waste_MethaneEmissionFactorWastewater_Title()} -> Methane emission factor for wastewater
D30: {=Wastewater_SourceData.Waste_MethaneEmissionFactorWastewater_Source()} -> VEERG 2026: 11.2.3 Constants
D31: {=Wastewater_SourceData.Waste_MethaneEmissionFactorWastewater_Variable()} -> EFww | E31: {=Wastewater_SourceData.Waste_MethaneEmissionFactorWastewater_Data()} -> 0.25 | F31: {=Wastewater_SourceData.Waste_MethaneEmissionFactorWastewater_Unit()} -> kg CH4 / kg COD
D34: {=Wastewater_SourceData.Waste_MethaneEmissionFactorSludge_Title()} -> Methane emission factor for sludge
D35: {=Wastewater_SourceData.Waste_MethaneEmissionFactorSludge_Source()} -> VEERG 2026: 11.2.3 Constants
D36: {=Wastewater_SourceData.Waste_MethaneEmissionFactorSludge_Variable()} -> EFsludge | E36: {=Wastewater_SourceData.Waste_MethaneEmissionFactorSludge_Data()} -> 0.25 | F36: {=Wastewater_SourceData.Waste_MethaneEmissionFactorSludge_Unit()} -> kg CH4 / kg COD
D39: {=Wastewater_SourceData.Waste_EnergyContentFactorSludgeBiogasFlared_Title()} -> Energy content factor of sludge biogas flared
D40: {=Wastewater_SourceData.Waste_EnergyContentFactorSludgeBiogasFlared_Source()} -> VEERG 2026: 11.2.3 Constants
D41: {=Wastewater_SourceData.Waste_EnergyContentFactorSludgeBiogasFlared_Variable()} -> ECflared | E41: {=Wastewater_SourceData.Waste_EnergyContentFactorSludgeBiogasFlared_Data()} -> 0.0377 | F41: {=Wastewater_SourceData.Waste_EnergyContentFactorSludgeBiogasFlared_Unit()} -> GJ / m3
D44: {=Wastewater_SourceData.Waste_MethaneEmissionFactorSludgeBiogasFlared_Title()} -> Methane emission factor for sludge biogas flared
D45: {=Wastewater_SourceData.Waste_MethaneEmissionFactorSludgeBiogasFlared_Source()} -> VEERG 2026: 11.2.3 Constants
D46: {=Wastewater_SourceData.Waste_MethaneEmissionFactorSludgeBiogasFlared_Variable()} -> EFflared,CH4 | E46: {=Wastewater_SourceData.Waste_MethaneEmissionFactorSludgeBiogasFlared_Data()} -> 0.2289 | F46: {=Wastewater_SourceData.Waste_MethaneEmissionFactorSludgeBiogasFlared_Unit()} -> kg CH4 / GJ
D49: {=Wastewater_SourceData.Waste_NitrousOxideEmissionFactorSludgeBiogasFlared_Title()} -> Nitrous oxide emission factor for sludge biogas flared
D50: {=Wastewater_SourceData.Waste_NitrousOxideEmissionFactorSludgeBiogasFlared_Source()} -> VEERG 2026: 11.2.3 Constants
D51: {=Wastewater_SourceData.Waste_NitrousOxideEmissionFactorSludgeBiogasFlared_Variable()} -> EFflared,N2O | E51: {=Wastewater_SourceData.Waste_NitrousOxideEmissionFactorSludgeBiogasFlared_Data()} -> 0.0001132 | F51: {=Wastewater_SourceData.Waste_NitrousOxideEmissionFactorSludgeBiogasFlared_Unit()} -> kg N2O / GJ

Sheet Constants - Common
A1: #VALUE! | C1: Constants - Common
A3: =HYPERLINK("#'Home'!A1", "Home") -> Home
A4: =HYPERLINK("#'Overview'!A1", "Overview") -> Overview
A5: =HYPERLINK("#'Results'!A1", "Results") -> Results | D5: {=Common_SourceData.Common_SourceData_AustralianStatesTerritories_Title()} -> Australian states and territories
D6: State/Territory | E6: Common Name | F6: Abbreviation
D7: {=Common_InputFunctions.Utility_DisplayArrayInTable(Common_SourceData.Common_SourceData_AustralianStatesTerritories_Data(),Table_AustralianStates[[#Headers],[State/Territory]],0)} -> New South Wales | E7: {=Common_InputFunctions.Utility_DisplayArrayInTable(Common_SourceData.Common_SourceData_AustralianStatesTerritories_Data(),Table_AustralianStates[[#Headers],[State/Territory]],0)} -> New South Wales | F7: {=Common_InputFunctions.Utility_DisplayArrayInTable(Common_SourceData.Common_SourceData_AustralianStatesTerritories_Data(),Table_AustralianStates[[#Headers],[State/Territory]],0)} -> NSW
A8: INPUTS | D8: {=Common_InputFunctions.Utility_DisplayArrayInTable(Common_SourceData.Common_SourceData_AustralianStatesTerritories_Data(),Table_AustralianStates[[#Headers],[State/Territory]],0)} -> Australian Capital Territory | E8: {=Common_InputFunctions.Utility_DisplayArrayInTable(Common_SourceData.Common_SourceData_AustralianStatesTerritories_Data(),Table_AustralianStates[[#Headers],[State/Territory]],0)} -> ACT | F8: {=Common_InputFunctions.Utility_DisplayArrayInTable(Common_SourceData.Common_SourceData_AustralianStatesTerritories_Data(),Table_AustralianStates[[#Headers],[State/Territory]],0)} -> ACT
A9: =HYPERLINK("#'Input - Wastewater'!A1", "Wastewater") -> Wastewater | D9: {=Common_InputFunctions.Utility_DisplayArrayInTable(Common_SourceData.Common_SourceData_AustralianStatesTerritories_Data(),Table_AustralianStates[[#Headers],[State/Territory]],0)} -> Victoria | E9: {=Common_InputFunctions.Utility_DisplayArrayInTable(Common_SourceData.Common_SourceData_AustralianStatesTerritories_Data(),Table_AustralianStates[[#Headers],[State/Territory]],0)} -> Victoria | F9: {=Common_InputFunctions.Utility_DisplayArrayInTable(Common_SourceData.Common_SourceData_AustralianStatesTerritories_Data(),Table_AustralianStates[[#Headers],[State/Territory]],0)} -> VIC
D10: {=Common_InputFunctions.Utility_DisplayArrayInTable(Common_SourceData.Common_SourceData_AustralianStatesTerritories_Data(),Table_AustralianStates[[#Headers],[State/Territory]],0)} -> Queensland | E10: {=Common_InputFunctions.Utility_DisplayArrayInTable(Common_SourceData.Common_SourceData_AustralianStatesTerritories_Data(),Table_AustralianStates[[#Headers],[State/Territory]],0)} -> Queensland | F10: {=Common_InputFunctions.Utility_DisplayArrayInTable(Common_SourceData.Common_SourceData_AustralianStatesTerritories_Data(),Table_AustralianStates[[#Headers],[State/Territory]],0)} -> QLD
D11: {=Common_InputFunctions.Utility_DisplayArrayInTable(Common_SourceData.Common_SourceData_AustralianStatesTerritories_Data(),Table_AustralianStates[[#Headers],[State/Territory]],0)} -> South Australia | E11: {=Common_InputFunctions.Utility_DisplayArrayInTable(Common_SourceData.Common_SourceData_AustralianStatesTerritories_Data(),Table_AustralianStates[[#Headers],[State/Territory]],0)} -> South Australia | F11: {=Common_InputFunctions.Utility_DisplayArrayInTable(Common_SourceData.Common_SourceData_AustralianStatesTerritories_Data(),Table_AustralianStates[[#Headers],[State/Territory]],0)} -> SA
A12: CALCULATIONS | D12: {=Common_InputFunctions.Utility_DisplayArrayInTable(Common_SourceData.Common_SourceData_AustralianStatesTerritories_Data(),Table_AustralianStates[[#Headers],[State/Territory]],0)} -> Western Australia | E12: {=Common_InputFunctions.Utility_DisplayArrayInTable(Common_SourceData.Common_SourceData_AustralianStatesTerritories_Data(),Table_AustralianStates[[#Headers],[State/Territory]],0)} -> Western Australia | F12: {=Common_InputFunctions.Utility_DisplayArrayInTable(Common_SourceData.Common_SourceData_AustralianStatesTerritories_Data(),Table_AustralianStates[[#Headers],[State/Territory]],0)} -> WA
A13: =HYPERLINK("#'11.1.1-2 Wastewater CH4'!A1", "11.1.1-2 Wastewater CH4") -> 11.1.1-2 Wastewater CH4 | D13: {=Common_InputFunctions.Utility_DisplayArrayInTable(Common_SourceData.Common_SourceData_AustralianStatesTerritories_Data(),Table_AustralianStates[[#Headers],[State/Territory]],0)} -> Tasmania | E13: {=Common_InputFunctions.Utility_DisplayArrayInTable(Common_SourceData.Common_SourceData_AustralianStatesTerritories_Data(),Table_AustralianStates[[#Headers],[State/Territory]],0)} -> Tasmania | F13: {=Common_InputFunctions.Utility_DisplayArrayInTable(Common_SourceData.Common_SourceData_AustralianStatesTerritories_Data(),Table_AustralianStates[[#Headers],[State/Territory]],0)} -> TAS
A14: =HYPERLINK("#'11.1.3-4 Wastewater N2O'!A1", "11.1.3-4 Wastewater N2O") -> 11.1.3-4 Wastewater N2O | D14: {=Common_InputFunctions.Utility_DisplayArrayInTable(Common_SourceData.Common_SourceData_AustralianStatesTerritories_Data(),Table_AustralianStates[[#Headers],[State/Territory]],0)} -> Northern Territory | E14: {=Common_InputFunctions.Utility_DisplayArrayInTable(Common_SourceData.Common_SourceData_AustralianStatesTerritories_Data(),Table_AustralianStates[[#Headers],[State/Territory]],0)} -> Northern Territory | F14: {=Common_InputFunctions.Utility_DisplayArrayInTable(Common_SourceData.Common_SourceData_AustralianStatesTerritories_Data(),Table_AustralianStates[[#Headers],[State/Territory]],0)} -> NT
A17: APPENDICES
A18: =HYPERLINK("#'Constants - Wastewater'!A1", "Constants - Wastewater") -> Constants - Wastewater | D18: {=Common_SourceData.Common_SourceData_WASA4Areas_Title()} -> ABS Statistcal Areas Level 4 - Western Australia
A19: =HYPERLINK("#'Constants - Common'!A1", "Constants - Common") -> Constants - Common | D19: {=Common_SourceData.Common_SourceData_WASA4Areas_Source()} -> Australian Bureau of Statistics (ABS) - Statistical Areas Level 2 - 2021 - Shapefile
D20: SA 4 Name
D21: {=Common_InputFunctions.Utility_DisplayArrayInTable(Common_SourceData.Common_SourceData_WASA4Areas_Data(), Table_WASA4Areas[[#Headers],[SA 4 Name]], 0)} -> Bunbury
D22: {=Common_InputFunctions.Utility_DisplayArrayInTable(Common_SourceData.Common_SourceData_WASA4Areas_Data(), Table_WASA4Areas[[#Headers],[SA 4 Name]], 0)} -> Mandurah
D23: {=Common_InputFunctions.Utility_DisplayArrayInTable(Common_SourceData.Common_SourceData_WASA4Areas_Data(), Table_WASA4Areas[[#Headers],[SA 4 Name]], 0)} -> Perth - Inner
D24: {=Common_InputFunctions.Utility_DisplayArrayInTable(Common_SourceData.Common_SourceData_WASA4Areas_Data(), Table_WASA4Areas[[#Headers],[SA 4 Name]], 0)} -> Perth - North East
D25: {=Common_InputFunctions.Utility_DisplayArrayInTable(Common_SourceData.Common_SourceData_WASA4Areas_Data(), Table_WASA4Areas[[#Headers],[SA 4 Name]], 0)} -> Perth - North West
D26: {=Common_InputFunctions.Utility_DisplayArrayInTable(Common_SourceData.Common_SourceData_WASA4Areas_Data(), Table_WASA4Areas[[#Headers],[SA 4 Name]], 0)} -> Perth - South East
D27: {=Common_InputFunctions.Utility_DisplayArrayInTable(Common_SourceData.Common_SourceData_WASA4Areas_Data(), Table_WASA4Areas[[#Headers],[SA 4 Name]], 0)} -> Perth - South West
D28: {=Common_InputFunctions.Utility_DisplayArrayInTable(Common_SourceData.Common_SourceData_WASA4Areas_Data(), Table_WASA4Areas[[#Headers],[SA 4 Name]], 0)} -> Western Australia - Wheat Belt
D29: {=Common_InputFunctions.Utility_DisplayArrayInTable(Common_SourceData.Common_SourceData_WASA4Areas_Data(), Table_WASA4Areas[[#Headers],[SA 4 Name]], 0)} -> Western Australia - Outback (North)
D30: {=Common_InputFunctions.Utility_DisplayArrayInTable(Common_SourceData.Common_SourceData_WASA4Areas_Data(), Table_WASA4Areas[[#Headers],[SA 4 Name]], 0)} -> Western Australia - Outback (South)
D34: {=Common_SourceData.Common_SourceData_GWP_Title()} -> Global warming potential for greenhouse gases
D35: {=Common_SourceData.Common_SourceData_GWP_Source()} -> XXXXXXX
D36: Gas | E36: CO2-e factor
D37: {=Common_InputFunctions.Utility_DisplayArrayInTable(Common_SourceData.Common_SourceData_GWP_Data(), Table_GWPData[[#Headers],[Gas]], 0)} -> CO2 | E37: {=Common_InputFunctions.Utility_DisplayArrayInTable(Common_SourceData.Common_SourceData_GWP_Data(), Table_GWPData[[#Headers],[Gas]], 0)} -> 1
D38: {=Common_InputFunctions.Utility_DisplayArrayInTable(Common_SourceData.Common_SourceData_GWP_Data(), Table_GWPData[[#Headers],[Gas]], 0)} -> CH4 | E38: {=Common_InputFunctions.Utility_DisplayArrayInTable(Common_SourceData.Common_SourceData_GWP_Data(), Table_GWPData[[#Headers],[Gas]], 0)} -> 28
D39: {=Common_InputFunctions.Utility_DisplayArrayInTable(Common_SourceData.Common_SourceData_GWP_Data(), Table_GWPData[[#Headers],[Gas]], 0)} -> N2O | E39: {=Common_InputFunctions.Utility_DisplayArrayInTable(Common_SourceData.Common_SourceData_GWP_Data(), Table_GWPData[[#Headers],[Gas]], 0)} -> 265
D40: {=Common_InputFunctions.Utility_DisplayArrayInTable(Common_SourceData.Common_SourceData_GWP_Data(), Table_GWPData[[#Headers],[Gas]], 0)} -> CF4 | E40: {=Common_InputFunctions.Utility_DisplayArrayInTable(Common_SourceData.Common_SourceData_GWP_Data(), Table_GWPData[[#Headers],[Gas]], 0)} -> 6630
D41: {=Common_InputFunctions.Utility_DisplayArrayInTable(Common_SourceData.Common_SourceData_GWP_Data(), Table_GWPData[[#Headers],[Gas]], 0)} -> C2F6 | E41: {=Common_InputFunctions.Utility_DisplayArrayInTable(Common_SourceData.Common_SourceData_GWP_Data(), Table_GWPData[[#Headers],[Gas]], 0)} -> 12200
D42: {=Common_InputFunctions.Utility_DisplayArrayInTable(Common_SourceData.Common_SourceData_GWP_Data(), Table_GWPData[[#Headers],[Gas]], 0)} -> SF6 | E42: {=Common_InputFunctions.Utility_DisplayArrayInTable(Common_SourceData.Common_SourceData_GWP_Data(), Table_GWPData[[#Headers],[Gas]], 0)} -> 22800
D43: {=Common_InputFunctions.Utility_DisplayArrayInTable(Common_SourceData.Common_SourceData_GWP_Data(), Table_GWPData[[#Headers],[Gas]], 0)} -> NF3 | E43: {=Common_InputFunctions.Utility_DisplayArrayInTable(Common_SourceData.Common_SourceData_GWP_Data(), Table_GWPData[[#Headers],[Gas]], 0)} -> 17200
D45: {=Common_SourceData.Common_SourceData_ConvertGasElementalToMolecular_Title()} -> Factor to convert elemental mass of gas to molecular mass
D46: {=Common_SourceData.Common_SourceData_ConvertGasElementalToMolecular_Source()} -> XXXXXXX
D47: Gas | E47: Conversion factor | F47: Conversion factor 1 | G47: Conversion factor 2 | H47: Conversion factor combined
...
