Workbook
Name AgResidue_Equations_FieldBurning.VEERG_6_4_1_1__1__MethaneEmissionsFromBurningOfCropResidues: _xlfn.LAMBDA(_xlpm.Mburnc,_xlpm.CCc,_xlpm.EFCH4,_xlpm.C_CH4, _xlpm.Mburnc * _xlpm.CCc * _xlpm.EFCH4 * _xlpm.C_CH4 * 10 ^ (-3))
Name AgResidue_Equations_FieldBurning.VEERG_6_4_1_1__1__MethaneEmissionsFromBurningOfCropResidues_FunctionName: _xlfn.LAMBDA("VEERG_6_4_1_1__1__MethaneEmissionsFromBurningOfCropResidues")
Name AgResidue_Equations_FieldBurning.VEERG_6_4_1_1__1__MethaneEmissionsFromBurningOfCropResidues_LatexEquation: _xlfn.LAMBDA("E_{CH4}=\sum_{c}(M_{burn,c}\times CC_{c}\times EF_{CH4}\times C_{CH4}\times 10^{-3})")
Name AgResidue_Equations_FieldBurning.VEERG_6_4_1_1__1__MethaneEmissionsFromBurningOfCropResidues_NIRReference: _xlfn.LAMBDA("")
Name AgResidue_Equations_FieldBurning.VEERG_6_4_1_1__1__MethaneEmissionsFromBurningOfCropResidues_Source: _xlfn.LAMBDA("VEERG 2026: 6.4.1.1, Equation (1)")
Name AgResidue_Equations_FieldBurning.VEERG_6_4_1_1__1__MethaneEmissionsFromBurningOfCropResidues_Title: _xlfn.LAMBDA("Methane emissions from the burning of crop residues")
Name AgResidue_Equations_FieldBurning.VEERG_6_4_1_1__1__MethaneEmissionsFromBurningOfCropResidues_Unit: _xlfn.LAMBDA("t CH4")
Name AgResidue_Equations_FieldBurning.VEERG_6_4_1_1__1__MethaneEmissionsFromBurningOfCropResidues_Variable: _xlfn.LAMBDA("ECH4")
Name AgResidue_Equations_FieldBurning.VEERG_6_4_1_1__2__NitrousOxideEmissionsFromBurningOfCropResidues: _xlfn.LAMBDA(_xlpm.Mburnc,_xlpm.NCAGc,_xlpm.EFN2O,_xlpm.CN2O, _xlpm.Mburnc * _xlpm.NCAGc * _xlpm.EFN2O * _xlpm.CN2O * 10 ^ (-3))
Name AgResidue_Equations_FieldBurning.VEERG_6_4_1_1__2__NitrousOxideEmissionsFromBurningOfCropResidues_FunctionName: _xlfn.LAMBDA("VEERG_6_4_1_1__2__NitrousOxideEmissionsFromBurningOfCropResidues")
Name AgResidue_Equations_FieldBurning.VEERG_6_4_1_1__2__NitrousOxideEmissionsFromBurningOfCropResidues_LatexEquation: _xlfn.LAMBDA("E_{N2O}=\sum_{c}(M_{burn,c}\times NC_{AGc}\times EF_{N2O}\times C_{N2O}\times 10^{-3})")
Name AgResidue_Equations_FieldBurning.VEERG_6_4_1_1__2__NitrousOxideEmissionsFromBurningOfCropResidues_NIRReference: _xlfn.LAMBDA("")
Name AgResidue_Equations_FieldBurning.VEERG_6_4_1_1__2__NitrousOxideEmissionsFromBurningOfCropResidues_Source: _xlfn.LAMBDA("VEERG 2026: 6.4.1.1, Equation (2)")
Name AgResidue_Equations_FieldBurning.VEERG_6_4_1_1__2__NitrousOxideEmissionsFromBurningOfCropResidues_Title: _xlfn.LAMBDA("Nitrous oxide emissions from the burning of crop residues")
Name AgResidue_Equations_FieldBurning.VEERG_6_4_1_1__2__NitrousOxideEmissionsFromBurningOfCropResidues_Unit: _xlfn.LAMBDA("t N2O")
Name AgResidue_Equations_FieldBurning.VEERG_6_4_1_1__2__NitrousOxideEmissionsFromBurningOfCropResidues_Variable: _xlfn.LAMBDA("EN2O")
Name AgResidue_Equations_FieldBurning.VEERG_6_4_1_1__3__MassOfCropResidueBurnt: _xlfn.LAMBDA(_xlpm.Pc,_xlpm.RAGc,_xlpm.Sc,_xlpm.DMc,_xlpm.Zc,_xlpm.Fc, _xlpm.Pc * _xlpm.RAGc * _xlpm.Sc * _xlpm.DMc * _xlpm.Zc * _xlpm.Fc)
Name AgResidue_Equations_FieldBurning.VEERG_6_4_1_1__3__MassOfCropResidueBurnt_FunctionName: _xlfn.LAMBDA("VEERG_6_4_1_1__3__MassOfCropResidueBurnt")
Name AgResidue_Equations_FieldBurning.VEERG_6_4_1_1__3__MassOfCropResidueBurnt_LatexEquation: _xlfn.LAMBDA("M_{burn,c}=P_{c}\times R_{AGc}\times S_{c}\times DM_{c}\times Z_{c}\times F_{c}")
Name AgResidue_Equations_FieldBurning.VEERG_6_4_1_1__3__MassOfCropResidueBurnt_NIRReference: _xlfn.LAMBDA("")
Name AgResidue_Equations_FieldBurning.VEERG_6_4_1_1__3__MassOfCropResidueBurnt_Source: _xlfn.LAMBDA("VEERG 2026: 6.4.1.1, Equation (3)")
Name AgResidue_Equations_FieldBurning.VEERG_6_4_1_1__3__MassOfCropResidueBurnt_Title: _xlfn.LAMBDA("Mass of residue of crop c burnt")
Name AgResidue_Equations_FieldBurning.VEERG_6_4_1_1__3__MassOfCropResidueBurnt_Unit: _xlfn.LAMBDA("kg")
Name AgResidue_Equations_FieldBurning.VEERG_6_4_1_1__3__MassOfCropResidueBurnt_Variable: _xlfn.LAMBDA("Mburnc")
Name AgResidues_Equations_CropResidues.VEERG_6_1_1_1__1__NitrousOxideEmissionsFromCropResidues: _xlfn.LAMBDA(_xlpm.Mc,_xlpm.EFNi,_xlpm.CgN2O, _xlpm.Mc * _xlpm.EFNi * _xlpm.CgN2O * 10 ^ (-3))
Name AgResidues_Equations_CropResidues.VEERG_6_1_1_1__1__NitrousOxideEmissionsFromCropResidues_FunctionName: _xlfn.LAMBDA("VEERG_6_1_1_1__1__NitrousOxideEmissionsFromCropResidues")
Name AgResidues_Equations_CropResidues.VEERG_6_1_1_1__1__NitrousOxideEmissionsFromCropResidues_LatexEquation: _xlfn.LAMBDA("E=\sum_{c}{M_{c}\times EF_{N}\times C_{g,N2O}\times 10^{-3}}")
Name AgResidues_Equations_CropResidues.VEERG_6_1_1_1__1__NitrousOxideEmissionsFromCropResidues_NIRReference: _xlfn.LAMBDA("")
Name AgResidues_Equations_CropResidues.VEERG_6_1_1_1__1__NitrousOxideEmissionsFromCropResidues_Source: _xlfn.LAMBDA("VEERG 2026: 6.1.1.1, Equation (1)")
Name AgResidues_Equations_CropResidues.VEERG_6_1_1_1__1__NitrousOxideEmissionsFromCropResidues_Title: _xlfn.LAMBDA("Nitrous oxide emissions from the return of crop residues across all crops c to the soil")
Name AgResidues_Equations_CropResidues.VEERG_6_1_1_1__1__NitrousOxideEmissionsFromCropResidues_Unit: _xlfn.LAMBDA("t N2O")
Name AgResidues_Equations_CropResidues.VEERG_6_1_1_1__1__NitrousOxideEmissionsFromCropResidues_Variable: _xlfn.LAMBDA("E")
Name AgResidues_Equations_CropResidues.VEERG_6_1_1_1__2__MassOfNitrogenInCropResidues_LatexEquation: _xlfn.LAMBDA("M_{c}=(P_{c}\times R_{AGc}\times(1-F_{c}-FFOD_{c})\times DM_{c}\times NC_{AGc})+(P_{c}\times R_{AGc}\times R_{BGc}\times DM_{c}\times NC_{BGc})")
Name AgResidues_Equations_CropResidues.VEERG_6_1_1_1__2__MassOfNitrogenInCropResidues_NIRReference: _xlfn.LAMBDA("")
Name AgResidues_Equations_CropResidues.VEERG_6_1_1_1__2__MassOfNitrogenInCropResidues_Source: _xlfn.LAMBDA("VEERG 2026: 6.1.1.1, Equation (2)")
Name AgResidues_Equations_CropResidues.VEERG_6_1_1_1__2__MassOfNitrogenInCropResidues_Title: _xlfn.LAMBDA("Mass of nitrogen in crop residues returned to the soil")
Name AgResidues_Equations_CropResidues.VEERG_6_1_1_1__2__MassOfNitrogenInCropResidues_Unit: _xlfn.LAMBDA("kg N")
Name AgResidues_Equations_CropResidues.VEERG_6_1_1_1__2__MassOfNitrogenInCropResidues_Variable: _xlfn.LAMBDA("Mc")
Name AgResidues_Equations_CropResidues.VEERG_6_1_1_2__1__FractionOfCropResidueRemovedBaled: _xlfn.LAMBDA(_xlpm.B,_xlpm.MB,_xlpm.Pc,_xlpm.RAGc, IFERROR((_xlpm.B * _xlpm.MB) / (_xlpm.Pc * _xlpm.RAGc), 0))
Name AgResidues_Equations_CropResidues.VEERG_6_1_1_2__1__FractionOfCropResidueRemovedBaled_LatexEquation: _xlfn.LAMBDA("FFOD_{c,baled}=\frac{B\times M_{B}}{P_{c}\times R_{AG,c}}")
Name AgResidues_Equations_CropResidues.VEERG_6_1_1_2__1__FractionOfCropResidueRemovedBaled_NIRReference: _xlfn.LAMBDA("")
Name AgResidues_Equations_CropResidues.VEERG_6_1_1_2__1__FractionOfCropResidueRemovedBaled_Source: _xlfn.LAMBDA("VEERG 2026: 6.1.1.2, Equation (1)")
Name AgResidues_Equations_CropResidues.VEERG_6_1_1_2__1__FractionOfCropResidueRemovedBaled_Title: _xlfn.LAMBDA("Fraction of crop residue that is removed for crop c, calculated where residues are baled")
Name AgResidues_Equations_CropResidues.VEERG_6_1_1_2__1__FractionOfCropResidueRemovedBaled_Unit: _xlfn.LAMBDA("dimensionless")
Name AgResidues_Equations_CropResidues.VEERG_6_1_1_2__1__FractionOfCropResidueRemovedBaled_Variable: _xlfn.LAMBDA("FFODcbaled")
Name AgResidues_Equations_CropResidues.VEERG_6_1_1_2__1__FractionOfCropResidueRemovedBaled_Variation: _xlfn.LAMBDA("VARIATION FROM SOURCE: Added 'baled' to variable subscript")
Name AgResidues_Equations_CropResidues.VEERG_6_1_1_2__1a__FractionOfCropResidueRemoved: _xlfn.LAMBDA(_xlpm.FFODcbaled,_xlpm.FFODcother, _xlpm.FFODcbaled + _xlpm.FFODcother)
Name AgResidues_Equations_CropResidues.VEERG_6_1_1_2__1a__FractionOfCropResidueRemoved_LatexEquation: _xlfn.LAMBDA("FFOD_{c} = FFOD_{c,baled} + FFOD_{c,other}")
Name AgResidues_Equations_CropResidues.VEERG_6_1_1_2__1a__FractionOfCropResidueRemoved_NIRReference: _xlfn.LAMBDA("")
Name AgResidues_Equations_CropResidues.VEERG_6_1_1_2__1a__FractionOfCropResidueRemoved_Source: _xlfn.LAMBDA("")
Name AgResidues_Equations_CropResidues.VEERG_6_1_1_2__1a__FractionOfCropResidueRemoved_Title: _xlfn.LAMBDA("Fraction of crop residue that is removed for crop c")
Name AgResidues_Equations_CropResidues.VEERG_6_1_1_2__1a__FractionOfCropResidueRemoved_Unit: _xlfn.LAMBDA("dimensionless")
Name AgResidues_Equations_CropResidues.VEERG_6_1_1_2__1a__FractionOfCropResidueRemoved_Variable: _xlfn.LAMBDA("FFODc")
Name AgResidues_Equations_CropResidues.VEERG_6_1_1_2__1a__FractionOfCropResidueRemoved_Variation: _xlfn.LAMBDA("VARIATION FROM SOURCE: Added this equation to accommodate user-defined residue removal other than baling.")
Name AgResidues_Equations_Leaching.VEERG_6_3_1_1__1__LeachingAndRunoffEmissionsCropAndPastureResidue: _xlfn.LAMBDA(_xlpm.Mleachcp,_xlpm.EFleach,_xlpm.CgN2O, _xlpm.Mleachcp * _xlpm.EFleach * _xlpm.CgN2O * 10 ^ (-3))
Name AgResidues_Equations_Leaching.VEERG_6_3_1_1__1__LeachingAndRunoffEmissionsCropAndPastureResidue_LatexEquation: _xlfn.LAMBDA("E_{N2O}=\sum_{c}\sum_{p}(M_{leach,cp}\times EF_{leach}\times Cg_{N2O}\times 10^{-3})")
Name AgResidues_Equations_Leaching.VEERG_6_3_1_1__1__LeachingAndRunoffEmissionsCropAndPastureResidue_NIRReference: _xlfn.LAMBDA("")
Name AgResidues_Equations_Leaching.VEERG_6_3_1_1__1__LeachingAndRunoffEmissionsCropAndPastureResidue_Source: _xlfn.LAMBDA("VEERG 2026: 6.3.1.1, Equation (1)")
Name AgResidues_Equations_Leaching.VEERG_6_3_1_1__1__LeachingAndRunoffEmissionsCropAndPastureResidue_Title: _xlfn.LAMBDA("Nitrous oxide leaching and runoff emissions from crop and pasture residues returned to the soil")
Name AgResidues_Equations_Leaching.VEERG_6_3_1_1__1__LeachingAndRunoffEmissionsCropAndPastureResidue_Unit: _xlfn.LAMBDA("t N2O")

Sheet Constants - Poultry
A1: #VALUE! | C1: Constants - Poultry
A3: =HYPERLINK("#'Home'!A1", "Home") -> Home
A4: =HYPERLINK("#'Overview'!A1", "Overview") -> Overview
A5: =HYPERLINK("#'Results'!A1", "Results") -> Results | D5: {=SourceData_Poultry.SourceData_Poultry_DietProperties_Title()} -> Poultry - Diet properties
D6: {=SourceData_Poultry.SourceData_Poultry_DietProperties_Source()} -> VEERG 2026: Table A.1.7.1: Poultry - Diet properties
A7: INPUTS
A8: =HYPERLINK("#'Input - Site'!A1", "Site") -> Site | D8: Nutrient analysis | E8: Layers | F8: Meat chicken growers | G8: Meat chicken breeder | H8: Meat other
A9: =HYPERLINK("#'Input - Poultry'!A1", "Poultry") -> Poultry | D9: {=Common_InputFunctions.Utility_DisplayArrayInTable(SourceData_Poultry.SourceData_Poultry_DietProperties_Data(), Table_SourceData_Poultry_DietProperties[[#Headers],[Nutrient analysis]], 0)} -> Dry matter intake (kg/head/day) | E9: {=Common_InputFunctions.Utility_DisplayArrayInTable(SourceData_Poultry.SourceData_Poultry_DietProperties_Data(), Table_SourceData_Poultry_DietProperties[[#Headers],[Nutrient analysis]], 0)} -> 0.086 | F9: {=Common_InputFunctions.Utility_DisplayArrayInTable(SourceData_Poultry.SourceData_Poultry_DietProperties_Data(), Table_SourceData_Poultry_DietProperties[[#Headers],[Nutrient analysis]], 0)} -> 0.093 | G9: {=Common_InputFunctions.Utility_DisplayArrayInTable(SourceData_Poultry.SourceData_Poultry_DietProperties_Data(), Table_SourceData_Poultry_DietProperties[[#Headers],[Nutrient analysis]], 0)} -> 0.103 | H9: {=Common_InputFunctions.Utility_DisplayArrayInTable(SourceData_Poultry.SourceData_Poultry_DietProperties_Data(), Table_SourceData_Poultry_DietProperties[[#Headers],[Nutrient analysis]], 0)} -> 0.093
D10: {=Common_InputFunctions.Utility_DisplayArrayInTable(SourceData_Poultry.SourceData_Poultry_DietProperties_Data(), Table_SourceData_Poultry_DietProperties[[#Headers],[Nutrient analysis]], 0)} -> Dry matter digestibility | E10: {=Common_InputFunctions.Utility_DisplayArrayInTable(SourceData_Poultry.SourceData_Poultry_DietProperties_Data(), Table_SourceData_Poultry_DietProperties[[#Headers],[Nutrient analysis]], 0)} -> 0.8 | F10: {=Common_InputFunctions.Utility_DisplayArrayInTable(SourceData_Poultry.SourceData_Poultry_DietProperties_Data(), Table_SourceData_Poultry_DietProperties[[#Headers],[Nutrient analysis]], 0)} -> 0.8 | G10: {=Common_InputFunctions.Utility_DisplayArrayInTable(SourceData_Poultry.SourceData_Poultry_DietProperties_Data(), Table_SourceData_Poultry_DietProperties[[#Headers],[Nutrient analysis]], 0)} -> 0.8 | H10: {=Common_InputFunctions.Utility_DisplayArrayInTable(SourceData_Poultry.SourceData_Poultry_DietProperties_Data(), Table_SourceData_Poultry_DietProperties[[#Headers],[Nutrient analysis]], 0)} -> 0.8
A11: CALCULATIONS | D11: {=Common_InputFunctions.Utility_DisplayArrayInTable(SourceData_Poultry.SourceData_Poultry_DietProperties_Data(), Table_SourceData_Poultry_DietProperties[[#Headers],[Nutrient analysis]], 0)} -> Crude protein | E11: {=Common_InputFunctions.Utility_DisplayArrayInTable(SourceData_Poultry.SourceData_Poultry_DietProperties_Data(), Table_SourceData_Poultry_DietProperties[[#Headers],[Nutrient analysis]], 0)} -> 0.19 | F11: {=Common_InputFunctions.Utility_DisplayArrayInTable(SourceData_Poultry.SourceData_Poultry_DietProperties_Data(), Table_SourceData_Poultry_DietProperties[[#Headers],[Nutrient analysis]], 0)} -> 0.23 | G11: {=Common_InputFunctions.Utility_DisplayArrayInTable(SourceData_Poultry.SourceData_Poultry_DietProperties_Data(), Table_SourceData_Poultry_DietProperties[[#Headers],[Nutrient analysis]], 0)} -> 0.19 | H11: {=Common_InputFunctions.Utility_DisplayArrayInTable(SourceData_Poultry.SourceData_Poultry_DietProperties_Data(), Table_SourceData_Poultry_DietProperties[[#Headers],[Nutrient analysis]], 0)} -> 0.23
A12: =HYPERLINK("#'4.6.1.1-2 Methane'!A1", "4.6.1.1-2 Methane") -> 4.6.1.1-2 Methane | D12: {=Common_InputFunctions.Utility_DisplayArrayInTable(SourceData_Poultry.SourceData_Poultry_DietProperties_Data(), Table_SourceData_Poultry_DietProperties[[#Headers],[Nutrient analysis]], 0)} -> Nitrogen retention rate | E12: {=Common_InputFunctions.Utility_DisplayArrayInTable(SourceData_Poultry.SourceData_Poultry_DietProperties_Data(), Table_SourceData_Poultry_DietProperties[[#Headers],[Nutrient analysis]], 0)} -> 0.35 | F12: {=Common_InputFunctions.Utility_DisplayArrayInTable(SourceData_Poultry.SourceData_Poultry_DietProperties_Data(), Table_SourceData_Poultry_DietProperties[[#Headers],[Nutrient analysis]], 0)} -> 0.47 | G12: {=Common_InputFunctions.Utility_DisplayArrayInTable(SourceData_Poultry.SourceData_Poultry_DietProperties_Data(), Table_SourceData_Poultry_DietProperties[[#Headers],[Nutrient analysis]], 0)} -> 0.32 | H12: {=Common_InputFunctions.Utility_DisplayArrayInTable(SourceData_Poultry.SourceData_Poultry_DietProperties_Data(), Table_SourceData_Poultry_DietProperties[[#Headers],[Nutrient analysis]], 0)} -> 0.47
A13: =HYPERLINK("#'4.6.1.3-4 Direct N20'!A1", "4.6.1.3-4 Direct N2O") -> 4.6.1.3-4 Direct N2O | D13: {=Common_InputFunctions.Utility_DisplayArrayInTable(SourceData_Poultry.SourceData_Poultry_DietProperties_Data(), Table_SourceData_Poultry_DietProperties[[#Headers],[Nutrient analysis]], 0)} -> Manure ash | E13: {=Common_InputFunctions.Utility_DisplayArrayInTable(SourceData_Poultry.SourceData_Poultry_DietProperties_Data(), Table_SourceData_Poultry_DietProperties[[#Headers],[Nutrient analysis]], 0)} -> 0.18 | F13: {=Common_InputFunctions.Utility_DisplayArrayInTable(SourceData_Poultry.SourceData_Poultry_DietProperties_Data(), Table_SourceData_Poultry_DietProperties[[#Headers],[Nutrient analysis]], 0)} -> 0.15 | G13: {=Common_InputFunctions.Utility_DisplayArrayInTable(SourceData_Poultry.SourceData_Poultry_DietProperties_Data(), Table_SourceData_Poultry_DietProperties[[#Headers],[Nutrient analysis]], 0)} -> 0.18 | H13: {=Common_InputFunctions.Utility_DisplayArrayInTable(SourceData_Poultry.SourceData_Poultry_DietProperties_Data(), Table_SourceData_Poultry_DietProperties[[#Headers],[Nutrient analysis]], 0)} -> 0.15
A14: =HYPERLINK("#'4.6.1.5-6 Atmos Dep'!A1", "4.6.1.5-6 Atmospheric deposition") -> 4.6.1.5-6 Atmospheric deposition
A15: =HYPERLINK("#'4.6.1.7-8 Leaching and runoff'!A1", "4.6.1.7-8 Leaching & runoff") -> 4.6.1.7-8 Leaching & runoff
A16: =HYPERLINK("#'4.6.1.9 Manure applied to soils'!A1", "4.6.1.9 Manure applied to soils") -> 4.6.1.9 Manure applied to soils
A17: =HYPERLINK("#'4.6.1.10-11 Soil direct N2O'!A1", "4.6.1.10-11 Soil direct N2O") -> 4.6.1.10-11 Soil direct N2O | D17: {=SourceData_Poultry.SourceData_Poultry_MethaneEmissionsPotential_Title()} -> Poultry - Methane emissions potential per class
A18: =HYPERLINK("#'4.6.1.12-13 Soil atmos dep'!A1", "4.6.1.12-13 Soil Atm. deposition") -> 4.6.1.12-13 Soil Atm. deposition | D18: {=SourceData_Poultry.SourceData_Poultry_MethaneEmissionsPotential_Source()} -> VEERG 2026: 4.6.2.3 CONSTANT: Poultry - Methane emissions potential per class
A19: =HYPERLINK("#'4.6.1.14-15 Soil leach runoff'!A1", "4.6.1.14-15 Soil leach & runoff") -> 4.6.1.14-15 Soil leach & runoff | D19: Poultry class | E19: B0
D20: {=Common_InputFunctions.Utility_DisplayArrayInTable(SourceData_Poultry.SourceData_Poultry_MethaneEmissionsPotential_Data(), Table_SourceData_Poultry_MethaneEmissionsPotential[[#Headers],[Poultry class]], 0)} -> Layers | E20: {=Common_InputFunctions.Utility_DisplayArrayInTable(SourceData_Poultry.SourceData_Poultry_MethaneEmissionsPotential_Data(), Table_SourceData_Poultry_MethaneEmissionsPotential[[#Headers],[Poultry class]], 0)} -> 0.39
A21: APPENDICES | D21: {=Common_InputFunctions.Utility_DisplayArrayInTable(SourceData_Poultry.SourceData_Poultry_MethaneEmissionsPotential_Data(), Table_SourceData_Poultry_MethaneEmissionsPotential[[#Headers],[Poultry class]], 0)} -> Meat chickens | E21: {=Common_InputFunctions.Utility_DisplayArrayInTable(SourceData_Poultry.SourceData_Poultry_MethaneEmissionsPotential_Data(), Table_SourceData_Poultry_MethaneEmissionsPotential[[#Headers],[Poultry class]], 0)} -> 0.36
A22: =HYPERLINK("#'Constants - Poultry'!A1", "Constants - Poultry") -> Constants - Poultry
A23: =HYPERLINK("#'Constants - Livestock'!A1", "Constants - Livestock") -> Constants - Livestock
A24: =HYPERLINK("#'Constants - Common'!A1", "Constants - Common") -> Constants - Common
D26: Poultry manure management systems | G26: Poultry manure management systems - Stage 1 | J26: Poultry manure management systems - Stage 2
D28: MMS | E28: Symbol and MMS | G28: MMS | H28: Symbol and MMS | J28: MMS | K28: Symbol and MMS
D29: Poultry manure with bedding | E29: Poultry manure with bedding (m=10) | G29: Poultry manure with bedding | H29: Poultry manure with bedding (m=10) | J29: Solid storage | K29: Solid storage (m=4)
D30: Belt manure removal | E30: Belt manure removal (m=11a) | G30: Belt manure removal | H30: Belt manure removal (m=11a) | J30: Composting (passive windrow) | K30: Composting (passive windrow) (m=6)
D31: Manure stored in house | E31: Manure stored in house (m=11b) | G31: Manure stored in house | H31: Manure stored in house (m=11b) | J31: Digester / covered lagoons | K31: Digester / covered lagoons (m=7)
D32: Pasture range and paddock | E32: Pasture range and paddock (m=14) | G32: Pasture range and paddock | H32: Pasture range and paddock (m=14) | J32: Direct processing | K32: Direct processing (m=12)
D33: Solid storage | E33: Solid storage (m=4) | G33: No MMS | H33: No MMS | J33: Direct application | K33: Direct application (m=13)
D34: Composting (passive windrow) | E34: Composting (passive windrow) (m=6) | J34: No MMS | K34: No MMS
D35: Digester / covered lagoons | E35: Digester / covered lagoons (m=7)
D36: Direct processing | E36: Direct processing (m=12)
D37: Direct application | E37: Direct application (m=13)
D38: No MMS | E38: No MMS
D42: Poultry production systems
D44: Production system
D45: {=Common_InputFunctions.Utility_DisplayArrayInTable(SourceData_Poultry.SourceData_Poultry_ProductionSystems_Data(), Table_SourceData_Poultry_ProductionSystems[[#Headers],[Production system]], 0)} -> Free range
D46: {=Common_InputFunctions.Utility_DisplayArrayInTable(SourceData_Poultry.SourceData_Poultry_ProductionSystems_Data(), Table_SourceData_Poultry_ProductionSystems[[#Headers],[Production system]], 0)} -> Barn
D47: {=Common_InputFunctions.Utility_DisplayArrayInTable(SourceData_Poultry.SourceData_Poultry_ProductionSystems_Data(), Table_SourceData_Poultry_ProductionSystems[[#Headers],[Production system]], 0)} -> Cage
...

Sheet Constants - Swine
A1: #VALUE! | C1: Constants - Swine
A3: =HYPERLINK("#'Home'!A1", "Home") -> Home
A4: =HYPERLINK("#'Overview'!A1", "Overview") -> Overview
A5: =HYPERLINK("#'Results'!A1", "Results") -> Results
D6: Swine crop or pasture production systems | G6: Irrigation methods
A7: INPUTS
A8: =HYPERLINK("#'Input - Site'!A1", "Site") -> Site | D8: Production system | G8: Irrigation method
A9: =HYPERLINK("#'Input - Swine'!A1", "Swine") -> Swine | D9: Pasture | G9: Not irrigated
D10: Crop | G10: Drip irrigation
A11: CALCULATIONS | G11: Sprinkler irrigation
A12: =HYPERLINK("#'3.5.1.1-2 Enteric Methane'!A1", "3.5.1.1-2 Enteric Methane") -> 3.5.1.1-2 Enteric Methane | G12: Surface irrigation
G13: Other irrigation
A14: APPENDICES | D14: {=SourceData_Swine.SourceData_Swine_FracLEACH_DrylotMMS_Title()} -> Fraction of nitrogen lost through leaching and runoff for drylot MMS
A15: =HYPERLINK("#'Constants - Swine'!A1", "Constants - Swine") -> Constants - Swine | D15: {=SourceData_Swine.SourceData_Swine_FracLEACH_DrylotMMS_Source()} -> VEERG 2026: 4.5.2.3 CONSTANT
A16: =HYPERLINK("#'Constants - Livestock'!A1", "Constants - Livestock") -> Constants - Livestock | D16: {=SourceData_Swine.SourceData_Swine_FracLEACH_DrylotMMS_Variation()} -> VARIATION ON SOURCE: Text refers to 'solid storage' MMS, but equation refers to 'drylot' MMS.
A17: =HYPERLINK("#'Constants - Common'!A1", "Constants - Common") -> Constants - Common | D17: {=SourceData_Swine.SourceData_Swine_FracLEACH_DrylotMMS_Variable()} -> FracLEACH_MS | E17: {=SourceData_Swine.SourceData_Swine_FracLEACH_DrylotMMS_Data()} -> 0.02 | F17: {=SourceData_Swine.SourceData_Swine_FracLEACH_DrylotMMS_Unit()} -> fraction
A18: =HYPERLINK("#'Acknowledgements'!A1", "Acknowledgements") -> Acknowledgements
D19: {=SourceData_Swine.SourceData_Swine_MethaneVolatileSolidsEmissionsPotential_Title()} -> Emissions potential of methane per kilogram of volatile solids
D20: {=SourceData_Swine.SourceData_Swine_MethaneVolatileSolidsEmissionsPotential_Source()} -> IPCC (2019), Chapter 10 [4]
D21: {=SourceData_Swine.SourceData_Swine_MethaneVolatileSolidsEmissionsPotential_Variable()} -> B0 | E21: {=SourceData_Swine.SourceData_Swine_MethaneVolatileSolidsEmissionsPotential_Data()} -> 0.19 | F21: {=SourceData_Swine.SourceData_Swine_MethaneVolatileSolidsEmissionsPotential_Unit()} -> m3 CH4 / kg VS
D24: {=SourceData_Swine.SourceData_Swine_MMS_MCFs_Title()} -> Methane conversion factor for temperature zone and manure management system. | H24: CHange title to match source
D25: {=SourceData_Swine.SourceData_Swine_MMS_MCFs_Source()} -> VEERG 2026: Table A.1.6.4: Swine - MCFs (MCFim) | H25: CHange source
D26: {=SourceData_Swine.SourceData_Swine_MMS_MCFs_Variation()} -> VARIATION ON SOURCE DATA: Added columns for ACT, split QLD and NT. Added extra column with MMS names that match NIR definitions
D28: MMS | E28: NSW | F28: ACT | G28: QLD | H28: NT | I28: SA | J28: TAS | K28: VIC | L28: WA | M28: NIR definition
D29: {=Common_InputFunctions.Utility_DisplayArrayInTable(SourceData_Swine.SourceData_Swine_MMS_MCFs_Data(),Table_SourceData_Swine_MMSMCF[[#Headers],[MMS]],0)} -> Outdoor (Dry lot) | E29: {=Common_InputFunctions.Utility_DisplayArrayInTable(SourceData_Swine.SourceData_Swine_MMS_MCFs_Data(),Table_SourceData_Swine_MMSMCF[[#Headers],[MMS]],0)} -> 0.01 | F29: {=Common_InputFunctions.Utility_DisplayArrayInTable(SourceData_Swine.SourceData_Swine_MMS_MCFs_Data(),Table_SourceData_Swine_MMSMCF[[#Headers],[MMS]],0)} -> 0.01 | G29: {=Common_InputFunctions.Utility_DisplayArrayInTable(SourceData_Swine.SourceData_Swine_MMS_MCFs_Data(),Table_SourceData_Swine_MMSMCF[[#Headers],[MMS]],0)} -> 0.03 | H29: {=Common_InputFunctions.Utility_DisplayArrayInTable(SourceData_Swine.SourceData_Swine_MMS_MCFs_Data(),Table_SourceData_Swine_MMSMCF[[#Headers],[MMS]],0)} -> 0.03 | I29: {=Common_InputFunctions.Utility_DisplayArrayInTable(SourceData_Swine.SourceData_Swine_MMS_MCFs_Data(),Table_SourceData_Swine_MMSMCF[[#Headers],[MMS]],0)} -> 0.01 | J29: {=Common_InputFunctions.Utility_DisplayArrayInTable(SourceData_Swine.SourceData_Swine_MMS_MCFs_Data(),Table_SourceData_Swine_MMSMCF[[#Headers],[MMS]],0)} -> 0.01 | K29: {=Common_InputFunctions.Utility_DisplayArrayInTable(SourceData_Swine.SourceData_Swine_MMS_MCFs_Data(),Table_SourceData_Swine_MMSMCF[[#Headers],[MMS]],0)} -> 0.01 | ... M29: {=Common_InputFunctions.Utility_DisplayArrayInTable(SourceData_Swine.SourceData_Swine_MMS_MCFs_Data(),Table_SourceData_Swine_MMSMCF[[#Headers],[MMS]],0)} -> Drylot (feed pad)
D30: {=Common_InputFunctions.Utility_DisplayArrayInTable(SourceData_Swine.SourceData_Swine_MMS_MCFs_Data(),Table_SourceData_Swine_MMSMCF[[#Headers],[MMS]],0)} -> Deep litter | E30: {=Common_InputFunctions.Utility_DisplayArrayInTable(SourceData_Swine.SourceData_Swine_MMS_MCFs_Data(),Table_SourceData_Swine_MMSMCF[[#Headers],[MMS]],0)} -> 0.04 | F30: {=Common_InputFunctions.Utility_DisplayArrayInTable(SourceData_Swine.SourceData_Swine_MMS_MCFs_Data(),Table_SourceData_Swine_MMSMCF[[#Headers],[MMS]],0)} -> 0.04 | G30: {=Common_InputFunctions.Utility_DisplayArrayInTable(SourceData_Swine.SourceData_Swine_MMS_MCFs_Data(),Table_SourceData_Swine_MMSMCF[[#Headers],[MMS]],0)} -> 0.04 | H30: {=Common_InputFunctions.Utility_DisplayArrayInTable(SourceData_Swine.SourceData_Swine_MMS_MCFs_Data(),Table_SourceData_Swine_MMSMCF[[#Headers],[MMS]],0)} -> 0.04 | I30: {=Common_InputFunctions.Utility_DisplayArrayInTable(SourceData_Swine.SourceData_Swine_MMS_MCFs_Data(),Table_SourceData_Swine_MMSMCF[[#Headers],[MMS]],0)} -> 0.04 | J30: {=Common_InputFunctions.Utility_DisplayArrayInTable(SourceData_Swine.SourceData_Swine_MMS_MCFs_Data(),Table_SourceData_Swine_MMSMCF[[#Headers],[MMS]],0)} -> 0.04 | K30: {=Common_InputFunctions.Utility_DisplayArrayInTable(SourceData_Swine.SourceData_Swine_MMS_MCFs_Data(),Table_SourceData_Swine_MMSMCF[[#Headers],[MMS]],0)} -> 0.04 | ... M30: {=Common_InputFunctions.Utility_DisplayArrayInTable(SourceData_Swine.SourceData_Swine_MMS_MCFs_Data(),Table_SourceData_Swine_MMSMCF[[#Headers],[MMS]],0)} -> Deep litter
D31: {=Common_InputFunctions.Utility_DisplayArrayInTable(SourceData_Swine.SourceData_Swine_MMS_MCFs_Data(),Table_SourceData_Swine_MMSMCF[[#Headers],[MMS]],0)} -> Stockpile (Solid storage) | E31: {=Common_InputFunctions.Utility_DisplayArrayInTable(SourceData_Swine.SourceData_Swine_MMS_MCFs_Data(),Table_SourceData_Swine_MMSMCF[[#Headers],[MMS]],0)} -> 0.02 | F31: {=Common_InputFunctions.Utility_DisplayArrayInTable(SourceData_Swine.SourceData_Swine_MMS_MCFs_Data(),Table_SourceData_Swine_MMSMCF[[#Headers],[MMS]],0)} -> 0.02 | G31: {=Common_InputFunctions.Utility_DisplayArrayInTable(SourceData_Swine.SourceData_Swine_MMS_MCFs_Data(),Table_SourceData_Swine_MMSMCF[[#Headers],[MMS]],0)} -> 0.02 | H31: {=Common_InputFunctions.Utility_DisplayArrayInTable(SourceData_Swine.SourceData_Swine_MMS_MCFs_Data(),Table_SourceData_Swine_MMSMCF[[#Headers],[MMS]],0)} -> 0.02 | I31: {=Common_InputFunctions.Utility_DisplayArrayInTable(SourceData_Swine.SourceData_Swine_MMS_MCFs_Data(),Table_SourceData_Swine_MMSMCF[[#Headers],[MMS]],0)} -> 0.02 | J31: {=Common_InputFunctions.Utility_DisplayArrayInTable(SourceData_Swine.SourceData_Swine_MMS_MCFs_Data(),Table_SourceData_Swine_MMSMCF[[#Headers],[MMS]],0)} -> 0.02 | K31: {=Common_InputFunctions.Utility_DisplayArrayInTable(SourceData_Swine.SourceData_Swine_MMS_MCFs_Data(),Table_SourceData_Swine_MMSMCF[[#Headers],[MMS]],0)} -> 0.02 | ... M31: {=Common_InputFunctions.Utility_DisplayArrayInTable(SourceData_Swine.SourceData_Swine_MMS_MCFs_Data(),Table_SourceData_Swine_MMSMCF[[#Headers],[MMS]],0)} -> Solid storage
D32: {=Common_InputFunctions.Utility_DisplayArrayInTable(SourceData_Swine.SourceData_Swine_MMS_MCFs_Data(),Table_SourceData_Swine_MMSMCF[[#Headers],[MMS]],0)} -> Effluent pond (Uncovered anaerobic lagoon) | E32: {=Common_InputFunctions.Utility_DisplayArrayInTable(SourceData_Swine.SourceData_Swine_MMS_MCFs_Data(),Table_SourceData_Swine_MMSMCF[[#Headers],[MMS]],0)} -> 0.75 | F32: {=Common_InputFunctions.Utility_DisplayArrayInTable(SourceData_Swine.SourceData_Swine_MMS_MCFs_Data(),Table_SourceData_Swine_MMSMCF[[#Headers],[MMS]],0)} -> 0.75 | G32: {=Common_InputFunctions.Utility_DisplayArrayInTable(SourceData_Swine.SourceData_Swine_MMS_MCFs_Data(),Table_SourceData_Swine_MMSMCF[[#Headers],[MMS]],0)} -> 0.78 | H32: {=Common_InputFunctions.Utility_DisplayArrayInTable(SourceData_Swine.SourceData_Swine_MMS_MCFs_Data(),Table_SourceData_Swine_MMSMCF[[#Headers],[MMS]],0)} -> 0.78 | I32: {=Common_InputFunctions.Utility_DisplayArrayInTable(SourceData_Swine.SourceData_Swine_MMS_MCFs_Data(),Table_SourceData_Swine_MMSMCF[[#Headers],[MMS]],0)} -> 0.75 | J32: {=Common_InputFunctions.Utility_DisplayArrayInTable(SourceData_Swine.SourceData_Swine_MMS_MCFs_Data(),Table_SourceData_Swine_MMSMCF[[#Headers],[MMS]],0)} -> 0.7 | K32: {=Common_InputFunctions.Utility_DisplayArrayInTable(SourceData_Swine.SourceData_Swine_MMS_MCFs_Data(),Table_SourceData_Swine_MMSMCF[[#Headers],[MMS]],0)} -> 0.74 | ... M32: {=Common_InputFunctions.Utility_DisplayArrayInTable(SourceData_Swine.SourceData_Swine_MMS_MCFs_Data(),Table_SourceData_Swine_MMSMCF[[#Headers],[MMS]],0)} -> Anaerobic lagoon
D33: {=Common_InputFunctions.Utility_DisplayArrayInTable(SourceData_Swine.SourceData_Swine_MMS_MCFs_Data(),Table_SourceData_Swine_MMSMCF[[#Headers],[MMS]],0)} -> Anaerobic digester / Covered lagoon | E33: {=Common_InputFunctions.Utility_DisplayArrayInTable(SourceData_Swine.SourceData_Swine_MMS_MCFs_Data(),Table_SourceData_Swine_MMSMCF[[#Headers],[MMS]],0)} -> 0.1 | F33: {=Common_InputFunctions.Utility_DisplayArrayInTable(SourceData_Swine.SourceData_Swine_MMS_MCFs_Data(),Table_SourceData_Swine_MMSMCF[[#Headers],[MMS]],0)} -> 0.1 | G33: {=Common_InputFunctions.Utility_DisplayArrayInTable(SourceData_Swine.SourceData_Swine_MMS_MCFs_Data(),Table_SourceData_Swine_MMSMCF[[#Headers],[MMS]],0)} -> 0.1 | H33: {=Common_InputFunctions.Utility_DisplayArrayInTable(SourceData_Swine.SourceData_Swine_MMS_MCFs_Data(),Table_SourceData_Swine_MMSMCF[[#Headers],[MMS]],0)} -> 0.1 | I33: {=Common_InputFunctions.Utility_DisplayArrayInTable(SourceData_Swine.SourceData_Swine_MMS_MCFs_Data(),Table_SourceData_Swine_MMSMCF[[#Headers],[MMS]],0)} -> 0.1 | J33: {=Common_InputFunctions.Utility_DisplayArrayInTable(SourceData_Swine.SourceData_Swine_MMS_MCFs_Data(),Table_SourceData_Swine_MMSMCF[[#Headers],[MMS]],0)} -> 0.1 | K33: {=Common_InputFunctions.Utility_DisplayArrayInTable(SourceData_Swine.SourceData_Swine_MMS_MCFs_Data(),Table_SourceData_Swine_MMSMCF[[#Headers],[MMS]],0)} -> 0.1 | ... M33: {=Common_InputFunctions.Utility_DisplayArrayInTable(SourceData_Swine.SourceData_Swine_MMS_MCFs_Data(),Table_SourceData_Swine_MMSMCF[[#Headers],[MMS]],0)} -> Digester / covered lagoons
D34: {=Common_InputFunctions.Utility_DisplayArrayInTable(SourceData_Swine.SourceData_Swine_MMS_MCFs_Data(),Table_SourceData_Swine_MMSMCF[[#Headers],[MMS]],0)} -> Short HRT tank storage < 1 month (pit storage) | E34: {=Common_InputFunctions.Utility_DisplayArrayInTable(SourceData_Swine.SourceData_Swine_MMS_MCFs_Data(),Table_SourceData_Swine_MMSMCF[[#Headers],[MMS]],0)} -> 0.03 | F34: {=Common_InputFunctions.Utility_DisplayArrayInTable(SourceData_Swine.SourceData_Swine_MMS_MCFs_Data(),Table_SourceData_Swine_MMSMCF[[#Headers],[MMS]],0)} -> 0.03 | G34: {=Common_InputFunctions.Utility_DisplayArrayInTable(SourceData_Swine.SourceData_Swine_MMS_MCFs_Data(),Table_SourceData_Swine_MMSMCF[[#Headers],[MMS]],0)} -> 0.03 | H34: {=Common_InputFunctions.Utility_DisplayArrayInTable(SourceData_Swine.SourceData_Swine_MMS_MCFs_Data(),Table_SourceData_Swine_MMSMCF[[#Headers],[MMS]],0)} -> 0.03 | I34: {=Common_InputFunctions.Utility_DisplayArrayInTable(SourceData_Swine.SourceData_Swine_MMS_MCFs_Data(),Table_SourceData_Swine_MMSMCF[[#Headers],[MMS]],0)} -> 0.03 | J34: {=Common_InputFunctions.Utility_DisplayArrayInTable(SourceData_Swine.SourceData_Swine_MMS_MCFs_Data(),Table_SourceData_Swine_MMSMCF[[#Headers],[MMS]],0)} -> 0.03 | K34: {=Common_InputFunctions.Utility_DisplayArrayInTable(SourceData_Swine.SourceData_Swine_MMS_MCFs_Data(),Table_SourceData_Swine_MMSMCF[[#Headers],[MMS]],0)} -> 0.03 | ... M34: {=Common_InputFunctions.Utility_DisplayArrayInTable(SourceData_Swine.SourceData_Swine_MMS_MCFs_Data(),Table_SourceData_Swine_MMSMCF[[#Headers],[MMS]],0)} -> Pit storage
D35: {=Common_InputFunctions.Utility_DisplayArrayInTable(SourceData_Swine.SourceData_Swine_MMS_MCFs_Data(),Table_SourceData_Swine_MMSMCF[[#Headers],[MMS]],0)} -> Direct Application to soil | E35: {=Common_InputFunctions.Utility_DisplayArrayInTable(SourceData_Swine.SourceData_Swine_MMS_MCFs_Data(),Table_SourceData_Swine_MMSMCF[[#Headers],[MMS]],0)} -> 0 | F35: {=Common_InputFunctions.Utility_DisplayArrayInTable(SourceData_Swine.SourceData_Swine_MMS_MCFs_Data(),Table_SourceData_Swine_MMSMCF[[#Headers],[MMS]],0)} -> 0 | G35: {=Common_InputFunctions.Utility_DisplayArrayInTable(SourceData_Swine.SourceData_Swine_MMS_MCFs_Data(),Table_SourceData_Swine_MMSMCF[[#Headers],[MMS]],0)} -> 0 | H35: {=Common_InputFunctions.Utility_DisplayArrayInTable(SourceData_Swine.SourceData_Swine_MMS_MCFs_Data(),Table_SourceData_Swine_MMSMCF[[#Headers],[MMS]],0)} -> 0 | I35: {=Common_InputFunctions.Utility_DisplayArrayInTable(SourceData_Swine.SourceData_Swine_MMS_MCFs_Data(),Table_SourceData_Swine_MMSMCF[[#Headers],[MMS]],0)} -> 0 | J35: {=Common_InputFunctions.Utility_DisplayArrayInTable(SourceData_Swine.SourceData_Swine_MMS_MCFs_Data(),Table_SourceData_Swine_MMSMCF[[#Headers],[MMS]],0)} -> 0 | K35: {=Common_InputFunctions.Utility_DisplayArrayInTable(SourceData_Swine.SourceData_Swine_MMS_MCFs_Data(),Table_SourceData_Swine_MMSMCF[[#Headers],[MMS]],0)} -> 0 | ... M35: {=Common_InputFunctions.Utility_DisplayArrayInTable(SourceData_Swine.SourceData_Swine_MMS_MCFs_Data(),Table_SourceData_Swine_MMSMCF[[#Headers],[MMS]],0)} -> Direct application
D38: Swine Manure management systems | G38: Swine Manure management systems excl. solid storage and direct application | K38: Swine Manure management systems excl. direct application
D40: MMS | E40: Symbol and MMS | G40: MMS | H40: Symbol and MMS | K40: MMS | L40: Symbol and MMS
D41: ='Constants - Common Livestock'!$E$7 -> Anaerobic lagoon | E41: ='Constants - Common Livestock'!$F$7 -> Anaerobic lagoon (m=1) | G41: ='Constants - Common Livestock'!$E$7 -> Anaerobic lagoon | H41: ='Constants - Common Livestock'!$F$7 -> Anaerobic lagoon (m=1) | K41: ='Constants - Common Livestock'!$E$7 -> Anaerobic lagoon | L41: ='Constants - Common Livestock'!$F$7 -> Anaerobic lagoon (m=1)
D42: ='Constants - Common Livestock'!$E$12 -> Solid storage | E42: ='Constants - Common Livestock'!$F$12 -> Solid storage (m=4) | G42: ='Constants - Common Livestock'!$E$13 -> Drylot (feed pad) | H42: ='Constants - Common Livestock'!$F$13 -> Drylot (feed pad) (m=5) | K42: ='Constants - Common Livestock'!$E$12 -> Solid storage | L42: ='Constants - Common Livestock'!$F$12 -> Solid storage (m=4)
D43: ='Constants - Common Livestock'!$E$13 -> Drylot (feed pad) | E43: ='Constants - Common Livestock'!$F$13 -> Drylot (feed pad) (m=5) | G43: ='Constants - Common Livestock'!$E$15 -> Digester / covered lagoons | H43: ='Constants - Common Livestock'!$F$15 -> Digester / covered lagoons (m=7) | K43: ='Constants - Common Livestock'!$E$13 -> Drylot (feed pad) | L43: ='Constants - Common Livestock'!$F$13 -> Drylot (feed pad) (m=5)
D44: ='Constants - Common Livestock'!$E$15 -> Digester / covered lagoons | E44: ='Constants - Common Livestock'!$F$15 -> Digester / covered lagoons (m=7) | G44: ='Constants - Common Livestock'!$E$16 -> Deep litter | H44: ='Constants - Common Livestock'!$F$16 -> Deep litter (m=8) | K44: ='Constants - Common Livestock'!$E$15 -> Digester / covered lagoons | L44: ='Constants - Common Livestock'!$F$15 -> Digester / covered lagoons (m=7)
D45: ='Constants - Common Livestock'!$E$16 -> Deep litter | E45: ='Constants - Common Livestock'!$F$16 -> Deep litter (m=8) | G45: ='Constants - Common Livestock'!$E$17 -> Pit storage | H45: ='Constants - Common Livestock'!$F$17 -> Pit storage (m=9) | K45: ='Constants - Common Livestock'!$E$16 -> Deep litter | L45: ='Constants - Common Livestock'!$F$16 -> Deep litter (m=8)
D46: ='Constants - Common Livestock'!$E$17 -> Pit storage | E46: ='Constants - Common Livestock'!$F$17 -> Pit storage (m=9) | K46: ='Constants - Common Livestock'!$E$17 -> Pit storage | L46: ='Constants - Common Livestock'!$F$17 -> Pit storage (m=9)
D47: ='Constants - Common Livestock'!$E$23 -> Direct application | E47: ='Constants - Common Livestock'!$F$23 -> Direct application (m=13)
...

Sheet Constants - Dairy
A1: #VALUE! | C1: Source Data - Dairy
D5: Dairy manure management systems | G5: Dairy crop or pasture production systems | J5: Irrigation methods
D7: MMS | E7: Symbol and MMS | G7: Production system | J7: Irrigation method
D8: ='Constants - Common Livestock'!E7 -> Anaerobic lagoon | E8: ='Constants - Common Livestock'!F7 -> Anaerobic lagoon (m=1) | G8: ='Constants - Common'!$F$187 -> Pasture | J8: Not irrigated
D9: ='Constants - Common Livestock'!E10 -> Sump and dispersal system | E9: ='Constants - Common Livestock'!F10 -> Sump and dispersal system (m=3a) | G9: ='Constants - Common'!$F$188 -> Crop | J9: Drip irrigation
D10: ='Constants - Common Livestock'!E11 -> Drains to paddock | E10: ='Constants - Common Livestock'!F11 -> Drains to paddock (m=3b) | J10: Sprinkler irrigation
D11: ='Constants - Common Livestock'!E12 -> Solid storage | E11: ='Constants - Common Livestock'!F12 -> Solid storage (m=4) | J11: Surface irrigation
J12: Other irrigation
D16: {=SourceData_Dairy.SourceData_Dairy_LiveweightCowsAndHeifers_Title()} -> Table A.1.3.1: Dairy cattle - Liveweight (kg) - Cows and Heifers (Wj)
D17: {=SourceData_Dairy.SourceData_Dairy_LiveweightCowsAndHeifers_Source()} -> VEERG 2026: Table A.1.3.1
D18: {=SourceData_Dairy.SourceData_Dairy_LiveweightCowsAndHeifers_Variable()} -> Wj
D19: {=SourceData_Dairy.SourceData_Dairy_LiveweightCowsAndHeifers_Unit()} -> kg
D20: {=SourceData_Dairy.SourceData_Dairy_LiveweightCowsAndHeifers_Variation()} -> VARIATION OF SOURCE: Excluded 'Reference', as the value is consistently 'Dairy Australia [1]' and is not used in calculation.
D21: Breed | E21: Milking cows | F21: Heifers > 1 | G21: Heifers < 1 (weaned)
D22: {=Common_InputFunctions.Utility_DisplayArrayInTable(SourceData_Dairy.SourceData_Dairy_LiveweightCowsAndHeifers_Data(), Table_SourceData_Dairy_WjCowsHeifers[[#Headers],[Breed]], 0)} -> Medium Friesian | E22: {=Common_InputFunctions.Utility_DisplayArrayInTable(SourceData_Dairy.SourceData_Dairy_LiveweightCowsAndHeifers_Data(), Table_SourceData_Dairy_WjCowsHeifers[[#Headers],[Breed]], 0)} -> 550 | F22: {=Common_InputFunctions.Utility_DisplayArrayInTable(SourceData_Dairy.SourceData_Dairy_LiveweightCowsAndHeifers_Data(), Table_SourceData_Dairy_WjCowsHeifers[[#Headers],[Breed]], 0)} -> 380 | G22: {=Common_InputFunctions.Utility_DisplayArrayInTable(SourceData_Dairy.SourceData_Dairy_LiveweightCowsAndHeifers_Data(), Table_SourceData_Dairy_WjCowsHeifers[[#Headers],[Breed]], 0)} -> 155
D23: {=Common_InputFunctions.Utility_DisplayArrayInTable(SourceData_Dairy.SourceData_Dairy_LiveweightCowsAndHeifers_Data(), Table_SourceData_Dairy_WjCowsHeifers[[#Headers],[Breed]], 0)} -> Large Friesian | E23: {=Common_InputFunctions.Utility_DisplayArrayInTable(SourceData_Dairy.SourceData_Dairy_LiveweightCowsAndHeifers_Data(), Table_SourceData_Dairy_WjCowsHeifers[[#Headers],[Breed]], 0)} -> 600 | F23: {=Common_InputFunctions.Utility_DisplayArrayInTable(SourceData_Dairy.SourceData_Dairy_LiveweightCowsAndHeifers_Data(), Table_SourceData_Dairy_WjCowsHeifers[[#Headers],[Breed]], 0)} -> 415 | G23: {=Common_InputFunctions.Utility_DisplayArrayInTable(SourceData_Dairy.SourceData_Dairy_LiveweightCowsAndHeifers_Data(), Table_SourceData_Dairy_WjCowsHeifers[[#Headers],[Breed]], 0)} -> 170
D24: {=Common_InputFunctions.Utility_DisplayArrayInTable(SourceData_Dairy.SourceData_Dairy_LiveweightCowsAndHeifers_Data(), Table_SourceData_Dairy_WjCowsHeifers[[#Headers],[Breed]], 0)} -> Holstein-Friesian | E24: {=Common_InputFunctions.Utility_DisplayArrayInTable(SourceData_Dairy.SourceData_Dairy_LiveweightCowsAndHeifers_Data(), Table_SourceData_Dairy_WjCowsHeifers[[#Headers],[Breed]], 0)} -> 650 | F24: {=Common_InputFunctions.Utility_DisplayArrayInTable(SourceData_Dairy.SourceData_Dairy_LiveweightCowsAndHeifers_Data(), Table_SourceData_Dairy_WjCowsHeifers[[#Headers],[Breed]], 0)} -> 450 | G24: {=Common_InputFunctions.Utility_DisplayArrayInTable(SourceData_Dairy.SourceData_Dairy_LiveweightCowsAndHeifers_Data(), Table_SourceData_Dairy_WjCowsHeifers[[#Headers],[Breed]], 0)} -> 185
D25: {=Common_InputFunctions.Utility_DisplayArrayInTable(SourceData_Dairy.SourceData_Dairy_LiveweightCowsAndHeifers_Data(), Table_SourceData_Dairy_WjCowsHeifers[[#Headers],[Breed]], 0)} -> Friesian crossbred | E25: {=Common_InputFunctions.Utility_DisplayArrayInTable(SourceData_Dairy.SourceData_Dairy_LiveweightCowsAndHeifers_Data(), Table_SourceData_Dairy_WjCowsHeifers[[#Headers],[Breed]], 0)} -> 500 | F25: {=Common_InputFunctions.Utility_DisplayArrayInTable(SourceData_Dairy.SourceData_Dairy_LiveweightCowsAndHeifers_Data(), Table_SourceData_Dairy_WjCowsHeifers[[#Headers],[Breed]], 0)} -> 350 | G25: {=Common_InputFunctions.Utility_DisplayArrayInTable(SourceData_Dairy.SourceData_Dairy_LiveweightCowsAndHeifers_Data(), Table_SourceData_Dairy_WjCowsHeifers[[#Headers],[Breed]], 0)} -> 145
D26: {=Common_InputFunctions.Utility_DisplayArrayInTable(SourceData_Dairy.SourceData_Dairy_LiveweightCowsAndHeifers_Data(), Table_SourceData_Dairy_WjCowsHeifers[[#Headers],[Breed]], 0)} -> Jersey | E26: {=Common_InputFunctions.Utility_DisplayArrayInTable(SourceData_Dairy.SourceData_Dairy_LiveweightCowsAndHeifers_Data(), Table_SourceData_Dairy_WjCowsHeifers[[#Headers],[Breed]], 0)} -> 400 | F26: {=Common_InputFunctions.Utility_DisplayArrayInTable(SourceData_Dairy.SourceData_Dairy_LiveweightCowsAndHeifers_Data(), Table_SourceData_Dairy_WjCowsHeifers[[#Headers],[Breed]], 0)} -> 275 | G26: {=Common_InputFunctions.Utility_DisplayArrayInTable(SourceData_Dairy.SourceData_Dairy_LiveweightCowsAndHeifers_Data(), Table_SourceData_Dairy_WjCowsHeifers[[#Headers],[Breed]], 0)} -> 115
D27: {=Common_InputFunctions.Utility_DisplayArrayInTable(SourceData_Dairy.SourceData_Dairy_LiveweightCowsAndHeifers_Data(), Table_SourceData_Dairy_WjCowsHeifers[[#Headers],[Breed]], 0)} -> Jersey crossbred | E27: {=Common_InputFunctions.Utility_DisplayArrayInTable(SourceData_Dairy.SourceData_Dairy_LiveweightCowsAndHeifers_Data(), Table_SourceData_Dairy_WjCowsHeifers[[#Headers],[Breed]], 0)} -> 450 | F27: {=Common_InputFunctions.Utility_DisplayArrayInTable(SourceData_Dairy.SourceData_Dairy_LiveweightCowsAndHeifers_Data(), Table_SourceData_Dairy_WjCowsHeifers[[#Headers],[Breed]], 0)} -> 315 | G27: {=Common_InputFunctions.Utility_DisplayArrayInTable(SourceData_Dairy.SourceData_Dairy_LiveweightCowsAndHeifers_Data(), Table_SourceData_Dairy_WjCowsHeifers[[#Headers],[Breed]], 0)} -> 130
D28: {=Common_InputFunctions.Utility_DisplayArrayInTable(SourceData_Dairy.SourceData_Dairy_LiveweightCowsAndHeifers_Data(), Table_SourceData_Dairy_WjCowsHeifers[[#Headers],[Breed]], 0)} -> Ayrshire | E28: {=Common_InputFunctions.Utility_DisplayArrayInTable(SourceData_Dairy.SourceData_Dairy_LiveweightCowsAndHeifers_Data(), Table_SourceData_Dairy_WjCowsHeifers[[#Headers],[Breed]], 0)} -> 540 | F28: {=Common_InputFunctions.Utility_DisplayArrayInTable(SourceData_Dairy.SourceData_Dairy_LiveweightCowsAndHeifers_Data(), Table_SourceData_Dairy_WjCowsHeifers[[#Headers],[Breed]], 0)} -> 375 | G28: {=Common_InputFunctions.Utility_DisplayArrayInTable(SourceData_Dairy.SourceData_Dairy_LiveweightCowsAndHeifers_Data(), Table_SourceData_Dairy_WjCowsHeifers[[#Headers],[Breed]], 0)} -> 150
D29: {=Common_InputFunctions.Utility_DisplayArrayInTable(SourceData_Dairy.SourceData_Dairy_LiveweightCowsAndHeifers_Data(), Table_SourceData_Dairy_WjCowsHeifers[[#Headers],[Breed]], 0)} -> Guernsey | E29: {=Common_InputFunctions.Utility_DisplayArrayInTable(SourceData_Dairy.SourceData_Dairy_LiveweightCowsAndHeifers_Data(), Table_SourceData_Dairy_WjCowsHeifers[[#Headers],[Breed]], 0)} -> 480 | F29: {=Common_InputFunctions.Utility_DisplayArrayInTable(SourceData_Dairy.SourceData_Dairy_LiveweightCowsAndHeifers_Data(), Table_SourceData_Dairy_WjCowsHeifers[[#Headers],[Breed]], 0)} -> 335 | G29: {=Common_InputFunctions.Utility_DisplayArrayInTable(SourceData_Dairy.SourceData_Dairy_LiveweightCowsAndHeifers_Data(), Table_SourceData_Dairy_WjCowsHeifers[[#Headers],[Breed]], 0)} -> 140
D30: {=Common_InputFunctions.Utility_DisplayArrayInTable(SourceData_Dairy.SourceData_Dairy_LiveweightCowsAndHeifers_Data(), Table_SourceData_Dairy_WjCowsHeifers[[#Headers],[Breed]], 0)} -> Brown Swiss | E30: {=Common_InputFunctions.Utility_DisplayArrayInTable(SourceData_Dairy.SourceData_Dairy_LiveweightCowsAndHeifers_Data(), Table_SourceData_Dairy_WjCowsHeifers[[#Headers],[Breed]], 0)} -> 600 | F30: {=Common_InputFunctions.Utility_DisplayArrayInTable(SourceData_Dairy.SourceData_Dairy_LiveweightCowsAndHeifers_Data(), Table_SourceData_Dairy_WjCowsHeifers[[#Headers],[Breed]], 0)} -> 415 | G30: {=Common_InputFunctions.Utility_DisplayArrayInTable(SourceData_Dairy.SourceData_Dairy_LiveweightCowsAndHeifers_Data(), Table_SourceData_Dairy_WjCowsHeifers[[#Headers],[Breed]], 0)} -> 170
D31: {=Common_InputFunctions.Utility_DisplayArrayInTable(SourceData_Dairy.SourceData_Dairy_LiveweightCowsAndHeifers_Data(), Table_SourceData_Dairy_WjCowsHeifers[[#Headers],[Breed]], 0)} -> Illawarra/Aussie Red | E31: {=Common_InputFunctions.Utility_DisplayArrayInTable(SourceData_Dairy.SourceData_Dairy_LiveweightCowsAndHeifers_Data(), Table_SourceData_Dairy_WjCowsHeifers[[#Headers],[Breed]], 0)} -> 550 | F31: {=Common_InputFunctions.Utility_DisplayArrayInTable(SourceData_Dairy.SourceData_Dairy_LiveweightCowsAndHeifers_Data(), Table_SourceData_Dairy_WjCowsHeifers[[#Headers],[Breed]], 0)} -> 375 | G31: {=Common_InputFunctions.Utility_DisplayArrayInTable(SourceData_Dairy.SourceData_Dairy_LiveweightCowsAndHeifers_Data(), Table_SourceData_Dairy_WjCowsHeifers[[#Headers],[Breed]], 0)} -> 150
D34: {=SourceData_Dairy.SourceData_Dairy_LiveweightBulls_Title()} -> Table A.1.3.2: Dairy cattle - Liveweight (kg) - Bulls (Wj)
D35: {=SourceData_Dairy.SourceData_Dairy_LiveweightBulls_Source()} -> VEERG 2026: Table A.1.3.2
D36: {=SourceData_Dairy.SourceData_Dairy_LiveweightBulls_Variable()} -> Wj
D37: {=SourceData_Dairy.SourceData_Dairy_LiveweightBulls_Unit()} -> kg
D38: Breed | E38: Bulls > 1 | F38: Bulls < 1 (weaned)
D39: {=Common_InputFunctions.Utility_DisplayArrayInTable(SourceData_Dairy.SourceData_Dairy_LiveweightBulls_Data(), Table_SourceData_Dairy_WjBulls[[#Headers],[Breed]], 0)} -> All breeds | E39: {=Common_InputFunctions.Utility_DisplayArrayInTable(SourceData_Dairy.SourceData_Dairy_LiveweightBulls_Data(), Table_SourceData_Dairy_WjBulls[[#Headers],[Breed]], 0)} -> 600 | F39: {=Common_InputFunctions.Utility_DisplayArrayInTable(SourceData_Dairy.SourceData_Dairy_LiveweightBulls_Data(), Table_SourceData_Dairy_WjBulls[[#Headers],[Breed]], 0)} -> 225
D42: {=SourceData_Dairy.SourceData_Dairy_LiveweightGain_Title()} -> Table A.1.3.3: Dairy cattle - Liveweight gain (kg) (LWGj)
D43: {=SourceData_Dairy.SourceData_Dairy_LiveweightGain_Source()} -> VEERG 2026: Table A.1.3.3
D44: {=SourceData_Dairy.SourceData_Dairy_LiveweightGain_Variable()} -> LWGj
D45: {=SourceData_Dairy.SourceData_Dairy_LiveweightGain_Unit()} -> kg
D46: Milking cows | E46: Heifers > 1 | F46: Heifers < 1 (weaned) | G46: Bulls > 1 | H46: Bulls < 1 (weaned)
D47: {=Common_InputFunctions.Utility_DisplayArrayInTable(SourceData_Dairy.SourceData_Dairy_LiveweightGain_Data(), Table_SourceData_Dairy_LWGj[[#Headers],[Milking cows]], 0)} -> 0.016 | E47: {=Common_InputFunctions.Utility_DisplayArrayInTable(SourceData_Dairy.SourceData_Dairy_LiveweightGain_Data(), Table_SourceData_Dairy_LWGj[[#Headers],[Milking cows]], 0)} -> 0.6 | F47: {=Common_InputFunctions.Utility_DisplayArrayInTable(SourceData_Dairy.SourceData_Dairy_LiveweightGain_Data(), Table_SourceData_Dairy_LWGj[[#Headers],[Milking cows]], 0)} -> 0.57 | G47: {=Common_InputFunctions.Utility_DisplayArrayInTable(SourceData_Dairy.SourceData_Dairy_LiveweightGain_Data(), Table_SourceData_Dairy_LWGj[[#Headers],[Milking cows]], 0)} -> 0.1 | H47: {=Common_InputFunctions.Utility_DisplayArrayInTable(SourceData_Dairy.SourceData_Dairy_LiveweightGain_Data(), Table_SourceData_Dairy_LWGj[[#Headers],[Milking cows]], 0)} -> 0.8
D50: {=SourceData_Dairy.SourceData_Dairy_ReferenceWeights_Title()} -> Table A.1.3.4: Dairy cattle - Reference weights (kg) (WRj)
D51: {=SourceData_Dairy.SourceData_Dairy_ReferenceWeights_Source()} -> VEERG 2026: Table A.1.3.4
D52: {=SourceData_Dairy.SourceData_Dairy_ReferenceWeights_Variable()} -> WRj
D53: {=SourceData_Dairy.SourceData_Dairy_ReferenceWeights_Unit()} -> kg
...

Sheet Constants - Pasture Beef
A1: #VALUE! | C1: Constants - Pasture Beef
A3: =HYPERLINK("#'Home'!A1", "Home") -> Home
A4: =HYPERLINK("#'Results'!A1", "Results") -> Results
D5: Pasture beefcrop or pasture production systems | G5: Irrigation methods | M5: Table_SourceData_PastureBeef_Region_WesternAustralia | O5: Table_SourceData_PastureBeef_Region_Queensland | Q5: Table_SourceData_PastureBeef_Region_NorthernTerritory | S5: Table_SourceData_PastureBeef_Region_Victoria
A6: INPUTS
A7: =HYPERLINK("#'Input - Site'!A1", "Site") -> Site | D7: Production system | G7: Irrigation method | M7: Region | O7: Region | Q7: Region | S7: Region
A8: =HYPERLINK("#'Input - Pasture Beef'!A1", "Pasture Beef") -> Pasture Beef | D8: ='Constants - Common'!$F$187 -> Pasture | G8: Not irrigated | M8: South West | O8: Alice Springs | Q8: High | S8: n/a
D9: ='Constants - Common'!$F$188 -> Crop | G9: Drip irrigation | M9: Pilbara | O9: Barkly | Q9: Moderate/High
A10: CALCULATIONS | G10: Sprinkler irrigation | M10: Kimberley | O10: Northern | Q10: Moderate/Low | S10: Table_SourceData_PastureBeef_Region_NewSouthWales
A11: =HYPERLINK("#'3.2.1.1-2 Enteric Methane'!A1", "3.2.1.1-2 Enteric Methane") -> 3.2.1.1-2 Enteric Methane | G11: Surface irrigation | Q11: Low
G12: Other irrigation | S12: Region
A13: APPENDICES | S13: n/a
A14: =HYPERLINK("#'Constants - Pasture Beef'!A1", "Constants - Pasture Beef") -> Constants - Pasture Beef | D14: {=SourceData_PastureBeef.SourceData_PastureBeef_Liveweight_Title()} -> Beef pasture cattle - Liveweight (kg) (Wjkl)
A15: =HYPERLINK("#'Constants - Livestock'!A1", "Constants - Livestock") -> Constants - Livestock | D15: {=SourceData_PastureBeef.SourceData_PastureBeef_Liveweight_Source()} -> VEERG 2026: Table A.1.2.1 | S15: Table_SourceData_PastureBeef_Region_SouthAustralia
A16: =HYPERLINK("#'Constants - Common'!A1", "Constants - Common") -> Constants - Common | D16: {=SourceData_PastureBeef.SourceData_PastureBeef_Liveweight_Variable()} -> Wjkl
A17: =HYPERLINK("#'Acknowledgements'!A1", "Acknowledgements") -> Acknowledgements | D17: {=SourceData_PastureBeef.SourceData_PastureBeef_Liveweight_Unit()} -> kg | S17: Region
D18: State | E18: Region | F18: Season | G18: Bull < 1 | H18: Bull > 1 | I18: Cow < 1 | J18: Cow 1-2 | K18: Cow > 2 | L18: Steer < 1 | M18: Steer > 1 | S18: n/a
D19: {=Common_InputFunctions.Utility_DisplayArrayInTable(SourceData_PastureBeef.SourceData_PastureBeef_Liveweight_Data(), Table_SourceData_PastureBeef_Liveweight[[#Headers],[State]], 0)} -> ACT/NSW | E19: {=Common_InputFunctions.Utility_DisplayArrayInTable(SourceData_PastureBeef.SourceData_PastureBeef_Liveweight_Data(), Table_SourceData_PastureBeef_Liveweight[[#Headers],[State]], 0)} -> n/a | F19: {=Common_InputFunctions.Utility_DisplayArrayInTable(SourceData_PastureBeef.SourceData_PastureBeef_Liveweight_Data(), Table_SourceData_PastureBeef_Liveweight[[#Headers],[State]], 0)} -> Spring | G19: {=Common_InputFunctions.Utility_DisplayArrayInTable(SourceData_PastureBeef.SourceData_PastureBeef_Liveweight_Data(), Table_SourceData_PastureBeef_Liveweight[[#Headers],[State]], 0)} -> 80 | H19: {=Common_InputFunctions.Utility_DisplayArrayInTable(SourceData_PastureBeef.SourceData_PastureBeef_Liveweight_Data(), Table_SourceData_PastureBeef_Liveweight[[#Headers],[State]], 0)} -> 480 | I19: {=Common_InputFunctions.Utility_DisplayArrayInTable(SourceData_PastureBeef.SourceData_PastureBeef_Liveweight_Data(), Table_SourceData_PastureBeef_Liveweight[[#Headers],[State]], 0)} -> 75 | J19: {=Common_InputFunctions.Utility_DisplayArrayInTable(SourceData_PastureBeef.SourceData_PastureBeef_Liveweight_Data(), Table_SourceData_PastureBeef_Liveweight[[#Headers],[State]], 0)} -> 300 | K19: {=Common_InputFunctions.Utility_DisplayArrayInTable(SourceData_PastureBeef.SourceData_PastureBeef_Liveweight_Data(), Table_SourceData_PastureBeef_Liveweight[[#Headers],[State]], 0)} -> 440 | ... M19: {=Common_InputFunctions.Utility_DisplayArrayInTable(SourceData_PastureBeef.SourceData_PastureBeef_Liveweight_Data(), Table_SourceData_PastureBeef_Liveweight[[#Headers],[State]], 0)} -> 380
D20: {=Common_InputFunctions.Utility_DisplayArrayInTable(SourceData_PastureBeef.SourceData_PastureBeef_Liveweight_Data(), Table_SourceData_PastureBeef_Liveweight[[#Headers],[State]], 0)} -> ACT/NSW | E20: {=Common_InputFunctions.Utility_DisplayArrayInTable(SourceData_PastureBeef.SourceData_PastureBeef_Liveweight_Data(), Table_SourceData_PastureBeef_Liveweight[[#Headers],[State]], 0)} -> n/a | F20: {=Common_InputFunctions.Utility_DisplayArrayInTable(SourceData_PastureBeef.SourceData_PastureBeef_Liveweight_Data(), Table_SourceData_PastureBeef_Liveweight[[#Headers],[State]], 0)} -> Summer | G20: {=Common_InputFunctions.Utility_DisplayArrayInTable(SourceData_PastureBeef.SourceData_PastureBeef_Liveweight_Data(), Table_SourceData_PastureBeef_Liveweight[[#Headers],[State]], 0)} -> 170 | H20: {=Common_InputFunctions.Utility_DisplayArrayInTable(SourceData_PastureBeef.SourceData_PastureBeef_Liveweight_Data(), Table_SourceData_PastureBeef_Liveweight[[#Headers],[State]], 0)} -> 520 | I20: {=Common_InputFunctions.Utility_DisplayArrayInTable(SourceData_PastureBeef.SourceData_PastureBeef_Liveweight_Data(), Table_SourceData_PastureBeef_Liveweight[[#Headers],[State]], 0)} -> 160 | J20: {=Common_InputFunctions.Utility_DisplayArrayInTable(SourceData_PastureBeef.SourceData_PastureBeef_Liveweight_Data(), Table_SourceData_PastureBeef_Liveweight[[#Headers],[State]], 0)} -> 360 | K20: {=Common_InputFunctions.Utility_DisplayArrayInTable(SourceData_PastureBeef.SourceData_PastureBeef_Liveweight_Data(), Table_SourceData_PastureBeef_Liveweight[[#Headers],[State]], 0)} -> 470 | ... M20: {=Common_InputFunctions.Utility_DisplayArrayInTable(SourceData_PastureBeef.SourceData_PastureBeef_Liveweight_Data(), Table_SourceData_PastureBeef_Liveweight[[#Headers],[State]], 0)} -> 420 | S20: Table_SourceData_PastureBeef_Region_Tasmania
D21: {=Common_InputFunctions.Utility_DisplayArrayInTable(SourceData_PastureBeef.SourceData_PastureBeef_Liveweight_Data(), Table_SourceData_PastureBeef_Liveweight[[#Headers],[State]], 0)} -> ACT/NSW | E21: {=Common_InputFunctions.Utility_DisplayArrayInTable(SourceData_PastureBeef.SourceData_PastureBeef_Liveweight_Data(), Table_SourceData_PastureBeef_Liveweight[[#Headers],[State]], 0)} -> n/a | F21: {=Common_InputFunctions.Utility_DisplayArrayInTable(SourceData_PastureBeef.SourceData_PastureBeef_Liveweight_Data(), Table_SourceData_PastureBeef_Liveweight[[#Headers],[State]], 0)} -> Autumn | G21: {=Common_InputFunctions.Utility_DisplayArrayInTable(SourceData_PastureBeef.SourceData_PastureBeef_Liveweight_Data(), Table_SourceData_PastureBeef_Liveweight[[#Headers],[State]], 0)} -> 240 | H21: {=Common_InputFunctions.Utility_DisplayArrayInTable(SourceData_PastureBeef.SourceData_PastureBeef_Liveweight_Data(), Table_SourceData_PastureBeef_Liveweight[[#Headers],[State]], 0)} -> 550 | I21: {=Common_InputFunctions.Utility_DisplayArrayInTable(SourceData_PastureBeef.SourceData_PastureBeef_Liveweight_Data(), Table_SourceData_PastureBeef_Liveweight[[#Headers],[State]], 0)} -> 220 | J21: {=Common_InputFunctions.Utility_DisplayArrayInTable(SourceData_PastureBeef.SourceData_PastureBeef_Liveweight_Data(), Table_SourceData_PastureBeef_Liveweight[[#Headers],[State]], 0)} -> 390 | K21: {=Common_InputFunctions.Utility_DisplayArrayInTable(SourceData_PastureBeef.SourceData_PastureBeef_Liveweight_Data(), Table_SourceData_PastureBeef_Liveweight[[#Headers],[State]], 0)} -> 490 | ... M21: {=Common_InputFunctions.Utility_DisplayArrayInTable(SourceData_PastureBeef.SourceData_PastureBeef_Liveweight_Data(), Table_SourceData_PastureBeef_Liveweight[[#Headers],[State]], 0)} -> 450
D22: {=Common_InputFunctions.Utility_DisplayArrayInTable(SourceData_PastureBeef.SourceData_PastureBeef_Liveweight_Data(), Table_SourceData_PastureBeef_Liveweight[[#Headers],[State]], 0)} -> ACT/NSW | E22: {=Common_InputFunctions.Utility_DisplayArrayInTable(SourceData_PastureBeef.SourceData_PastureBeef_Liveweight_Data(), Table_SourceData_PastureBeef_Liveweight[[#Headers],[State]], 0)} -> n/a | F22: {=Common_InputFunctions.Utility_DisplayArrayInTable(SourceData_PastureBeef.SourceData_PastureBeef_Liveweight_Data(), Table_SourceData_PastureBeef_Liveweight[[#Headers],[State]], 0)} -> Winter | G22: {=Common_InputFunctions.Utility_DisplayArrayInTable(SourceData_PastureBeef.SourceData_PastureBeef_Liveweight_Data(), Table_SourceData_PastureBeef_Liveweight[[#Headers],[State]], 0)} -> 280 | H22: {=Common_InputFunctions.Utility_DisplayArrayInTable(SourceData_PastureBeef.SourceData_PastureBeef_Liveweight_Data(), Table_SourceData_PastureBeef_Liveweight[[#Headers],[State]], 0)} -> 560 | I22: {=Common_InputFunctions.Utility_DisplayArrayInTable(SourceData_PastureBeef.SourceData_PastureBeef_Liveweight_Data(), Table_SourceData_PastureBeef_Liveweight[[#Headers],[State]], 0)} -> 260 | J22: {=Common_InputFunctions.Utility_DisplayArrayInTable(SourceData_PastureBeef.SourceData_PastureBeef_Liveweight_Data(), Table_SourceData_PastureBeef_Liveweight[[#Headers],[State]], 0)} -> 410 | K22: {=Common_InputFunctions.Utility_DisplayArrayInTable(SourceData_PastureBeef.SourceData_PastureBeef_Liveweight_Data(), Table_SourceData_PastureBeef_Liveweight[[#Headers],[State]], 0)} -> 500 | ... M22: {=Common_InputFunctions.Utility_DisplayArrayInTable(SourceData_PastureBeef.SourceData_PastureBeef_Liveweight_Data(), Table_SourceData_PastureBeef_Liveweight[[#Headers],[State]], 0)} -> 460 | S22: Region
