Workbook
Name _Toc225350871: '5.4.1.1-4 Atmos deposition'!$C$1
Name _Toc225350871: '5.5.1.1-2 Leaching and runoff'!$C$1
Name Common_Equations.Common_ConvertCH4ToCO2e: _xlfn.LAMBDA(_xlpm.E_CH4,_xlpm.GWP_CH4, _xlpm.E_CH4 * _xlpm.GWP_CH4)
Name Common_Equations.Common_ConvertCH4ToCO2e: _xlfn.LAMBDA(_xlpm.E_CH4,_xlpm.GWP_CH4, _xlpm.E_CH4 * _xlpm.GWP_CH4)
Name Common_Equations.Common_ConvertCH4ToCO2e: _xlfn.LAMBDA(_xlpm.E_CH4,_xlpm.GWP_CH4, _xlpm.E_CH4 * _xlpm.GWP_CH4)
Name Common_Equations.Common_ConvertCH4ToCO2e_Arguments: _xlfn.LAMBDA(_xlfn.MAKEARRAY(2, 2, _xlfn.LAMBDA(_xlpm.r,_xlpm.c, INDEX({"ECH4","Methane emissions (t CH4)";"GWPCH4","Global warming potential for methane (t CO2-e / t CH4)"}, _xlpm.r, _xlpm.c))))
Name Common_Equations.Common_ConvertCH4ToCO2e_Arguments: _xlfn.LAMBDA(_xlfn.MAKEARRAY(2, 2, _xlfn.LAMBDA(_xlpm.r,_xlpm.c, INDEX({"ECH4","Methane emissions (t CH4)";"GWPCH4","Global warming potential for methane (t CO2-e / t CH4)"}, _xlpm.r, _xlpm.c))))
Name Common_Equations.Common_ConvertCH4ToCO2e_Arguments: _xlfn.LAMBDA(_xlfn.MAKEARRAY(2, 2, _xlfn.LAMBDA(_xlpm.r,_xlpm.c, INDEX({"ECH4","Methane emissions (t CH4)";"GWPCH4","Global warming potential for methane (t CO2-e / t CH4)"}, _xlpm.r, _xlpm.c))))
Name Common_Equations.Common_ConvertCH4ToCO2e_LatexEquation: _xlfn.LAMBDA("CO2_e = E_{CH4} \times GWP_{CH4}")
Name Common_Equations.Common_ConvertCH4ToCO2e_NIRReference: _xlfn.LAMBDA("")
Name Common_Equations.Common_ConvertCH4ToCO2e_Title: _xlfn.LAMBDA("Convert methane emissions to carbon dioxide equivalent emissions")
Name Common_Equations.Common_ConvertCH4ToCO2e_Unit: _xlfn.LAMBDA("t CO2e")
Name Common_Equations.Common_ConvertCH4ToCO2e_Variable: _xlfn.LAMBDA("ECH4 CO2e")
Name Common_Equations.Common_ConvertN2OToCO2e: _xlfn.LAMBDA(_xlpm.E_N2O,_xlpm.GWP_N2O, _xlpm.E_N2O * _xlpm.GWP_N2O)
Name Common_Equations.Common_ConvertN2OToCO2e: _xlfn.LAMBDA(_xlpm.E_N2O,_xlpm.GWP_N2O, _xlpm.E_N2O * _xlpm.GWP_N2O)
Name Common_Equations.Common_ConvertN2OToCO2e: _xlfn.LAMBDA(_xlpm.E_N2O,_xlpm.GWP_N2O, _xlpm.E_N2O * _xlpm.GWP_N2O)
Name Common_Equations.Common_ConvertN2OToCO2e_LatexEquation: _xlfn.LAMBDA("CO2_e = E_{N2O} \times GWP_{N2O}")
Name Common_Equations.Common_ConvertN2OToCO2e_NIRReference: _xlfn.LAMBDA("")
Name Common_Equations.Common_ConvertN2OToCO2e_Title: _xlfn.LAMBDA("Convert nitrous oxide emissions to carbon dioxide equivalent emissions")
Name Common_Equations.Common_ConvertN2OToCO2e_Unit: _xlfn.LAMBDA("t CO2e")
Name Common_Equations.Common_ConvertN2OToCO2e_Variable: _xlfn.LAMBDA("EN2O CO2e")
Name Common_InputFunctions.Utility_ConvertStateCommonNameToAbbreviation: _xlfn.LAMBDA(_xlpm.StateCommonName,_xlpm.StateCommonNameArray,_xlpm.StateAbbreviationArray, _xlfn.XLOOKUP(_xlpm.StateCommonName, _xlpm.StateCommonNameArray, _xlpm.StateAbbreviationArray, ""))
Name Common_InputFunctions.Utility_ConvertStateCommonNameToAbbreviation: _xlfn.LAMBDA(_xlpm.StateCommonName,_xlpm.StateCommonNameArray,_xlpm.StateAbbreviationArray, _xlfn.XLOOKUP(_xlpm.StateCommonName, _xlpm.StateCommonNameArray, _xlpm.StateAbbreviationArray, ""))
Name Common_InputFunctions.Utility_ConvertStateCommonNameToAbbreviation: _xlfn.LAMBDA(_xlpm.StateCommonName,_xlpm.StateCommonNameArray,_xlpm.StateAbbreviationArray, _xlfn.XLOOKUP(_xlpm.StateCommonName, _xlpm.StateCommonNameArray, _xlpm.StateAbbreviationArray, ""))
Name Common_InputFunctions.Utility_DisplayArguments_1_2: _xlfn.LAMBDA(_xlpm.ArgumentsArray, _xlfn.CHOOSECOLS(_xlpm.ArgumentsArray, 1, 2))
Name Common_InputFunctions.Utility_DisplayArguments_1_2: _xlfn.LAMBDA(_xlpm.ArgumentsArray, _xlfn.CHOOSECOLS(_xlpm.ArgumentsArray, 1, 2))
Name Common_InputFunctions.Utility_DisplayArguments_1_2: _xlfn.LAMBDA(_xlpm.ArgumentsArray, _xlfn.CHOOSECOLS(_xlpm.ArgumentsArray, 1, 2))
Name Common_InputFunctions.Utility_DisplayArguments_3_4: _xlfn.LAMBDA(_xlpm.ArgumentsArray, _xlfn.CHOOSECOLS(_xlpm.ArgumentsArray, 3, 4))
Name Common_InputFunctions.Utility_DisplayArguments_3_4: _xlfn.LAMBDA(_xlpm.ArgumentsArray, _xlfn.CHOOSECOLS(_xlpm.ArgumentsArray, 3, 4))
Name Common_InputFunctions.Utility_DisplayArguments_3_4: _xlfn.LAMBDA(_xlpm.ArgumentsArray, _xlfn.CHOOSECOLS(_xlpm.ArgumentsArray, 3, 4))
Name Common_InputFunctions.Utility_DisplayFunctionName: _xlfn.LAMBDA(_xlpm.Function, _xlfn.TEXTBEFORE(_xlfn.FORMULATEXT(_xlpm.Function), "("))
Name Common_InputFunctions.Utility_DisplayFunctionName: _xlfn.LAMBDA(_xlpm.Function, _xlfn.TEXTBEFORE(_xlfn.FORMULATEXT(_xlpm.Function), "("))
Name Common_InputFunctions.Utility_DisplayFunctionName: _xlfn.LAMBDA(_xlpm.Function, _xlfn.TEXTBEFORE(_xlfn.FORMULATEXT(_xlpm.Function), "("))
Name Common_InputFunctions.Utility_GetArrayTableColumnStartNumber: _xlfn.LAMBDA(_xlpm.TableHeaderCell, COLUMN(_xlpm.TableHeaderCell))
Name Common_InputFunctions.Utility_GetArrayTableColumnStartNumber: _xlfn.LAMBDA(_xlpm.TableHeaderCell, COLUMN(_xlpm.TableHeaderCell))
Name Common_InputFunctions.Utility_GetArrayTableColumnStartNumber: _xlfn.LAMBDA(_xlpm.TableHeaderCell, COLUMN(_xlpm.TableHeaderCell))
Name Common_InputFunctions.Utility_GetArrayTableRowStartNumber: _xlfn.LAMBDA(_xlpm.TableheaderCell,_xlpm.RowsBetweenHeaderandArray, ROW(_xlpm.TableheaderCell) + _xlpm.RowsBetweenHeaderandArray - 1)
Name Common_InputFunctions.Utility_GetArrayTableRowStartNumber: _xlfn.LAMBDA(_xlpm.TableheaderCell,_xlpm.RowsBetweenHeaderandArray, ROW(_xlpm.TableheaderCell) + _xlpm.RowsBetweenHeaderandArray - 1)
Name Common_InputFunctions.Utility_GetArrayTableRowStartNumber: _xlfn.LAMBDA(_xlpm.TableheaderCell,_xlpm.RowsBetweenHeaderandArray, ROW(_xlpm.TableheaderCell) + _xlpm.RowsBetweenHeaderandArray - 1)
Name Common_InputFunctions.Utility_LookupValueInTable: _xlfn.LAMBDA(_xlpm.LookupValue,_xlpm.LookupArray,_xlpm.ReturnArray, _xlfn.XLOOKUP(_xlpm.LookupValue, _xlpm.LookupArray, _xlpm.ReturnArray, ""))
Name Common_InputFunctions.Utility_LookupValueInTable: _xlfn.LAMBDA(_xlpm.LookupValue,_xlpm.LookupArray,_xlpm.ReturnArray, _xlfn.XLOOKUP(_xlpm.LookupValue, _xlpm.LookupArray, _xlpm.ReturnArray, ""))
Name Common_InputFunctions.Utility_LookupValueInTable: _xlfn.LAMBDA(_xlpm.LookupValue,_xlpm.LookupArray,_xlpm.ReturnArray, _xlfn.XLOOKUP(_xlpm.LookupValue, _xlpm.LookupArray, _xlpm.ReturnArray, ""))
Name Common_InputFunctions.Utility_SourceHyperlink: _xlfn.LAMBDA(_xlpm.TargetCell, _xlfn.LET(_xlpm.sh, _xlfn.TEXTAFTER(CELL("filename", _xlpm.TargetCell), "]"), _xlpm.addr, CELL("address", _xlpm.TargetCell), "#'" & _xlpm.sh & "'!" & _xlpm.addr))
Name Common_InputFunctions.Utility_SourceHyperlink: _xlfn.LAMBDA(_xlpm.TargetCell, _xlfn.LET(_xlpm.sh, _xlfn.TEXTAFTER(CELL("filename", _xlpm.TargetCell), "]"), _xlpm.addr, CELL("address", _xlpm.TargetCell), "#'" & _xlpm.sh & "'!" & _xlpm.addr))
Name Common_InputFunctions.Utility_SourceHyperlink: _xlfn.LAMBDA(_xlpm.TargetCell, _xlfn.LET(_xlpm.sh, _xlfn.TEXTAFTER(CELL("filename", _xlpm.TargetCell), "]"), _xlpm.addr, CELL("address", _xlpm.TargetCell), "#'" & _xlpm.sh & "'!" & _xlpm.addr))
Name Common_SourceData.Common_SourceData_AustralianStatesTerritories_Source: _xlfn.LAMBDA("")
Name Common_SourceData.Common_SourceData_AustralianStatesTerritories_Title: _xlfn.LAMBDA("Australian states and territories")
Name Common_SourceData.Common_SourceData_AustralianStatesTerritories_Unit: _xlfn.LAMBDA("")
Name Common_SourceData.Common_SourceData_AustralianStatesTerritories_Variable: _xlfn.LAMBDA("")
Name Common_SourceData.Common_SourceData_ClimateZones_Source: _xlfn.LAMBDA("VEERG 2026: Table 1.3: Climate and Rainfall zone classifications and definitions")
Name Common_SourceData.Common_SourceData_ClimateZones_Title: _xlfn.LAMBDA("VEERG Australian climate zones")
Name Common_SourceData.Common_SourceData_ClimateZones_Unit: _xlfn.LAMBDA("")
Name Common_SourceData.Common_SourceData_ClimateZones_Variable: _xlfn.LAMBDA("")
Name Common_SourceData.Common_SourceData_ConvertGasElementalToMolecular_Source: _xlfn.LAMBDA("XXXXXXX")
Name Common_SourceData.Common_SourceData_ConvertGasElementalToMolecular_Title: _xlfn.LAMBDA("Factor to convert elemental mass of gas to molecular mass")
Name Common_SourceData.Common_SourceData_ConvertGasElementalToMolecular_Unit: _xlfn.LAMBDA("factor")
Name Common_SourceData.Common_SourceData_ConvertGasElementalToMolecular_Variable: _xlfn.LAMBDA("Cg")
Name Common_SourceData.Common_SourceData_ConvertN2oElementalToMolecularCg_Data: _xlfn.LAMBDA(44 / 28)
Name Common_SourceData.Common_SourceData_ConvertN2oElementalToMolecularCg_Source: _xlfn.LAMBDA("National Inventory Report 2023 Volume 1")
Name Common_SourceData.Common_SourceData_ConvertN2oElementalToMolecularCg_Title: _xlfn.LAMBDA("Factor to convert elemental mass of N2O to molecular mass")

Sheet Home
A1: Home

Sheet Overview
A1: #VALUE! | C1: 5: Fertiliser Use: Overview
A3: =HYPERLINK("#'Home'!A1", "Home") -> Home
A4: =HYPERLINK("#'Overview'!A1", "Overview") -> Overview
A5: =HYPERLINK("#'Results'!A1", "Results") -> Results | D5: 💡 Below is a diagram that maps the equations used to calculate emissions, and how they interact with each other.
D6: Click on a box to go to the corresponding calculation.
A7: INPUTS
A8: =HYPERLINK("#'Input - Site'!A1", "Site") -> Site
A9: =HYPERLINK("#'Input - Fertiliser'!A1", "Fertiliser") -> Fertiliser
A11: CALCULATIONS
A12: =HYPERLINK("#'5.1.1.1-2 Inorganic Fert N2O'!A1", "5.1.1.1-2 Inorganic Fert N2O") -> 5.1.1.1-2 Inorganic Fert N2O
A13: =HYPERLINK("#'5.1.1.3-4 Inorganic fert CO2'!A1", "5.1.1.3-4 Inorganic fert CO2") -> 5.1.1.3-4 Inorganic fert CO2
A14: =HYPERLINK("#'5.2.1.1-2 Organic Fert N2O'!A1", "5.2.1.1-2 Organic Fert N2O") -> 5.2.1.1-2 Organic Fert N2O
A15: =HYPERLINK("#'5.3.1.1-2 Lime CO2'!A1", "5.3.1.1-2 Lime CO2") -> 5.3.1.1-2 Lime CO2
A16: =HYPERLINK("#'5.4.1.1-4 Atmos deposition'!A1", "5.4.1.1-4 Atmos deposition") -> 5.4.1.1-4 Atmos deposition
A17: =HYPERLINK("#'5.5.1.1-2 Leaching and runoff'!A1", "5.5.1.1-2 Leaching and runoff") -> 5.5.1.1-2 Leaching and runoff
A19: APPENDICES
A20: =HYPERLINK("#'Constants - Fertiliser'!A1", "Constants - Fertiliser") -> Constants - Fertiliser
A21: =HYPERLINK("#'Constants - Common'!A1", "Constants - Common") -> Constants - Common
L37: `

Sheet Results
A1: #VALUE! | C1: 5: Fertiliser Use: Results
A3: =HYPERLINK("#'Home'!A1", "Home") -> Home
A4: =HYPERLINK("#'Overview'!A1", "Overview") -> Overview | D4: Emissions breakdown
A5: =HYPERLINK("#'Results'!A1", "Results") -> Results
D6: 💡 NOTE: When there is no Method 2, the Method 2 result are the same as Method 1
A7: INPUTS
A8: =HYPERLINK("#'Input - Site'!A1", "Site") -> Site | D8: Scope 1 source | E8: GHG emissions method 1 | F8: GHG emissions method 2 | G8: GHG Unit | H8: CO2-e emissions method 1 | I8: CO2-e emissions method 2 | J8: CO2-e unit
A9: =HYPERLINK("#'Input - Fertiliser'!A1", "Fertiliser") -> Fertiliser | D9: 5.1.1.1-2 Inorganic fertiliser N2O | E9: ='5.1.1.1-2 Inorganic fert N2O'!$E$78 -> 0.13266 | F9: ='5.1.1.1-2 Inorganic fert N2O'!$N$88 -> 0.13266 | G9: t N2O | H9: ='5.1.1.1-2 Inorganic fert N2O'!E83 -> 35.1549 | I9: ='5.1.1.1-2 Inorganic fert N2O'!N93 -> 35.1549 | J9: t CO2e
D10: 5.1.1.3-4 Inorganic fertiliser CO2 | E10: ='5.1.1.3-4 Inorganic fert CO2'!$E$76 -> 9.4695652 | F10: =E10 -> 9.4695652 | G10: t CO2 | H10: ='5.1.1.3-4 Inorganic fert CO2'!$E$76 -> 9.4695652 | I10: =H10 -> 9.4695652 | J10: t CO2e
A11: CALCULATIONS | D11: 5.2.1.1-2 Organic fertiliser N2O | E11: ='5.2.1.1-2 Organic Fert N2O'!$E$50 -> 0.0043214286 | F11: =E11 -> 0.0043214286 | G11: t N2O | H11: ='5.2.1.1-2 Organic Fert N2O'!$E$55 -> 1.1451786 | I11: =H11 -> 1.1451786 | J11: t CO2e
A12: =HYPERLINK("#'5.1.1.1-2 Inorganic Fert N2O'!A1", "5.1.1.1-2 Inorganic Fert N2O") -> 5.1.1.1-2 Inorganic Fert N2O | D12: 5.3.1.1-3 Lime CO2 | E12: ='5.3.1.1-2 Lime CO2'!$E$31 -> 7.4708333 | F12: =E12 -> 7.4708333 | G12: t CO2 | H12: ='5.3.1.1-2 Lime CO2'!$E$31 -> 7.4708333 | I12: =H12 -> 7.4708333 | J12: t CO2e
A13: =HYPERLINK("#'5.1.1.3-4 Inorganic fert CO2'!A1", "5.1.1.3-4 Inorganic fert CO2") -> 5.1.1.3-4 Inorganic fert CO2 | D13: 5.4.1.1-5 Atmospheric deposition | E13: ='5.4.1.1-4 Atmos deposition'!$E$144 -> 0.0012705 | F13: =E13 -> 0.0012705 | G13: t N2O | H13: ='5.4.1.1-4 Atmos deposition'!$E$149 -> 0.3366825 | I13: =H13 -> 0.3366825 | J13: t CO2e
A14: =HYPERLINK("#'5.2.1.1-2 Organic Fert N2O'!A1", "5.2.1.1-2 Organic Fert N2O") -> 5.2.1.1-2 Organic Fert N2O | D14: 5.5.1.1-2 Leaching and runoff | E14: ='5.5.1.1-2 Leaching and runoff'!$E$93 -> 0 | F14: =E14 -> 0 | G14: t N2O | H14: ='5.5.1.1-2 Leaching and runoff'!$E$98 -> 0 | I14: =H14 -> 0 | J14: t CO2e
A15: =HYPERLINK("#'5.3.1.1-2 Lime CO2'!A1", "5.3.1.1-2 Lime CO2") -> 5.3.1.1-2 Lime CO2 | D15: Total | H15: =SUM(H9:H14) -> 53.57716 | I15: =SUM(I9:I14) -> 53.57716 | J15: t CO2e
A16: =HYPERLINK("#'5.4.1.1-4 Atmos deposition'!A1", "5.4.1.1-4 Atmos deposition") -> 5.4.1.1-4 Atmos deposition
A17: =HYPERLINK("#'5.5.1.1-2 Leaching and runoff'!A1", "5.5.1.1-2 Leaching and runoff") -> 5.5.1.1-2 Leaching and runoff
A19: APPENDICES
A20: =HYPERLINK("#'Constants - Fertiliser'!A1", "Constants - Fertiliser") -> Constants - Fertiliser
A21: =HYPERLINK("#'Constants - Common'!A1", "Constants - Common") -> Constants - Common

Sheet Input - Site
A1: #VALUE! | C1: Input - Site
A3: =HYPERLINK("#'Home'!A1", "Home") -> Home
A4: =HYPERLINK("#'Overview'!A1", "Overview") -> Overview
A5: =HYPERLINK("#'Results'!A1", "Results") -> Results | D5: Your business
A7: INPUTS | D7: Farm name | E7: Test Farms
A8: =HYPERLINK("#'Input - Site'!A1", "Site") -> Site | D8: Reporting entity name | E8: Test Farms Pty Ltd
A9: =HYPERLINK("#'Input - Fertiliser'!A1", "Fertiliser") -> Fertiliser
D10: 💡An 'Emissions accounting period' is a 12 month period where the business can report on the emissions, and is typically the same as the business' financial accounting period.
A11: CALCULATIONS
A12: =HYPERLINK("#'5.1.1.1-2 Inorganic Fert N2O'!A1", "5.1.1.1-2 Inorganic Fert N2O") -> 5.1.1.1-2 Inorganic Fert N2O | D12: Emissions calculation period start date | E12: 45292 | F12: ← DD/MM/YYYY or DD Month YYYY
A13: =HYPERLINK("#'5.1.1.3-4 Inorganic fert CO2'!A1", "5.1.1.3-4 Inorganic fert CO2") -> 5.1.1.3-4 Inorganic fert CO2 | D13: Emissions calculation period end date | E13: =DATE(YEAR(E12)+1,MONTH(E12),DAY(E12))-1 -> 45657 | F13: ← Automatically calculated, 12 months after start date
A14: =HYPERLINK("#'5.2.1.1-2 Organic Fert N2O'!A1", "5.2.1.1-2 Organic Fert N2O") -> 5.2.1.1-2 Organic Fert N2O
A15: =HYPERLINK("#'5.3.1.1-2 Lime CO2'!A1", "5.3.1.1-2 Lime CO2") -> 5.3.1.1-2 Lime CO2
A16: =HYPERLINK("#'5.4.1.1-4 Atmos deposition'!A1", "5.4.1.1-4 Atmos deposition") -> 5.4.1.1-4 Atmos deposition | D16: Location and climate
A17: =HYPERLINK("#'5.5.1.1-2 Leaching and runoff'!A1", "5.5.1.1-2 Leaching and runoff") -> 5.5.1.1-2 Leaching and runoff
D18: Location information is used to reference some region and climate-specific emission factors
A19: APPENDICES | D19: Tip: Use the web-based GAF Location Helper tool to easily get region and climate information. You will need an internet connection to use the GAF Location Helper.
A20: =HYPERLINK("#'Constants - Fertiliser'!A1", "Constants - Fertiliser") -> Constants - Fertiliser
A21: =HYPERLINK("#'Constants - Common'!A1", "Constants - Common") -> Constants - Common | D21: State | E21: Western Australia | F21: ← Please select
D22: Region (ABS Statistical area level 4) if state is WA | E22: Western Australia - Outback (South) | F22: ← Please select
D23: Leaching zone | E23: NO - Not in leaching zone | F23: ← Please select
D24: Elevation | E24: 307.7 | F24: Meters
D25: Average temperature for reporting period | E25: 18 | F25: Degrees celsius
D26: Total rainfall for reporting period | E26: 599 | F26: Millimetres
D27: Potential evapotranspiration for reporting period | E27: 1326 | F27: Millimetres
D28: Number of frost days for reporting period | E28: 7 | F28: Days
D29: MAP:PET ratio | E29: =E26/E27 -> 0.45173454
D30: Rainfall zone | E30: =Common_InputFunctions.Utility_LookupItemFromMinMax(E26,Table_SourceData_RainfallZones[Min rainfall],Table_SourceData_RainfallZones[Max rainfall],Table_SourceData_RainfallZones[Rainfall Zone]) -> Low rainfall
D31: Climate zone | E31: =Common_InputFunctions.Utility_GetClimateZone(E25,E26,E28,E24,E29,Table_SourceData_ClimateZones[Min temp],Table_SourceData_ClimateZones[Max temp],Table_SourceData_ClimateZones[Min rainfall],Table_SourceData_ClimateZones[Max rainfall],Table_SourceData_ClimateZones[Min frost days],Table_SourceData_ClimateZones[Max frost days],Table_SourceData_ClimateZones[Min elevation],Table_SourceData_ClimateZones[Max elevation],Table_SourceData_ClimateZones[Min MAP:PET],Table_SourceData_ClimateZones[Max MAP:PET],Table_SourceData_ClimateZones[Climate zone]) -> Warm temperate dry
D32: Wet or dry climate zone | E32: =Common_InputFunctions.Utility_LookupValueInTable($E$31,Table_SourceData_WetDryZones[Climate zone],Table_SourceData_WetDryZones[Wet or Dry Zone]) -> Dry climate zone
D33: Temperature zone | E33: =Common_InputFunctions.Utility_LookupItemFromMinMax(E25,Table_SourceData_TemperatureZones[Min MAT],Table_SourceData_TemperatureZones[Max MAT],Table_SourceData_TemperatureZones[Temperature Zone]) -> Temperate

Sheet Input - Fertiliser
A1: #VALUE! | C1: Input - Fertiliser
A3: =HYPERLINK("#'Home'!A1", "Home") -> Home
A4: =HYPERLINK("#'Overview'!A1", "Overview") -> Overview
A5: =HYPERLINK("#'Results'!A1", "Results") -> Results
D6: Production system | E6: Crop | F6: ← Please select
A7: INPUTS | D7: Crop type | E7: Grains | F7: ← Please select
A8: =HYPERLINK("#'Input - Site'!A1", "Site") -> Site | D8: Irrigation method | E8: Drip irrigation | F8: ← Please select
A9: =HYPERLINK("#'Input - Fertiliser'!A1", "Fertiliser") -> Fertiliser | D9: Area under cropping | E9: 100 | F9: hectares
A11: CALCULATIONS | D11: Inorganic fertiliser applied
A12: =HYPERLINK("#'5.1.1.1-2 Inorganic Fert N2O'!A1", "5.1.1.1-2 Inorganic Fert N2O") -> 5.1.1.1-2 Inorganic Fert N2O
A13: =HYPERLINK("#'5.1.1.3-4 Inorganic fert CO2'!A1", "5.1.1.3-4 Inorganic fert CO2") -> 5.1.1.3-4 Inorganic fert CO2 | D13: 💡You can add more rows to tables by right-clicking on the table and selecting "Insert > Table rows above/below".
A14: =HYPERLINK("#'5.2.1.1-2 Organic Fert N2O'!A1", "5.2.1.1-2 Organic Fert N2O") -> 5.2.1.1-2 Organic Fert N2O | D14: 💡The application area is the same as the area under pasture / cropping by default. You can edit it if the application area is different.
A15: =HYPERLINK("#'5.3.1.1-2 Lime CO2'!A1", "5.3.1.1-2 Lime CO2") -> 5.3.1.1-2 Lime CO2
A16: =HYPERLINK("#'5.4.1.1-4 Atmos deposition'!A1", "5.4.1.1-4 Atmos deposition") -> 5.4.1.1-4 Atmos deposition | D16: Branded fertiliser products
A17: =HYPERLINK("#'5.5.1.1-2 Leaching and runoff'!A1", "5.5.1.1-2 Leaching and runoff") -> 5.5.1.1-2 Leaching and runoff | D17: Product (select) | E17: Amount applied (kg / ha) | F17: Application area (ha) | G17: Total applied (kg) | H17: Ingredient 1 | I17: Ingredient 1 percent | J17: Ingredient 2 | K17: Ingredient 2 percent | L17: Ingredient 3 | M17: Ingredient 3 percent | N17: Ingredient 4 | O17: Ingredient 4 percent | P17: Ingredient 5 | Q17: Ingredient 5 percent | R17: Ingredient 6 | S17: Ingredient 6 percent | T17: N application rate (kg/ha)
D18: Aqua Finish | E18: 200 | F18: =$E$9 -> 100 | G18: =Table_Input_InorganicFertiliser_Brands[[#This Row],[Amount applied (kg / ha)]]*Table_Input_InorganicFertiliser_Brands[[#This Row],[Application area (ha)]] -> 20000 | H18: {=Fertiliser_InputFunctions.Fertiliser_FertiliserProductLookup(Table_Input_InorganicFertiliser_Brands[[#This Row],[Product (select)]], Table_Input_InorganicFertiliser_Brands[[#Headers],[Ingredient 1]], FertiliserProducts[#Data], FertiliserProducts[Product name], FertiliserProducts[#Headers])} -> Potassium - Generic | I18: {=Fertiliser_InputFunctions.Fertiliser_FertiliserProductLookup(Table_Input_InorganicFertiliser_Brands[[#This Row],[Product (select)]], Table_Input_InorganicFertiliser_Brands[[#Headers],[Ingredient 1 percent]], FertiliserProducts[#Data], FertiliserProducts[Product name], FertiliserProducts[#Headers])} -> 0.225 | J18: {=Fertiliser_InputFunctions.Fertiliser_FertiliserProductLookup(Table_Input_InorganicFertiliser_Brands[[#This Row],[Product (select)]], Table_Input_InorganicFertiliser_Brands[[#Headers],[Ingredient 2]], FertiliserProducts[#Data], FertiliserProducts[Product name], FertiliserProducts[#Headers])} -> Phosphorus - Generic | K18: {=Fertiliser_InputFunctions.Fertiliser_FertiliserProductLookup(Table_Input_InorganicFertiliser_Brands[[#This Row],[Product (select)]], Table_Input_InorganicFertiliser_Brands[[#Headers],[Ingredient 2 percent]], FertiliserProducts[#Data], FertiliserProducts[Product name], FertiliserProducts[#Headers])} -> 0.04 | L18: {=Fertiliser_InputFunctions.Fertiliser_FertiliserProductLookup(Table_Input_InorganicFertiliser_Brands[[#This Row],[Product (select)]], Table_Input_InorganicFertiliser_Brands[[#Headers],[Ingredient 3]], FertiliserProducts[#Data], FertiliserProducts[Product name], FertiliserProducts[#Headers])} -> Nitrogen - Generic | M18: {=Fertiliser_InputFunctions.Fertiliser_FertiliserProductLookup(Table_Input_InorganicFertiliser_Brands[[#This Row],[Product (select)]], Table_Input_InorganicFertiliser_Brands[[#Headers],[Ingredient 3 percent]], FertiliserProducts[#Data], FertiliserProducts[Product name], FertiliserProducts[#Headers])} -> 0.026 | N18: {=Fertiliser_InputFunctions.Fertiliser_FertiliserProductLookup(Table_Input_InorganicFertiliser_Brands[[#This Row],[Product (select)]], Table_Input_InorganicFertiliser_Brands[[#Headers],[Ingredient 4]], FertiliserProducts[#Data], FertiliserProducts[Product name], FertiliserProducts[#Headers])} | O18: {=Fertiliser_InputFunctions.Fertiliser_FertiliserProductLookup(Table_Input_InorganicFertiliser_Brands[[#This Row],[Product (select)]], Table_Input_InorganicFertiliser_Brands[[#Headers],[Ingredient 4 percent]], FertiliserProducts[#Data], FertiliserProducts[Product name], FertiliserProducts[#Headers])} | P18: {=Fertiliser_InputFunctions.Fertiliser_FertiliserProductLookup(Table_Input_InorganicFertiliser_Brands[[#This Row],[Product (select)]], Table_Input_InorganicFertiliser_Brands[[#Headers],[Ingredient 5]], FertiliserProducts[#Data], FertiliserProducts[Product name], FertiliserProducts[#Headers])} | Q18: {=Fertiliser_InputFunctions.Fertiliser_FertiliserProductLookup(Table_Input_InorganicFertiliser_Brands[[#This Row],[Product (select)]], Table_Input_InorganicFertiliser_Brands[[#Headers],[Ingredient 5 percent]], FertiliserProducts[#Data], FertiliserProducts[Product name], FertiliserProducts[#Headers])} | R18: {=Fertiliser_InputFunctions.Fertiliser_FertiliserProductLookup(Table_Input_InorganicFertiliser_Brands[[#This Row],[Product (select)]], Table_Input_InorganicFertiliser_Brands[[#Headers],[Ingredient 6]], FertiliserProducts[#Data], FertiliserProducts[Product name], FertiliserProducts[#Headers])} | S18: {=Fertiliser_InputFunctions.Fertiliser_FertiliserProductLookup(Table_Input_InorganicFertiliser_Brands[[#This Row],[Product (select)]], Table_Input_InorganicFertiliser_Brands[[#Headers],[Ingredient 6 percent]], FertiliserProducts[#Data], FertiliserProducts[Product name], FertiliserProducts[#Headers])} | T18: =Table_Input_InorganicFertiliser_Brands[[#This Row],[Amount applied (kg / ha)]]*(IFERROR((_xlfn.XLOOKUP(Table_Input_InorganicFertiliser_Brands[[#This Row],[Ingredient 1]], Table_Fertiliser_ChemicalCompounds[Fertiliser type f],Table_Fertiliser_ChemicalCompounds[FNinorganic f])*Table_Input_InorganicFertiliser_Brands[[#This Row],[Ingredient 1 percent]]), 0)+ IFERROR((_xlfn.XLOOKUP(Table_Input_InorganicFertiliser_Brands[[#This Row],[Ingredient 2]],Table_Fertiliser_ChemicalCompounds[Fertiliser type f],Table_Fertiliser_ChemicalCompounds[FNinorganic f])*Table_Input_InorganicFertiliser_Brands[[#This Row],[Ingredient 2 percent]]), 0)+ IFERROR((_xlfn.XLOOKUP(Table_Input_InorganicFertiliser_Brands[[#This Row],[Ingredient 3]],Table_Fertiliser_ChemicalCompounds[Fertiliser type f],Table_Fertiliser_ChemicalCompounds[FNinorganic f])*Table_Input_InorganicFertiliser_Brands[[#This Row],[Ingredient 3 percent]]), 0)+ IFERROR((_xlfn.XLOOKUP(Table_Input_InorganicFertiliser_Brands[[#This Row],[Ingredient 4]],Table_Fertiliser_ChemicalCompounds[Fertiliser type f],Table_Fertiliser_ChemicalCompounds[FNinorganic f])*Table_Input_InorganicFertiliser_Brands[[#This Row],[Ingredient 4 percent]]), 0)+ IFERROR((_xlfn.XLOOKUP(Table_Input_InorganicFertiliser_Brands[[#This Row],[Ingredient 5]],Table_Fertiliser_ChemicalCompounds[Fertiliser type f],Table_Fertiliser_ChemicalCompounds[FNinorganic f])*Table_Input_InorganicFertiliser_Brands[[#This Row],[Ingredient 5 percent]]), 0)+ IFERROR((_xlfn.XLOOKUP(Table_Input_InorganicFertiliser_Brands[[#This Row],[Ingredient 6]],Table_Fertiliser_ChemicalCompounds[Fertiliser type f],Table_Fertiliser_ChemicalCompounds[FNinorganic f])*Table_Input_InorganicFertiliser_Brands[[#This Row],[Ingredient 6 percent]]), 0)) -> 5.2
A19: APPENDICES | D19: Compass | E19: 200 | F19: =$E$9 -> 100 | G19: =Table_Input_InorganicFertiliser_Brands[[#This Row],[Amount applied (kg / ha)]]*Table_Input_InorganicFertiliser_Brands[[#This Row],[Application area (ha)]] -> 20000 | H19: {=Fertiliser_InputFunctions.Fertiliser_FertiliserProductLookup(Table_Input_InorganicFertiliser_Brands[[#This Row],[Product (select)]], Table_Input_InorganicFertiliser_Brands[[#Headers],[Ingredient 1]], FertiliserProducts[#Data], FertiliserProducts[Product name], FertiliserProducts[#Headers])} -> Nitrogen - Ammoniacal | I19: {=Fertiliser_InputFunctions.Fertiliser_FertiliserProductLookup(Table_Input_InorganicFertiliser_Brands[[#This Row],[Product (select)]], Table_Input_InorganicFertiliser_Brands[[#Headers],[Ingredient 1 percent]], FertiliserProducts[#Data], FertiliserProducts[Product name], FertiliserProducts[#Headers])} -> 0.075 | J19: {=Fertiliser_InputFunctions.Fertiliser_FertiliserProductLookup(Table_Input_InorganicFertiliser_Brands[[#This Row],[Product (select)]], Table_Input_InorganicFertiliser_Brands[[#Headers],[Ingredient 2]], FertiliserProducts[#Data], FertiliserProducts[Product name], FertiliserProducts[#Headers])} -> Nitrogen - Nitrate | K19: {=Fertiliser_InputFunctions.Fertiliser_FertiliserProductLookup(Table_Input_InorganicFertiliser_Brands[[#This Row],[Product (select)]], Table_Input_InorganicFertiliser_Brands[[#Headers],[Ingredient 2 percent]], FertiliserProducts[#Data], FertiliserProducts[Product name], FertiliserProducts[#Headers])} -> 0.075 | L19: {=Fertiliser_InputFunctions.Fertiliser_FertiliserProductLookup(Table_Input_InorganicFertiliser_Brands[[#This Row],[Product (select)]], Table_Input_InorganicFertiliser_Brands[[#Headers],[Ingredient 3]], FertiliserProducts[#Data], FertiliserProducts[Product name], FertiliserProducts[#Headers])} -> Potassium - Generic | M19: {=Fertiliser_InputFunctions.Fertiliser_FertiliserProductLookup(Table_Input_InorganicFertiliser_Brands[[#This Row],[Product (select)]], Table_Input_InorganicFertiliser_Brands[[#Headers],[Ingredient 3 percent]], FertiliserProducts[#Data], FertiliserProducts[Product name], FertiliserProducts[#Headers])} -> 0.125 | N19: {=Fertiliser_InputFunctions.Fertiliser_FertiliserProductLookup(Table_Input_InorganicFertiliser_Brands[[#This Row],[Product (select)]], Table_Input_InorganicFertiliser_Brands[[#Headers],[Ingredient 4]], FertiliserProducts[#Data], FertiliserProducts[Product name], FertiliserProducts[#Headers])} -> Phosphorus-Generic | O19: {=Fertiliser_InputFunctions.Fertiliser_FertiliserProductLookup(Table_Input_InorganicFertiliser_Brands[[#This Row],[Product (select)]], Table_Input_InorganicFertiliser_Brands[[#Headers],[Ingredient 4 percent]], FertiliserProducts[#Data], FertiliserProducts[Product name], FertiliserProducts[#Headers])} -> 0.065 | P19: {=Fertiliser_InputFunctions.Fertiliser_FertiliserProductLookup(Table_Input_InorganicFertiliser_Brands[[#This Row],[Product (select)]], Table_Input_InorganicFertiliser_Brands[[#Headers],[Ingredient 5]], FertiliserProducts[#Data], FertiliserProducts[Product name], FertiliserProducts[#Headers])} -> Sulfur - Generic | Q19: {=Fertiliser_InputFunctions.Fertiliser_FertiliserProductLookup(Table_Input_InorganicFertiliser_Brands[[#This Row],[Product (select)]], Table_Input_InorganicFertiliser_Brands[[#Headers],[Ingredient 5 percent]], FertiliserProducts[#Data], FertiliserProducts[Product name], FertiliserProducts[#Headers])} -> 0.06 | R19: {=Fertiliser_InputFunctions.Fertiliser_FertiliserProductLookup(Table_Input_InorganicFertiliser_Brands[[#This Row],[Product (select)]], Table_Input_InorganicFertiliser_Brands[[#Headers],[Ingredient 6]], FertiliserProducts[#Data], FertiliserProducts[Product name], FertiliserProducts[#Headers])} | S19: {=Fertiliser_InputFunctions.Fertiliser_FertiliserProductLookup(Table_Input_InorganicFertiliser_Brands[[#This Row],[Product (select)]], Table_Input_InorganicFertiliser_Brands[[#Headers],[Ingredient 6 percent]], FertiliserProducts[#Data], FertiliserProducts[Product name], FertiliserProducts[#Headers])} | T19: =Table_Input_InorganicFertiliser_Brands[[#This Row],[Amount applied (kg / ha)]]*(IFERROR((_xlfn.XLOOKUP(Table_Input_InorganicFertiliser_Brands[[#This Row],[Ingredient 1]], Table_Fertiliser_ChemicalCompounds[Fertiliser type f],Table_Fertiliser_ChemicalCompounds[FNinorganic f])*Table_Input_InorganicFertiliser_Brands[[#This Row],[Ingredient 1 percent]]), 0)+ IFERROR((_xlfn.XLOOKUP(Table_Input_InorganicFertiliser_Brands[[#This Row],[Ingredient 2]],Table_Fertiliser_ChemicalCompounds[Fertiliser type f],Table_Fertiliser_ChemicalCompounds[FNinorganic f])*Table_Input_InorganicFertiliser_Brands[[#This Row],[Ingredient 2 percent]]), 0)+ IFERROR((_xlfn.XLOOKUP(Table_Input_InorganicFertiliser_Brands[[#This Row],[Ingredient 3]],Table_Fertiliser_ChemicalCompounds[Fertiliser type f],Table_Fertiliser_ChemicalCompounds[FNinorganic f])*Table_Input_InorganicFertiliser_Brands[[#This Row],[Ingredient 3 percent]]), 0)+ IFERROR((_xlfn.XLOOKUP(Table_Input_InorganicFertiliser_Brands[[#This Row],[Ingredient 4]],Table_Fertiliser_ChemicalCompounds[Fertiliser type f],Table_Fertiliser_ChemicalCompounds[FNinorganic f])*Table_Input_InorganicFertiliser_Brands[[#This Row],[Ingredient 4 percent]]), 0)+ IFERROR((_xlfn.XLOOKUP(Table_Input_InorganicFertiliser_Brands[[#This Row],[Ingredient 5]],Table_Fertiliser_ChemicalCompounds[Fertiliser type f],Table_Fertiliser_ChemicalCompounds[FNinorganic f])*Table_Input_InorganicFertiliser_Brands[[#This Row],[Ingredient 5 percent]]), 0)+ IFERROR((_xlfn.XLOOKUP(Table_Input_InorganicFertiliser_Brands[[#This Row],[Ingredient 6]],Table_Fertiliser_ChemicalCompounds[Fertiliser type f],Table_Fertiliser_ChemicalCompounds[FNinorganic f])*Table_Input_InorganicFertiliser_Brands[[#This Row],[Ingredient 6 percent]]), 0)) -> 30
A20: =HYPERLINK("#'Constants - Fertiliser'!A1", "Constants - Fertiliser") -> Constants - Fertiliser | D20: CoRoN 12-0-10 | E20: 200 | F20: =$E$9 -> 100 | G20: =Table_Input_InorganicFertiliser_Brands[[#This Row],[Amount applied (kg / ha)]]*Table_Input_InorganicFertiliser_Brands[[#This Row],[Application area (ha)]] -> 20000 | H20: {=Fertiliser_InputFunctions.Fertiliser_FertiliserProductLookup(Table_Input_InorganicFertiliser_Brands[[#This Row],[Product (select)]], Table_Input_InorganicFertiliser_Brands[[#Headers],[Ingredient 1]], FertiliserProducts[#Data], FertiliserProducts[Product name], FertiliserProducts[#Headers])} -> Urea | I20: {=Fertiliser_InputFunctions.Fertiliser_FertiliserProductLookup(Table_Input_InorganicFertiliser_Brands[[#This Row],[Product (select)]], Table_Input_InorganicFertiliser_Brands[[#Headers],[Ingredient 1 percent]], FertiliserProducts[#Data], FertiliserProducts[Product name], FertiliserProducts[#Headers])} -> 0.19565217 | J20: {=Fertiliser_InputFunctions.Fertiliser_FertiliserProductLookup(Table_Input_InorganicFertiliser_Brands[[#This Row],[Product (select)]], Table_Input_InorganicFertiliser_Brands[[#Headers],[Ingredient 2]], FertiliserProducts[#Data], FertiliserProducts[Product name], FertiliserProducts[#Headers])} -> Potassium - Generic | K20: {=Fertiliser_InputFunctions.Fertiliser_FertiliserProductLookup(Table_Input_InorganicFertiliser_Brands[[#This Row],[Product (select)]], Table_Input_InorganicFertiliser_Brands[[#Headers],[Ingredient 2 percent]], FertiliserProducts[#Data], FertiliserProducts[Product name], FertiliserProducts[#Headers])} -> 0.1 | L20: {=Fertiliser_InputFunctions.Fertiliser_FertiliserProductLookup(Table_Input_InorganicFertiliser_Brands[[#This Row],[Product (select)]], Table_Input_InorganicFertiliser_Brands[[#Headers],[Ingredient 3]], FertiliserProducts[#Data], FertiliserProducts[Product name], FertiliserProducts[#Headers])} -> Nitrogen - Generic | M20: {=Fertiliser_InputFunctions.Fertiliser_FertiliserProductLookup(Table_Input_InorganicFertiliser_Brands[[#This Row],[Product (select)]], Table_Input_InorganicFertiliser_Brands[[#Headers],[Ingredient 3 percent]], FertiliserProducts[#Data], FertiliserProducts[Product name], FertiliserProducts[#Headers])} -> 0.03 | N20: {=Fertiliser_InputFunctions.Fertiliser_FertiliserProductLookup(Table_Input_InorganicFertiliser_Brands[[#This Row],[Product (select)]], Table_Input_InorganicFertiliser_Brands[[#Headers],[Ingredient 4]], FertiliserProducts[#Data], FertiliserProducts[Product name], FertiliserProducts[#Headers])} -> Boron | O20: {=Fertiliser_InputFunctions.Fertiliser_FertiliserProductLookup(Table_Input_InorganicFertiliser_Brands[[#This Row],[Product (select)]], Table_Input_InorganicFertiliser_Brands[[#Headers],[Ingredient 4 percent]], FertiliserProducts[#Data], FertiliserProducts[Product name], FertiliserProducts[#Headers])} -> 0.005 | P20: {=Fertiliser_InputFunctions.Fertiliser_FertiliserProductLookup(Table_Input_InorganicFertiliser_Brands[[#This Row],[Product (select)]], Table_Input_InorganicFertiliser_Brands[[#Headers],[Ingredient 5]], FertiliserProducts[#Data], FertiliserProducts[Product name], FertiliserProducts[#Headers])} | Q20: {=Fertiliser_InputFunctions.Fertiliser_FertiliserProductLookup(Table_Input_InorganicFertiliser_Brands[[#This Row],[Product (select)]], Table_Input_InorganicFertiliser_Brands[[#Headers],[Ingredient 5 percent]], FertiliserProducts[#Data], FertiliserProducts[Product name], FertiliserProducts[#Headers])} | R20: {=Fertiliser_InputFunctions.Fertiliser_FertiliserProductLookup(Table_Input_InorganicFertiliser_Brands[[#This Row],[Product (select)]], Table_Input_InorganicFertiliser_Brands[[#Headers],[Ingredient 6]], FertiliserProducts[#Data], FertiliserProducts[Product name], FertiliserProducts[#Headers])} | S20: {=Fertiliser_InputFunctions.Fertiliser_FertiliserProductLookup(Table_Input_InorganicFertiliser_Brands[[#This Row],[Product (select)]], Table_Input_InorganicFertiliser_Brands[[#Headers],[Ingredient 6 percent]], FertiliserProducts[#Data], FertiliserProducts[Product name], FertiliserProducts[#Headers])} | T20: =Table_Input_InorganicFertiliser_Brands[[#This Row],[Amount applied (kg / ha)]]*(IFERROR((_xlfn.XLOOKUP(Table_Input_InorganicFertiliser_Brands[[#This Row],[Ingredient 1]], Table_Fertiliser_ChemicalCompounds[Fertiliser type f],Table_Fertiliser_ChemicalCompounds[FNinorganic f])*Table_Input_InorganicFertiliser_Brands[[#This Row],[Ingredient 1 percent]]), 0)+ IFERROR((_xlfn.XLOOKUP(Table_Input_InorganicFertiliser_Brands[[#This Row],[Ingredient 2]],Table_Fertiliser_ChemicalCompounds[Fertiliser type f],Table_Fertiliser_ChemicalCompounds[FNinorganic f])*Table_Input_InorganicFertiliser_Brands[[#This Row],[Ingredient 2 percent]]), 0)+ IFERROR((_xlfn.XLOOKUP(Table_Input_InorganicFertiliser_Brands[[#This Row],[Ingredient 3]],Table_Fertiliser_ChemicalCompounds[Fertiliser type f],Table_Fertiliser_ChemicalCompounds[FNinorganic f])*Table_Input_InorganicFertiliser_Brands[[#This Row],[Ingredient 3 percent]]), 0)+ IFERROR((_xlfn.XLOOKUP(Table_Input_InorganicFertiliser_Brands[[#This Row],[Ingredient 4]],Table_Fertiliser_ChemicalCompounds[Fertiliser type f],Table_Fertiliser_ChemicalCompounds[FNinorganic f])*Table_Input_InorganicFertiliser_Brands[[#This Row],[Ingredient 4 percent]]), 0)+ IFERROR((_xlfn.XLOOKUP(Table_Input_InorganicFertiliser_Brands[[#This Row],[Ingredient 5]],Table_Fertiliser_ChemicalCompounds[Fertiliser type f],Table_Fertiliser_ChemicalCompounds[FNinorganic f])*Table_Input_InorganicFertiliser_Brands[[#This Row],[Ingredient 5 percent]]), 0)+ IFERROR((_xlfn.XLOOKUP(Table_Input_InorganicFertiliser_Brands[[#This Row],[Ingredient 6]],Table_Fertiliser_ChemicalCompounds[Fertiliser type f],Table_Fertiliser_ChemicalCompounds[FNinorganic f])*Table_Input_InorganicFertiliser_Brands[[#This Row],[Ingredient 6 percent]]), 0)) -> 24
A21: =HYPERLINK("#'Constants - Common'!A1", "Constants - Common") -> Constants - Common
D22: Custom fertiliser blends
D23: Custom blend name | E23: Amount applied (kg / ha) | F23: Application area (ha) | G23: Total applied (kg) | H23: Ingredient 1 (select) | I23: Ingredient 1 percent | J23: Ingredient 2 | K23: Ingredient 2 percent | L23: Ingredient 3 | M23: Ingredient 3 percent | N23: Ingredient 4 | O23: Ingredient 4 percent | P23: N application rate (kg/ha)
D24: My first custom blend | E24: 200 | F24: =$E$9 -> 100 | G24: =Table_Input_InorganicFertiliser_Custom[[#This Row],[Amount applied (kg / ha)]]*Table_Input_InorganicFertiliser_Custom[[#This Row],[Application area (ha)]] -> 20000 | H24: Urea | I24: 0.45 | J24: Phosphorus - Generic | K24: 0.3 | L24: Potassium - Generic | M24: 0 | N24: Sulfur - Generic | O24: 0 | P24: =Table_Input_InorganicFertiliser_Custom[[#This Row],[Amount applied (kg / ha)]]* (IFERROR((_xlfn.XLOOKUP(Table_Input_InorganicFertiliser_Custom[[#This Row],[Ingredient 1 (select)]], Table_Fertiliser_ChemicalCompounds[Fertiliser type f],Table_Fertiliser_ChemicalCompounds[FNinorganic f])*Table_Input_InorganicFertiliser_Custom[[#This Row],[Ingredient 1 percent]]), 0) + IFERROR((_xlfn.XLOOKUP(Table_Input_InorganicFertiliser_Custom[[#This Row],[Ingredient 2]], Table_Fertiliser_ChemicalCompounds[Fertiliser type f],Table_Fertiliser_ChemicalCompounds[FNinorganic f])*Table_Input_InorganicFertiliser_Custom[[#This Row],[Ingredient 2 percent]]), 0) + IFERROR((_xlfn.XLOOKUP(Table_Input_InorganicFertiliser_Custom[[#This Row],[Ingredient 3]], Table_Fertiliser_ChemicalCompounds[Fertiliser type f],Table_Fertiliser_ChemicalCompounds[FNinorganic f])*Table_Input_InorganicFertiliser_Custom[[#This Row],[Ingredient 3 percent]]), 0) + IFERROR((_xlfn.XLOOKUP(Table_Input_InorganicFertiliser_Custom[[#This Row],[Ingredient 4]], Table_Fertiliser_ChemicalCompounds[Fertiliser type f],Table_Fertiliser_ChemicalCompounds[FNinorganic f])*Table_Input_InorganicFertiliser_Custom[[#This Row],[Ingredient 4 percent]]), 0) ) -> 41.4
D25: My second custom blend | E25: 200 | F25: =$E$9 -> 100 | G25: =Table_Input_InorganicFertiliser_Custom[[#This Row],[Amount applied (kg / ha)]]*Table_Input_InorganicFertiliser_Custom[[#This Row],[Application area (ha)]] -> 20000 | H25: Nitrogen - Ammoniacal | I25: 0.1 | P25: =Table_Input_InorganicFertiliser_Custom[[#This Row],[Amount applied (kg / ha)]]* (IFERROR((_xlfn.XLOOKUP(Table_Input_InorganicFertiliser_Custom[[#This Row],[Ingredient 1 (select)]], Table_Fertiliser_ChemicalCompounds[Fertiliser type f],Table_Fertiliser_ChemicalCompounds[FNinorganic f])*Table_Input_InorganicFertiliser_Custom[[#This Row],[Ingredient 1 percent]]), 0) + IFERROR((_xlfn.XLOOKUP(Table_Input_InorganicFertiliser_Custom[[#This Row],[Ingredient 2]], Table_Fertiliser_ChemicalCompounds[Fertiliser type f],Table_Fertiliser_ChemicalCompounds[FNinorganic f])*Table_Input_InorganicFertiliser_Custom[[#This Row],[Ingredient 2 percent]]), 0) + IFERROR((_xlfn.XLOOKUP(Table_Input_InorganicFertiliser_Custom[[#This Row],[Ingredient 3]], Table_Fertiliser_ChemicalCompounds[Fertiliser type f],Table_Fertiliser_ChemicalCompounds[FNinorganic f])*Table_Input_InorganicFertiliser_Custom[[#This Row],[Ingredient 3 percent]]), 0) + IFERROR((_xlfn.XLOOKUP(Table_Input_InorganicFertiliser_Custom[[#This Row],[Ingredient 4]], Table_Fertiliser_ChemicalCompounds[Fertiliser type f],Table_Fertiliser_ChemicalCompounds[FNinorganic f])*Table_Input_InorganicFertiliser_Custom[[#This Row],[Ingredient 4 percent]]), 0) ) -> 20
D27: Soil amendments
D29: 💡 You can add more rows to the table by right-clicking on the table and selecting "Insert > Table rows above/below".
D30: 💡 'Lime' refers to calcium carbonate - CaCO3. 'Dolomite' refers to calcium magnesium carbonate - CaMg(CO3)2
D31: 💡The application area is the same as the area under pasture / cropping by default. You can edit it if the application area is different.
D32: =IF(MAX(Table_Input_Lime[Total]) > 1, "There can not be more than 100% ingredients in a product. Check the table below.", "")
D33: Product | E33: Amount applied (t/hectare) | F33: Application area (ha) | G33: Total amount applied (t) | H33: Percent Lime CaCO3 | I33: Percent Dolomite CaMg(CO3)2 | J33: Percent Gypsum | K33: Percent Potash | L33: Total
D34: Lime product 1 | E34: 100 | F34: =$E$9 -> 100 | G34: =IFERROR(Table_Input_Lime[[#This Row],[Amount applied (t/hectare)]]*Table_Input_Lime[[#This Row],[Application area (ha)]], 0) -> 10000 | H34: 0.4 | I34: 0.3 | J34: 0.25 | K34: 0.05 | L34: =SUM(Table_Input_Lime[[#This Row],[Percent Lime CaCO3]:[Percent Potash]]) -> 1
D35: Lime product 2 | E35: 100 | F35: =$E$9 -> 100 | G35: =IFERROR(Table_Input_Lime[[#This Row],[Amount applied (t/hectare)]]*Table_Input_Lime[[#This Row],[Application area (ha)]], 0) -> 10000 | I35: 1 | L35: =SUM(Table_Input_Lime[[#This Row],[Percent Lime CaCO3]:[Percent Potash]]) -> 1
D38: Organic fertiliser applied
D40: 💡 You can add more rows to the table by right-clicking on the table and selecting "Insert > Table rows above/below".
D41: 💡The application area is the same as the area under pasture / cropping by default. You can edit it if the application area is different.
D43: Organic fertiliser type (select) | E43: Percentage of N in fertiliser | F43: Amount applied (kg/hectare) | G43: Amount N applied (kg/hectare) | H43: Application area (ha) | I43: Total organic fertliser applied | J43: Total nitrogen applied (kg)
A44: =HYPERLINK("#A1", "▲ Back to top") -> ▲ Back to top | D44: Manure - Other | E44: 0.3 | F44: 10 | G44: =Table_Input_OrganicFertiliser[[#This Row],[Amount applied (kg/hectare)]]*Table_Input_OrganicFertiliser[[#This Row],[Percentage of N in fertiliser]] -> 3 | H44: =$E$9 -> 100 | I44: =Table_Input_OrganicFertiliser[[#This Row],[Amount applied (kg/hectare)]]*Table_Input_OrganicFertiliser[[#This Row],[Application area (ha)]] -> 1000 | J44: =IFERROR(Table_Input_OrganicFertiliser[[#This Row],[Amount N applied (kg/hectare)]]*Table_Input_OrganicFertiliser[[#This Row],[Application area (ha)]], 0) -> 300
D45: Manure - Poultry | E45: 0.25 | F45: 10 | G45: =Table_Input_OrganicFertiliser[[#This Row],[Amount applied (kg/hectare)]]*Table_Input_OrganicFertiliser[[#This Row],[Percentage of N in fertiliser]] -> 2.5 | H45: =$E$9 -> 100 | I45: =Table_Input_OrganicFertiliser[[#This Row],[Amount applied (kg/hectare)]]*Table_Input_OrganicFertiliser[[#This Row],[Application area (ha)]] -> 1000 | J45: =IFERROR(Table_Input_OrganicFertiliser[[#This Row],[Amount N applied (kg/hectare)]]*Table_Input_OrganicFertiliser[[#This Row],[Application area (ha)]], 0) -> 250

Sheet Input - Fuel
A1: #VALUE! | C1: Input - Fuel
A3: =HYPERLINK("#'Home'!A1", "Home") -> Home
A4: =HYPERLINK("#'Overview'!A1", "Overview") -> Overview
A5: =HYPERLINK("#'Results'!A1", "Results") -> Results | D5: Fuel purchases and consumption
A7: INPUTS | D7: 💡 You can add more rows to the table by right-clicking on the table and selecting "Insert > Table rows above/below"
A8: =HYPERLINK("#'Input - Fuel'!A1", "Fuel") -> Fuel | D8: 💡 'Percent consumed" is 100% by default. If you purchased more fuel than was consumed you can edit this field.
A10: CALCULATIONS | D10: Fuel use (select) | E10: Fuel type (select) | F10: Amount purchased | G10: Amount unit | H10: Percent consumed | I10: Amount consumed
A11: =HYPERLINK("#'8.1.1.1-2 Transport fuel'!A1", "8.1.1.1-2 Transport fuel") -> 8.1.1.1-2 Transport fuel | D11: Cars and light commercial vehicles | E11: Petrol | F11: 100000 | G11: {=Common_InputFunctions.Utility_LookupValueInTable(Table_Input_Fuel[[#This Row],[Fuel type (select)]],[1]!Table_FuelTypes_Units[Fuel type], [1]!Table_FuelTypes_Units[Unit])} -> kL | H11: =1 -> 1 | I11: =Table_Input_Fuel[[#This Row],[Amount purchased]]*Table_Input_Fuel[[#This Row],[Percent consumed]]*10^-3 -> 100
A12: =HYPERLINK("#'8.2.1.1-2 Stationary fuel'!A1", "8.2.1.1-2 Stationary fuel") -> 8.2.1.1-2 Stationary fuel
A13: =HYPERLINK("#'8.X.1.1-2 General use fuel'!A1", "8.X.1.1-2 General use fuel") -> 8.X.1.1-2 General use fuel
A15: APPENDICES
A16: =HYPERLINK("#'Constants - Fuel'!A1", "Constants - Fuel") -> Constants - Fuel
A17: =HYPERLINK("#'Constants - Common'!A1", "Constants - Common") -> Constants - Common

Sheet Sheet3
D4: Fuel
D6: Fuel use | E6: Fuel type (NGAF terminology) | F6: Fuel type (q)
D7: =[1]!Table_FuelTypesPerUse[[#Headers],[Cars and light commercial vehicles]] -> Cars and light commercial vehicles | E7: ='[1]Constants - Fuel'!$E$10 -> Gasoline | F7: ='[1]Constants - Fuel'!$G$131 -> Petrol | H7: {=Fuel_InputFunctions.Fuel_TotalConsumption(Table_Input_Fuel[Amount consumed], Table_Input_Fuel[Fuel use (select)], D7, Table_Input_Fuel[Fuel type (select)],F7)} -> 100
D8: =$D$25 -> 0 | E8: ='[1]Constants - Fuel'!$E$11 -> Diesel oil | F8: ='[1]Constants - Fuel'!$G$132 -> Diesel | H8: {=Fuel_InputFunctions.Fuel_TotalConsumption(Table_Input_Fuel[Amount consumed], Table_Input_Fuel[Fuel use (select)], D8, Table_Input_Fuel[Fuel type (select)],F8)} -> 0
D9: =$D$25 -> 0 | E9: ='[1]Constants - Fuel'!$E$12 -> Liquefied petroleum gas (LPG) | F9: ='[1]Constants - Fuel'!$G$133 -> Liquefied petroleum gas (LPG) | H9: {=Fuel_InputFunctions.Fuel_TotalConsumption(Table_Input_Fuel[Amount consumed], Table_Input_Fuel[Fuel use (select)], D9, Table_Input_Fuel[Fuel type (select)],F9)} -> 0
D10: =$D$25 -> 0 | E10: ='[1]Constants - Fuel'!$E$13 -> Fuel oil | F10: ='[1]Constants - Fuel'!$G$134 -> Fuel oil | H10: {=Fuel_InputFunctions.Fuel_TotalConsumption(Table_Input_Fuel[Amount consumed], Table_Input_Fuel[Fuel use (select)], D10, Table_Input_Fuel[Fuel type (select)],F10)} -> 0
D11: =$D$25 -> 0 | E11: ='[1]Constants - Fuel'!$E$14 -> Ethanol | F11: ='[1]Constants - Fuel'!$G$135 -> Ethanol | H11: {=Fuel_InputFunctions.Fuel_TotalConsumption(Table_Input_Fuel[Amount consumed], Table_Input_Fuel[Fuel use (select)], D11, Table_Input_Fuel[Fuel type (select)],F11)} -> 0
D12: =$D$25 -> 0 | E12: ='[1]Constants - Fuel'!$E$15 -> Biodiesel | F12: ='[1]Constants - Fuel'!$G$136 -> Biodiesel | H12: {=Fuel_InputFunctions.Fuel_TotalConsumption(Table_Input_Fuel[Amount consumed], Table_Input_Fuel[Fuel use (select)], D12, Table_Input_Fuel[Fuel type (select)],F12)} -> 0
D13: =$D$25 -> 0 | E13: ='[1]Constants - Fuel'!$E$16 -> Renewable diesel | F13: ='[1]Constants - Fuel'!$G$137 -> Renewable diesel | H13: {=Fuel_InputFunctions.Fuel_TotalConsumption(Table_Input_Fuel[Amount consumed], Table_Input_Fuel[Fuel use (select)], D13, Table_Input_Fuel[Fuel type (select)],F13)} -> 0
D14: =$D$25 -> 0 | E14: ='[1]Constants - Fuel'!$E$17 -> Other biofuels | F14: ='[1]Constants - Fuel'!$G$138 -> Other biofuels | H14: {=Fuel_InputFunctions.Fuel_TotalConsumption(Table_Input_Fuel[Amount consumed], Table_Input_Fuel[Fuel use (select)], D14, Table_Input_Fuel[Fuel type (select)],F14)} -> 0
D15: =[1]!Table_FuelTypesPerUse[[#Headers],[Off-road Agriculture and forestry equipment]] -> Off-road Agriculture and forestry equipment | E15: ='[1]Constants - Fuel'!$E$11 -> Diesel oil | F15: ='[1]Constants - Fuel'!$H$131 -> Diesel | H15: {=Fuel_InputFunctions.Fuel_TotalConsumption(Table_Input_Fuel[Amount consumed], Table_Input_Fuel[Fuel use (select)], D15, Table_Input_Fuel[Fuel type (select)],F15)} -> 0
D16: =[1]!Table_FuelTypesPerUse[[#Headers],[Aviation]] -> Aviation | E16: ='[1]Constants - Fuel'!$E$28 -> Gasoline for use as fuel in an aircraft | F16: ='[1]Constants - Fuel'!F$131 -> Avgas | H16: {=Fuel_InputFunctions.Fuel_TotalConsumption(Table_Input_Fuel[Amount consumed], Table_Input_Fuel[Fuel use (select)], D16, Table_Input_Fuel[Fuel type (select)],F16)} -> 0
D17: =$D$34 -> 0 | E17: ='[1]Constants - Fuel'!$E$29 -> Kerosene for use as fuel in an aircraft | F17: ='[1]Constants - Fuel'!F$132 -> Jet A1, Jet B | H17: {=Fuel_InputFunctions.Fuel_TotalConsumption(Table_Input_Fuel[Amount consumed], Table_Input_Fuel[Fuel use (select)], D17, Table_Input_Fuel[Fuel type (select)],F17)} -> 0
D18: =$D$34 -> 0 | E18: ='[1]Constants - Fuel'!$E$30 -> Renewable aviation kerosene | F18: ='[1]Constants - Fuel'!F$133 -> Renewable aviation kerosene | H18: {=Fuel_InputFunctions.Fuel_TotalConsumption(Table_Input_Fuel[Amount consumed], Table_Input_Fuel[Fuel use (select)], D18, Table_Input_Fuel[Fuel type (select)],F18)} -> 0
D19: =[1]!Table_FuelTypesPerUse[[#Headers],[Vessels]] -> Vessels | E19: ='[1]Constants - Fuel'!$E$10 -> Gasoline | F19: ='[1]Constants - Fuel'!I$131 -> Petrol | H19: {=Fuel_InputFunctions.Fuel_TotalConsumption(Table_Input_Fuel[Amount consumed], Table_Input_Fuel[Fuel use (select)], D19, Table_Input_Fuel[Fuel type (select)],F19)} -> 0
D20: =D19 -> Vessels | E20: ='[1]Constants - Fuel'!$E$11 -> Diesel oil | F20: ='[1]Constants - Fuel'!I$132 -> Diesel | H20: {=Fuel_InputFunctions.Fuel_TotalConsumption(Table_Input_Fuel[Amount consumed], Table_Input_Fuel[Fuel use (select)], D20, Table_Input_Fuel[Fuel type (select)],F20)} -> 0
D21: =D19 -> Vessels | E21: ='[1]Constants - Fuel'!$E$33 -> Fuel Oil | F21: ='[1]Constants - Fuel'!I$133 -> Fuel oil | H21: {=Fuel_InputFunctions.Fuel_TotalConsumption(Table_Input_Fuel[Amount consumed], Table_Input_Fuel[Fuel use (select)], D21, Table_Input_Fuel[Fuel type (select)],F21)} -> 0

Sheet 5.1.1.1-2 Inorganic fert N2O
A1: #VALUE! | C1: 5.1.1.1-2 Inorganic fertiliser application N2O emissions
A3: =HYPERLINK("#'Home'!A1", "Home") -> Home | D3: Method 1 | M3: Method 2
A4: =HYPERLINK("#'Overview'!A1", "Overview") -> Overview
A5: =HYPERLINK("#'Results'!A1", "Results") -> Results | D5: {=Fertiliser_Equations_InorganicN2O.VEERG_5_1_1_1__2_MassOfNitrogenInInorganicFertiliser_Title()} -> Mass of nitrogen in inorganic fertiliser applied to production system | M5: {=Fertiliser_Equations_InorganicN2O.VEERG_5_1_1_2__1_EmissionFactorIrrigatedMaize_Title()} -> Emission factor for nitrous oxide for irrigated maize
D6: {=Fertiliser_Equations_InorganicN2O.VEERG_5_1_1_1__2_MassOfNitrogenInInorganicFertiliser_Source()} -> VEERG 2026: 5.1.1.1, Equation (2) | M6: {=Fertiliser_Equations_InorganicN2O.VEERG_5_1_1_2__1_EmissionFactorIrrigatedMaize_Source()} -> VEERG 2026: 5.1.1.2, Equation (1)
A7: INPUTS | D7: Function name | E7: {=Common_InputFunctions.Utility_DisplayFunctionName(G19)} -> =Fertiliser_Equations_InorganicN2O.VEERG_5_1_1_1__2_MassOfNitrogenInInorganicFertiliser
A8: =HYPERLINK("#'Input - Site'!A1", "Site") -> Site
A9: =HYPERLINK("#'Input - Fertiliser'!A1", "Fertiliser") -> Fertiliser | M9: Variable | N9: {=Fertiliser_Equations_InorganicN2O.VEERG_5_1_1_2__1_EmissionFactorIrrigatedMaize_Variable()} -> EF_fjIrrigatedMaizeN2O
D10: Variable | E10: {=Fertiliser_Equations_InorganicN2O.VEERG_5_1_1_1__2_MassOfNitrogenInInorganicFertiliser_Variable()} -> MN_jf | M10: Unit | N10: {=Fertiliser_Equations_InorganicN2O.VEERG_5_1_1_2__1_EmissionFactorIrrigatedMaize_Unit()} -> kg N2O-N/kg N applied
A11: CALCULATIONS | D11: Unit | E11: {=Fertiliser_Equations_InorganicN2O.VEERG_5_1_1_1__2_MassOfNitrogenInInorganicFertiliser_Unit()} -> kg N
A12: =HYPERLINK("#'5.1.1.1-2 Inorganic Fert N2O'!A1", "5.1.1.1-2 Inorganic Fert N2O") -> 5.1.1.1-2 Inorganic Fert N2O | M12: {=_xlfn.CHOOSECOLS(Fertiliser_Equations_InorganicN2O.VEERG_5_1_1_2__1_EmissionFactorIrrigatedMaize_Arguments(), 1, 2)} -> N_fjIrrigatedMaize | N12: application rate of inorganic fertiliser type f in the irrigated maize crop | P12: {=_xlfn.CHOOSECOLS(Fertiliser_Equations_InorganicN2O.VEERG_5_1_1_2__1_EmissionFactorIrrigatedMaize_Arguments(), 3,4)} -> kg N/ha | Q12: Input | R12: {=HYPERLINK(Common_InputFunctions.Utility_SourceHyperlink($M$41), $M$41)} -> M2_Table_FertApplications
A13: =HYPERLINK("#'5.1.1.3-4 Inorganic fert CO2'!A1", "5.1.1.3-4 Inorganic fert CO2") -> 5.1.1.3-4 Inorganic fert CO2 | D13: {=_xlfn.CHOOSECOLS(Fertiliser_Equations_InorganicN2O.VEERG_5_1_1_1__2_MassOfNitrogenInInorganicFertiliser_Arguments(), 1,2)} -> TM_jf | E13: total mass of inorganic fertiliser type f applied to production system j | G13: {=_xlfn.CHOOSECOLS(Fertiliser_Equations_InorganicN2O.VEERG_5_1_1_1__2_MassOfNitrogenInInorganicFertiliser_Arguments(), 3,4)} -> kg | H13: Input | I13: {=HYPERLINK(Common_InputFunctions.Utility_SourceHyperlink($D$16), $D$16)} -> Table_MN_j_f | M13: f | N13: Inorganic fertiliser type | Q13: Constant | R13: Not used - application rate calculated per product blend application
A14: =HYPERLINK("#'5.2.1.1-2 Organic Fert N2O'!A1", "5.2.1.1-2 Organic Fert N2O") -> 5.2.1.1-2 Organic Fert N2O | D14: FN_inorganicf | E14: fraction of nitrogen in inorganic fertiliser type f | G14: kg N/kg | H14: Constant | I14: {=HYPERLINK(Common_InputFunctions.Utility_SourceHyperlink($D$16), $D$16)} -> Table_MN_j_f
A15: =HYPERLINK("#'5.3.1.1-2 Lime CO2'!A1", "5.3.1.1-2 Lime CO2") -> 5.3.1.1-2 Lime CO2
A16: =HYPERLINK("#'5.4.1.1-4 Atmos deposition'!A1", "5.4.1.1-4 Atmos deposition") -> 5.4.1.1-4 Atmos deposition | D16: Table_MN_j_f | M16: {=Fertiliser_Equations_InorganicN2O.VEERG_5_1_1_2__2_EmissionFactorNonIrrigatedGrainsHighRainfall_Title()} -> Emission factor for nitrous oxide for non-irrigated grains in high rainfall zone
A17: =HYPERLINK("#'5.5.1.1-2 Leaching and runoff'!A1", "5.5.1.1-2 Leaching and runoff") -> 5.5.1.1-2 Leaching and runoff | D17: Mass of nitrogen applied | M17: {=Fertiliser_Equations_InorganicN2O.VEERG_5_1_1_2__2_EmissionFactorNonIrrigatedGrainsHighRainfall_Source()} -> VEERG 2026: 5.1.1.2, Equation (2)
D18: Fertiliser type f | E18: TMjf | F18: FNinorganic,f | G18: MNjf
A19: APPENDICES | D19: {=Table_Fertiliser_ChemicalCompounds[Fertiliser type f]} -> Monoammonium phosphate (MAP) | E19: {=Fertiliser_InputFunctions.Fertiliser_TotalChemicalCompoundAppliedAllIngredients($D19,Table_Input_InorganicFertiliser_Brands[Total applied (kg)],Table_Input_InorganicFertiliser_Brands[Ingredient 1],Table_Input_InorganicFertiliser_Brands[Ingredient 1 percent],Table_Input_InorganicFertiliser_Brands[Ingredient 2],Table_Input_InorganicFertiliser_Brands[Ingredient 2 percent],Table_Input_InorganicFertiliser_Brands[Ingredient 3],Table_Input_InorganicFertiliser_Brands[Ingredient 3 percent],Table_Input_InorganicFertiliser_Brands[Ingredient 4],Table_Input_InorganicFertiliser_Brands[Ingredient 4 percent],Table_Input_InorganicFertiliser_Brands[Ingredient 5],Table_Input_InorganicFertiliser_Brands[Ingredient 5 percent],Table_Input_InorganicFertiliser_Brands[Ingredient 6],Table_Input_InorganicFertiliser_Brands[Ingredient 6 percent])+ Fertiliser_InputFunctions.Fertiliser_TotalChemicalCompoundAppliedAllIngredients($D19,Table_Input_InorganicFertiliser_Custom[Total applied (kg)],Table_Input_InorganicFertiliser_Custom[Ingredient 1 (select)],Table_Input_InorganicFertiliser_Custom[Ingredient 1 percent],Table_Input_InorganicFertiliser_Custom[Ingredient 2],Table_Input_InorganicFertiliser_Custom[Ingredient 2 percent],Table_Input_InorganicFertiliser_Custom[Ingredient 3],Table_Input_InorganicFertiliser_Custom[Ingredient 3 percent],Table_Input_InorganicFertiliser_Custom[Ingredient 4],Table_Input_InorganicFertiliser_Custom[Ingredient 4 percent])} -> 0 | F19: {=Common_InputFunctions.Utility_LookupValueInTableNumber(D19,Table_Fertiliser_ChemicalCompounds[Fertiliser type f],Table_Fertiliser_ChemicalCompounds[FNinorganic f])} -> 0.1 | G19: {=Fertiliser_Equations_InorganicN2O.VEERG_5_1_1_1__2_MassOfNitrogenInInorganicFertiliser(E19,F19)} -> 0
A20: =HYPERLINK("#'Constants - Fertiliser'!A1", "Constants - Fertiliser") -> Constants - Fertiliser | D20: Diammonium phosphate (DAP) | E20: {=Fertiliser_InputFunctions.Fertiliser_TotalChemicalCompoundAppliedAllIngredients($D20,Table_Input_InorganicFertiliser_Brands[Total applied (kg)],Table_Input_InorganicFertiliser_Brands[Ingredient 1],Table_Input_InorganicFertiliser_Brands[Ingredient 1 percent],Table_Input_InorganicFertiliser_Brands[Ingredient 2],Table_Input_InorganicFertiliser_Brands[Ingredient 2 percent],Table_Input_InorganicFertiliser_Brands[Ingredient 3],Table_Input_InorganicFertiliser_Brands[Ingredient 3 percent],Table_Input_InorganicFertiliser_Brands[Ingredient 4],Table_Input_InorganicFertiliser_Brands[Ingredient 4 percent],Table_Input_InorganicFertiliser_Brands[Ingredient 5],Table_Input_InorganicFertiliser_Brands[Ingredient 5 percent],Table_Input_InorganicFertiliser_Brands[Ingredient 6],Table_Input_InorganicFertiliser_Brands[Ingredient 6 percent])+ Fertiliser_InputFunctions.Fertiliser_TotalChemicalCompoundAppliedAllIngredients($D20,Table_Input_InorganicFertiliser_Custom[Total applied (kg)],Table_Input_InorganicFertiliser_Custom[Ingredient 1 (select)],Table_Input_InorganicFertiliser_Custom[Ingredient 1 percent],Table_Input_InorganicFertiliser_Custom[Ingredient 2],Table_Input_InorganicFertiliser_Custom[Ingredient 2 percent],Table_Input_InorganicFertiliser_Custom[Ingredient 3],Table_Input_InorganicFertiliser_Custom[Ingredient 3 percent],Table_Input_InorganicFertiliser_Custom[Ingredient 4],Table_Input_InorganicFertiliser_Custom[Ingredient 4 percent])} -> 0 | F20: {=Common_InputFunctions.Utility_LookupValueInTableNumber(D20,Table_Fertiliser_ChemicalCompounds[Fertiliser type f],Table_Fertiliser_ChemicalCompounds[FNinorganic f])} -> 0.18 | G20: {=Fertiliser_Equations_InorganicN2O.VEERG_5_1_1_1__2_MassOfNitrogenInInorganicFertiliser(E20,F20)} -> 0 | M20: Variable | N20: {=Fertiliser_Equations_InorganicN2O.VEERG_5_1_1_2__2_EmissionFactorNonIrrigatedGrainsHighRainfall_Variable()} -> EF_fjNonIrrigatedGrainsN2O
A21: =HYPERLINK("#'Constants - Common'!A1", "Constants - Common") -> Constants - Common | D21: Urea | E21: {=Fertiliser_InputFunctions.Fertiliser_TotalChemicalCompoundAppliedAllIngredients($D21,Table_Input_InorganicFertiliser_Brands[Total applied (kg)],Table_Input_InorganicFertiliser_Brands[Ingredient 1],Table_Input_InorganicFertiliser_Brands[Ingredient 1 percent],Table_Input_InorganicFertiliser_Brands[Ingredient 2],Table_Input_InorganicFertiliser_Brands[Ingredient 2 percent],Table_Input_InorganicFertiliser_Brands[Ingredient 3],Table_Input_InorganicFertiliser_Brands[Ingredient 3 percent],Table_Input_InorganicFertiliser_Brands[Ingredient 4],Table_Input_InorganicFertiliser_Brands[Ingredient 4 percent],Table_Input_InorganicFertiliser_Brands[Ingredient 5],Table_Input_InorganicFertiliser_Brands[Ingredient 5 percent],Table_Input_InorganicFertiliser_Brands[Ingredient 6],Table_Input_InorganicFertiliser_Brands[Ingredient 6 percent])+ Fertiliser_InputFunctions.Fertiliser_TotalChemicalCompoundAppliedAllIngredients($D21,Table_Input_InorganicFertiliser_Custom[Total applied (kg)],Table_Input_InorganicFertiliser_Custom[Ingredient 1 (select)],Table_Input_InorganicFertiliser_Custom[Ingredient 1 percent],Table_Input_InorganicFertiliser_Custom[Ingredient 2],Table_Input_InorganicFertiliser_Custom[Ingredient 2 percent],Table_Input_InorganicFertiliser_Custom[Ingredient 3],Table_Input_InorganicFertiliser_Custom[Ingredient 3 percent],Table_Input_InorganicFertiliser_Custom[Ingredient 4],Table_Input_InorganicFertiliser_Custom[Ingredient 4 percent])} -> 12913.043 | F21: {=Common_InputFunctions.Utility_LookupValueInTableNumber(D21,Table_Fertiliser_ChemicalCompounds[Fertiliser type f],Table_Fertiliser_ChemicalCompounds[FNinorganic f])} -> 0.46 | G21: {=Fertiliser_Equations_InorganicN2O.VEERG_5_1_1_1__2_MassOfNitrogenInInorganicFertiliser(E21,F21)} -> 5940 | M21: Unit | N21: {=Fertiliser_Equations_InorganicN2O.VEERG_5_1_1_2__2_EmissionFactorNonIrrigatedGrainsHighRainfall_Unit()} -> kg N2O-N/kg N applied
