Workbook
Name AgResidue_Equations_FieldBurning.VEERG_6_4_1_1__1__MethaneEmissionsFromBurningOfCropResidues: _xlfn.LAMBDA(_xlpm.Mburnc,_xlpm.CCc,_xlpm.EFCH4,_xlpm.C_CH4, _xlpm.Mburnc * _xlpm.CCc * _xlpm.EFCH4 * _xlpm.C_CH4 * 10 ^ (-3))
Name AgResidue_Equations_FieldBurning.VEERG_6_4_1_1__1__MethaneEmissionsFromBurningOfCropResidues_FunctionName: _xlfn.LAMBDA("VEERG_6_4_1_1__1__MethaneEmissionsFromBurningOfCropResidues")
Name AgResidue_Equations_FieldBurning.VEERG_6_4_1_1__1__MethaneEmissionsFromBurningOfCropResidues_LatexEquation: _xlfn.LAMBDA("E_{CH4}=\sum_{c}(M_{burn,c}\times CC_{c}\times EF_{CH4}\times C_{CH4}\times 10^{-3})")
Name AgResidue_Equations_FieldBurning.VEERG_6_4_1_1__1__MethaneEmissionsFromBurningOfCropResidues_NIRReference: _xlfn.LAMBDA("")
Name AgResidue_Equations_FieldBurning.VEERG_6_4_1_1__1__MethaneEmissionsFromBurningOfCropResidues_Source: _xlfn.LAMBDA("VEERG 2026: 6.4.1.1, Equation (1)")
Name AgResidue_Equations_FieldBurning.VEERG_6_4_1_1__1__MethaneEmissionsFromBurningOfCropResidues_Title: _xlfn.LAMBDA("Methane emissions from the burning of crop residues")
Name AgResidue_Equations_FieldBurning.VEERG_6_4_1_1__1__MethaneEmissionsFromBurningOfCropResidues_Unit: _xlfn.LAMBDA("t CH4")
Name AgResidue_Equations_FieldBurning.VEERG_6_4_1_1__1__MethaneEmissionsFromBurningOfCropResidues_Variable: _xlfn.LAMBDA("ECH4")
Name AgResidue_Equations_FieldBurning.VEERG_6_4_1_1__2__NitrousOxideEmissionsFromBurningOfCropResidues: _xlfn.LAMBDA(_xlpm.Mburnc,_xlpm.NCAGc,_xlpm.EFN2O,_xlpm.CN2O, _xlpm.Mburnc * _xlpm.NCAGc * _xlpm.EFN2O * _xlpm.CN2O * 10 ^ (-3))
Name AgResidue_Equations_FieldBurning.VEERG_6_4_1_1__2__NitrousOxideEmissionsFromBurningOfCropResidues_FunctionName: _xlfn.LAMBDA("VEERG_6_4_1_1__2__NitrousOxideEmissionsFromBurningOfCropResidues")
Name AgResidue_Equations_FieldBurning.VEERG_6_4_1_1__2__NitrousOxideEmissionsFromBurningOfCropResidues_LatexEquation: _xlfn.LAMBDA("E_{N2O}=\sum_{c}(M_{burn,c}\times NC_{AGc}\times EF_{N2O}\times C_{N2O}\times 10^{-3})")
Name AgResidue_Equations_FieldBurning.VEERG_6_4_1_1__2__NitrousOxideEmissionsFromBurningOfCropResidues_NIRReference: _xlfn.LAMBDA("")
Name AgResidue_Equations_FieldBurning.VEERG_6_4_1_1__2__NitrousOxideEmissionsFromBurningOfCropResidues_Source: _xlfn.LAMBDA("VEERG 2026: 6.4.1.1, Equation (2)")
Name AgResidue_Equations_FieldBurning.VEERG_6_4_1_1__2__NitrousOxideEmissionsFromBurningOfCropResidues_Title: _xlfn.LAMBDA("Nitrous oxide emissions from the burning of crop residues")
Name AgResidue_Equations_FieldBurning.VEERG_6_4_1_1__2__NitrousOxideEmissionsFromBurningOfCropResidues_Unit: _xlfn.LAMBDA("t N2O")
Name AgResidue_Equations_FieldBurning.VEERG_6_4_1_1__2__NitrousOxideEmissionsFromBurningOfCropResidues_Variable: _xlfn.LAMBDA("EN2O")
Name AgResidue_Equations_FieldBurning.VEERG_6_4_1_1__3__MassOfCropResidueBurnt: _xlfn.LAMBDA(_xlpm.Pc,_xlpm.RAGc,_xlpm.Sc,_xlpm.DMc,_xlpm.Zc,_xlpm.Fc, _xlpm.Pc * _xlpm.RAGc * _xlpm.Sc * _xlpm.DMc * _xlpm.Zc * _xlpm.Fc)
Name AgResidue_Equations_FieldBurning.VEERG_6_4_1_1__3__MassOfCropResidueBurnt_FunctionName: _xlfn.LAMBDA("VEERG_6_4_1_1__3__MassOfCropResidueBurnt")
Name AgResidue_Equations_FieldBurning.VEERG_6_4_1_1__3__MassOfCropResidueBurnt_LatexEquation: _xlfn.LAMBDA("M_{burn,c}=P_{c}\times R_{AGc}\times S_{c}\times DM_{c}\times Z_{c}\times F_{c}")
Name AgResidue_Equations_FieldBurning.VEERG_6_4_1_1__3__MassOfCropResidueBurnt_NIRReference: _xlfn.LAMBDA("")
Name AgResidue_Equations_FieldBurning.VEERG_6_4_1_1__3__MassOfCropResidueBurnt_Source: _xlfn.LAMBDA("VEERG 2026: 6.4.1.1, Equation (3)")
Name AgResidue_Equations_FieldBurning.VEERG_6_4_1_1__3__MassOfCropResidueBurnt_Title: _xlfn.LAMBDA("Mass of residue of crop c burnt")
Name AgResidue_Equations_FieldBurning.VEERG_6_4_1_1__3__MassOfCropResidueBurnt_Unit: _xlfn.LAMBDA("kg")
Name AgResidue_Equations_FieldBurning.VEERG_6_4_1_1__3__MassOfCropResidueBurnt_Variable: _xlfn.LAMBDA("Mburnc")
Name AgResidues_Equations_CropResidues.VEERG_6_1_1_1__1__NitrousOxideEmissionsFromCropResidues: _xlfn.LAMBDA(_xlpm.Mc,_xlpm.EFNi,_xlpm.CgN2O, _xlpm.Mc * _xlpm.EFNi * _xlpm.CgN2O * 10 ^ (-3))
Name AgResidues_Equations_CropResidues.VEERG_6_1_1_1__1__NitrousOxideEmissionsFromCropResidues_FunctionName: _xlfn.LAMBDA("VEERG_6_1_1_1__1__NitrousOxideEmissionsFromCropResidues")
Name AgResidues_Equations_CropResidues.VEERG_6_1_1_1__1__NitrousOxideEmissionsFromCropResidues_LatexEquation: _xlfn.LAMBDA("E=\sum_{c}{M_{c}\times EF_{N}\times C_{g,N2O}\times 10^{-3}}")
Name AgResidues_Equations_CropResidues.VEERG_6_1_1_1__1__NitrousOxideEmissionsFromCropResidues_NIRReference: _xlfn.LAMBDA("")
Name AgResidues_Equations_CropResidues.VEERG_6_1_1_1__1__NitrousOxideEmissionsFromCropResidues_Source: _xlfn.LAMBDA("VEERG 2026: 6.1.1.1, Equation (1)")
Name AgResidues_Equations_CropResidues.VEERG_6_1_1_1__1__NitrousOxideEmissionsFromCropResidues_Title: _xlfn.LAMBDA("Nitrous oxide emissions from the return of crop residues across all crops c to the soil")
Name AgResidues_Equations_CropResidues.VEERG_6_1_1_1__1__NitrousOxideEmissionsFromCropResidues_Unit: _xlfn.LAMBDA("t N2O")
Name AgResidues_Equations_CropResidues.VEERG_6_1_1_1__1__NitrousOxideEmissionsFromCropResidues_Variable: _xlfn.LAMBDA("E")
Name AgResidues_Equations_CropResidues.VEERG_6_1_1_1__2__MassOfNitrogenInCropResidues_LatexEquation: _xlfn.LAMBDA("M_{c}=(P_{c}\times R_{AGc}\times(1-F_{c}-FFOD_{c})\times DM_{c}\times NC_{AGc})+(P_{c}\times R_{AGc}\times R_{BGc}\times DM_{c}\times NC_{BGc})")
Name AgResidues_Equations_CropResidues.VEERG_6_1_1_1__2__MassOfNitrogenInCropResidues_NIRReference: _xlfn.LAMBDA("")
Name AgResidues_Equations_CropResidues.VEERG_6_1_1_1__2__MassOfNitrogenInCropResidues_Source: _xlfn.LAMBDA("VEERG 2026: 6.1.1.1, Equation (2)")
Name AgResidues_Equations_CropResidues.VEERG_6_1_1_1__2__MassOfNitrogenInCropResidues_Title: _xlfn.LAMBDA("Mass of nitrogen in crop residues returned to the soil")
Name AgResidues_Equations_CropResidues.VEERG_6_1_1_1__2__MassOfNitrogenInCropResidues_Unit: _xlfn.LAMBDA("kg N")
Name AgResidues_Equations_CropResidues.VEERG_6_1_1_1__2__MassOfNitrogenInCropResidues_Variable: _xlfn.LAMBDA("Mc")
Name AgResidues_Equations_CropResidues.VEERG_6_1_1_2__1__FractionOfCropResidueRemovedBaled: _xlfn.LAMBDA(_xlpm.B,_xlpm.MB,_xlpm.Pc,_xlpm.RAGc, IFERROR((_xlpm.B * _xlpm.MB) / (_xlpm.Pc * _xlpm.RAGc), 0))
Name AgResidues_Equations_CropResidues.VEERG_6_1_1_2__1__FractionOfCropResidueRemovedBaled_LatexEquation: _xlfn.LAMBDA("FFOD_{c,baled}=\frac{B\times M_{B}}{P_{c}\times R_{AG,c}}")
Name AgResidues_Equations_CropResidues.VEERG_6_1_1_2__1__FractionOfCropResidueRemovedBaled_NIRReference: _xlfn.LAMBDA("")
Name AgResidues_Equations_CropResidues.VEERG_6_1_1_2__1__FractionOfCropResidueRemovedBaled_Source: _xlfn.LAMBDA("VEERG 2026: 6.1.1.2, Equation (1)")
Name AgResidues_Equations_CropResidues.VEERG_6_1_1_2__1__FractionOfCropResidueRemovedBaled_Title: _xlfn.LAMBDA("Fraction of crop residue that is removed for crop c, calculated where residues are baled")
Name AgResidues_Equations_CropResidues.VEERG_6_1_1_2__1__FractionOfCropResidueRemovedBaled_Unit: _xlfn.LAMBDA("dimensionless")
Name AgResidues_Equations_CropResidues.VEERG_6_1_1_2__1__FractionOfCropResidueRemovedBaled_Variable: _xlfn.LAMBDA("FFODcbaled")
Name AgResidues_Equations_CropResidues.VEERG_6_1_1_2__1__FractionOfCropResidueRemovedBaled_Variation: _xlfn.LAMBDA("VARIATION FROM SOURCE: Added 'baled' to variable subscript")
Name AgResidues_Equations_CropResidues.VEERG_6_1_1_2__1a__FractionOfCropResidueRemoved: _xlfn.LAMBDA(_xlpm.FFODcbaled,_xlpm.FFODcother, _xlpm.FFODcbaled + _xlpm.FFODcother)
Name AgResidues_Equations_CropResidues.VEERG_6_1_1_2__1a__FractionOfCropResidueRemoved_LatexEquation: _xlfn.LAMBDA("FFOD_{c} = FFOD_{c,baled} + FFOD_{c,other}")
Name AgResidues_Equations_CropResidues.VEERG_6_1_1_2__1a__FractionOfCropResidueRemoved_NIRReference: _xlfn.LAMBDA("")
Name AgResidues_Equations_CropResidues.VEERG_6_1_1_2__1a__FractionOfCropResidueRemoved_Source: _xlfn.LAMBDA("")
Name AgResidues_Equations_CropResidues.VEERG_6_1_1_2__1a__FractionOfCropResidueRemoved_Title: _xlfn.LAMBDA("Fraction of crop residue that is removed for crop c")
Name AgResidues_Equations_CropResidues.VEERG_6_1_1_2__1a__FractionOfCropResidueRemoved_Unit: _xlfn.LAMBDA("dimensionless")
Name AgResidues_Equations_CropResidues.VEERG_6_1_1_2__1a__FractionOfCropResidueRemoved_Variable: _xlfn.LAMBDA("FFODc")
Name AgResidues_Equations_CropResidues.VEERG_6_1_1_2__1a__FractionOfCropResidueRemoved_Variation: _xlfn.LAMBDA("VARIATION FROM SOURCE: Added this equation to accommodate user-defined residue removal other than baling.")
Name AgResidues_Equations_Leaching.VEERG_6_3_1_1__1__LeachingAndRunoffEmissionsCropAndPastureResidue: _xlfn.LAMBDA(_xlpm.Mleachcp,_xlpm.EFleach,_xlpm.CgN2O, _xlpm.Mleachcp * _xlpm.EFleach * _xlpm.CgN2O * 10 ^ (-3))
Name AgResidues_Equations_Leaching.VEERG_6_3_1_1__1__LeachingAndRunoffEmissionsCropAndPastureResidue_LatexEquation: _xlfn.LAMBDA("E_{N2O}=\sum_{c}\sum_{p}(M_{leach,cp}\times EF_{leach}\times Cg_{N2O}\times 10^{-3})")
Name AgResidues_Equations_Leaching.VEERG_6_3_1_1__1__LeachingAndRunoffEmissionsCropAndPastureResidue_NIRReference: _xlfn.LAMBDA("")
Name AgResidues_Equations_Leaching.VEERG_6_3_1_1__1__LeachingAndRunoffEmissionsCropAndPastureResidue_Source: _xlfn.LAMBDA("VEERG 2026: 6.3.1.1, Equation (1)")
Name AgResidues_Equations_Leaching.VEERG_6_3_1_1__1__LeachingAndRunoffEmissionsCropAndPastureResidue_Title: _xlfn.LAMBDA("Nitrous oxide leaching and runoff emissions from crop and pasture residues returned to the soil")
Name AgResidues_Equations_Leaching.VEERG_6_3_1_1__1__LeachingAndRunoffEmissionsCropAndPastureResidue_Unit: _xlfn.LAMBDA("t N2O")

Sheet Input - Site
A1: #VALUE! | C1: Input - Site
A3: =HYPERLINK("#'Home'!A1", "Home") -> Home
A4: =HYPERLINK("#'Overview'!A1", "Overview") -> Overview
A5: =HYPERLINK("#'Results'!A1", "Results") -> Results | D5: Your business
A7: INPUTS | D7: Farm name | E7: Test Farms
A8: =HYPERLINK("#'Input - Electricity'!A1", "Electricity") -> Electricity | D8: Reporting entity name | E8: Test Farms Pty Ltd
A10: CALCULATIONS | D10: 💡An 'Emissions accounting period' is a 12 month period where the business can report on the emissions, and is typically the same as the business' financial accounting period.
A11: =HYPERLINK("#'14.1.1-2 Purchased electricity'!A1", "14.1.1-2 Purchased electricity") -> 14.1.1-2 Purchased electricity
D12: Emissions calculation period start date | E12: 45292 | F12: ← DD/MM/YYYY or DD Month YYYY
A13: APPENDICES | D13: Emissions calculation period end date | E13: =DATE(YEAR(E12)+1,MONTH(E12),DAY(E12))-1 -> 45657 | F13: ← Automatically calculated, 12 months after start date
A14: =HYPERLINK("#'Constants - Electricity'!A1", "Constants - Electricity") -> Constants - Electricity
A15: =HYPERLINK("#'Constants - Common'!A1", "Constants - Common") -> Constants - Common
D16: Location and climate
D18: Location information is used to reference some region and climate-specific emission factors
D19: Tip: Use the web-based GAF Location Helper tool to easily get region and climate information. You will need an internet connection to use the GAF Location Helper.
D21: State | E21: ACT | F21: ← Please select
D22: Region (ABS Statistical area level 4) if state is WA | E22: Western Australia - Outback (South) | F22: ← Please select

Sheet Input - Fertiliser
A1: #VALUE! | C1: Input - Fertiliser
A3: =HYPERLINK("#'Home'!A1", "Home") -> Home
A4: =HYPERLINK("#'Overview'!A1", "Overview") -> Overview
A5: =HYPERLINK("#'Results'!A1", "Results") -> Results
D6: Production system | E6: Crop | F6: ← Please select
A7: INPUTS | D7: Crop type | E7: Grains | F7: ← Please select
A8: =HYPERLINK("#'Input - Site'!A1", "Site") -> Site | D8: Irrigation method | E8: Drip irrigation | F8: ← Please select
A9: =HYPERLINK("#'Input - Fertiliser'!A1", "Fertiliser") -> Fertiliser | D9: Area under cropping | E9: 100 | F9: hectares
A11: CALCULATIONS | D11: Inorganic fertiliser applied
A12: =HYPERLINK("#'5.1.1.1-2 Inorganic Fert N2O'!A1", "5.1.1.1-2 Inorganic Fert N2O") -> 5.1.1.1-2 Inorganic Fert N2O
A13: =HYPERLINK("#'5.1.1.3-4 Inorganic fert CO2'!A1", "5.1.1.3-4 Inorganic fert CO2") -> 5.1.1.3-4 Inorganic fert CO2 | D13: 💡You can add more rows to tables by right-clicking on the table and selecting "Insert > Table rows above/below".
A14: =HYPERLINK("#'5.2.1.1-2 Organic Fert N2O'!A1", "5.2.1.1-2 Organic Fert N2O") -> 5.2.1.1-2 Organic Fert N2O | D14: 💡The application area is the same as the area under pasture / cropping by default. You can edit it if the application area is different.
A15: =HYPERLINK("#'5.3.1.1-2 Lime CO2'!A1", "5.3.1.1-2 Lime CO2") -> 5.3.1.1-2 Lime CO2
A16: =HYPERLINK("#'5.4.1.1-4 Atmos deposition'!A1", "5.4.1.1-4 Atmos deposition") -> 5.4.1.1-4 Atmos deposition | D16: Branded fertiliser products
A17: =HYPERLINK("#'5.5.1.1-2 Leaching and runoff'!A1", "5.5.1.1-2 Leaching and runoff") -> 5.5.1.1-2 Leaching and runoff | D17: Product (select) | E17: Amount applied per hectare | F17: Application unit | G17: Density | H17: Application area (ha) | I17: Total applied (kg) | J17: Ingredient 1 | K17: Ingredient 1 percent | L17: Ingredient 2 | M17: Ingredient 2 percent | N17: Ingredient 3 | O17: Ingredient 3 percent | P17: Ingredient 4 | Q17: Ingredient 4 percent | R17: Ingredient 5 | S17: Ingredient 5 percent | T17: Ingredient 6 | U17: Ingredient 6 percent | V17: N application rate (kg/ha) | W17: Urea source | X17: Ammonia source
D18: CoRoN 12-0-10 | E18: 100 | F18: =_xlfn.XLOOKUP(Table_Input_InorganicFertiliser_Brands[[#This Row],[Product (select)]],FertiliserProducts[Product name],FertiliserProducts[Unit]) -> L | G18: =_xlfn.XLOOKUP(Table_Input_InorganicFertiliser_Brands[[#This Row],[Product (select)]],FertiliserProducts[Product name],FertiliserProducts[Density / gravity]) -> 1.215 | H18: =$E$9 -> 100 | I18: =(Table_Input_InorganicFertiliser_Brands[[#This Row],[Amount applied per hectare]]*Table_Input_InorganicFertiliser_Brands[[#This Row],[Density]])*Table_Input_InorganicFertiliser_Brands[[#This Row],[Application area (ha)]] -> 12150 | J18: {=Fertiliser_InputFunctions.Fertiliser_FertiliserProductLookup(Table_Input_InorganicFertiliser_Brands[[#This Row],[Product (select)]], Table_Input_InorganicFertiliser_Brands[[#Headers],[Ingredient 1]], FertiliserProducts[#Data], FertiliserProducts[Product name], FertiliserProducts[#Headers])} -> Urea | K18: {=Fertiliser_InputFunctions.Fertiliser_FertiliserProductLookup(Table_Input_InorganicFertiliser_Brands[[#This Row],[Product (select)]], Table_Input_InorganicFertiliser_Brands[[#Headers],[Ingredient 1 percent]], FertiliserProducts[#Data], FertiliserProducts[Product name], FertiliserProducts[#Headers])} -> 0.19565217 | L18: {=Fertiliser_InputFunctions.Fertiliser_FertiliserProductLookup(Table_Input_InorganicFertiliser_Brands[[#This Row],[Product (select)]], Table_Input_InorganicFertiliser_Brands[[#Headers],[Ingredient 2]], FertiliserProducts[#Data], FertiliserProducts[Product name], FertiliserProducts[#Headers])} -> Potassium - Generic | M18: {=Fertiliser_InputFunctions.Fertiliser_FertiliserProductLookup(Table_Input_InorganicFertiliser_Brands[[#This Row],[Product (select)]], Table_Input_InorganicFertiliser_Brands[[#Headers],[Ingredient 2 percent]], FertiliserProducts[#Data], FertiliserProducts[Product name], FertiliserProducts[#Headers])} -> 0.1 | N18: {=Fertiliser_InputFunctions.Fertiliser_FertiliserProductLookup(Table_Input_InorganicFertiliser_Brands[[#This Row],[Product (select)]], Table_Input_InorganicFertiliser_Brands[[#Headers],[Ingredient 3]], FertiliserProducts[#Data], FertiliserProducts[Product name], FertiliserProducts[#Headers])} -> Nitrogen - Generic | O18: {=Fertiliser_InputFunctions.Fertiliser_FertiliserProductLookup(Table_Input_InorganicFertiliser_Brands[[#This Row],[Product (select)]], Table_Input_InorganicFertiliser_Brands[[#Headers],[Ingredient 3 percent]], FertiliserProducts[#Data], FertiliserProducts[Product name], FertiliserProducts[#Headers])} -> 0.03 | P18: {=Fertiliser_InputFunctions.Fertiliser_FertiliserProductLookup(Table_Input_InorganicFertiliser_Brands[[#This Row],[Product (select)]], Table_Input_InorganicFertiliser_Brands[[#Headers],[Ingredient 4]], FertiliserProducts[#Data], FertiliserProducts[Product name], FertiliserProducts[#Headers])} -> Boron | Q18: {=Fertiliser_InputFunctions.Fertiliser_FertiliserProductLookup(Table_Input_InorganicFertiliser_Brands[[#This Row],[Product (select)]], Table_Input_InorganicFertiliser_Brands[[#Headers],[Ingredient 4 percent]], FertiliserProducts[#Data], FertiliserProducts[Product name], FertiliserProducts[#Headers])} -> 0.005 | R18: {=Fertiliser_InputFunctions.Fertiliser_FertiliserProductLookup(Table_Input_InorganicFertiliser_Brands[[#This Row],[Product (select)]], Table_Input_InorganicFertiliser_Brands[[#Headers],[Ingredient 5]], FertiliserProducts[#Data], FertiliserProducts[Product name], FertiliserProducts[#Headers])} | S18: {=Fertiliser_InputFunctions.Fertiliser_FertiliserProductLookup(Table_Input_InorganicFertiliser_Brands[[#This Row],[Product (select)]], Table_Input_InorganicFertiliser_Brands[[#Headers],[Ingredient 5 percent]], FertiliserProducts[#Data], FertiliserProducts[Product name], FertiliserProducts[#Headers])} | T18: {=Fertiliser_InputFunctions.Fertiliser_FertiliserProductLookup(Table_Input_InorganicFertiliser_Brands[[#This Row],[Product (select)]], Table_Input_InorganicFertiliser_Brands[[#Headers],[Ingredient 6]], FertiliserProducts[#Data], FertiliserProducts[Product name], FertiliserProducts[#Headers])} | U18: {=Fertiliser_InputFunctions.Fertiliser_FertiliserProductLookup(Table_Input_InorganicFertiliser_Brands[[#This Row],[Product (select)]], Table_Input_InorganicFertiliser_Brands[[#Headers],[Ingredient 6 percent]], FertiliserProducts[#Data], FertiliserProducts[Product name], FertiliserProducts[#Headers])} | V18: =(Table_Input_InorganicFertiliser_Brands[[#This Row],[Amount applied per hectare]]*Table_Input_InorganicFertiliser_Brands[[#This Row],[Density]])*(IFERROR((_xlfn.XLOOKUP(Table_Input_InorganicFertiliser_Brands[[#This Row],[Ingredient 1]], Table_Fertiliser_ChemicalCompounds[Fertiliser type f],Table_Fertiliser_ChemicalCompounds[FNinorganic f])*Table_Input_InorganicFertiliser_Brands[[#This Row],[Ingredient 1 percent]]), 0)+ IFERROR((_xlfn.XLOOKUP(Table_Input_InorganicFertiliser_Brands[[#This Row],[Ingredient 2]],Table_Fertiliser_ChemicalCompounds[Fertiliser type f],Table_Fertiliser_ChemicalCompounds[FNinorganic f])*Table_Input_InorganicFertiliser_Brands[[#This Row],[Ingredient 2 percent]]), 0)+ IFERROR((_xlfn.XLOOKUP(Table_Input_InorganicFertiliser_Brands[[#This Row],[Ingredient 3]],Table_Fertiliser_ChemicalCompounds[Fertiliser type f],Table_Fertiliser_ChemicalCompounds[FNinorganic f])*Table_Input_InorganicFertiliser_Brands[[#This Row],[Ingredient 3 percent]]), 0)+ IFERROR((_xlfn.XLOOKUP(Table_Input_InorganicFertiliser_Brands[[#This Row],[Ingredient 4]],Table_Fertiliser_ChemicalCompounds[Fertiliser type f],Table_Fertiliser_ChemicalCompounds[FNinorganic f])*Table_Input_InorganicFertiliser_Brands[[#This Row],[Ingredient 4 percent]]), 0)+ IFERROR((_xlfn.XLOOKUP(Table_Input_InorganicFertiliser_Brands[[#This Row],[Ingredient 5]],Table_Fertiliser_ChemicalCompounds[Fertiliser type f],Table_Fertiliser_ChemicalCompounds[FNinorganic f])*Table_Input_InorganicFertiliser_Brands[[#This Row],[Ingredient 5 percent]]), 0)+ IFERROR((_xlfn.XLOOKUP(Table_Input_InorganicFertiliser_Brands[[#This Row],[Ingredient 6]],Table_Fertiliser_ChemicalCompounds[Fertiliser type f],Table_Fertiliser_ChemicalCompounds[FNinorganic f])*Table_Input_InorganicFertiliser_Brands[[#This Row],[Ingredient 6 percent]]), 0)) -> 14.58 | W18: =_xlfn.XLOOKUP(Table_Input_InorganicFertiliser_Brands[[#This Row],[Product (select)]],FertiliserProducts[Product name],FertiliserProducts[Urea source]) | X18: =_xlfn.XLOOKUP(Table_Input_InorganicFertiliser_Brands[[#This Row],[Product (select)]],FertiliserProducts[Product name],FertiliserProducts[Ammonia source])
A19: APPENDICES | D19: Boost-It | E19: 200 | F19: =_xlfn.XLOOKUP(Table_Input_InorganicFertiliser_Brands[[#This Row],[Product (select)]],FertiliserProducts[Product name],FertiliserProducts[Unit]) -> kg | G19: =_xlfn.XLOOKUP(Table_Input_InorganicFertiliser_Brands[[#This Row],[Product (select)]],FertiliserProducts[Product name],FertiliserProducts[Density / gravity]) -> 1 | H19: =$E$9 -> 100 | I19: =(Table_Input_InorganicFertiliser_Brands[[#This Row],[Amount applied per hectare]]*Table_Input_InorganicFertiliser_Brands[[#This Row],[Density]])*Table_Input_InorganicFertiliser_Brands[[#This Row],[Application area (ha)]] -> 20000 | J19: {=Fertiliser_InputFunctions.Fertiliser_FertiliserProductLookup(Table_Input_InorganicFertiliser_Brands[[#This Row],[Product (select)]], Table_Input_InorganicFertiliser_Brands[[#Headers],[Ingredient 1]], FertiliserProducts[#Data], FertiliserProducts[Product name], FertiliserProducts[#Headers])} -> Urea | K19: {=Fertiliser_InputFunctions.Fertiliser_FertiliserProductLookup(Table_Input_InorganicFertiliser_Brands[[#This Row],[Product (select)]], Table_Input_InorganicFertiliser_Brands[[#Headers],[Ingredient 1 percent]], FertiliserProducts[#Data], FertiliserProducts[Product name], FertiliserProducts[#Headers])} -> 0.52173913 | L19: {=Fertiliser_InputFunctions.Fertiliser_FertiliserProductLookup(Table_Input_InorganicFertiliser_Brands[[#This Row],[Product (select)]], Table_Input_InorganicFertiliser_Brands[[#Headers],[Ingredient 2]], FertiliserProducts[#Data], FertiliserProducts[Product name], FertiliserProducts[#Headers])} -> Potassium - Generic | M19: {=Fertiliser_InputFunctions.Fertiliser_FertiliserProductLookup(Table_Input_InorganicFertiliser_Brands[[#This Row],[Product (select)]], Table_Input_InorganicFertiliser_Brands[[#Headers],[Ingredient 2 percent]], FertiliserProducts[#Data], FertiliserProducts[Product name], FertiliserProducts[#Headers])} -> 0.08 | N19: {=Fertiliser_InputFunctions.Fertiliser_FertiliserProductLookup(Table_Input_InorganicFertiliser_Brands[[#This Row],[Product (select)]], Table_Input_InorganicFertiliser_Brands[[#Headers],[Ingredient 3]], FertiliserProducts[#Data], FertiliserProducts[Product name], FertiliserProducts[#Headers])} -> Sulfur - Generic | O19: {=Fertiliser_InputFunctions.Fertiliser_FertiliserProductLookup(Table_Input_InorganicFertiliser_Brands[[#This Row],[Product (select)]], Table_Input_InorganicFertiliser_Brands[[#Headers],[Ingredient 3 percent]], FertiliserProducts[#Data], FertiliserProducts[Product name], FertiliserProducts[#Headers])} -> 0.053 | P19: {=Fertiliser_InputFunctions.Fertiliser_FertiliserProductLookup(Table_Input_InorganicFertiliser_Brands[[#This Row],[Product (select)]], Table_Input_InorganicFertiliser_Brands[[#Headers],[Ingredient 4]], FertiliserProducts[#Data], FertiliserProducts[Product name], FertiliserProducts[#Headers])} -> Phosphorus - Generic | Q19: {=Fertiliser_InputFunctions.Fertiliser_FertiliserProductLookup(Table_Input_InorganicFertiliser_Brands[[#This Row],[Product (select)]], Table_Input_InorganicFertiliser_Brands[[#Headers],[Ingredient 4 percent]], FertiliserProducts[#Data], FertiliserProducts[Product name], FertiliserProducts[#Headers])} -> 0.052 | R19: {=Fertiliser_InputFunctions.Fertiliser_FertiliserProductLookup(Table_Input_InorganicFertiliser_Brands[[#This Row],[Product (select)]], Table_Input_InorganicFertiliser_Brands[[#Headers],[Ingredient 5]], FertiliserProducts[#Data], FertiliserProducts[Product name], FertiliserProducts[#Headers])} -> Magnesium | S19: {=Fertiliser_InputFunctions.Fertiliser_FertiliserProductLookup(Table_Input_InorganicFertiliser_Brands[[#This Row],[Product (select)]], Table_Input_InorganicFertiliser_Brands[[#Headers],[Ingredient 5 percent]], FertiliserProducts[#Data], FertiliserProducts[Product name], FertiliserProducts[#Headers])} -> 0.013 | T19: {=Fertiliser_InputFunctions.Fertiliser_FertiliserProductLookup(Table_Input_InorganicFertiliser_Brands[[#This Row],[Product (select)]], Table_Input_InorganicFertiliser_Brands[[#Headers],[Ingredient 6]], FertiliserProducts[#Data], FertiliserProducts[Product name], FertiliserProducts[#Headers])} -> Zinc | U19: {=Fertiliser_InputFunctions.Fertiliser_FertiliserProductLookup(Table_Input_InorganicFertiliser_Brands[[#This Row],[Product (select)]], Table_Input_InorganicFertiliser_Brands[[#Headers],[Ingredient 6 percent]], FertiliserProducts[#Data], FertiliserProducts[Product name], FertiliserProducts[#Headers])} -> 0.002 | V19: =(Table_Input_InorganicFertiliser_Brands[[#This Row],[Amount applied per hectare]]*Table_Input_InorganicFertiliser_Brands[[#This Row],[Density]])*(IFERROR((_xlfn.XLOOKUP(Table_Input_InorganicFertiliser_Brands[[#This Row],[Ingredient 1]], Table_Fertiliser_ChemicalCompounds[Fertiliser type f],Table_Fertiliser_ChemicalCompounds[FNinorganic f])*Table_Input_InorganicFertiliser_Brands[[#This Row],[Ingredient 1 percent]]), 0)+ IFERROR((_xlfn.XLOOKUP(Table_Input_InorganicFertiliser_Brands[[#This Row],[Ingredient 2]],Table_Fertiliser_ChemicalCompounds[Fertiliser type f],Table_Fertiliser_ChemicalCompounds[FNinorganic f])*Table_Input_InorganicFertiliser_Brands[[#This Row],[Ingredient 2 percent]]), 0)+ IFERROR((_xlfn.XLOOKUP(Table_Input_InorganicFertiliser_Brands[[#This Row],[Ingredient 3]],Table_Fertiliser_ChemicalCompounds[Fertiliser type f],Table_Fertiliser_ChemicalCompounds[FNinorganic f])*Table_Input_InorganicFertiliser_Brands[[#This Row],[Ingredient 3 percent]]), 0)+ IFERROR((_xlfn.XLOOKUP(Table_Input_InorganicFertiliser_Brands[[#This Row],[Ingredient 4]],Table_Fertiliser_ChemicalCompounds[Fertiliser type f],Table_Fertiliser_ChemicalCompounds[FNinorganic f])*Table_Input_InorganicFertiliser_Brands[[#This Row],[Ingredient 4 percent]]), 0)+ IFERROR((_xlfn.XLOOKUP(Table_Input_InorganicFertiliser_Brands[[#This Row],[Ingredient 5]],Table_Fertiliser_ChemicalCompounds[Fertiliser type f],Table_Fertiliser_ChemicalCompounds[FNinorganic f])*Table_Input_InorganicFertiliser_Brands[[#This Row],[Ingredient 5 percent]]), 0)+ IFERROR((_xlfn.XLOOKUP(Table_Input_InorganicFertiliser_Brands[[#This Row],[Ingredient 6]],Table_Fertiliser_ChemicalCompounds[Fertiliser type f],Table_Fertiliser_ChemicalCompounds[FNinorganic f])*Table_Input_InorganicFertiliser_Brands[[#This Row],[Ingredient 6 percent]]), 0)) -> 48 | W19: =_xlfn.XLOOKUP(Table_Input_InorganicFertiliser_Brands[[#This Row],[Product (select)]],FertiliserProducts[Product name],FertiliserProducts[Urea source]) | X19: =_xlfn.XLOOKUP(Table_Input_InorganicFertiliser_Brands[[#This Row],[Product (select)]],FertiliserProducts[Product name],FertiliserProducts[Ammonia source])
A20: =HYPERLINK("#'Constants - Fertiliser'!A1", "Constants - Fertiliser") -> Constants - Fertiliser | D20: CoRoN 12-0-10 | E20: 100 | F20: =_xlfn.XLOOKUP(Table_Input_InorganicFertiliser_Brands[[#This Row],[Product (select)]],FertiliserProducts[Product name],FertiliserProducts[Unit]) -> L | G20: =_xlfn.XLOOKUP(Table_Input_InorganicFertiliser_Brands[[#This Row],[Product (select)]],FertiliserProducts[Product name],FertiliserProducts[Density / gravity]) -> 1.215 | H20: =$E$9 -> 100 | I20: =(Table_Input_InorganicFertiliser_Brands[[#This Row],[Amount applied per hectare]]*Table_Input_InorganicFertiliser_Brands[[#This Row],[Density]])*Table_Input_InorganicFertiliser_Brands[[#This Row],[Application area (ha)]] -> 12150 | J20: {=Fertiliser_InputFunctions.Fertiliser_FertiliserProductLookup(Table_Input_InorganicFertiliser_Brands[[#This Row],[Product (select)]], Table_Input_InorganicFertiliser_Brands[[#Headers],[Ingredient 1]], FertiliserProducts[#Data], FertiliserProducts[Product name], FertiliserProducts[#Headers])} -> Urea | K20: {=Fertiliser_InputFunctions.Fertiliser_FertiliserProductLookup(Table_Input_InorganicFertiliser_Brands[[#This Row],[Product (select)]], Table_Input_InorganicFertiliser_Brands[[#Headers],[Ingredient 1 percent]], FertiliserProducts[#Data], FertiliserProducts[Product name], FertiliserProducts[#Headers])} -> 0.19565217 | L20: {=Fertiliser_InputFunctions.Fertiliser_FertiliserProductLookup(Table_Input_InorganicFertiliser_Brands[[#This Row],[Product (select)]], Table_Input_InorganicFertiliser_Brands[[#Headers],[Ingredient 2]], FertiliserProducts[#Data], FertiliserProducts[Product name], FertiliserProducts[#Headers])} -> Potassium - Generic | M20: {=Fertiliser_InputFunctions.Fertiliser_FertiliserProductLookup(Table_Input_InorganicFertiliser_Brands[[#This Row],[Product (select)]], Table_Input_InorganicFertiliser_Brands[[#Headers],[Ingredient 2 percent]], FertiliserProducts[#Data], FertiliserProducts[Product name], FertiliserProducts[#Headers])} -> 0.1 | N20: {=Fertiliser_InputFunctions.Fertiliser_FertiliserProductLookup(Table_Input_InorganicFertiliser_Brands[[#This Row],[Product (select)]], Table_Input_InorganicFertiliser_Brands[[#Headers],[Ingredient 3]], FertiliserProducts[#Data], FertiliserProducts[Product name], FertiliserProducts[#Headers])} -> Nitrogen - Generic | O20: {=Fertiliser_InputFunctions.Fertiliser_FertiliserProductLookup(Table_Input_InorganicFertiliser_Brands[[#This Row],[Product (select)]], Table_Input_InorganicFertiliser_Brands[[#Headers],[Ingredient 3 percent]], FertiliserProducts[#Data], FertiliserProducts[Product name], FertiliserProducts[#Headers])} -> 0.03 | P20: {=Fertiliser_InputFunctions.Fertiliser_FertiliserProductLookup(Table_Input_InorganicFertiliser_Brands[[#This Row],[Product (select)]], Table_Input_InorganicFertiliser_Brands[[#Headers],[Ingredient 4]], FertiliserProducts[#Data], FertiliserProducts[Product name], FertiliserProducts[#Headers])} -> Boron | Q20: {=Fertiliser_InputFunctions.Fertiliser_FertiliserProductLookup(Table_Input_InorganicFertiliser_Brands[[#This Row],[Product (select)]], Table_Input_InorganicFertiliser_Brands[[#Headers],[Ingredient 4 percent]], FertiliserProducts[#Data], FertiliserProducts[Product name], FertiliserProducts[#Headers])} -> 0.005 | R20: {=Fertiliser_InputFunctions.Fertiliser_FertiliserProductLookup(Table_Input_InorganicFertiliser_Brands[[#This Row],[Product (select)]], Table_Input_InorganicFertiliser_Brands[[#Headers],[Ingredient 5]], FertiliserProducts[#Data], FertiliserProducts[Product name], FertiliserProducts[#Headers])} | S20: {=Fertiliser_InputFunctions.Fertiliser_FertiliserProductLookup(Table_Input_InorganicFertiliser_Brands[[#This Row],[Product (select)]], Table_Input_InorganicFertiliser_Brands[[#Headers],[Ingredient 5 percent]], FertiliserProducts[#Data], FertiliserProducts[Product name], FertiliserProducts[#Headers])} | T20: {=Fertiliser_InputFunctions.Fertiliser_FertiliserProductLookup(Table_Input_InorganicFertiliser_Brands[[#This Row],[Product (select)]], Table_Input_InorganicFertiliser_Brands[[#Headers],[Ingredient 6]], FertiliserProducts[#Data], FertiliserProducts[Product name], FertiliserProducts[#Headers])} | U20: {=Fertiliser_InputFunctions.Fertiliser_FertiliserProductLookup(Table_Input_InorganicFertiliser_Brands[[#This Row],[Product (select)]], Table_Input_InorganicFertiliser_Brands[[#Headers],[Ingredient 6 percent]], FertiliserProducts[#Data], FertiliserProducts[Product name], FertiliserProducts[#Headers])} | V20: =(Table_Input_InorganicFertiliser_Brands[[#This Row],[Amount applied per hectare]]*Table_Input_InorganicFertiliser_Brands[[#This Row],[Density]])*(IFERROR((_xlfn.XLOOKUP(Table_Input_InorganicFertiliser_Brands[[#This Row],[Ingredient 1]], Table_Fertiliser_ChemicalCompounds[Fertiliser type f],Table_Fertiliser_ChemicalCompounds[FNinorganic f])*Table_Input_InorganicFertiliser_Brands[[#This Row],[Ingredient 1 percent]]), 0)+ IFERROR((_xlfn.XLOOKUP(Table_Input_InorganicFertiliser_Brands[[#This Row],[Ingredient 2]],Table_Fertiliser_ChemicalCompounds[Fertiliser type f],Table_Fertiliser_ChemicalCompounds[FNinorganic f])*Table_Input_InorganicFertiliser_Brands[[#This Row],[Ingredient 2 percent]]), 0)+ IFERROR((_xlfn.XLOOKUP(Table_Input_InorganicFertiliser_Brands[[#This Row],[Ingredient 3]],Table_Fertiliser_ChemicalCompounds[Fertiliser type f],Table_Fertiliser_ChemicalCompounds[FNinorganic f])*Table_Input_InorganicFertiliser_Brands[[#This Row],[Ingredient 3 percent]]), 0)+ IFERROR((_xlfn.XLOOKUP(Table_Input_InorganicFertiliser_Brands[[#This Row],[Ingredient 4]],Table_Fertiliser_ChemicalCompounds[Fertiliser type f],Table_Fertiliser_ChemicalCompounds[FNinorganic f])*Table_Input_InorganicFertiliser_Brands[[#This Row],[Ingredient 4 percent]]), 0)+ IFERROR((_xlfn.XLOOKUP(Table_Input_InorganicFertiliser_Brands[[#This Row],[Ingredient 5]],Table_Fertiliser_ChemicalCompounds[Fertiliser type f],Table_Fertiliser_ChemicalCompounds[FNinorganic f])*Table_Input_InorganicFertiliser_Brands[[#This Row],[Ingredient 5 percent]]), 0)+ IFERROR((_xlfn.XLOOKUP(Table_Input_InorganicFertiliser_Brands[[#This Row],[Ingredient 6]],Table_Fertiliser_ChemicalCompounds[Fertiliser type f],Table_Fertiliser_ChemicalCompounds[FNinorganic f])*Table_Input_InorganicFertiliser_Brands[[#This Row],[Ingredient 6 percent]]), 0)) -> 14.58 | W20: =_xlfn.XLOOKUP(Table_Input_InorganicFertiliser_Brands[[#This Row],[Product (select)]],FertiliserProducts[Product name],FertiliserProducts[Urea source]) | X20: =_xlfn.XLOOKUP(Table_Input_InorganicFertiliser_Brands[[#This Row],[Product (select)]],FertiliserProducts[Product name],FertiliserProducts[Ammonia source])
A21: =HYPERLINK("#'Constants - Common'!A1", "Constants - Common") -> Constants - Common
D22: Custom fertiliser blends
D23: Custom blend name | E23: Amount applied (kg / ha) | F23: Application area (ha) | G23: Total applied (kg) | H23: Ingredient 1 (select) | I23: Ingredient 1 percent | J23: Ingredient 2 | K23: Ingredient 2 percent | L23: Ingredient 3 | M23: Ingredient 3 percent | N23: Ingredient 4 | O23: Ingredient 4 percent | P23: N application rate (kg/ha) | Q23: Urea source | R23: Ammonia source
D24: My first custom blend | E24: 100 | F24: =$E$9 -> 100 | G24: =Table_Input_InorganicFertiliser_Custom[[#This Row],[Amount applied (kg / ha)]]*Table_Input_InorganicFertiliser_Custom[[#This Row],[Application area (ha)]] -> 10000 | H24: Ammonia | I24: 0.45 | J24: Calcium nitrate | K24: 0.3 | L24: Potassium - Generic | M24: 0.1 | N24: Sulfur - Generic | O24: 0.1 | P24: =Table_Input_InorganicFertiliser_Custom[[#This Row],[Amount applied (kg / ha)]]* (IFERROR((_xlfn.XLOOKUP(Table_Input_InorganicFertiliser_Custom[[#This Row],[Ingredient 1 (select)]], Table_Fertiliser_ChemicalCompounds[Fertiliser type f],Table_Fertiliser_ChemicalCompounds[FNinorganic f])*Table_Input_InorganicFertiliser_Custom[[#This Row],[Ingredient 1 percent]]), 0) + IFERROR((_xlfn.XLOOKUP(Table_Input_InorganicFertiliser_Custom[[#This Row],[Ingredient 2]], Table_Fertiliser_ChemicalCompounds[Fertiliser type f],Table_Fertiliser_ChemicalCompounds[FNinorganic f])*Table_Input_InorganicFertiliser_Custom[[#This Row],[Ingredient 2 percent]]), 0) + IFERROR((_xlfn.XLOOKUP(Table_Input_InorganicFertiliser_Custom[[#This Row],[Ingredient 3]], Table_Fertiliser_ChemicalCompounds[Fertiliser type f],Table_Fertiliser_ChemicalCompounds[FNinorganic f])*Table_Input_InorganicFertiliser_Custom[[#This Row],[Ingredient 3 percent]]), 0) + IFERROR((_xlfn.XLOOKUP(Table_Input_InorganicFertiliser_Custom[[#This Row],[Ingredient 4]], Table_Fertiliser_ChemicalCompounds[Fertiliser type f],Table_Fertiliser_ChemicalCompounds[FNinorganic f])*Table_Input_InorganicFertiliser_Custom[[#This Row],[Ingredient 4 percent]]), 0) ) -> 41.7075 | Q24: Canada | R24: Global
E25: 100 | F25: =$E$9 -> 100 | G25: =Table_Input_InorganicFertiliser_Custom[[#This Row],[Amount applied (kg / ha)]]*Table_Input_InorganicFertiliser_Custom[[#This Row],[Application area (ha)]] -> 10000 | H25: Urea | I25: 0.9 | J25: Ammonia | K25: 0.1 | P25: =Table_Input_InorganicFertiliser_Custom[[#This Row],[Amount applied (kg / ha)]]* (IFERROR((_xlfn.XLOOKUP(Table_Input_InorganicFertiliser_Custom[[#This Row],[Ingredient 1 (select)]], Table_Fertiliser_ChemicalCompounds[Fertiliser type f],Table_Fertiliser_ChemicalCompounds[FNinorganic f])*Table_Input_InorganicFertiliser_Custom[[#This Row],[Ingredient 1 percent]]), 0) + IFERROR((_xlfn.XLOOKUP(Table_Input_InorganicFertiliser_Custom[[#This Row],[Ingredient 2]], Table_Fertiliser_ChemicalCompounds[Fertiliser type f],Table_Fertiliser_ChemicalCompounds[FNinorganic f])*Table_Input_InorganicFertiliser_Custom[[#This Row],[Ingredient 2 percent]]), 0) + IFERROR((_xlfn.XLOOKUP(Table_Input_InorganicFertiliser_Custom[[#This Row],[Ingredient 3]], Table_Fertiliser_ChemicalCompounds[Fertiliser type f],Table_Fertiliser_ChemicalCompounds[FNinorganic f])*Table_Input_InorganicFertiliser_Custom[[#This Row],[Ingredient 3 percent]]), 0) + IFERROR((_xlfn.XLOOKUP(Table_Input_InorganicFertiliser_Custom[[#This Row],[Ingredient 4]], Table_Fertiliser_ChemicalCompounds[Fertiliser type f],Table_Fertiliser_ChemicalCompounds[FNinorganic f])*Table_Input_InorganicFertiliser_Custom[[#This Row],[Ingredient 4 percent]]), 0) ) -> 49.635 | Q25: Canada | R25: Canada
D27: Soil ameliorants
D29: 💡 You can add more rows to the table by right-clicking on the table and selecting "Insert > Table rows above/below".
D30: 💡 'Lime' refers to calcium carbonate - CaCO3. 'Dolomite' refers to calcium magnesium carbonate - CaMg(CO3)2
D31: 💡The application area is the same as the area under pasture / cropping by default. You can edit it if the application area is different.
D32: =IF(MAX(Table_Input_SoilAmeliorants[Total]) > 1, "There can not be more than 100% ingredients in a product. Check the table below.", "")
D33: Product | E33: Amount applied (t/hectare) | F33: Application area (ha) | G33: Total amount applied (t) | H33: Percent Lime CaCO3 | I33: Percent Dolomite CaMg(CO3)2 | J33: Percent Gypsum | K33: Total
D34: Lime product 1 | E34: 100 | F34: =$E$9 -> 100 | G34: =IFERROR(Table_Input_SoilAmeliorants[[#This Row],[Amount applied (t/hectare)]]*Table_Input_SoilAmeliorants[[#This Row],[Application area (ha)]], 0) -> 10000 | H34: 0.4 | I34: 0.3 | J34: 0.25 | K34: =SUM(Table_Input_SoilAmeliorants[[#This Row],[Percent Lime CaCO3]:[Percent Gypsum]]) -> 0.95
D35: Lime product 2 | E35: 100 | F35: =$E$9 -> 100 | G35: =IFERROR(Table_Input_SoilAmeliorants[[#This Row],[Amount applied (t/hectare)]]*Table_Input_SoilAmeliorants[[#This Row],[Application area (ha)]], 0) -> 10000 | H35: 1 | K35: =SUM(Table_Input_SoilAmeliorants[[#This Row],[Percent Lime CaCO3]:[Percent Gypsum]]) -> 1
D38: Organic fertiliser applied
D40: 💡 You can add more rows to the table by right-clicking on the table and selecting "Insert > Table rows above/below".
D41: 💡The application area is the same as the area under pasture / cropping by default. You can edit it if the application area is different.
D43: Organic fertiliser type (select) | E43: Percentage of N in fertiliser | F43: Amount applied (kg/hectare) | G43: Amount N applied (kg/hectare) | H43: Application area (ha) | I43: Total organic fertliser applied | J43: Total nitrogen applied (kg)
A44: =HYPERLINK("#A1", "▲ Back to top") -> ▲ Back to top | D44: Manure - Other | E44: 0.3 | F44: 10 | G44: =Table_Input_OrganicFertiliser[[#This Row],[Amount applied (kg/hectare)]]*Table_Input_OrganicFertiliser[[#This Row],[Percentage of N in fertiliser]] -> 3 | H44: =$E$9 -> 100 | I44: =Table_Input_OrganicFertiliser[[#This Row],[Amount applied (kg/hectare)]]*Table_Input_OrganicFertiliser[[#This Row],[Application area (ha)]] -> 1000 | J44: =IFERROR(Table_Input_OrganicFertiliser[[#This Row],[Amount N applied (kg/hectare)]]*Table_Input_OrganicFertiliser[[#This Row],[Application area (ha)]], 0) -> 300
D45: Manure - Poultry | E45: 0.25 | F45: 10 | G45: =Table_Input_OrganicFertiliser[[#This Row],[Amount applied (kg/hectare)]]*Table_Input_OrganicFertiliser[[#This Row],[Percentage of N in fertiliser]] -> 2.5 | H45: =$E$9 -> 100 | I45: =Table_Input_OrganicFertiliser[[#This Row],[Amount applied (kg/hectare)]]*Table_Input_OrganicFertiliser[[#This Row],[Application area (ha)]] -> 1000 | J45: =IFERROR(Table_Input_OrganicFertiliser[[#This Row],[Amount N applied (kg/hectare)]]*Table_Input_OrganicFertiliser[[#This Row],[Application area (ha)]], 0) -> 250

Sheet Input - Feed
A1: #VALUE! | C1: Input - Purchased feed - Livestock
A3: Home
A4: =HYPERLINK("#'Results'!A1", "Results") -> Results
D5: Supplemental feed
A6: INPUTS
A7: =HYPERLINK("#'Input - Site'!A1", "Site") -> Site | D7: Lick blocks
A8: =HYPERLINK("#'Input - Production'!A1", "Production and outputs") -> Production and outputs | D8: {=Table_SourceData_Scope3_LickBlocks[Product]} -> Lick block, dry season mix | E8: 100 | F8: kg
A9: =HYPERLINK("#'Input - Herd - Dairy'!A1", "Herd - Dairy") -> Herd - Dairy | D9: Lick block, mineral | E9: 100 | F9: kg
A10: =HYPERLINK("#'Input - Feed - Dairy'!A1", "Purchased feed - Livestock") -> Purchased feed - Livestock | D10: Lick block, weaner | E10: 100 | F10: kg
A11: =HYPERLINK("#'Input - Herd - Feedlot'!A1", "Herd - Feedlot") -> Herd - Feedlot
A12: =HYPERLINK("#'Input - Pasture'!A1", "Pasture") -> Pasture
A13: =HYPERLINK("#'Input - Grains'!A1", "Crop - Grains") -> Crop - Grains | D13: Feed blends
A14: =HYPERLINK("#'Input - Fert Lime Chem'!A1", "Fertiliser, Lime & Chemicals") -> Fertiliser, Lime & Chemicals | D14: Tip: You can add more rows to the table by right-clicking on the table and selecting "Insert > Table rows above/below".
A15: =HYPERLINK("#'Input - Fuel & Energy'!A1", "Electricity and fuel") -> Electricity and fuel
A16: Waste | D16: Feed blend name | E16: Amount fed (kg) | F16: Ingredient 1 (select) | G16: Ingredient 1 source region | H16: Ingredient 1 percent | I16: Ingredient 2 (select) | J16: Ingredient 2 source region | K16: Ingredient 2 percent | L16: Ingredient 3 (select) | M16: Ingredient 3 source region | N16: Ingredient 3 percent | O16: Ingredient 4 (select) | P16: Ingredient 4 source region | Q16: Ingredient 4 percent
A17: Freight and transport | E17: 1200 | F17: Oaten hay | G17: WA | H17: 0.35 | I17: Sardines (whole) | J17: SA | K17: 0.22 | L17: Canola oil | M17: Australia | N17: 0.12 | O17: Molasses | P17: QLD | Q17: 0.05
A18: =HYPERLINK("#'Input - Other Farm Inputs'!A1", "Other farm inputs") -> Other farm inputs | E18: 3456 | F18: Cereal hay | G18: TAS | H18: 0.2 | I18: Lucerne hay | J18: NSW | K18: 0.2
A19: =HYPERLINK("#'Input - Data quality'!A1", "Data quality") -> Data quality | D19: Hay bales in paddock | E19: 300 | F19: Maize grain | G19: QLD | H19: 0.8 | I19: Soybean meal | J19: Brazil | K19: 0.2
E20: 500 | F20: Pasture hay | G20: NSW | H20: 1
A21: CALCULATIONS
A22: N2O MMS
A23: Enteric methane | D23: Feed rations
A24: =HYPERLINK("#'Calcs - Fert Lime'!A1", "Fertiliser & soil amendments") -> Fertiliser & soil amendments | D24: {=Table_SourceData_Scope3_MixedRations[Product]} -> Feed for chickens | E24: 100 | F24: kg
A25: =HYPERLINK("#'Calcs - Residue mgmt - Crop'!A1", "Residue management - Crop") -> Residue management - Crop | D25: Feed for dairy calves | E25: 100 | F25: kg
A26: =HYPERLINK("#'Calcs - Residue mgmt - Pasture'!A1", "Residue management - Pasture") -> Residue management - Pasture | D26: Feed for dairy cows | E26: 100 | F26: kg
A27: =HYPERLINK("#'Calcs - Field burning'!A1", "Field burning - Crop") -> Field burning - Crop | D27: Feed for pigs | E27: 100 | F27: kg
A28: =HYPERLINK("#'Calcs - Fuel'!A1", "Fuel") -> Fuel
A29: =HYPERLINK("#'Calcs - Electricity'!A1", "Electricity") -> Electricity
A30: =HYPERLINK("#'Calcs - Refrigerants'!A1", "Refrigerants") -> Refrigerants
A31: Waste
A32: Freight and transport
A33: =HYPERLINK("#'Calcs - Scope 3'!A1", "Purchased goods scope 3") -> Purchased goods scope 3
A35: APPENDICES
A36: =HYPERLINK("#'Constants - Common'!A1", "Constants - Common") -> Constants - Common
A37: =HYPERLINK("#'Constants - Cropping'!A1", "Constants - Cropping") -> Constants - Cropping
A38: =HYPERLINK("#'Constants - Livestock'!A1", "Constants - Livestock") -> Constants - Livestock
A39: =HYPERLINK("#'Constants - Dairy'!A1", "Constants - Dairy") -> Constants - Dairy
A40: Sources & acknowledgements

Sheet Input - Farm Inputs
A1: #VALUE! | C1: Input - Other farm inputs
D5: Miscellaneous inputs
D6: ='Constants - Scope 3'!E202 -> Animal ear tags (large) | E6: 100 | F6: tags
D7: ='Constants - Scope 3'!E203 -> Animal ear tags (small) | E7: 200 | F7: tags
D8: ='Constants - Scope 3'!E206 -> Nylon netting | E8: 300 | F8: kg
D11: Seed
D12: ='Constants - Scope 3'!E204 -> Barley grain (for seed) | E12: 500 | F12: kg
D13: ='Constants - Scope 3'!E205 -> Maize grain (for seed) | E13: 600 | F13: kg
D14: ='Constants - Scope 3'!E207 -> Oat grain (for seed) | E14: 700 | F14: kg
D15: ='Constants - Scope 3'!E208 -> Sorghum grain (for seed) | E15: 800 | F15: kg
D16: ='Constants - Scope 3'!E209 -> Wheat grain (for seed) | E16: 900 | F16: kg
D19: Pesticides
D21: 💡You can add more rows to the table by right-clicking on the table and selecting "Insert > Table rows above/below".
D22: 💡You can find specific product information in the Australian Government's 'PubCRIS' database search.
D23: Click here to find instructions on how to use the PubCRIS database
K24: {=IF( SUMPRODUCT((Table_Input_Pesticides[Constituent unit (select)]="fraction of product")*(Table_Input_Pesticides[Active ingredient 1 amount]>1)*(Table_Input_Pesticides[Active ingredient 2 amount]<>""))>0, "Alert: If constituent unit is fraction of product, amount cannot exceed 1", IF( SUMPRODUCT((Table_Input_Pesticides[Constituent unit (select)]="grams/litre or grams/kg")*(Table_Input_Pesticides[Active ingredient 1 amount]<1)*(Table_Input_Pesticides[Active ingredient 2 amount]<>""))>0, "Alert: If constituent unit is grams/kg or litre, amount cannot be less than 1", "" ) )} | N24: {=IF( SUMPRODUCT((Table_Input_Pesticides[Constituent unit (select)]="fraction of product")*(Table_Input_Pesticides[Active ingredient 2 amount]>1)*(Table_Input_Pesticides[Active ingredient 2 amount]<>""))>0, "Alert: If constituent unit is fraction of product, amount cannot exceed 1", IF( SUMPRODUCT((Table_Input_Pesticides[Constituent unit (select)]="grams/litre or grams/kg")*(Table_Input_Pesticides[Active ingredient 2 amount]<1)*(Table_Input_Pesticides[Active ingredient 2 amount]<>""))>0, "Alert: If constituent unit is grams/kg or litre, amount cannot be less than 1", "" ) )} | Q24: {=IF( SUMPRODUCT((Table_Input_Pesticides[Constituent unit (select)]="fraction of product")*(Table_Input_Pesticides[Active ingredient 3 amount]>1)*(Table_Input_Pesticides[Active ingredient 3 amount]<>""))>0, "Alert: If constituent unit is fraction of product, amount cannot exceed 1", IF( SUMPRODUCT((Table_Input_Pesticides[Constituent unit (select)]="grams/litre or grams/kg")*(Table_Input_Pesticides[Active ingredient 3 amount]<1)*(Table_Input_Pesticides[Active ingredient 3 amount]<>""))>0, "Alert: If constituent unit is grams/kg or litre, amount cannot be less than 1", "" ) )}
D25: Product name | E25: Amount applied per ha | F25: Application unit (select) | G25: Application area (ha) | H25: Total applied | I25: Constituent unit (select) | J25: Active ingredient 1 (select) | K25: Active ingredient 1 amount | L25: Total active ingredient 1 (kg) | M25: Active ingredient 2 (select) | N25: Active ingredient 2 amount | O25: Total active ingredient 2 (kg) | P25: Active ingredient 3 (select) | Q25: Active ingredient 3 amount | R25: Total active ingredient 3 (kg)
D26: QA MCPA + Picloram SL Herbicide | E26: 10 | F26: kg / hectare | G26: 100 | H26: =Table_Input_Pesticides[[#This Row],[Amount applied per ha]]*Table_Input_Pesticides[[#This Row],[Application area (ha)]] -> 1000 | I26: grams/litre or grams/kg | J26: Pesticides (generic) | K26: 26 | L26: =Table_Input_Pesticides[[#This Row],[Total applied]]*Table_Input_Pesticides[[#This Row],[Active ingredient 1 amount]]*IF(Table_Input_Pesticides[[#This Row],[Constituent unit (select)]]="fraction of product", 1, 10^-3) -> 26 | M26: Pesticides (generic) | N26: 420 | O26: =Table_Input_Pesticides[[#This Row],[Total applied]]*Table_Input_Pesticides[[#This Row],[Active ingredient 2 amount]]*IF(Table_Input_Pesticides[[#This Row],[Constituent unit (select)]]="fraction of product", 1, 10^-3) -> 420 | R26: =Table_Input_Pesticides[[#This Row],[Total applied]]*Table_Input_Pesticides[[#This Row],[Active ingredient 3 amount]]*IF(Table_Input_Pesticides[[#This Row],[Constituent unit (select)]]="fraction of product", 1, 10^-3) -> 0
D27: Heben Propiconazole 550EC Fungicide | E27: 10 | F27: litre / hectare | G27: 100 | H27: =Table_Input_Pesticides[[#This Row],[Amount applied per ha]]*Table_Input_Pesticides[[#This Row],[Application area (ha)]] -> 1000 | I27: grams/litre or grams/kg | J27: Pesticides (generic) | K27: 550 | L27: =Table_Input_Pesticides[[#This Row],[Total applied]]*Table_Input_Pesticides[[#This Row],[Active ingredient 1 amount]]*IF(Table_Input_Pesticides[[#This Row],[Constituent unit (select)]]="fraction of product", 1, 10^-3) -> 550 | O27: =Table_Input_Pesticides[[#This Row],[Total applied]]*Table_Input_Pesticides[[#This Row],[Active ingredient 2 amount]]*IF(Table_Input_Pesticides[[#This Row],[Constituent unit (select)]]="fraction of product", 1, 10^-3) -> 0 | R27: =Table_Input_Pesticides[[#This Row],[Total applied]]*Table_Input_Pesticides[[#This Row],[Active ingredient 3 amount]]*IF(Table_Input_Pesticides[[#This Row],[Constituent unit (select)]]="fraction of product", 1, 10^-3) -> 0
D28: NovaGuard Boscalid 500 WG Fungicide | E28: 10 | F28: kg / hectare | G28: 100 | H28: =Table_Input_Pesticides[[#This Row],[Amount applied per ha]]*Table_Input_Pesticides[[#This Row],[Application area (ha)]] -> 1000 | I28: grams/litre or grams/kg | J28: Pesticides (generic) | K28: 500 | L28: =Table_Input_Pesticides[[#This Row],[Total applied]]*Table_Input_Pesticides[[#This Row],[Active ingredient 1 amount]]*IF(Table_Input_Pesticides[[#This Row],[Constituent unit (select)]]="fraction of product", 1, 10^-3) -> 500 | O28: =Table_Input_Pesticides[[#This Row],[Total applied]]*Table_Input_Pesticides[[#This Row],[Active ingredient 2 amount]]*IF(Table_Input_Pesticides[[#This Row],[Constituent unit (select)]]="fraction of product", 1, 10^-3) -> 0 | R28: =Table_Input_Pesticides[[#This Row],[Total applied]]*Table_Input_Pesticides[[#This Row],[Active ingredient 3 amount]]*IF(Table_Input_Pesticides[[#This Row],[Constituent unit (select)]]="fraction of product", 1, 10^-3) -> 0
D31: Livestock
D33: Transaction name | E33: Livestock type (select) | F33: Class (select) | G33: Source region (Select) | H33: Quantity (head) | I33: Average liveweight (kg/head) | J33: Total liveweight (kg)
D34: Chooks from Barry | E34: Chickens | F34: Chickens | G34: Australia | H34: 100 | I34: 250 | J34: =Table_Input_LivestockPurchases[[#This Row],[Quantity (head)]]*Table_Input_LivestockPurchases[[#This Row],[Average liveweight (kg/head)]] -> 25000
E35: Beef cattle | F35: Cattle, for manufacturing beef | G35: NSW | H35: 100 | I35: 250 | J35: =Table_Input_LivestockPurchases[[#This Row],[Quantity (head)]]*Table_Input_LivestockPurchases[[#This Row],[Average liveweight (kg/head)]] -> 25000
E36: Dairy cattle | F36: Dairy cows | G36: VIC | H36: 100 | I36: 250 | J36: =Table_Input_LivestockPurchases[[#This Row],[Quantity (head)]]*Table_Input_LivestockPurchases[[#This Row],[Average liveweight (kg/head)]] -> 25000
E37: Pigs | F37: Pigs | G37: Australia | H37: 100 | I37: 250 | J37: =Table_Input_LivestockPurchases[[#This Row],[Quantity (head)]]*Table_Input_LivestockPurchases[[#This Row],[Average liveweight (kg/head)]] -> 25000
E38: Sheep | F38: Sheep, for mutton | G38: Australia | H38: 100 | I38: 250 | J38: =Table_Input_LivestockPurchases[[#This Row],[Quantity (head)]]*Table_Input_LivestockPurchases[[#This Row],[Average liveweight (kg/head)]] -> 25000
E39: Sheep | F39: Sheep, for prime lamb | G39: WA | H39: 100 | I39: 250 | J39: =Table_Input_LivestockPurchases[[#This Row],[Quantity (head)]]*Table_Input_LivestockPurchases[[#This Row],[Average liveweight (kg/head)]] -> 25000
D42: Packaging
D44: Tip: You can add more rows to the table by right-clicking on the table and selecting "Insert > Table rows above/below".
D46: Packaging name | E46: Primary material | F46: Quantity purchased | G46: Weight per unit (kg) | H46: Total weight purchased
D47: 250g punnet | E47: Plastic sheet HDPE | F47: 100 | G47: 0.02 | H47: =Table_Input_Packaging[[#This Row],[Quantity purchased]]*Table_Input_Packaging[[#This Row],[Weight per unit (kg)]] -> 2
D48: 500g punnet | E48: Plastic crate polypropylene | F48: 1000 | G48: 100 | H48: =Table_Input_Packaging[[#This Row],[Quantity purchased]]*Table_Input_Packaging[[#This Row],[Weight per unit (kg)]] -> 100000
E49: Plastic sheet HDPE | F49: 456 | G49: 100 | H49: =Table_Input_Packaging[[#This Row],[Quantity purchased]]*Table_Input_Packaging[[#This Row],[Weight per unit (kg)]] -> 45600
D50: Cardboard box 50 litre | E50: Corrugated board | F50: 1234 | G50: 100 | H50: =Table_Input_Packaging[[#This Row],[Quantity purchased]]*Table_Input_Packaging[[#This Row],[Weight per unit (kg)]] -> 123400
D53: Cleaning chemicals
D55: Tip: You can add more rows to the table by right-clicking on the table and selecting "Insert > Table rows above/below".
D57: Product name | E57: Type (select) | F57: Quantity purchased (kg)
D58: Acid kleen | E58: Phosphoric acid | F58: 100
D59: Kleen alk | E59: Alkaline cleaner | F59: 100
...

Sheet Input - Fuel
A1: #VALUE! | C1: Input - Fuel
A3: =HYPERLINK("#'Home'!A1", "Home") -> Home
A4: =HYPERLINK("#'Overview'!A1", "Overview") -> Overview
A5: =HYPERLINK("#'Results'!A1", "Results") -> Results | D5: Fuel purchases and consumption
A7: INPUTS | D7: 💡 You can add more rows to the table by right-clicking on the table and selecting "Insert > Table rows above/below"
A8: =HYPERLINK("#'Input - Fuel'!A1", "Fuel") -> Fuel | D8: 💡 'Percent consumed" is 100% by default. If you purchased more fuel than was consumed you can edit this field.
A10: CALCULATIONS | D10: Fuel use (select) | E10: Fuel type (select) | F10: Amount purchased | G10: Amount unit | H10: Percent consumed | I10: Amount consumed
A11: =HYPERLINK("#'8.1.1.1-2 Transport fuel'!A1", "8.1.1.1-2 Transport fuel") -> 8.1.1.1-2 Transport fuel | D11: Cars and light commercial vehicles | E11: Petrol | F11: 1000 | G11: {=Common_InputFunctions.Utility_LookupValueInTable(Table_Input_Fuel[[#This Row],[Fuel type (select)]],Table_FuelTypes_Units[Fuel type], Table_FuelTypes_Units[Unit])} -> kL | H11: =1 -> 1 | I11: =Table_Input_Fuel[[#This Row],[Amount purchased]]*Table_Input_Fuel[[#This Row],[Percent consumed]]*10^-3 -> 1
A12: =HYPERLINK("#'8.2.1.1-2 Stationary fuel'!A1", "8.2.1.1-2 Stationary fuel") -> 8.2.1.1-2 Stationary fuel | D12: Cars and light commercial vehicles | E12: Petrol | F12: 1000 | G12: {=Common_InputFunctions.Utility_LookupValueInTable(Table_Input_Fuel[[#This Row],[Fuel type (select)]],Table_FuelTypes_Units[Fuel type], Table_FuelTypes_Units[Unit])} -> kL | H12: =1 -> 1 | I12: =Table_Input_Fuel[[#This Row],[Amount purchased]]*Table_Input_Fuel[[#This Row],[Percent consumed]]*10^-3 -> 1
A13: =HYPERLINK("#'8.X.1.1-2 General use fuel'!A1", "8.X.1.1-2 General use fuel") -> 8.X.1.1-2 General use fuel
A15: APPENDICES
A16: =HYPERLINK("#'Constants - Fuel'!A1", "Constants - Fuel") -> Constants - Fuel
A17: =HYPERLINK("#'Constants - Common'!A1", "Constants - Common") -> Constants - Common

Sheet Input - Electricity
A1: #VALUE! | C1: Input - Electricity
A3: =HYPERLINK("#'Home'!A1", "Home") -> Home
A4: =HYPERLINK("#'Overview'!A1", "Overview") -> Overview
A5: =HYPERLINK("#'Results'!A1", "Results") -> Results | D5: Option 1: Location-based electricity
A7: INPUTS | D7: State grid electricity purchases
A8: =HYPERLINK("#'Input - Electricity'!A1", "Electricity") -> Electricity
D9: 💡The grid you purchase electricity from is typically the same as the state and region the farm is in.
A10: CALCULATIONS
A11: =HYPERLINK("#'14.1.1-2 Purchased electricity'!A1", "14.1.1-2 Purchased electricity") -> 14.1.1-2 Purchased electricity | D11: Amount purchased in kWh | E11: 500 | F11: kWh
D12: State and region your farm is in | E12: =IF('Input - Site'!E21="Western Australia", 'Input - Site'!E22, 'Input - Site'!E21) -> ACT
A13: APPENDICES | D13: Grid where electricity purchased from | E13: Western Australia - South West Interconnected System (SWIS) | F13: ← Please select
A14: =HYPERLINK("#'Constants - Electricity'!A1", "Constants - Electricity") -> Constants - Electricity
A15: =HYPERLINK("#'Constants - Common'!A1", "Constants - Common") -> Constants - Common
D17: Option 2: Market-based electricity
E18: =IF(E12="ACT", "", "ALERT: Your farm is not in the ACT, so the JRPP is not applicable")
D19: Electricity purchased in kWh (excluding GreenPower providers) | E19: 30000 | F19: kWh
D20: Renewable Power Percentage | E20: 0.1 | F20: percent
D21: Jurisdictional renewable power percentage (ACT only) | E21: 0.1 | F21: percent
D23: Electricity purchased from an accredited GreenPower provider | E23: 10000 | F23: kWh
D25: Start of reporting year | E25: =TEXT('Input - Site'!$E$12, "dd mmm yyyy") -> 01 Jan 2024
D26: End of reporting year | E26: =TEXT('Input - Site'!$E$13, "dd mmm yyyy") -> 31 Dec 2024
D28: Voluntarily surrendered Renewable Energy Certificates (RECs)
D30: 💡 You can add more rows to the table by right-clicking on the table and selecting "Insert > Table rows above/below"
D32: Description | E32: Source (select) | F32: Generation date | G32: Number of certificates | H32: MWh | I32: Elegibility
D33: Dec 2023 certs | E33: Purchased certificate | F33: 44185 | G33: 12 | H33: =Table_Input_RECSurrendered[[#This Row],[Number of certificates]] -> 12 | I33: =IF(DATEDIF(Table_Input_RECSurrendered[[#This Row],[Generation date]],DATEVALUE($E$26),"M")>36,"Ineligible - older than 36 months","Elegible") -> Ineligible - older than 36 months
E34: Issued for generated electricity | F34: 44575 | G34: 5 | H34: =Table_Input_RECSurrendered[[#This Row],[Number of certificates]] -> 5 | I34: =IF(DATEDIF(Table_Input_RECSurrendered[[#This Row],[Generation date]],DATEVALUE($E$26),"M")>36,"Ineligible - older than 36 months","Elegible") -> Elegible
E35: Purchased certificate | F35: 45438 | G35: 5 | H35: =Table_Input_RECSurrendered[[#This Row],[Number of certificates]] -> 5 | I35: =IF(DATEDIF(Table_Input_RECSurrendered[[#This Row],[Generation date]],DATEVALUE($E$26),"M")>36,"Ineligible - older than 36 months","Elegible") -> Elegible
D37: Total elegible voluntarily surrendered RECs | E37: =SUMIF(Table_Input_RECSurrendered[Elegibility], "Elegible", Table_Input_RECSurrendered[MWh]) -> 10 | F37: MWh
D39: Renewable Energy Certificates (RECs) for electricity produced on-site and consumed by the entity
D41: Description | E41: Source | F41: Generation date | G41: Number of certificates | H41: MWh | I41: Elegibility
D42: May 2022 generated | E42: ="Issued for generated electricity" -> Issued for generated electricity | F42: 44697 | G42: 10 | H42: =Table_Input_RECConsumedByEntity[[#This Row],[Number of certificates]] -> 10 | I42: =IF(AND(Table_Input_RECConsumedByEntity[[#This Row],[Generation date]]>=DATEVALUE($E$25), Table_Input_RECConsumedByEntity[[#This Row],[Generation date]]<= DATEVALUE($E$26)), "Elegible", "Ineligible - outside reporting year") -> Ineligible - outside reporting year
E43: ="Issued for generated electricity" -> Issued for generated electricity | F43: 45483 | G43: 4 | H43: =Table_Input_RECConsumedByEntity[[#This Row],[Number of certificates]] -> 4 | I43: =IF(AND(Table_Input_RECConsumedByEntity[[#This Row],[Generation date]]>=DATEVALUE($E$25), Table_Input_RECConsumedByEntity[[#This Row],[Generation date]]<= DATEVALUE($E$26)), "Elegible", "Ineligible - outside reporting year") -> Elegible
E44: ="Issued for generated electricity" -> Issued for generated electricity | F44: 45607 | G44: 7 | H44: =Table_Input_RECConsumedByEntity[[#This Row],[Number of certificates]] -> 7 | I44: =IF(AND(Table_Input_RECConsumedByEntity[[#This Row],[Generation date]]>=DATEVALUE($E$25), Table_Input_RECConsumedByEntity[[#This Row],[Generation date]]<= DATEVALUE($E$26)), "Elegible", "Ineligible - outside reporting year") -> Elegible
D46: Total elegible RECs for electricity produced on-site and consumed by entity | E46: =SUMIF(Table_Input_RECConsumedByEntity[Elegibility], "Elegible", Table_Input_RECConsumedByEntity[Number of certificates]) -> 11 | F46: MWh

Sheet Input - Livestock

Sheet Constants - Scope 3
