Workbook
Name Common_Equations.Common_ConvertCH4ToCO2e: _xlfn.LAMBDA(_xlpm.E_CH4,_xlpm.GWP_CH4, _xlpm.E_CH4 * _xlpm.GWP_CH4)
Name Common_Equations.Common_ConvertCH4ToCO2e_Arguments: _xlfn.LAMBDA(_xlfn.MAKEARRAY(2, 2, _xlfn.LAMBDA(_xlpm.r,_xlpm.c, INDEX({"ECH4","Methane emissions (t CH4)";"GWPCH4","Global warming potential for methane (t CO2-e / t CH4)"}, _xlpm.r, _xlpm.c))))
Name Common_Equations.Common_ConvertCH4ToCO2e_LatexEquation: _xlfn.LAMBDA("CO2_e = E_{CH4} \times GWP_{CH4}")
Name Common_Equations.Common_ConvertCH4ToCO2e_NIRReference: _xlfn.LAMBDA("")
Name Common_Equations.Common_ConvertCH4ToCO2e_Title: _xlfn.LAMBDA("Convert methane emissions to carbon dioxide equivalent emissions")
Name Common_Equations.Common_ConvertCH4ToCO2e_Unit: _xlfn.LAMBDA("t CO2e")
Name Common_Equations.Common_ConvertCH4ToCO2e_Variable: _xlfn.LAMBDA("ECH4 CO2e")
Name Common_Equations.Common_ConvertN2OToCO2e: _xlfn.LAMBDA(_xlpm.E_N2O,_xlpm.GWP_N2O, _xlpm.E_N2O * _xlpm.GWP_N2O)
Name Common_Equations.Common_ConvertN2OToCO2e_LatexEquation: _xlfn.LAMBDA("CO2_e = E_{N2O} \times GWP_{N2O}")
Name Common_Equations.Common_ConvertN2OToCO2e_NIRReference: _xlfn.LAMBDA("")
Name Common_Equations.Common_ConvertN2OToCO2e_Title: _xlfn.LAMBDA("Convert nitrous oxide emissions to carbon dioxide equivalent emissions")
Name Common_Equations.Common_ConvertN2OToCO2e_Unit: _xlfn.LAMBDA("t CO2e")
Name Common_Equations.Common_ConvertN2OToCO2e_Variable: _xlfn.LAMBDA("EN2O CO2e")
Name Common_InputFunctions.Utility_ConvertStateCommonNameToAbbreviation: _xlfn.LAMBDA(_xlpm.StateCommonName,_xlpm.StateCommonNameArray,_xlpm.StateAbbreviationArray, _xlfn.XLOOKUP(_xlpm.StateCommonName, _xlpm.StateCommonNameArray, _xlpm.StateAbbreviationArray, ""))
Name Common_InputFunctions.Utility_DisplayArguments_1_2: _xlfn.LAMBDA(_xlpm.ArgumentsArray, _xlfn.CHOOSECOLS(_xlpm.ArgumentsArray, 1, 2))
Name Common_InputFunctions.Utility_DisplayArguments_3_4: _xlfn.LAMBDA(_xlpm.ArgumentsArray, _xlfn.CHOOSECOLS(_xlpm.ArgumentsArray, 3, 4))
Name Common_InputFunctions.Utility_DisplayFunctionName: _xlfn.LAMBDA(_xlpm.Function, _xlfn.TEXTBEFORE(_xlfn.FORMULATEXT(_xlpm.Function), "("))
Name Common_InputFunctions.Utility_GetArrayTableColumnStartNumber: _xlfn.LAMBDA(_xlpm.TableHeaderCell, COLUMN(_xlpm.TableHeaderCell))
Name Common_InputFunctions.Utility_GetArrayTableRowStartNumber: _xlfn.LAMBDA(_xlpm.TableheaderCell,_xlpm.RowsBetweenHeaderandArray, ROW(_xlpm.TableheaderCell) + _xlpm.RowsBetweenHeaderandArray - 1)
Name Common_InputFunctions.Utility_LookupValueInTable: _xlfn.LAMBDA(_xlpm.LookupValue,_xlpm.LookupArray,_xlpm.ReturnArray, _xlfn.XLOOKUP(_xlpm.LookupValue, _xlpm.LookupArray, _xlpm.ReturnArray, ""))
Name Common_InputFunctions.Utility_ResultsItemFromEquationTitleAndSource: _xlfn.LAMBDA(_xlpm.TitleCell,_xlpm.SourceCell, SUBSTITUTE(LEFT(_xlpm.SourceCell, FIND(",", _xlpm.SourceCell) - 1), "VEERG 2026: ", "") & " " & _xlpm.TitleCell)
Name Common_InputFunctions.Utility_SourceHyperlink: _xlfn.LAMBDA(_xlpm.TargetCell, _xlfn.LET(_xlpm.sh, _xlfn.TEXTAFTER(CELL("filename", _xlpm.TargetCell), "]"), _xlpm.addr, CELL("address", _xlpm.TargetCell), "#'" & _xlpm.sh & "'!" & _xlpm.addr))
Name Common_InputFunctions.Utility_SourceHyperlinkDifferentSheet: _xlfn.LAMBDA(_xlpm.TargetCell, _xlfn.LET(_xlpm.sh, _xlfn.TEXTAFTER(CELL("filename", _xlpm.TargetCell), "]"), _xlpm.addr, CELL("address", _xlpm.TargetCell), "#" & _xlpm.addr))
Name Common_SourceData.Common_SourceData_AustralianStatesTerritories_Source: _xlfn.LAMBDA("")
Name Common_SourceData.Common_SourceData_AustralianStatesTerritories_Title: _xlfn.LAMBDA("Australian states and territories")
Name Common_SourceData.Common_SourceData_AustralianStatesTerritories_Unit: _xlfn.LAMBDA("")
Name Common_SourceData.Common_SourceData_AustralianStatesTerritories_Variable: _xlfn.LAMBDA("")
Name Common_SourceData.Common_SourceData_ClimateZones_Source: _xlfn.LAMBDA("VEERG 2026: Table 1.3: Climate and Rainfall zone classifications and definitions")
Name Common_SourceData.Common_SourceData_ClimateZones_Title: _xlfn.LAMBDA("VEERG Australian climate zones")
Name Common_SourceData.Common_SourceData_ClimateZones_Unit: _xlfn.LAMBDA("")
Name Common_SourceData.Common_SourceData_ClimateZones_Variable: _xlfn.LAMBDA("")
Name Common_SourceData.Common_SourceData_ConvertGasElementalToMolecular_Source: _xlfn.LAMBDA("XXXXXXX")
Name Common_SourceData.Common_SourceData_ConvertGasElementalToMolecular_Title: _xlfn.LAMBDA("Factor to convert elemental mass of gas to molecular mass")
Name Common_SourceData.Common_SourceData_ConvertGasElementalToMolecular_Unit: _xlfn.LAMBDA("factor")
Name Common_SourceData.Common_SourceData_ConvertGasElementalToMolecular_Variable: _xlfn.LAMBDA("Cg")
Name Common_SourceData.Common_SourceData_ConvertN2oElementalToMolecularCg_Data: _xlfn.LAMBDA(44 / 28)
Name Common_SourceData.Common_SourceData_ConvertN2oElementalToMolecularCg_Source: _xlfn.LAMBDA("National Inventory Report 2023 Volume 1")
Name Common_SourceData.Common_SourceData_ConvertN2oElementalToMolecularCg_Title: _xlfn.LAMBDA("Factor to convert elemental mass of N2O to molecular mass")
Name Common_SourceData.Common_SourceData_ConvertN2oElementalToMolecularCg_Unit: _xlfn.LAMBDA("factor")
Name Common_SourceData.Common_SourceData_ConvertN2oElementalToMolecularCg_Variable: _xlfn.LAMBDA("CgN2O")
Name Common_SourceData.Common_SourceData_DataScores_Scope3_Source: _xlfn.LAMBDA("VEERG 2026: XXXXXXXX")
Name Common_SourceData.Common_SourceData_DataScores_Scope3_Title: _xlfn.LAMBDA("Australian data scores for scope 3")
Name Common_SourceData.Common_SourceData_DataScores_Scope3_Unit: _xlfn.LAMBDA("")
Name Common_SourceData.Common_SourceData_DataScores_Scope3_Variable: _xlfn.LAMBDA("")
Name Common_SourceData.Common_SourceData_DataScores_Scope3_Variation: _xlfn.LAMBDA("")
Name Common_SourceData.Common_SourceData_DensityOfMethane_Data: _xlfn.LAMBDA(0.6784)
Name Common_SourceData.Common_SourceData_DensityOfMethane_Source: _xlfn.LAMBDA("National Inventory Report 2023 Volume 1: Equations 3.B.1a_2, 3.B.1c_2, 3.B.3_1, 3.B.4g_2")
Name Common_SourceData.Common_SourceData_DensityOfMethane_Title: _xlfn.LAMBDA("p = density of methane")
Name Common_SourceData.Common_SourceData_DensityOfMethane_Unit: _xlfn.LAMBDA("kg/m3")
Name Common_SourceData.Common_SourceData_EFleach_Data: _xlfn.LAMBDA(_xlfn.MAKEARRAY(1, 2, _xlfn.LAMBDA(_xlpm.r,_xlpm.c, INDEX({"EFleach",0.011}, _xlpm.r, _xlpm.c))))
Name Common_SourceData.Common_SourceData_EFleach_NIRReference: _xlfn.LAMBDA("National Inventory Report Volume 1: Equation 3.D.B_10")
Name Common_SourceData.Common_SourceData_EFleach_Source: _xlfn.LAMBDA("VEERG 2026:5.5.2.3 Constant Parameters")
Name Common_SourceData.Common_SourceData_EFleach_Title: _xlfn.LAMBDA("Emission factor for nitrogen leaching and runoff")
Name Common_SourceData.Common_SourceData_EFleach_Unit: _xlfn.LAMBDA("(kg N2O-N / kg N")
Name Common_SourceData.Common_SourceData_EFleach_Variation: _xlfn.LAMBDA((""))
Name Common_SourceData.Common_SourceData_EFN2O_NIRReference: _xlfn.LAMBDA("")
Name Common_SourceData.Common_SourceData_EFN2O_Source: _xlfn.LAMBDA("VEERG 2026: Table A.2.2.1")
Name Common_SourceData.Common_SourceData_EFN2O_Title: _xlfn.LAMBDA("Nitrous oxide emission factors for inorganic fertiliser application")
Name Common_SourceData.Common_SourceData_EFN2O_Unit: _xlfn.LAMBDA("(kg N2O-N / kg N")
Name Common_SourceData.Common_SourceData_EFOrganicFertiliserAndCropResidues_Data: _xlfn.LAMBDA(_xlfn.MAKEARRAY(3, 2, _xlfn.LAMBDA(_xlpm.r,_xlpm.c, INDEX({"Climate zone","EFNi & EFN2O";"Wet climate zone",0.006;"Dry climate zone",0.005}, _xlpm.r, _xlpm.c))))

Sheet Home
A1: Home

Sheet Overview
A1: #VALUE! | C1: 3.3: Enteric Methane: Dairy: Overview
A3: =HYPERLINK("#'Home'!A1", "Home") -> Home
A4: =HYPERLINK("#'Overview'!A1", "Overview") -> Overview
A5: =HYPERLINK("#'Results'!A1", "Results") -> Results | D5: 💡 Below is a diagram that maps the equations used to calculate emissions and how they interact with each other.
D6: Click on a box to go to the corresponding calculation.
A7: INPUTS
A8: =HYPERLINK("#'Input - Site'!A1", "Site") -> Site
A9: =HYPERLINK("#'Input - Dairy'!A1", "Dairy") -> Dairy
A11: CALCULATIONS
A12: =HYPERLINK("#'3.3.1.1-2 Enteric Methane'!A1", "3.3.1.1-2 Enteric Methane") -> 3.3.1.1-2 Enteric Methane
A14: APPENDICES
A15: =HYPERLINK("#'Constants - Dairy'!A1", "Constants - Dairy") -> Constants - Dairy
A16: =HYPERLINK("#'Constants - Livestock'!A1", "Constants - Livestock") -> Constants - Livestock
A17: =HYPERLINK("#'Constants - Common'!A1", "Constants - Common") -> Constants - Common
A18: =HYPERLINK("#'Acknowledgements'!A1", "Acknowledgements") -> Acknowledgements

Sheet Results
A1: #VALUE! | C1: 3.3 Enteric Methane: Dairy: Results
A3: =HYPERLINK("#'Home'!A1", "Home") -> Home
A4: =HYPERLINK("#'Overview'!A1", "Overview") -> Overview | D4: Emissions breakdown
A5: =HYPERLINK("#'Results'!A1", "Results") -> Results
D6: Scope 1 source | E6: GHG emissions method 1 | F6: GHG emissions method 2 | G6: GHG Unit | H6: CO2-e emissions method 1 | I6: CO2-e emissions method 2 | J6: CO2-e unit
A7: INPUTS | D7: 3.3.1.1-2 Enteric methane | E7: =VEERG_3_3_1_1__1_TotalAnnualMethaneFromEntericFermentationVariation_Result_Method1 -> 13.50547 | F7: =VEERG_3_3_1_1__1_TotalAnnualMethaneFromEntericFermentationVariation_Result_Method2 -> 13.50547 | G7: ='3.3.1.1-2 Enteric Methane'!$F$182 -> t CH4 | H7: ='3.3.1.1-2 Enteric Methane'!E187 -> 378.15316 | I7: ='3.3.1.1-2 Enteric Methane'!N187 -> 378.15316 | J7: t CO2e
A8: =HYPERLINK("#'Input - Site'!A1", "Site") -> Site | D8: Total | H8: =SUM(H7) -> 378.15316 | I8: =SUM(I7:I7) -> 378.15316 | J8: t CO2e
A9: =HYPERLINK("#'Input - Dairy'!A1", "Dairy") -> Dairy
A11: CALCULATIONS
A12: =HYPERLINK("#'3.3.1.1-2 Enteric Methane'!A1", "3.3.1.1-2 Enteric Methane") -> 3.3.1.1-2 Enteric Methane
A14: APPENDICES
A15: =HYPERLINK("#'Constants - Dairy'!A1", "Constants - Dairy") -> Constants - Dairy
A16: =HYPERLINK("#'Constants - Livestock'!A1", "Constants - Livestock") -> Constants - Livestock
A17: =HYPERLINK("#'Constants - Common'!A1", "Constants - Common") -> Constants - Common
A18: =HYPERLINK("#'Acknowledgements'!A1", "Acknowledgements") -> Acknowledgements

Sheet Input - Site
A1: #VALUE! | C1: Input - Site
A3: =HYPERLINK("#'Home'!A1", "Home") -> Home
A4: =HYPERLINK("#'Overview'!A1", "Overview") -> Overview
A5: =HYPERLINK("#'Results'!A1", "Results") -> Results | D5: Your business
A7: INPUTS | D7: Farm name | E7: Test Farms
A8: =HYPERLINK("#'Input - Site'!A1", "Site") -> Site | D8: Reporting entity name | E8: Test Farms Pty Ltd
A9: =HYPERLINK("#'Input - Dairy'!A1", "Dairy") -> Dairy
D10: 💡An 'Emissions accounting period' is a 12 month period where the business can report on the emissions, and is typically the same as the business' financial accounting period.
A11: CALCULATIONS
A12: =HYPERLINK("#'3.3.1.1-2 Enteric Methane'!A1", "3.3.1.1-2 Enteric Methane") -> 3.3.1.1-2 Enteric Methane | D12: Emissions calculation period start date | E12: 45292 | F12: ← DD/MM/YYYY or DD Month YYYY
D13: Emissions calculation period end date | E13: =DATE(YEAR(X_Cell_Site_StartDate)+1,MONTH(X_Cell_Site_StartDate),DAY(X_Cell_Site_StartDate))-1 -> 45657 | F13: ← Automatically calculated, 12 months after start date
A14: APPENDICES
A15: =HYPERLINK("#'Constants - Dairy'!A1", "Constants - Dairy") -> Constants - Dairy
A16: =HYPERLINK("#'Constants - Livestock'!A1", "Constants - Livestock") -> Constants - Livestock | D16: Location and climate
A17: =HYPERLINK("#'Constants - Common'!A1", "Constants - Common") -> Constants - Common
A18: =HYPERLINK("#'Acknowledgements'!A1", "Acknowledgements") -> Acknowledgements | D18: Location information is used to reference some region and climate-specific emission factors
D19: Tip: Use the web-based GAF Location Helper tool to easily get region and climate information. You will need an internet connection to use the GAF Location Helper.
D21: State | E21: Victoria | F21: ← Please select
D22: Region (ABS Statistical area level 4) if state is WA | E22: Western Australia - Outback (South) | F22: ← Please select
D23: Leaching zone | E23: NO - Not in leaching zone | F23: ← Please select
D24: Elevation | E24: 307.7 | F24: Meters
D25: Average temperature for reporting period | E25: 18 | F25: Degrees celsius
D26: Total rainfall for reporting period | E26: 601 | F26: Millimetres
D27: Potential evapotranspiration for reporting period | E27: 1326 | F27: Millimetres
D28: Number of frost days for reporting period | E28: 7 | F28: Days
D29: MAP:PET ratio | E29: =X_Cell_Site_TotalRainfall/X_Cell_Site_PotentialEvapotranspiration -> 0.45324284
D30: Rainfall zone | E30: =Common_InputFunctions.Utility_LookupItemFromMinMax(X_Cell_Site_TotalRainfall,Table_SourceData_RainfallZones[Min rainfall],Table_SourceData_RainfallZones[Max rainfall],Table_SourceData_RainfallZones[Rainfall Zone]) -> High rainfall
D31: Climate zone | E31: =Common_InputFunctions.Utility_GetClimateZone(X_Cell_Site_AverageTemperature,X_Cell_Site_TotalRainfall,X_Cell_Site_FrostDays,X_Cell_Site_Elevation,X_Cell_Site_MapPetRatio,Table_SourceData_ClimateZones[Min temp],Table_SourceData_ClimateZones[Max temp],Table_SourceData_ClimateZones[Min rainfall],Table_SourceData_ClimateZones[Max rainfall],Table_SourceData_ClimateZones[Min frost days],Table_SourceData_ClimateZones[Max frost days],Table_SourceData_ClimateZones[Min elevation],Table_SourceData_ClimateZones[Max elevation],Table_SourceData_ClimateZones[Min MAP:PET],Table_SourceData_ClimateZones[Max MAP:PET],Table_SourceData_ClimateZones[Climate zone]) -> Warm temperate dry
D32: Wet or dry climate zone | E32: =Common_InputFunctions.Utility_LookupValueInTable(X_Cell_Site_ClimateZone,Table_SourceData_WetDryZones[Climate zone],Table_SourceData_WetDryZones[Wet or Dry Zone]) -> Dry climate zone
D33: Temperature zone | E33: =Common_InputFunctions.Utility_LookupItemFromMinMax(X_Cell_Site_AverageTemperature,Table_SourceData_TemperatureZones[Min MAT],Table_SourceData_TemperatureZones[Max MAT],Table_SourceData_TemperatureZones[Temperature Zone]) -> Temperate

Sheet Input - Dairy
A1: #VALUE! | C1: Input -Dairy
A3: =HYPERLINK("#'Home'!A1", "Home") -> Home
A4: =HYPERLINK("#'Overview'!A1", "Overview") -> Overview
A5: =HYPERLINK("#'Results'!A1", "Results") -> Results | D5: Herd movement
A7: INPUTS | D7: Breed | E7: Medium Friesian | F7: ← Please select
A8: =HYPERLINK("#'Input - Site'!A1", "Site") -> Site
A9: =HYPERLINK("#'Input - Dairy'!A1", "Dairy") -> Dairy | E9: Milking cows | F9: Heifers > 1 year | G9: Heifers < 1 year | H9: Bulls > 1 year | I9: Bulls < 1 year
D10: ="Average number of head between " & TEXT(X_Cell_Site_StartDate, "dd mmm yy") & " and " & TEXT(X_Cell_Site_EndDate, "dd mmm yy") -> Average number of head between 01 Jan 24 and 31 Dec 24 | E10: 100 | F10: 0 | G10: 0 | H10: 0 | I10: 0 | J10: head
A11: CALCULATIONS
A12: =HYPERLINK("#'3.3.1.1-2 Enteric Methane'!A1", "3.3.1.1-2 Enteric Methane") -> 3.3.1.1-2 Enteric Methane | D12: Liveweight
D13: Method 1 default values (Do not edit) | E13: Milking cows | F13: Heifers > 1 year | G13: Heifers < 1 year | H13: Bulls > 1 year | I13: Bulls < 1 year
A14: APPENDICES | D14: Average liveweight | E14: =Common_InputFunctions.Utility_LookupValueInTableNumber(X_Cell_Dairy_Breed, Table_SourceData_Dairy_WjCowsHeifers[Breed],Table_SourceData_Dairy_WjCowsHeifers[Milking cows]) -> 550 | F14: 0 | G14: 0 | H14: 0 | I14: 0 | J14: kg/head
A15: =HYPERLINK("#'Constants - Dairy'!A1", "Constants - Dairy") -> Constants - Dairy | D15: Average liveweight gain | E15: {=Table_SourceData_Dairy_LWGj[Milking cows]} -> 0.016 | F15: 0 | G15: 0 | H15: 0 | I15: 0 | J15: kg/head/day
A16: =HYPERLINK("#'Constants - Livestock'!A1", "Constants - Livestock") -> Constants - Livestock
A17: =HYPERLINK("#'Constants - Common'!A1", "Constants - Common") -> Constants - Common | D17: Method 2 custom values (Edit if known) | E17: Milking cows | F17: Heifers > 1 year | G17: Heifers < 1 year | H17: Bulls > 1 year | I17: Bulls < 1 year
A18: =HYPERLINK("#'Acknowledgements'!A1", "Acknowledgements") -> Acknowledgements | D18: Average liveweight | E18: =Common_InputFunctions.Utility_LookupValueInTableNumber(X_Cell_Dairy_Breed, Table_SourceData_Dairy_WjCowsHeifers[Breed],Table_SourceData_Dairy_WjCowsHeifers[Milking cows]) -> 550 | F18: 0 | G18: 0 | H18: 0 | I18: 0 | J18: kg/head
D19: Average liveweight gain | E19: {=Table_SourceData_Dairy_LWGj[Milking cows]} -> 0.016 | F19: 0 | G19: 0 | H19: 0 | I19: 0 | J19: kg/head/day
D21: Duration of stay
D23: Method 1 default values (Do not edit) | E23: Milking cows | F23: Heifers > 1 year | G23: Heifers < 1 year | H23: Bulls > 1 year | I23: Bulls < 1 year
D24: ="Average duration of stay between " & TEXT(X_Cell_Site_StartDate, "dd mmm yy") & " and " & TEXT(X_Cell_Site_EndDate, "dd mmm yy") & " weaned livestock" -> Average duration of stay between 01 Jan 24 and 31 Dec 24 weaned livestock | E24: {=Common_InputFunctions.Utility_LookupValueInTableNumber(E23,Table_SourceData_Dairy_Duration[Animal class j],Table_SourceData_Dairy_Duration[Duration (weaned)])} -> 365 | F24: 0 | G24: 0 | H24: 0 | I24: 0 | J24: Days
D25: ="Average duration of stay between " & TEXT(X_Cell_Site_StartDate, "dd mmm yy") & " and " & TEXT(X_Cell_Site_EndDate, "dd mmm yy") & " pre-weaned livestock" -> Average duration of stay between 01 Jan 24 and 31 Dec 24 pre-weaned livestock | E25: {=Common_InputFunctions.Utility_LookupValueInTableNumber(E23,Table_SourceData_Dairy_Duration[Animal class j],Table_SourceData_Dairy_Duration[Duration (pre-weaned)])} -> 0 | F25: {=Common_InputFunctions.Utility_LookupValueInTableNumber(F23,Table_SourceData_Dairy_Duration[Animal class j],Table_SourceData_Dairy_Duration[Duration (pre-weaned)])} -> 0 | G25: 0 | H25: 0 | I25: 0 | J25: Days
D27: Method 2 custom values (Edit if known) | E27: Milking cows | F27: Heifers > 1 year | G27: Heifers < 1 year | H27: Bulls > 1 year | I27: Bulls < 1 year
D28: ="Average duration of stay between " & TEXT(X_Cell_Site_StartDate, "dd mmm yy") & " and " & TEXT(X_Cell_Site_EndDate, "dd mmm yy") & " weaned livestock" -> Average duration of stay between 01 Jan 24 and 31 Dec 24 weaned livestock | E28: {=Common_InputFunctions.Utility_LookupValueInTableNumber(E27,Table_SourceData_Dairy_Duration[Animal class j],Table_SourceData_Dairy_Duration[Duration (weaned)])} -> 365 | F28: 0 | G28: 0 | H28: 0 | I28: 0 | J28: Days
D29: ="Average duration of stay between " & TEXT(X_Cell_Site_StartDate, "dd mmm yy") & " and " & TEXT(X_Cell_Site_EndDate, "dd mmm yy") & " pre-weaned livestock" -> Average duration of stay between 01 Jan 24 and 31 Dec 24 pre-weaned livestock | E29: =365-E28 -> 0 | F29: 0 | G29: 0 | H29: 0 | I29: 0 | J29: Days
D33: Diet
D35: Method 1 default values (Do not edit) | E35: Milking cows | F35: Heifers > 1 year | G35: Heifers < 1 year | H35: Bulls > 1 year | I35: Bulls < 1 year
D36: Dry matter digestibility | E36: =SourceData_Dairy_DryMatterDigestibility_Data -> 0.75 | F36: =SourceData_Dairy_DryMatterDigestibility_Data -> 0.75 | G36: =SourceData_Dairy_DryMatterDigestibility_Data -> 0.75 | H36: =SourceData_Dairy_DryMatterDigestibility_Data -> 0.75 | I36: =SourceData_Dairy_DryMatterDigestibility_Data -> 0.75 | J36: Fraction
D37: Crude protein | E37: =SourceData_Dairy_CrudeProtein_Data -> 0.2 | F37: =SourceData_Dairy_CrudeProtein_Data -> 0.2 | G37: =SourceData_Dairy_CrudeProtein_Data -> 0.2 | H37: =SourceData_Dairy_CrudeProtein_Data -> 0.2 | I37: =SourceData_Dairy_CrudeProtein_Data -> 0.2 | J37: Fraction
D39: Method 2 custom values (Edit if known) | E39: Milking cows | F39: Heifers > 1 year | G39: Heifers < 1 year | H39: Bulls > 1 year | I39: Bulls < 1 year
D40: Dry matter digestibility | E40: =SourceData_Dairy_DryMatterDigestibility_Data -> 0.75 | F40: =SourceData_Dairy_DryMatterDigestibility_Data -> 0.75 | G40: =SourceData_Dairy_DryMatterDigestibility_Data -> 0.75 | H40: =SourceData_Dairy_DryMatterDigestibility_Data -> 0.75 | I40: =SourceData_Dairy_DryMatterDigestibility_Data -> 0.75 | J40: Fraction
D41: Crude protein | E41: =SourceData_Dairy_CrudeProtein_Data -> 0.2 | F41: =SourceData_Dairy_CrudeProtein_Data -> 0.2 | G41: =SourceData_Dairy_CrudeProtein_Data -> 0.2 | H41: =SourceData_Dairy_CrudeProtein_Data -> 0.2 | I41: =SourceData_Dairy_CrudeProtein_Data -> 0.2 | J41: Fraction
D47: Milk production
D49: Milk production unit | E49: Litres of milk | F49: ← Please select
E51: Milking cows
D52: Average daily milk production | E52: =6569/365 -> 17.99726 | F52: =IF(X_Cell_Dairy_MilkProductionUnit="Litres of milk", "litres/head/day", "kg milk solids/head/day") -> litres/head/day
D54: For milk solids only: | E54: Method 1 (don't edit) | F54: Method 2 (edit if known)
D55: Fat content in fat and protein corrected milk | E55: =SourceData_Dairy_FatContentInMilk_Data/100 -> 0.04 | F55: =SourceData_Dairy_FatContentInMilk_Data/100 -> 0.04 | G55: percent
D56: Protein content in fat and protein corrected milk | E56: =SourceData_Dairy_ProteinContentInMilk_Data/100 -> 0.033 | F56: =SourceData_Dairy_ProteinContentInMilk_Data/100 -> 0.033 | G56: percent

Sheet 3.3.1.1-2 Enteric Methane
A1: #VALUE! | C1: 3.3.1.1-2 Enteric Methane
A3: =HYPERLINK("#'Home'!A1", "Home") -> Home | D3: Method 1 | M3: Method 2
A4: =HYPERLINK("#'Overview'!A1", "Overview") -> Overview
A5: =HYPERLINK("#'Results'!A1", "Results") -> Results | D5: {=EntericMethane_Dairy_Equations.VEERG_3_3_1_1__6_MetabolisabilityOfDiet_Title()} -> Metabolisability of diet
D6: {=EntericMethane_Dairy_Equations.VEERG_3_3_1_1__6_MetabolisabilityOfDiet_Variation()} -> VARIATION ON SOURCE: changed 0.795 to 0.00795 which is the value used in the National Inventory Report
A7: INPUTS | D7: {=EntericMethane_Dairy_Equations.VEERG_3_3_1_1__6_MetabolisabilityOfDiet_Source()} -> VEERG 2026: 3.3.1.1, Equation (6)
A8: =HYPERLINK("#'Input - Site'!A1", "Site") -> Site | D8: Function name | E8: {=Common_InputFunctions.Utility_DisplayFunctionName(D24)} -> =EntericMethane_Dairy_Equations.VEERG_3_3_1_1__6_MetabolisabilityOfDietVariation
A9: =HYPERLINK("#'Input - Dairy'!A1", "Dairy") -> Dairy
A11: CALCULATIONS | D11: Variable | E11: {=EntericMethane_Dairy_Equations.VEERG_3_3_1_1__6_MetabolisabilityOfDiet_Variable()} -> qm_j
A12: =HYPERLINK("#'3.3.1.1-2 Enteric Methane'!A1", "3.3.1.1-2 Enteric Methane") -> 3.3.1.1-2 Enteric Methane | D12: Unit | E12: {=EntericMethane_Dairy_Equations.VEERG_3_3_1_1__6_MetabolisabilityOfDiet_Unit()} -> fraction
A14: APPENDICES | D14: {=_xlfn.CHOOSECOLS(EntericMethane_Dairy_Equations.VEERG_3_3_1_1__6_MetabolisabilityOfDiet_Arguments(), 1,2)} -> DMD_j | E14: dry matter digestibility expressed as a fraction | G14: {=_xlfn.CHOOSECOLS(EntericMethane_Dairy_Equations.VEERG_3_3_1_1__6_MetabolisabilityOfDiet_Arguments(), 3,4)} -> fraction | H14: Input | I14: ="See " & D16 -> See M1_Table_DMD_j
A15: =HYPERLINK("#'Constants - Dairy'!A1", "Constants - Dairy") -> Constants - Dairy
A16: =HYPERLINK("#'Constants - Livestock'!A1", "Constants - Livestock") -> Constants - Livestock | D16: M1_Table_DMD_j | M16: M2_Table_DMD_j
A17: =HYPERLINK("#'Constants - Common'!A1", "Constants - Common") -> Constants - Common | D17: Dry matter digestibility (Method 1) | M17: Dry matter digestibility (Method 2)
A18: =HYPERLINK("#'Acknowledgements'!A1", "Acknowledgements") -> Acknowledgements | D18: Milking cows | E18: Heifers > 1 year | F18: Heifers < 1 year | G18: Bulls > 1 year | H18: Bulls < 1 year | M18: Milking cows | N18: Heifers > 1 year | O18: Heifers < 1 year | P18: Bulls > 1 year | Q18: Bulls < 1 year
D19: =INDEX(X_Table_Dairy_Diet_Method1,2,2) -> 0.75 | E19: =INDEX(X_Table_Dairy_Diet_Method1,2,3) -> 0.75 | F19: =INDEX(X_Table_Dairy_Diet_Method1,2,4) -> 0.75 | G19: =INDEX(X_Table_Dairy_Diet_Method1,2,5) -> 0.75 | H19: =INDEX(X_Table_Dairy_Diet_Method1,2,6) -> 0.75 | I19: fraction | M19: =INDEX(X_Table_Dairy_Diet_Method2,2,2) -> 0.75 | N19: =INDEX(X_Table_Dairy_Diet_Method2,2,3) -> 0.75 | O19: =INDEX(X_Table_Dairy_Diet_Method2,2,4) -> 0.75 | P19: =INDEX(X_Table_Dairy_Diet_Method2,2,5) -> 0.75 | Q19: =INDEX(X_Table_Dairy_Diet_Method2,2,6) -> 0.75 | R19: fraction
D21: M1_Table_qm_j | M21: M2_Table_qm_j
D22: Metabolisability of diet (Method 1) | M22: Metabolisability of diet (Method 2)
D23: Milking cows | E23: Heifers > 1 year | F23: Heifers < 1 year | G23: Bulls > 1 year | H23: Bulls < 1 year | M23: Milking cows | N23: Heifers > 1 year | O23: Heifers < 1 year | P23: Bulls > 1 year | Q23: Bulls < 1 year
D24: {=EntericMethane_Dairy_Equations.VEERG_3_3_1_1__6_MetabolisabilityOfDietVariation(D19)} -> 0.59485 | E24: {=EntericMethane_Dairy_Equations.VEERG_3_3_1_1__6_MetabolisabilityOfDietVariation(E19)} -> 0.59485 | F24: {=EntericMethane_Dairy_Equations.VEERG_3_3_1_1__6_MetabolisabilityOfDietVariation(F19)} -> 0.59485 | G24: {=EntericMethane_Dairy_Equations.VEERG_3_3_1_1__6_MetabolisabilityOfDietVariation(G19)} -> 0.59485 | H24: {=EntericMethane_Dairy_Equations.VEERG_3_3_1_1__6_MetabolisabilityOfDietVariation(H19)} -> 0.59485 | I24: =$E$12 -> fraction | M24: {=EntericMethane_Dairy_Equations.VEERG_3_3_1_1__6_MetabolisabilityOfDietVariation(M19)} -> 0.59485 | N24: {=EntericMethane_Dairy_Equations.VEERG_3_3_1_1__6_MetabolisabilityOfDietVariation(N19)} -> 0.59485 | O24: {=EntericMethane_Dairy_Equations.VEERG_3_3_1_1__6_MetabolisabilityOfDietVariation(O19)} -> 0.59485 | P24: {=EntericMethane_Dairy_Equations.VEERG_3_3_1_1__6_MetabolisabilityOfDietVariation(P19)} -> 0.59485 | Q24: {=EntericMethane_Dairy_Equations.VEERG_3_3_1_1__6_MetabolisabilityOfDietVariation(Q19)} -> 0.59485 | R24: =$E$12 -> fraction
D28: {=EntericMethane_Dairy_Equations.VEERG_3_3_1_1__5_MilkProductionFromMilkSolids_Title()} -> Milk production converted from milk solids
D29: {=EntericMethane_Dairy_Equations.VEERG_3_3_1_1__5_MilkProductionFromMilkSolids_Source()} -> VEERG 2026: 3.3.1.1, Equation (5)
D30: {=EntericMethane_Dairy_Equations.VEERG_3_3_1_1__5_MilkProductionFromMilkSolids_Variation()} -> VARATION ON SOURCE: Added milk production unit variable to allow for use of either milk solids or litres of milk. Converted input FC and PC percent to integer.
D31: Function name | E31: {=Common_InputFunctions.Utility_DisplayFunctionName(D50)} -> =EntericMethane_Dairy_Equations.VEERG_3_3_1_1__5_MilkProductionFromMilkSolids
D34: Variable | E34: {=EntericMethane_Dairy_Equations.VEERG_3_3_1_1__5_MilkProductionFromMilkSolids_Variable()} -> MP_j
D35: Unit | E35: {=EntericMethane_Dairy_Equations.VEERG_3_3_1_1__5_MilkProductionFromMilkSolids_Unit()} -> L/head/day
D37: {=_xlfn.CHOOSECOLS(EntericMethane_Dairy_Equations.VEERG_3_3_1_1__5_MilkProductionFromMilkSolids_Arguments(),1,2)} -> MPU | E37: input milk production unit | G37: {=_xlfn.CHOOSECOLS(EntericMethane_Dairy_Equations.VEERG_3_3_1_1__5_MilkProductionFromMilkSolids_Arguments(),3,4)} | H37: Input | I37: =X_Cell_Dairy_MilkProductionUnit -> Litres of milk | M37: {=_xlfn.CHOOSECOLS(EntericMethane_Dairy_Equations.VEERG_3_3_1_1__5_MilkProductionFromMilkSolids_Arguments_Method2(),1,2)} -> MPU | N37: milk production unit | P37: {=_xlfn.CHOOSECOLS(EntericMethane_Dairy_Equations.VEERG_3_3_1_1__5_MilkProductionFromMilkSolids_Arguments_Method2(),3,4)} | Q37: Input
D38: MS_j | E38: daily production of milk solids | G38: kg MS/head/day | H38: Input | I38: {=HYPERLINK(Common_InputFunctions.Utility_SourceHyperlink($D$42),$D$42)} -> M1_Table_MS_j | M38: MS_j | N38: daily production of milk solids | P38: kg MS/head/day | Q38: Input
D39: FC_j | E39: fat content in fat and protein corrected milk | G39: per cent | H39: Input | I39: =INDEX(X_Table_Dairy_MilkSolidAttributes,2,2)*100 -> 4 | M39: FC_j | N39: fat content in fat and protein corrected milk | P39: per cent | Q39: Input | R39: =INDEX(X_Table_Dairy_MilkSolidAttributes,2,3)*100 -> 4
D40: PC_j | E40: protein content in fat and protein corrected milk | G40: per cent | H40: Input | I40: =INDEX(X_Table_Dairy_MilkSolidAttributes,3,2)*100 -> 3.3 | M40: PC_j | N40: protein content in fat and protein corrected milk | P40: per cent | Q40: Input | R40: =INDEX(X_Table_Dairy_MilkSolidAttributes,3,3)*100 -> 3.3
D42: M1_Table_MS_j
D43: Milk solids production (Method 1)
D44: Milking cows | E44: Heifers > 1 year | F44: Heifers < 1 year | G44: Bulls > 1 year | H44: Bulls < 1 year
D45: =IF($I$37="Milk solids", X_Cell_Dairy_MilkProductionAmount, 0) -> 0 | E45: 0 | F45: 0 | G45: 0 | H45: 0 | I45: L/head/day
D47: M1_Table_MP_j_from_solids | M47: M2_Table_MP_j_from_solids
D48: Milk production from milk solids (Method 1) | M48: Milk production from milk solids (Method 2)
D49: Milking cows | E49: Heifers > 1 year | F49: Heifers < 1 year | G49: Bulls > 1 year | H49: Bulls < 1 year | M49: Milking cows | N49: Heifers > 1 year | O49: Heifers < 1 year | P49: Bulls > 1 year | Q49: Bulls < 1 year
D50: {=EntericMethane_Dairy_Equations.VEERG_3_3_1_1__5_MilkProductionFromMilkSolids(D45,I39,I40)} -> 0 | E50: 0 | F50: 0 | G50: 0 | H50: 0 | I50: L/head/day | M50: {=EntericMethane_Dairy_Equations.VEERG_3_3_1_1__5_MilkProductionFromMilkSolids(D45,R39,R40)} -> 0 | N50: 0 | O50: 0 | P50: 0 | Q50: 0 | R50: L/head/day
A51: =HYPERLINK("#A1", "▲ Back to top") -> ▲ Back to top
D54: {=EntericMethane_Dairy_Equations.VEERG_3_3_1_1__4_AdditionalIntakeForMilkProduction_Title()} -> Additional intake required for milk production
...

Sheet Constants - Dairy
A1: #VALUE! | C1: Source Data - Dairy
A3: =HYPERLINK("#'Home'!A1", "Home") -> Home
A4: =HYPERLINK("#'Overview'!A1", "Overview") -> Overview
A5: =HYPERLINK("#'Results'!A1", "Results") -> Results | D5: Dairy manure management systems | G5: Dairy crop or pasture production systems | J5: Irrigation methods
A7: INPUTS | D7: MMS | E7: Symbol and MMS | G7: Production system | J7: Irrigation method
A8: =HYPERLINK("#'Input - Site'!A1", "Site") -> Site | D8: ='Constants - Livestock'!$E$9 -> Anaerobic lagoon | E8: ='Constants - Livestock'!$F$9 -> Anaerobic lagoon (m=1) | G8: ='Constants - Common'!$F$187 -> Pasture | J8: Not irrigated
A9: =HYPERLINK("#'Input - Dairy'!A1", "Dairy") -> Dairy | D9: ='Constants - Livestock'!$E$12 -> Sump and dispersal system | E9: ='Constants - Livestock'!$F$12 -> Sump and dispersal system (m=3a) | G9: ='Constants - Common'!$F$188 -> Crop | J9: Drip irrigation
D10: ='Constants - Livestock'!$E$13 -> Drains to paddock | E10: ='Constants - Livestock'!$F$13 -> Drains to paddock (m=3b) | J10: Sprinkler irrigation
A11: CALCULATIONS | D11: ='Constants - Livestock'!$E$14 -> Solid storage | E11: ='Constants - Livestock'!$F$14 -> Solid storage (m=4) | J11: Surface irrigation
A12: =HYPERLINK("#'3.3.1.1-2 Enteric Methane'!A1", "3.3.1.1-2 Enteric Methane") -> 3.3.1.1-2 Enteric Methane | J12: Other irrigation
A14: APPENDICES
A15: =HYPERLINK("#'Constants - Dairy'!A1", "Constants - Dairy") -> Constants - Dairy
A16: =HYPERLINK("#'Constants - Livestock'!A1", "Constants - Livestock") -> Constants - Livestock | D16: {=SourceData_Dairy.SourceData_Dairy_LiveweightCowsAndHeifers_Title()} -> Table A.1.3.1: Dairy cattle - Liveweight (kg) - Cows and Heifers (Wj)
A17: =HYPERLINK("#'Constants - Common'!A1", "Constants - Common") -> Constants - Common | D17: {=SourceData_Dairy.SourceData_Dairy_LiveweightCowsAndHeifers_Source()} -> VEERG 2026: Table A.1.3.1
A18: =HYPERLINK("#'Acknowledgements'!A1", "Acknowledgements") -> Acknowledgements | D18: {=SourceData_Dairy.SourceData_Dairy_LiveweightCowsAndHeifers_Variable()} -> Wj
D19: {=SourceData_Dairy.SourceData_Dairy_LiveweightCowsAndHeifers_Unit()} -> kg
D20: {=SourceData_Dairy.SourceData_Dairy_LiveweightCowsAndHeifers_Variation()} -> VARIATION OF SOURCE: Excluded 'Reference', as the value is consistently 'Dairy Australia [1]' and is not used in calculation.
D21: Breed | E21: Milking cows | F21: Heifers > 1 | G21: Heifers < 1 (weaned)
D22: {=Common_InputFunctions.Utility_DisplayArrayInTable(SourceData_Dairy.SourceData_Dairy_LiveweightCowsAndHeifers_Data(), Table_SourceData_Dairy_WjCowsHeifers[[#Headers],[Breed]], 0)} -> Medium Friesian | E22: {=Common_InputFunctions.Utility_DisplayArrayInTable(SourceData_Dairy.SourceData_Dairy_LiveweightCowsAndHeifers_Data(), Table_SourceData_Dairy_WjCowsHeifers[[#Headers],[Breed]], 0)} -> 550 | F22: {=Common_InputFunctions.Utility_DisplayArrayInTable(SourceData_Dairy.SourceData_Dairy_LiveweightCowsAndHeifers_Data(), Table_SourceData_Dairy_WjCowsHeifers[[#Headers],[Breed]], 0)} -> 380 | G22: {=Common_InputFunctions.Utility_DisplayArrayInTable(SourceData_Dairy.SourceData_Dairy_LiveweightCowsAndHeifers_Data(), Table_SourceData_Dairy_WjCowsHeifers[[#Headers],[Breed]], 0)} -> 155
D23: {=Common_InputFunctions.Utility_DisplayArrayInTable(SourceData_Dairy.SourceData_Dairy_LiveweightCowsAndHeifers_Data(), Table_SourceData_Dairy_WjCowsHeifers[[#Headers],[Breed]], 0)} -> Large Friesian | E23: {=Common_InputFunctions.Utility_DisplayArrayInTable(SourceData_Dairy.SourceData_Dairy_LiveweightCowsAndHeifers_Data(), Table_SourceData_Dairy_WjCowsHeifers[[#Headers],[Breed]], 0)} -> 600 | F23: {=Common_InputFunctions.Utility_DisplayArrayInTable(SourceData_Dairy.SourceData_Dairy_LiveweightCowsAndHeifers_Data(), Table_SourceData_Dairy_WjCowsHeifers[[#Headers],[Breed]], 0)} -> 415 | G23: {=Common_InputFunctions.Utility_DisplayArrayInTable(SourceData_Dairy.SourceData_Dairy_LiveweightCowsAndHeifers_Data(), Table_SourceData_Dairy_WjCowsHeifers[[#Headers],[Breed]], 0)} -> 170
D24: {=Common_InputFunctions.Utility_DisplayArrayInTable(SourceData_Dairy.SourceData_Dairy_LiveweightCowsAndHeifers_Data(), Table_SourceData_Dairy_WjCowsHeifers[[#Headers],[Breed]], 0)} -> Holstein-Friesian | E24: {=Common_InputFunctions.Utility_DisplayArrayInTable(SourceData_Dairy.SourceData_Dairy_LiveweightCowsAndHeifers_Data(), Table_SourceData_Dairy_WjCowsHeifers[[#Headers],[Breed]], 0)} -> 650 | F24: {=Common_InputFunctions.Utility_DisplayArrayInTable(SourceData_Dairy.SourceData_Dairy_LiveweightCowsAndHeifers_Data(), Table_SourceData_Dairy_WjCowsHeifers[[#Headers],[Breed]], 0)} -> 450 | G24: {=Common_InputFunctions.Utility_DisplayArrayInTable(SourceData_Dairy.SourceData_Dairy_LiveweightCowsAndHeifers_Data(), Table_SourceData_Dairy_WjCowsHeifers[[#Headers],[Breed]], 0)} -> 185
D25: {=Common_InputFunctions.Utility_DisplayArrayInTable(SourceData_Dairy.SourceData_Dairy_LiveweightCowsAndHeifers_Data(), Table_SourceData_Dairy_WjCowsHeifers[[#Headers],[Breed]], 0)} -> Friesian crossbred | E25: {=Common_InputFunctions.Utility_DisplayArrayInTable(SourceData_Dairy.SourceData_Dairy_LiveweightCowsAndHeifers_Data(), Table_SourceData_Dairy_WjCowsHeifers[[#Headers],[Breed]], 0)} -> 500 | F25: {=Common_InputFunctions.Utility_DisplayArrayInTable(SourceData_Dairy.SourceData_Dairy_LiveweightCowsAndHeifers_Data(), Table_SourceData_Dairy_WjCowsHeifers[[#Headers],[Breed]], 0)} -> 350 | G25: {=Common_InputFunctions.Utility_DisplayArrayInTable(SourceData_Dairy.SourceData_Dairy_LiveweightCowsAndHeifers_Data(), Table_SourceData_Dairy_WjCowsHeifers[[#Headers],[Breed]], 0)} -> 145
D26: {=Common_InputFunctions.Utility_DisplayArrayInTable(SourceData_Dairy.SourceData_Dairy_LiveweightCowsAndHeifers_Data(), Table_SourceData_Dairy_WjCowsHeifers[[#Headers],[Breed]], 0)} -> Jersey | E26: {=Common_InputFunctions.Utility_DisplayArrayInTable(SourceData_Dairy.SourceData_Dairy_LiveweightCowsAndHeifers_Data(), Table_SourceData_Dairy_WjCowsHeifers[[#Headers],[Breed]], 0)} -> 400 | F26: {=Common_InputFunctions.Utility_DisplayArrayInTable(SourceData_Dairy.SourceData_Dairy_LiveweightCowsAndHeifers_Data(), Table_SourceData_Dairy_WjCowsHeifers[[#Headers],[Breed]], 0)} -> 275 | G26: {=Common_InputFunctions.Utility_DisplayArrayInTable(SourceData_Dairy.SourceData_Dairy_LiveweightCowsAndHeifers_Data(), Table_SourceData_Dairy_WjCowsHeifers[[#Headers],[Breed]], 0)} -> 115
D27: {=Common_InputFunctions.Utility_DisplayArrayInTable(SourceData_Dairy.SourceData_Dairy_LiveweightCowsAndHeifers_Data(), Table_SourceData_Dairy_WjCowsHeifers[[#Headers],[Breed]], 0)} -> Jersey crossbred | E27: {=Common_InputFunctions.Utility_DisplayArrayInTable(SourceData_Dairy.SourceData_Dairy_LiveweightCowsAndHeifers_Data(), Table_SourceData_Dairy_WjCowsHeifers[[#Headers],[Breed]], 0)} -> 450 | F27: {=Common_InputFunctions.Utility_DisplayArrayInTable(SourceData_Dairy.SourceData_Dairy_LiveweightCowsAndHeifers_Data(), Table_SourceData_Dairy_WjCowsHeifers[[#Headers],[Breed]], 0)} -> 315 | G27: {=Common_InputFunctions.Utility_DisplayArrayInTable(SourceData_Dairy.SourceData_Dairy_LiveweightCowsAndHeifers_Data(), Table_SourceData_Dairy_WjCowsHeifers[[#Headers],[Breed]], 0)} -> 130
D28: {=Common_InputFunctions.Utility_DisplayArrayInTable(SourceData_Dairy.SourceData_Dairy_LiveweightCowsAndHeifers_Data(), Table_SourceData_Dairy_WjCowsHeifers[[#Headers],[Breed]], 0)} -> Ayrshire | E28: {=Common_InputFunctions.Utility_DisplayArrayInTable(SourceData_Dairy.SourceData_Dairy_LiveweightCowsAndHeifers_Data(), Table_SourceData_Dairy_WjCowsHeifers[[#Headers],[Breed]], 0)} -> 540 | F28: {=Common_InputFunctions.Utility_DisplayArrayInTable(SourceData_Dairy.SourceData_Dairy_LiveweightCowsAndHeifers_Data(), Table_SourceData_Dairy_WjCowsHeifers[[#Headers],[Breed]], 0)} -> 375 | G28: {=Common_InputFunctions.Utility_DisplayArrayInTable(SourceData_Dairy.SourceData_Dairy_LiveweightCowsAndHeifers_Data(), Table_SourceData_Dairy_WjCowsHeifers[[#Headers],[Breed]], 0)} -> 150
D29: {=Common_InputFunctions.Utility_DisplayArrayInTable(SourceData_Dairy.SourceData_Dairy_LiveweightCowsAndHeifers_Data(), Table_SourceData_Dairy_WjCowsHeifers[[#Headers],[Breed]], 0)} -> Guernsey | E29: {=Common_InputFunctions.Utility_DisplayArrayInTable(SourceData_Dairy.SourceData_Dairy_LiveweightCowsAndHeifers_Data(), Table_SourceData_Dairy_WjCowsHeifers[[#Headers],[Breed]], 0)} -> 480 | F29: {=Common_InputFunctions.Utility_DisplayArrayInTable(SourceData_Dairy.SourceData_Dairy_LiveweightCowsAndHeifers_Data(), Table_SourceData_Dairy_WjCowsHeifers[[#Headers],[Breed]], 0)} -> 335 | G29: {=Common_InputFunctions.Utility_DisplayArrayInTable(SourceData_Dairy.SourceData_Dairy_LiveweightCowsAndHeifers_Data(), Table_SourceData_Dairy_WjCowsHeifers[[#Headers],[Breed]], 0)} -> 140
D30: {=Common_InputFunctions.Utility_DisplayArrayInTable(SourceData_Dairy.SourceData_Dairy_LiveweightCowsAndHeifers_Data(), Table_SourceData_Dairy_WjCowsHeifers[[#Headers],[Breed]], 0)} -> Brown Swiss | E30: {=Common_InputFunctions.Utility_DisplayArrayInTable(SourceData_Dairy.SourceData_Dairy_LiveweightCowsAndHeifers_Data(), Table_SourceData_Dairy_WjCowsHeifers[[#Headers],[Breed]], 0)} -> 600 | F30: {=Common_InputFunctions.Utility_DisplayArrayInTable(SourceData_Dairy.SourceData_Dairy_LiveweightCowsAndHeifers_Data(), Table_SourceData_Dairy_WjCowsHeifers[[#Headers],[Breed]], 0)} -> 415 | G30: {=Common_InputFunctions.Utility_DisplayArrayInTable(SourceData_Dairy.SourceData_Dairy_LiveweightCowsAndHeifers_Data(), Table_SourceData_Dairy_WjCowsHeifers[[#Headers],[Breed]], 0)} -> 170
D31: {=Common_InputFunctions.Utility_DisplayArrayInTable(SourceData_Dairy.SourceData_Dairy_LiveweightCowsAndHeifers_Data(), Table_SourceData_Dairy_WjCowsHeifers[[#Headers],[Breed]], 0)} -> Illawarra/Aussie Red | E31: {=Common_InputFunctions.Utility_DisplayArrayInTable(SourceData_Dairy.SourceData_Dairy_LiveweightCowsAndHeifers_Data(), Table_SourceData_Dairy_WjCowsHeifers[[#Headers],[Breed]], 0)} -> 550 | F31: {=Common_InputFunctions.Utility_DisplayArrayInTable(SourceData_Dairy.SourceData_Dairy_LiveweightCowsAndHeifers_Data(), Table_SourceData_Dairy_WjCowsHeifers[[#Headers],[Breed]], 0)} -> 375 | G31: {=Common_InputFunctions.Utility_DisplayArrayInTable(SourceData_Dairy.SourceData_Dairy_LiveweightCowsAndHeifers_Data(), Table_SourceData_Dairy_WjCowsHeifers[[#Headers],[Breed]], 0)} -> 150
D34: {=SourceData_Dairy.SourceData_Dairy_LiveweightBulls_Title()} -> Table A.1.3.2: Dairy cattle - Liveweight (kg) - Bulls (Wj)
D35: {=SourceData_Dairy.SourceData_Dairy_LiveweightBulls_Source()} -> VEERG 2026: Table A.1.3.2
D36: {=SourceData_Dairy.SourceData_Dairy_LiveweightBulls_Variable()} -> Wj
D37: {=SourceData_Dairy.SourceData_Dairy_LiveweightBulls_Unit()} -> kg
D38: Breed | E38: Bulls > 1 | F38: Bulls < 1 (weaned)
D39: {=Common_InputFunctions.Utility_DisplayArrayInTable(SourceData_Dairy.SourceData_Dairy_LiveweightBulls_Data(), Table_SourceData_Dairy_WjBulls[[#Headers],[Breed]], 0)} -> All breeds | E39: {=Common_InputFunctions.Utility_DisplayArrayInTable(SourceData_Dairy.SourceData_Dairy_LiveweightBulls_Data(), Table_SourceData_Dairy_WjBulls[[#Headers],[Breed]], 0)} -> 600 | F39: {=Common_InputFunctions.Utility_DisplayArrayInTable(SourceData_Dairy.SourceData_Dairy_LiveweightBulls_Data(), Table_SourceData_Dairy_WjBulls[[#Headers],[Breed]], 0)} -> 225
D42: {=SourceData_Dairy.SourceData_Dairy_LiveweightGain_Title()} -> Table A.1.3.3: Dairy cattle - Liveweight gain (kg) (LWGj)
D43: {=SourceData_Dairy.SourceData_Dairy_LiveweightGain_Source()} -> VEERG 2026: Table A.1.3.3
D44: {=SourceData_Dairy.SourceData_Dairy_LiveweightGain_Variable()} -> LWGj
D45: {=SourceData_Dairy.SourceData_Dairy_LiveweightGain_Unit()} -> kg
D46: Milking cows | E46: Heifers > 1 | F46: Heifers < 1 (weaned) | G46: Bulls > 1 | H46: Bulls < 1 (weaned)
D47: {=Common_InputFunctions.Utility_DisplayArrayInTable(SourceData_Dairy.SourceData_Dairy_LiveweightGain_Data(), Table_SourceData_Dairy_LWGj[[#Headers],[Milking cows]], 0)} -> 0.016 | E47: {=Common_InputFunctions.Utility_DisplayArrayInTable(SourceData_Dairy.SourceData_Dairy_LiveweightGain_Data(), Table_SourceData_Dairy_LWGj[[#Headers],[Milking cows]], 0)} -> 0.6 | F47: {=Common_InputFunctions.Utility_DisplayArrayInTable(SourceData_Dairy.SourceData_Dairy_LiveweightGain_Data(), Table_SourceData_Dairy_LWGj[[#Headers],[Milking cows]], 0)} -> 0.57 | G47: {=Common_InputFunctions.Utility_DisplayArrayInTable(SourceData_Dairy.SourceData_Dairy_LiveweightGain_Data(), Table_SourceData_Dairy_LWGj[[#Headers],[Milking cows]], 0)} -> 0.1 | H47: {=Common_InputFunctions.Utility_DisplayArrayInTable(SourceData_Dairy.SourceData_Dairy_LiveweightGain_Data(), Table_SourceData_Dairy_LWGj[[#Headers],[Milking cows]], 0)} -> 0.8
...

Sheet Constants - Common
A1: #VALUE! | C1: Constants - Common
D5: {=Common_SourceData.Common_SourceData_AustralianStatesTerritories_Title()} -> Australian states and territories
D6: State/Territory | E6: Common Name | F6: Abbreviation
D7: {=Common_InputFunctions.Utility_DisplayArrayInTable(Common_SourceData.Common_SourceData_AustralianStatesTerritories_Data(),Table_AustralianStates[[#Headers],[State/Territory]],0)} -> New South Wales | E7: {=Common_InputFunctions.Utility_DisplayArrayInTable(Common_SourceData.Common_SourceData_AustralianStatesTerritories_Data(),Table_AustralianStates[[#Headers],[State/Territory]],0)} -> New South Wales | F7: {=Common_InputFunctions.Utility_DisplayArrayInTable(Common_SourceData.Common_SourceData_AustralianStatesTerritories_Data(),Table_AustralianStates[[#Headers],[State/Territory]],0)} -> NSW
D8: {=Common_InputFunctions.Utility_DisplayArrayInTable(Common_SourceData.Common_SourceData_AustralianStatesTerritories_Data(),Table_AustralianStates[[#Headers],[State/Territory]],0)} -> Australian Capital Territory | E8: {=Common_InputFunctions.Utility_DisplayArrayInTable(Common_SourceData.Common_SourceData_AustralianStatesTerritories_Data(),Table_AustralianStates[[#Headers],[State/Territory]],0)} -> ACT | F8: {=Common_InputFunctions.Utility_DisplayArrayInTable(Common_SourceData.Common_SourceData_AustralianStatesTerritories_Data(),Table_AustralianStates[[#Headers],[State/Territory]],0)} -> ACT
D9: {=Common_InputFunctions.Utility_DisplayArrayInTable(Common_SourceData.Common_SourceData_AustralianStatesTerritories_Data(),Table_AustralianStates[[#Headers],[State/Territory]],0)} -> Victoria | E9: {=Common_InputFunctions.Utility_DisplayArrayInTable(Common_SourceData.Common_SourceData_AustralianStatesTerritories_Data(),Table_AustralianStates[[#Headers],[State/Territory]],0)} -> Victoria | F9: {=Common_InputFunctions.Utility_DisplayArrayInTable(Common_SourceData.Common_SourceData_AustralianStatesTerritories_Data(),Table_AustralianStates[[#Headers],[State/Territory]],0)} -> VIC
D10: {=Common_InputFunctions.Utility_DisplayArrayInTable(Common_SourceData.Common_SourceData_AustralianStatesTerritories_Data(),Table_AustralianStates[[#Headers],[State/Territory]],0)} -> Queensland | E10: {=Common_InputFunctions.Utility_DisplayArrayInTable(Common_SourceData.Common_SourceData_AustralianStatesTerritories_Data(),Table_AustralianStates[[#Headers],[State/Territory]],0)} -> Queensland | F10: {=Common_InputFunctions.Utility_DisplayArrayInTable(Common_SourceData.Common_SourceData_AustralianStatesTerritories_Data(),Table_AustralianStates[[#Headers],[State/Territory]],0)} -> QLD
D11: {=Common_InputFunctions.Utility_DisplayArrayInTable(Common_SourceData.Common_SourceData_AustralianStatesTerritories_Data(),Table_AustralianStates[[#Headers],[State/Territory]],0)} -> South Australia | E11: {=Common_InputFunctions.Utility_DisplayArrayInTable(Common_SourceData.Common_SourceData_AustralianStatesTerritories_Data(),Table_AustralianStates[[#Headers],[State/Territory]],0)} -> South Australia | F11: {=Common_InputFunctions.Utility_DisplayArrayInTable(Common_SourceData.Common_SourceData_AustralianStatesTerritories_Data(),Table_AustralianStates[[#Headers],[State/Territory]],0)} -> SA
D12: {=Common_InputFunctions.Utility_DisplayArrayInTable(Common_SourceData.Common_SourceData_AustralianStatesTerritories_Data(),Table_AustralianStates[[#Headers],[State/Territory]],0)} -> Western Australia | E12: {=Common_InputFunctions.Utility_DisplayArrayInTable(Common_SourceData.Common_SourceData_AustralianStatesTerritories_Data(),Table_AustralianStates[[#Headers],[State/Territory]],0)} -> Western Australia | F12: {=Common_InputFunctions.Utility_DisplayArrayInTable(Common_SourceData.Common_SourceData_AustralianStatesTerritories_Data(),Table_AustralianStates[[#Headers],[State/Territory]],0)} -> WA
D13: {=Common_InputFunctions.Utility_DisplayArrayInTable(Common_SourceData.Common_SourceData_AustralianStatesTerritories_Data(),Table_AustralianStates[[#Headers],[State/Territory]],0)} -> Tasmania | E13: {=Common_InputFunctions.Utility_DisplayArrayInTable(Common_SourceData.Common_SourceData_AustralianStatesTerritories_Data(),Table_AustralianStates[[#Headers],[State/Territory]],0)} -> Tasmania | F13: {=Common_InputFunctions.Utility_DisplayArrayInTable(Common_SourceData.Common_SourceData_AustralianStatesTerritories_Data(),Table_AustralianStates[[#Headers],[State/Territory]],0)} -> TAS
D14: {=Common_InputFunctions.Utility_DisplayArrayInTable(Common_SourceData.Common_SourceData_AustralianStatesTerritories_Data(),Table_AustralianStates[[#Headers],[State/Territory]],0)} -> Northern Territory | E14: {=Common_InputFunctions.Utility_DisplayArrayInTable(Common_SourceData.Common_SourceData_AustralianStatesTerritories_Data(),Table_AustralianStates[[#Headers],[State/Territory]],0)} -> Northern Territory | F14: {=Common_InputFunctions.Utility_DisplayArrayInTable(Common_SourceData.Common_SourceData_AustralianStatesTerritories_Data(),Table_AustralianStates[[#Headers],[State/Territory]],0)} -> NT
D18: {=Common_SourceData.Common_SourceData_WASA4Areas_Title()} -> ABS Statistcal Areas Level 4 - Western Australia
D19: {=Common_SourceData.Common_SourceData_WASA4Areas_Source()} -> Australian Bureau of Statistics (ABS) - Statistical Areas Level 2 - 2021 - Shapefile
D20: SA 4 Name
D21: {=Common_InputFunctions.Utility_DisplayArrayInTable(Common_SourceData.Common_SourceData_WASA4Areas_Data(), Table_WASA4Areas[[#Headers],[SA 4 Name]], 0)} -> Bunbury
D22: {=Common_InputFunctions.Utility_DisplayArrayInTable(Common_SourceData.Common_SourceData_WASA4Areas_Data(), Table_WASA4Areas[[#Headers],[SA 4 Name]], 0)} -> Mandurah
D23: {=Common_InputFunctions.Utility_DisplayArrayInTable(Common_SourceData.Common_SourceData_WASA4Areas_Data(), Table_WASA4Areas[[#Headers],[SA 4 Name]], 0)} -> Perth - Inner
D24: {=Common_InputFunctions.Utility_DisplayArrayInTable(Common_SourceData.Common_SourceData_WASA4Areas_Data(), Table_WASA4Areas[[#Headers],[SA 4 Name]], 0)} -> Perth - North East
D25: {=Common_InputFunctions.Utility_DisplayArrayInTable(Common_SourceData.Common_SourceData_WASA4Areas_Data(), Table_WASA4Areas[[#Headers],[SA 4 Name]], 0)} -> Perth - North West
D26: {=Common_InputFunctions.Utility_DisplayArrayInTable(Common_SourceData.Common_SourceData_WASA4Areas_Data(), Table_WASA4Areas[[#Headers],[SA 4 Name]], 0)} -> Perth - South East
D27: {=Common_InputFunctions.Utility_DisplayArrayInTable(Common_SourceData.Common_SourceData_WASA4Areas_Data(), Table_WASA4Areas[[#Headers],[SA 4 Name]], 0)} -> Perth - South West
D28: {=Common_InputFunctions.Utility_DisplayArrayInTable(Common_SourceData.Common_SourceData_WASA4Areas_Data(), Table_WASA4Areas[[#Headers],[SA 4 Name]], 0)} -> Western Australia - Wheat Belt
D29: {=Common_InputFunctions.Utility_DisplayArrayInTable(Common_SourceData.Common_SourceData_WASA4Areas_Data(), Table_WASA4Areas[[#Headers],[SA 4 Name]], 0)} -> Western Australia - Outback (North)
D30: {=Common_InputFunctions.Utility_DisplayArrayInTable(Common_SourceData.Common_SourceData_WASA4Areas_Data(), Table_WASA4Areas[[#Headers],[SA 4 Name]], 0)} -> Western Australia - Outback (South)
D34: {=Common_SourceData.Common_SourceData_GWP_Title()} -> Global warming potential for greenhouse gases
D35: {=Common_SourceData.Common_SourceData_GWP_Source()} -> XXXXXXX
D36: Gas | E36: CO2-e factor
D37: {=Common_InputFunctions.Utility_DisplayArrayInTable(Common_SourceData.Common_SourceData_GWP_Data(), Table_GWPData[[#Headers],[Gas]], 0)} -> CO2 | E37: {=Common_InputFunctions.Utility_DisplayArrayInTable(Common_SourceData.Common_SourceData_GWP_Data(), Table_GWPData[[#Headers],[Gas]], 0)} -> 1
D38: {=Common_InputFunctions.Utility_DisplayArrayInTable(Common_SourceData.Common_SourceData_GWP_Data(), Table_GWPData[[#Headers],[Gas]], 0)} -> CH4 | E38: {=Common_InputFunctions.Utility_DisplayArrayInTable(Common_SourceData.Common_SourceData_GWP_Data(), Table_GWPData[[#Headers],[Gas]], 0)} -> 28
D39: {=Common_InputFunctions.Utility_DisplayArrayInTable(Common_SourceData.Common_SourceData_GWP_Data(), Table_GWPData[[#Headers],[Gas]], 0)} -> N2O | E39: {=Common_InputFunctions.Utility_DisplayArrayInTable(Common_SourceData.Common_SourceData_GWP_Data(), Table_GWPData[[#Headers],[Gas]], 0)} -> 265
D40: {=Common_InputFunctions.Utility_DisplayArrayInTable(Common_SourceData.Common_SourceData_GWP_Data(), Table_GWPData[[#Headers],[Gas]], 0)} -> CF4 | E40: {=Common_InputFunctions.Utility_DisplayArrayInTable(Common_SourceData.Common_SourceData_GWP_Data(), Table_GWPData[[#Headers],[Gas]], 0)} -> 6630
D41: {=Common_InputFunctions.Utility_DisplayArrayInTable(Common_SourceData.Common_SourceData_GWP_Data(), Table_GWPData[[#Headers],[Gas]], 0)} -> C2F6 | E41: {=Common_InputFunctions.Utility_DisplayArrayInTable(Common_SourceData.Common_SourceData_GWP_Data(), Table_GWPData[[#Headers],[Gas]], 0)} -> 12200
D42: {=Common_InputFunctions.Utility_DisplayArrayInTable(Common_SourceData.Common_SourceData_GWP_Data(), Table_GWPData[[#Headers],[Gas]], 0)} -> SF6 | E42: {=Common_InputFunctions.Utility_DisplayArrayInTable(Common_SourceData.Common_SourceData_GWP_Data(), Table_GWPData[[#Headers],[Gas]], 0)} -> 22800
D43: {=Common_InputFunctions.Utility_DisplayArrayInTable(Common_SourceData.Common_SourceData_GWP_Data(), Table_GWPData[[#Headers],[Gas]], 0)} -> NF3 | E43: {=Common_InputFunctions.Utility_DisplayArrayInTable(Common_SourceData.Common_SourceData_GWP_Data(), Table_GWPData[[#Headers],[Gas]], 0)} -> 17200
D45: {=Common_SourceData.Common_SourceData_ConvertGasElementalToMolecular_Title()} -> Factor to convert elemental mass of gas to molecular mass
D46: {=Common_SourceData.Common_SourceData_ConvertGasElementalToMolecular_Source()} -> XXXXXXX
D47: Gas | E47: Conversion factor | F47: Conversion factor 1 | G47: Conversion factor 2 | H47: Conversion factor combined
D48: {=Common_InputFunctions.Utility_DisplayArrayInTable(Common_SourceData.Common_SourceData_ConvertGasElementalToMolecular_Data(),Table_GasToMolecularConversionFactor[[#Headers],[Gas]], 0)} -> CO2 | E48: {=Common_InputFunctions.Utility_DisplayArrayInTable(Common_SourceData.Common_SourceData_ConvertGasElementalToMolecular_Data(),Table_GasToMolecularConversionFactor[[#Headers],[Gas]], 0)} -> 44/12 | F48: {=Common_InputFunctions.Utility_DisplayArrayInTable(Common_SourceData.Common_SourceData_ConvertGasElementalToMolecular_Data(),Table_GasToMolecularConversionFactor[[#Headers],[Gas]], 0)} -> 44 | G48: {=Common_InputFunctions.Utility_DisplayArrayInTable(Common_SourceData.Common_SourceData_ConvertGasElementalToMolecular_Data(),Table_GasToMolecularConversionFactor[[#Headers],[Gas]], 0)} -> 12 | H48: =Table_GasToMolecularConversionFactor[[#This Row],[Conversion factor 1]]/Table_GasToMolecularConversionFactor[[#This Row],[Conversion factor 2]] -> 3.6666667
D49: {=Common_InputFunctions.Utility_DisplayArrayInTable(Common_SourceData.Common_SourceData_ConvertGasElementalToMolecular_Data(),Table_GasToMolecularConversionFactor[[#Headers],[Gas]], 0)} -> CH4 | E49: {=Common_InputFunctions.Utility_DisplayArrayInTable(Common_SourceData.Common_SourceData_ConvertGasElementalToMolecular_Data(),Table_GasToMolecularConversionFactor[[#Headers],[Gas]], 0)} -> 16/12 | F49: {=Common_InputFunctions.Utility_DisplayArrayInTable(Common_SourceData.Common_SourceData_ConvertGasElementalToMolecular_Data(),Table_GasToMolecularConversionFactor[[#Headers],[Gas]], 0)} -> 16 | G49: {=Common_InputFunctions.Utility_DisplayArrayInTable(Common_SourceData.Common_SourceData_ConvertGasElementalToMolecular_Data(),Table_GasToMolecularConversionFactor[[#Headers],[Gas]], 0)} -> 12 | H49: =Table_GasToMolecularConversionFactor[[#This Row],[Conversion factor 1]]/Table_GasToMolecularConversionFactor[[#This Row],[Conversion factor 2]] -> 1.3333333
D50: {=Common_InputFunctions.Utility_DisplayArrayInTable(Common_SourceData.Common_SourceData_ConvertGasElementalToMolecular_Data(),Table_GasToMolecularConversionFactor[[#Headers],[Gas]], 0)} -> N2O | E50: {=Common_InputFunctions.Utility_DisplayArrayInTable(Common_SourceData.Common_SourceData_ConvertGasElementalToMolecular_Data(),Table_GasToMolecularConversionFactor[[#Headers],[Gas]], 0)} -> 44/28 | F50: {=Common_InputFunctions.Utility_DisplayArrayInTable(Common_SourceData.Common_SourceData_ConvertGasElementalToMolecular_Data(),Table_GasToMolecularConversionFactor[[#Headers],[Gas]], 0)} -> 44 | G50: {=Common_InputFunctions.Utility_DisplayArrayInTable(Common_SourceData.Common_SourceData_ConvertGasElementalToMolecular_Data(),Table_GasToMolecularConversionFactor[[#Headers],[Gas]], 0)} -> 28 | H50: =Table_GasToMolecularConversionFactor[[#This Row],[Conversion factor 1]]/Table_GasToMolecularConversionFactor[[#This Row],[Conversion factor 2]] -> 1.5714286
...

Sheet Constants - Livestock
A1: #VALUE! | C1: Constants - Livestock
A3: =HYPERLINK("#'Home'!A1", "Home") -> Home
A4: =HYPERLINK("#'Overview'!A1", "Overview") -> Overview
A5: =HYPERLINK("#'Results'!A1", "Results") -> Results | D5: {=CommonLivestock_SourceData.SourceData_Livestock_Common_SymbolsMMS_Title()} -> Table 5.12 Additional symbols used in algorithms for manure related emissions
D6: {=CommonLivestock_SourceData.SourceData_Livestock_Common_SymbolsMMS_Vairable()} -> MMS
A7: INPUTS | D7: {=CommonLivestock_SourceData.SourceData_Livestock_Common_SymbolsMMS_Source()} -> National Inventory Report 2023 Volume 1: Table 5.12
A8: =HYPERLINK("#'Input - Site'!A1", "Site") -> Site | D8: Symbol | E8: Manure management system | F8: Symbol and MMS
A9: =HYPERLINK("#'Input - Dairy'!A1", "Dairy") -> Dairy | D9: {=Common_InputFunctions.Utility_DisplayArrayInTable(CommonLivestock_SourceData.SourceData_Livestock_Common_SymbolsMMS_Data(), Table_Data_MMSSymbols[[#Headers],[Symbol]], 0)} -> 1 | E9: {=Common_InputFunctions.Utility_DisplayArrayInTable(CommonLivestock_SourceData.SourceData_Livestock_Common_SymbolsMMS_Data(), Table_Data_MMSSymbols[[#Headers],[Symbol]], 0)} -> Anaerobic lagoon | F9: {=Common_InputFunctions.Utility_DisplayArrayInTable(CommonLivestock_SourceData.SourceData_Livestock_Common_SymbolsMMS_Data(), Table_Data_MMSSymbols[[#Headers],[Symbol]], 0)} -> Anaerobic lagoon (m=1)
D10: {=Common_InputFunctions.Utility_DisplayArrayInTable(CommonLivestock_SourceData.SourceData_Livestock_Common_SymbolsMMS_Data(), Table_Data_MMSSymbols[[#Headers],[Symbol]], 0)} -> 2 | E10: {=Common_InputFunctions.Utility_DisplayArrayInTable(CommonLivestock_SourceData.SourceData_Livestock_Common_SymbolsMMS_Data(), Table_Data_MMSSymbols[[#Headers],[Symbol]], 0)} -> Liquid systems | F10: {=Common_InputFunctions.Utility_DisplayArrayInTable(CommonLivestock_SourceData.SourceData_Livestock_Common_SymbolsMMS_Data(), Table_Data_MMSSymbols[[#Headers],[Symbol]], 0)} -> Liquid systems (m=2)
A11: CALCULATIONS | D11: {=Common_InputFunctions.Utility_DisplayArrayInTable(CommonLivestock_SourceData.SourceData_Livestock_Common_SymbolsMMS_Data(), Table_Data_MMSSymbols[[#Headers],[Symbol]], 0)} -> 3 | E11: {=Common_InputFunctions.Utility_DisplayArrayInTable(CommonLivestock_SourceData.SourceData_Livestock_Common_SymbolsMMS_Data(), Table_Data_MMSSymbols[[#Headers],[Symbol]], 0)} -> Daily spread | F11: {=Common_InputFunctions.Utility_DisplayArrayInTable(CommonLivestock_SourceData.SourceData_Livestock_Common_SymbolsMMS_Data(), Table_Data_MMSSymbols[[#Headers],[Symbol]], 0)} -> Daily spread (m=3)
A12: =HYPERLINK("#'3.3.1.1-2 Enteric Methane'!A1", "3.3.1.1-2 Enteric Methane") -> 3.3.1.1-2 Enteric Methane | D12: {=Common_InputFunctions.Utility_DisplayArrayInTable(CommonLivestock_SourceData.SourceData_Livestock_Common_SymbolsMMS_Data(), Table_Data_MMSSymbols[[#Headers],[Symbol]], 0)} -> 3a | E12: {=Common_InputFunctions.Utility_DisplayArrayInTable(CommonLivestock_SourceData.SourceData_Livestock_Common_SymbolsMMS_Data(), Table_Data_MMSSymbols[[#Headers],[Symbol]], 0)} -> Sump and dispersal system | F12: {=Common_InputFunctions.Utility_DisplayArrayInTable(CommonLivestock_SourceData.SourceData_Livestock_Common_SymbolsMMS_Data(), Table_Data_MMSSymbols[[#Headers],[Symbol]], 0)} -> Sump and dispersal system (m=3a)
D13: {=Common_InputFunctions.Utility_DisplayArrayInTable(CommonLivestock_SourceData.SourceData_Livestock_Common_SymbolsMMS_Data(), Table_Data_MMSSymbols[[#Headers],[Symbol]], 0)} -> 3b | E13: {=Common_InputFunctions.Utility_DisplayArrayInTable(CommonLivestock_SourceData.SourceData_Livestock_Common_SymbolsMMS_Data(), Table_Data_MMSSymbols[[#Headers],[Symbol]], 0)} -> Drains to paddock | F13: {=Common_InputFunctions.Utility_DisplayArrayInTable(CommonLivestock_SourceData.SourceData_Livestock_Common_SymbolsMMS_Data(), Table_Data_MMSSymbols[[#Headers],[Symbol]], 0)} -> Drains to paddock (m=3b)
A14: APPENDICES | D14: {=Common_InputFunctions.Utility_DisplayArrayInTable(CommonLivestock_SourceData.SourceData_Livestock_Common_SymbolsMMS_Data(), Table_Data_MMSSymbols[[#Headers],[Symbol]], 0)} -> 4 | E14: {=Common_InputFunctions.Utility_DisplayArrayInTable(CommonLivestock_SourceData.SourceData_Livestock_Common_SymbolsMMS_Data(), Table_Data_MMSSymbols[[#Headers],[Symbol]], 0)} -> Solid storage | F14: {=Common_InputFunctions.Utility_DisplayArrayInTable(CommonLivestock_SourceData.SourceData_Livestock_Common_SymbolsMMS_Data(), Table_Data_MMSSymbols[[#Headers],[Symbol]], 0)} -> Solid storage (m=4)
A15: =HYPERLINK("#'Constants - Dairy'!A1", "Constants - Dairy") -> Constants - Dairy | D15: {=Common_InputFunctions.Utility_DisplayArrayInTable(CommonLivestock_SourceData.SourceData_Livestock_Common_SymbolsMMS_Data(), Table_Data_MMSSymbols[[#Headers],[Symbol]], 0)} -> 5 | E15: {=Common_InputFunctions.Utility_DisplayArrayInTable(CommonLivestock_SourceData.SourceData_Livestock_Common_SymbolsMMS_Data(), Table_Data_MMSSymbols[[#Headers],[Symbol]], 0)} -> Drylot (feed pad) | F15: {=Common_InputFunctions.Utility_DisplayArrayInTable(CommonLivestock_SourceData.SourceData_Livestock_Common_SymbolsMMS_Data(), Table_Data_MMSSymbols[[#Headers],[Symbol]], 0)} -> Drylot (feed pad) (m=5)
