Workbook
Name Common_Equations.Common_ConvertCH4ToCO2e: _xlfn.LAMBDA(_xlpm.E_CH4,_xlpm.GWP_CH4, _xlpm.E_CH4 * _xlpm.GWP_CH4)
Name Common_Equations.Common_ConvertCH4ToCO2e_Arguments: _xlfn.LAMBDA(_xlfn.MAKEARRAY(2, 2, _xlfn.LAMBDA(_xlpm.r,_xlpm.c, INDEX({"ECH4","Methane emissions (t CH4)";"GWPCH4","Global warming potential for methane (t CO2-e / t CH4)"}, _xlpm.r, _xlpm.c))))
Name Common_Equations.Common_ConvertCH4ToCO2e_LatexEquation: _xlfn.LAMBDA("CO2_e = E_{CH4} \times GWP_{CH4}")
Name Common_Equations.Common_ConvertCH4ToCO2e_NIRReference: _xlfn.LAMBDA("")
Name Common_Equations.Common_ConvertCH4ToCO2e_Title: _xlfn.LAMBDA("Convert methane emissions to carbon dioxide equivalent emissions")
Name Common_Equations.Common_ConvertCH4ToCO2e_Unit: _xlfn.LAMBDA("t CO2e")
Name Common_Equations.Common_ConvertCH4ToCO2e_Variable: _xlfn.LAMBDA("ECH4 CO2e")
Name Common_Equations.Common_ConvertN2OToCO2e: _xlfn.LAMBDA(_xlpm.E_N2O,_xlpm.GWP_N2O, _xlpm.E_N2O * _xlpm.GWP_N2O)
Name Common_Equations.Common_ConvertN2OToCO2e_LatexEquation: _xlfn.LAMBDA("CO2_e = E_{N2O} \times GWP_{N2O}")
Name Common_Equations.Common_ConvertN2OToCO2e_NIRReference: _xlfn.LAMBDA("")
Name Common_Equations.Common_ConvertN2OToCO2e_Title: _xlfn.LAMBDA("Convert nitrous oxide emissions to carbon dioxide equivalent emissions")
Name Common_Equations.Common_ConvertN2OToCO2e_Unit: _xlfn.LAMBDA("t CO2e")
Name Common_Equations.Common_ConvertN2OToCO2e_Variable: _xlfn.LAMBDA("EN2O CO2e")
Name Common_InputFunctions.Utility_DisplayFunctionName: _xlfn.LAMBDA(_xlpm.Function, _xlfn.FORMULATEXT(_xlpm.Function))
Name Common_InputFunctions.Utility_GetArrayTableColumnStartNumber: _xlfn.LAMBDA(_xlpm.TableHeaderCell, COLUMN(_xlpm.TableHeaderCell))
Name Common_InputFunctions.Utility_GetArrayTableRowStartNumber: _xlfn.LAMBDA(_xlpm.TableheaderCell,_xlpm.RowsBetweenHeaderandArray, ROW(_xlpm.TableheaderCell) + _xlpm.RowsBetweenHeaderandArray - 1)
Name Common_InputFunctions.Utility_LookupValueInTable: _xlfn.LAMBDA(_xlpm.LookupValue,_xlpm.LookupArray,_xlpm.ReturnArray, _xlfn.XLOOKUP(_xlpm.LookupValue, _xlpm.LookupArray, _xlpm.ReturnArray, ""))
Name Common_SourceData.Common_SourceData_AustralianStatesTerritories_Source: _xlfn.LAMBDA("")
Name Common_SourceData.Common_SourceData_AustralianStatesTerritories_Title: _xlfn.LAMBDA("Australian states and territories")
Name Common_SourceData.Common_SourceData_AustralianStatesTerritories_Unit: _xlfn.LAMBDA("")
Name Common_SourceData.Common_SourceData_AustralianStatesTerritories_Variable: _xlfn.LAMBDA("")
Name Common_SourceData.Common_SourceData_ClimateZones_Source: _xlfn.LAMBDA("VEERG 2026: Table 1.3: Climate and Rainfall zone classifications and definitions")
Name Common_SourceData.Common_SourceData_ClimateZones_Title: _xlfn.LAMBDA("VEERG Australian climate zones")
Name Common_SourceData.Common_SourceData_ClimateZones_Unit: _xlfn.LAMBDA("")
Name Common_SourceData.Common_SourceData_ClimateZones_Variable: _xlfn.LAMBDA("")
Name Common_SourceData.Common_SourceData_ConvertGasElementalToMolecular_Source: _xlfn.LAMBDA("XXXXXXX")
Name Common_SourceData.Common_SourceData_ConvertGasElementalToMolecular_Title: _xlfn.LAMBDA("Factor to convert elemental mass of gas to molecular mass")
Name Common_SourceData.Common_SourceData_ConvertGasElementalToMolecular_Unit: _xlfn.LAMBDA("factor")
Name Common_SourceData.Common_SourceData_ConvertGasElementalToMolecular_Variable: _xlfn.LAMBDA("Cg")
Name Common_SourceData.Common_SourceData_ConvertN2oElementalToMolecularCg_Data: _xlfn.LAMBDA(44 / 28)
Name Common_SourceData.Common_SourceData_ConvertN2oElementalToMolecularCg_Source: _xlfn.LAMBDA("National Inventory Report 2023 Volume 1")
Name Common_SourceData.Common_SourceData_ConvertN2oElementalToMolecularCg_Title: _xlfn.LAMBDA("Factor to convert elemental mass of N2O to molecular mass")
Name Common_SourceData.Common_SourceData_ConvertN2oElementalToMolecularCg_Unit: _xlfn.LAMBDA("factor")
Name Common_SourceData.Common_SourceData_ConvertN2oElementalToMolecularCg_Variable: _xlfn.LAMBDA("CgN2O")
Name Common_SourceData.Common_SourceData_DataScores_Scope3_Source: _xlfn.LAMBDA("VEERG 2026: XXXXXXXX")
Name Common_SourceData.Common_SourceData_DataScores_Scope3_Title: _xlfn.LAMBDA("Australian data scores for scope 3")
Name Common_SourceData.Common_SourceData_DataScores_Scope3_Unit: _xlfn.LAMBDA("")
Name Common_SourceData.Common_SourceData_DataScores_Scope3_Variable: _xlfn.LAMBDA("")
Name Common_SourceData.Common_SourceData_DataScores_Scope3_Variation: _xlfn.LAMBDA("")
Name Common_SourceData.Common_SourceData_DensityOfMethane_Data: _xlfn.LAMBDA(0.6784)
Name Common_SourceData.Common_SourceData_DensityOfMethane_Source: _xlfn.LAMBDA("National Inventory Report 2023 Volume 1: Equations 3.B.1a_2, 3.B.1c_2, 3.B.3_1, 3.B.4g_2")
Name Common_SourceData.Common_SourceData_DensityOfMethane_Title: _xlfn.LAMBDA("p = density of methane")
Name Common_SourceData.Common_SourceData_DensityOfMethane_Unit: _xlfn.LAMBDA("kg/m3")
Name Common_SourceData.Common_SourceData_EFleach_Data: _xlfn.LAMBDA(_xlfn.MAKEARRAY(1, 2, _xlfn.LAMBDA(_xlpm.r,_xlpm.c, INDEX({"EFleach",0.011}, _xlpm.r, _xlpm.c))))
Name Common_SourceData.Common_SourceData_EFleach_NIRReference: _xlfn.LAMBDA("National Inventory Report Volume 1: Equation 3.D.B_10")
Name Common_SourceData.Common_SourceData_EFleach_Source: _xlfn.LAMBDA("VEERG 2026:5.5.2.3 Constant Parameters")
Name Common_SourceData.Common_SourceData_EFleach_Title: _xlfn.LAMBDA("Emission factor for nitrogen leaching and runoff")
Name Common_SourceData.Common_SourceData_EFleach_Unit: _xlfn.LAMBDA("(kg N2O-N / kg N")
Name Common_SourceData.Common_SourceData_EFleach_Variation: _xlfn.LAMBDA((""))
Name Common_SourceData.Common_SourceData_EFN2O_NIRReference: _xlfn.LAMBDA("")
Name Common_SourceData.Common_SourceData_EFN2O_Source: _xlfn.LAMBDA("VEERG 2026: Table A.2.2.1")
Name Common_SourceData.Common_SourceData_EFN2O_Title: _xlfn.LAMBDA("Nitrous oxide emission factors for inorganic fertiliser application")
Name Common_SourceData.Common_SourceData_EFN2O_Unit: _xlfn.LAMBDA("(kg N2O-N / kg N")
Name Common_SourceData.Common_SourceData_EFPastureRangeAndPaddock_Data: _xlfn.LAMBDA(_xlfn.MAKEARRAY(3, 2, _xlfn.LAMBDA(_xlpm.r,_xlpm.c, INDEX({"Climate zone","EFPRP";"Wet climate zone",0.006;"Dry climate zone",0.002}, _xlpm.r, _xlpm.c))))
Name Common_SourceData.Common_SourceData_EFPastureRangeAndPaddock_NIRReference: _xlfn.LAMBDA("")
Name Common_SourceData.Common_SourceData_EFPastureRangeAndPaddock_Source: _xlfn.LAMBDA("VEERG 2026: Table A.2.2.2")
Name Common_SourceData.Common_SourceData_EFPastureRangeAndPaddock_Title: _xlfn.LAMBDA("Emission factor for urine and dung deposited on pasture, range or paddock")
Name Common_SourceData.Common_SourceData_EFPastureRangeAndPaddock_Unit: _xlfn.LAMBDA("kg N2O - N / kg N")
Name Common_SourceData.Common_SourceData_EFPastureRangeAndPaddock_Variation: _xlfn.LAMBDA("VARIATION FROM SOURCE DATA: Changed 'Dry climate zones' to singular 'Dry climate zone' to aid lookup.")
Name Common_SourceData.Common_SourceData_FracLEACH_Data: _xlfn.LAMBDA(_xlfn.MAKEARRAY(1, 2, _xlfn.LAMBDA(_xlpm.r,_xlpm.c, INDEX({"FracLEACH",0.24}, _xlpm.r, _xlpm.c))))

Sheet Home
A1: Home

Sheet Results
A1: #VALUE! | C1: =#REF! -> #REF!
A3: =HYPERLINK("#'Home'!A1", "Home") -> Home
A4: =HYPERLINK("#'Results'!A1", "Results") -> Results | D4: Emissions overview
A6: INPUTS | D6: Net emissions
A7: =HYPERLINK("#'Input - Site'!A1", "Site") -> Site | D7: Scope 1 | E7: 123
A8: =HYPERLINK("#'Input - MMS - Feedlot'!A1", "MMS - Feedlot") -> MMS - Feedlot | D8: Scope 2 | E8: 20
D9: Scope 3 | E9: 300
A10: CALCULATIONS | D10: Sequestration | E10: -10
A11: =HYPERLINK("#'Calcs - CH4 MMS Feedlot'!A1", "MMS Methane") -> MMS Methane | D11: Net farm emissions | E11: =SUM(E7:E10) -> 433 | F11: t CO2-e / farm
A13: APPENDICES | D13: Emissions intensity - IF THIS YEAR IS FULL PRODUCTION CYCLE
A14: =HYPERLINK("#'Constants - Common'!A1", "Constants - Common") -> Constants - Common | D14: Allocation method: Mass
A15: =HYPERLINK("#'Constants - Livestock'!A1", "Constants - Livestock") -> Constants - Livestock | D15: Allocation of net emissions between primary product, co-products and residual products
A16: =HYPERLINK("#'Acknowledgements'!A1", "Acknowledgements") -> Acknowledgements | D16: Grains allocation | E16: 0.9 | F16: percent
D17: Fodder allocation | E17: 0.1 | F17: percent
D18: Residual product X allocation | E18: N/A
D19: For production timeframes that touch multiple years, use the emissions intensity tool
D20: Grains emissions intensity
D21: Grains yield | E21: 100 | F21: tonnes
D22: Grains emissions intensity : Excluding sequestration | E22: =(E11+E10)*E16/E21 -> 3.807 | F22: t CO2-e / t grains
D23: Grains emissions intensity : Including sequestration | E23: =E11*E16/E21 -> 3.897 | F23: t CO2-e / t grains
D25: Fodder emissions intensity
D26: Fodder yield | E26: 10 | F26: tonnes
D27: Fodder emissions intensity : Excluding sequestration | E27: =(E11+E10)*E17/E26 -> 4.23 | F27: t CO2-e / t fodder
D28: Fodder emissions intensity : Including sequestration | E28: =E11*E17/E26 -> 4.33 | F28: t CO2-e / t fodder
D30: Residual product X emissions intensity (only the processing of the residual product)
D31: Residual product X yield / amount produced | E31: 50 | F31: tonnes
D32: Residual product X emissions intensity : Excluding sequestration | E32: =(E11+E10)/E31 -> 8.46 | F32: t CO2-e / t fodder
D33: Residual product X emissions intensity : Including sequestration | E33: =E11/E31 -> 8.66 | F33: t CO2-e / t fodder
D36: Emissions breakdown
D38: Scope 1 | F38: Notes | G38: =#REF! -> #REF! | I38: =#REF! -> #REF!
D39: CO2 - Fuel | E39: =#REF! -> #REF! | F39: Most fuel used at harvest | G39: 0.2 | H39: =E39*G39 -> #REF! | I39: 0.8 | J39: =E39*I39 -> #REF!
D40: CO2 - Lime | E40: =#REF! -> #REF! | F40: Applied lime before planting | G40: 1 | H40: =E40*G40 -> #REF! | I40: 0 | J40: =E40*I40 -> #REF!
D41: CO2 - Urea | E41: =#REF! -> #REF! | F41: Urea at start | G41: 1 | H41: =E41*G41 -> #REF! | I41: 0 | J41: =E41*I41 -> #REF!
D42: CH4 - Fuel | E42: =#REF! -> #REF! | F42: Most fuel used at harvest | G42: 0.2 | H42: =E42*G42 -> #REF! | I42: 0.8 | J42: =E42*I42 -> #REF!
D43: CH4 - Enteric | E43: 3 | F43: Cows all the way through | G43: 0.5 | H43: =E43*G43 -> 1.5 | I43: 0.5 | J43: =E43*I43 -> 1.5
D44: CH4 - Manure Management | E44: 7 | F44: Cows all the way through | G44: 0.5 | H44: =E44*G44 -> 3.5 | I44: 0.5 | J44: =E44*I44 -> 3.5
D45: CH4 - Savannah Burning | E45: 123 | F45: burned at end | G45: 0 | H45: =E45*G45 -> 0 | I45: 1 | J45: =E45*I45 -> 123
D46: N2O - Fertiliser - inorganic | E46: =#REF! -> #REF! | F46: 3 fert applications | G46: 0.6 | H46: =E46*G46 -> #REF! | I46: 0.4 | J46: =E46*I46 -> #REF!
D47: N2O - Fertiliser - organic | E47: =#REF! -> #REF! | H47: =E47*G47 -> #REF! | J47: =E47*I47 -> #REF!
D48: N2O - Urine and Dung | E48: 123 | F48: Cows all the way through | G48: 0.5 | H48: =E48*G48 -> 61.5 | I48: 0.5 | J48: =E48*I48 -> 61.5
...

Sheet Input - Site
A1: #VALUE! | C1: Input - Site
A3: =HYPERLINK("#'Home'!A1", "Home") -> Home
A4: =HYPERLINK("#'Results'!A1", "Results") -> Results
D5: Your business
A6: INPUTS
A7: =HYPERLINK("#'Input - Site'!A1", "Site") -> Site | D7: Farm name | E7: Test Farms
A8: =HYPERLINK("#'Input - MMS - Feedlot'!A1", "MMS - Feedlot") -> MMS - Feedlot | D8: Reporting entity name | E8: Test Farms Pty Ltd
A10: CALCULATIONS | D10: 💡An 'Emissions accounting period' is a 12 month period where the business can report on the emissions, and is typically the same as the business' financial accounting period.
A11: =HYPERLINK("#'Calcs - CH4 MMS Feedlot'!A1", "MMS Methane") -> MMS Methane
D12: Emissions calculation period start date | E12: 45292 | F12: ← DD/MM/YYYY or DD Month YYYY
A13: APPENDICES | D13: Emissions calculation period end date | E13: =DATE(YEAR(E12)+1,MONTH(E12),DAY(E12))-1 -> 45657 | F13: ← Automatically calculated, 12 months after start date
A14: =HYPERLINK("#'Constants - Common'!A1", "Constants - Common") -> Constants - Common
A15: =HYPERLINK("#'Constants - Livestock'!A1", "Constants - Livestock") -> Constants - Livestock
A16: =HYPERLINK("#'Acknowledgements'!A1", "Acknowledgements") -> Acknowledgements | D16: Location and climate
D18: Location information is used to reference some region and climate-specific emission factors
D19: Tip: Use the web-based GAF Location Helper tool to easily get region and climate information. You will need an internet connection to use the GAF Location Helper.
D21: State | E21: New South Wales | F21: ← Please select
D22: Region (ABS Statistical area level 4) if state is WA | E22: Western Australia - Outback (South) | F22: ← Please select
D23: Leaching zone | E23: NO - Not in leaching zone | F23: ← Please select
D24: Elevation | E24: 307.7 | F24: Meters
D25: Average temperature for reporting period | E25: 18 | F25: Degrees celsius
D26: Total rainfall for reporting period | E26: 3000 | F26: Millimetres
D27: Potential evapotranspiration for reporting period | E27: 1326 | F27: Millimetres
D28: Number of frost days for reporting period | E28: 7 | F28: Days
D29: MAP:PET ratio | E29: =E26/E27 -> 2.2624434
D30: Rainfall zone | E30: {=Common_InputFunctions.Utility_LookupItemFromMinMax(E26,#REF!,#REF!,#REF!)} -> #REF!
D31: Climate zone | E31: {=Common_InputFunctions.Utility_GetClimateZone(E25,E26,E28,E24,E29)} -> #REF!
D32: Wet or dry climate zone | E32: {=Common_InputFunctions.Utility_LookupValueInTable($E$31,#REF!,#REF!)} -> #REF!
D33: Temperature zone | E33: {=Common_InputFunctions.Utility_LookupItemFromMinMax(E25,#REF!,#REF!,#REF!)} -> #REF!

Sheet Input - MMS - Feedlot
A1: #VALUE! | C1: Input - MMS - Feedlot
A3: =HYPERLINK("#'Home'!A1", "Home") -> Home
A4: =HYPERLINK("#'Results'!A1", "Results") -> Results
D5: Herd movement
A6: INPUTS
A7: =HYPERLINK("#'Input - Site'!A1", "Site") -> Site | E7: Domestic (70-80 days) | F7: Export mid fed (80-200 days) | G7: Export long fed (200+ days)
A8: =HYPERLINK("#'Input - MMS - Feedlot'!A1", "MMS - Feedlot") -> MMS - Feedlot | D8: ="Average number of head between " & TEXT('Input - Site'!$E$12, "dd mmm yy") & " and " & TEXT('Input - Site'!$E$13, "dd mmm yy") -> Average number of head between 01 Jan 24 and 31 Dec 24 | E8: 4300 | F8: 100 | G8: 100 | H8: head
D9: ="Average duration of stay between " & TEXT('Input - Site'!$E$12, "dd mmm yy") & " and " & TEXT('Input - Site'!$E$13, "dd mmm yy") -> Average duration of stay between 01 Jan 24 and 31 Dec 24 | E9: 90 | F9: 140 | G9: 250 | H9: Days
A10: CALCULATIONS
A11: =HYPERLINK("#'Calcs - CH4 MMS Feedlot'!A1", "MMS Methane") -> MMS Methane | D11: Intake
A13: APPENDICES | E13: Domestic (70-80 days) | F13: Export mid fed (80-200 days) | G13: Export long fed (200+ days)
A14: =HYPERLINK("#'Constants - Common'!A1", "Constants - Common") -> Constants - Common | D14: Dry matter intake | E14: 10.4 | F14: 10.8 | G14: 8.2 | H14: kg dry matter / head day
A15: =HYPERLINK("#'Constants - Livestock'!A1", "Constants - Livestock") -> Constants - Livestock | D15: Dry matter digestibility | E15: 0.81 | F15: 0.81 | G15: 0.79 | H15: Percent
A16: =HYPERLINK("#'Acknowledgements'!A1", "Acknowledgements") -> Acknowledgements
D18: Manure management systems
D20: Stage 1
D21: Stage 1 MMS | E21: Domestic (70-80 days) | F21: Export mid fed (80-200 days) | G21: Export long fed (200+ days)
D22: Drylot (feed pad) | E22: 1 | F22: 1 | G22: 1 | H22: Percent
D25: Stage 2
D26: Stage 2 MMS | E26: Domestic (70-80 days) | F26: Export mid fed (80-200 days) | G26: Export long fed (200+ days)
D27: ="Sent from " & $D$22 -> Sent from Drylot (feed pad) | E27: =IF($D$30="Pasture range and paddock", "⚠️ ALERT: Manure sent to 'pasture range and paddock do not go to stage 2. Select 'No MMS'.", "")
D28: ='Calcs - CH4 MMS Feedlot'!M44 -> Solid storage | E28: 0.2 | F28: 0.2 | G28: 0.2 | H28: Percent
D29: ='Calcs - CH4 MMS Feedlot'!M45 -> Composting (passive windrow) | E29: 0.2 | F29: 0.2 | G29: 0.2 | H29: Percent
D30: ='Calcs - CH4 MMS Feedlot'!M46 -> Direct application | E30: 0.6 | F30: 0.6 | G30: 0.6 | H30: Percent
D31: Total (must equal 100%) | E31: =IF($D$30="Pasture range and paddock", "N/A", SUM(E28:E30)) -> 1 | F31: =IF($D$30="Pasture range and paddock", "N/A", SUM(F28:F30)) -> 1 | G31: =IF($D$30="Pasture range and paddock", "N/A", SUM(G28:G30)) -> 1 | H31: Percent
D34: Stage 3
D35: Stage 3 MMS | E35: Domestic (70-80 days) | F35: Export mid fed (80-200 days) | G35: Export long fed (200+ days)
D36: ='Calcs - CH4 MMS Feedlot'!$M$47 -> Anaerobic lagoon | E36: ='Calcs - CH4 MMS Feedlot'!$N$12 -> 0.02 | F36: ='Calcs - CH4 MMS Feedlot'!$N$12 -> 0.02 | G36: ='Calcs - CH4 MMS Feedlot'!$N$12 -> 0.02 | H36: Percent
D38: Production system 1: Post-treatment destinations
D39: ="Sent from " & $D$22 -> Sent from Drylot (feed pad) | E39: =IF($D$30="Pasture range and paddock", "⚠️ ALERT Manure sent to 'pasture range and paddock do not go to stage 2, or post-treatment destinations.", "")
D40: ="Percent sold from " & $D$28 -> Percent sold from Solid storage | E40: 0.25 | F40: 0.25 | G40: 0.25 | H40: Percent
D41: ="Percent deposited on farm soils from " & $D$28 -> Percent deposited on farm soils from Solid storage | E41: =1-E40 -> 0.75 | F41: =1-F40 -> 0.75 | G41: =1-G40 -> 0.75 | H41: Percent
D43: ="Percent sold from " & $D$29 -> Percent sold from Composting (passive windrow) | E43: 0.25 | F43: 0.25 | G43: 0.25 | H43: Percent
D44: ="Percent deposited on farm soils from " & $D$29 -> Percent deposited on farm soils from Composting (passive windrow) | E44: =1-E43 -> 0.75 | F44: =1-F43 -> 0.75 | G44: =1-G43 -> 0.75 | H44: Percent
D46: ="Percent sold from " & $D$30 & " for sale" -> Percent sold from Direct application for sale | E46: 0.25 | F46: 0.25 | G46: 0.25 | H46: Percent
D47: ="Percent deposited on farm soils from " & $D$30 -> Percent deposited on farm soils from Direct application | E47: =1-E46 -> 0.75 | F47: =1-F46 -> 0.75 | G47: =1-G46 -> 0.75 | H47: Percent

Sheet Calcs - CH4 MMS Feedlot
A1: #VALUE! | C1: Calculations - Manure management - Methane - Feedlot
A3: =HYPERLINK("#'Home'!A1", "Home") -> Home | D3: Equations | M3: Source data
A4: =HYPERLINK("#'Results'!A1", "Results") -> Results
D5: {=MMS_Feedlot_Methane_Equations.VEERG_4_1_1_1__5_VolatileSolidProduction_Title()} -> Volatile solid production | M5: {=SourceData_Feedlot.SourceData_Feedlot_VSL_Title()} -> Feedlot - Fraction of volatile solids lost during storage in the primary system
A6: INPUTS | D6: {=MMS_Feedlot_Methane_Equations.VEERG_4_1_1_1__5_VolatileSolidProduction_Source()} -> VEERG 2026: 4.1.1.1, Equation (5) | M6: {=SourceData_Feedlot.SourceData_Feedlot_VSL_Source()} -> VEERG 2026: 4.1.2.3 CONSTANTS
A7: =HYPERLINK("#'Input - Site'!A1", "Site") -> Site | D7: Function name | E7: {=Common_InputFunctions.Utility_DisplayFunctionName(D30)} -> =MMS_Feedlot_Methane_Equations.VEERG_4_1_1_1__5_VolatileSolidProduction(D20,D25,$G$15) | M7: {=SourceData_Feedlot.SourceData_Feedlot_VSL_Variable()} -> VSL | N7: {=SourceData_Feedlot.SourceData_Feedlot_VSL_Data()} -> 0.5 | O7: {=SourceData_Feedlot.SourceData_Feedlot_VSL_Unit()} -> Fraction
A8: =HYPERLINK("#'Input - MMS - Feedlot'!A1", "MMS - Feedlot") -> MMS - Feedlot
A10: CALCULATIONS | D10: Variable | E10: {=MMS_Feedlot_Methane_Equations.VEERG_4_1_1_1__5_VolatileSolidProduction_Variable()} -> VSj | M10: {=SourceData_Feedlot.SourceData_Feedlot_MMSm1T3_Title()} -> Fraction of volatile solids to each tertiary system assumed that 2 per cent is run - off from the feed pad.
A11: =HYPERLINK("#'Calcs - CH4 MMS Feedlot'!A1", "MMS Methane") -> MMS Methane | D11: Unit | E11: {=MMS_Feedlot_Methane_Equations.VEERG_4_1_1_1__5_VolatileSolidProduction_Unit()} -> kg/head/day | M11: {=SourceData_Feedlot.SourceData_Feedlot_MMSm1T3_Source()} -> VEERG 2026: 4.1.2.3 CONSTANTS
A12: MMS N2O | M12: {=SourceData_Feedlot.SourceData_Feedlot_MMSm1T3_Variable()} -> MMSm1T3 | N12: {=SourceData_Feedlot.SourceData_Feedlot_MMSm1T3_Data()} -> 0.02 | O12: {=SourceData_Feedlot.SourceData_Feedlot_MMSm1T3_Unit()} -> Fraction
D13: {=MMS_Feedlot_Methane_Equations.VEERG_4_1_1_1__5_VolatileSolidProduction_Arguments()} -> Ij | E13: dry matter intake for each group : kg DM/head/day | G13: ="See " & D17 -> See Table_I_j
A14: APPENDICES | D14: DMDj | E14: dry matter digestibility for each group : fraction | G14: ="See " & D22 -> See Table_DMD_j
A15: =HYPERLINK("#'Constants - Common'!A1", "Constants - Common") -> Constants - Common | D15: A | E15: ash content of manure : fraction | G15: =$N$17 -> 0.16 | M15: {=SourceData_Feedlot.SourceData_Feedlot_AshContent_Title()} -> Ash content of manure.
A16: =HYPERLINK("#'Constants - Livestock'!A1", "Constants - Livestock") -> Constants - Livestock | M16: {=SourceData_Feedlot.SourceData_Feedlot_AshContent_Source()} -> VEERG 2026: 4.1.2.3 CONSTANTS
A17: =HYPERLINK("#'Acknowledgements'!A1", "Acknowledgements") -> Acknowledgements | D17: Table_I_j | M17: {=SourceData_Feedlot.SourceData_Feedlot_AshContent_Variable()} -> A | N17: {=SourceData_Feedlot.SourceData_Feedlot_AshContent_Data()} -> 0.16 | O17: {=SourceData_Feedlot.SourceData_Feedlot_AshContent_Unit()} -> Fraction
D18: Dry matter intake
D19: Domestic (70-80 days) | E19: Export mid fed (80-200 days) | F19: Export long fed (200+ days)
D20: ='Input - MMS - Feedlot'!$E$14 -> 10.4 | E20: ='Input - MMS - Feedlot'!$F$14 -> 10.8 | F20: ='Input - MMS - Feedlot'!$G$14 -> 8.2 | G20: kg DM/head/day | M20: {=SourceData_Feedlot.SourceData_Feedlot_MethaneEmissionsPotential_Title()} -> Methane emissions potential.
M21: {=SourceData_Feedlot.SourceData_Feedlot_MethaneEmissionsPotential_Source()} -> VEERG 2026: 4.1.2.3 CONSTANTS
D22: Table_DMD_j | M22: {=SourceData_Feedlot.SourceData_Feedlot_MethaneEmissionsPotential_Variable()} -> B0 | N22: {=SourceData_Feedlot.SourceData_Feedlot_MethaneEmissionsPotential_Data()} -> 0.19 | O22: {=SourceData_Feedlot.SourceData_Feedlot_MethaneEmissionsPotential_Unit()} -> m3 CH4 / kg VS
D23: Dry matter digestibility
D24: Domestic (70-80 days) | E24: Export mid fed (80-200 days) | F24: Export long fed (200+ days)
D25: ='Input - MMS - Feedlot'!$E$15 -> 0.81 | E25: ='Input - MMS - Feedlot'!$F$15 -> 0.81 | F25: ='Input - MMS - Feedlot'!$G$15 -> 0.79 | G25: Fraction | M25: {=SourceData_Feedlot.SourceData_Feedlot_MCF_Title()} -> Feedlot - MCFs
M26: {=SourceData_Feedlot.SourceData_Feedlot_MCF_Source()} -> VEERG 2026: Table A.1.7.4: Feedlot - MCFs
D27: Table_VS_j | M27: {=SourceData_Feedlot.SourceData_Feedlot_MCF_Variation()} -> VARIATION ON SOURCE:
D28: Volatile solid production | M28: Duplicated NSW values for ACT
D29: Domestic (70-80 days) | E29: Export mid fed (80-200 days) | F29: Export long fed (200+ days) | M29: Added NT and TAS columns with 'no data' values
D30: {=MMS_Feedlot_Methane_Equations.VEERG_4_1_1_1__5_VolatileSolidProduction(D20,D25,$G$15)} -> 1.65984 | E30: {=MMS_Feedlot_Methane_Equations.VEERG_4_1_1_1__5_VolatileSolidProduction(E20,E25,$G$15)} -> 1.72368 | F30: {=MMS_Feedlot_Methane_Equations.VEERG_4_1_1_1__5_VolatileSolidProduction(F20,F25,$G$15)} -> 1.44648 | G30: =$E$11 -> kg/head/day | M30: Added 'NIR definition' column with MMS names that match NIR definitions.
M32: Treatment stage T | N32: MMS m | O32: NSW | P32: ACT | Q32: QLD | R32: NT | S32: SA | T32: VIC | U32: WA | V32: TAS | W32: NIR definition
M33: {=Common_InputFunctions.Utility_DisplayArrayInTable(SourceData_Feedlot.SourceData_Feedlot_MCF_Data(), Table_SourceData_Feedlot_MCF[[#Headers],[Treatment stage T]], 0)} -> Primary | N33: {=Common_InputFunctions.Utility_DisplayArrayInTable(SourceData_Feedlot.SourceData_Feedlot_MCF_Data(), Table_SourceData_Feedlot_MCF[[#Headers],[Treatment stage T]], 0)} -> Dry lot (Feedpad) | O33: {=Common_InputFunctions.Utility_DisplayArrayInTable(SourceData_Feedlot.SourceData_Feedlot_MCF_Data(), Table_SourceData_Feedlot_MCF[[#Headers],[Treatment stage T]], 0)} -> 0.01 | P33: {=Common_InputFunctions.Utility_DisplayArrayInTable(SourceData_Feedlot.SourceData_Feedlot_MCF_Data(), Table_SourceData_Feedlot_MCF[[#Headers],[Treatment stage T]], 0)} -> 0.01 | Q33: {=Common_InputFunctions.Utility_DisplayArrayInTable(SourceData_Feedlot.SourceData_Feedlot_MCF_Data(), Table_SourceData_Feedlot_MCF[[#Headers],[Treatment stage T]], 0)} -> 0.03 | R33: {=Common_InputFunctions.Utility_DisplayArrayInTable(SourceData_Feedlot.SourceData_Feedlot_MCF_Data(), Table_SourceData_Feedlot_MCF[[#Headers],[Treatment stage T]], 0)} -> No data | S33: {=Common_InputFunctions.Utility_DisplayArrayInTable(SourceData_Feedlot.SourceData_Feedlot_MCF_Data(), Table_SourceData_Feedlot_MCF[[#Headers],[Treatment stage T]], 0)} -> 0.01 | T33: {=Common_InputFunctions.Utility_DisplayArrayInTable(SourceData_Feedlot.SourceData_Feedlot_MCF_Data(), Table_SourceData_Feedlot_MCF[[#Headers],[Treatment stage T]], 0)} -> 0.01 | ... W33: {=Common_InputFunctions.Utility_DisplayArrayInTable(SourceData_Feedlot.SourceData_Feedlot_MCF_Data(), Table_SourceData_Feedlot_MCF[[#Headers],[Treatment stage T]], 0)} -> Drylot (feed pad)
D34: {=MMS_Feedlot_Methane_Equations.VEERG_4_1_1_1__2_Stage1MethaneProductionDrylot_Title()} -> Production of methane in treatment stage 1 MMS | M34: {=Common_InputFunctions.Utility_DisplayArrayInTable(SourceData_Feedlot.SourceData_Feedlot_MCF_Data(), Table_SourceData_Feedlot_MCF[[#Headers],[Treatment stage T]], 0)} -> Secondary | N34: {=Common_InputFunctions.Utility_DisplayArrayInTable(SourceData_Feedlot.SourceData_Feedlot_MCF_Data(), Table_SourceData_Feedlot_MCF[[#Headers],[Treatment stage T]], 0)} -> Solid Storage (Stockpile) | O34: {=Common_InputFunctions.Utility_DisplayArrayInTable(SourceData_Feedlot.SourceData_Feedlot_MCF_Data(), Table_SourceData_Feedlot_MCF[[#Headers],[Treatment stage T]], 0)} -> 0.02 | P34: {=Common_InputFunctions.Utility_DisplayArrayInTable(SourceData_Feedlot.SourceData_Feedlot_MCF_Data(), Table_SourceData_Feedlot_MCF[[#Headers],[Treatment stage T]], 0)} -> 0.02 | Q34: {=Common_InputFunctions.Utility_DisplayArrayInTable(SourceData_Feedlot.SourceData_Feedlot_MCF_Data(), Table_SourceData_Feedlot_MCF[[#Headers],[Treatment stage T]], 0)} -> 0.02 | R34: {=Common_InputFunctions.Utility_DisplayArrayInTable(SourceData_Feedlot.SourceData_Feedlot_MCF_Data(), Table_SourceData_Feedlot_MCF[[#Headers],[Treatment stage T]], 0)} -> No data | S34: {=Common_InputFunctions.Utility_DisplayArrayInTable(SourceData_Feedlot.SourceData_Feedlot_MCF_Data(), Table_SourceData_Feedlot_MCF[[#Headers],[Treatment stage T]], 0)} -> 0.02 | T34: {=Common_InputFunctions.Utility_DisplayArrayInTable(SourceData_Feedlot.SourceData_Feedlot_MCF_Data(), Table_SourceData_Feedlot_MCF[[#Headers],[Treatment stage T]], 0)} -> 0.02 | ... W34: {=Common_InputFunctions.Utility_DisplayArrayInTable(SourceData_Feedlot.SourceData_Feedlot_MCF_Data(), Table_SourceData_Feedlot_MCF[[#Headers],[Treatment stage T]], 0)} -> Solid storage
D35: {=MMS_Feedlot_Methane_Equations.VEERG_4_1_1_1__2_Stage1MethaneProductionDrylot_Source()} -> VEERG 2026: 4.1.1.1, Equation (2) | M35: {=Common_InputFunctions.Utility_DisplayArrayInTable(SourceData_Feedlot.SourceData_Feedlot_MCF_Data(), Table_SourceData_Feedlot_MCF[[#Headers],[Treatment stage T]], 0)} -> Secondary | N35: {=Common_InputFunctions.Utility_DisplayArrayInTable(SourceData_Feedlot.SourceData_Feedlot_MCF_Data(), Table_SourceData_Feedlot_MCF[[#Headers],[Treatment stage T]], 0)} -> Composting (Passive Windrow) | O35: {=Common_InputFunctions.Utility_DisplayArrayInTable(SourceData_Feedlot.SourceData_Feedlot_MCF_Data(), Table_SourceData_Feedlot_MCF[[#Headers],[Treatment stage T]], 0)} -> 0.01 | P35: {=Common_InputFunctions.Utility_DisplayArrayInTable(SourceData_Feedlot.SourceData_Feedlot_MCF_Data(), Table_SourceData_Feedlot_MCF[[#Headers],[Treatment stage T]], 0)} -> 0.01 | Q35: {=Common_InputFunctions.Utility_DisplayArrayInTable(SourceData_Feedlot.SourceData_Feedlot_MCF_Data(), Table_SourceData_Feedlot_MCF[[#Headers],[Treatment stage T]], 0)} -> 0.01 | R35: {=Common_InputFunctions.Utility_DisplayArrayInTable(SourceData_Feedlot.SourceData_Feedlot_MCF_Data(), Table_SourceData_Feedlot_MCF[[#Headers],[Treatment stage T]], 0)} -> No data | S35: {=Common_InputFunctions.Utility_DisplayArrayInTable(SourceData_Feedlot.SourceData_Feedlot_MCF_Data(), Table_SourceData_Feedlot_MCF[[#Headers],[Treatment stage T]], 0)} -> 0.01 | T35: {=Common_InputFunctions.Utility_DisplayArrayInTable(SourceData_Feedlot.SourceData_Feedlot_MCF_Data(), Table_SourceData_Feedlot_MCF[[#Headers],[Treatment stage T]], 0)} -> 0.01 | ... W35: {=Common_InputFunctions.Utility_DisplayArrayInTable(SourceData_Feedlot.SourceData_Feedlot_MCF_Data(), Table_SourceData_Feedlot_MCF[[#Headers],[Treatment stage T]], 0)} -> Composting (passive windrow)
D36: Function name | E36: {=Common_InputFunctions.Utility_DisplayFunctionName(E57)} -> =MMS_Feedlot_Methane_Equations.VEERG_4_1_1_1__2_Stage1MethaneProductionDrylot(D30,$G$43,E52,$G$45,$G$46) | M36: {=Common_InputFunctions.Utility_DisplayArrayInTable(SourceData_Feedlot.SourceData_Feedlot_MCF_Data(), Table_SourceData_Feedlot_MCF[[#Headers],[Treatment stage T]], 0)} -> Secondary | N36: {=Common_InputFunctions.Utility_DisplayArrayInTable(SourceData_Feedlot.SourceData_Feedlot_MCF_Data(), Table_SourceData_Feedlot_MCF[[#Headers],[Treatment stage T]], 0)} -> Direct Application to soil | O36: {=Common_InputFunctions.Utility_DisplayArrayInTable(SourceData_Feedlot.SourceData_Feedlot_MCF_Data(), Table_SourceData_Feedlot_MCF[[#Headers],[Treatment stage T]], 0)} -> 0 | P36: {=Common_InputFunctions.Utility_DisplayArrayInTable(SourceData_Feedlot.SourceData_Feedlot_MCF_Data(), Table_SourceData_Feedlot_MCF[[#Headers],[Treatment stage T]], 0)} -> 0 | Q36: {=Common_InputFunctions.Utility_DisplayArrayInTable(SourceData_Feedlot.SourceData_Feedlot_MCF_Data(), Table_SourceData_Feedlot_MCF[[#Headers],[Treatment stage T]], 0)} -> 0 | R36: {=Common_InputFunctions.Utility_DisplayArrayInTable(SourceData_Feedlot.SourceData_Feedlot_MCF_Data(), Table_SourceData_Feedlot_MCF[[#Headers],[Treatment stage T]], 0)} -> No data | S36: {=Common_InputFunctions.Utility_DisplayArrayInTable(SourceData_Feedlot.SourceData_Feedlot_MCF_Data(), Table_SourceData_Feedlot_MCF[[#Headers],[Treatment stage T]], 0)} -> 0 | T36: {=Common_InputFunctions.Utility_DisplayArrayInTable(SourceData_Feedlot.SourceData_Feedlot_MCF_Data(), Table_SourceData_Feedlot_MCF[[#Headers],[Treatment stage T]], 0)} -> 0 | ... W36: {=Common_InputFunctions.Utility_DisplayArrayInTable(SourceData_Feedlot.SourceData_Feedlot_MCF_Data(), Table_SourceData_Feedlot_MCF[[#Headers],[Treatment stage T]], 0)} -> Direct application
M37: {=Common_InputFunctions.Utility_DisplayArrayInTable(SourceData_Feedlot.SourceData_Feedlot_MCF_Data(), Table_SourceData_Feedlot_MCF[[#Headers],[Treatment stage T]], 0)} -> Tertiary | N37: {=Common_InputFunctions.Utility_DisplayArrayInTable(SourceData_Feedlot.SourceData_Feedlot_MCF_Data(), Table_SourceData_Feedlot_MCF[[#Headers],[Treatment stage T]], 0)} -> Uncovered anaerobic lagoon (Effluent pond) | O37: {=Common_InputFunctions.Utility_DisplayArrayInTable(SourceData_Feedlot.SourceData_Feedlot_MCF_Data(), Table_SourceData_Feedlot_MCF[[#Headers],[Treatment stage T]], 0)} -> 0.75 | P37: {=Common_InputFunctions.Utility_DisplayArrayInTable(SourceData_Feedlot.SourceData_Feedlot_MCF_Data(), Table_SourceData_Feedlot_MCF[[#Headers],[Treatment stage T]], 0)} -> 0.75 | Q37: {=Common_InputFunctions.Utility_DisplayArrayInTable(SourceData_Feedlot.SourceData_Feedlot_MCF_Data(), Table_SourceData_Feedlot_MCF[[#Headers],[Treatment stage T]], 0)} -> 0.77 | R37: {=Common_InputFunctions.Utility_DisplayArrayInTable(SourceData_Feedlot.SourceData_Feedlot_MCF_Data(), Table_SourceData_Feedlot_MCF[[#Headers],[Treatment stage T]], 0)} -> No data | S37: {=Common_InputFunctions.Utility_DisplayArrayInTable(SourceData_Feedlot.SourceData_Feedlot_MCF_Data(), Table_SourceData_Feedlot_MCF[[#Headers],[Treatment stage T]], 0)} -> 0.75 | T37: {=Common_InputFunctions.Utility_DisplayArrayInTable(SourceData_Feedlot.SourceData_Feedlot_MCF_Data(), Table_SourceData_Feedlot_MCF[[#Headers],[Treatment stage T]], 0)} -> 0.75 | ... W37: {=Common_InputFunctions.Utility_DisplayArrayInTable(SourceData_Feedlot.SourceData_Feedlot_MCF_Data(), Table_SourceData_Feedlot_MCF[[#Headers],[Treatment stage T]], 0)} -> Anaerobic lagoon
D39: Variable | E39: {=MMS_Feedlot_Methane_Equations.VEERG_4_1_1_1__2_Stage1MethaneProductionDrylot_Variable()} -> Mjm5T1
D40: Unit | E40: {=MMS_Feedlot_Methane_Equations.VEERG_4_1_1_1__2_Stage1MethaneProductionDrylot_Unit()} -> kg CH4/head/day | M40: Feedlot manure management systems
D42: {=MMS_Feedlot_Methane_Equations.VEERG_4_1_1_1__2_Stage1MethaneProductionDrylot_Arguments()} -> VSj | E42: volatile solid production from feedlot cattle in each group : kg/head/day | G42: ="See " & $D$27 -> See Table_VS_j | M42: MMS | N42: Symbol and MMS
D43: BO | E43: emissions potential : m3 CH4/kg VS | G43: =$N$22 -> 0.19 | M43: ='Constants - Livestock'!$E$16 -> Drylot (feed pad) | N43: ='Constants - Livestock'!$F$16 -> Drylot (feed pad) (m=5)
D44: MMSm5T1 | E44: fraction of manure in primary system drylot MMS : fraction | G44: ="See" & D49 -> SeeTable_MMS_m-5_T-1 | M44: ='Constants - Livestock'!$E$15 -> Solid storage | N44: ='Constants - Livestock'!$F$15 -> Solid storage (m=4)
D45: MCFim5 | E45: methane conversion factor for temperature zone and drylot system : fraction | G45: =HLOOKUP(G47, Table_SourceData_Feedlot_MCF[#All], 2, FALSE) -> #REF! | M45: ='Constants - Livestock'!$E$17 -> Composting (passive windrow) | N45: ='Constants - Livestock'!$F$17 -> Composting (passive windrow) (m=6)
...

Sheet Constants - Livestock
A1: #VALUE! | C1: Constants - Livestock
A3: Home
A4: =HYPERLINK("#'Results'!A1", "Results") -> Results
A6: INPUTS | D6: {=CommonLivestock_SourceData.SourceData_Livestock_Common_SymbolsMMS_Title()} -> Table 5.12 Additional symbols used in algorithms for manure related emissions
A7: =HYPERLINK("#'Input - Site'!A1", "Site") -> Site | D7: {=CommonLivestock_SourceData.SourceData_Livestock_Common_SymbolsMMS_Vairable()} -> MMS
A8: =HYPERLINK("#'Input - Production'!A1", "Production and outputs") -> Production and outputs | D8: {=CommonLivestock_SourceData.SourceData_Livestock_Common_SymbolsMMS_Source()} -> National Inventory Report 2023 Volume 1: Table 5.12
A9: =HYPERLINK("#'Input - Herd - Dairy'!A1", "Herd - Dairy") -> Herd - Dairy | D9: Symbol | E9: Manure management system | F9: Symbol and MMS
A10: =HYPERLINK("#'Input - Feed - Dairy'!A1", "Purchased feed - Livestock") -> Purchased feed - Livestock | D10: {=Common_InputFunctions.Utility_DisplayArrayInTable(CommonLivestock_SourceData.SourceData_Livestock_Common_SymbolsMMS_Data(), Table_Data_MMSSymbols[[#Headers],[Symbol]], 0)} -> 1 | E10: {=Common_InputFunctions.Utility_DisplayArrayInTable(CommonLivestock_SourceData.SourceData_Livestock_Common_SymbolsMMS_Data(), Table_Data_MMSSymbols[[#Headers],[Symbol]], 0)} -> Anaerobic lagoon | F10: {=Common_InputFunctions.Utility_DisplayArrayInTable(CommonLivestock_SourceData.SourceData_Livestock_Common_SymbolsMMS_Data(), Table_Data_MMSSymbols[[#Headers],[Symbol]], 0)} -> Anaerobic lagoon (m=1)
A11: =HYPERLINK("#'Input - Herd - Feedlot'!A1", "Herd - Feedlot") -> Herd - Feedlot | D11: {=Common_InputFunctions.Utility_DisplayArrayInTable(CommonLivestock_SourceData.SourceData_Livestock_Common_SymbolsMMS_Data(), Table_Data_MMSSymbols[[#Headers],[Symbol]], 0)} -> 2 | E11: {=Common_InputFunctions.Utility_DisplayArrayInTable(CommonLivestock_SourceData.SourceData_Livestock_Common_SymbolsMMS_Data(), Table_Data_MMSSymbols[[#Headers],[Symbol]], 0)} -> Liquid systems | F11: {=Common_InputFunctions.Utility_DisplayArrayInTable(CommonLivestock_SourceData.SourceData_Livestock_Common_SymbolsMMS_Data(), Table_Data_MMSSymbols[[#Headers],[Symbol]], 0)} -> Liquid systems (m=2)
A12: =HYPERLINK("#'Input - Pasture'!A1", "Pasture") -> Pasture | D12: {=Common_InputFunctions.Utility_DisplayArrayInTable(CommonLivestock_SourceData.SourceData_Livestock_Common_SymbolsMMS_Data(), Table_Data_MMSSymbols[[#Headers],[Symbol]], 0)} -> 3 | E12: {=Common_InputFunctions.Utility_DisplayArrayInTable(CommonLivestock_SourceData.SourceData_Livestock_Common_SymbolsMMS_Data(), Table_Data_MMSSymbols[[#Headers],[Symbol]], 0)} -> Daily spread | F12: {=Common_InputFunctions.Utility_DisplayArrayInTable(CommonLivestock_SourceData.SourceData_Livestock_Common_SymbolsMMS_Data(), Table_Data_MMSSymbols[[#Headers],[Symbol]], 0)} -> Daily spread (m=3)
A13: =HYPERLINK("#'Input - Grains'!A1", "Crop - Grains") -> Crop - Grains | D13: {=Common_InputFunctions.Utility_DisplayArrayInTable(CommonLivestock_SourceData.SourceData_Livestock_Common_SymbolsMMS_Data(), Table_Data_MMSSymbols[[#Headers],[Symbol]], 0)} -> 3a | E13: {=Common_InputFunctions.Utility_DisplayArrayInTable(CommonLivestock_SourceData.SourceData_Livestock_Common_SymbolsMMS_Data(), Table_Data_MMSSymbols[[#Headers],[Symbol]], 0)} -> Sump and dispersal system | F13: {=Common_InputFunctions.Utility_DisplayArrayInTable(CommonLivestock_SourceData.SourceData_Livestock_Common_SymbolsMMS_Data(), Table_Data_MMSSymbols[[#Headers],[Symbol]], 0)} -> Sump and dispersal system (m=3a)
A14: =HYPERLINK("#'Input - Fert Lime Chem'!A1", "Fertiliser, Lime & Chemicals") -> Fertiliser, Lime & Chemicals | D14: {=Common_InputFunctions.Utility_DisplayArrayInTable(CommonLivestock_SourceData.SourceData_Livestock_Common_SymbolsMMS_Data(), Table_Data_MMSSymbols[[#Headers],[Symbol]], 0)} -> 3b | E14: {=Common_InputFunctions.Utility_DisplayArrayInTable(CommonLivestock_SourceData.SourceData_Livestock_Common_SymbolsMMS_Data(), Table_Data_MMSSymbols[[#Headers],[Symbol]], 0)} -> Drains to paddock | F14: {=Common_InputFunctions.Utility_DisplayArrayInTable(CommonLivestock_SourceData.SourceData_Livestock_Common_SymbolsMMS_Data(), Table_Data_MMSSymbols[[#Headers],[Symbol]], 0)} -> Drains to paddock (m=3b)
A15: =HYPERLINK("#'Input - Fuel & Energy'!A1", "Electricity and fuel") -> Electricity and fuel | D15: {=Common_InputFunctions.Utility_DisplayArrayInTable(CommonLivestock_SourceData.SourceData_Livestock_Common_SymbolsMMS_Data(), Table_Data_MMSSymbols[[#Headers],[Symbol]], 0)} -> 4 | E15: {=Common_InputFunctions.Utility_DisplayArrayInTable(CommonLivestock_SourceData.SourceData_Livestock_Common_SymbolsMMS_Data(), Table_Data_MMSSymbols[[#Headers],[Symbol]], 0)} -> Solid storage | F15: {=Common_InputFunctions.Utility_DisplayArrayInTable(CommonLivestock_SourceData.SourceData_Livestock_Common_SymbolsMMS_Data(), Table_Data_MMSSymbols[[#Headers],[Symbol]], 0)} -> Solid storage (m=4)
A16: Waste | D16: {=Common_InputFunctions.Utility_DisplayArrayInTable(CommonLivestock_SourceData.SourceData_Livestock_Common_SymbolsMMS_Data(), Table_Data_MMSSymbols[[#Headers],[Symbol]], 0)} -> 5 | E16: {=Common_InputFunctions.Utility_DisplayArrayInTable(CommonLivestock_SourceData.SourceData_Livestock_Common_SymbolsMMS_Data(), Table_Data_MMSSymbols[[#Headers],[Symbol]], 0)} -> Drylot (feed pad) | F16: {=Common_InputFunctions.Utility_DisplayArrayInTable(CommonLivestock_SourceData.SourceData_Livestock_Common_SymbolsMMS_Data(), Table_Data_MMSSymbols[[#Headers],[Symbol]], 0)} -> Drylot (feed pad) (m=5)
A17: Freight and transport | D17: {=Common_InputFunctions.Utility_DisplayArrayInTable(CommonLivestock_SourceData.SourceData_Livestock_Common_SymbolsMMS_Data(), Table_Data_MMSSymbols[[#Headers],[Symbol]], 0)} -> 6 | E17: {=Common_InputFunctions.Utility_DisplayArrayInTable(CommonLivestock_SourceData.SourceData_Livestock_Common_SymbolsMMS_Data(), Table_Data_MMSSymbols[[#Headers],[Symbol]], 0)} -> Composting (passive windrow) | F17: {=Common_InputFunctions.Utility_DisplayArrayInTable(CommonLivestock_SourceData.SourceData_Livestock_Common_SymbolsMMS_Data(), Table_Data_MMSSymbols[[#Headers],[Symbol]], 0)} -> Composting (passive windrow) (m=6)
A18: =HYPERLINK("#'Input - Other Farm Inputs'!A1", "Other farm inputs") -> Other farm inputs | D18: {=Common_InputFunctions.Utility_DisplayArrayInTable(CommonLivestock_SourceData.SourceData_Livestock_Common_SymbolsMMS_Data(), Table_Data_MMSSymbols[[#Headers],[Symbol]], 0)} -> 7 | E18: {=Common_InputFunctions.Utility_DisplayArrayInTable(CommonLivestock_SourceData.SourceData_Livestock_Common_SymbolsMMS_Data(), Table_Data_MMSSymbols[[#Headers],[Symbol]], 0)} -> Digester / covered lagoons | F18: {=Common_InputFunctions.Utility_DisplayArrayInTable(CommonLivestock_SourceData.SourceData_Livestock_Common_SymbolsMMS_Data(), Table_Data_MMSSymbols[[#Headers],[Symbol]], 0)} -> Digester / covered lagoons (m=7)
A19: =HYPERLINK("#'Input - Data quality'!A1", "Data quality") -> Data quality | D19: {=Common_InputFunctions.Utility_DisplayArrayInTable(CommonLivestock_SourceData.SourceData_Livestock_Common_SymbolsMMS_Data(), Table_Data_MMSSymbols[[#Headers],[Symbol]], 0)} -> 8 | E19: {=Common_InputFunctions.Utility_DisplayArrayInTable(CommonLivestock_SourceData.SourceData_Livestock_Common_SymbolsMMS_Data(), Table_Data_MMSSymbols[[#Headers],[Symbol]], 0)} -> Deep litter | F19: {=Common_InputFunctions.Utility_DisplayArrayInTable(CommonLivestock_SourceData.SourceData_Livestock_Common_SymbolsMMS_Data(), Table_Data_MMSSymbols[[#Headers],[Symbol]], 0)} -> Deep litter (m=8)
D20: {=Common_InputFunctions.Utility_DisplayArrayInTable(CommonLivestock_SourceData.SourceData_Livestock_Common_SymbolsMMS_Data(), Table_Data_MMSSymbols[[#Headers],[Symbol]], 0)} -> 9 | E20: {=Common_InputFunctions.Utility_DisplayArrayInTable(CommonLivestock_SourceData.SourceData_Livestock_Common_SymbolsMMS_Data(), Table_Data_MMSSymbols[[#Headers],[Symbol]], 0)} -> Pit storage | F20: {=Common_InputFunctions.Utility_DisplayArrayInTable(CommonLivestock_SourceData.SourceData_Livestock_Common_SymbolsMMS_Data(), Table_Data_MMSSymbols[[#Headers],[Symbol]], 0)} -> Pit storage (m=9)
A21: CALCULATIONS | D21: {=Common_InputFunctions.Utility_DisplayArrayInTable(CommonLivestock_SourceData.SourceData_Livestock_Common_SymbolsMMS_Data(), Table_Data_MMSSymbols[[#Headers],[Symbol]], 0)} -> 10 | E21: {=Common_InputFunctions.Utility_DisplayArrayInTable(CommonLivestock_SourceData.SourceData_Livestock_Common_SymbolsMMS_Data(), Table_Data_MMSSymbols[[#Headers],[Symbol]], 0)} -> Poultry manure with bedding | F21: {=Common_InputFunctions.Utility_DisplayArrayInTable(CommonLivestock_SourceData.SourceData_Livestock_Common_SymbolsMMS_Data(), Table_Data_MMSSymbols[[#Headers],[Symbol]], 0)} -> Poultry manure with bedding (m=10)
A22: N2O MMS | D22: {=Common_InputFunctions.Utility_DisplayArrayInTable(CommonLivestock_SourceData.SourceData_Livestock_Common_SymbolsMMS_Data(), Table_Data_MMSSymbols[[#Headers],[Symbol]], 0)} -> 11 | E22: {=Common_InputFunctions.Utility_DisplayArrayInTable(CommonLivestock_SourceData.SourceData_Livestock_Common_SymbolsMMS_Data(), Table_Data_MMSSymbols[[#Headers],[Symbol]], 0)} -> Poultry manure without bedding | F22: {=Common_InputFunctions.Utility_DisplayArrayInTable(CommonLivestock_SourceData.SourceData_Livestock_Common_SymbolsMMS_Data(), Table_Data_MMSSymbols[[#Headers],[Symbol]], 0)} -> Poultry manure without bedding (m=11)
A23: Enteric methane | D23: {=Common_InputFunctions.Utility_DisplayArrayInTable(CommonLivestock_SourceData.SourceData_Livestock_Common_SymbolsMMS_Data(), Table_Data_MMSSymbols[[#Headers],[Symbol]], 0)} -> 11a | E23: {=Common_InputFunctions.Utility_DisplayArrayInTable(CommonLivestock_SourceData.SourceData_Livestock_Common_SymbolsMMS_Data(), Table_Data_MMSSymbols[[#Headers],[Symbol]], 0)} -> Belt manure removal | F23: {=Common_InputFunctions.Utility_DisplayArrayInTable(CommonLivestock_SourceData.SourceData_Livestock_Common_SymbolsMMS_Data(), Table_Data_MMSSymbols[[#Headers],[Symbol]], 0)} -> Belt manure removal (m=11a)
A24: =HYPERLINK("#'Calcs - Fert Lime'!A1", "Fertiliser & soil amendments") -> Fertiliser & soil amendments | D24: {=Common_InputFunctions.Utility_DisplayArrayInTable(CommonLivestock_SourceData.SourceData_Livestock_Common_SymbolsMMS_Data(), Table_Data_MMSSymbols[[#Headers],[Symbol]], 0)} -> 11b | E24: {=Common_InputFunctions.Utility_DisplayArrayInTable(CommonLivestock_SourceData.SourceData_Livestock_Common_SymbolsMMS_Data(), Table_Data_MMSSymbols[[#Headers],[Symbol]], 0)} -> Manure stored in house | F24: {=Common_InputFunctions.Utility_DisplayArrayInTable(CommonLivestock_SourceData.SourceData_Livestock_Common_SymbolsMMS_Data(), Table_Data_MMSSymbols[[#Headers],[Symbol]], 0)} -> Manure stored in house (m=11b)
A25: =HYPERLINK("#'Calcs - Residue mgmt - Crop'!A1", "Residue management - Crop") -> Residue management - Crop | D25: {=Common_InputFunctions.Utility_DisplayArrayInTable(CommonLivestock_SourceData.SourceData_Livestock_Common_SymbolsMMS_Data(), Table_Data_MMSSymbols[[#Headers],[Symbol]], 0)} -> 12 | E25: {=Common_InputFunctions.Utility_DisplayArrayInTable(CommonLivestock_SourceData.SourceData_Livestock_Common_SymbolsMMS_Data(), Table_Data_MMSSymbols[[#Headers],[Symbol]], 0)} -> Direct processing | F25: {=Common_InputFunctions.Utility_DisplayArrayInTable(CommonLivestock_SourceData.SourceData_Livestock_Common_SymbolsMMS_Data(), Table_Data_MMSSymbols[[#Headers],[Symbol]], 0)} -> Direct processing (m=12)
A26: =HYPERLINK("#'Calcs - Residue mgmt - Pasture'!A1", "Residue management - Pasture") -> Residue management - Pasture | D26: {=Common_InputFunctions.Utility_DisplayArrayInTable(CommonLivestock_SourceData.SourceData_Livestock_Common_SymbolsMMS_Data(), Table_Data_MMSSymbols[[#Headers],[Symbol]], 0)} -> 13 | E26: {=Common_InputFunctions.Utility_DisplayArrayInTable(CommonLivestock_SourceData.SourceData_Livestock_Common_SymbolsMMS_Data(), Table_Data_MMSSymbols[[#Headers],[Symbol]], 0)} -> Direct application | F26: {=Common_InputFunctions.Utility_DisplayArrayInTable(CommonLivestock_SourceData.SourceData_Livestock_Common_SymbolsMMS_Data(), Table_Data_MMSSymbols[[#Headers],[Symbol]], 0)} -> Direct application (m=13)
A27: =HYPERLINK("#'Calcs - Field burning'!A1", "Field burning - Crop") -> Field burning - Crop | D27: {=Common_InputFunctions.Utility_DisplayArrayInTable(CommonLivestock_SourceData.SourceData_Livestock_Common_SymbolsMMS_Data(), Table_Data_MMSSymbols[[#Headers],[Symbol]], 0)} -> 14 | E27: {=Common_InputFunctions.Utility_DisplayArrayInTable(CommonLivestock_SourceData.SourceData_Livestock_Common_SymbolsMMS_Data(), Table_Data_MMSSymbols[[#Headers],[Symbol]], 0)} -> Pasture range and paddock | F27: {=Common_InputFunctions.Utility_DisplayArrayInTable(CommonLivestock_SourceData.SourceData_Livestock_Common_SymbolsMMS_Data(), Table_Data_MMSSymbols[[#Headers],[Symbol]], 0)} -> Pasture range and paddock (m=14)
A28: =HYPERLINK("#'Calcs - Fuel'!A1", "Fuel") -> Fuel
A29: =HYPERLINK("#'Calcs - Electricity'!A1", "Electricity") -> Electricity
A30: =HYPERLINK("#'Calcs - Refrigerants'!A1", "Refrigerants") -> Refrigerants
A31: Waste
A32: Freight and transport
A33: =HYPERLINK("#'Calcs - Scope 3'!A1", "Purchased goods scope 3") -> Purchased goods scope 3
A35: APPENDICES
A36: =HYPERLINK("#'Constants - Common'!A1", "Constants - Common") -> Constants - Common
A37: =HYPERLINK("#'Constants - Cropping'!A1", "Constants - Cropping") -> Constants - Cropping
A38: =HYPERLINK("#'Constants - Livestock'!A1", "Constants - Livestock") -> Constants - Livestock
A39: =HYPERLINK("#'Constants - Dairy'!A1", "Constants - Dairy") -> Constants - Dairy
A40: Sources & acknowledgements

Sheet Acknowledgements
A1: Acknowledgements

Sheet Constants - Common
A1: #VALUE! | C1: Constants - Common
D5: {=Common_SourceData.Common_SourceData_AustralianStatesTerritories_Title()} -> Australian states and territories
D6: State/Territory | E6: Common Name | F6: Abbreviation
D7: {=Common_InputFunctions.Utility_DisplayArrayInTable(Common_SourceData.Common_SourceData_AustralianStatesTerritories_Data(),Table_AustralianStates[[#Headers],[State/Territory]],0)} -> New South Wales | E7: {=Common_InputFunctions.Utility_DisplayArrayInTable(Common_SourceData.Common_SourceData_AustralianStatesTerritories_Data(),Table_AustralianStates[[#Headers],[State/Territory]],0)} -> New South Wales | F7: {=Common_InputFunctions.Utility_DisplayArrayInTable(Common_SourceData.Common_SourceData_AustralianStatesTerritories_Data(),Table_AustralianStates[[#Headers],[State/Territory]],0)} -> NSW
D8: {=Common_InputFunctions.Utility_DisplayArrayInTable(Common_SourceData.Common_SourceData_AustralianStatesTerritories_Data(),Table_AustralianStates[[#Headers],[State/Territory]],0)} -> Australian Capital Territory | E8: {=Common_InputFunctions.Utility_DisplayArrayInTable(Common_SourceData.Common_SourceData_AustralianStatesTerritories_Data(),Table_AustralianStates[[#Headers],[State/Territory]],0)} -> ACT | F8: {=Common_InputFunctions.Utility_DisplayArrayInTable(Common_SourceData.Common_SourceData_AustralianStatesTerritories_Data(),Table_AustralianStates[[#Headers],[State/Territory]],0)} -> ACT
D9: {=Common_InputFunctions.Utility_DisplayArrayInTable(Common_SourceData.Common_SourceData_AustralianStatesTerritories_Data(),Table_AustralianStates[[#Headers],[State/Territory]],0)} -> Victoria | E9: {=Common_InputFunctions.Utility_DisplayArrayInTable(Common_SourceData.Common_SourceData_AustralianStatesTerritories_Data(),Table_AustralianStates[[#Headers],[State/Territory]],0)} -> Victoria | F9: {=Common_InputFunctions.Utility_DisplayArrayInTable(Common_SourceData.Common_SourceData_AustralianStatesTerritories_Data(),Table_AustralianStates[[#Headers],[State/Territory]],0)} -> VIC
D10: {=Common_InputFunctions.Utility_DisplayArrayInTable(Common_SourceData.Common_SourceData_AustralianStatesTerritories_Data(),Table_AustralianStates[[#Headers],[State/Territory]],0)} -> Queensland | E10: {=Common_InputFunctions.Utility_DisplayArrayInTable(Common_SourceData.Common_SourceData_AustralianStatesTerritories_Data(),Table_AustralianStates[[#Headers],[State/Territory]],0)} -> Queensland | F10: {=Common_InputFunctions.Utility_DisplayArrayInTable(Common_SourceData.Common_SourceData_AustralianStatesTerritories_Data(),Table_AustralianStates[[#Headers],[State/Territory]],0)} -> QLD
D11: {=Common_InputFunctions.Utility_DisplayArrayInTable(Common_SourceData.Common_SourceData_AustralianStatesTerritories_Data(),Table_AustralianStates[[#Headers],[State/Territory]],0)} -> South Australia | E11: {=Common_InputFunctions.Utility_DisplayArrayInTable(Common_SourceData.Common_SourceData_AustralianStatesTerritories_Data(),Table_AustralianStates[[#Headers],[State/Territory]],0)} -> South Australia | F11: {=Common_InputFunctions.Utility_DisplayArrayInTable(Common_SourceData.Common_SourceData_AustralianStatesTerritories_Data(),Table_AustralianStates[[#Headers],[State/Territory]],0)} -> SA
D12: {=Common_InputFunctions.Utility_DisplayArrayInTable(Common_SourceData.Common_SourceData_AustralianStatesTerritories_Data(),Table_AustralianStates[[#Headers],[State/Territory]],0)} -> Western Australia | E12: {=Common_InputFunctions.Utility_DisplayArrayInTable(Common_SourceData.Common_SourceData_AustralianStatesTerritories_Data(),Table_AustralianStates[[#Headers],[State/Territory]],0)} -> Western Australia | F12: {=Common_InputFunctions.Utility_DisplayArrayInTable(Common_SourceData.Common_SourceData_AustralianStatesTerritories_Data(),Table_AustralianStates[[#Headers],[State/Territory]],0)} -> WA
D13: {=Common_InputFunctions.Utility_DisplayArrayInTable(Common_SourceData.Common_SourceData_AustralianStatesTerritories_Data(),Table_AustralianStates[[#Headers],[State/Territory]],0)} -> Tasmania | E13: {=Common_InputFunctions.Utility_DisplayArrayInTable(Common_SourceData.Common_SourceData_AustralianStatesTerritories_Data(),Table_AustralianStates[[#Headers],[State/Territory]],0)} -> Tasmania | F13: {=Common_InputFunctions.Utility_DisplayArrayInTable(Common_SourceData.Common_SourceData_AustralianStatesTerritories_Data(),Table_AustralianStates[[#Headers],[State/Territory]],0)} -> TAS
D14: {=Common_InputFunctions.Utility_DisplayArrayInTable(Common_SourceData.Common_SourceData_AustralianStatesTerritories_Data(),Table_AustralianStates[[#Headers],[State/Territory]],0)} -> Northern Territory | E14: {=Common_InputFunctions.Utility_DisplayArrayInTable(Common_SourceData.Common_SourceData_AustralianStatesTerritories_Data(),Table_AustralianStates[[#Headers],[State/Territory]],0)} -> Northern Territory | F14: {=Common_InputFunctions.Utility_DisplayArrayInTable(Common_SourceData.Common_SourceData_AustralianStatesTerritories_Data(),Table_AustralianStates[[#Headers],[State/Territory]],0)} -> NT
D18: {=Common_SourceData.Common_SourceData_WASA4Areas_Title()} -> ABS Statistcal Areas Level 4 - Western Australia
D19: {=Common_SourceData.Common_SourceData_WASA4Areas_Source()} -> Australian Bureau of Statistics (ABS) - Statistical Areas Level 2 - 2021 - Shapefile
D20: SA 4 Name
D21: {=Common_InputFunctions.Utility_DisplayArrayInTable(Common_SourceData.Common_SourceData_WASA4Areas_Data(), Table_WASA4Areas[[#Headers],[SA 4 Name]], 0)} -> Bunbury
D22: {=Common_InputFunctions.Utility_DisplayArrayInTable(Common_SourceData.Common_SourceData_WASA4Areas_Data(), Table_WASA4Areas[[#Headers],[SA 4 Name]], 0)} -> Mandurah
D23: {=Common_InputFunctions.Utility_DisplayArrayInTable(Common_SourceData.Common_SourceData_WASA4Areas_Data(), Table_WASA4Areas[[#Headers],[SA 4 Name]], 0)} -> Perth - Inner
D24: {=Common_InputFunctions.Utility_DisplayArrayInTable(Common_SourceData.Common_SourceData_WASA4Areas_Data(), Table_WASA4Areas[[#Headers],[SA 4 Name]], 0)} -> Perth - North East
D25: {=Common_InputFunctions.Utility_DisplayArrayInTable(Common_SourceData.Common_SourceData_WASA4Areas_Data(), Table_WASA4Areas[[#Headers],[SA 4 Name]], 0)} -> Perth - North West
D26: {=Common_InputFunctions.Utility_DisplayArrayInTable(Common_SourceData.Common_SourceData_WASA4Areas_Data(), Table_WASA4Areas[[#Headers],[SA 4 Name]], 0)} -> Perth - South East
D27: {=Common_InputFunctions.Utility_DisplayArrayInTable(Common_SourceData.Common_SourceData_WASA4Areas_Data(), Table_WASA4Areas[[#Headers],[SA 4 Name]], 0)} -> Perth - South West
D28: {=Common_InputFunctions.Utility_DisplayArrayInTable(Common_SourceData.Common_SourceData_WASA4Areas_Data(), Table_WASA4Areas[[#Headers],[SA 4 Name]], 0)} -> Western Australia - Wheat Belt
D29: {=Common_InputFunctions.Utility_DisplayArrayInTable(Common_SourceData.Common_SourceData_WASA4Areas_Data(), Table_WASA4Areas[[#Headers],[SA 4 Name]], 0)} -> Western Australia - Outback (North)
D30: {=Common_InputFunctions.Utility_DisplayArrayInTable(Common_SourceData.Common_SourceData_WASA4Areas_Data(), Table_WASA4Areas[[#Headers],[SA 4 Name]], 0)} -> Western Australia - Outback (South)
D34: {=Common_SourceData.Common_SourceData_GWP_Title()} -> Global warming potential for greenhouse gases
D35: {=Common_SourceData.Common_SourceData_GWP_Source()} -> XXXXXXX
D36: Gas | E36: CO2-e factor
D37: {=Common_InputFunctions.Utility_DisplayArrayInTable(Common_SourceData.Common_SourceData_GWP_Data(), Table_GWPData[[#Headers],[Gas]], 0)} -> CO2 | E37: {=Common_InputFunctions.Utility_DisplayArrayInTable(Common_SourceData.Common_SourceData_GWP_Data(), Table_GWPData[[#Headers],[Gas]], 0)} -> 1
D38: {=Common_InputFunctions.Utility_DisplayArrayInTable(Common_SourceData.Common_SourceData_GWP_Data(), Table_GWPData[[#Headers],[Gas]], 0)} -> CH4 | E38: {=Common_InputFunctions.Utility_DisplayArrayInTable(Common_SourceData.Common_SourceData_GWP_Data(), Table_GWPData[[#Headers],[Gas]], 0)} -> 28
D39: {=Common_InputFunctions.Utility_DisplayArrayInTable(Common_SourceData.Common_SourceData_GWP_Data(), Table_GWPData[[#Headers],[Gas]], 0)} -> N2O | E39: {=Common_InputFunctions.Utility_DisplayArrayInTable(Common_SourceData.Common_SourceData_GWP_Data(), Table_GWPData[[#Headers],[Gas]], 0)} -> 265
D40: {=Common_InputFunctions.Utility_DisplayArrayInTable(Common_SourceData.Common_SourceData_GWP_Data(), Table_GWPData[[#Headers],[Gas]], 0)} -> CF4 | E40: {=Common_InputFunctions.Utility_DisplayArrayInTable(Common_SourceData.Common_SourceData_GWP_Data(), Table_GWPData[[#Headers],[Gas]], 0)} -> 6630
D41: {=Common_InputFunctions.Utility_DisplayArrayInTable(Common_SourceData.Common_SourceData_GWP_Data(), Table_GWPData[[#Headers],[Gas]], 0)} -> C2F6 | E41: {=Common_InputFunctions.Utility_DisplayArrayInTable(Common_SourceData.Common_SourceData_GWP_Data(), Table_GWPData[[#Headers],[Gas]], 0)} -> 12200
D42: {=Common_InputFunctions.Utility_DisplayArrayInTable(Common_SourceData.Common_SourceData_GWP_Data(), Table_GWPData[[#Headers],[Gas]], 0)} -> SF6 | E42: {=Common_InputFunctions.Utility_DisplayArrayInTable(Common_SourceData.Common_SourceData_GWP_Data(), Table_GWPData[[#Headers],[Gas]], 0)} -> 22800
D43: {=Common_InputFunctions.Utility_DisplayArrayInTable(Common_SourceData.Common_SourceData_GWP_Data(), Table_GWPData[[#Headers],[Gas]], 0)} -> NF3 | E43: {=Common_InputFunctions.Utility_DisplayArrayInTable(Common_SourceData.Common_SourceData_GWP_Data(), Table_GWPData[[#Headers],[Gas]], 0)} -> 17200
D45: {=Common_SourceData.Common_SourceData_ConvertGasElementalToMolecular_Title()} -> Factor to convert elemental mass of gas to molecular mass
D46: {=Common_SourceData.Common_SourceData_ConvertGasElementalToMolecular_Source()} -> XXXXXXX
D47: Gas | E47: Conversion factor | F47: Conversion factor 1 | G47: Conversion factor 2 | H47: Conversion factor combined
D48: {=Common_InputFunctions.Utility_DisplayArrayInTable(Common_SourceData.Common_SourceData_ConvertGasElementalToMolecular_Data(),Table_GasToMolecularConversionFactor[[#Headers],[Gas]], 0)} -> CO2 | E48: {=Common_InputFunctions.Utility_DisplayArrayInTable(Common_SourceData.Common_SourceData_ConvertGasElementalToMolecular_Data(),Table_GasToMolecularConversionFactor[[#Headers],[Gas]], 0)} -> 44/12 | F48: {=Common_InputFunctions.Utility_DisplayArrayInTable(Common_SourceData.Common_SourceData_ConvertGasElementalToMolecular_Data(),Table_GasToMolecularConversionFactor[[#Headers],[Gas]], 0)} -> 44 | G48: {=Common_InputFunctions.Utility_DisplayArrayInTable(Common_SourceData.Common_SourceData_ConvertGasElementalToMolecular_Data(),Table_GasToMolecularConversionFactor[[#Headers],[Gas]], 0)} -> 12 | H48: =Table_GasToMolecularConversionFactor[[#This Row],[Conversion factor 1]]/Table_GasToMolecularConversionFactor[[#This Row],[Conversion factor 2]] -> 3.6666667
D49: {=Common_InputFunctions.Utility_DisplayArrayInTable(Common_SourceData.Common_SourceData_ConvertGasElementalToMolecular_Data(),Table_GasToMolecularConversionFactor[[#Headers],[Gas]], 0)} -> CH4 | E49: {=Common_InputFunctions.Utility_DisplayArrayInTable(Common_SourceData.Common_SourceData_ConvertGasElementalToMolecular_Data(),Table_GasToMolecularConversionFactor[[#Headers],[Gas]], 0)} -> 16/12 | F49: {=Common_InputFunctions.Utility_DisplayArrayInTable(Common_SourceData.Common_SourceData_ConvertGasElementalToMolecular_Data(),Table_GasToMolecularConversionFactor[[#Headers],[Gas]], 0)} -> 16 | G49: {=Common_InputFunctions.Utility_DisplayArrayInTable(Common_SourceData.Common_SourceData_ConvertGasElementalToMolecular_Data(),Table_GasToMolecularConversionFactor[[#Headers],[Gas]], 0)} -> 12 | H49: =Table_GasToMolecularConversionFactor[[#This Row],[Conversion factor 1]]/Table_GasToMolecularConversionFactor[[#This Row],[Conversion factor 2]] -> 1.3333333
D50: {=Common_InputFunctions.Utility_DisplayArrayInTable(Common_SourceData.Common_SourceData_ConvertGasElementalToMolecular_Data(),Table_GasToMolecularConversionFactor[[#Headers],[Gas]], 0)} -> N2O | E50: {=Common_InputFunctions.Utility_DisplayArrayInTable(Common_SourceData.Common_SourceData_ConvertGasElementalToMolecular_Data(),Table_GasToMolecularConversionFactor[[#Headers],[Gas]], 0)} -> 44/28 | F50: {=Common_InputFunctions.Utility_DisplayArrayInTable(Common_SourceData.Common_SourceData_ConvertGasElementalToMolecular_Data(),Table_GasToMolecularConversionFactor[[#Headers],[Gas]], 0)} -> 44 | G50: {=Common_InputFunctions.Utility_DisplayArrayInTable(Common_SourceData.Common_SourceData_ConvertGasElementalToMolecular_Data(),Table_GasToMolecularConversionFactor[[#Headers],[Gas]], 0)} -> 28 | H50: =Table_GasToMolecularConversionFactor[[#This Row],[Conversion factor 1]]/Table_GasToMolecularConversionFactor[[#This Row],[Conversion factor 2]] -> 1.5714286
...
