Workbook
Name Common_Equations.Common_ConvertCH4ToCO2e: _xlfn.LAMBDA(_xlpm.E_CH4,_xlpm.GWP_CH4, _xlpm.E_CH4 * _xlpm.GWP_CH4)
Name Common_Equations.Common_ConvertCH4ToCO2e_Arguments: _xlfn.LAMBDA(_xlfn.MAKEARRAY(2, 2, _xlfn.LAMBDA(_xlpm.r,_xlpm.c, INDEX({"ECH4","Methane emissions (t CH4)";"GWPCH4","Global warming potential for methane (t CO2-e / t CH4)"}, _xlpm.r, _xlpm.c))))
Name Common_Equations.Common_ConvertCH4ToCO2e_LatexEquation: _xlfn.LAMBDA("CO2_e = E_{CH4} \times GWP_{CH4}")
Name Common_Equations.Common_ConvertCH4ToCO2e_NIRReference: _xlfn.LAMBDA("")
Name Common_Equations.Common_ConvertCH4ToCO2e_Title: _xlfn.LAMBDA("Convert methane emissions to carbon dioxide equivalent emissions")
Name Common_Equations.Common_ConvertCH4ToCO2e_Unit: _xlfn.LAMBDA("t CO2e")
Name Common_Equations.Common_ConvertCH4ToCO2e_Variable: _xlfn.LAMBDA("ECH4 CO2e")
Name Common_Equations.Common_ConvertN2OToCO2e: _xlfn.LAMBDA(_xlpm.E_N2O,_xlpm.GWP_N2O, _xlpm.E_N2O * _xlpm.GWP_N2O)
Name Common_Equations.Common_ConvertN2OToCO2e_LatexEquation: _xlfn.LAMBDA("CO2_e = E_{N2O} \times GWP_{N2O}")
Name Common_Equations.Common_ConvertN2OToCO2e_NIRReference: _xlfn.LAMBDA("")
Name Common_Equations.Common_ConvertN2OToCO2e_Title: _xlfn.LAMBDA("Convert nitrous oxide emissions to carbon dioxide equivalent emissions")
Name Common_Equations.Common_ConvertN2OToCO2e_Unit: _xlfn.LAMBDA("t CO2e")
Name Common_Equations.Common_ConvertN2OToCO2e_Variable: _xlfn.LAMBDA("EN2O CO2e")
Name Common_InputFunctions.Utility_DisplayFunctionName: _xlfn.LAMBDA(_xlpm.Function, _xlfn.TEXTBEFORE(_xlfn.FORMULATEXT(_xlpm.Function), "("))
Name Common_InputFunctions.Utility_GetArrayTableColumnStartNumber: _xlfn.LAMBDA(_xlpm.TableHeaderCell, COLUMN(_xlpm.TableHeaderCell))
Name Common_InputFunctions.Utility_GetArrayTableRowStartNumber: _xlfn.LAMBDA(_xlpm.TableheaderCell,_xlpm.RowsBetweenHeaderandArray, ROW(_xlpm.TableheaderCell) + _xlpm.RowsBetweenHeaderandArray - 1)
Name Common_InputFunctions.Utility_LookupValueInTable: _xlfn.LAMBDA(_xlpm.LookupValue,_xlpm.LookupArray,_xlpm.ReturnArray, _xlfn.XLOOKUP(_xlpm.LookupValue, _xlpm.LookupArray, _xlpm.ReturnArray, ""))
Name Common_SourceData.Common_SourceData_AustralianStatesTerritories_Source: _xlfn.LAMBDA("")
Name Common_SourceData.Common_SourceData_AustralianStatesTerritories_Title: _xlfn.LAMBDA("Australian states and territories")
Name Common_SourceData.Common_SourceData_AustralianStatesTerritories_Unit: _xlfn.LAMBDA("")
Name Common_SourceData.Common_SourceData_AustralianStatesTerritories_Variable: _xlfn.LAMBDA("")
Name Common_SourceData.Common_SourceData_ClimateZones_Source: _xlfn.LAMBDA("VEERG 2026: Table 1.3: Climate and Rainfall zone classifications and definitions")
Name Common_SourceData.Common_SourceData_ClimateZones_Title: _xlfn.LAMBDA("VEERG Australian climate zones")
Name Common_SourceData.Common_SourceData_ClimateZones_Unit: _xlfn.LAMBDA("")
Name Common_SourceData.Common_SourceData_ClimateZones_Variable: _xlfn.LAMBDA("")
Name Common_SourceData.Common_SourceData_ConvertGasElementalToMolecular_Source: _xlfn.LAMBDA("XXXXXXX")
Name Common_SourceData.Common_SourceData_ConvertGasElementalToMolecular_Title: _xlfn.LAMBDA("Factor to convert elemental mass of gas to molecular mass")
Name Common_SourceData.Common_SourceData_ConvertGasElementalToMolecular_Unit: _xlfn.LAMBDA("factor")
Name Common_SourceData.Common_SourceData_ConvertGasElementalToMolecular_Variable: _xlfn.LAMBDA("Cg")
Name Common_SourceData.Common_SourceData_ConvertN2oElementalToMolecularCg_Data: _xlfn.LAMBDA(44 / 28)
Name Common_SourceData.Common_SourceData_ConvertN2oElementalToMolecularCg_Source: _xlfn.LAMBDA("National Inventory Report 2023 Volume 1")
Name Common_SourceData.Common_SourceData_ConvertN2oElementalToMolecularCg_Title: _xlfn.LAMBDA("Factor to convert elemental mass of N2O to molecular mass")
Name Common_SourceData.Common_SourceData_ConvertN2oElementalToMolecularCg_Unit: _xlfn.LAMBDA("factor")
Name Common_SourceData.Common_SourceData_ConvertN2oElementalToMolecularCg_Variable: _xlfn.LAMBDA("CgN2O")
Name Common_SourceData.Common_SourceData_DataScores_Scope3_Source: _xlfn.LAMBDA("VEERG 2026: XXXXXXXX")
Name Common_SourceData.Common_SourceData_DataScores_Scope3_Title: _xlfn.LAMBDA("Australian data scores for scope 3")
Name Common_SourceData.Common_SourceData_DataScores_Scope3_Unit: _xlfn.LAMBDA("")
Name Common_SourceData.Common_SourceData_DataScores_Scope3_Variable: _xlfn.LAMBDA("")
Name Common_SourceData.Common_SourceData_DataScores_Scope3_Variation: _xlfn.LAMBDA("")
Name Common_SourceData.Common_SourceData_DensityOfMethane_Data: _xlfn.LAMBDA(0.6784)
Name Common_SourceData.Common_SourceData_DensityOfMethane_Source: _xlfn.LAMBDA("National Inventory Report 2023 Volume 1: Equations 3.B.1a_2, 3.B.1c_2, 3.B.3_1, 3.B.4g_2")
Name Common_SourceData.Common_SourceData_DensityOfMethane_Title: _xlfn.LAMBDA("p = density of methane")
Name Common_SourceData.Common_SourceData_DensityOfMethane_Unit: _xlfn.LAMBDA("kg/m3")
Name Common_SourceData.Common_SourceData_EFleach_Data: _xlfn.LAMBDA(_xlfn.MAKEARRAY(1, 2, _xlfn.LAMBDA(_xlpm.r,_xlpm.c, INDEX({"EFleach",0.011}, _xlpm.r, _xlpm.c))))
Name Common_SourceData.Common_SourceData_EFleach_NIRReference: _xlfn.LAMBDA("National Inventory Report Volume 1: Equation 3.D.B_10")
Name Common_SourceData.Common_SourceData_EFleach_Source: _xlfn.LAMBDA("VEERG 2026:5.5.2.3 Constant Parameters")
Name Common_SourceData.Common_SourceData_EFleach_Title: _xlfn.LAMBDA("Emission factor for nitrogen leaching and runoff")
Name Common_SourceData.Common_SourceData_EFleach_Unit: _xlfn.LAMBDA("(kg N2O-N / kg N")
Name Common_SourceData.Common_SourceData_EFleach_Variation: _xlfn.LAMBDA((""))
Name Common_SourceData.Common_SourceData_EFN2O_NIRReference: _xlfn.LAMBDA("")
Name Common_SourceData.Common_SourceData_EFN2O_Source: _xlfn.LAMBDA("VEERG 2026: Table A.2.2.1")
Name Common_SourceData.Common_SourceData_EFN2O_Title: _xlfn.LAMBDA("Nitrous oxide emission factors for inorganic fertiliser application")
Name Common_SourceData.Common_SourceData_EFN2O_Unit: _xlfn.LAMBDA("(kg N2O-N / kg N")
Name Common_SourceData.Common_SourceData_EFPastureRangeAndPaddock_Data: _xlfn.LAMBDA(_xlfn.MAKEARRAY(3, 2, _xlfn.LAMBDA(_xlpm.r,_xlpm.c, INDEX({"Climate zone","EFPRP";"Wet climate zone",0.006;"Dry climate zone",0.002}, _xlpm.r, _xlpm.c))))
Name Common_SourceData.Common_SourceData_EFPastureRangeAndPaddock_NIRReference: _xlfn.LAMBDA("")
Name Common_SourceData.Common_SourceData_EFPastureRangeAndPaddock_Source: _xlfn.LAMBDA("VEERG 2026: Table A.2.2.2")
Name Common_SourceData.Common_SourceData_EFPastureRangeAndPaddock_Title: _xlfn.LAMBDA("Emission factor for urine and dung deposited on pasture, range or paddock")
Name Common_SourceData.Common_SourceData_EFPastureRangeAndPaddock_Unit: _xlfn.LAMBDA("kg N2O - N / kg N")
Name Common_SourceData.Common_SourceData_EFPastureRangeAndPaddock_Variation: _xlfn.LAMBDA("VARIATION FROM SOURCE DATA: Changed 'Dry climate zones' to singular 'Dry climate zone' to aid lookup.")
Name Common_SourceData.Common_SourceData_FracLEACH_Data: _xlfn.LAMBDA(_xlfn.MAKEARRAY(1, 2, _xlfn.LAMBDA(_xlpm.r,_xlpm.c, INDEX({"FracLEACH",0.24}, _xlpm.r, _xlpm.c))))

Sheet Home
A1: Home

Sheet Results
A1: #VALUE! | C1: 4.1 Manure management: Beef Feedlot: Results
A3: =HYPERLINK("#'Home'!A1", "Home") -> Home
A4: =HYPERLINK("#'Results'!A1", "Results") -> Results | D4: Emissions breakdown
A6: INPUTS | D6: Scope 1 source | E6: GHG emissions | F6: GHG Unit | G6: CO2-e emissions | H6: CO2-e unit
A7: =HYPERLINK("#'Input - Site'!A1", "Site") -> Site | D7: 4.1.1.1 Method 1 Manure methane | E7: ='4.3.1.1-2 Methane'!$E$264 -> 8.1869605 | F7: ='4.3.1.1-2 Methane'!$F$264 -> t CH4 | G7: ='4.3.1.1-2 Methane'!$E$269 -> 0 | H7: ='4.3.1.1-2 Methane'!$F$269 -> t CO2e
A8: =HYPERLINK("#'Input - Feedlot'!A1", "Feedlot") -> Feedlot | D8: 4.1.1.2 Method 2 Manure methane | E8: ='4.3.1.1-2 Methane'!$P$264 -> 8.0754443 | F8: ='4.3.1.1-2 Methane'!$Q$264 -> t CH4 | G8: ='4.3.1.1-2 Methane'!$P$269 -> 0 | H8: ='4.3.1.1-2 Methane'!$Q$269 -> t CO2e
D9: 4.1.1.3 Method 1 Manure direct N2O | E9: ='4.3.1.3-4 Direct N20'!#REF! -> #REF! | F9: ='4.3.1.3-4 Direct N20'!#REF! -> #REF! | G9: ='4.3.1.3-4 Direct N20'!#REF! -> #REF! | H9: ='4.3.1.3-4 Direct N20'!#REF! -> #REF!
A10: CALCULATIONS | D10: 4.1.1.4 Method 2 Manure direct N2O | E10: ='4.3.1.3-4 Direct N20'!O207 -> 0 | F10: ='4.3.1.3-4 Direct N20'!P207 -> 0 | G10: ='4.3.1.3-4 Direct N20'!O212 -> 0 | H10: ='4.3.1.3-4 Direct N20'!P212 -> 0
A11: =HYPERLINK("#'4.1.1.1-2 Methane'!A1", "4.1.1.1-2 Methane") -> 4.1.1.1-2 Methane | D11: 4.1.1.5 Method 1 Manure atmospheric deposition | E11: ='4.1.1.5-6 Atmos Deposition'!$E$60 -> #NAME? | F11: ='4.1.1.5-6 Atmos Deposition'!$F$60 -> #NAME? | G11: ='4.1.1.5-6 Atmos Deposition'!$E$65 -> #NAME? | H11: ='4.1.1.5-6 Atmos Deposition'!$F$65 -> t CO2e
A12: =HYPERLINK("#'4.1.1.3-4 Direct N20'!A1", "4.1.1.3-4 Direct N2O") -> 4.1.1.3-4 Direct N2O | D12: 4.1.1.6 Method 2 Manure atmospheric deposition | E12: ='4.1.1.5-6 Atmos Deposition'!$M$60 -> #NAME? | F12: ='4.1.1.5-6 Atmos Deposition'!$N$60 -> #NAME? | G12: ='4.1.1.5-6 Atmos Deposition'!$M$65 -> #NAME? | H12: ='4.1.1.5-6 Atmos Deposition'!$N$65 -> t CO2e
A13: =HYPERLINK("#'4.1.1.5-6 Atmos Deposition'!A1", "4.1.1.5-6 Atmospheric deposition") -> 4.1.1.5-6 Atmospheric deposition | D13: 4.1.1.7 Method 1 Manure leaching and runoff | E13: N/A | F13: N/A | G13: 0 | H13: N/A
A14: =HYPERLINK("#'4.1.1.9 Manure applied to soils'!A1", "4.1.1.9 Manure applied to soils") -> 4.1.1.9 Manure applied to soils | D14: 4.1.1.8 Method 1 Manure leaching and runoff | E14: N/A | F14: N/A | G14: 0 | H14: N/A
D15: Total | G15: =SUM(G7:G14) -> #REF! | H15: ='4.1.1.5-6 Atmos Deposition'!$N$65 -> t CO2e
A16: APPENDICES
A17: =HYPERLINK("#'Constants - Feedlot'!A1", "Constants - Feedlot") -> Constants - Feedlot | D17: WARNING: Manure nitrogen that was applied to soils must be accounted for
A18: =HYPERLINK("#'Constants - Livestock'!A1", "Constants - Livestock") -> Constants - Livestock | D18: See the table below for how to account for manure applied to soils for scope 1 and 3.
A19: =HYPERLINK("#'Constants - Common'!A1", "Constants - Common") -> Constants - Common
A20: =HYPERLINK("#'Acknowledgements'!A1", "Acknowledgements") -> Acknowledgements | D20: Manure nitrogen use | E20: Amount of N in manure | F20: N unit | G20: Emissions allocated to | H20: VEERG Calculation method
D21: Manure nitrogen deposited on farm soils with no other purpose (aka waste) | E21: ='4.1.1.9 Manure applied to soils'!$E$56 -> #NAME? | F21: ='4.1.1.9 Manure applied to soils'!$F$56 -> #NAME? | G21: This feedlot | H21: 5.2.2.1 (1), 5.4.1.3 (1, 2), 5.5.1.1 (1, 3)
D22: Manure nitrogen deposited on farm soils as fertiliser for other farm enterpsies (eg crops) | E22: ='4.1.1.9 Manure applied to soils'!$E$104 -> #NAME? | F22: ='4.1.1.9 Manure applied to soils'!$F$104 -> #NAME? | G22: Crops or pasture that use manure as fertiliser | H22: 5.2.2.1 (1), 5.4.1.3 (1, 2), 5.5.1.1 (1, 3)
D23: Manure nitrogen sold | E23: ='4.1.1.9 Manure applied to soils'!$E$123 -> #NAME? | F23: ='4.1.1.9 Manure applied to soils'!$F$123 -> #NAME? | G23: Scope 3 (downstream) | H23: 15.13.1.1 (1), 5.2.2.1 (1), 5.4.1.3 (1, 2), 5.5.1.1 (1, 3)

Sheet Input - Site
A1: #VALUE! | C1: Input - Site
A3: =HYPERLINK("#'Home'!A1", "Home") -> Home
A4: =HYPERLINK("#'Results'!A1", "Results") -> Results
D5: Your business
A6: INPUTS
A7: =HYPERLINK("#'Input - Site'!A1", "Site") -> Site | D7: Farm name | E7: Test Farms
A8: =HYPERLINK("#'Input - Feedlot'!A1", "Feedlot") -> Feedlot | D8: Reporting entity name | E8: Test Farms Pty Ltd
A10: CALCULATIONS | D10: 💡An 'Emissions accounting period' is a 12 month period where the business can report on the emissions, and is typically the same as the business' financial accounting period.
A11: =HYPERLINK("#'4.1.1.1-2 Methane'!A1", "4.1.1.1-2 Methane") -> 4.1.1.1-2 Methane
A12: =HYPERLINK("#'4.1.1.3-4 Direct N20'!A1", "4.1.1.3-4 Direct N2O") -> 4.1.1.3-4 Direct N2O | D12: Emissions calculation period start date | E12: 45292 | F12: ← DD/MM/YYYY or DD Month YYYY
A13: =HYPERLINK("#'4.1.1.5-6 Atmos Deposition'!A1", "4.1.1.5-6 Atmospheric deposition") -> 4.1.1.5-6 Atmospheric deposition | D13: Emissions calculation period end date | E13: =DATE(YEAR(E12)+1,MONTH(E12),DAY(E12))-1 -> 45657 | F13: ← Automatically calculated, 12 months after start date
A14: =HYPERLINK("#'4.1.1.9 Manure applied to soils'!A1", "4.1.1.9 Manure applied to soils") -> 4.1.1.9 Manure applied to soils
A16: APPENDICES | D16: Location and climate
A17: =HYPERLINK("#'Constants - Feedlot'!A1", "Constants - Feedlot") -> Constants - Feedlot
A18: =HYPERLINK("#'Constants - Livestock'!A1", "Constants - Livestock") -> Constants - Livestock | D18: Location information is used to reference some region and climate-specific emission factors
A19: =HYPERLINK("#'Constants - Common'!A1", "Constants - Common") -> Constants - Common | D19: Tip: Use the web-based GAF Location Helper tool to easily get region and climate information. You will need an internet connection to use the GAF Location Helper.
A20: =HYPERLINK("#'Acknowledgements'!A1", "Acknowledgements") -> Acknowledgements
D21: State | E21: New South Wales | F21: ← Please select
D22: Region (ABS Statistical area level 4) if state is WA | E22: Western Australia - Outback (South) | F22: ← Please select
D23: Leaching zone | E23: NO - Not in leaching zone | F23: ← Please select
D24: Elevation | E24: 307.7 | F24: Meters
D25: Average temperature for reporting period | E25: 18 | F25: Degrees celsius
D26: Total rainfall for reporting period | E26: 601 | F26: Millimetres
D27: Potential evapotranspiration for reporting period | E27: 1326 | F27: Millimetres
D28: Number of frost days for reporting period | E28: 7 | F28: Days
D29: MAP:PET ratio | E29: =E26/E27 -> 0.45324284
D30: Rainfall zone | E30: =Common_InputFunctions.Utility_LookupItemFromMinMax(E26,Table_SourceData_RainfallZones[Min rainfall],Table_SourceData_RainfallZones[Max rainfall],Table_SourceData_RainfallZones[Rainfall Zone]) -> High rainfall
D31: Climate zone | E31: =Common_InputFunctions.Utility_GetClimateZone(E25,E26,E28,E24,E29,Table_SourceData_ClimateZones[Min temp],Table_SourceData_ClimateZones[Max temp],Table_SourceData_ClimateZones[Min rainfall],Table_SourceData_ClimateZones[Max rainfall],Table_SourceData_ClimateZones[Min frost days],Table_SourceData_ClimateZones[Max frost days],Table_SourceData_ClimateZones[Min elevation],Table_SourceData_ClimateZones[Max elevation],Table_SourceData_ClimateZones[Min MAP:PET],Table_SourceData_ClimateZones[Max MAP:PET],Table_SourceData_ClimateZones[Climate zone]) -> Warm temperate dry
D32: Wet or dry climate zone | E32: =Common_InputFunctions.Utility_LookupValueInTable($E$31,Table_SourceData_WetDryZones[Climate zone],Table_SourceData_WetDryZones[Wet or Dry Zone]) -> Dry climate zone
D33: Temperature zone | E33: =Common_InputFunctions.Utility_LookupItemFromMinMax(E25,Table_SourceData_TemperatureZones[Min MAT],Table_SourceData_TemperatureZones[Max MAT],Table_SourceData_TemperatureZones[Temperature Zone]) -> Temperate

Sheet Input - Dairy
A1: #VALUE! | C1: Input -Dairy
A3: =HYPERLINK("#'Home'!A1", "Home") -> Home
A4: =HYPERLINK("#'Results'!A1", "Results") -> Results
D5: Herd movement
A6: INPUTS
A7: =HYPERLINK("#'Input - Site'!A1", "Site") -> Site | D7: Breed | E7: Medium Friesian | F7: ← Please select
A8: =HYPERLINK("#'Input - Dairy'!A1", "Dairy") -> Dairy
E9: Milking cows | F9: Heifers > 1 year | G9: Heifers < 1 year | H9: Bulls > 1 year | I9: Bulls < 1 year
A10: CALCULATIONS | D10: ="Average number of head between " & TEXT('Input - Site'!$E$12, "dd mmm yy") & " and " & TEXT('Input - Site'!$E$13, "dd mmm yy") -> Average number of head between 01 Jan 24 and 31 Dec 24 | E10: 100 | F10: 100 | G10: 100 | H10: 100 | I10: 100 | J10: head
A11: =HYPERLINK("#'4.1.1.1-2 Methane'!A1", "4.1.1.1-2 Methane") -> 4.1.1.1-2 Methane
A12: =HYPERLINK("#'4.1.1.3-4 Direct N20'!A1", "4.1.1.3-4 Direct N2O") -> 4.1.1.3-4 Direct N2O | D12: Liveweight
A13: =HYPERLINK("#'4.1.1.5-6 Atmos Deposition'!A1", "4.1.1.5-6 Atmospheric deposition") -> 4.1.1.5-6 Atmospheric deposition | D13: Method 1 default values (Do not edit) | E13: Milking cows | F13: Heifers > 1 year | G13: Heifers < 1 year | H13: Bulls > 1 year | I13: Bulls < 1 year
A14: =HYPERLINK("#'4.1.1.9 Manure applied to soils'!A1", "4.1.1.9 Manure applied to soils") -> 4.1.1.9 Manure applied to soils | D14: Average liveweight | E14: {=Common_InputFunctions.Utility_LookupValueInTableNumber($E$7, Table_SourceData_Dairy_WjCowsHeifers[Breed],Table_SourceData_Dairy_WjCowsHeifers[Milking cows])} -> 550 | F14: {=Common_InputFunctions.Utility_LookupValueInTableNumber($E$7, Table_SourceData_Dairy_WjCowsHeifers[Breed],Table_SourceData_Dairy_WjCowsHeifers[Heifers > 1])} -> 380 | G14: {=Common_InputFunctions.Utility_LookupValueInTableNumber($E$7, Table_SourceData_Dairy_WjCowsHeifers[Breed],Table_SourceData_Dairy_WjCowsHeifers[Heifers < 1 (weaned)])} -> 155 | H14: {=Table_SourceData_Dairy_WjBulls[Bulls > 1]} -> 600 | I14: {=Table_SourceData_Dairy_WjBulls[Bulls < 1 (weaned)]} -> 225 | J14: kg/head
D15: Average liveweight gain | E15: {=Table_SourceData_Dairy_LWGj[Milking cows]} -> 0.016 | F15: {=Table_SourceData_Dairy_LWGj[Heifers > 1]} -> 0.6 | G15: {=Table_SourceData_Dairy_LWGj[Heifers < 1 (weaned)]} -> 0.57 | H15: {=Table_SourceData_Dairy_LWGj[Bulls > 1]} -> 0.1 | I15: {=Table_SourceData_Dairy_LWGj[Bulls < 1 (weaned)]} -> 0.8 | J15: kg/head/day
A16: APPENDICES
A17: =HYPERLINK("#'Constants - Dairy'!A1", "Constants - Dairy") -> Constants - Dairy | D17: Method 2 custom values (Edit if known) | E17: Milking cows | F17: Heifers > 1 year | G17: Heifers < 1 year | H17: Bulls > 1 year | I17: Bulls < 1 year
A18: =HYPERLINK("#'Constants - Livestock'!A1", "Constants - Livestock") -> Constants - Livestock | D18: Average liveweight | E18: {=Common_InputFunctions.Utility_LookupValueInTableNumber($E$7, Table_SourceData_Dairy_WjCowsHeifers[Breed],Table_SourceData_Dairy_WjCowsHeifers[Milking cows])} -> 550 | F18: {=Common_InputFunctions.Utility_LookupValueInTableNumber($E$7, Table_SourceData_Dairy_WjCowsHeifers[Breed],Table_SourceData_Dairy_WjCowsHeifers[Heifers > 1])} -> 380 | G18: {=Common_InputFunctions.Utility_LookupValueInTableNumber($E$7, Table_SourceData_Dairy_WjCowsHeifers[Breed],Table_SourceData_Dairy_WjCowsHeifers[Heifers < 1 (weaned)])} -> 155 | H18: {=Table_SourceData_Dairy_WjBulls[Bulls > 1]} -> 600 | I18: {=Table_SourceData_Dairy_WjBulls[Bulls < 1 (weaned)]} -> 225 | J18: kg/head
A19: =HYPERLINK("#'Constants - Common'!A1", "Constants - Common") -> Constants - Common | D19: Average liveweight gain | E19: {=Table_SourceData_Dairy_LWGj[Milking cows]} -> 0.016 | F19: {=Table_SourceData_Dairy_LWGj[Heifers > 1]} -> 0.6 | G19: {=Table_SourceData_Dairy_LWGj[Heifers < 1 (weaned)]} -> 0.57 | H19: {=Table_SourceData_Dairy_LWGj[Bulls > 1]} -> 0.1 | I19: {=Table_SourceData_Dairy_LWGj[Bulls < 1 (weaned)]} -> 0.8 | J19: kg/head/day
A20: =HYPERLINK("#'Acknowledgements'!A1", "Acknowledgements") -> Acknowledgements
D21: Duration of stay
D23: Method 1 default values (Do not edit) | E23: Milking cows | F23: Heifers > 1 year | G23: Heifers < 1 year | H23: Bulls > 1 year | I23: Bulls < 1 year
D24: ="Average duration of stay between " & TEXT('Input - Site'!$E$12, "dd mmm yy") & " and " & TEXT('Input - Site'!$E$13, "dd mmm yy") & " weaned livestock" -> Average duration of stay between 01 Jan 24 and 31 Dec 24 weaned livestock | E24: {=Common_InputFunctions.Utility_LookupValueInTableNumber(E23,Table_SourceData_Dairy_Duration[Animal class j],Table_SourceData_Dairy_Duration[Duration (weaned)])} -> 365 | F24: {=Common_InputFunctions.Utility_LookupValueInTableNumber(F23,Table_SourceData_Dairy_Duration[Animal class j],Table_SourceData_Dairy_Duration[Duration (weaned)])} -> 365 | G24: {=Common_InputFunctions.Utility_LookupValueInTableNumber(G23,Table_SourceData_Dairy_Duration[Animal class j],Table_SourceData_Dairy_Duration[Duration (weaned)])} -> 281 | H24: {=Common_InputFunctions.Utility_LookupValueInTableNumber(H23,Table_SourceData_Dairy_Duration[Animal class j],Table_SourceData_Dairy_Duration[Duration (weaned)])} -> 365 | I24: {=Common_InputFunctions.Utility_LookupValueInTableNumber(I23,Table_SourceData_Dairy_Duration[Animal class j],Table_SourceData_Dairy_Duration[Duration (weaned)])} -> 281 | J24: Days
D25: ="Average duration of stay between " & TEXT('Input - Site'!$E$12, "dd mmm yy") & " and " & TEXT('Input - Site'!$E$13, "dd mmm yy") & " pre-weaned livestock" -> Average duration of stay between 01 Jan 24 and 31 Dec 24 pre-weaned livestock | E25: {=Common_InputFunctions.Utility_LookupValueInTableNumber(E23,Table_SourceData_Dairy_Duration[Animal class j],Table_SourceData_Dairy_Duration[Duration (pre-weaned)])} -> 0 | F25: {=Common_InputFunctions.Utility_LookupValueInTableNumber(F23,Table_SourceData_Dairy_Duration[Animal class j],Table_SourceData_Dairy_Duration[Duration (pre-weaned)])} -> 0 | G25: {=Common_InputFunctions.Utility_LookupValueInTableNumber(G23,Table_SourceData_Dairy_Duration[Animal class j],Table_SourceData_Dairy_Duration[Duration (pre-weaned)])} -> 84 | H25: {=Common_InputFunctions.Utility_LookupValueInTableNumber(H23,Table_SourceData_Dairy_Duration[Animal class j],Table_SourceData_Dairy_Duration[Duration (pre-weaned)])} -> 0 | I25: {=Common_InputFunctions.Utility_LookupValueInTableNumber(I23,Table_SourceData_Dairy_Duration[Animal class j],Table_SourceData_Dairy_Duration[Duration (pre-weaned)])} -> 84 | J25: Days
D27: Method 2 custom values (Edit if known) | E27: Milking cows | F27: Heifers > 1 year | G27: Heifers < 1 year | H27: Bulls > 1 year | I27: Bulls < 1 year
D28: ="Average duration of stay between " & TEXT('Input - Site'!$E$12, "dd mmm yy") & " and " & TEXT('Input - Site'!$E$13, "dd mmm yy") & " weaned livestock" -> Average duration of stay between 01 Jan 24 and 31 Dec 24 weaned livestock | E28: {=Common_InputFunctions.Utility_LookupValueInTableNumber(E27,Table_SourceData_Dairy_Duration[Animal class j],Table_SourceData_Dairy_Duration[Duration (weaned)])} -> 365 | F28: {=Common_InputFunctions.Utility_LookupValueInTableNumber(F27,Table_SourceData_Dairy_Duration[Animal class j],Table_SourceData_Dairy_Duration[Duration (weaned)])} -> 365 | G28: {=Common_InputFunctions.Utility_LookupValueInTableNumber(G27,Table_SourceData_Dairy_Duration[Animal class j],Table_SourceData_Dairy_Duration[Duration (weaned)])} -> 281 | H28: {=Common_InputFunctions.Utility_LookupValueInTableNumber(H27,Table_SourceData_Dairy_Duration[Animal class j],Table_SourceData_Dairy_Duration[Duration (weaned)])} -> 365 | I28: {=Common_InputFunctions.Utility_LookupValueInTableNumber(I27,Table_SourceData_Dairy_Duration[Animal class j],Table_SourceData_Dairy_Duration[Duration (weaned)])} -> 281 | J28: Days
D29: ="Average duration of stay between " & TEXT('Input - Site'!$E$12, "dd mmm yy") & " and " & TEXT('Input - Site'!$E$13, "dd mmm yy") & " pre-weaned livestock" -> Average duration of stay between 01 Jan 24 and 31 Dec 24 pre-weaned livestock | E29: =365-E28 -> 0 | F29: =365-F28 -> 0 | G29: =365-G28 -> 84 | H29: =365-H28 -> 0 | I29: =365-I28 -> 84 | J29: Days
D32: Diet
D34: Method 1 default values (Do not edit) | E34: Milking cows | F34: Heifers > 1 year | G34: Heifers < 1 year | H34: Bulls > 1 year | I34: Bulls < 1 year
D35: Dry matter intake | E35: {=Common_InputFunctions.Utility_LookupValueInTableNumber(E34,Table_SourceData_Dairy_Duration[Animal class j],Table_SourceData_Dairy_Duration[Duration (weaned)])} -> 365 | F35: {=Common_InputFunctions.Utility_LookupValueInTableNumber(F34,Table_SourceData_Dairy_Duration[Animal class j],Table_SourceData_Dairy_Duration[Duration (weaned)])} -> 365 | G35: {=Common_InputFunctions.Utility_LookupValueInTableNumber(G34,Table_SourceData_Dairy_Duration[Animal class j],Table_SourceData_Dairy_Duration[Duration (weaned)])} -> 281 | H35: {=Common_InputFunctions.Utility_LookupValueInTableNumber(H34,Table_SourceData_Dairy_Duration[Animal class j],Table_SourceData_Dairy_Duration[Duration (weaned)])} -> 365 | I35: {=Common_InputFunctions.Utility_LookupValueInTableNumber(I34,Table_SourceData_Dairy_Duration[Animal class j],Table_SourceData_Dairy_Duration[Duration (weaned)])} -> 281 | J35: kgDM/head/day
D36: Dry matter digestibility | E36: ='Constants - Dairy'!$D$160 -> 0.75 | F36: ='Constants - Dairy'!$D$160 -> 0.75 | G36: ='Constants - Dairy'!$D$160 -> 0.75 | H36: ='Constants - Dairy'!$D$160 -> 0.75 | I36: ='Constants - Dairy'!$D$160 -> 0.75 | J36: Fraction
D37: Crude protein | E37: ='Constants - Dairy'!$D$153 -> 0.2 | F37: ='Constants - Dairy'!$D$153 -> 0.2 | G37: ='Constants - Dairy'!$D$153 -> 0.2 | H37: ='Constants - Dairy'!$D$153 -> 0.2 | I37: ='Constants - Dairy'!$D$153 -> 0.2 | J37: Fraction
D39: Method 2 custom values (Edit if known) | E39: Milking cows | F39: Heifers > 1 year | G39: Heifers < 1 year | H39: Bulls > 1 year | I39: Bulls < 1 year
D40: Dry matter intake | E40: {=Common_InputFunctions.Utility_LookupValueInTableNumber(E39,Table_SourceData_Dairy_Duration[Animal class j],Table_SourceData_Dairy_Duration[Duration (weaned)])} -> 365 | F40: {=Common_InputFunctions.Utility_LookupValueInTableNumber(F39,Table_SourceData_Dairy_Duration[Animal class j],Table_SourceData_Dairy_Duration[Duration (weaned)])} -> 365 | G40: {=Common_InputFunctions.Utility_LookupValueInTableNumber(G39,Table_SourceData_Dairy_Duration[Animal class j],Table_SourceData_Dairy_Duration[Duration (weaned)])} -> 281 | H40: {=Common_InputFunctions.Utility_LookupValueInTableNumber(H39,Table_SourceData_Dairy_Duration[Animal class j],Table_SourceData_Dairy_Duration[Duration (weaned)])} -> 365 | I40: {=Common_InputFunctions.Utility_LookupValueInTableNumber(I39,Table_SourceData_Dairy_Duration[Animal class j],Table_SourceData_Dairy_Duration[Duration (weaned)])} -> 281 | J40: kgDM/head/day
D41: Dry matter digestibility | E41: 0.75 | F41: 0.75 | G41: 0.75 | H41: 0.75 | I41: 0.75 | J41: Fraction
D42: Crude protein | E42: 0.2 | F42: 0.2 | G42: 0.2 | H42: 0.2 | I42: 0.2 | J42: Fraction
D44: Milk production
E45: Milking cows
D46: Average daily milk production | E46: 44 | F46: litres/head/day
D48: Production systems
D49: Time spent in production systems
...

Sheet 4.3.1.1-2 Methane
A1: #VALUE! | C1: 4.3.1.1-2 Manure Methane
A3: =HYPERLINK("#'Home'!A1", "Home") -> Home | D3: Method 1 | O3: Method 2
A4: =HYPERLINK("#'Results'!A1", "Results") -> Results
D5: {=EntericMethane_Dairy_Equations.VEERG_3_3_1_1__6_MetabolisabilityOfDiet_Title()} -> Metabolisability of the diet based on Minson and McDonald (1987)
A6: INPUTS | D6: {=EntericMethane_Dairy_Equations.VEERG_3_3_1_1__6_MetabolisabilityOfDiet_Source()} -> VEERG 2026: 3.3.1.1, Equation (6)
A7: =HYPERLINK("#'Input - Site'!A1", "Site") -> Site | D7: Function name | E7: {=Common_InputFunctions.Utility_DisplayFunctionName(D23)} -> =EntericMethane_Dairy_Equations.VEERG_3_3_1_1__6_MetabolisabilityOfDiet
A8: =HYPERLINK("#'Input - Feedlot'!A1", "Feedlot") -> Feedlot
A10: CALCULATIONS | D10: Variable | E10: {=EntericMethane_Dairy_Equations.VEERG_3_3_1_1__6_MetabolisabilityOfDiet_Variable()} -> qm_j
A11: =HYPERLINK("#'4.1.1.1-2 Methane'!A1", "4.1.1.1-2 Methane") -> 4.1.1.1-2 Methane | D11: Unit | E11: {=EntericMethane_Dairy_Equations.VEERG_3_3_1_1__6_MetabolisabilityOfDiet_Unit()} -> fraction
A12: =HYPERLINK("#'4.1.1.3-4 Direct N20'!A1", "4.1.1.3-4 Direct N2O") -> 4.1.1.3-4 Direct N2O
A13: =HYPERLINK("#'4.1.1.5-6 Atmos Deposition'!A1", "4.1.1.5-6 Atmospheric deposition") -> 4.1.1.5-6 Atmospheric deposition | D13: {=EntericMethane_Dairy_Equations.VEERG_3_3_1_1__6_MetabolisabilityOfDiet_Arguments()} -> DMD_j | E13: dry matter digestibility expressed as a fraction | G13: ="See " & D15 -> See M1_Table_DMD_j
A14: =HYPERLINK("#'4.1.1.9 Manure applied to soils'!A1", "4.1.1.9 Manure applied to soils") -> 4.1.1.9 Manure applied to soils
D15: M1_Table_DMD_j | O15: M2_Table_DMD_j
A16: APPENDICES | D16: Dry matter digestibility (Method 1) | O16: Dry matter digestibility (Method 2)
A17: =HYPERLINK("#'Constants - Feedlot'!A1", "Constants - Feedlot") -> Constants - Feedlot | D17: Milking cows | E17: Heifers > 1 year | F17: Heifers < 1 year | G17: Bulls > 1 year | H17: Bulls < 1 year | O17: Milking cows | P17: Heifers > 1 year | Q17: Heifers < 1 year | R17: Bulls > 1 year | S17: Bulls < 1 year
A18: =HYPERLINK("#'Constants - Livestock'!A1", "Constants - Livestock") -> Constants - Livestock | D18: ='Input - Dairy'!$E$36 -> 0.75 | E18: ='Input - Dairy'!$F$36 -> 0.75 | F18: ='Input - Dairy'!$G$36 -> 0.75 | G18: ='Input - Dairy'!$H$36 -> 0.75 | H18: ='Input - Dairy'!$I$36 -> 0.75 | I18: fraction | O18: ='Input - Dairy'!$E$41 -> 0.75 | P18: ='Input - Dairy'!$F$41 -> 0.75 | Q18: ='Input - Dairy'!$G$41 -> 0.75 | R18: ='Input - Dairy'!$H$41 -> 0.75 | S18: ='Input - Dairy'!$I$41 -> 0.75 | T18: fraction
A19: =HYPERLINK("#'Constants - Common'!A1", "Constants - Common") -> Constants - Common
A20: =HYPERLINK("#'Acknowledgements'!A1", "Acknowledgements") -> Acknowledgements | D20: M1_Table_qm_j | O20: M2_Table_qm_j
D21: Metabolisability of diet (Method 1) | O21: Metabolisability of diet (Method 2)
D22: Milking cows | E22: Heifers > 1 year | F22: Heifers < 1 year | G22: Bulls > 1 year | H22: Bulls < 1 year | O22: Milking cows | P22: Heifers > 1 year | Q22: Heifers < 1 year | R22: Bulls > 1 year | S22: Bulls < 1 year
D23: {=EntericMethane_Dairy_Equations.VEERG_3_3_1_1__6_MetabolisabilityOfDiet(D18)} -> 59.6236 | E23: {=EntericMethane_Dairy_Equations.VEERG_3_3_1_1__6_MetabolisabilityOfDiet(E18)} -> 59.6236 | F23: {=EntericMethane_Dairy_Equations.VEERG_3_3_1_1__6_MetabolisabilityOfDiet(F18)} -> 59.6236 | G23: {=EntericMethane_Dairy_Equations.VEERG_3_3_1_1__6_MetabolisabilityOfDiet(G18)} -> 59.6236 | H23: {=EntericMethane_Dairy_Equations.VEERG_3_3_1_1__6_MetabolisabilityOfDiet(H18)} -> 59.6236 | I23: =$E$11 -> fraction | O23: {=EntericMethane_Dairy_Equations.VEERG_3_3_1_1__6_MetabolisabilityOfDiet(O18)} -> 59.6236 | P23: {=EntericMethane_Dairy_Equations.VEERG_3_3_1_1__6_MetabolisabilityOfDiet(P18)} -> 59.6236 | Q23: {=EntericMethane_Dairy_Equations.VEERG_3_3_1_1__6_MetabolisabilityOfDiet(Q18)} -> 59.6236 | R23: {=EntericMethane_Dairy_Equations.VEERG_3_3_1_1__6_MetabolisabilityOfDiet(R18)} -> 59.6236 | S23: {=EntericMethane_Dairy_Equations.VEERG_3_3_1_1__6_MetabolisabilityOfDiet(S18)} -> 59.6236 | T23: =$E$11 -> fraction
D27: {=EntericMethane_Dairy_Equations.VEERG_3_3_1_1__4_AdditionalIntakeForMilkProduction_Title()} -> Additional intake required for milk production
D28: {=EntericMethane_Dairy_Equations.VEERG_3_3_1_1__4_AdditionalIntakeForMilkProduction_Source()} -> VEERG 2026: 3.3.1.1, Equation (4)
D29: Function name | E29: {=Common_InputFunctions.Utility_DisplayFunctionName(D49)} -> =EntericMethane_Dairy_Equations.VEERG_3_3_1_1__4_AdditionalIntakeForMilkProduction
D32: Variable | E32: {=EntericMethane_Dairy_Equations.VEERG_3_3_1_1__4_AdditionalIntakeForMilkProduction_Variable()} -> MI_j
D33: Unit | E33: {=EntericMethane_Dairy_Equations.VEERG_3_3_1_1__4_AdditionalIntakeForMilkProduction_Unit()} -> kg DM/head/day
D35: {=EntericMethane_Dairy_Equations.VEERG_3_3_1_1__4_AdditionalIntakeForMilkProduction_Arguments()} -> MP_j | E35: milk production (L/head/day) | G35: ="See " & D41 -> See Table_MP_j
D36: NE | E36: net energy (MJ net energy/kg milk) | G36: ='Constants - Dairy'!$D$167 -> 3.054
D37: GEC | E37: gross energy content (MJ/kgDM) | G37: ='Constants - Dairy'!$D$174 -> 18.4
D38: k | E38: efficiency of metabolizable energy use for milk production (fraction) | G38: ='Constants - Dairy'!$D$181 -> 0.6
D39: qm_j | E39: metabolisability of the diet (fraction) | G39: ="See " & D20 -> See M1_Table_qm_j
D41: Table_MP_j
D42: Milk production
D43: Milking cows | E43: Heifers > 1 year | F43: Heifers < 1 year | G43: Bulls > 1 year | H43: Bulls < 1 year
D44: ='Input - Dairy'!$E$46 -> 44 | E44: 0 | F44: 0 | G44: 0 | H44: 0 | I44: L/head/day
D46: M1_Table_MI_j | O46: M2_Table_MI_j
D47: Additional intake for milk production (Method 1) | O47: Additional intake for milk production (Method 2)
D48: Milking cows | E48: Heifers > 1 year | F48: Heifers < 1 year | G48: Bulls > 1 year | H48: Bulls < 1 year | O48: Milking cows | P48: Heifers > 1 year | Q48: Heifers < 1 year | R48: Bulls > 1 year | S48: Bulls < 1 year
D49: {=EntericMethane_Dairy_Equations.VEERG_3_3_1_1__4_AdditionalIntakeForMilkProduction(D44, $G$36,$G$37,$G$38,D23)} -> 0.21026727 | E49: {=EntericMethane_Dairy_Equations.VEERG_3_3_1_1__4_AdditionalIntakeForMilkProduction(E44, $G$36,$G$37,$G$38,E23)} -> 0 | F49: {=EntericMethane_Dairy_Equations.VEERG_3_3_1_1__4_AdditionalIntakeForMilkProduction(F44, $G$36,$G$37,$G$38,F23)} -> 0 | G49: {=EntericMethane_Dairy_Equations.VEERG_3_3_1_1__4_AdditionalIntakeForMilkProduction(G44, $G$36,$G$37,$G$38,G23)} -> 0 | H49: {=EntericMethane_Dairy_Equations.VEERG_3_3_1_1__4_AdditionalIntakeForMilkProduction(H44, $G$36,$G$37,$G$38,H23)} -> 0 | I49: =$E$33 -> kg DM/head/day | O49: {=EntericMethane_Dairy_Equations.VEERG_3_3_1_1__4_AdditionalIntakeForMilkProduction(D44, $G$36,$G$37,$G$38,O23)} -> 0.21026727 | P49: {=EntericMethane_Dairy_Equations.VEERG_3_3_1_1__4_AdditionalIntakeForMilkProduction(E44, $G$36,$G$37,$G$38,P23)} -> 0 | Q49: {=EntericMethane_Dairy_Equations.VEERG_3_3_1_1__4_AdditionalIntakeForMilkProduction(F44, $G$36,$G$37,$G$38,Q23)} -> 0 | R49: {=EntericMethane_Dairy_Equations.VEERG_3_3_1_1__4_AdditionalIntakeForMilkProduction(G44, $G$36,$G$37,$G$38,R23)} -> 0 | S49: {=EntericMethane_Dairy_Equations.VEERG_3_3_1_1__4_AdditionalIntakeForMilkProduction(H44, $G$36,$G$37,$G$38,S23)} -> 0 | T49: =$E$33 -> kg DM/head/day
D53: {=EntericMethane_Dairy_Equations.VEERG_3_3_1_1__3_DryMatterFeedIntake_Title()} -> Feed intake based on Minson and McDonald (1987)
...

Sheet 4.3.1.3-4 Direct N20
A1: #VALUE! | C1: 4.3.1.3-4 Manure Direct N2O
A3: =HYPERLINK("#'Home'!A1", "Home") -> Home | D3: Method 1 | N3: Method 2
A4: =HYPERLINK("#'Results'!A1", "Results") -> Results
D5: {=MMS_Dairy_N2ODirect_Equations.VEERG_4_3_1_3__8_RelativeSize_Title()} -> Relative size
A6: INPUTS | D6: {=MMS_Dairy_N2ODirect_Equations.VEERG_4_3_1_3__8_RelativeSize_Source()} -> VEERG 2026: 4.3.1.3, Equation (8)
A7: =HYPERLINK("#'Input - Site'!A1", "Site") -> Site | D7: Function name | E7: {=Common_InputFunctions.Utility_DisplayFunctionName(D29)} -> =MMS_Dairy_N2ODirect_Equations.VEERG_4_3_1_3__8_RelativeSize
A8: =HYPERLINK("#'Input - Feedlot'!A1", "Feedlot") -> Feedlot
A10: CALCULATIONS | D10: Variable | E10: {=MMS_Dairy_N2ODirect_Equations.VEERG_4_3_1_3__8_RelativeSize_Variable()} -> Z_j
A11: =HYPERLINK("#'4.1.1.1-2 Methane'!A1", "4.1.1.1-2 Methane") -> 4.1.1.1-2 Methane | D11: Unit | E11: {=MMS_Dairy_N2ODirect_Equations.VEERG_4_3_1_3__8_RelativeSize_Unit()} -> ratio
A12: =HYPERLINK("#'4.1.1.3-4 Direct N20'!A1", "4.1.1.3-4 Direct N2O") -> 4.1.1.3-4 Direct N2O
A13: =HYPERLINK("#'4.1.1.5-6 Atmos Deposition'!A1", "4.1.1.5-6 Atmospheric deposition") -> 4.1.1.5-6 Atmospheric deposition | D13: {=MMS_Dairy_N2ODirect_Equations.VEERG_4_3_1_3__8_RelativeSize_Arguments()} -> W_j | E13: liveweight (kg) | F13: ="See " & D16 -> See M1_Table_W_j
A14: =HYPERLINK("#'4.1.1.9 Manure applied to soils'!A1", "4.1.1.9 Manure applied to soils") -> 4.1.1.9 Manure applied to soils | D14: WR_j | E14: reference weight (kg) | F14: ="See " & D21 -> See Table_WR_j
A16: APPENDICES | D16: M1_Table_W_j | N16: M2_Table_W_j
A17: =HYPERLINK("#'Constants - Feedlot'!A1", "Constants - Feedlot") -> Constants - Feedlot | D17: Liveweight for each animal class j (Method 1) | N17: Liveweight for each animal class j (Method 2)
A18: =HYPERLINK("#'Constants - Livestock'!A1", "Constants - Livestock") -> Constants - Livestock | D18: Milking cows | E18: Heifers > 1 year | F18: Heifers < 1 year | G18: Bulls > 1 year | H18: Bulls < 1 year | N18: Milking cows | O18: Heifers > 1 year | P18: Heifers < 1 year | Q18: Bulls > 1 year | R18: Bulls < 1 year
A19: =HYPERLINK("#'Constants - Common'!A1", "Constants - Common") -> Constants - Common | D19: ='Input - Dairy'!$E$14 -> 550 | E19: ='Input - Dairy'!$F$14 -> 380 | F19: ='Input - Dairy'!$G$14 -> 155 | G19: ='Input - Dairy'!$H$14 -> 600 | H19: ='Input - Dairy'!$I$14 -> 225 | I19: kg/head | N19: ='Input - Dairy'!$E$18 -> 550 | O19: ='Input - Dairy'!$F$18 -> 380 | P19: ='Input - Dairy'!$G$18 -> 155 | Q19: ='Input - Dairy'!$H$18 -> 600 | R19: ='Input - Dairy'!$I$18 -> 225 | S19: kg/head
A20: =HYPERLINK("#'Acknowledgements'!A1", "Acknowledgements") -> Acknowledgements
D21: Table_WR_j
D22: Reference weight for each animal class
D23: Milking cows | E23: Heifers > 1 year | F23: Heifers < 1 year | G23: Bulls > 1 year | H23: Bulls < 1 year
D24: {=Table_SourceData_Dairy_WRj[Milking cows]} -> 590 | E24: {=Table_SourceData_Dairy_WRj[Heifers > 1]} -> 590 | F24: {=Table_SourceData_Dairy_WRj[Heifers < 1 (weaned)]} -> 590 | G24: {=Table_SourceData_Dairy_WRj[Bulls > 1]} -> 770 | H24: {=Table_SourceData_Dairy_WRj[Bulls < 1 (weaned)]} -> 770 | I24: kg/head
D26: M1_Table_Z_j | N26: M1_Table_Z_j
D27: Relative size for each animal class (Method 1) | N27: Relative size for each animal class (Method 1)
D28: Milking cows | E28: Heifers > 1 year | F28: Heifers < 1 year | G28: Bulls > 1 year | H28: Bulls < 1 year | N28: Milking cows | O28: Heifers > 1 year | P28: Heifers < 1 year | Q28: Bulls > 1 year | R28: Bulls < 1 year
D29: {=MMS_Dairy_N2ODirect_Equations.VEERG_4_3_1_3__8_RelativeSize(D19,D24)} -> 0.93220339 | E29: {=MMS_Dairy_N2ODirect_Equations.VEERG_4_3_1_3__8_RelativeSize(E19,E24)} -> 0.6440678 | F29: {=MMS_Dairy_N2ODirect_Equations.VEERG_4_3_1_3__8_RelativeSize(F19,F24)} -> 0.26271186 | G29: {=MMS_Dairy_N2ODirect_Equations.VEERG_4_3_1_3__8_RelativeSize(G19,G24)} -> 0.77922078 | H29: {=MMS_Dairy_N2ODirect_Equations.VEERG_4_3_1_3__8_RelativeSize(H19,H24)} -> 0.29220779 | I29: =$E$11 -> ratio | N29: {=MMS_Dairy_N2ODirect_Equations.VEERG_4_3_1_3__8_RelativeSize(N19,D24)} -> 0.93220339 | O29: {=MMS_Dairy_N2ODirect_Equations.VEERG_4_3_1_3__8_RelativeSize(O19,E24)} -> 0.6440678 | P29: {=MMS_Dairy_N2ODirect_Equations.VEERG_4_3_1_3__8_RelativeSize(P19,F24)} -> 0.26271186 | Q29: {=MMS_Dairy_N2ODirect_Equations.VEERG_4_3_1_3__8_RelativeSize(Q19,G24)} -> 0.77922078 | R29: {=MMS_Dairy_N2ODirect_Equations.VEERG_4_3_1_3__8_RelativeSize(R19,H24)} -> 0.29220779 | S29: =$E$11 -> ratio
D33: {=MMS_Dairy_N2ODirect_Equations.VEERG_4_3_1_3__7_IntakeRelativeToMaintenance_Title()} -> Intake relative to maintenance
D34: {=MMS_Dairy_N2ODirect_Equations.VEERG_4_3_1_3__7_IntakeRelativeToMaintenance_Source()} -> VEERG 2026: 4.3.1.3, Equation (7)
D35: Function name | E35: {=Common_InputFunctions.Utility_DisplayFunctionName(D65)} -> =MMS_Dairy_N2ODirect_Equations.VEERG_4_3_1_3__7_IntakeRelativeToMaintenance
D39: Variable | E39: {=MMS_Dairy_N2ODirect_Equations.VEERG_4_3_1_3__7_IntakeRelativeToMaintenance_Variable()} -> L_j
D40: Unit | E40: {=MMS_Dairy_N2ODirect_Equations.VEERG_4_3_1_3__7_IntakeRelativeToMaintenance_Unit()} -> ratio
D42: {=MMS_Dairy_N2ODirect_Equations.VEERG_4_3_1_3__7_IntakeRelativeToMaintenance_Arguments()} -> I_j | E42: dry matter intake (kgDM/head/day) | G42: ="See " & D47 -> See M1_Table_I_j
D43: W_j | E43: liveweight (kg) | G43: ="See " & D16 -> See M1_Table_W_j
D44: MR_j | E44: increase in metabolic rate when producing milk | G44: ="See " & D52 -> See Table_MR_j
D45: MI_j | E45: additional intake required for milk production (kgDM/head/day) | G45: ="See " & D57 -> See M1_Table_MI_j
D47: M1_Table_I_j | N47: M2_Table_I_j
D48: Feed intake (Method 1) | N48: Feed intake (Method 2)
D49: Milking cows | E49: Heifers > 1 year | F49: Heifers < 1 year | G49: Bulls > 1 year | H49: Bulls < 1 year | N49: Milking cows | O49: Heifers > 1 year | P49: Heifers < 1 year | Q49: Bulls > 1 year | R49: Bulls < 1 year
D50: ='4.3.1.1-2 Methane'!D84 -> 9.4647128 | E50: ='4.3.1.1-2 Methane'!E84 -> 7.4188685 | F50: ='4.3.1.1-2 Methane'!F84 -> 4.0231735 | G50: ='4.3.1.1-2 Methane'!G84 -> 9.0270202 | H50: ='4.3.1.1-2 Methane'!H84 -> 5.4143473 | I50: ='4.3.1.1-2 Methane'!I84 -> kg DM/head/day | N50: ='4.3.1.1-2 Methane'!O84 -> 9.4647128 | O50: ='4.3.1.1-2 Methane'!P84 -> 7.4188685 | P50: ='4.3.1.1-2 Methane'!Q84 -> 4.0231735 | Q50: ='4.3.1.1-2 Methane'!R84 -> 9.0270202 | R50: ='4.3.1.1-2 Methane'!S84 -> 5.4143473 | S50: ='4.3.1.1-2 Methane'!T84 -> kg DM/head/day
D52: Table_MR_j
D53: Increase in metabolic rate when producing milk
...

Sheet 4.1.1.5-6 Atmos Deposition
A1: #VALUE! | C1: 4.1.1.5-6 Manure Atmospheric Deposition
A3: =HYPERLINK("#'Home'!A1", "Home") -> Home | D3: Method 1 | L3: Method 2
A4: =HYPERLINK("#'Results'!A1", "Results") -> Results
D5: {=MMS_Feedlot_AtmosphericDeposition_Equations.VEERG_4_1_1_5__2_VolatilisedNitrogenFromManureManagement_Title()} -> #NAME?
A6: INPUTS | D6: {=MMS_Feedlot_AtmosphericDeposition_Equations.VEERG_4_1_1_5__2_VolatilisedNitrogenFromManureManagement_Source()} -> #NAME?
A7: =HYPERLINK("#'Input - Site'!A1", "Site") -> Site | D7: Function name | E7: {=Common_InputFunctions.Utility_DisplayFunctionName(E36)} -> =MMS_Feedlot_AtmosphericDeposition_Equations.VEERG_4_1_1_5__2_VolatilisedNitrogenFromManureManagement
A8: =HYPERLINK("#'Input - Feedlot'!A1", "Feedlot") -> Feedlot
A10: CALCULATIONS
A11: =HYPERLINK("#'4.1.1.1-2 Methane'!A1", "4.1.1.1-2 Methane") -> 4.1.1.1-2 Methane | D11: Variable | E11: {=MMS_Feedlot_AtmosphericDeposition_Equations.VEERG_4_1_1_5__2_VolatilisedNitrogenFromManureManagement_Variable()} -> #NAME?
A12: =HYPERLINK("#'4.1.1.3-4 Direct N20'!A1", "4.1.1.3-4 Direct N2O") -> 4.1.1.3-4 Direct N2O | D12: Unit | E12: {=MMS_Feedlot_AtmosphericDeposition_Equations.VEERG_4_1_1_5__2_VolatilisedNitrogenFromManureManagement_Unit()} -> #NAME?
A13: =HYPERLINK("#'4.1.1.5-6 Atmos Deposition'!A1", "4.1.1.5-6 Atmospheric deposition") -> 4.1.1.5-6 Atmospheric deposition
A14: =HYPERLINK("#'4.1.1.9 Manure applied to soils'!A1", "4.1.1.9 Manure applied to soils") -> 4.1.1.9 Manure applied to soils | D14: {=MMS_Feedlot_AtmosphericDeposition_Equations.VEERG_4_1_1_5__2_VolatilisedNitrogenFromManureManagement_Arguments()} -> #NAME? | G14: ="See " & D17 -> See M1_Table_MN_j_m_T
G15: ="See " & D25 -> See Table_FracGASM_m_T-2-3
A16: APPENDICES
A17: =HYPERLINK("#'Constants - Feedlot'!A1", "Constants - Feedlot") -> Constants - Feedlot | D17: M1_Table_MN_j_m_T | L17: M2_Table_MN_j_m_T
A18: =HYPERLINK("#'Constants - Livestock'!A1", "Constants - Livestock") -> Constants - Livestock | D18: Nitrogen in each MMS excluding direct application (Method 1) | L18: Nitrogen in each MMS excluding direct application (Method 2)
A19: =HYPERLINK("#'Constants - Common'!A1", "Constants - Common") -> Constants - Common | D19: MMS | E19: Domestic | F19: Mid-fed | G19: Long-fed | L19: MMS | M19: Domestic | N19: Mid-fed | O19: Long-fed
A20: =HYPERLINK("#'Acknowledgements'!A1", "Acknowledgements") -> Acknowledgements | D20: ='Input - Dairy'!$D$95 -> Total manure sent to MMS (Must equal 100%) (Method 2) | E20: ='4.3.1.3-4 Direct N20'!$E$106 -> kg/head/day | F20: ='4.3.1.3-4 Direct N20'!$F$106 -> 0 | G20: ='4.3.1.3-4 Direct N20'!$G$106 -> 0 | H20: kg N | L20: ='Input - Dairy'!$D$95 -> Total manure sent to MMS (Must equal 100%) (Method 2) | M20: ='4.3.1.3-4 Direct N20'!$O$106 -> 0 | N20: ='4.3.1.3-4 Direct N20'!$P$106 -> 0 | O20: ='4.3.1.3-4 Direct N20'!$Q$106 -> 0 | P20: kg N
D21: ='Input - Dairy'!$D$101 -> Anaerobic lagoon | E21: ='4.3.1.3-4 Direct N20'!$E$173 -> 0 | F21: ='4.3.1.3-4 Direct N20'!$F$173 -> 0 | G21: ='4.3.1.3-4 Direct N20'!$G$173 -> 0 | H21: kg N | L21: ='Input - Dairy'!$D$101 -> Anaerobic lagoon | M21: ='4.3.1.3-4 Direct N20'!$O$173 -> 0 | N21: ='4.3.1.3-4 Direct N20'!$P$173 -> 0 | O21: ='4.3.1.3-4 Direct N20'!$Q$173 -> 0 | P21: kg N
D22: ='Input - Dairy'!$D$102 -> Were solids separated from Anaerobic lagoon? | E22: ='4.3.1.3-4 Direct N20'!$E$174 -> 0 | F22: ='4.3.1.3-4 Direct N20'!$F$174 -> 0 | G22: ='4.3.1.3-4 Direct N20'!$G$174 -> 0 | H22: kg N | L22: ='Input - Dairy'!$D$102 -> Were solids separated from Anaerobic lagoon? | M22: ='4.3.1.3-4 Direct N20'!$O$174 -> 0 | N22: ='4.3.1.3-4 Direct N20'!$P$174 -> 0 | O22: ='4.3.1.3-4 Direct N20'!$Q$174 -> 0 | P22: kg N
D23: ='Input - Dairy'!$D$107 -> Were solids separated from Sump and dispersal system? | E23: ='4.3.1.3-4 Direct N20'!$E$130 -> kg N/head/day | F23: ='4.3.1.3-4 Direct N20'!$F$130 -> 0 | G23: ='4.3.1.3-4 Direct N20'!$G$130 -> 0 | H23: kg N | L23: ='Input - Dairy'!$D$107 -> Were solids separated from Sump and dispersal system? | M23: ='4.3.1.3-4 Direct N20'!$O$129 -> 0 | N23: ='4.3.1.3-4 Direct N20'!$P$129 -> 0 | O23: ='4.3.1.3-4 Direct N20'!$Q$129 -> 0 | P23: kg N
D25: Table_FracGASM_m_T-2-3
D26: Fraction of N volatilised in each MMS
D27: MMS | E27: EFjm
D28: ='Input - Dairy'!$D$95 -> Total manure sent to MMS (Must equal 100%) (Method 2) | E28: =_xlfn.XLOOKUP(D28,#REF!,#REF!) -> #REF! | F28: (kg NH3-N + NOx-N)/kg N
D29: ='Input - Dairy'!$D$101 -> Anaerobic lagoon | E29: =_xlfn.XLOOKUP(D29,#REF!,#REF!) -> #REF! | F29: (kg NH3-N + NOx-N)/kg N
D30: ='Input - Dairy'!$D$102 -> Were solids separated from Anaerobic lagoon? | E30: =_xlfn.XLOOKUP(D30,#REF!,#REF!) -> #REF! | F30: (kg NH3-N + NOx-N)/kg N
D31: ='Input - Dairy'!$D$107 -> Were solids separated from Sump and dispersal system? | E31: =_xlfn.XLOOKUP(D31,#REF!,#REF!) -> #REF! | F31: (kg NH3-N + NOx-N)/kg N
D33: M1_Table_MMS_ATMOS | L33: M1_Table_MMS_ATMOS
D34: Nitrogen in each MMS excluding direct application (Method 1) | L34: Nitrogen in each MMS excluding direct application (Method 1)
D35: MMS | E35: Domestic | F35: Mid-fed | G35: Long-fed | L35: MMS | M35: Domestic | N35: Mid-fed | O35: Long-fed
D36: ='Input - Dairy'!$D$95 -> Total manure sent to MMS (Must equal 100%) (Method 2) | E36: {=MMS_Feedlot_AtmosphericDeposition_Equations.VEERG_4_1_1_5__2_VolatilisedNitrogenFromManureManagement(E20,$E28)} -> #NAME? | F36: {=MMS_Feedlot_AtmosphericDeposition_Equations.VEERG_4_1_1_5__2_VolatilisedNitrogenFromManureManagement(F20,$E28)} -> #NAME? | G36: {=MMS_Feedlot_AtmosphericDeposition_Equations.VEERG_4_1_1_5__2_VolatilisedNitrogenFromManureManagement(G20,$E28)} -> #NAME? | H36: =$E$12 -> #NAME? | L36: ='Input - Dairy'!$D$95 -> Total manure sent to MMS (Must equal 100%) (Method 2) | M36: {=MMS_Feedlot_AtmosphericDeposition_Equations.VEERG_4_1_1_5__2_VolatilisedNitrogenFromManureManagement(M20,$E28)} -> #NAME? | N36: {=MMS_Feedlot_AtmosphericDeposition_Equations.VEERG_4_1_1_5__2_VolatilisedNitrogenFromManureManagement(N20,$E28)} -> #NAME? | O36: {=MMS_Feedlot_AtmosphericDeposition_Equations.VEERG_4_1_1_5__2_VolatilisedNitrogenFromManureManagement(O20,$E28)} -> #NAME? | P36: kg N
D37: ='Input - Dairy'!$D$101 -> Anaerobic lagoon | E37: {=MMS_Feedlot_AtmosphericDeposition_Equations.VEERG_4_1_1_5__2_VolatilisedNitrogenFromManureManagement(E21,$E29)} -> #NAME? | F37: {=MMS_Feedlot_AtmosphericDeposition_Equations.VEERG_4_1_1_5__2_VolatilisedNitrogenFromManureManagement(F21,$E29)} -> #NAME? | G37: {=MMS_Feedlot_AtmosphericDeposition_Equations.VEERG_4_1_1_5__2_VolatilisedNitrogenFromManureManagement(G21,$E29)} -> #NAME? | H37: =$E$12 -> #NAME? | L37: ='Input - Dairy'!$D$101 -> Anaerobic lagoon | M37: {=MMS_Feedlot_AtmosphericDeposition_Equations.VEERG_4_1_1_5__2_VolatilisedNitrogenFromManureManagement(M21,$E29)} -> #NAME? | N37: {=MMS_Feedlot_AtmosphericDeposition_Equations.VEERG_4_1_1_5__2_VolatilisedNitrogenFromManureManagement(N21,$E29)} -> #NAME? | O37: {=MMS_Feedlot_AtmosphericDeposition_Equations.VEERG_4_1_1_5__2_VolatilisedNitrogenFromManureManagement(O21,$E29)} -> #NAME? | P37: kg N
D38: ='Input - Dairy'!$D$102 -> Were solids separated from Anaerobic lagoon? | E38: {=MMS_Feedlot_AtmosphericDeposition_Equations.VEERG_4_1_1_5__2_VolatilisedNitrogenFromManureManagement(E22,$E30)} -> #NAME? | F38: {=MMS_Feedlot_AtmosphericDeposition_Equations.VEERG_4_1_1_5__2_VolatilisedNitrogenFromManureManagement(F22,$E30)} -> #NAME? | G38: {=MMS_Feedlot_AtmosphericDeposition_Equations.VEERG_4_1_1_5__2_VolatilisedNitrogenFromManureManagement(G22,$E30)} -> #NAME? | H38: =$E$12 -> #NAME? | L38: ='Input - Dairy'!$D$102 -> Were solids separated from Anaerobic lagoon? | M38: {=MMS_Feedlot_AtmosphericDeposition_Equations.VEERG_4_1_1_5__2_VolatilisedNitrogenFromManureManagement(M22,$E30)} -> #NAME? | N38: {=MMS_Feedlot_AtmosphericDeposition_Equations.VEERG_4_1_1_5__2_VolatilisedNitrogenFromManureManagement(N22,$E30)} -> #NAME? | O38: {=MMS_Feedlot_AtmosphericDeposition_Equations.VEERG_4_1_1_5__2_VolatilisedNitrogenFromManureManagement(O22,$E30)} -> #NAME? | P38: kg N
D39: ='Input - Dairy'!$D$107 -> Were solids separated from Sump and dispersal system? | E39: {=MMS_Feedlot_AtmosphericDeposition_Equations.VEERG_4_1_1_5__2_VolatilisedNitrogenFromManureManagement(E23,$E31)} -> #NAME? | F39: {=MMS_Feedlot_AtmosphericDeposition_Equations.VEERG_4_1_1_5__2_VolatilisedNitrogenFromManureManagement(F23,$E31)} -> #NAME? | G39: {=MMS_Feedlot_AtmosphericDeposition_Equations.VEERG_4_1_1_5__2_VolatilisedNitrogenFromManureManagement(G23,$E31)} -> #NAME? | H39: =$E$12 -> #NAME? | L39: ='Input - Dairy'!$D$107 -> Were solids separated from Sump and dispersal system? | M39: {=MMS_Feedlot_AtmosphericDeposition_Equations.VEERG_4_1_1_5__2_VolatilisedNitrogenFromManureManagement(M23,$E31)} -> #NAME? | N39: {=MMS_Feedlot_AtmosphericDeposition_Equations.VEERG_4_1_1_5__2_VolatilisedNitrogenFromManureManagement(N23,$E31)} -> #NAME? | O39: {=MMS_Feedlot_AtmosphericDeposition_Equations.VEERG_4_1_1_5__2_VolatilisedNitrogenFromManureManagement(O23,$E31)} -> #NAME? | P39: kg N
D41: MMSATMOS | E41: =SUM(E36:G39) -> #NAME? | F41: =$E$12 -> #NAME? | L41: MMSATMOS | M41: =SUM(M36:O39) -> #NAME? | N41: =$E$12 -> #NAME?
D45: {=MMS_Feedlot_AtmosphericDeposition_Equations.VEERG_4_1_1_5__1_TotalAnnualAtmosphericDepositionEmissions_Title()} -> #NAME?
D46: {=MMS_Feedlot_AtmosphericDeposition_Equations.VEERG_4_1_1_5__1_TotalAnnualAtmosphericDepositionEmissions_Source()} -> #NAME?
D47: Function name | E47: {=Common_InputFunctions.Utility_DisplayFunctionName(E60)} -> =MMS_Feedlot_AtmosphericDeposition_Equations.VEERG_4_1_1_5__1_TotalAnnualAtmosphericDepositionEmissions
D50: Variable | E50: {=MMS_Feedlot_AtmosphericDeposition_Equations.VEERG_4_1_1_5__1_TotalAnnualAtmosphericDepositionEmissions_Variable()} -> #NAME?
...

Sheet 4.1.1.9 Manure applied to soils
A1: #VALUE! | C1: 4.1.1.9 Manure applied to soils
A3: =HYPERLINK("#'Home'!A1", "Home") -> Home | D3: Method 1 | L3: Method 2
A4: =HYPERLINK("#'Results'!A1", "Results") -> Results
D5: {=MMS_Feedlot_ManureAppliedToSoils_Equations.VEERG_4_1_1_9__1_MassOfNitrogenAppliedToSoilsScope1_Title()} -> #NAME?
A6: INPUTS | D6: {=MMS_Feedlot_ManureAppliedToSoils_Equations.VEERG_4_1_1_9__1_MassOfNitrogenAppliedToSoilsScope1_Source()} -> #NAME?
A7: =HYPERLINK("#'Input - Site'!A1", "Site") -> Site | D7: Function name | E7: {=Common_InputFunctions.Utility_DisplayFunctionName(E52)} -> =MMS_Feedlot_ManureAppliedToSoils_Equations.VEERG_4_1_1_9__1_MassOfNitrogenAppliedToSoilsScope1
A8: =HYPERLINK("#'Input - Feedlot'!A1", "Feedlot") -> Feedlot
A10: CALCULATIONS
A11: =HYPERLINK("#'4.1.1.1-2 Methane'!A1", "4.1.1.1-2 Methane") -> 4.1.1.1-2 Methane | D11: Variable | E11: {=MMS_Feedlot_ManureAppliedToSoils_Equations.VEERG_4_1_1_9__1_MassOfNitrogenAppliedToSoilsScope1_Variable()} -> #NAME?
A12: =HYPERLINK("#'4.1.1.3-4 Direct N20'!A1", "4.1.1.3-4 Direct N2O") -> 4.1.1.3-4 Direct N2O | D12: Unit | E12: {=MMS_Feedlot_ManureAppliedToSoils_Equations.VEERG_4_1_1_9__1_MassOfNitrogenAppliedToSoilsScope1_Unit()} -> #NAME?
A13: =HYPERLINK("#'4.1.1.5-6 Atmos Deposition'!A1", "4.1.1.5-6 Atmospheric deposition") -> 4.1.1.5-6 Atmospheric deposition
A14: =HYPERLINK("#'4.1.1.9 Manure applied to soils'!A1", "4.1.1.9 Manure applied to soils") -> 4.1.1.9 Manure applied to soils | D14: {=MMS_Feedlot_ManureAppliedToSoils_Equations.VEERG_4_1_1_9__1_MassOfNitrogenAppliedToSoilsScope1_Arguments()} -> #NAME? | H14: ="See " & $D$19 -> See M1_Table_MN_j_m_T-2-3
H15: ="See " & $D$26 -> See Table_EF_j_m_T-2-3
A16: APPENDICES | H16: ="See " & $D$34 -> See Table_FracGASM_m_T-2-3
A17: =HYPERLINK("#'Constants - Feedlot'!A1", "Constants - Feedlot") -> Constants - Feedlot | H17: ="See " & $D$42 -> See Table_PF
A18: =HYPERLINK("#'Constants - Livestock'!A1", "Constants - Livestock") -> Constants - Livestock
A19: =HYPERLINK("#'Constants - Common'!A1", "Constants - Common") -> Constants - Common | D19: M1_Table_MN_j_m_T-2-3 | L19: M2_Table_MN_j_m_T-2-3
A20: =HYPERLINK("#'Acknowledgements'!A1", "Acknowledgements") -> Acknowledgements | D20: Mass on N in stage 2 and 3 MMS (Method 1) | L20: Mass on N in stage 2 and 3 MMS (Method 2)
D21: MMS | E21: Domestic | F21: Mid-fed | G21: Long-fed | L21: MMS | M21: Domestic | N21: Mid-fed | O21: Long-fed
D22: ='Input - Dairy'!$D$101 -> Anaerobic lagoon | E22: ='4.3.1.3-4 Direct N20'!$E$173 -> 0 | F22: ='4.3.1.3-4 Direct N20'!$F$173 -> 0 | G22: ='4.3.1.3-4 Direct N20'!$G$173 -> 0 | H22: kg N | L22: ='Input - Dairy'!$D$101 -> Anaerobic lagoon | M22: ='4.3.1.3-4 Direct N20'!$O$173 -> 0 | N22: ='4.3.1.3-4 Direct N20'!$P$173 -> 0 | O22: ='4.3.1.3-4 Direct N20'!$Q$173 -> 0 | P22: kg N
D23: ='Input - Dairy'!$D$102 -> Were solids separated from Anaerobic lagoon? | E23: ='4.3.1.3-4 Direct N20'!$E$174 -> 0 | F23: ='4.3.1.3-4 Direct N20'!$F$174 -> 0 | G23: ='4.3.1.3-4 Direct N20'!$G$174 -> 0 | H23: kg N | L23: ='Input - Dairy'!$D$102 -> Were solids separated from Anaerobic lagoon? | M23: ='4.3.1.3-4 Direct N20'!$O$174 -> 0 | N23: ='4.3.1.3-4 Direct N20'!$P$174 -> 0 | O23: ='4.3.1.3-4 Direct N20'!$Q$174 -> 0 | P23: kg N
D24: ='Input - Dairy'!$D$107 -> Were solids separated from Sump and dispersal system? | E24: ='4.3.1.3-4 Direct N20'!$E$130 -> kg N/head/day | F24: ='4.3.1.3-4 Direct N20'!$F$130 -> 0 | G24: ='4.3.1.3-4 Direct N20'!$G$130 -> 0 | H24: kg N | L24: ='Input - Dairy'!$D$107 -> Were solids separated from Sump and dispersal system? | M24: ='4.3.1.3-4 Direct N20'!$O$129 -> 0 | N24: ='4.3.1.3-4 Direct N20'!$P$129 -> 0 | O24: ='4.3.1.3-4 Direct N20'!$Q$129 -> 0 | P24: kg N
D26: Table_EF_j_m_T-2-3
D27: EFs for MMS
D28: MMS | E28: EFjm
D29: ='Input - Dairy'!$D$95 -> Total manure sent to MMS (Must equal 100%) (Method 2) | E29: =_xlfn.XLOOKUP(D29,#REF!,#REF!) -> #REF! | F29: kg N2O/kg N
D30: ='Input - Dairy'!$D$101 -> Anaerobic lagoon | E30: =_xlfn.XLOOKUP($D$30,#REF!,#REF!) -> #REF! | F30: kg N2O/kg N
D31: ='Input - Dairy'!$D$102 -> Were solids separated from Anaerobic lagoon? | E31: =_xlfn.XLOOKUP($D$31,#REF!,#REF!) -> #REF! | F31: kg N2O/kg N
D32: ='Input - Dairy'!$D$107 -> Were solids separated from Sump and dispersal system? | E32: =_xlfn.XLOOKUP($D$32,#REF!,#REF!) -> #REF! | F32: kg N2O/kg N
D34: Table_FracGASM_m_T-2-3
D35: Fraction of N volatilised in each MMS
D36: MMS | E36: EFjm
D37: ='Input - Dairy'!$D$95 -> Total manure sent to MMS (Must equal 100%) (Method 2) | E37: =_xlfn.XLOOKUP(D37,#REF!,#REF!) -> #REF! | F37: (kg NH3-N + NOx-N)/kg N
D38: ='Input - Dairy'!$D$101 -> Anaerobic lagoon | E38: =_xlfn.XLOOKUP(D38,#REF!,#REF!) -> #REF! | F38: (kg NH3-N + NOx-N)/kg N
D39: ='Input - Dairy'!$D$102 -> Were solids separated from Anaerobic lagoon? | E39: =_xlfn.XLOOKUP(D39,#REF!,#REF!) -> #REF! | F39: (kg NH3-N + NOx-N)/kg N
D40: ='Input - Dairy'!$D$107 -> Were solids separated from Sump and dispersal system? | E40: =_xlfn.XLOOKUP(D40,#REF!,#REF!) -> #REF! | F40: (kg NH3-N + NOx-N)/kg N
D42: Table_PF
D43: Fraction of manure applied to soil from MMS
D44: MMS | E44: Domestic | F44: Mid-fed | G44: Long-fed
D45: ='Input - Dairy'!$D$101 -> Anaerobic lagoon | E45: ='Input - Dairy'!E139 -> 0.5 | F45: ='Input - Dairy'!F139 -> 0.5 | G45: ='Input - Dairy'!G139 -> 0.5 | H45: Fraction
...

Sheet Constants - Dairy
A1: #VALUE! | C1: Source Data - Feedlot
A3: =HYPERLINK("#'Home'!A1", "Home") -> Home
A4: =HYPERLINK("#'Results'!A1", "Results") -> Results
D5: Dairy manure management systems | G5: Dairy crop or pasture production systems | J5: Irrigation methods
A6: INPUTS
A7: =HYPERLINK("#'Input - Site'!A1", "Site") -> Site | D7: MMS | E7: Symbol and MMS | G7: Production system | J7: Irrigation method
A8: =HYPERLINK("#'Input - Feedlot'!A1", "Feedlot") -> Feedlot | D8: ='Constants - Livestock'!$E$10 -> Anaerobic lagoon | E8: ='Constants - Livestock'!$F$10 -> Anaerobic lagoon (m=1) | G8: ='Constants - Common'!$F$176 -> Pasture | J8: Not irrigated
D9: ='Constants - Livestock'!$E$13 -> Sump and dispersal system | E9: ='Constants - Livestock'!$F$13 -> Sump and dispersal system (m=3a) | G9: ='Constants - Common'!$F$177 -> Crop | J9: Drip irrigation
A10: CALCULATIONS | D10: ='Constants - Livestock'!$E$14 -> Drains to paddock | E10: ='Constants - Livestock'!$F$14 -> Drains to paddock (m=3b) | J10: Sprinkler irrigation
A11: =HYPERLINK("#'4.1.1.1-2 Methane'!A1", "4.1.1.1-2 Methane") -> 4.1.1.1-2 Methane | D11: ='Constants - Livestock'!$E$15 -> Solid storage | E11: ='Constants - Livestock'!$F$15 -> Solid storage (m=4) | J11: Surface irrigation
A12: =HYPERLINK("#'4.1.1.3-4 Direct N20'!A1", "4.1.1.3-4 Direct N2O") -> 4.1.1.3-4 Direct N2O | J12: Other irrigation
A13: =HYPERLINK("#'4.1.1.5-6 Atmos Deposition'!A1", "4.1.1.5-6 Atmospheric deposition") -> 4.1.1.5-6 Atmospheric deposition
A14: =HYPERLINK("#'4.1.1.9 Manure applied to soils'!A1", "4.1.1.9 Manure applied to soils") -> 4.1.1.9 Manure applied to soils
A16: APPENDICES | D16: {=SourceData_Dairy.SourceData_Dairy_LiveweightCowsAndHeifers_Title()} -> Table A.1.3.1: Dairy cattle - Liveweight (kg) - Cows and Heifers (Wj)
A17: =HYPERLINK("#'Constants - Feedlot'!A1", "Constants - Feedlot") -> Constants - Feedlot | D17: {=SourceData_Dairy.SourceData_Dairy_LiveweightCowsAndHeifers_Source()} -> VEERG 2026: Table A.1.3.1
A18: =HYPERLINK("#'Constants - Livestock'!A1", "Constants - Livestock") -> Constants - Livestock | D18: {=SourceData_Dairy.SourceData_Dairy_LiveweightCowsAndHeifers_Variable()} -> Wj
A19: =HYPERLINK("#'Constants - Common'!A1", "Constants - Common") -> Constants - Common | D19: {=SourceData_Dairy.SourceData_Dairy_LiveweightCowsAndHeifers_Unit()} -> kg
A20: =HYPERLINK("#'Acknowledgements'!A1", "Acknowledgements") -> Acknowledgements | D20: {=SourceData_Dairy.SourceData_Dairy_LiveweightCowsAndHeifers_Variation()} -> VARIATION OF SOURCE: Excluded 'Reference', as the value is consistently 'Dairy Australia [1]' and is not used in calculation.
D21: Breed | E21: Milking cows | F21: Heifers > 1 | G21: Heifers < 1 (weaned)
D22: {=Common_InputFunctions.Utility_DisplayArrayInTable(SourceData_Dairy.SourceData_Dairy_LiveweightCowsAndHeifers_Data(), Table_SourceData_Dairy_WjCowsHeifers[[#Headers],[Breed]], 0)} -> Medium Friesian | E22: {=Common_InputFunctions.Utility_DisplayArrayInTable(SourceData_Dairy.SourceData_Dairy_LiveweightCowsAndHeifers_Data(), Table_SourceData_Dairy_WjCowsHeifers[[#Headers],[Breed]], 0)} -> 550 | F22: {=Common_InputFunctions.Utility_DisplayArrayInTable(SourceData_Dairy.SourceData_Dairy_LiveweightCowsAndHeifers_Data(), Table_SourceData_Dairy_WjCowsHeifers[[#Headers],[Breed]], 0)} -> 380 | G22: {=Common_InputFunctions.Utility_DisplayArrayInTable(SourceData_Dairy.SourceData_Dairy_LiveweightCowsAndHeifers_Data(), Table_SourceData_Dairy_WjCowsHeifers[[#Headers],[Breed]], 0)} -> 155
D23: {=Common_InputFunctions.Utility_DisplayArrayInTable(SourceData_Dairy.SourceData_Dairy_LiveweightCowsAndHeifers_Data(), Table_SourceData_Dairy_WjCowsHeifers[[#Headers],[Breed]], 0)} -> Large Friesian | E23: {=Common_InputFunctions.Utility_DisplayArrayInTable(SourceData_Dairy.SourceData_Dairy_LiveweightCowsAndHeifers_Data(), Table_SourceData_Dairy_WjCowsHeifers[[#Headers],[Breed]], 0)} -> 600 | F23: {=Common_InputFunctions.Utility_DisplayArrayInTable(SourceData_Dairy.SourceData_Dairy_LiveweightCowsAndHeifers_Data(), Table_SourceData_Dairy_WjCowsHeifers[[#Headers],[Breed]], 0)} -> 415 | G23: {=Common_InputFunctions.Utility_DisplayArrayInTable(SourceData_Dairy.SourceData_Dairy_LiveweightCowsAndHeifers_Data(), Table_SourceData_Dairy_WjCowsHeifers[[#Headers],[Breed]], 0)} -> 170
