Workbook
Name Common_Equations.Common_ConvertCH4ToCO2e: _xlfn.LAMBDA(_xlpm.E_CH4,_xlpm.GWP_CH4, _xlpm.E_CH4 * _xlpm.GWP_CH4)
Name Common_Equations.Common_ConvertCH4ToCO2e_Arguments: _xlfn.LAMBDA(_xlfn.MAKEARRAY(2, 2, _xlfn.LAMBDA(_xlpm.r,_xlpm.c, INDEX({"ECH4","Methane emissions (t CH4)";"GWPCH4","Global warming potential for methane (t CO2-e / t CH4)"}, _xlpm.r, _xlpm.c))))
Name Common_Equations.Common_ConvertCH4ToCO2e_LatexEquation: _xlfn.LAMBDA("CO2_e = E_{CH4} \times GWP_{CH4}")
Name Common_Equations.Common_ConvertCH4ToCO2e_NIRReference: _xlfn.LAMBDA("")
Name Common_Equations.Common_ConvertCH4ToCO2e_Title: _xlfn.LAMBDA("Convert methane emissions to carbon dioxide equivalent emissions")
Name Common_Equations.Common_ConvertCH4ToCO2e_Unit: _xlfn.LAMBDA("t CO2e")
Name Common_Equations.Common_ConvertCH4ToCO2e_Variable: _xlfn.LAMBDA("ECH4 CO2e")
Name Common_Equations.Common_ConvertN2OToCO2e: _xlfn.LAMBDA(_xlpm.E_N2O,_xlpm.GWP_N2O, _xlpm.E_N2O * _xlpm.GWP_N2O)
Name Common_Equations.Common_ConvertN2OToCO2e_LatexEquation: _xlfn.LAMBDA("CO2_e = E_{N2O} \times GWP_{N2O}")
Name Common_Equations.Common_ConvertN2OToCO2e_NIRReference: _xlfn.LAMBDA("")
Name Common_Equations.Common_ConvertN2OToCO2e_Title: _xlfn.LAMBDA("Convert nitrous oxide emissions to carbon dioxide equivalent emissions")
Name Common_Equations.Common_ConvertN2OToCO2e_Unit: _xlfn.LAMBDA("t CO2e")
Name Common_Equations.Common_ConvertN2OToCO2e_Variable: _xlfn.LAMBDA("EN2O CO2e")
Name Common_InputFunctions.Utility_ConvertStateCommonNameToAbbreviation: _xlfn.LAMBDA(_xlpm.StateCommonName,_xlpm.StateCommonNameArray,_xlpm.StateAbbreviationArray, _xlfn.XLOOKUP(_xlpm.StateCommonName, _xlpm.StateCommonNameArray, _xlpm.StateAbbreviationArray, ""))
Name Common_InputFunctions.Utility_DisplayArguments_1_2: _xlfn.LAMBDA(_xlpm.ArgumentsArray, _xlfn.CHOOSECOLS(_xlpm.ArgumentsArray, 1, 2))
Name Common_InputFunctions.Utility_DisplayArguments_3_4: _xlfn.LAMBDA(_xlpm.ArgumentsArray, _xlfn.CHOOSECOLS(_xlpm.ArgumentsArray, 3, 4))
Name Common_InputFunctions.Utility_DisplayFunctionName: _xlfn.LAMBDA(_xlpm.Function, _xlfn.TEXTBEFORE(_xlfn.FORMULATEXT(_xlpm.Function), "("))
Name Common_InputFunctions.Utility_GetArrayTableColumnStartNumber: _xlfn.LAMBDA(_xlpm.TableHeaderCell, COLUMN(_xlpm.TableHeaderCell))
Name Common_InputFunctions.Utility_GetArrayTableRowStartNumber: _xlfn.LAMBDA(_xlpm.TableheaderCell,_xlpm.RowsBetweenHeaderandArray, ROW(_xlpm.TableheaderCell) + _xlpm.RowsBetweenHeaderandArray - 1)
Name Common_InputFunctions.Utility_LookupValueInTable: _xlfn.LAMBDA(_xlpm.LookupValue,_xlpm.LookupArray,_xlpm.ReturnArray, _xlfn.XLOOKUP(_xlpm.LookupValue, _xlpm.LookupArray, _xlpm.ReturnArray, ""))
Name Common_InputFunctions.Utility_SourceHyperlink: _xlfn.LAMBDA(_xlpm.TargetCell, _xlfn.LET(_xlpm.sh, _xlfn.TEXTAFTER(CELL("filename", _xlpm.TargetCell), "]"), _xlpm.addr, CELL("address", _xlpm.TargetCell), "#'" & _xlpm.sh & "'!" & _xlpm.addr))
Name Common_SourceData.Common_SourceData_AustralianStatesTerritories_Source: _xlfn.LAMBDA("")
Name Common_SourceData.Common_SourceData_AustralianStatesTerritories_Title: _xlfn.LAMBDA("Australian states and territories")
Name Common_SourceData.Common_SourceData_AustralianStatesTerritories_Unit: _xlfn.LAMBDA("")
Name Common_SourceData.Common_SourceData_AustralianStatesTerritories_Variable: _xlfn.LAMBDA("")
Name Common_SourceData.Common_SourceData_ClimateZones_Source: _xlfn.LAMBDA("VEERG 2026: Table 1.3: Climate and Rainfall zone classifications and definitions")
Name Common_SourceData.Common_SourceData_ClimateZones_Title: _xlfn.LAMBDA("VEERG Australian climate zones")
Name Common_SourceData.Common_SourceData_ClimateZones_Unit: _xlfn.LAMBDA("")
Name Common_SourceData.Common_SourceData_ClimateZones_Variable: _xlfn.LAMBDA("")
Name Common_SourceData.Common_SourceData_ConvertGasElementalToMolecular_Source: _xlfn.LAMBDA("XXXXXXX")
Name Common_SourceData.Common_SourceData_ConvertGasElementalToMolecular_Title: _xlfn.LAMBDA("Factor to convert elemental mass of gas to molecular mass")
Name Common_SourceData.Common_SourceData_ConvertGasElementalToMolecular_Unit: _xlfn.LAMBDA("factor")
Name Common_SourceData.Common_SourceData_ConvertGasElementalToMolecular_Variable: _xlfn.LAMBDA("Cg")
Name Common_SourceData.Common_SourceData_ConvertN2oElementalToMolecularCg_Data: _xlfn.LAMBDA(44 / 28)
Name Common_SourceData.Common_SourceData_ConvertN2oElementalToMolecularCg_Source: _xlfn.LAMBDA("National Inventory Report 2023 Volume 1")
Name Common_SourceData.Common_SourceData_ConvertN2oElementalToMolecularCg_Title: _xlfn.LAMBDA("Factor to convert elemental mass of N2O to molecular mass")
Name Common_SourceData.Common_SourceData_ConvertN2oElementalToMolecularCg_Unit: _xlfn.LAMBDA("factor")
Name Common_SourceData.Common_SourceData_ConvertN2oElementalToMolecularCg_Variable: _xlfn.LAMBDA("CgN2O")
Name Common_SourceData.Common_SourceData_DataScores_Scope3_Source: _xlfn.LAMBDA("VEERG 2026: XXXXXXXX")
Name Common_SourceData.Common_SourceData_DataScores_Scope3_Title: _xlfn.LAMBDA("Australian data scores for scope 3")
Name Common_SourceData.Common_SourceData_DataScores_Scope3_Unit: _xlfn.LAMBDA("")
Name Common_SourceData.Common_SourceData_DataScores_Scope3_Variable: _xlfn.LAMBDA("")
Name Common_SourceData.Common_SourceData_DataScores_Scope3_Variation: _xlfn.LAMBDA("")
Name Common_SourceData.Common_SourceData_DensityOfMethane_Data: _xlfn.LAMBDA(0.6784)
Name Common_SourceData.Common_SourceData_DensityOfMethane_Source: _xlfn.LAMBDA("National Inventory Report 2023 Volume 1: Equations 3.B.1a_2, 3.B.1c_2, 3.B.3_1, 3.B.4g_2")
Name Common_SourceData.Common_SourceData_DensityOfMethane_Title: _xlfn.LAMBDA("p = density of methane")
Name Common_SourceData.Common_SourceData_DensityOfMethane_Unit: _xlfn.LAMBDA("kg/m3")
Name Common_SourceData.Common_SourceData_EFleach_Data: _xlfn.LAMBDA(_xlfn.MAKEARRAY(1, 2, _xlfn.LAMBDA(_xlpm.r,_xlpm.c, INDEX({"EFleach",0.011}, _xlpm.r, _xlpm.c))))
Name Common_SourceData.Common_SourceData_EFleach_NIRReference: _xlfn.LAMBDA("National Inventory Report Volume 1: Equation 3.D.B_10")
Name Common_SourceData.Common_SourceData_EFleach_Source: _xlfn.LAMBDA("VEERG 2026:5.5.2.3 Constant Parameters")
Name Common_SourceData.Common_SourceData_EFleach_Title: _xlfn.LAMBDA("Emission factor for nitrogen leaching and runoff")
Name Common_SourceData.Common_SourceData_EFleach_Unit: _xlfn.LAMBDA("(kg N2O-N / kg N")
Name Common_SourceData.Common_SourceData_EFleach_Variation: _xlfn.LAMBDA((""))
Name Common_SourceData.Common_SourceData_EFN2O_NIRReference: _xlfn.LAMBDA("")
Name Common_SourceData.Common_SourceData_EFN2O_Source: _xlfn.LAMBDA("VEERG 2026: Table A.2.2.1")
Name Common_SourceData.Common_SourceData_EFN2O_Title: _xlfn.LAMBDA("Nitrous oxide emission factors for inorganic fertiliser application")
Name Common_SourceData.Common_SourceData_EFN2O_Unit: _xlfn.LAMBDA("(kg N2O-N / kg N")
Name Common_SourceData.Common_SourceData_EFPastureRangeAndPaddock_Data: _xlfn.LAMBDA(_xlfn.MAKEARRAY(3, 2, _xlfn.LAMBDA(_xlpm.r,_xlpm.c, INDEX({"Climate zone","EFPRP";"Wet climate zone",0.006;"Dry climate zone",0.002}, _xlpm.r, _xlpm.c))))
Name Common_SourceData.Common_SourceData_EFPastureRangeAndPaddock_NIRReference: _xlfn.LAMBDA("")
Name Common_SourceData.Common_SourceData_EFPastureRangeAndPaddock_Source: _xlfn.LAMBDA("VEERG 2026: Table A.2.2.2")

Sheet Home
A1: Home

Sheet Results
A1: #VALUE! | C1: 4.2 Manure management: Pasture Beef: Results
A3: =HYPERLINK("#'Home'!A1", "Home") -> Home
A4: =HYPERLINK("#'Results'!A1", "Results") -> Results | D4: Emissions breakdown
A6: INPUTS | D6: Scope 1 source | E6: GHG emissions method 1 | F6: GHG emissions method 2 | G6: GHG Unit | H6: CO2-e emissions method 1 | I6: CO2-e emissions method 2 | J6: CO2-e unit
A7: =HYPERLINK("#'Input - Site'!A1", "Site") -> Site | D7: 4.2.1.1-2 Manure methane | E7: ='4.2.1.1-2 Methane'!$E$244 -> 2.1890553 | F7: ='4.2.1.1-2 Methane'!U276 -> 2.1930247 | G7: t CH4 | H7: ='4.2.1.1-2 Methane'!$E$249 -> 61.293548 | I7: ='4.2.1.1-2 Methane'!$U$281 -> 61.404693 | J7: t CO2e
A8: =HYPERLINK("#'Input - Pasture Beef'!A1", "Pasture Beef") -> Pasture Beef | D8: 4.2.1.3-4 Soil direct N2O | E8: ='4.2.1.3-4 Soil direct N20'!$E$229 -> 0.18675564 | F8: ='4.2.1.3-4 Soil direct N20'!$U$263 -> 0.18838337 | G8: t N2O | H8: ='4.2.1.3-4 Soil direct N20'!$E$234 -> 49.490246 | I8: ='4.2.1.3-4 Soil direct N20'!$U$268 -> 49.921593 | J8: t CO2e
D9: 4.2.1.5-6 Soil atmospheric deposition | E9: ='4.2.1.5-6 Soil Atmos Dep'!$E$35 -> 0.035296817 | F9: ='4.2.1.5-6 Soil Atmos Dep'!$M$35 -> 0.035604457 | G9: ='4.2.1.5-6 Soil Atmos Dep'!$F$35 -> t N2O | H9: ='4.2.1.5-6 Soil Atmos Dep'!$E$40 -> 9.3536565 | I9: ='4.2.1.5-6 Soil Atmos Dep'!$M$40 -> 9.4351811 | J9: t CO2e
A10: CALCULATIONS | D10: 4.2.1.7-8 Soil leaching and runoff | E10: ='4.2.1.7-8 Soil leach runoff'!$E$36 -> 0 | F10: ='4.2.1.7-8 Soil leach runoff'!$L$36 -> 0 | G10: ='4.2.1.7-8 Soil leach runoff'!$F$36 -> t N2O | H10: ='4.2.1.7-8 Soil leach runoff'!$E$41 -> 0 | I10: ='4.2.1.7-8 Soil leach runoff'!$L$41 -> 0 | J10: t CO2e
A11: =HYPERLINK("#'4.2.1.1-2 Methane'!A1", "4.2.1.1-2 Methane") -> 4.2.1.1-2 Methane | D11: Total | H11: =SUM(H7:H10) -> 120.13745 | I11: =SUM(I7:I10) -> 120.76147 | J11: t CO2e
A12: =HYPERLINK("#'4.2.1.3-4 Soil direct N2O'!A1", "4.2.1.3-4 Soil direct N2O") -> 4.2.1.3-4 Soil direct N2O
A13: =HYPERLINK("#'4.2.1.5-6 Soil Atmos Dep'!A1", "4.2.1.5-6 Soil atm. deposition") -> 4.2.1.5-6 Soil atm. deposition
A14: =HYPERLINK("#'4.2.1.7-8 Soil leach runoff'!A1", "4.2.1.7-8 Soil leach & runoff") -> 4.2.1.7-8 Soil leach & runoff
A16: APPENDICES
A17: =HYPERLINK("#'Constants - Pasture Beef'!A1", "Constants - Pasture Beef") -> Constants - Pasture Beef
A18: =HYPERLINK("#'Constants - Livestock'!A1", "Constants - Livestock") -> Constants - Livestock
A19: =HYPERLINK("#'Constants - Common'!A1", "Constants - Common") -> Constants - Common
A20: =HYPERLINK("#'Acknowledgements'!A1", "Acknowledgements") -> Acknowledgements

Sheet Input - Site
A1: #VALUE! | C1: Input - Site
A3: =HYPERLINK("#'Home'!A1", "Home") -> Home
A4: =HYPERLINK("#'Results'!A1", "Results") -> Results
D5: Your business
A6: INPUTS
A7: =HYPERLINK("#'Input - Site'!A1", "Site") -> Site | D7: Farm name | E7: Test Farms
A8: =HYPERLINK("#'Input - Pasture Beef'!A1", "Pasture Beef") -> Pasture Beef | D8: Reporting entity name | E8: Test Farms Pty Ltd
A10: CALCULATIONS | D10: 💡An 'Emissions accounting period' is a 12 month period where the business can report on the emissions, and is typically the same as the business' financial accounting period.
A11: =HYPERLINK("#'4.2.1.1-2 Methane'!A1", "4.2.1.1-2 Methane") -> 4.2.1.1-2 Methane
A12: =HYPERLINK("#'4.2.1.3-4 Soil direct N2O'!A1", "4.2.1.3-4 Soil direct N2O") -> 4.2.1.3-4 Soil direct N2O | D12: Emissions calculation period start date | E12: 45292 | F12: ← DD/MM/YYYY or DD Month YYYY
A13: =HYPERLINK("#'4.2.1.5-6 Soil Atmos Dep'!A1", "4.2.1.5-6 Soil atm. deposition") -> 4.2.1.5-6 Soil atm. deposition | D13: Emissions calculation period end date | E13: =DATE(YEAR(E12)+1,MONTH(E12),DAY(E12))-1 -> 45657 | F13: ← Automatically calculated, 12 months after start date
A14: =HYPERLINK("#'4.2.1.7-8 Soil leach runoff'!A1", "4.2.1.7-8 Soil leach & runoff") -> 4.2.1.7-8 Soil leach & runoff
A16: APPENDICES | D16: Location and climate
A17: =HYPERLINK("#'Constants - Pasture Beef'!A1", "Constants - Pasture Beef") -> Constants - Pasture Beef
A18: =HYPERLINK("#'Constants - Livestock'!A1", "Constants - Livestock") -> Constants - Livestock | D18: Location information is used to reference some region and climate-specific emission factors
A19: =HYPERLINK("#'Constants - Common'!A1", "Constants - Common") -> Constants - Common | D19: Tip: Use the web-based GAF Location Helper tool to easily get region and climate information. You will need an internet connection to use the GAF Location Helper.
A20: =HYPERLINK("#'Acknowledgements'!A1", "Acknowledgements") -> Acknowledgements
D21: State | E21: Western Australia | F21: ← Please select
D22: Region (ABS Statistical area level 4) if state is WA | E22: Western Australia - Outback (South) | F22: ← Please select
D23: Leaching zone | E23: NO - Not in leaching zone | F23: ← Please select
D24: Elevation | E24: 307.7 | F24: Meters
D25: Average temperature for reporting period | E25: 18 | F25: Degrees celsius
D26: Total rainfall for reporting period | E26: 601 | F26: Millimetres
D27: Potential evapotranspiration for reporting period | E27: 1326 | F27: Millimetres
D28: Number of frost days for reporting period | E28: 7 | F28: Days
D29: MAP:PET ratio | E29: =E26/E27 -> 0.45324284
D30: Rainfall zone | E30: =Common_InputFunctions.Utility_LookupItemFromMinMax(E26,Table_SourceData_RainfallZones[Min rainfall],Table_SourceData_RainfallZones[Max rainfall],Table_SourceData_RainfallZones[Rainfall Zone]) -> High rainfall
D31: Climate zone | E31: =Common_InputFunctions.Utility_GetClimateZone(E25,E26,E28,E24,E29,Table_SourceData_ClimateZones[Min temp],Table_SourceData_ClimateZones[Max temp],Table_SourceData_ClimateZones[Min rainfall],Table_SourceData_ClimateZones[Max rainfall],Table_SourceData_ClimateZones[Min frost days],Table_SourceData_ClimateZones[Max frost days],Table_SourceData_ClimateZones[Min elevation],Table_SourceData_ClimateZones[Max elevation],Table_SourceData_ClimateZones[Min MAP:PET],Table_SourceData_ClimateZones[Max MAP:PET],Table_SourceData_ClimateZones[Climate zone]) -> Warm temperate dry
D32: Wet or dry climate zone | E32: =Common_InputFunctions.Utility_LookupValueInTable($E$31,Table_SourceData_WetDryZones[Climate zone],Table_SourceData_WetDryZones[Wet or Dry Zone]) -> Dry climate zone
D33: Temperature zone | E33: =Common_InputFunctions.Utility_LookupItemFromMinMax(E25,Table_SourceData_TemperatureZones[Min MAT],Table_SourceData_TemperatureZones[Max MAT],Table_SourceData_TemperatureZones[Temperature Zone]) -> Temperate

Sheet Input - Pasture Beef
A1: #VALUE! | C1: Input -Pasture Beef
A3: =HYPERLINK("#'Home'!A1", "Home") -> Home
A4: =HYPERLINK("#'Results'!A1", "Results") -> Results
D5: Herd movement
A6: INPUTS
A7: =HYPERLINK("#'Input - Site'!A1", "Site") -> Site | D7: State | E7: ='Input - Site'!$E$21 -> Western Australia
A8: =HYPERLINK("#'Input - Pasture Beef'!A1", "Pasture Beef") -> Pasture Beef | D8: Livestock production region | E8: South West | F8: ← Please select
D9: Cattle breed | E9: Hereford or Shorthorn breeds | F9: ← Please select
A10: CALCULATIONS
A11: =HYPERLINK("#'4.2.1.1-2 Methane'!A1", "4.2.1.1-2 Methane") -> 4.2.1.1-2 Methane
A12: =HYPERLINK("#'4.2.1.3-4 Soil direct N2O'!A1", "4.2.1.3-4 Soil direct N2O") -> 4.2.1.3-4 Soil direct N2O | D12: NOTE: VEERG states that under method 2, time periods may be seasons, months or a custom time period. In this example, method 2 time periods are months.
A13: =HYPERLINK("#'4.2.1.5-6 Soil Atmos Dep'!A1", "4.2.1.5-6 Soil atm. deposition") -> 4.2.1.5-6 Soil atm. deposition
A14: =HYPERLINK("#'4.2.1.7-8 Soil leach runoff'!A1", "4.2.1.7-8 Soil leach & runoff") -> 4.2.1.7-8 Soil leach & runoff | D14: Duration on farm
D15: Method 1 default values (do not edit) | E15: Bulls < 1 year | F15: Bulls > 1 year | G15: Cows < 1 year | H15: Cows 1-2 years | I15: Cows 2-3 years | J15: Cows > 3 years | K15: Steers < 1 year | L15: Steers 1-2 years | M15: Steers 2-3 years | N15: Steers >3 years
A16: APPENDICES | D16: Spring | E16: 91.25 | F16: 91.25 | G16: 91.25 | H16: 91.25 | I16: 91.25 | J16: 91.25 | K16: 91.25 | L16: 91.25 | M16: 91.25 | N16: 91.25 | O16: Days
A17: =HYPERLINK("#'Constants - Pasture Beef'!A1", "Constants - Pasture Beef") -> Constants - Pasture Beef | D17: Summer | E17: 91.25 | F17: 91.25 | G17: 91.25 | H17: 91.25 | I17: 91.25 | J17: 91.25 | K17: 91.25 | L17: 91.25 | M17: 91.25 | N17: 91.25 | O17: Days
A18: =HYPERLINK("#'Constants - Livestock'!A1", "Constants - Livestock") -> Constants - Livestock | D18: Autumn | E18: 91.25 | F18: 91.25 | G18: 91.25 | H18: 91.25 | I18: 91.25 | J18: 91.25 | K18: 91.25 | L18: 91.25 | M18: 91.25 | N18: 91.25 | O18: Days
A19: =HYPERLINK("#'Constants - Common'!A1", "Constants - Common") -> Constants - Common | D19: Winter | E19: 91.25 | F19: 91.25 | G19: 91.25 | H19: 91.25 | I19: 91.25 | J19: 91.25 | K19: 91.25 | L19: 91.25 | M19: 91.25 | N19: 91.25 | O19: Days
A20: =HYPERLINK("#'Acknowledgements'!A1", "Acknowledgements") -> Acknowledgements
D21: Method 2 custom values (edit if known) | E21: Bulls < 1 year | F21: Bulls > 1 year | G21: Cows < 1 year | H21: Cows 1-2 years | I21: Cows 2-3 years | J21: Cows > 3 years | K21: Steers < 1 year | L21: Steers 1-2 years | M21: Steers 2-3 years | N21: Steers >3 years
D22: =TEXT('Input - Site'!$E$12, "mmmm yyyy") -> January 2024 | E22: =DAY(EOMONTH($D22,0)) -> 31 | F22: =DAY(EOMONTH($D22,0)) -> 31 | G22: =DAY(EOMONTH($D22,0)) -> 31 | H22: =DAY(EOMONTH($D22,0)) -> 31 | I22: =DAY(EOMONTH($D22,0)) -> 31 | J22: =DAY(EOMONTH($D22,0)) -> 31 | K22: =DAY(EOMONTH($D22,0)) -> 31 | L22: =DAY(EOMONTH($D22,0)) -> 31 | ... N22: =DAY(EOMONTH($D22,0)) -> 31 | O22: Days
D23: =TEXT(EDATE('Input - Site'!$E$12,1), "mmmm yyyy") -> February 2024 | E23: =DAY(EOMONTH($D23,0)) -> 29 | F23: =DAY(EOMONTH($D23,0)) -> 29 | G23: =DAY(EOMONTH($D23,0)) -> 29 | H23: =DAY(EOMONTH($D23,0)) -> 29 | I23: =DAY(EOMONTH($D23,0)) -> 29 | J23: =DAY(EOMONTH($D23,0)) -> 29 | K23: =DAY(EOMONTH($D23,0)) -> 29 | L23: =DAY(EOMONTH($D23,0)) -> 29 | ... N23: =DAY(EOMONTH($D23,0)) -> 29 | O23: Days
D24: =TEXT(EDATE('Input - Site'!$E$12,2), "mmmm yyyy") -> March 2024 | E24: =DAY(EOMONTH($D24,0)) -> 31 | F24: =DAY(EOMONTH($D24,0)) -> 31 | G24: =DAY(EOMONTH($D24,0)) -> 31 | H24: =DAY(EOMONTH($D24,0)) -> 31 | I24: =DAY(EOMONTH($D24,0)) -> 31 | J24: =DAY(EOMONTH($D24,0)) -> 31 | K24: =DAY(EOMONTH($D24,0)) -> 31 | L24: =DAY(EOMONTH($D24,0)) -> 31 | ... N24: =DAY(EOMONTH($D24,0)) -> 31 | O24: Days
D25: =TEXT(EDATE('Input - Site'!$E$12,3), "mmmm yyyy") -> April 2024 | E25: =DAY(EOMONTH($D25,0)) -> 30 | F25: =DAY(EOMONTH($D25,0)) -> 30 | G25: =DAY(EOMONTH($D25,0)) -> 30 | H25: =DAY(EOMONTH($D25,0)) -> 30 | I25: =DAY(EOMONTH($D25,0)) -> 30 | J25: =DAY(EOMONTH($D25,0)) -> 30 | K25: =DAY(EOMONTH($D25,0)) -> 30 | L25: =DAY(EOMONTH($D25,0)) -> 30 | ... N25: =DAY(EOMONTH($D25,0)) -> 30 | O25: Days
D26: =TEXT(EDATE('Input - Site'!$E$12,4), "mmmm yyyy") -> May 2024 | E26: =DAY(EOMONTH($D26,0)) -> 31 | F26: =DAY(EOMONTH($D26,0)) -> 31 | G26: =DAY(EOMONTH($D26,0)) -> 31 | H26: =DAY(EOMONTH($D26,0)) -> 31 | I26: =DAY(EOMONTH($D26,0)) -> 31 | J26: =DAY(EOMONTH($D26,0)) -> 31 | K26: =DAY(EOMONTH($D26,0)) -> 31 | L26: =DAY(EOMONTH($D26,0)) -> 31 | ... N26: =DAY(EOMONTH($D26,0)) -> 31 | O26: Days
D27: =TEXT(EDATE('Input - Site'!$E$12,5), "mmmm yyyy") -> June 2024 | E27: =DAY(EOMONTH($D27,0)) -> 30 | F27: =DAY(EOMONTH($D27,0)) -> 30 | G27: =DAY(EOMONTH($D27,0)) -> 30 | H27: =DAY(EOMONTH($D27,0)) -> 30 | I27: =DAY(EOMONTH($D27,0)) -> 30 | J27: =DAY(EOMONTH($D27,0)) -> 30 | K27: =DAY(EOMONTH($D27,0)) -> 30 | L27: =DAY(EOMONTH($D27,0)) -> 30 | ... N27: =DAY(EOMONTH($D27,0)) -> 30 | O27: Days
D28: =TEXT(EDATE('Input - Site'!$E$12,6), "mmmm yyyy") -> July 2024 | E28: =DAY(EOMONTH($D28,0)) -> 31 | F28: =DAY(EOMONTH($D28,0)) -> 31 | G28: =DAY(EOMONTH($D28,0)) -> 31 | H28: =DAY(EOMONTH($D28,0)) -> 31 | I28: =DAY(EOMONTH($D28,0)) -> 31 | J28: =DAY(EOMONTH($D28,0)) -> 31 | K28: =DAY(EOMONTH($D28,0)) -> 31 | L28: =DAY(EOMONTH($D28,0)) -> 31 | ... N28: =DAY(EOMONTH($D28,0)) -> 31 | O28: Days
D29: =TEXT(EDATE('Input - Site'!$E$12,7), "mmmm yyyy") -> August 2024 | E29: =DAY(EOMONTH($D29,0)) -> 31 | F29: =DAY(EOMONTH($D29,0)) -> 31 | G29: =DAY(EOMONTH($D29,0)) -> 31 | H29: =DAY(EOMONTH($D29,0)) -> 31 | I29: =DAY(EOMONTH($D29,0)) -> 31 | J29: =DAY(EOMONTH($D29,0)) -> 31 | K29: =DAY(EOMONTH($D29,0)) -> 31 | L29: =DAY(EOMONTH($D29,0)) -> 31 | ... N29: =DAY(EOMONTH($D29,0)) -> 31 | O29: Days
D30: =TEXT(EDATE('Input - Site'!$E$12,8), "mmmm yyyy") -> September 2024 | E30: =DAY(EOMONTH($D30,0)) -> 30 | F30: =DAY(EOMONTH($D30,0)) -> 30 | G30: =DAY(EOMONTH($D30,0)) -> 30 | H30: =DAY(EOMONTH($D30,0)) -> 30 | I30: =DAY(EOMONTH($D30,0)) -> 30 | J30: =DAY(EOMONTH($D30,0)) -> 30 | K30: =DAY(EOMONTH($D30,0)) -> 30 | L30: =DAY(EOMONTH($D30,0)) -> 30 | ... N30: =DAY(EOMONTH($D30,0)) -> 30 | O30: Days
D31: =TEXT(EDATE('Input - Site'!$E$12,9), "mmmm yyyy") -> October 2024 | E31: =DAY(EOMONTH($D31,0)) -> 31 | F31: =DAY(EOMONTH($D31,0)) -> 31 | G31: =DAY(EOMONTH($D31,0)) -> 31 | H31: =DAY(EOMONTH($D31,0)) -> 31 | I31: =DAY(EOMONTH($D31,0)) -> 31 | J31: =DAY(EOMONTH($D31,0)) -> 31 | K31: =DAY(EOMONTH($D31,0)) -> 31 | L31: =DAY(EOMONTH($D31,0)) -> 31 | ... N31: =DAY(EOMONTH($D31,0)) -> 31 | O31: Days
D32: =TEXT(EDATE('Input - Site'!$E$12,10), "mmmm yyyy") -> November 2024 | E32: =DAY(EOMONTH($D32,0)) -> 30 | F32: =DAY(EOMONTH($D32,0)) -> 30 | G32: =DAY(EOMONTH($D32,0)) -> 30 | H32: =DAY(EOMONTH($D32,0)) -> 30 | I32: =DAY(EOMONTH($D32,0)) -> 30 | J32: =DAY(EOMONTH($D32,0)) -> 30 | K32: =DAY(EOMONTH($D32,0)) -> 30 | L32: =DAY(EOMONTH($D32,0)) -> 30 | ... N32: =DAY(EOMONTH($D32,0)) -> 30 | O32: Days
D33: =TEXT(EDATE('Input - Site'!$E$12,11), "mmmm yyyy") -> December 2024 | E33: =DAY(EOMONTH($D33,0)) -> 31 | F33: =DAY(EOMONTH($D33,0)) -> 31 | G33: =DAY(EOMONTH($D33,0)) -> 31 | H33: =DAY(EOMONTH($D33,0)) -> 31 | I33: =DAY(EOMONTH($D33,0)) -> 31 | J33: =DAY(EOMONTH($D33,0)) -> 31 | K33: =DAY(EOMONTH($D33,0)) -> 31 | L33: =DAY(EOMONTH($D33,0)) -> 31 | ... N33: =DAY(EOMONTH($D33,0)) -> 31 | O33: Days
D36: Head
D37: Method 1 values | E37: Bulls < 1 year | F37: Bulls > 1 year | G37: Cows < 1 year | H37: Cows 1-2 years | I37: Cows 2-3 years | J37: Cows > 3 years | K37: Steers < 1 year | L37: Steers 1-2 years | M37: Steers 2-3 years | N37: Steers >3 years
D38: Spring | E38: 100 | F38: 100 | G38: 100 | H38: 100 | I38: 100 | J38: 100 | K38: 100 | L38: 100 | M38: 100 | N38: 100 | O38: Head
D39: Summer | E39: 100 | F39: 100 | G39: 100 | H39: 100 | I39: 100 | J39: 100 | K39: 100 | L39: 100 | M39: 100 | N39: 100 | O39: Head
D40: Autumn | E40: 100 | F40: 100 | G40: 100 | H40: 100 | I40: 100 | J40: 100 | K40: 100 | L40: 100 | M40: 100 | N40: 100 | O40: Head
D41: Winter | E41: 100 | F41: 100 | G41: 100 | H41: 100 | I41: 100 | J41: 100 | K41: 100 | L41: 100 | M41: 100 | N41: 100 | O41: Head
D43: Method 2 values | E43: Bulls < 1 year | F43: Bulls > 1 year | G43: Cows < 1 year | H43: Cows 1-2 years | I43: Cows 2-3 years | J43: Cows > 3 years | K43: Steers < 1 year | L43: Steers 1-2 years | M43: Steers 2-3 years | N43: Steers >3 years
D44: =TEXT('Input - Site'!$E$12, "mmmm yyyy") -> January 2024 | E44: 100 | F44: 100 | G44: 100 | H44: 100 | I44: 100 | J44: 100 | K44: 100 | L44: 100 | M44: 100 | N44: 100 | O44: Head
...

Sheet 4.2.1.1-2 Methane
A1: #VALUE! | C1: 4.2.1.1-2 Manure Methane
A3: =HYPERLINK("#'Home'!A1", "Home") -> Home | D3: Method 1 | T3: Method 2
A4: =HYPERLINK("#'Results'!A1", "Results") -> Results
D5: {=EntericMethane_PastureBeef_Equations.VEERG_3_2_1_1__4_AdditionalIntakeForMilkProduction_Title()} -> Additional intake for milk production in the season of calving and the season after calving
A6: INPUTS | D6: {=EntericMethane_PastureBeef_Equations.VEERG_3_2_1_1__4_AdditionalIntakeForMilkProduction_Source()} -> VEERG 2026: 3.2.1.1, Equation (4)
A7: =HYPERLINK("#'Input - Site'!A1", "Site") -> Site | D7: Function name | E7: {=Common_InputFunctions.Utility_DisplayFunctionName($H$30)} -> =EntericMethane_PastureBeef_Equations.VEERG_3_2_1_1__4_AdditionalIntakeForMilkProductionVariation
A8: =HYPERLINK("#'Input - Pasture Beef'!A1", "Pasture Beef") -> Pasture Beef
A10: CALCULATIONS | D10: Variable | E10: {=EntericMethane_PastureBeef_Equations.VEERG_3_2_1_1__4_AdditionalIntakeForMilkProduction_Variable()} -> MA_jk45
A11: =HYPERLINK("#'4.2.1.1-2 Methane'!A1", "4.2.1.1-2 Methane") -> 4.2.1.1-2 Methane | D11: Unit | E11: {=EntericMethane_PastureBeef_Equations.VEERG_3_2_1_1__4_AdditionalIntakeForMilkProduction_Unit()} -> fraction | J11: Assumes last year calving was identical to this year
A12: =HYPERLINK("#'4.2.1.3-4 Soil direct N2O'!A1", "4.2.1.3-4 Soil direct N2O") -> 4.2.1.3-4 Soil direct N2O
A13: =HYPERLINK("#'4.2.1.5-6 Soil Atmos Dep'!A1", "4.2.1.5-6 Soil atm. deposition") -> 4.2.1.5-6 Soil atm. deposition | D13: {=EntericMethane_PastureBeef_Equations.VEERG_3_2_1_1__4_AdditionalIntakeForMilkProduction_ArgumentsVariation()} -> LC_jk45curr | E13: proportion of cows greater than 1 year in calf in the season of calving expressed as a fraction | H13: ="See " & $D$19 -> See M1_Table_LC_j_k-4-5 | J13: {=EntericMethane_PastureBeef_Equations.VEERG_3_2_1_1__4_AdditionalIntakeForMilkProduction_Arguments()} -> LC_jk45 | K13: proportion of cows greater than 1 year in calf in the season of calving expressed as a fraction
A14: =HYPERLINK("#'4.2.1.7-8 Soil leach runoff'!A1", "4.2.1.7-8 Soil leach & runoff") -> 4.2.1.7-8 Soil leach & runoff | D14: LC_jk45prev | E14: proportion of cows greater than 1 year in calf in the previous season of calving expressed as a fraction | H14: ="See " & $D$19 -> See M1_Table_LC_j_k-4-5 | J14: FA_jk45 | K14: feed adjustment value for lactating cows in the season of calving and the season immediately after calving expressed as a fraction
D15: FA_jk45calv | E15: feed adjustment value for lactating cows in the season of calving expressed as a fraction | H15: {=_xlfn.XLOOKUP(1, (Table_SourceData_PastureBeef_FeedIntakeAdjustment_Variation[Breed]=$H$17)*(Table_SourceData_PastureBeef_FeedIntakeAdjustment_Variation[Season]=+"Calving season"),Table_SourceData_PastureBeef_FeedIntakeAdjustment_Variation[Feed adjustment])} -> 1.3 | J15: b | K15: breed of cattle
A16: APPENDICES | D16: FA_jk45after | E16: feed adjustment value for lactating cows in the season immediately after calving expressed as a fraction | H16: {=_xlfn.XLOOKUP(1, (Table_SourceData_PastureBeef_FeedIntakeAdjustment_Variation[Breed]=$H$17)*(Table_SourceData_PastureBeef_FeedIntakeAdjustment_Variation[Season]=+"Season after calving"),Table_SourceData_PastureBeef_FeedIntakeAdjustment_Variation[Feed adjustment])} -> 1.1
A17: =HYPERLINK("#'Constants - Pasture Beef'!A1", "Constants - Pasture Beef") -> Constants - Pasture Beef | D17: b | E17: breed of cattle | H17: ='Input - Pasture Beef'!$E$9 -> Hereford or Shorthorn breeds
A18: =HYPERLINK("#'Constants - Livestock'!A1", "Constants - Livestock") -> Constants - Livestock
A19: =HYPERLINK("#'Constants - Common'!A1", "Constants - Common") -> Constants - Common | D19: M1_Table_LC_j_k-4-5 | T19: M2_Table_LC_j_k-4-5
A20: =HYPERLINK("#'Acknowledgements'!A1", "Acknowledgements") -> Acknowledgements | D20: Proportion of cows in calf during season (Method 1) | T20: Proportion of cows in calf during season (Method 2)
D21: Season | E21: Cows 1-2 years | F21: Cows 2-3 years | G21: Cows > 3 years | J21: MAjk45 if done twice and summed | T21: Season | U21: Cows 1-2 years | V21: Cows 2-3 years | W21: Cows > 3 years
D22: ='Input - Pasture Beef'!D104 -> Spring | E22: ='Input - Pasture Beef'!E104 -> 0.5 | F22: ='Input - Pasture Beef'!F104 -> 0.5 | G22: ='Input - Pasture Beef'!G104 -> 0.5 | H22: Fraction | J22: Calving season | K22: Next season | T22: ='Input - Pasture Beef'!$D$128 -> January 2024 to March 2024 | U22: ='Input - Pasture Beef'!E128 -> 0 | V22: ='Input - Pasture Beef'!F128 -> 0 | W22: ='Input - Pasture Beef'!G128 -> 0 | X22: Fraction
D23: ='Input - Pasture Beef'!D105 -> Summer | E23: ='Input - Pasture Beef'!E105 -> 0.5 | F23: ='Input - Pasture Beef'!F105 -> 0.5 | G23: ='Input - Pasture Beef'!G105 -> 0.5 | H23: Fraction | J23: {=EntericMethane_PastureBeef_Equations.VEERG_3_2_1_1__4_AdditionalIntakeForMilkProduction(E22,$H$15)} -> 1.15 | K23: {=EntericMethane_PastureBeef_Equations.VEERG_3_2_1_1__4_AdditionalIntakeForMilkProduction(E25,$H$16)} -> 1 | L23: =SUM(J23:K23) -> 2.15 | T23: ='Input - Pasture Beef'!$D$129 -> April 2024 to June 2024 | U23: ='Input - Pasture Beef'!E129 -> 0 | V23: ='Input - Pasture Beef'!F129 -> 0 | W23: ='Input - Pasture Beef'!G129 -> 0 | X23: Fraction
D24: ='Input - Pasture Beef'!D106 -> Autumn | E24: ='Input - Pasture Beef'!E106 -> 0 | F24: ='Input - Pasture Beef'!F106 -> 0 | G24: ='Input - Pasture Beef'!G106 -> 0 | H24: Fraction | J24: {=EntericMethane_PastureBeef_Equations.VEERG_3_2_1_1__4_AdditionalIntakeForMilkProduction(E23,$H$15)} -> 1.15 | K24: {=EntericMethane_PastureBeef_Equations.VEERG_3_2_1_1__4_AdditionalIntakeForMilkProduction(E22,$H$16)} -> 1.05 | L24: =SUM(J24:K24) -> 2.2 | T24: ='Input - Pasture Beef'!$D$130 -> July 2024 to September 2024 | U24: ='Input - Pasture Beef'!E130 -> 0.25 | V24: ='Input - Pasture Beef'!F130 -> 0.25 | W24: ='Input - Pasture Beef'!G130 -> 0.25 | X24: Fraction
D25: ='Input - Pasture Beef'!D107 -> Winter | E25: ='Input - Pasture Beef'!E107 -> 0 | F25: ='Input - Pasture Beef'!F107 -> 0 | G25: ='Input - Pasture Beef'!G107 -> 0 | H25: Fraction | J25: {=EntericMethane_PastureBeef_Equations.VEERG_3_2_1_1__4_AdditionalIntakeForMilkProduction(E24,$H$15)} -> 1 | K25: {=EntericMethane_PastureBeef_Equations.VEERG_3_2_1_1__4_AdditionalIntakeForMilkProduction(E23,$H$16)} -> 1.05 | L25: =SUM(J25:K25) -> 2.05 | T25: ='Input - Pasture Beef'!$D$131 -> October 2024 to December 2024 | U25: ='Input - Pasture Beef'!E131 -> 0.75 | V25: ='Input - Pasture Beef'!F131 -> 0.75 | W25: ='Input - Pasture Beef'!G131 -> 0.75 | X25: Fraction
J26: {=EntericMethane_PastureBeef_Equations.VEERG_3_2_1_1__4_AdditionalIntakeForMilkProduction(E25,$H$15)} -> 1 | K26: {=EntericMethane_PastureBeef_Equations.VEERG_3_2_1_1__4_AdditionalIntakeForMilkProduction(E24,$H$16)} -> 1 | L26: =SUM(J26:K26) -> 2
D27: M1_Table_MA_j_k-4-5 | T27: M2_Table_MA_j_k-4-5
D28: Additional intake for milk production in calving and post-calving seasons (Method 1) | T28: Additional intake for milk production in calving and post-calving seasons (Method 2)
D29: Season | E29: Bulls < 1 year | F29: Bulls > 1 year | G29: Cows < 1 year | H29: Cows 1-2 years | I29: Cows 2-3 years | J29: Cows > 3 years | K29: Steers < 1 year | L29: Steers 1-2 years | M29: Steers 2-3 years | N29: Steers >3 years | T29: Season | U29: Bulls < 1 year | V29: Bulls > 1 year | W29: Cows < 1 year | X29: Cows 1-2 years | Y29: Cows 2-3 years | Z29: Cows > 3 years | AA29: Steers < 1 year | AB29: Steers 1-2 years | AC29: Steers 2-3 years | AD29: Steers >3 years
D30: Spring | E30: 1 | F30: 1 | G30: 1 | H30: {=EntericMethane_PastureBeef_Equations.VEERG_3_2_1_1__4_AdditionalIntakeForMilkProductionVariation(E22,E25,$H$15,$H$16)} -> 1.15 | I30: {=EntericMethane_PastureBeef_Equations.VEERG_3_2_1_1__4_AdditionalIntakeForMilkProductionVariation(F22,F25,$H$15,$H$16)} -> 1.15 | J30: {=EntericMethane_PastureBeef_Equations.VEERG_3_2_1_1__4_AdditionalIntakeForMilkProductionVariation(G22,G25,$H$15,$H$16)} -> 1.15 | K30: 1 | L30: 1 | M30: 1 | N30: 1 | O30: =$E$11 -> fraction | T30: ='Input - Pasture Beef'!$D$128 -> January 2024 to March 2024 | U30: 1 | V30: 1 | W30: 1 | X30: {=EntericMethane_PastureBeef_Equations.VEERG_3_2_1_1__4_AdditionalIntakeForMilkProductionVariation(U22,U25,$H$15,$H$16)} -> 1.075 | Y30: {=EntericMethane_PastureBeef_Equations.VEERG_3_2_1_1__4_AdditionalIntakeForMilkProductionVariation(V22,V25,$H$15,$H$16)} -> 1.075 | Z30: {=EntericMethane_PastureBeef_Equations.VEERG_3_2_1_1__4_AdditionalIntakeForMilkProductionVariation(W22,W25,$H$15,$H$16)} -> 1.075 | AA30: 1 | AB30: 1 | AC30: 1 | AD30: 1 | AE30: =$E$11 -> fraction
D31: Summer | E31: 1 | F31: 1 | G31: 1 | H31: {=EntericMethane_PastureBeef_Equations.VEERG_3_2_1_1__4_AdditionalIntakeForMilkProductionVariation(E23,E22,$H$15,$H$16)} -> 1.2 | I31: {=EntericMethane_PastureBeef_Equations.VEERG_3_2_1_1__4_AdditionalIntakeForMilkProductionVariation(F23,F22,$H$15,$H$16)} -> 1.2 | J31: {=EntericMethane_PastureBeef_Equations.VEERG_3_2_1_1__4_AdditionalIntakeForMilkProductionVariation(G23,G22,$H$15,$H$16)} -> 1.2 | K31: 1 | L31: 1 | M31: 1 | N31: 1 | O31: =$E$11 -> fraction | T31: ='Input - Pasture Beef'!$D$129 -> April 2024 to June 2024 | U31: 1 | V31: 1 | W31: 1 | X31: {=EntericMethane_PastureBeef_Equations.VEERG_3_2_1_1__4_AdditionalIntakeForMilkProductionVariation(U23,U22,$H$15,$H$16)} -> 1 | Y31: {=EntericMethane_PastureBeef_Equations.VEERG_3_2_1_1__4_AdditionalIntakeForMilkProductionVariation(V23,V22,$H$15,$H$16)} -> 1 | Z31: {=EntericMethane_PastureBeef_Equations.VEERG_3_2_1_1__4_AdditionalIntakeForMilkProductionVariation(W23,W22,$H$15,$H$16)} -> 1 | AA31: 1 | AB31: 1 | AC31: 1 | AD31: 1 | AE31: =$E$11 -> fraction
D32: Autumn | E32: 1 | F32: 1 | G32: 1 | H32: {=EntericMethane_PastureBeef_Equations.VEERG_3_2_1_1__4_AdditionalIntakeForMilkProductionVariation(E24,E23,$H$15,$H$16)} -> 1.05 | I32: {=EntericMethane_PastureBeef_Equations.VEERG_3_2_1_1__4_AdditionalIntakeForMilkProductionVariation(F24,F23,$H$15,$H$16)} -> 1.05 | J32: {=EntericMethane_PastureBeef_Equations.VEERG_3_2_1_1__4_AdditionalIntakeForMilkProductionVariation(G24,G23,$H$15,$H$16)} -> 1.05 | K32: 1 | L32: 1 | M32: 1 | N32: 1 | O32: =$E$11 -> fraction | T32: ='Input - Pasture Beef'!$D$130 -> July 2024 to September 2024 | U32: 1 | V32: 1 | W32: 1 | X32: {=EntericMethane_PastureBeef_Equations.VEERG_3_2_1_1__4_AdditionalIntakeForMilkProductionVariation(U24,U23,$H$15,$H$16)} -> 1.075 | Y32: {=EntericMethane_PastureBeef_Equations.VEERG_3_2_1_1__4_AdditionalIntakeForMilkProductionVariation(V24,V23,$H$15,$H$16)} -> 1.075 | Z32: {=EntericMethane_PastureBeef_Equations.VEERG_3_2_1_1__4_AdditionalIntakeForMilkProductionVariation(W24,W23,$H$15,$H$16)} -> 1.075 | AA32: 1 | AB32: 1 | AC32: 1 | AD32: 1 | AE32: =$E$11 -> fraction
D33: Winter | E33: 1 | F33: 1 | G33: 1 | H33: {=EntericMethane_PastureBeef_Equations.VEERG_3_2_1_1__4_AdditionalIntakeForMilkProductionVariation(E25,E24,$H$15,$H$16)} -> 1 | I33: {=EntericMethane_PastureBeef_Equations.VEERG_3_2_1_1__4_AdditionalIntakeForMilkProductionVariation(F25,F24,$H$15,$H$16)} -> 1 | J33: {=EntericMethane_PastureBeef_Equations.VEERG_3_2_1_1__4_AdditionalIntakeForMilkProductionVariation(G25,G24,$H$15,$H$16)} -> 1 | K33: 1 | L33: 1 | M33: 1 | N33: 1 | O33: =$E$11 -> fraction | T33: ='Input - Pasture Beef'!$D$131 -> October 2024 to December 2024 | U33: 1 | V33: 1 | W33: 1 | X33: {=EntericMethane_PastureBeef_Equations.VEERG_3_2_1_1__4_AdditionalIntakeForMilkProductionVariation(U25,U24,$H$15,$H$16)} -> 1.25 | Y33: {=EntericMethane_PastureBeef_Equations.VEERG_3_2_1_1__4_AdditionalIntakeForMilkProductionVariation(V25,V24,$H$15,$H$16)} -> 1.25 | Z33: {=EntericMethane_PastureBeef_Equations.VEERG_3_2_1_1__4_AdditionalIntakeForMilkProductionVariation(W25,W24,$H$15,$H$16)} -> 1.25 | AA33: 1 | AB33: 1 | AC33: 1 | AD33: 1 | AE33: =$E$11 -> fraction
D37: {=EntericMethane_PastureBeef_Equations.VEERG_3_2_1_1__3_FeedIntakeForGrazingBeef_Title()} -> Feed intake for grazing beef cattle
D38: {=EntericMethane_PastureBeef_Equations.VEERG_3_2_1_1__3_FeedIntakeForGrazingBeef_Source()} -> VEERG 2026: 3.2.1.1, Equation (3)
D39: Function name | E39: {=Common_InputFunctions.Utility_DisplayFunctionName($E$84)} -> =EntericMethane_PastureBeef_Equations.VEERG_3_2_1_1__3_FeedIntakeForGrazingBeef
D42: Variable | E42: {=EntericMethane_PastureBeef_Equations.VEERG_3_2_1_1__3_FeedIntakeForGrazingBeef_Variable()} -> I_jkl
D43: Unit | E43: {=EntericMethane_PastureBeef_Equations.VEERG_3_2_1_1__3_FeedIntakeForGrazingBeef_Unit()} -> kg DM/head/day
D45: {=EntericMethane_PastureBeef_Equations.VEERG_3_2_1_1__3_FeedIntakeForGrazingBeef_Arguments()} -> W_jkl | E45: liveweight (kg) | G45: ="See " & D49 -> See M1_Table_LW_j_k_l
D46: LWG_jkl | E46: live weight gain (kg/head/day) | G46: ="See " & D65 -> See M1_Table_LWG_j_k_l
D47: MA_jk45 | E47: additional intake for milk production in cows greater than 2 years (kg/head/day) | G47: ="See " & D27 -> See M1_Table_MA_j_k-4-5
D49: M1_Table_LW_j_k_l | T49: M2_Table_LW_j_k_l
...

Sheet 4.2.1.3-4 Soil direct N20
A1: #VALUE! | C1: 4.2.1.3-4 Manure Direct N2O
A3: =HYPERLINK("#'Home'!A1", "Home") -> Home | D3: Method 1 | T3: Method 2
A4: =HYPERLINK("#'Results'!A1", "Results") -> Results
D5: {=MMS_PastureBeef_Soil_N2ODirect_Equations.VEERG_4_2_1_3__7_RelativeSize_Title()} -> Relative size of the cattle
A6: INPUTS | D6: {=MMS_PastureBeef_Soil_N2ODirect_Equations.VEERG_4_2_1_3__7_RelativeSize_Source()} -> VEERG 2026: 4.2.1.3, Equation (7)
A7: =HYPERLINK("#'Input - Site'!A1", "Site") -> Site | D7: Function name | E7: {=Common_InputFunctions.Utility_DisplayFunctionName(E33)} -> =MMS_PastureBeef_Soil_N2ODirect_Equations.VEERG_4_2_1_3__7_RelativeSize
A8: =HYPERLINK("#'Input - Pasture Beef'!A1", "Pasture Beef") -> Pasture Beef
A10: CALCULATIONS | D10: Variable | E10: {=MMS_PastureBeef_Soil_N2ODirect_Equations.VEERG_4_2_1_3__7_RelativeSize_Variable()} -> Z_jkl
A11: =HYPERLINK("#'4.2.1.1-2 Methane'!A1", "4.2.1.1-2 Methane") -> 4.2.1.1-2 Methane | D11: Unit | E11: {=MMS_PastureBeef_Soil_N2ODirect_Equations.VEERG_4_2_1_3__7_RelativeSize_Unit()} -> ratio
A12: =HYPERLINK("#'4.2.1.3-4 Soil direct N2O'!A1", "4.2.1.3-4 Soil direct N2O") -> 4.2.1.3-4 Soil direct N2O
A13: =HYPERLINK("#'4.2.1.5-6 Soil Atmos Dep'!A1", "4.2.1.5-6 Soil atm. deposition") -> 4.2.1.5-6 Soil atm. deposition | D13: {=MMS_PastureBeef_Soil_N2ODirect_Equations.VEERG_4_2_1_3__7_RelativeSize_Arguments()} -> W_jkl | E13: liveweight (kg) | F13: ="See " & D17 -> See M1_Table_W_j_k_l | G13: Variable is LW in Methane
A14: =HYPERLINK("#'4.2.1.7-8 Soil leach runoff'!A1", "4.2.1.7-8 Soil leach & runoff") -> 4.2.1.7-8 Soil leach & runoff | D14: SRW_k | E14: standard reference weight (kg) | F14: ="See " & D25 -> See Table_SRW_k
D15: i | E15: state | F15: ='Input - Pasture Beef'!$E$7 -> Western Australia
A16: APPENDICES
A17: =HYPERLINK("#'Constants - Pasture Beef'!A1", "Constants - Pasture Beef") -> Constants - Pasture Beef | D17: M1_Table_W_j_k_l | T17: M2_Table_LW_j_k_l
A18: =HYPERLINK("#'Constants - Livestock'!A1", "Constants - Livestock") -> Constants - Livestock | D18: Liveweight (Method 1) | T18: Liveweight (Method 2)
A19: =HYPERLINK("#'Constants - Common'!A1", "Constants - Common") -> Constants - Common | D19: Season | E19: Bulls < 1 year | F19: Bulls > 1 year | G19: Cows < 1 year | H19: Cows 1-2 years | I19: Cows 2-3 years | J19: Cows > 3 years | K19: Steers < 1 year | L19: Steers 1-2 years | M19: Steers 2-3 years | N19: Steers >3 years | T19: Month | U19: Bulls < 1 year | V19: Bulls > 1 year | W19: Cows < 1 year | X19: Cows 1-2 years | Y19: Cows 2-3 years | Z19: Cows > 3 years | AA19: Steers < 1 year | AB19: Steers 1-2 years | AC19: Steers 2-3 years | AD19: Steers >3 years
A20: =HYPERLINK("#'Acknowledgements'!A1", "Acknowledgements") -> Acknowledgements | D20: ='Input - Pasture Beef'!D60 -> Spring | E20: ='Input - Pasture Beef'!E60 -> 340 | F20: ='Input - Pasture Beef'!F60 -> 800 | G20: ='Input - Pasture Beef'!G60 -> 260 | H20: ='Input - Pasture Beef'!H60 -> 420 | I20: ='Input - Pasture Beef'!I60 -> 550 | J20: ='Input - Pasture Beef'!J60 -> 550 | K20: ='Input - Pasture Beef'!K60 -> 300 | ... N20: ='Input - Pasture Beef'!N60 -> 480 | O20: kg/head | T20: =TEXT('Input - Site'!$E$12, "mmmm yyyy") -> January 2024 | U20: ='Input - Pasture Beef'!E66 -> 380 | V20: ='Input - Pasture Beef'!F66 -> 780 | W20: ='Input - Pasture Beef'!G66 -> 300 | X20: ='Input - Pasture Beef'!H66 -> 450 | Y20: ='Input - Pasture Beef'!I66 -> 530 | Z20: ='Input - Pasture Beef'!J66 -> 530 | AA20: ='Input - Pasture Beef'!K66 -> 340 | AB20: ='Input - Pasture Beef'!L66 -> 470 | ... AD20: ='Input - Pasture Beef'!N66 -> 470 | AE20: kg/head
D21: ='Input - Pasture Beef'!D61 -> Summer | E21: ='Input - Pasture Beef'!E61 -> 380 | F21: ='Input - Pasture Beef'!F61 -> 780 | G21: ='Input - Pasture Beef'!G61 -> 300 | H21: ='Input - Pasture Beef'!H61 -> 450 | I21: ='Input - Pasture Beef'!I61 -> 530 | J21: ='Input - Pasture Beef'!J61 -> 530 | K21: ='Input - Pasture Beef'!K61 -> 340 | ... N21: ='Input - Pasture Beef'!N61 -> 470 | O21: kg/head | T21: =TEXT(EDATE('Input - Site'!$E$12,1), "mmmm yyyy") -> February 2024 | U21: ='Input - Pasture Beef'!E67 -> 380 | V21: ='Input - Pasture Beef'!F67 -> 780 | W21: ='Input - Pasture Beef'!G67 -> 300 | X21: ='Input - Pasture Beef'!H67 -> 450 | Y21: ='Input - Pasture Beef'!I67 -> 530 | Z21: ='Input - Pasture Beef'!J67 -> 530 | AA21: ='Input - Pasture Beef'!K67 -> 340 | AB21: ='Input - Pasture Beef'!L67 -> 470 | ... AD21: ='Input - Pasture Beef'!N67 -> 470 | AE21: kg/head
D22: ='Input - Pasture Beef'!D62 -> Autumn | E22: ='Input - Pasture Beef'!E62 -> 100 | F22: ='Input - Pasture Beef'!F62 -> 680 | G22: ='Input - Pasture Beef'!G62 -> 80 | H22: ='Input - Pasture Beef'!H62 -> 320 | I22: ='Input - Pasture Beef'!I62 -> 480 | J22: ='Input - Pasture Beef'!J62 -> 480 | K22: ='Input - Pasture Beef'!K62 -> 100 | ... N22: ='Input - Pasture Beef'!N62 -> 340 | O22: kg/head | T22: =TEXT(EDATE('Input - Site'!$E$12,2), "mmmm yyyy") -> March 2024 | U22: ='Input - Pasture Beef'!E68 -> 100 | V22: ='Input - Pasture Beef'!F68 -> 680 | W22: ='Input - Pasture Beef'!G68 -> 80 | X22: ='Input - Pasture Beef'!H68 -> 320 | Y22: ='Input - Pasture Beef'!I68 -> 480 | Z22: ='Input - Pasture Beef'!J68 -> 480 | AA22: ='Input - Pasture Beef'!K68 -> 100 | AB22: ='Input - Pasture Beef'!L68 -> 340 | ... AD22: ='Input - Pasture Beef'!N68 -> 340 | AE22: kg/head
D23: ='Input - Pasture Beef'!D63 -> Winter | E23: ='Input - Pasture Beef'!E63 -> 190 | F23: ='Input - Pasture Beef'!F63 -> 700 | G23: ='Input - Pasture Beef'!G63 -> 150 | H23: ='Input - Pasture Beef'!H63 -> 330 | I23: ='Input - Pasture Beef'!I63 -> 490 | J23: ='Input - Pasture Beef'!J63 -> 490 | K23: ='Input - Pasture Beef'!K63 -> 170 | ... N23: ='Input - Pasture Beef'!N63 -> 360 | O23: kg/head | T23: =TEXT(EDATE('Input - Site'!$E$12,3), "mmmm yyyy") -> April 2024 | U23: ='Input - Pasture Beef'!E69 -> 100 | V23: ='Input - Pasture Beef'!F69 -> 680 | W23: ='Input - Pasture Beef'!G69 -> 80 | X23: ='Input - Pasture Beef'!H69 -> 320 | Y23: ='Input - Pasture Beef'!I69 -> 480 | Z23: ='Input - Pasture Beef'!J69 -> 480 | AA23: ='Input - Pasture Beef'!K69 -> 100 | AB23: ='Input - Pasture Beef'!L69 -> 340 | ... AD23: ='Input - Pasture Beef'!N69 -> 340 | AE23: kg/head
T24: =TEXT(EDATE('Input - Site'!$E$12,4), "mmmm yyyy") -> May 2024 | U24: ='Input - Pasture Beef'!E70 -> 100 | V24: ='Input - Pasture Beef'!F70 -> 680 | W24: ='Input - Pasture Beef'!G70 -> 80 | X24: ='Input - Pasture Beef'!H70 -> 320 | Y24: ='Input - Pasture Beef'!I70 -> 480 | Z24: ='Input - Pasture Beef'!J70 -> 480 | AA24: ='Input - Pasture Beef'!K70 -> 100 | AB24: ='Input - Pasture Beef'!L70 -> 340 | ... AD24: ='Input - Pasture Beef'!N70 -> 340 | AE24: kg/head
D25: Table_SRW_k | T25: =TEXT(EDATE('Input - Site'!$E$12,5), "mmmm yyyy") -> June 2024 | U25: ='Input - Pasture Beef'!E71 -> 190 | V25: ='Input - Pasture Beef'!F71 -> 700 | W25: ='Input - Pasture Beef'!G71 -> 150 | X25: ='Input - Pasture Beef'!H71 -> 330 | Y25: ='Input - Pasture Beef'!I71 -> 490 | Z25: ='Input - Pasture Beef'!J71 -> 490 | AA25: ='Input - Pasture Beef'!K71 -> 170 | AB25: ='Input - Pasture Beef'!L71 -> 360 | ... AD25: ='Input - Pasture Beef'!N71 -> 360 | AE25: kg/head
D26: Standard reference weight | T26: =TEXT(EDATE('Input - Site'!$E$12,6), "mmmm yyyy") -> July 2024 | U26: ='Input - Pasture Beef'!E72 -> 190 | V26: ='Input - Pasture Beef'!F72 -> 700 | W26: ='Input - Pasture Beef'!G72 -> 150 | X26: ='Input - Pasture Beef'!H72 -> 330 | Y26: ='Input - Pasture Beef'!I72 -> 490 | Z26: ='Input - Pasture Beef'!J72 -> 490 | AA26: ='Input - Pasture Beef'!K72 -> 170 | AB26: ='Input - Pasture Beef'!L72 -> 360 | ... AD26: ='Input - Pasture Beef'!N72 -> 360 | AE26: kg/head
D27: Bulls < 1 year | E27: Bulls > 1 year | F27: Cows < 1 year | G27: Cows 1-2 years | H27: Cows 2-3 years | I27: Cows > 3 years | J27: Steers < 1 year | K27: Steers 1-2 years | L27: Steers 2-3 years | M27: Steers >3 years | T27: =TEXT(EDATE('Input - Site'!$E$12,7), "mmmm yyyy") -> August 2024 | U27: ='Input - Pasture Beef'!E73 -> 190 | V27: ='Input - Pasture Beef'!F73 -> 700 | W27: ='Input - Pasture Beef'!G73 -> 150 | X27: ='Input - Pasture Beef'!H73 -> 330 | Y27: ='Input - Pasture Beef'!I73 -> 490 | Z27: ='Input - Pasture Beef'!J73 -> 490 | AA27: ='Input - Pasture Beef'!K73 -> 170 | AB27: ='Input - Pasture Beef'!L73 -> 360 | ... AD27: ='Input - Pasture Beef'!N73 -> 360 | AE27: kg/head
D28: =Common_InputFunctions.Utility_LookupValueInTableOneColumnAndHeader(Common_InputFunctions.Utility_ConvertStateCommonNameToAbbreviation($F$15,Table_AustralianStates[Common Name],Table_AustralianStates[Abbreviation]),D27,Table_SourceData_PastureBeef_StandardReferenceWeightsExpanded[State abbreviation],Table_SourceData_PastureBeef_StandardReferenceWeightsExpanded[#Headers],Table_SourceData_PastureBeef_StandardReferenceWeightsExpanded[]) -> 770 | E28: =Common_InputFunctions.Utility_LookupValueInTableOneColumnAndHeader(Common_InputFunctions.Utility_ConvertStateCommonNameToAbbreviation($F$15,Table_AustralianStates[Common Name],Table_AustralianStates[Abbreviation]),E27,Table_SourceData_PastureBeef_StandardReferenceWeightsExpanded[State abbreviation],Table_SourceData_PastureBeef_StandardReferenceWeightsExpanded[#Headers],Table_SourceData_PastureBeef_StandardReferenceWeightsExpanded[]) -> 770 | F28: =Common_InputFunctions.Utility_LookupValueInTableOneColumnAndHeader(Common_InputFunctions.Utility_ConvertStateCommonNameToAbbreviation($F$15,Table_AustralianStates[Common Name],Table_AustralianStates[Abbreviation]),F27,Table_SourceData_PastureBeef_StandardReferenceWeightsExpanded[State abbreviation],Table_SourceData_PastureBeef_StandardReferenceWeightsExpanded[#Headers],Table_SourceData_PastureBeef_StandardReferenceWeightsExpanded[]) -> 550 | G28: =Common_InputFunctions.Utility_LookupValueInTableOneColumnAndHeader(Common_InputFunctions.Utility_ConvertStateCommonNameToAbbreviation($F$15,Table_AustralianStates[Common Name],Table_AustralianStates[Abbreviation]),G27,Table_SourceData_PastureBeef_StandardReferenceWeightsExpanded[State abbreviation],Table_SourceData_PastureBeef_StandardReferenceWeightsExpanded[#Headers],Table_SourceData_PastureBeef_StandardReferenceWeightsExpanded[]) -> 550 | H28: =Common_InputFunctions.Utility_LookupValueInTableOneColumnAndHeader(Common_InputFunctions.Utility_ConvertStateCommonNameToAbbreviation($F$15,Table_AustralianStates[Common Name],Table_AustralianStates[Abbreviation]),H27,Table_SourceData_PastureBeef_StandardReferenceWeightsExpanded[State abbreviation],Table_SourceData_PastureBeef_StandardReferenceWeightsExpanded[#Headers],Table_SourceData_PastureBeef_StandardReferenceWeightsExpanded[]) -> 550 | I28: =Common_InputFunctions.Utility_LookupValueInTableOneColumnAndHeader(Common_InputFunctions.Utility_ConvertStateCommonNameToAbbreviation($F$15,Table_AustralianStates[Common Name],Table_AustralianStates[Abbreviation]),I27,Table_SourceData_PastureBeef_StandardReferenceWeightsExpanded[State abbreviation],Table_SourceData_PastureBeef_StandardReferenceWeightsExpanded[#Headers],Table_SourceData_PastureBeef_StandardReferenceWeightsExpanded[]) -> 550 | J28: =Common_InputFunctions.Utility_LookupValueInTableOneColumnAndHeader(Common_InputFunctions.Utility_ConvertStateCommonNameToAbbreviation($F$15,Table_AustralianStates[Common Name],Table_AustralianStates[Abbreviation]),J27,Table_SourceData_PastureBeef_StandardReferenceWeightsExpanded[State abbreviation],Table_SourceData_PastureBeef_StandardReferenceWeightsExpanded[#Headers],Table_SourceData_PastureBeef_StandardReferenceWeightsExpanded[]) -> 660 | K28: =Common_InputFunctions.Utility_LookupValueInTableOneColumnAndHeader(Common_InputFunctions.Utility_ConvertStateCommonNameToAbbreviation($F$15,Table_AustralianStates[Common Name],Table_AustralianStates[Abbreviation]),K27,Table_SourceData_PastureBeef_StandardReferenceWeightsExpanded[State abbreviation],Table_SourceData_PastureBeef_StandardReferenceWeightsExpanded[#Headers],Table_SourceData_PastureBeef_StandardReferenceWeightsExpanded[]) -> 660 | ... M28: =Common_InputFunctions.Utility_LookupValueInTableOneColumnAndHeader(Common_InputFunctions.Utility_ConvertStateCommonNameToAbbreviation($F$15,Table_AustralianStates[Common Name],Table_AustralianStates[Abbreviation]),M27,Table_SourceData_PastureBeef_StandardReferenceWeightsExpanded[State abbreviation],Table_SourceData_PastureBeef_StandardReferenceWeightsExpanded[#Headers],Table_SourceData_PastureBeef_StandardReferenceWeightsExpanded[]) -> 660 | N28: kg/head | T28: =TEXT(EDATE('Input - Site'!$E$12,8), "mmmm yyyy") -> September 2024 | U28: ='Input - Pasture Beef'!E74 -> 340 | V28: ='Input - Pasture Beef'!F74 -> 800 | W28: ='Input - Pasture Beef'!G74 -> 260 | X28: ='Input - Pasture Beef'!H74 -> 420 | Y28: ='Input - Pasture Beef'!I74 -> 550 | Z28: ='Input - Pasture Beef'!J74 -> 550 | AA28: ='Input - Pasture Beef'!K74 -> 300 | AB28: ='Input - Pasture Beef'!L74 -> 480 | ... AD28: ='Input - Pasture Beef'!N74 -> 480 | AE28: kg/head
T29: =TEXT(EDATE('Input - Site'!$E$12,9), "mmmm yyyy") -> October 2024 | U29: ='Input - Pasture Beef'!E75 -> 340 | V29: ='Input - Pasture Beef'!F75 -> 800 | W29: ='Input - Pasture Beef'!G75 -> 260 | X29: ='Input - Pasture Beef'!H75 -> 420 | Y29: ='Input - Pasture Beef'!I75 -> 550 | Z29: ='Input - Pasture Beef'!J75 -> 550 | AA29: ='Input - Pasture Beef'!K75 -> 300 | AB29: ='Input - Pasture Beef'!L75 -> 480 | ... AD29: ='Input - Pasture Beef'!N75 -> 480 | AE29: kg/head
D30: M1_Table_Z_j_k_l | T30: =TEXT(EDATE('Input - Site'!$E$12,10), "mmmm yyyy") -> November 2024 | U30: ='Input - Pasture Beef'!E76 -> 340 | V30: ='Input - Pasture Beef'!F76 -> 800 | W30: ='Input - Pasture Beef'!G76 -> 260 | X30: ='Input - Pasture Beef'!H76 -> 420 | Y30: ='Input - Pasture Beef'!I76 -> 550 | Z30: ='Input - Pasture Beef'!J76 -> 550 | AA30: ='Input - Pasture Beef'!K76 -> 300 | AB30: ='Input - Pasture Beef'!L76 -> 480 | ... AD30: ='Input - Pasture Beef'!N76 -> 480 | AE30: kg/head
D31: Relative size (Method 1) | T31: =TEXT(EDATE('Input - Site'!$E$12,11), "mmmm yyyy") -> December 2024 | U31: ='Input - Pasture Beef'!E77 -> 380 | V31: ='Input - Pasture Beef'!F77 -> 780 | W31: ='Input - Pasture Beef'!G77 -> 300 | X31: ='Input - Pasture Beef'!H77 -> 450 | Y31: ='Input - Pasture Beef'!I77 -> 530 | Z31: ='Input - Pasture Beef'!J77 -> 530 | AA31: ='Input - Pasture Beef'!K77 -> 340 | AB31: ='Input - Pasture Beef'!L77 -> 470 | ... AD31: ='Input - Pasture Beef'!N77 -> 470 | AE31: kg/head
D32: Season | E32: Bulls < 1 year | F32: Bulls > 1 year | G32: Cows < 1 year | H32: Cows 1-2 years | I32: Cows 2-3 years | J32: Cows > 3 years | K32: Steers < 1 year | L32: Steers 1-2 years | M32: Steers 2-3 years | N32: Steers >3 years
D33: ='Input - Pasture Beef'!D60 -> Spring | E33: {=MMS_PastureBeef_Soil_N2ODirect_Equations.VEERG_4_2_1_3__7_RelativeSize(E20,D$28)} -> 0.44155844 | F33: {=MMS_PastureBeef_Soil_N2ODirect_Equations.VEERG_4_2_1_3__7_RelativeSize(F20,E$28)} -> 1.038961 | G33: {=MMS_PastureBeef_Soil_N2ODirect_Equations.VEERG_4_2_1_3__7_RelativeSize(G20,F$28)} -> 0.47272727 | H33: {=MMS_PastureBeef_Soil_N2ODirect_Equations.VEERG_4_2_1_3__7_RelativeSize(H20,G$28)} -> 0.76363636 | I33: {=MMS_PastureBeef_Soil_N2ODirect_Equations.VEERG_4_2_1_3__7_RelativeSize(I20,H$28)} -> 1 | J33: {=MMS_PastureBeef_Soil_N2ODirect_Equations.VEERG_4_2_1_3__7_RelativeSize(J20,I$28)} -> 1 | K33: {=MMS_PastureBeef_Soil_N2ODirect_Equations.VEERG_4_2_1_3__7_RelativeSize(K20,J$28)} -> 0.45454545 | L33: {=MMS_PastureBeef_Soil_N2ODirect_Equations.VEERG_4_2_1_3__7_RelativeSize(L20,K$28)} -> 0.72727273 | ... N33: {=MMS_PastureBeef_Soil_N2ODirect_Equations.VEERG_4_2_1_3__7_RelativeSize(N20,M$28)} -> 0.72727273 | O33: =$E$11 -> ratio | T33: M2_Table_Z_j_k_l
D34: ='Input - Pasture Beef'!D61 -> Summer | E34: {=MMS_PastureBeef_Soil_N2ODirect_Equations.VEERG_4_2_1_3__7_RelativeSize(E21,D$28)} -> 0.49350649 | F34: {=MMS_PastureBeef_Soil_N2ODirect_Equations.VEERG_4_2_1_3__7_RelativeSize(F21,E$28)} -> 1.012987 | G34: {=MMS_PastureBeef_Soil_N2ODirect_Equations.VEERG_4_2_1_3__7_RelativeSize(G21,F$28)} -> 0.54545455 | H34: {=MMS_PastureBeef_Soil_N2ODirect_Equations.VEERG_4_2_1_3__7_RelativeSize(H21,G$28)} -> 0.81818182 | I34: {=MMS_PastureBeef_Soil_N2ODirect_Equations.VEERG_4_2_1_3__7_RelativeSize(I21,H$28)} -> 0.96363636 | J34: {=MMS_PastureBeef_Soil_N2ODirect_Equations.VEERG_4_2_1_3__7_RelativeSize(J21,I$28)} -> 0.96363636 | K34: {=MMS_PastureBeef_Soil_N2ODirect_Equations.VEERG_4_2_1_3__7_RelativeSize(K21,J$28)} -> 0.51515152 | L34: {=MMS_PastureBeef_Soil_N2ODirect_Equations.VEERG_4_2_1_3__7_RelativeSize(L21,K$28)} -> 0.71212121 | ... N34: {=MMS_PastureBeef_Soil_N2ODirect_Equations.VEERG_4_2_1_3__7_RelativeSize(N21,M$28)} -> 0.71212121 | O34: =$E$11 -> ratio | T34: Relative size (Method 2)
D35: ='Input - Pasture Beef'!D62 -> Autumn | E35: {=MMS_PastureBeef_Soil_N2ODirect_Equations.VEERG_4_2_1_3__7_RelativeSize(E22,D$28)} -> 0.12987013 | F35: {=MMS_PastureBeef_Soil_N2ODirect_Equations.VEERG_4_2_1_3__7_RelativeSize(F22,E$28)} -> 0.88311688 | G35: {=MMS_PastureBeef_Soil_N2ODirect_Equations.VEERG_4_2_1_3__7_RelativeSize(G22,F$28)} -> 0.14545455 | H35: {=MMS_PastureBeef_Soil_N2ODirect_Equations.VEERG_4_2_1_3__7_RelativeSize(H22,G$28)} -> 0.58181818 | I35: {=MMS_PastureBeef_Soil_N2ODirect_Equations.VEERG_4_2_1_3__7_RelativeSize(I22,H$28)} -> 0.87272727 | J35: {=MMS_PastureBeef_Soil_N2ODirect_Equations.VEERG_4_2_1_3__7_RelativeSize(J22,I$28)} -> 0.87272727 | K35: {=MMS_PastureBeef_Soil_N2ODirect_Equations.VEERG_4_2_1_3__7_RelativeSize(K22,J$28)} -> 0.15151515 | L35: {=MMS_PastureBeef_Soil_N2ODirect_Equations.VEERG_4_2_1_3__7_RelativeSize(L22,K$28)} -> 0.51515152 | ... N35: {=MMS_PastureBeef_Soil_N2ODirect_Equations.VEERG_4_2_1_3__7_RelativeSize(N22,M$28)} -> 0.51515152 | O35: =$E$11 -> ratio | T35: Month | U35: Bulls < 1 year | V35: Bulls > 1 year | W35: Cows < 1 year | X35: Cows 1-2 years | Y35: Cows 2-3 years | Z35: Cows > 3 years | AA35: Steers < 1 year | AB35: Steers 1-2 years | AC35: Steers 2-3 years | AD35: Steers >3 years
D36: ='Input - Pasture Beef'!D63 -> Winter | E36: {=MMS_PastureBeef_Soil_N2ODirect_Equations.VEERG_4_2_1_3__7_RelativeSize(E23,D$28)} -> 0.24675325 | F36: {=MMS_PastureBeef_Soil_N2ODirect_Equations.VEERG_4_2_1_3__7_RelativeSize(F23,E$28)} -> 0.90909091 | G36: {=MMS_PastureBeef_Soil_N2ODirect_Equations.VEERG_4_2_1_3__7_RelativeSize(G23,F$28)} -> 0.27272727 | H36: {=MMS_PastureBeef_Soil_N2ODirect_Equations.VEERG_4_2_1_3__7_RelativeSize(H23,G$28)} -> 0.6 | I36: {=MMS_PastureBeef_Soil_N2ODirect_Equations.VEERG_4_2_1_3__7_RelativeSize(I23,H$28)} -> 0.89090909 | J36: {=MMS_PastureBeef_Soil_N2ODirect_Equations.VEERG_4_2_1_3__7_RelativeSize(J23,I$28)} -> 0.89090909 | K36: {=MMS_PastureBeef_Soil_N2ODirect_Equations.VEERG_4_2_1_3__7_RelativeSize(K23,J$28)} -> 0.25757576 | L36: {=MMS_PastureBeef_Soil_N2ODirect_Equations.VEERG_4_2_1_3__7_RelativeSize(L23,K$28)} -> 0.54545455 | ... N36: {=MMS_PastureBeef_Soil_N2ODirect_Equations.VEERG_4_2_1_3__7_RelativeSize(N23,M$28)} -> 0.54545455 | O36: =$E$11 -> ratio | T36: =TEXT('Input - Site'!$E$12, "mmmm yyyy") -> January 2024 | U36: {=MMS_PastureBeef_Soil_N2ODirect_Equations.VEERG_4_2_1_3__7_RelativeSize(U20,D$28)} -> 0.49350649 | V36: {=MMS_PastureBeef_Soil_N2ODirect_Equations.VEERG_4_2_1_3__7_RelativeSize(V20,E$28)} -> 1.012987 | W36: {=MMS_PastureBeef_Soil_N2ODirect_Equations.VEERG_4_2_1_3__7_RelativeSize(W20,F$28)} -> 0.54545455 | X36: {=MMS_PastureBeef_Soil_N2ODirect_Equations.VEERG_4_2_1_3__7_RelativeSize(X20,G$28)} -> 0.81818182 | Y36: {=MMS_PastureBeef_Soil_N2ODirect_Equations.VEERG_4_2_1_3__7_RelativeSize(Y20,H$28)} -> 0.96363636 | Z36: {=MMS_PastureBeef_Soil_N2ODirect_Equations.VEERG_4_2_1_3__7_RelativeSize(Z20,I$28)} -> 0.96363636 | AA36: {=MMS_PastureBeef_Soil_N2ODirect_Equations.VEERG_4_2_1_3__7_RelativeSize(AA20,J$28)} -> 0.51515152 | AB36: {=MMS_PastureBeef_Soil_N2ODirect_Equations.VEERG_4_2_1_3__7_RelativeSize(AB20,K$28)} -> 0.71212121 | ... AD36: {=MMS_PastureBeef_Soil_N2ODirect_Equations.VEERG_4_2_1_3__7_RelativeSize(AD20,M$28)} -> 0.71212121 | AE36: =$E$11 -> ratio
T37: =TEXT(EDATE('Input - Site'!$E$12,1), "mmmm yyyy") -> February 2024 | U37: {=MMS_PastureBeef_Soil_N2ODirect_Equations.VEERG_4_2_1_3__7_RelativeSize(U21,D$28)} -> 0.49350649 | V37: {=MMS_PastureBeef_Soil_N2ODirect_Equations.VEERG_4_2_1_3__7_RelativeSize(V21,E$28)} -> 1.012987 | W37: {=MMS_PastureBeef_Soil_N2ODirect_Equations.VEERG_4_2_1_3__7_RelativeSize(W21,F$28)} -> 0.54545455 | X37: {=MMS_PastureBeef_Soil_N2ODirect_Equations.VEERG_4_2_1_3__7_RelativeSize(X21,G$28)} -> 0.81818182 | Y37: {=MMS_PastureBeef_Soil_N2ODirect_Equations.VEERG_4_2_1_3__7_RelativeSize(Y21,H$28)} -> 0.96363636 | Z37: {=MMS_PastureBeef_Soil_N2ODirect_Equations.VEERG_4_2_1_3__7_RelativeSize(Z21,I$28)} -> 0.96363636 | AA37: {=MMS_PastureBeef_Soil_N2ODirect_Equations.VEERG_4_2_1_3__7_RelativeSize(AA21,J$28)} -> 0.51515152 | AB37: {=MMS_PastureBeef_Soil_N2ODirect_Equations.VEERG_4_2_1_3__7_RelativeSize(AB21,K$28)} -> 0.71212121 | ... AD37: {=MMS_PastureBeef_Soil_N2ODirect_Equations.VEERG_4_2_1_3__7_RelativeSize(AD21,M$28)} -> 0.71212121 | AE37: =$E$11 -> ratio
T38: =TEXT(EDATE('Input - Site'!$E$12,2), "mmmm yyyy") -> March 2024 | U38: {=MMS_PastureBeef_Soil_N2ODirect_Equations.VEERG_4_2_1_3__7_RelativeSize(U22,D$28)} -> 0.12987013 | V38: {=MMS_PastureBeef_Soil_N2ODirect_Equations.VEERG_4_2_1_3__7_RelativeSize(V22,E$28)} -> 0.88311688 | W38: {=MMS_PastureBeef_Soil_N2ODirect_Equations.VEERG_4_2_1_3__7_RelativeSize(W22,F$28)} -> 0.14545455 | X38: {=MMS_PastureBeef_Soil_N2ODirect_Equations.VEERG_4_2_1_3__7_RelativeSize(X22,G$28)} -> 0.58181818 | Y38: {=MMS_PastureBeef_Soil_N2ODirect_Equations.VEERG_4_2_1_3__7_RelativeSize(Y22,H$28)} -> 0.87272727 | Z38: {=MMS_PastureBeef_Soil_N2ODirect_Equations.VEERG_4_2_1_3__7_RelativeSize(Z22,I$28)} -> 0.87272727 | AA38: {=MMS_PastureBeef_Soil_N2ODirect_Equations.VEERG_4_2_1_3__7_RelativeSize(AA22,J$28)} -> 0.15151515 | AB38: {=MMS_PastureBeef_Soil_N2ODirect_Equations.VEERG_4_2_1_3__7_RelativeSize(AB22,K$28)} -> 0.51515152 | ... AD38: {=MMS_PastureBeef_Soil_N2ODirect_Equations.VEERG_4_2_1_3__7_RelativeSize(AD22,M$28)} -> 0.51515152 | AE38: =$E$11 -> ratio
T39: =TEXT(EDATE('Input - Site'!$E$12,3), "mmmm yyyy") -> April 2024 | U39: {=MMS_PastureBeef_Soil_N2ODirect_Equations.VEERG_4_2_1_3__7_RelativeSize(U23,D$28)} -> 0.12987013 | V39: {=MMS_PastureBeef_Soil_N2ODirect_Equations.VEERG_4_2_1_3__7_RelativeSize(V23,E$28)} -> 0.88311688 | W39: {=MMS_PastureBeef_Soil_N2ODirect_Equations.VEERG_4_2_1_3__7_RelativeSize(W23,F$28)} -> 0.14545455 | X39: {=MMS_PastureBeef_Soil_N2ODirect_Equations.VEERG_4_2_1_3__7_RelativeSize(X23,G$28)} -> 0.58181818 | Y39: {=MMS_PastureBeef_Soil_N2ODirect_Equations.VEERG_4_2_1_3__7_RelativeSize(Y23,H$28)} -> 0.87272727 | Z39: {=MMS_PastureBeef_Soil_N2ODirect_Equations.VEERG_4_2_1_3__7_RelativeSize(Z23,I$28)} -> 0.87272727 | AA39: {=MMS_PastureBeef_Soil_N2ODirect_Equations.VEERG_4_2_1_3__7_RelativeSize(AA23,J$28)} -> 0.15151515 | AB39: {=MMS_PastureBeef_Soil_N2ODirect_Equations.VEERG_4_2_1_3__7_RelativeSize(AB23,K$28)} -> 0.51515152 | ... AD39: {=MMS_PastureBeef_Soil_N2ODirect_Equations.VEERG_4_2_1_3__7_RelativeSize(AD23,M$28)} -> 0.51515152 | AE39: =$E$11 -> ratio
D40: {=MMS_PastureBeef_Soil_N2ODirect_Equations.VEERG_4_2_1_3__6_IntakeRelativeToMaintenance_Title()} -> Intake relative to that needed for maintenance | T40: =TEXT(EDATE('Input - Site'!$E$12,4), "mmmm yyyy") -> May 2024 | U40: {=MMS_PastureBeef_Soil_N2ODirect_Equations.VEERG_4_2_1_3__7_RelativeSize(U24,D$28)} -> 0.12987013 | V40: {=MMS_PastureBeef_Soil_N2ODirect_Equations.VEERG_4_2_1_3__7_RelativeSize(V24,E$28)} -> 0.88311688 | W40: {=MMS_PastureBeef_Soil_N2ODirect_Equations.VEERG_4_2_1_3__7_RelativeSize(W24,F$28)} -> 0.14545455 | X40: {=MMS_PastureBeef_Soil_N2ODirect_Equations.VEERG_4_2_1_3__7_RelativeSize(X24,G$28)} -> 0.58181818 | Y40: {=MMS_PastureBeef_Soil_N2ODirect_Equations.VEERG_4_2_1_3__7_RelativeSize(Y24,H$28)} -> 0.87272727 | Z40: {=MMS_PastureBeef_Soil_N2ODirect_Equations.VEERG_4_2_1_3__7_RelativeSize(Z24,I$28)} -> 0.87272727 | AA40: {=MMS_PastureBeef_Soil_N2ODirect_Equations.VEERG_4_2_1_3__7_RelativeSize(AA24,J$28)} -> 0.15151515 | AB40: {=MMS_PastureBeef_Soil_N2ODirect_Equations.VEERG_4_2_1_3__7_RelativeSize(AB24,K$28)} -> 0.51515152 | ... AD40: {=MMS_PastureBeef_Soil_N2ODirect_Equations.VEERG_4_2_1_3__7_RelativeSize(AD24,M$28)} -> 0.51515152 | AE40: =$E$11 -> ratio
