Workbook
Name Common_Equations.Common_ConvertCH4ToCO2e: _xlfn.LAMBDA(_xlpm.E_CH4,_xlpm.GWP_CH4, _xlpm.E_CH4 * _xlpm.GWP_CH4)
Name Common_Equations.Common_ConvertCH4ToCO2e_Arguments: _xlfn.LAMBDA(_xlfn.MAKEARRAY(2, 2, _xlfn.LAMBDA(_xlpm.r,_xlpm.c, INDEX({"ECH4","Methane emissions (t CH4)";"GWPCH4","Global warming potential for methane (t CO2-e / t CH4)"}, _xlpm.r, _xlpm.c))))
Name Common_Equations.Common_ConvertCH4ToCO2e_LatexEquation: _xlfn.LAMBDA("CO2_e = E_{CH4} \times GWP_{CH4}")
Name Common_Equations.Common_ConvertCH4ToCO2e_NIRReference: _xlfn.LAMBDA("")
Name Common_Equations.Common_ConvertCH4ToCO2e_Title: _xlfn.LAMBDA("Convert methane emissions to carbon dioxide equivalent emissions")
Name Common_Equations.Common_ConvertCH4ToCO2e_Unit: _xlfn.LAMBDA("t CO2e")
Name Common_Equations.Common_ConvertCH4ToCO2e_Variable: _xlfn.LAMBDA("ECH4 CO2e")
Name Common_Equations.Common_ConvertN2OToCO2e: _xlfn.LAMBDA(_xlpm.E_N2O,_xlpm.GWP_N2O, _xlpm.E_N2O * _xlpm.GWP_N2O)
Name Common_Equations.Common_ConvertN2OToCO2e_LatexEquation: _xlfn.LAMBDA("CO2_e = E_{N2O} \times GWP_{N2O}")
Name Common_Equations.Common_ConvertN2OToCO2e_NIRReference: _xlfn.LAMBDA("")
Name Common_Equations.Common_ConvertN2OToCO2e_Title: _xlfn.LAMBDA("Convert nitrous oxide emissions to carbon dioxide equivalent emissions")
Name Common_Equations.Common_ConvertN2OToCO2e_Unit: _xlfn.LAMBDA("t CO2e")
Name Common_Equations.Common_ConvertN2OToCO2e_Variable: _xlfn.LAMBDA("EN2O CO2e")
Name Common_InputFunctions.Utility_ConvertStateCommonNameToAbbreviation: _xlfn.LAMBDA(_xlpm.StateCommonName,_xlpm.StateCommonNameArray,_xlpm.StateAbbreviationArray, _xlfn.XLOOKUP(_xlpm.StateCommonName, _xlpm.StateCommonNameArray, _xlpm.StateAbbreviationArray, ""))
Name Common_InputFunctions.Utility_DisplayArguments_1_2: _xlfn.LAMBDA(_xlpm.ArgumentsArray, _xlfn.CHOOSECOLS(_xlpm.ArgumentsArray, 1, 2))
Name Common_InputFunctions.Utility_DisplayArguments_3_4: _xlfn.LAMBDA(_xlpm.ArgumentsArray, _xlfn.CHOOSECOLS(_xlpm.ArgumentsArray, 3, 4))
Name Common_InputFunctions.Utility_DisplayFunctionName: _xlfn.LAMBDA(_xlpm.Function, _xlfn.TEXTBEFORE(_xlfn.FORMULATEXT(_xlpm.Function), "("))
Name Common_InputFunctions.Utility_GetArrayTableColumnStartNumber: _xlfn.LAMBDA(_xlpm.TableHeaderCell, COLUMN(_xlpm.TableHeaderCell))
Name Common_InputFunctions.Utility_GetArrayTableRowStartNumber: _xlfn.LAMBDA(_xlpm.TableheaderCell,_xlpm.RowsBetweenHeaderandArray, ROW(_xlpm.TableheaderCell) + _xlpm.RowsBetweenHeaderandArray - 1)
Name Common_InputFunctions.Utility_LookupValueInTable: _xlfn.LAMBDA(_xlpm.LookupValue,_xlpm.LookupArray,_xlpm.ReturnArray, _xlfn.XLOOKUP(_xlpm.LookupValue, _xlpm.LookupArray, _xlpm.ReturnArray, ""))
Name Common_InputFunctions.Utility_ResultsItemFromEquationTitleAndSource: _xlfn.LAMBDA(_xlpm.TitleCell,_xlpm.SourceCell, SUBSTITUTE(LEFT(_xlpm.SourceCell, FIND(",", _xlpm.SourceCell) - 1), "VEERG 2026: ", "") & " " & _xlpm.TitleCell)
Name Common_InputFunctions.Utility_SourceHyperlink: _xlfn.LAMBDA(_xlpm.TargetCell, _xlfn.LET(_xlpm.sh, _xlfn.TEXTAFTER(CELL("filename", _xlpm.TargetCell), "]"), _xlpm.addr, CELL("address", _xlpm.TargetCell), "#'" & _xlpm.sh & "'!" & _xlpm.addr))
Name Common_InputFunctions.Utility_SourceHyperlinkDifferentSheet: _xlfn.LAMBDA(_xlpm.TargetCell, _xlfn.LET(_xlpm.sh, _xlfn.TEXTAFTER(CELL("filename", _xlpm.TargetCell), "]"), _xlpm.addr, CELL("address", _xlpm.TargetCell), "#" & _xlpm.addr))
Name Common_SourceData.Common_SourceData_AustralianStatesTerritories_Source: _xlfn.LAMBDA("")
Name Common_SourceData.Common_SourceData_AustralianStatesTerritories_Title: _xlfn.LAMBDA("Australian states and territories")
Name Common_SourceData.Common_SourceData_AustralianStatesTerritories_Unit: _xlfn.LAMBDA("")
Name Common_SourceData.Common_SourceData_AustralianStatesTerritories_Variable: _xlfn.LAMBDA("")
Name Common_SourceData.Common_SourceData_ClimateZones_Source: _xlfn.LAMBDA("VEERG 2026: Table 1.3: Climate and Rainfall zone classifications and definitions")
Name Common_SourceData.Common_SourceData_ClimateZones_Title: _xlfn.LAMBDA("VEERG Australian climate zones")
Name Common_SourceData.Common_SourceData_ClimateZones_Unit: _xlfn.LAMBDA("")
Name Common_SourceData.Common_SourceData_ClimateZones_Variable: _xlfn.LAMBDA("")
Name Common_SourceData.Common_SourceData_ConvertGasElementalToMolecular_Source: _xlfn.LAMBDA("XXXXXXX")
Name Common_SourceData.Common_SourceData_ConvertGasElementalToMolecular_Title: _xlfn.LAMBDA("Factor to convert elemental mass of gas to molecular mass")
Name Common_SourceData.Common_SourceData_ConvertGasElementalToMolecular_Unit: _xlfn.LAMBDA("factor")
Name Common_SourceData.Common_SourceData_ConvertGasElementalToMolecular_Variable: _xlfn.LAMBDA("Cg")
Name Common_SourceData.Common_SourceData_ConvertN2oElementalToMolecularCg_Data: _xlfn.LAMBDA(44 / 28)
Name Common_SourceData.Common_SourceData_ConvertN2oElementalToMolecularCg_Source: _xlfn.LAMBDA("National Inventory Report 2023 Volume 1")
Name Common_SourceData.Common_SourceData_ConvertN2oElementalToMolecularCg_Title: _xlfn.LAMBDA("Factor to convert elemental mass of N2O to molecular mass")
Name Common_SourceData.Common_SourceData_ConvertN2oElementalToMolecularCg_Unit: _xlfn.LAMBDA("factor")
Name Common_SourceData.Common_SourceData_ConvertN2oElementalToMolecularCg_Variable: _xlfn.LAMBDA("CgN2O")
Name Common_SourceData.Common_SourceData_DataScores_Scope3_Source: _xlfn.LAMBDA("VEERG 2026: XXXXXXXX")
Name Common_SourceData.Common_SourceData_DataScores_Scope3_Title: _xlfn.LAMBDA("Australian data scores for scope 3")
Name Common_SourceData.Common_SourceData_DataScores_Scope3_Unit: _xlfn.LAMBDA("")
Name Common_SourceData.Common_SourceData_DataScores_Scope3_Variable: _xlfn.LAMBDA("")
Name Common_SourceData.Common_SourceData_DataScores_Scope3_Variation: _xlfn.LAMBDA("")
Name Common_SourceData.Common_SourceData_DensityOfMethane_Data: _xlfn.LAMBDA(0.6784)
Name Common_SourceData.Common_SourceData_DensityOfMethane_Source: _xlfn.LAMBDA("National Inventory Report 2023 Volume 1: Equations 3.B.1a_2, 3.B.1c_2, 3.B.3_1, 3.B.4g_2")
Name Common_SourceData.Common_SourceData_DensityOfMethane_Title: _xlfn.LAMBDA("p = density of methane")
Name Common_SourceData.Common_SourceData_DensityOfMethane_Unit: _xlfn.LAMBDA("kg/m3")
Name Common_SourceData.Common_SourceData_EFleach_Data: _xlfn.LAMBDA(_xlfn.MAKEARRAY(1, 2, _xlfn.LAMBDA(_xlpm.r,_xlpm.c, INDEX({"EFleach",0.011}, _xlpm.r, _xlpm.c))))
Name Common_SourceData.Common_SourceData_EFleach_NIRReference: _xlfn.LAMBDA("National Inventory Report Volume 1: Equation 3.D.B_10")
Name Common_SourceData.Common_SourceData_EFleach_Source: _xlfn.LAMBDA("VEERG 2026:5.5.2.3 Constant Parameters")
Name Common_SourceData.Common_SourceData_EFleach_Title: _xlfn.LAMBDA("Emission factor for nitrogen leaching and runoff")
Name Common_SourceData.Common_SourceData_EFleach_Unit: _xlfn.LAMBDA("(kg N2O-N / kg N")
Name Common_SourceData.Common_SourceData_EFleach_Variation: _xlfn.LAMBDA((""))
Name Common_SourceData.Common_SourceData_EFN2O_NIRReference: _xlfn.LAMBDA("")
Name Common_SourceData.Common_SourceData_EFN2O_Source: _xlfn.LAMBDA("VEERG 2026: Table A.2.2.1")
Name Common_SourceData.Common_SourceData_EFN2O_Title: _xlfn.LAMBDA("Nitrous oxide emission factors for inorganic fertiliser application")
Name Common_SourceData.Common_SourceData_EFN2O_Unit: _xlfn.LAMBDA("(kg N2O-N / kg N")
Name Common_SourceData.Common_SourceData_EFOrganicFertiliserAndCropResidues_Data: _xlfn.LAMBDA(_xlfn.MAKEARRAY(3, 2, _xlfn.LAMBDA(_xlpm.r,_xlpm.c, INDEX({"Climate zone","EFNi & EFN2O";"Wet climate zone",0.006;"Dry climate zone",0.005}, _xlpm.r, _xlpm.c))))

Sheet Home
A1: Home

Sheet Overview
A1: #VALUE! | C1: 4.6: Manure Management: Poultry: Overview
A3: =HYPERLINK("#'Home'!A1", "Home") -> Home
A4: =HYPERLINK("#'Overview'!A1", "Overview") -> Overview
A5: =HYPERLINK("#'Results'!A1", "Results") -> Results | D5: 💡 Below is a diagram that maps the equations used to calculate emissions, how they interact with each other and how they align with dairy manure management processes.
D6: Click on a box to go to the corresponding calculation.
A7: INPUTS
A8: =HYPERLINK("#'Input - Site'!A1", "Site") -> Site
A9: =HYPERLINK("#'Input - Poultry'!A1", "Poultry") -> Poultry
A11: CALCULATIONS
A12: =HYPERLINK("#'4.6.1.1-2 Methane'!A1", "4.6.1.1-2 Methane") -> 4.6.1.1-2 Methane
A13: =HYPERLINK("#'4.6.1.3-4 Direct N20'!A1", "4.6.1.3-4 Direct N2O") -> 4.6.1.3-4 Direct N2O
A14: =HYPERLINK("#'4.6.1.5-6 Atmos Dep'!A1", "4.6.1.5-6 Atmospheric deposition") -> 4.6.1.5-6 Atmospheric deposition
A15: =HYPERLINK("#'4.6.1.7-8 Leaching and runoff'!A1", "4.6.1.7-8 Leaching & runoff") -> 4.6.1.7-8 Leaching & runoff
A16: =HYPERLINK("#'4.6.1.9 Manure applied to soils'!A1", "4.6.1.9 Manure applied to soils") -> 4.6.1.9 Manure applied to soils
A17: =HYPERLINK("#'4.6.1.10-11 Soil direct N2O'!A1", "4.6.1.10-11 Soil direct N2O") -> 4.6.1.10-11 Soil direct N2O
A18: =HYPERLINK("#'4.6.1.12-13 Soil atmos dep'!A1", "4.6.1.12-13 Soil Atm. deposition") -> 4.6.1.12-13 Soil Atm. deposition
A19: =HYPERLINK("#'4.6.1.14-15 Soil leach runoff'!A1", "4.6.1.14-15 Soil leach & runoff") -> 4.6.1.14-15 Soil leach & runoff
A21: APPENDICES
A22: =HYPERLINK("#'Constants - Poultry'!A1", "Constants - Poultry") -> Constants - Poultry
A23: =HYPERLINK("#'Constants - Livestock'!A1", "Constants - Livestock") -> Constants - Livestock
A24: =HYPERLINK("#'Constants - Common'!A1", "Constants - Common") -> Constants - Common

Sheet Results
A1: #VALUE! | C1: 4.6 Manure management: Poultry: Results
A3: =HYPERLINK("#'Home'!A1", "Home") -> Home
A4: =HYPERLINK("#'Overview'!A1", "Overview") -> Overview | D4: Emissions breakdown
A5: =HYPERLINK("#'Results'!A1", "Results") -> Results
D6: Scope 1 source | E6: GHG emissions method 1 | F6: GHG emissions method 2 | G6: GHG Unit | H6: CO2-e emissions method 1 | I6: CO2-e emissions method 2 | J6: CO2-e unit
A7: INPUTS | D7: 4.6.1.1-2 Manure methane | E7: ='4.6.1.1-2 Methane'!E222 -> 0.019999321 | F7: ='4.6.1.1-2 Methane'!O222 -> 0.019245864 | G7: t CH4 | H7: ='4.6.1.1-2 Methane'!E227 -> 0.55998099 | I7: ='4.6.1.1-2 Methane'!O227 -> 0.53888418 | J7: t CO2e
A8: =HYPERLINK("#'Input - Site'!A1", "Site") -> Site | D8: 4.6.1.3-4 Direct N2O | E8: ='4.6.1.3-4 Direct N20'!E245 -> 0.00057674955 | F8: ='4.6.1.3-4 Direct N20'!O245 -> 0.00057674955 | G8: t N2O | H8: ='4.6.1.3-4 Direct N20'!E250 -> 0.15283863 | I8: ='4.6.1.3-4 Direct N20'!O250 -> 0.15283863 | J8: t CO2e
A9: =HYPERLINK("#'Input - Poultry'!A1", "Poultry") -> Poultry | D9: 4.6.1.5-6 Atmospheric deposition | E9: ='4.6.1.5-6 Atmos Dep'!E96 -> 0.00022877541 | F9: ='4.6.1.5-6 Atmos Dep'!O96 -> 0.00022877541 | G9: t N2O | H9: ='4.6.1.5-6 Atmos Dep'!E101 -> 0.060625483 | I9: ='4.6.1.5-6 Atmos Dep'!O101 -> 0.060625483 | J9: t CO2e
D10: 4.6.1.7-8 Leaching and runoff | E10: ='4.6.1.7-8 Leaching and runoff'!E59 -> 3.4753311e-06 | F10: ='4.6.1.7-8 Leaching and runoff'!O59 -> 3.4753311e-06 | G10: t N2O | H10: ='4.6.1.7-8 Leaching and runoff'!E64 -> 0.00092096274 | I10: ='4.6.1.7-8 Leaching and runoff'!O64 -> 0.00092096274 | J10: t CO2e
A11: CALCULATIONS | D11: 4.6.1.10-11 Soil direct N2O | E11: ='4.6.1.10-11 Soil direct N2O'!E27 -> 0.00023434149 | F11: ='4.6.1.10-11 Soil direct N2O'!O27 -> 0.00023434149 | G11: t N2O | H11: ='4.6.1.10-11 Soil direct N2O'!E32 -> 0.062100494 | I11: ='4.6.1.10-11 Soil direct N2O'!O32 -> 0.062100494 | J11: t CO2e
A12: =HYPERLINK("#'4.6.1.1-2 Methane'!A1", "4.6.1.1-2 Methane") -> 4.6.1.1-2 Methane | D12: 4.6.1.12-13 Soil Atmospheric deposition | E12: ='4.6.1.12-13 Soil atmos dep'!E45 -> 1.7224099e-05 | F12: ='4.6.1.12-13 Soil atmos dep'!N45 -> 1.7224099e-05 | G12: t N2O | H12: ='4.6.1.12-13 Soil atmos dep'!E50 -> 0.0045643863 | I12: ='4.6.1.12-13 Soil atmos dep'!N50 -> 0.0045643863 | J12: t CO2e
A13: =HYPERLINK("#'4.6.1.3-4 Direct N20'!A1", "4.6.1.3-4 Direct N2O") -> 4.6.1.3-4 Direct N2O | D13: 4.6.1.14-15 Soil leaching and runoff | E13: ='4.6.1.14-15 Soil leach runoff'!E47 -> 2.5777563e-06 | F13: ='4.6.1.14-15 Soil leach runoff'!O47 -> 2.5777563e-06 | G13: t N2O | H13: ='4.6.1.14-15 Soil leach runoff'!E52 -> 0.00068310543 | I13: ='4.6.1.14-15 Soil leach runoff'!O52 -> 0.00068310543 | J13: t CO2e
A14: =HYPERLINK("#'4.6.1.5-6 Atmos Dep'!A1", "4.6.1.5-6 Atmospheric deposition") -> 4.6.1.5-6 Atmospheric deposition | D14: Total | H14: =SUM(H7:H13) -> 0.84171405 | I14: =SUM(I7:I13) -> 0.82061724 | J14: t CO2e
A15: =HYPERLINK("#'4.6.1.7-8 Leaching and runoff'!A1", "4.6.1.7-8 Leaching & runoff") -> 4.6.1.7-8 Leaching & runoff
A16: =HYPERLINK("#'4.6.1.9 Manure applied to soils'!A1", "4.6.1.9 Manure applied to soils") -> 4.6.1.9 Manure applied to soils | D16: 4.6.1.9 Manure applied to soils
A17: =HYPERLINK("#'4.6.1.10-11 Soil direct N2O'!A1", "4.6.1.10-11 Soil direct N2O") -> 4.6.1.10-11 Soil direct N2O | D17: WARNING: Manure nitrogen that was applied to soils must be accounted for
A18: =HYPERLINK("#'4.6.1.12-13 Soil atmos dep'!A1", "4.6.1.12-13 Soil Atm. deposition") -> 4.6.1.12-13 Soil Atm. deposition | D18: See the table below for how to account for manure applied to soils for scope 1 and 3.
A19: =HYPERLINK("#'4.6.1.14-15 Soil leach runoff'!A1", "4.6.1.14-15 Soil leach & runoff") -> 4.6.1.14-15 Soil leach & runoff | D19: Manure nitrogen use | E19: N in manure (Method 1) | F19: N in manure (Method 2) | G19: N unit | H19: Emissions allocated to | I19: VEERG Calculation method
D20: Manure nitrogen deposited on farm soils (including use as fertiliser for other enterprises on own farm eg crops) | E20: ='4.6.1.9 Manure applied to soils'!E121 -> 36.930778 | F20: =VEERG_4_6_1_9__1_MassOfNitrogenAppliedToSoilsScope1_Result_Method2 -> 36.930778 | G20: kg N | H20: Scope 1 - This poultry enterprise | I20: 5.2.2.1 (1), 5.4.1.3 (1, 2), 5.5.1.1 (1, 3)
A21: APPENDICES | D21: Manure nitrogen deposited on farm soils as fertiliser for other farm enterpsies (eg crops) | E21: ='4.6.1.9 Manure applied to soils'!E205 -> 8.9593892 | F21: ='4.6.1.9 Manure applied to soils'!O205 -> 8.9593892 | G21: kg N | H21: Scope 1 - This poultry enterprise | I21: 5.2.2.1 (1), 5.4.1.3 (1, 2), 5.5.1.1 (1, 3)
A22: =HYPERLINK("#'Constants - Poultry'!A1", "Constants - Poultry") -> Constants - Poultry | D22: Manure nitrogen sold | E22: ='4.6.1.9 Manure applied to soils'!E158 -> 8.9593892 | F22: =VEERG_4_6_1_9__2_MassOfNitrogenAppliedToSoilsScope3_Result_Method2 -> 8.9593892 | G22: kg N | H22: Scope 3 (downstream) | I22: 15.13.1.1 (1), 5.2.2.1 (1), 5.4.1.3 (1, 2), 5.5.1.1 (1, 3)
A23: =HYPERLINK("#'Constants - Livestock'!A1", "Constants - Livestock") -> Constants - Livestock
A24: =HYPERLINK("#'Constants - Common'!A1", "Constants - Common") -> Constants - Common

Sheet Input - Site
A1: #VALUE! | C1: Input - Site
A3: =HYPERLINK("#'Home'!A1", "Home") -> Home
A4: =HYPERLINK("#'Overview'!A1", "Overview") -> Overview
A5: =HYPERLINK("#'Results'!A1", "Results") -> Results | D5: Your business
A7: INPUTS | D7: Farm name | E7: Test Farms
A8: =HYPERLINK("#'Input - Site'!A1", "Site") -> Site | D8: Reporting entity name | E8: Test Farms Pty Ltd
A9: =HYPERLINK("#'Input - Poultry'!A1", "Poultry") -> Poultry
D10: 💡An 'Emissions accounting period' is a 12 month period where the business can report on the emissions, and is typically the same as the business' financial accounting period.
A11: CALCULATIONS
A12: =HYPERLINK("#'4.6.1.1-2 Methane'!A1", "4.6.1.1-2 Methane") -> 4.6.1.1-2 Methane | D12: Emissions calculation period start date | E12: 45292 | F12: ← DD/MM/YYYY or DD Month YYYY
A13: =HYPERLINK("#'4.6.1.3-4 Direct N20'!A1", "4.6.1.3-4 Direct N2O") -> 4.6.1.3-4 Direct N2O | D13: Emissions calculation period end date | E13: =DATE(YEAR(E12)+1,MONTH(E12),DAY(E12))-1 -> 45657 | F13: ← Automatically calculated, 12 months after start date
A14: =HYPERLINK("#'4.6.1.5-6 Atmos Dep'!A1", "4.6.1.5-6 Atmospheric deposition") -> 4.6.1.5-6 Atmospheric deposition
A15: =HYPERLINK("#'4.6.1.7-8 Leaching and runoff'!A1", "4.6.1.7-8 Leaching & runoff") -> 4.6.1.7-8 Leaching & runoff
A16: =HYPERLINK("#'4.6.1.9 Manure applied to soils'!A1", "4.6.1.9 Manure applied to soils") -> 4.6.1.9 Manure applied to soils | D16: Location and climate
A17: =HYPERLINK("#'4.6.1.10-11 Soil direct N2O'!A1", "4.6.1.10-11 Soil direct N2O") -> 4.6.1.10-11 Soil direct N2O
A18: =HYPERLINK("#'4.6.1.12-13 Soil atmos dep'!A1", "4.6.1.12-13 Soil Atm. deposition") -> 4.6.1.12-13 Soil Atm. deposition | D18: Location information is used to reference some region and climate-specific emission factors
A19: =HYPERLINK("#'4.6.1.14-15 Soil leach runoff'!A1", "4.6.1.14-15 Soil leach & runoff") -> 4.6.1.14-15 Soil leach & runoff | D19: Tip: Use the web-based GAF Location Helper tool to easily get region and climate information. You will need an internet connection to use the GAF Location Helper.
A21: APPENDICES | D21: State | E21: Western Australia | F21: ← Please select
A22: =HYPERLINK("#'Constants - Poultry'!A1", "Constants - Poultry") -> Constants - Poultry | D22: Region (ABS Statistical area level 4) if state is WA | E22: Western Australia - Outback (South) | F22: ← Please select
A23: =HYPERLINK("#'Constants - Livestock'!A1", "Constants - Livestock") -> Constants - Livestock | D23: Leaching zone | E23: NO - Not in leaching zone | F23: ← Please select
A24: =HYPERLINK("#'Constants - Common'!A1", "Constants - Common") -> Constants - Common | D24: Elevation | E24: 307.7 | F24: Meters
D25: Average temperature for reporting period | E25: 18 | F25: Degrees celsius
D26: Total rainfall for reporting period | E26: 601 | F26: Millimetres
D27: Potential evapotranspiration for reporting period | E27: 1326 | F27: Millimetres
D28: Number of frost days for reporting period | E28: 7 | F28: Days
D29: MAP:PET ratio | E29: =E26/E27 -> 0.45324284
D30: Rainfall zone | E30: =Common_InputFunctions.Utility_LookupItemFromMinMax(E26,Table_SourceData_RainfallZones[Min rainfall],Table_SourceData_RainfallZones[Max rainfall],Table_SourceData_RainfallZones[Rainfall Zone]) -> High rainfall
D31: Climate zone | E31: =Common_InputFunctions.Utility_GetClimateZone(E25,E26,E28,E24,E29,Table_SourceData_ClimateZones[Min temp],Table_SourceData_ClimateZones[Max temp],Table_SourceData_ClimateZones[Min rainfall],Table_SourceData_ClimateZones[Max rainfall],Table_SourceData_ClimateZones[Min frost days],Table_SourceData_ClimateZones[Max frost days],Table_SourceData_ClimateZones[Min elevation],Table_SourceData_ClimateZones[Max elevation],Table_SourceData_ClimateZones[Min MAP:PET],Table_SourceData_ClimateZones[Max MAP:PET],Table_SourceData_ClimateZones[Climate zone]) -> Warm temperate dry
D32: Wet or dry climate zone | E32: =Common_InputFunctions.Utility_LookupValueInTable($E$31,Table_SourceData_WetDryZones[Climate zone],Table_SourceData_WetDryZones[Wet or Dry Zone]) -> Dry climate zone
D33: Temperature zone | E33: =Common_InputFunctions.Utility_LookupItemFromMinMax(E25,Table_SourceData_TemperatureZones[Min MAT],Table_SourceData_TemperatureZones[Max MAT],Table_SourceData_TemperatureZones[Temperature Zone]) -> Temperate

Sheet Input - Poultry
A1: #VALUE! | C1: Input -Poultry
A3: =HYPERLINK("#'Home'!A1", "Home") -> Home
A4: =HYPERLINK("#'Overview'!A1", "Overview") -> Overview
A5: =HYPERLINK("#'Results'!A1", "Results") -> Results | D5: This tool demostrates inputs for one production system.
A7: INPUTS
A8: =HYPERLINK("#'Input - Site'!A1", "Site") -> Site
A9: =HYPERLINK("#'Input - Poultry'!A1", "Poultry") -> Poultry | E9: Layers | F9: Meat chicken growers | G9: Meat chicken breeders | H9: Other
D10: ="Average duration of stay between " & TEXT('Input - Site'!$E$12, "dd mmm yy") & " and " & TEXT('Input - Site'!$E$13, "dd mmm yy") -> Average duration of stay between 01 Jan 24 and 31 Dec 24 | E10: 365 | F10: 365 | G10: 365 | H10: 365 | I10: Days
A11: CALCULATIONS | D11: ="Average number of birds between " & TEXT('Input - Site'!$E$12, "dd mmm yy") & " and " & TEXT('Input - Site'!$E$13, "dd mmm yy") -> Average number of birds between 01 Jan 24 and 31 Dec 24 | E11: 100 | F11: 100 | G11: 100 | H11: 100 | I11: Head
A12: =HYPERLINK("#'4.6.1.1-2 Methane'!A1", "4.6.1.1-2 Methane") -> 4.6.1.1-2 Methane
A13: =HYPERLINK("#'4.6.1.3-4 Direct N20'!A1", "4.6.1.3-4 Direct N2O") -> 4.6.1.3-4 Direct N2O | D13: Manure production
A14: =HYPERLINK("#'4.6.1.5-6 Atmos Dep'!A1", "4.6.1.5-6 Atmospheric deposition") -> 4.6.1.5-6 Atmospheric deposition
A15: =HYPERLINK("#'4.6.1.7-8 Leaching and runoff'!A1", "4.6.1.7-8 Leaching & runoff") -> 4.6.1.7-8 Leaching & runoff | D15: Method 1 default values (Do not edit) | E15: Layers | F15: Meat chicken growers | G15: Meat chicken breeders | H15: Other
A16: =HYPERLINK("#'4.6.1.9 Manure applied to soils'!A1", "4.6.1.9 Manure applied to soils") -> 4.6.1.9 Manure applied to soils | D16: Dry matter intake | E16: ='Constants - Poultry'!E9 -> 0.086 | F16: ='Constants - Poultry'!F9 -> 0.093 | G16: ='Constants - Poultry'!G9 -> 0.103 | H16: ='Constants - Poultry'!H9 -> 0.093 | I16: kg/DM/bird/day
A17: =HYPERLINK("#'4.6.1.10-11 Soil direct N2O'!A1", "4.6.1.10-11 Soil direct N2O") -> 4.6.1.10-11 Soil direct N2O | D17: Dry matter digestibility (DMD) | E17: ='Constants - Poultry'!E10 -> 0.8 | F17: ='Constants - Poultry'!F10 -> 0.8 | G17: ='Constants - Poultry'!G10 -> 0.8 | H17: ='Constants - Poultry'!H10 -> 0.8 | I17: fraction
A18: =HYPERLINK("#'4.6.1.12-13 Soil atmos dep'!A1", "4.6.1.12-13 Soil Atm. deposition") -> 4.6.1.12-13 Soil Atm. deposition | D18: Crude protein (CP) | E18: ='Constants - Poultry'!E11 -> 0.19 | F18: ='Constants - Poultry'!F11 -> 0.23 | G18: ='Constants - Poultry'!G11 -> 0.19 | H18: ='Constants - Poultry'!H11 -> 0.23 | I18: fraction
A19: =HYPERLINK("#'4.6.1.14-15 Soil leach runoff'!A1", "4.6.1.14-15 Soil leach & runoff") -> 4.6.1.14-15 Soil leach & runoff
D20: Method 2 custom values (Edit if known) | E20: Layers | F20: Meat chicken growers | G20: Meat chicken breeders | H20: Other
A21: APPENDICES | D21: Dry matter intake | E21: ='Constants - Poultry'!E9 -> 0.086 | F21: ='Constants - Poultry'!F9 -> 0.093 | G21: ='Constants - Poultry'!G9 -> 0.103 | H21: ='Constants - Poultry'!H9 -> 0.093 | I21: kg/DM/bird/day
A22: =HYPERLINK("#'Constants - Poultry'!A1", "Constants - Poultry") -> Constants - Poultry | D22: Dry matter digestibility (DMD) | E22: ='Constants - Poultry'!E10 -> 0.8 | F22: ='Constants - Poultry'!F10 -> 0.8 | G22: ='Constants - Poultry'!G10 -> 0.8 | H22: ='Constants - Poultry'!H10 -> 0.8 | I22: fraction
A23: =HYPERLINK("#'Constants - Livestock'!A1", "Constants - Livestock") -> Constants - Livestock | D23: Crude protein (CP) | E23: ='Constants - Poultry'!E11 -> 0.19 | F23: ='Constants - Poultry'!F11 -> 0.23 | G23: ='Constants - Poultry'!G11 -> 0.19 | H23: ='Constants - Poultry'!H11 -> 0.23 | I23: fraction
A24: =HYPERLINK("#'Constants - Common'!A1", "Constants - Common") -> Constants - Common
D25: Manure management systems
D27: Production system | E27: Cage | F27: ← Please select
D29: Stage 1 MMS | E29: Layers | F29: Meat chicken growers | G29: Meat chicken breeders | H29: Other
D30: ='Constants - Poultry'!G29 -> Poultry manure with bedding | E30: 0.3 | F30: 0.3 | G30: 0.3 | H30: 0.3 | I30: Percent
D31: ='Constants - Poultry'!G30 -> Belt manure removal | E31: 0.3 | F31: 0.3 | G31: 0.3 | H31: 0.3 | I31: Percent
D32: ='Constants - Poultry'!G31 -> Manure stored in house | E32: 0.3 | F32: 0.3 | G32: 0.3 | H32: 0.3 | I32: Percent
D33: ='Constants - Poultry'!G32 -> Pasture range and paddock | E33: 0.1 | F33: 0.1 | G33: 0.1 | H33: 0.1 | I33: Percent
D34: Total sent to all MMS (Must equal 100%) | E34: =SUM(E30,E31,E32,E33) -> 1 | F34: =SUM(F30,F31,F32,F33) -> 1 | G34: =SUM(G30,G31,G32,G33) -> 1 | H34: =SUM(H30,H31,H32,H33) -> 1
D35: ▼
D36: Stage 2 MMS | E36: Layers | F36: Meat chicken growers | G36: Meat chicken breeders | H36: Other | I36: ► | K36: Destination after stage 2 MMS (Percent)
D37: ="From stage 1: " & $D$30 -> From stage 1: Poultry manure with bedding | E37: =IF(SUM(E30:H30)>0,"Manure was sent to this MMS, please complete this section.","No manure was sent to this MMS. Leave this section blank.") -> Manure was sent to this MMS, please complete this section. | K37: Sold | L37: Fert for own farm (eg crop) | M37: Direct application to soil
D38: ='Constants - Poultry'!$J$29 -> Solid storage | E38: 0.2 | F38: 0.2 | G38: 0.2 | H38: 0.2 | I38: Percent | K38: 0.25 | L38: 0.25 | M38: =1-SUM(K38:L38) -> 0.5
D39: ='Constants - Poultry'!$J$30 -> Composting (passive windrow) | E39: 0.2 | F39: 0.2 | G39: 0.2 | H39: 0.2 | I39: Percent | K39: 0.25 | L39: 0.25 | M39: =1-SUM(K39:L39) -> 0.5
D40: ='Constants - Poultry'!$J$31 -> Digester / covered lagoons | E40: 0.2 | F40: 0.2 | G40: 0.2 | H40: 0.2 | I40: Percent | K40: 0.25 | L40: 0.25 | M40: =1-SUM(K40:L40) -> 0.5
D41: ='Constants - Poultry'!$J$32 -> Direct processing | E41: 0.2 | F41: 0.2 | G41: 0.2 | H41: 0.2 | I41: Percent | K41: 0.25 | L41: 0.25 | M41: =1-SUM(K41:L41) -> 0.5
D42: ='Constants - Poultry'!$J$33 -> Direct application | E42: =1-SUM(E38:E41) -> 0.2 | F42: =1-SUM(F38:F41) -> 0.2 | G42: =1-SUM(G38:G41) -> 0.2 | H42: =1-SUM(H38:H41) -> 0.2 | I42: Percent | K42: 0 | L42: 0 | M42: =1-SUM(K42:L42) -> 1
D44: ="From stage 1: " & $D$31 -> From stage 1: Belt manure removal | E44: =IF(SUM(E31:H31)>0,"Manure was sent to this MMS, please complete this section.","No manure was sent to this MMS. Leave this section blank.") -> Manure was sent to this MMS, please complete this section. | K44: Sold | L44: Fert for own farm (eg crop) | M44: Direct application to soil
D45: ='Constants - Poultry'!$J$29 -> Solid storage | E45: 0.2 | F45: 0.2 | G45: 0.2 | H45: 0.2 | I45: Percent | K45: 0.25 | L45: 0.25 | M45: =1-SUM(K45:L45) -> 0.5
...

Sheet 4.6.1.1-2 Methane
A1: #VALUE! | C1: 4.6.1.1-2 Manure Methane
A3: =HYPERLINK("#'Home'!A1", "Home") -> Home | D3: Method 1 | N3: Method 2
A4: =HYPERLINK("#'Overview'!A1", "Overview") -> Overview
A5: =HYPERLINK("#'Results'!A1", "Results") -> Results | D5: {=MMS_Poultry_Methane_Equations.VEERG_4_6_1_1__5_VolatileSolidProduction_Title()} -> Volatile solid production poultry classes
D6: {=MMS_Poultry_Methane_Equations.VEERG_4_6_1_1__5_VolatileSolidProduction_Source()} -> VEERG 2026: 4.4.1.1, Equation (5)
A7: INPUTS | D7: Function name | E7: {=Common_InputFunctions.Utility_DisplayFunctionName(D35)} -> =MMS_Poultry_Methane_Equations.VEERG_4_6_1_1__5_VolatileSolidProduction
A8: =HYPERLINK("#'Input - Site'!A1", "Site") -> Site
A9: =HYPERLINK("#'Input - Poultry'!A1", "Poultry") -> Poultry
D10: Variable | E10: {=MMS_Poultry_Methane_Equations.VEERG_4_6_1_1__5_VolatileSolidProduction_Variable()} -> VS_jk
A11: CALCULATIONS | D11: Unit | E11: {=MMS_Poultry_Methane_Equations.VEERG_4_6_1_1__5_VolatileSolidProduction_Unit()} -> kg VS/bird/day
A12: =HYPERLINK("#'4.6.1.1-2 Methane'!A1", "4.6.1.1-2 Methane") -> 4.6.1.1-2 Methane
A13: =HYPERLINK("#'4.6.1.3-4 Direct N20'!A1", "4.6.1.3-4 Direct N2O") -> 4.6.1.3-4 Direct N2O | D13: {=_xlfn.CHOOSECOLS(MMS_Poultry_Methane_Equations.VEERG_4_6_1_1__5_VolatileSolidProduction_Arguments(),1,2)} -> I_jk | E13: dry matter intake for each class and subclass | G13: {=_xlfn.CHOOSECOLS(MMS_Poultry_Methane_Equations.VEERG_4_6_1_1__5_VolatileSolidProduction_Arguments(),3,4)} -> kg DM/bird/day | H13: Input | I13: {=HYPERLINK(Common_InputFunctions.Utility_SourceHyperlink($D$17), $D$17)} -> M1_Table_I_j_k
A14: =HYPERLINK("#'4.6.1.5-6 Atmos Dep'!A1", "4.6.1.5-6 Atmospheric deposition") -> 4.6.1.5-6 Atmospheric deposition | D14: DMD_jk | E14: dry matter digestibility for each class and subclass | G14: fraction | H14: Input | I14: {=HYPERLINK(Common_InputFunctions.Utility_SourceHyperlink($D$22), $D$22)} -> M1_Table_DMD_j_k
A15: =HYPERLINK("#'4.6.1.7-8 Leaching and runoff'!A1", "4.6.1.7-8 Leaching & runoff") -> 4.6.1.7-8 Leaching & runoff | D15: A_j | E15: ash content of manure for each class and subclass | G15: fraction | H15: Constant | I15: {=HYPERLINK(Common_InputFunctions.Utility_SourceHyperlink($D$32), $D$32)} -> M1_Table_VS_j_k
A16: =HYPERLINK("#'4.6.1.9 Manure applied to soils'!A1", "4.6.1.9 Manure applied to soils") -> 4.6.1.9 Manure applied to soils
A17: =HYPERLINK("#'4.6.1.10-11 Soil direct N2O'!A1", "4.6.1.10-11 Soil direct N2O") -> 4.6.1.10-11 Soil direct N2O | D17: M1_Table_I_j_k | N17: M2_Table_I_j_k
A18: =HYPERLINK("#'4.6.1.12-13 Soil atmos dep'!A1", "4.6.1.12-13 Soil Atm. deposition") -> 4.6.1.12-13 Soil Atm. deposition | D18: Dry matter intake (Method 1) | N18: Dry matter intake (Method 2)
A19: =HYPERLINK("#'4.6.1.14-15 Soil leach runoff'!A1", "4.6.1.14-15 Soil leach & runoff") -> 4.6.1.14-15 Soil leach & runoff | D19: Layers | E19: Meat chicken growers | F19: Meat chicken breeders | G19: Other | N19: Layers | O19: Meat chicken growers | P19: Meat chicken breeders | Q19: Other
D20: ='Input - Poultry'!E16 -> 0.086 | E20: ='Input - Poultry'!F16 -> 0.093 | F20: ='Input - Poultry'!G16 -> 0.103 | G20: ='Input - Poultry'!H16 -> 0.093 | H20: =$G$13 -> kg DM/bird/day | N20: ='Input - Poultry'!E21 -> 0.086 | O20: ='Input - Poultry'!F21 -> 0.093 | P20: ='Input - Poultry'!G21 -> 0.103 | Q20: ='Input - Poultry'!H21 -> 0.093 | R20: =$G$13 -> kg DM/bird/day
A21: APPENDICES
A22: =HYPERLINK("#'Constants - Poultry'!A1", "Constants - Poultry") -> Constants - Poultry | D22: M1_Table_DMD_j_k | N22: M2_Table_DMD_j_k
A23: =HYPERLINK("#'Constants - Livestock'!A1", "Constants - Livestock") -> Constants - Livestock | D23: Dry matter digestibility (Method 1) | N23: Dry matter digestibility (Method 2)
A24: =HYPERLINK("#'Constants - Common'!A1", "Constants - Common") -> Constants - Common | D24: Layers | E24: Meat chicken growers | F24: Meat chicken breeders | G24: Other | N24: Layers | O24: Meat chicken growers | P24: Meat chicken breeders | Q24: Other
D25: ='Input - Poultry'!E17 -> 0.8 | E25: ='Input - Poultry'!F17 -> 0.8 | F25: ='Input - Poultry'!G17 -> 0.8 | G25: ='Input - Poultry'!H17 -> 0.8 | H25: =$G$14 -> fraction | N25: ='Input - Poultry'!E22 -> 0.8 | O25: ='Input - Poultry'!F22 -> 0.8 | P25: ='Input - Poultry'!G22 -> 0.8 | Q25: ='Input - Poultry'!H22 -> 0.8 | R25: =$G$14 -> fraction
D27: Table_A_j
D28: Ash content of manure
D29: Layers | E29: Meat chicken growers | F29: Meat chicken breeders | G29: Other
D30: ='Constants - Poultry'!E13 -> 0.18 | E30: ='Constants - Poultry'!F13 -> 0.15 | F30: ='Constants - Poultry'!G13 -> 0.18 | G30: ='Constants - Poultry'!H13 -> 0.15 | H30: =$G$15 -> fraction
D32: M1_Table_VS_j_k | N32: M2_Table_VS_j_k
D33: Volatile solid production (Method 1) | N33: Volatile solid production (Method 2)
D34: Layers | E34: Meat chicken growers | F34: Meat chicken breeders | G34: Other | N34: Layers | O34: Meat chicken growers | P34: Meat chicken breeders | Q34: Other
D35: {=MMS_Poultry_Methane_Equations.VEERG_4_6_1_1__5_VolatileSolidProduction(D20,D25,D30)} -> 0.014104 | E35: {=MMS_Poultry_Methane_Equations.VEERG_4_6_1_1__5_VolatileSolidProduction(E20,E25,E30)} -> 0.01581 | F35: {=MMS_Poultry_Methane_Equations.VEERG_4_6_1_1__5_VolatileSolidProduction(F20,F25,F30)} -> 0.016892 | G35: {=MMS_Poultry_Methane_Equations.VEERG_4_6_1_1__5_VolatileSolidProduction(G20,G25,G30)} -> 0.01581 | H35: =$E$11 -> kg VS/bird/day | N35: {=MMS_Poultry_Methane_Equations.VEERG_4_6_1_1__5_VolatileSolidProduction(N20,N25,D30)} -> 0.014104 | O35: {=MMS_Poultry_Methane_Equations.VEERG_4_6_1_1__5_VolatileSolidProduction(O20,O25,E30)} -> 0.01581 | P35: {=MMS_Poultry_Methane_Equations.VEERG_4_6_1_1__5_VolatileSolidProduction(P20,P25,F30)} -> 0.016892 | Q35: {=MMS_Poultry_Methane_Equations.VEERG_4_6_1_1__5_VolatileSolidProduction(Q20,Q25,G30)} -> 0.01581 | R35: =$E$11 -> kg VS/bird/day
D39: {=MMS_Poultry_Methane_Equations.VEERG_4_6_1_1__2_Stage1MethaneProduction_Title()} -> Production of methane in treatment stage 1 MMS
D40: {=MMS_Poultry_Methane_Equations.VEERG_4_6_1_1__2_Stage1MethaneProduction_Source()} -> VEERG 2026: 4.4.1.1, Equation (2)
D41: {=MMS_Poultry_Methane_Equations.VEERG_4_6_1_1__2_Stage1MethaneProduction_Variation()} -> VARIATION ON SOURCE:
D42: Used mean annual temperature instead of temperature zone to determine MCF as MCF values are specific to temperature
D43: Method 2: Used state based MCF values for 'Belt manure removal' and 'Manure stored in house' MMS as no temperature values exist in Table A.1.8.1
D44: Function name | E44: {=Common_InputFunctions.Utility_DisplayFunctionName(E86)} -> =MMS_Poultry_Methane_Equations.VEERG_4_6_1_1__2_Stage1MethaneProduction
D47: Variable | E47: {=MMS_Poultry_Methane_Equations.VEERG_4_6_1_1__2_Stage1MethaneProduction_Variable()} -> M_jkmT1
D48: Unit | E48: {=MMS_Poultry_Methane_Equations.VEERG_4_6_1_1__2_Stage1MethaneProduction_Unit()} -> kg CH4/bird/day
...

Sheet 4.6.1.3-4 Direct N20
A1: #VALUE! | C1: 4.6.1.3-4 Manure Direct N2O
A3: =HYPERLINK("#'Home'!A1", "Home") -> Home | D3: Method 1 | N3: Method 2
A4: =HYPERLINK("#'Overview'!A1", "Overview") -> Overview
A5: =HYPERLINK("#'Results'!A1", "Results") -> Results | D5: {=MMS_Poultry_N2ODirect_Equations.VEERG_4_6_1_3__5_NitrogenIntake_Title()} -> Nitrogen intake of poultry
D6: {=MMS_Poultry_N2ODirect_Equations.VEERG_4_6_1_3__5_NitrogenIntake_Source()} -> VEERG 2026: 4.6.1.3, Equation (5)
A7: INPUTS | D7: Function name | E7: {=Common_InputFunctions.Utility_DisplayFunctionName(D30)} -> =MMS_Poultry_N2ODirect_Equations.VEERG_4_6_1_3__5_NitrogenIntake
A8: =HYPERLINK("#'Input - Site'!A1", "Site") -> Site
A9: =HYPERLINK("#'Input - Poultry'!A1", "Poultry") -> Poultry
D10: Variable | E10: {=MMS_Poultry_N2ODirect_Equations.VEERG_4_6_1_3__5_NitrogenIntake_Variable()} -> NI_jk
A11: CALCULATIONS | D11: Unit | E11: {=MMS_Poultry_N2ODirect_Equations.VEERG_4_6_1_3__5_NitrogenIntake_Unit()} -> kg N/bird/day
A12: =HYPERLINK("#'4.6.1.1-2 Methane'!A1", "4.6.1.1-2 Methane") -> 4.6.1.1-2 Methane
A13: =HYPERLINK("#'4.6.1.3-4 Direct N20'!A1", "4.6.1.3-4 Direct N2O") -> 4.6.1.3-4 Direct N2O | D13: {=_xlfn.CHOOSECOLS(MMS_Poultry_N2ODirect_Equations.VEERG_4_6_1_3__5_NitrogenIntake_Arguments(),1,2)} -> I_jk | E13: dry matter intake for each class and subclass | G13: {=_xlfn.CHOOSECOLS(MMS_Poultry_N2ODirect_Equations.VEERG_4_6_1_3__5_NitrogenIntake_Arguments(),3,4)} -> kg DM/bird/day | H13: Input | I13: {=HYPERLINK(Common_InputFunctions.Utility_SourceHyperlink($D$17),$D$17)} -> M1_Table_I_j_k
A14: =HYPERLINK("#'4.6.1.5-6 Atmos Dep'!A1", "4.6.1.5-6 Atmospheric deposition") -> 4.6.1.5-6 Atmospheric deposition | D14: CP_jk | E14: crude protein content of feed | G14: fraction | H14: Input | I14: {=HYPERLINK(Common_InputFunctions.Utility_SourceHyperlink($D$22),$D$22)} -> M1_Table_CP_j_k
A15: =HYPERLINK("#'4.6.1.7-8 Leaching and runoff'!A1", "4.6.1.7-8 Leaching & runoff") -> 4.6.1.7-8 Leaching & runoff | D15: 6.25 | E15: factor for converting crude protein into nitrogen | G15: ratio | H15: Constant | I15: =$D$15 -> 6.25
A16: =HYPERLINK("#'4.6.1.9 Manure applied to soils'!A1", "4.6.1.9 Manure applied to soils") -> 4.6.1.9 Manure applied to soils
A17: =HYPERLINK("#'4.6.1.10-11 Soil direct N2O'!A1", "4.6.1.10-11 Soil direct N2O") -> 4.6.1.10-11 Soil direct N2O | D17: M1_Table_I_j_k | N17: M2_Table_I_j_k
A18: =HYPERLINK("#'4.6.1.12-13 Soil atmos dep'!A1", "4.6.1.12-13 Soil Atm. deposition") -> 4.6.1.12-13 Soil Atm. deposition | D18: Dry matter intake (Method 1) | N18: Dry matter intake (Method 2)
A19: =HYPERLINK("#'4.6.1.14-15 Soil leach runoff'!A1", "4.6.1.14-15 Soil leach & runoff") -> 4.6.1.14-15 Soil leach & runoff | D19: Layers | E19: Meat chicken growers | F19: Meat chicken breeders | G19: Other | N19: Layers | O19: Meat chicken growers | P19: Meat chicken breeders | Q19: Other
D20: ='Input - Poultry'!E16 -> 0.086 | E20: ='Input - Poultry'!F16 -> 0.093 | F20: ='Input - Poultry'!G16 -> 0.103 | G20: ='Input - Poultry'!H16 -> 0.093 | H20: =$G$13 -> kg DM/bird/day | N20: ='Input - Poultry'!E21 -> 0.086 | O20: ='Input - Poultry'!F21 -> 0.093 | P20: ='Input - Poultry'!G21 -> 0.103 | Q20: ='Input - Poultry'!H21 -> 0.093 | R20: =$G$13 -> kg DM/bird/day
A21: APPENDICES
A22: =HYPERLINK("#'Constants - Poultry'!A1", "Constants - Poultry") -> Constants - Poultry | D22: M1_Table_CP_j_k | N22: M2_Table_CP_j_k
A23: =HYPERLINK("#'Constants - Livestock'!A1", "Constants - Livestock") -> Constants - Livestock | D23: Crude protein content of feed (Method 1) | N23: Crude protein content of feed (Method 2)
A24: =HYPERLINK("#'Constants - Common'!A1", "Constants - Common") -> Constants - Common | D24: Layers | E24: Meat chicken growers | F24: Meat chicken breeders | G24: Other | N24: Layers | O24: Meat chicken growers | P24: Meat chicken breeders | Q24: Other
D25: ='Input - Poultry'!E18 -> 0.19 | E25: ='Input - Poultry'!F18 -> 0.23 | F25: ='Input - Poultry'!G18 -> 0.19 | G25: ='Input - Poultry'!H18 -> 0.23 | H25: =$G$14 -> fraction | N25: ='Input - Poultry'!E23 -> 0.19 | O25: ='Input - Poultry'!F23 -> 0.23 | P25: ='Input - Poultry'!G23 -> 0.19 | Q25: ='Input - Poultry'!H23 -> 0.23 | R25: =$G$14 -> fraction
D27: M1_Table_NI_j_k | N27: M2_Table_NI_j_k
D28: Nitrogen intake (Method 1) | N28: Nitrogen intake (Method 2)
D29: Layers | E29: Meat chicken growers | F29: Meat chicken breeders | G29: Other | N29: Layers | O29: Meat chicken growers | P29: Meat chicken breeders | Q29: Other
D30: {=MMS_Poultry_N2ODirect_Equations.VEERG_4_6_1_3__5_NitrogenIntake(D20,D25)} -> 0.0026144 | E30: {=MMS_Poultry_N2ODirect_Equations.VEERG_4_6_1_3__5_NitrogenIntake(E20,E25)} -> 0.0034224 | F30: {=MMS_Poultry_N2ODirect_Equations.VEERG_4_6_1_3__5_NitrogenIntake(F20,F25)} -> 0.0031312 | G30: {=MMS_Poultry_N2ODirect_Equations.VEERG_4_6_1_3__5_NitrogenIntake(G20,G25)} -> 0.0034224 | H30: =$E$11 -> kg N/bird/day | N30: {=MMS_Poultry_N2ODirect_Equations.VEERG_4_6_1_3__5_NitrogenIntake(N20,N25)} -> 0.0026144 | O30: {=MMS_Poultry_N2ODirect_Equations.VEERG_4_6_1_3__5_NitrogenIntake(O20,O25)} -> 0.0034224 | P30: {=MMS_Poultry_N2ODirect_Equations.VEERG_4_6_1_3__5_NitrogenIntake(P20,P25)} -> 0.0031312 | Q30: {=MMS_Poultry_N2ODirect_Equations.VEERG_4_6_1_3__5_NitrogenIntake(Q20,Q25)} -> 0.0034224 | R30: =$E$11 -> kg N/bird/day
D34: {=MMS_Poultry_N2ODirect_Equations.VEERG_4_6_1_3__4_NitrogenExcretionPerBird_Title()} -> Nitrogen excretion per bird per day
D35: {=MMS_Poultry_N2ODirect_Equations.VEERG_4_6_1_3__4_NitrogenExcretionPerBird_Source()} -> VEERG 2026: 4.6.1.3, Equation (4)
D36: Function name | E36: {=Common_InputFunctions.Utility_DisplayFunctionName(D53)} -> =MMS_Poultry_N2ODirect_Equations.VEERG_4_6_1_3__4_NitrogenExcretionPerBird
D39: Variable | E39: {=MMS_Poultry_N2ODirect_Equations.VEERG_4_6_1_3__4_NitrogenExcretionPerBird_Variable()} -> NE_jk
D40: Unit | E40: {=MMS_Poultry_N2ODirect_Equations.VEERG_4_6_1_3__4_NitrogenExcretionPerBird_Unit()} -> kg N/bird/day
D42: {=_xlfn.CHOOSECOLS(MMS_Poultry_N2ODirect_Equations.VEERG_4_6_1_3__4_NitrogenExcretionPerBird_Arguments(),1,2)} -> NI_jk | E42: nitrogen intake | G42: {=_xlfn.CHOOSECOLS(MMS_Poultry_N2ODirect_Equations.VEERG_4_6_1_3__4_NitrogenExcretionPerBird_Arguments(),3,4)} -> kg N/bird/day | H42: Calculated from 4.6.1.3 (5) | I42: {=HYPERLINK(Common_InputFunctions.Utility_SourceHyperlink($D$27),$D$27)} -> M1_Table_NI_j_k
D43: NR_jk | E43: nitrogen retention expressed as a fraction of intake | G43: fraction | H43: Constant | I43: {=HYPERLINK(Common_InputFunctions.Utility_SourceHyperlink($D$45),$D$45)} -> Table_NR_j_k
D45: Table_NR_j_k
D46: Nitrogen retention rate
D47: Layers | E47: Meat chicken growers | F47: Meat chicken breeders | G47: Other
D48: ='Constants - Poultry'!E12 -> 0.35 | E48: ='Constants - Poultry'!F12 -> 0.47 | F48: ='Constants - Poultry'!G12 -> 0.32 | G48: ='Constants - Poultry'!H12 -> 0.47 | H48: =$G$43 -> fraction
D50: M1_Table_NE_j_k | N50: M2_Table_NE_j_k
...

Sheet 4.6.1.5-6 Atmos Dep
A1: #VALUE! | C1: 4.6.1.5-6 Atmospheric deposition N2O
A3: =HYPERLINK("#'Home'!A1", "Home") -> Home | D3: Method 1 | N3: Method 2
A4: =HYPERLINK("#'Overview'!A1", "Overview") -> Overview
A5: =HYPERLINK("#'Results'!A1", "Results") -> Results | D5: {=MMS_Poultry_AtmosphericDeposition_Equations.VEERG_4_6_1_5__2_TotalNitrogenVolatilisedFromMMS_Title()} -> Total nitrogen volatilised from manure management systems
D6: {=MMS_Poultry_AtmosphericDeposition_Equations.VEERG_4_6_1_5__2_TotalNitrogenVolatilisedFromMMS_Source()} -> VEERG 2026: 4.6.1.5, Equation (2)
A7: INPUTS | D7: Function name | E7: {=Common_InputFunctions.Utility_DisplayFunctionName(F57)} -> =MMS_Poultry_AtmosphericDeposition_Equations.VEERG_4_6_1_5__2_TotalNitrogenVolatilisedFromMMS
A8: =HYPERLINK("#'Input - Site'!A1", "Site") -> Site
A9: =HYPERLINK("#'Input - Poultry'!A1", "Poultry") -> Poultry
D10: Variable | E10: {=MMS_Poultry_AtmosphericDeposition_Equations.VEERG_4_6_1_5__2_TotalNitrogenVolatilisedFromMMS_Variable()} -> MMS_ATMOS
A11: CALCULATIONS | D11: Unit | E11: {=MMS_Poultry_AtmosphericDeposition_Equations.VEERG_4_6_1_5__2_TotalNitrogenVolatilisedFromMMS_Unit()} -> kg N
A12: =HYPERLINK("#'4.6.1.1-2 Methane'!A1", "4.6.1.1-2 Methane") -> 4.6.1.1-2 Methane
A13: =HYPERLINK("#'4.6.1.3-4 Direct N20'!A1", "4.6.1.3-4 Direct N2O") -> 4.6.1.3-4 Direct N2O | D13: {=_xlfn.CHOOSECOLS(MMS_Poultry_AtmosphericDeposition_Equations.VEERG_4_6_1_5__2_TotalNitrogenVolatilisedFromMMS_Arguments(),1,2)} -> MN_jkmT | E13: nitrogen in each treatment stage MMS (excluding MN_jkm13T2) | G13: {=_xlfn.CHOOSECOLS(MMS_Poultry_AtmosphericDeposition_Equations.VEERG_4_6_1_5__2_TotalNitrogenVolatilisedFromMMS_Arguments(),3,4)} -> kg N | H13: Calculated from 4.6.1.3 (2)(6) | I13: {=HYPERLINK(Common_InputFunctions.Utility_SourceHyperlink($D$19),$D$19)} -> M1_Table_MN_j_k_m_T
A14: =HYPERLINK("#'4.6.1.5-6 Atmos Dep'!A1", "4.6.1.5-6 Atmospheric deposition") -> 4.6.1.5-6 Atmospheric deposition | D14: FracGASM_mT | E14: fraction of N volatilised in each MMS | G14: (kg NH3-N + NOx-N)/kg N | H14: Constant | I14: {=HYPERLINK(Common_InputFunctions.Utility_SourceHyperlink($D$42),$D$42)} -> Table_FracGASM_m_T
A15: =HYPERLINK("#'4.6.1.7-8 Leaching and runoff'!A1", "4.6.1.7-8 Leaching & runoff") -> 4.6.1.7-8 Leaching & runoff
A16: =HYPERLINK("#'4.6.1.9 Manure applied to soils'!A1", "4.6.1.9 Manure applied to soils") -> 4.6.1.9 Manure applied to soils | D16: Note: Manure that is directly applied to soil after stage 1 is not included in Atmospheric Deposition calculations
A17: =HYPERLINK("#'4.6.1.10-11 Soil direct N2O'!A1", "4.6.1.10-11 Soil direct N2O") -> 4.6.1.10-11 Soil direct N2O | D17: and instead is handled in 'Manure applied to soils'.
A18: =HYPERLINK("#'4.6.1.12-13 Soil atmos dep'!A1", "4.6.1.12-13 Soil Atm. deposition") -> 4.6.1.12-13 Soil Atm. deposition
A19: =HYPERLINK("#'4.6.1.14-15 Soil leach runoff'!A1", "4.6.1.14-15 Soil leach & runoff") -> 4.6.1.14-15 Soil leach & runoff | D19: M1_Table_MN_j_k_m_T | N19: M2_Table_MN_j_k_m_T
D20: Nitrogen in each MMS (Method 1) | N20: Nitrogen in each MMS (Method 2)
A21: APPENDICES | D21: Stage 1 MMS | E21: Stage 2 MMS | F21: Layers | G21: Meat chicken growers | H21: Meat chicken breeders | I21: Other | N21: Stage 1 MMS | O21: Stage 2 MMS | P21: Layers | Q21: Meat chicken growers | R21: Meat chicken breeders | S21: Other
A22: =HYPERLINK("#'Constants - Poultry'!A1", "Constants - Poultry") -> Constants - Poultry | D22: ='Input - Poultry'!$D$30 -> Poultry manure with bedding | E22: N/A | F22: ='4.6.1.3-4 Direct N20'!E108 -> 5.09808 | G22: ='4.6.1.3-4 Direct N20'!F108 -> 5.441616 | H22: ='4.6.1.3-4 Direct N20'!G108 -> 6.387648 | I22: ='4.6.1.3-4 Direct N20'!H108 -> 5.441616 | J22: =$G$13 -> kg N | N22: ='Input - Poultry'!$D$30 -> Poultry manure with bedding | O22: N/A | P22: ='4.6.1.3-4 Direct N20'!O108 -> 5.09808 | Q22: ='4.6.1.3-4 Direct N20'!P108 -> 5.441616 | R22: ='4.6.1.3-4 Direct N20'!Q108 -> 6.387648 | S22: ='4.6.1.3-4 Direct N20'!R108 -> 5.441616 | T22: =$G$13 -> kg N
A23: =HYPERLINK("#'Constants - Livestock'!A1", "Constants - Livestock") -> Constants - Livestock | D23: ='Input - Poultry'!$D$31 -> Belt manure removal | E23: N/A | F23: ='4.6.1.3-4 Direct N20'!E109 -> 5.09808 | G23: ='4.6.1.3-4 Direct N20'!F109 -> 5.441616 | H23: ='4.6.1.3-4 Direct N20'!G109 -> 6.387648 | I23: ='4.6.1.3-4 Direct N20'!H109 -> 5.441616 | N23: ='Input - Poultry'!$D$31 -> Belt manure removal | O23: N/A | P23: ='4.6.1.3-4 Direct N20'!O109 -> 5.09808 | Q23: ='4.6.1.3-4 Direct N20'!P109 -> 5.441616 | R23: ='4.6.1.3-4 Direct N20'!Q109 -> 6.387648 | S23: ='4.6.1.3-4 Direct N20'!R109 -> 5.441616
A24: =HYPERLINK("#'Constants - Common'!A1", "Constants - Common") -> Constants - Common | D24: ='Input - Poultry'!$D$32 -> Manure stored in house | E24: N/A | F24: ='4.6.1.3-4 Direct N20'!E110 -> 5.09808 | G24: ='4.6.1.3-4 Direct N20'!F110 -> 5.441616 | H24: ='4.6.1.3-4 Direct N20'!G110 -> 6.387648 | I24: ='4.6.1.3-4 Direct N20'!H110 -> 5.441616 | N24: ='Input - Poultry'!$D$32 -> Manure stored in house | O24: N/A | P24: ='4.6.1.3-4 Direct N20'!O110 -> 5.09808 | Q24: ='4.6.1.3-4 Direct N20'!P110 -> 5.441616 | R24: ='4.6.1.3-4 Direct N20'!Q110 -> 6.387648 | S24: ='4.6.1.3-4 Direct N20'!R110 -> 5.441616
D25: ='Input - Poultry'!$D$33 -> Pasture range and paddock | E25: N/A | F25: ='4.6.1.3-4 Direct N20'!E111 -> 1.69936 | G25: ='4.6.1.3-4 Direct N20'!F111 -> 1.813872 | H25: ='4.6.1.3-4 Direct N20'!G111 -> 2.129216 | I25: ='4.6.1.3-4 Direct N20'!H111 -> 1.813872 | N25: ='Input - Poultry'!$D$33 -> Pasture range and paddock | O25: N/A | P25: ='4.6.1.3-4 Direct N20'!O111 -> 1.69936 | Q25: ='4.6.1.3-4 Direct N20'!P111 -> 1.813872 | R25: ='4.6.1.3-4 Direct N20'!Q111 -> 2.129216 | S25: ='4.6.1.3-4 Direct N20'!R111 -> 1.813872
D26: ='Input - Poultry'!$D$30 -> Poultry manure with bedding | E26: ='Input - Poultry'!$D$38 -> Solid storage | F26: ='4.6.1.3-4 Direct N20'!F189 -> 0.71271158 | G26: ='4.6.1.3-4 Direct N20'!G189 -> 0.76073792 | H26: ='4.6.1.3-4 Direct N20'!H189 -> 0.89299319 | I26: ='4.6.1.3-4 Direct N20'!I189 -> 0.76073792 | N26: ='Input - Poultry'!$D$30 -> Poultry manure with bedding | O26: ='Input - Poultry'!$D$38 -> Solid storage | P26: ='4.6.1.3-4 Direct N20'!P189 -> 0.71271158 | Q26: ='4.6.1.3-4 Direct N20'!Q189 -> 0.76073792 | R26: ='4.6.1.3-4 Direct N20'!R189 -> 0.89299319 | S26: ='4.6.1.3-4 Direct N20'!S189 -> 0.76073792
E27: ='Input - Poultry'!$D$39 -> Composting (passive windrow) | F27: ='4.6.1.3-4 Direct N20'!F190 -> 0.71271158 | G27: ='4.6.1.3-4 Direct N20'!G190 -> 0.76073792 | H27: ='4.6.1.3-4 Direct N20'!H190 -> 0.89299319 | I27: ='4.6.1.3-4 Direct N20'!I190 -> 0.76073792 | O27: ='Input - Poultry'!$D$39 -> Composting (passive windrow) | P27: ='4.6.1.3-4 Direct N20'!P190 -> 0.71271158 | Q27: ='4.6.1.3-4 Direct N20'!Q190 -> 0.76073792 | R27: ='4.6.1.3-4 Direct N20'!R190 -> 0.89299319 | S27: ='4.6.1.3-4 Direct N20'!S190 -> 0.76073792
E28: ='Input - Poultry'!$D$40 -> Digester / covered lagoons | F28: ='4.6.1.3-4 Direct N20'!F191 -> 0.71271158 | G28: ='4.6.1.3-4 Direct N20'!G191 -> 0.76073792 | H28: ='4.6.1.3-4 Direct N20'!H191 -> 0.89299319 | I28: ='4.6.1.3-4 Direct N20'!I191 -> 0.76073792 | O28: ='Input - Poultry'!$D$40 -> Digester / covered lagoons | P28: ='4.6.1.3-4 Direct N20'!P191 -> 0.71271158 | Q28: ='4.6.1.3-4 Direct N20'!Q191 -> 0.76073792 | R28: ='4.6.1.3-4 Direct N20'!R191 -> 0.89299319 | S28: ='4.6.1.3-4 Direct N20'!S191 -> 0.76073792
E29: ='Input - Poultry'!$D$41 -> Direct processing | F29: ='4.6.1.3-4 Direct N20'!F192 -> 0.71271158 | G29: ='4.6.1.3-4 Direct N20'!G192 -> 0.76073792 | H29: ='4.6.1.3-4 Direct N20'!H192 -> 0.89299319 | I29: ='4.6.1.3-4 Direct N20'!I192 -> 0.76073792 | O29: ='Input - Poultry'!$D$41 -> Direct processing | P29: ='4.6.1.3-4 Direct N20'!P192 -> 0.71271158 | Q29: ='4.6.1.3-4 Direct N20'!Q192 -> 0.76073792 | R29: ='4.6.1.3-4 Direct N20'!R192 -> 0.89299319 | S29: ='4.6.1.3-4 Direct N20'!S192 -> 0.76073792
E30: ='Input - Poultry'!$D$42 -> Direct application | F30: ='4.6.1.3-4 Direct N20'!F193 -> 0.71271158 | G30: ='4.6.1.3-4 Direct N20'!G193 -> 0.76073792 | H30: ='4.6.1.3-4 Direct N20'!H193 -> 0.89299319 | I30: ='4.6.1.3-4 Direct N20'!I193 -> 0.76073792 | O30: ='Input - Poultry'!$D$42 -> Direct application | P30: ='4.6.1.3-4 Direct N20'!P193 -> 0.71271158 | Q30: ='4.6.1.3-4 Direct N20'!Q193 -> 0.76073792 | R30: ='4.6.1.3-4 Direct N20'!R193 -> 0.89299319 | S30: ='4.6.1.3-4 Direct N20'!S193 -> 0.76073792
D31: ='Input - Poultry'!$D$31 -> Belt manure removal | E31: ='Input - Poultry'!$D$45 -> Solid storage | F31: ='4.6.1.3-4 Direct N20'!F194 -> 0.96761558 | G31: ='4.6.1.3-4 Direct N20'!G194 -> 1.0328187 | H31: ='4.6.1.3-4 Direct N20'!H194 -> 1.2123756 | I31: ='4.6.1.3-4 Direct N20'!I194 -> 1.0328187 | N31: ='Input - Poultry'!$D$31 -> Belt manure removal | O31: ='Input - Poultry'!$D$45 -> Solid storage | P31: ='4.6.1.3-4 Direct N20'!P194 -> 0.96761558 | Q31: ='4.6.1.3-4 Direct N20'!Q194 -> 1.0328187 | R31: ='4.6.1.3-4 Direct N20'!R194 -> 1.2123756 | S31: ='4.6.1.3-4 Direct N20'!S194 -> 1.0328187
E32: ='Input - Poultry'!$D$46 -> Composting (passive windrow) | F32: ='4.6.1.3-4 Direct N20'!F195 -> 0.96761558 | G32: ='4.6.1.3-4 Direct N20'!G195 -> 1.0328187 | H32: ='4.6.1.3-4 Direct N20'!H195 -> 1.2123756 | I32: ='4.6.1.3-4 Direct N20'!I195 -> 1.0328187 | O32: ='Input - Poultry'!$D$46 -> Composting (passive windrow) | P32: ='4.6.1.3-4 Direct N20'!P195 -> 0.96761558 | Q32: ='4.6.1.3-4 Direct N20'!Q195 -> 1.0328187 | R32: ='4.6.1.3-4 Direct N20'!R195 -> 1.2123756 | S32: ='4.6.1.3-4 Direct N20'!S195 -> 1.0328187
E33: ='Input - Poultry'!$D$47 -> Digester / covered lagoons | F33: ='4.6.1.3-4 Direct N20'!F196 -> 0.96761558 | G33: ='4.6.1.3-4 Direct N20'!G196 -> 1.0328187 | H33: ='4.6.1.3-4 Direct N20'!H196 -> 1.2123756 | I33: ='4.6.1.3-4 Direct N20'!I196 -> 1.0328187 | O33: ='Input - Poultry'!$D$47 -> Digester / covered lagoons | P33: ='4.6.1.3-4 Direct N20'!P196 -> 0.96761558 | Q33: ='4.6.1.3-4 Direct N20'!Q196 -> 1.0328187 | R33: ='4.6.1.3-4 Direct N20'!R196 -> 1.2123756 | S33: ='4.6.1.3-4 Direct N20'!S196 -> 1.0328187
E34: ='Input - Poultry'!$D$48 -> Direct processing | F34: ='4.6.1.3-4 Direct N20'!F197 -> 0.96761558 | G34: ='4.6.1.3-4 Direct N20'!G197 -> 1.0328187 | H34: ='4.6.1.3-4 Direct N20'!H197 -> 1.2123756 | I34: ='4.6.1.3-4 Direct N20'!I197 -> 1.0328187 | O34: ='Input - Poultry'!$D$48 -> Direct processing | P34: ='4.6.1.3-4 Direct N20'!P197 -> 0.96761558 | Q34: ='4.6.1.3-4 Direct N20'!Q197 -> 1.0328187 | R34: ='4.6.1.3-4 Direct N20'!R197 -> 1.2123756 | S34: ='4.6.1.3-4 Direct N20'!S197 -> 1.0328187
E35: ='Input - Poultry'!$D$49 -> Direct application | F35: ='4.6.1.3-4 Direct N20'!F198 -> 0.96761558 | G35: ='4.6.1.3-4 Direct N20'!G198 -> 1.0328187 | H35: ='4.6.1.3-4 Direct N20'!H198 -> 1.2123756 | I35: ='4.6.1.3-4 Direct N20'!I198 -> 1.0328187 | O35: ='Input - Poultry'!$D$49 -> Direct application | P35: ='4.6.1.3-4 Direct N20'!P198 -> 0.96761558 | Q35: ='4.6.1.3-4 Direct N20'!Q198 -> 1.0328187 | R35: ='4.6.1.3-4 Direct N20'!R198 -> 1.2123756 | S35: ='4.6.1.3-4 Direct N20'!S198 -> 1.0328187
D36: ='Input - Poultry'!$D$32 -> Manure stored in house | E36: ='Input - Poultry'!$D$52 -> Solid storage | F36: ='4.6.1.3-4 Direct N20'!F199 -> 0.61074998 | G36: ='4.6.1.3-4 Direct N20'!G199 -> 0.6519056 | H36: ='4.6.1.3-4 Direct N20'!H199 -> 0.76524023 | I36: ='4.6.1.3-4 Direct N20'!I199 -> 0.6519056 | N36: ='Input - Poultry'!$D$32 -> Manure stored in house | O36: ='Input - Poultry'!$D$52 -> Solid storage | P36: ='4.6.1.3-4 Direct N20'!P199 -> 0.61074998 | Q36: ='4.6.1.3-4 Direct N20'!Q199 -> 0.6519056 | R36: ='4.6.1.3-4 Direct N20'!R199 -> 0.76524023 | S36: ='4.6.1.3-4 Direct N20'!S199 -> 0.6519056
E37: ='Input - Poultry'!$D$53 -> Composting (passive windrow) | F37: ='4.6.1.3-4 Direct N20'!F200 -> 0.61074998 | G37: ='4.6.1.3-4 Direct N20'!G200 -> 0.6519056 | H37: ='4.6.1.3-4 Direct N20'!H200 -> 0.76524023 | I37: ='4.6.1.3-4 Direct N20'!I200 -> 0.6519056 | O37: ='Input - Poultry'!$D$53 -> Composting (passive windrow) | P37: ='4.6.1.3-4 Direct N20'!P200 -> 0.61074998 | Q37: ='4.6.1.3-4 Direct N20'!Q200 -> 0.6519056 | R37: ='4.6.1.3-4 Direct N20'!R200 -> 0.76524023 | S37: ='4.6.1.3-4 Direct N20'!S200 -> 0.6519056
E38: ='Input - Poultry'!$D$54 -> Digester / covered lagoons | F38: ='4.6.1.3-4 Direct N20'!F201 -> 0.61074998 | G38: ='4.6.1.3-4 Direct N20'!G201 -> 0.6519056 | H38: ='4.6.1.3-4 Direct N20'!H201 -> 0.76524023 | I38: ='4.6.1.3-4 Direct N20'!I201 -> 0.6519056 | O38: ='Input - Poultry'!$D$54 -> Digester / covered lagoons | P38: ='4.6.1.3-4 Direct N20'!P201 -> 0.61074998 | Q38: ='4.6.1.3-4 Direct N20'!Q201 -> 0.6519056 | R38: ='4.6.1.3-4 Direct N20'!R201 -> 0.76524023 | S38: ='4.6.1.3-4 Direct N20'!S201 -> 0.6519056
E39: ='Input - Poultry'!$D$55 -> Direct processing | F39: ='4.6.1.3-4 Direct N20'!F202 -> 0.61074998 | G39: ='4.6.1.3-4 Direct N20'!G202 -> 0.6519056 | H39: ='4.6.1.3-4 Direct N20'!H202 -> 0.76524023 | I39: ='4.6.1.3-4 Direct N20'!I202 -> 0.6519056 | O39: ='Input - Poultry'!$D$55 -> Direct processing | P39: ='4.6.1.3-4 Direct N20'!P202 -> 0.61074998 | Q39: ='4.6.1.3-4 Direct N20'!Q202 -> 0.6519056 | R39: ='4.6.1.3-4 Direct N20'!R202 -> 0.76524023 | S39: ='4.6.1.3-4 Direct N20'!S202 -> 0.6519056
E40: ='Input - Poultry'!$D$56 -> Direct application | F40: ='4.6.1.3-4 Direct N20'!F203 -> 0.61074998 | G40: ='4.6.1.3-4 Direct N20'!G203 -> 0.6519056 | H40: ='4.6.1.3-4 Direct N20'!H203 -> 0.76524023 | I40: ='4.6.1.3-4 Direct N20'!I203 -> 0.6519056 | O40: ='Input - Poultry'!$D$56 -> Direct application | P40: ='4.6.1.3-4 Direct N20'!P203 -> 0.61074998 | Q40: ='4.6.1.3-4 Direct N20'!Q203 -> 0.6519056 | R40: ='4.6.1.3-4 Direct N20'!R203 -> 0.76524023 | S40: ='4.6.1.3-4 Direct N20'!S203 -> 0.6519056
D42: Table_FracGASM_m_T
...

Sheet 4.6.1.7-8 Leaching and runoff
A1: #VALUE! | C1: 4.6.1.7-8 Leaching and runoff
A3: =HYPERLINK("#'Home'!A1", "Home") -> Home | D3: Method 1 | N3: Method 2
A4: =HYPERLINK("#'Overview'!A1", "Overview") -> Overview
A5: =HYPERLINK("#'Results'!A1", "Results") -> Results | D5: {=MMS_Poultry_LeachingAndRunoff_Equations.VEERG_4_6_1_7__2_MassOfNitrogenLostToLeachingAndRunoffFromSolidStorage_Title()} -> Mass of nitrogen lost to leaching and runoff from solid storage systems
D6: {=MMS_Poultry_LeachingAndRunoff_Equations.VEERG_4_6_1_7__2_MassOfNitrogenLostToLeachingAndRunoffFromSolidStorage_Source()} -> VEERG 2026: 4.6.1.7, Equation (2)
A7: INPUTS | D7: Function name | E7: {=Common_InputFunctions.Utility_DisplayFunctionName(F34)} -> =MMS_Poultry_LeachingAndRunoff_Equations.VEERG_4_6_1_7__2_MassOfNitrogenLostToLeachingAndRunoffFromSolidStorage
A8: =HYPERLINK("#'Input - Site'!A1", "Site") -> Site
A9: =HYPERLINK("#'Input - Poultry'!A1", "Poultry") -> Poultry
D10: Variable | E10: {=MMS_Poultry_LeachingAndRunoff_Equations.VEERG_4_6_1_7__2_MassOfNitrogenLostToLeachingAndRunoffFromSolidStorage_Variable()} -> MNLeach_jkm4
A11: CALCULATIONS | D11: Unit | E11: {=MMS_Poultry_LeachingAndRunoff_Equations.VEERG_4_6_1_7__2_MassOfNitrogenLostToLeachingAndRunoffFromSolidStorage_Unit()} -> kg N
A12: =HYPERLINK("#'4.6.1.1-2 Methane'!A1", "4.6.1.1-2 Methane") -> 4.6.1.1-2 Methane
A13: =HYPERLINK("#'4.6.1.3-4 Direct N20'!A1", "4.6.1.3-4 Direct N2O") -> 4.6.1.3-4 Direct N2O | D13: {=_xlfn.CHOOSECOLS(MMS_Poultry_LeachingAndRunoff_Equations.VEERG_4_6_1_7__2_MassOfNitrogenLostToLeachingAndRunoffFromSolidStorage_Arguments(),1,2)} -> MN_jkm4T2 | E13: nitrogen in solid storage MMS treatment stage 2 | G13: {=_xlfn.CHOOSECOLS(MMS_Poultry_LeachingAndRunoff_Equations.VEERG_4_6_1_7__2_MassOfNitrogenLostToLeachingAndRunoffFromSolidStorage_Arguments(),3,4)} -> kg N | H13: Calculated from 4.6.1.3 (6) | I13: {=HYPERLINK(Common_InputFunctions.Utility_SourceHyperlink($D$24),$D$24)} -> M1_Table_MN_j_k_m-4
A14: =HYPERLINK("#'4.6.1.5-6 Atmos Dep'!A1", "4.6.1.5-6 Atmospheric deposition") -> 4.6.1.5-6 Atmospheric deposition | D14: FracWET | E14: fraction of N available for leaching and runoff | G14: fraction | H14: Input | I14: =Common_InputFunctions.CommonCropping_GetFracWET(I16,I18,#REF!,#REF!,Table_SourceData_FracWETIrrigation[Irrigation type i],Table_SourceData_FracWETIrrigation[FracWET]) -> 1
A15: =HYPERLINK("#'4.6.1.7-8 Leaching and runoff'!A1", "4.6.1.7-8 Leaching & runoff") -> 4.6.1.7-8 Leaching & runoff | D15: FracLEACH_MS | E15: fraction of N lost through leaching and runoff | G15: fraction | H15: Input | I15: ='Constants - Poultry'!$E$110 -> 0.02
A16: =HYPERLINK("#'4.6.1.9 Manure applied to soils'!A1", "4.6.1.9 Manure applied to soils") -> 4.6.1.9 Manure applied to soils | D16: z | E16: location in leaching zone | H16: Input | I16: ='Input - Site'!$E$23 -> NO - Not in leaching zone
A17: =HYPERLINK("#'4.6.1.10-11 Soil direct N2O'!A1", "4.6.1.10-11 Soil direct N2O") -> 4.6.1.10-11 Soil direct N2O | D17: j | E17: production system | H17: Input | I17: ='Input - Poultry'!$E$59 -> Crop
A18: =HYPERLINK("#'4.6.1.12-13 Soil atmos dep'!A1", "4.6.1.12-13 Soil Atm. deposition") -> 4.6.1.12-13 Soil Atm. deposition | D18: ir | E18: irrigation method | H18: Input | I18: ='Input - Poultry'!$E$60 -> Sprinkler irrigation
A19: =HYPERLINK("#'4.6.1.14-15 Soil leach runoff'!A1", "4.6.1.14-15 Soil leach & runoff") -> 4.6.1.14-15 Soil leach & runoff
D20: MNleach is assumed to be 0 for all MMS except free range operations manure excreted on pasture in free range operations and manure and manure stockpiles.
A21: APPENDICES | D21: Leaching from emissions from the pasture component (m=14) is estimated in the manure applied to soils equations (Section 4.6.1.10 - 4.6.1.15).
A22: =HYPERLINK("#'Constants - Poultry'!A1", "Constants - Poultry") -> Constants - Poultry | D22: Therefore, emissions from leaching and run off are only estimated for solid storage stockpiles MMS (m=4)
A23: =HYPERLINK("#'Constants - Livestock'!A1", "Constants - Livestock") -> Constants - Livestock
A24: =HYPERLINK("#'Constants - Common'!A1", "Constants - Common") -> Constants - Common | D24: M1_Table_MN_j_k_m-4 | N24: M1_Table_MN_j_k_m-4
D25: Nitrogen in solid storage MMS (Method 1) | N25: Nitrogen in solid storage MMS (Method 1)
D26: Stage 1 MMS | E26: Stage 2 MMS | F26: Layers | G26: Meat chicken growers | H26: Meat chicken breeders | I26: Other | N26: Stage 1 MMS | O26: Stage 2 MMS | P26: Layers | Q26: Meat chicken growers | R26: Meat chicken breeders | S26: Other
D27: ='Input - Poultry'!$D$30 -> Poultry manure with bedding | E27: ='Input - Poultry'!$D$38 -> Solid storage | F27: ='4.6.1.3-4 Direct N20'!F189 -> 0.71271158 | G27: ='4.6.1.3-4 Direct N20'!G189 -> 0.76073792 | H27: ='4.6.1.3-4 Direct N20'!H189 -> 0.89299319 | I27: ='4.6.1.3-4 Direct N20'!I189 -> 0.76073792 | J27: =$G$13 -> kg N | N27: ='Input - Poultry'!$D$30 -> Poultry manure with bedding | O27: ='Input - Poultry'!$D$38 -> Solid storage | P27: ='4.6.1.3-4 Direct N20'!P189 -> 0.71271158 | Q27: ='4.6.1.3-4 Direct N20'!Q189 -> 0.76073792 | R27: ='4.6.1.3-4 Direct N20'!R189 -> 0.89299319 | S27: ='4.6.1.3-4 Direct N20'!S189 -> 0.76073792 | T27: =$G$13 -> kg N
D28: ='Input - Poultry'!$D$31 -> Belt manure removal | E28: ='Input - Poultry'!$D$45 -> Solid storage | F28: ='4.6.1.3-4 Direct N20'!F194 -> 0.96761558 | G28: ='4.6.1.3-4 Direct N20'!G194 -> 1.0328187 | H28: ='4.6.1.3-4 Direct N20'!H194 -> 1.2123756 | I28: ='4.6.1.3-4 Direct N20'!I194 -> 1.0328187 | N28: ='Input - Poultry'!$D$31 -> Belt manure removal | O28: ='Input - Poultry'!$D$45 -> Solid storage | P28: ='4.6.1.3-4 Direct N20'!P194 -> 0.96761558 | Q28: ='4.6.1.3-4 Direct N20'!Q194 -> 1.0328187 | R28: ='4.6.1.3-4 Direct N20'!R194 -> 1.2123756 | S28: ='4.6.1.3-4 Direct N20'!S194 -> 1.0328187
D29: ='Input - Poultry'!$D$32 -> Manure stored in house | E29: ='Input - Poultry'!$D$52 -> Solid storage | F29: ='4.6.1.3-4 Direct N20'!F199 -> 0.61074998 | G29: ='4.6.1.3-4 Direct N20'!G199 -> 0.6519056 | H29: ='4.6.1.3-4 Direct N20'!H199 -> 0.76524023 | I29: ='4.6.1.3-4 Direct N20'!I199 -> 0.6519056 | N29: ='Input - Poultry'!$D$32 -> Manure stored in house | O29: ='Input - Poultry'!$D$52 -> Solid storage | P29: ='4.6.1.3-4 Direct N20'!P199 -> 0.61074998 | Q29: ='4.6.1.3-4 Direct N20'!Q199 -> 0.6519056 | R29: ='4.6.1.3-4 Direct N20'!R199 -> 0.76524023 | S29: ='4.6.1.3-4 Direct N20'!S199 -> 0.6519056
D31: M1_Table_MN_Leach_j_k_m-4 | N31: M2_Table_MN_j_k_m-4
D32: Mass of N lost to leaching and runoff (Method 1) | N32: Mass of N lost to leaching and runoff (Method 2)
