Workbook
Name Common_Equations.Common_ConvertCH4ToCO2e: _xlfn.LAMBDA(_xlpm.E_CH4,_xlpm.GWP_CH4, _xlpm.E_CH4 * _xlpm.GWP_CH4)
Name Common_Equations.Common_ConvertCH4ToCO2e_Arguments: _xlfn.LAMBDA(_xlfn.MAKEARRAY(2, 2, _xlfn.LAMBDA(_xlpm.r,_xlpm.c, INDEX({"ECH4","Methane emissions (t CH4)";"GWPCH4","Global warming potential for methane (t CO2-e / t CH4)"}, _xlpm.r, _xlpm.c))))
Name Common_Equations.Common_ConvertCH4ToCO2e_LatexEquation: _xlfn.LAMBDA("CO2_e = E_{CH4} \times GWP_{CH4}")
Name Common_Equations.Common_ConvertCH4ToCO2e_NIRReference: _xlfn.LAMBDA("")
Name Common_Equations.Common_ConvertCH4ToCO2e_Title: _xlfn.LAMBDA("Convert methane emissions to carbon dioxide equivalent emissions")
Name Common_Equations.Common_ConvertCH4ToCO2e_Unit: _xlfn.LAMBDA("t CO2e")
Name Common_Equations.Common_ConvertCH4ToCO2e_Variable: _xlfn.LAMBDA("ECH4 CO2e")
Name Common_Equations.Common_ConvertN2OToCO2e: _xlfn.LAMBDA(_xlpm.E_N2O,_xlpm.GWP_N2O, _xlpm.E_N2O * _xlpm.GWP_N2O)
Name Common_Equations.Common_ConvertN2OToCO2e_LatexEquation: _xlfn.LAMBDA("CO2_e = E_{N2O} \times GWP_{N2O}")
Name Common_Equations.Common_ConvertN2OToCO2e_NIRReference: _xlfn.LAMBDA("")
Name Common_Equations.Common_ConvertN2OToCO2e_Title: _xlfn.LAMBDA("Convert nitrous oxide emissions to carbon dioxide equivalent emissions")
Name Common_Equations.Common_ConvertN2OToCO2e_Unit: _xlfn.LAMBDA("t CO2e")
Name Common_Equations.Common_ConvertN2OToCO2e_Variable: _xlfn.LAMBDA("EN2O CO2e")
Name Common_InputFunctions.Utility_ConvertStateCommonNameToAbbreviation: _xlfn.LAMBDA(_xlpm.StateCommonName,_xlpm.StateCommonNameArray,_xlpm.StateAbbreviationArray, _xlfn.XLOOKUP(_xlpm.StateCommonName, _xlpm.StateCommonNameArray, _xlpm.StateAbbreviationArray, ""))
Name Common_InputFunctions.Utility_DisplayArguments_1_2: _xlfn.LAMBDA(_xlpm.ArgumentsArray, _xlfn.CHOOSECOLS(_xlpm.ArgumentsArray, 1, 2))
Name Common_InputFunctions.Utility_DisplayArguments_3_4: _xlfn.LAMBDA(_xlpm.ArgumentsArray, _xlfn.CHOOSECOLS(_xlpm.ArgumentsArray, 3, 4))
Name Common_InputFunctions.Utility_DisplayFunctionName: _xlfn.LAMBDA(_xlpm.Function, _xlfn.TEXTBEFORE(_xlfn.FORMULATEXT(_xlpm.Function), "("))
Name Common_InputFunctions.Utility_GetArrayTableColumnStartNumber: _xlfn.LAMBDA(_xlpm.TableHeaderCell, COLUMN(_xlpm.TableHeaderCell))
Name Common_InputFunctions.Utility_GetArrayTableRowStartNumber: _xlfn.LAMBDA(_xlpm.TableheaderCell,_xlpm.RowsBetweenHeaderandArray, ROW(_xlpm.TableheaderCell) + _xlpm.RowsBetweenHeaderandArray - 1)
Name Common_InputFunctions.Utility_LookupValueInTable: _xlfn.LAMBDA(_xlpm.LookupValue,_xlpm.LookupArray,_xlpm.ReturnArray, _xlfn.XLOOKUP(_xlpm.LookupValue, _xlpm.LookupArray, _xlpm.ReturnArray, ""))
Name Common_InputFunctions.Utility_SourceHyperlink: _xlfn.LAMBDA(_xlpm.TargetCell, _xlfn.LET(_xlpm.sh, _xlfn.TEXTAFTER(CELL("filename", _xlpm.TargetCell), "]"), _xlpm.addr, CELL("address", _xlpm.TargetCell), "#'" & _xlpm.sh & "'!" & _xlpm.addr))
Name Common_SourceData.Common_SourceData_AustralianStatesTerritories_Source: _xlfn.LAMBDA("")
Name Common_SourceData.Common_SourceData_AustralianStatesTerritories_Title: _xlfn.LAMBDA("Australian states and territories")
Name Common_SourceData.Common_SourceData_AustralianStatesTerritories_Unit: _xlfn.LAMBDA("")
Name Common_SourceData.Common_SourceData_AustralianStatesTerritories_Variable: _xlfn.LAMBDA("")
Name Common_SourceData.Common_SourceData_ClimateZones_Source: _xlfn.LAMBDA("VEERG 2026: Table 1.3: Climate and Rainfall zone classifications and definitions")
Name Common_SourceData.Common_SourceData_ClimateZones_Title: _xlfn.LAMBDA("VEERG Australian climate zones")
Name Common_SourceData.Common_SourceData_ClimateZones_Unit: _xlfn.LAMBDA("")
Name Common_SourceData.Common_SourceData_ClimateZones_Variable: _xlfn.LAMBDA("")
Name Common_SourceData.Common_SourceData_ConvertGasElementalToMolecular_Source: _xlfn.LAMBDA("XXXXXXX")
Name Common_SourceData.Common_SourceData_ConvertGasElementalToMolecular_Title: _xlfn.LAMBDA("Factor to convert elemental mass of gas to molecular mass")
Name Common_SourceData.Common_SourceData_ConvertGasElementalToMolecular_Unit: _xlfn.LAMBDA("factor")
Name Common_SourceData.Common_SourceData_ConvertGasElementalToMolecular_Variable: _xlfn.LAMBDA("Cg")
Name Common_SourceData.Common_SourceData_ConvertN2oElementalToMolecularCg_Data: _xlfn.LAMBDA(44 / 28)
Name Common_SourceData.Common_SourceData_ConvertN2oElementalToMolecularCg_Source: _xlfn.LAMBDA("National Inventory Report 2023 Volume 1")
Name Common_SourceData.Common_SourceData_ConvertN2oElementalToMolecularCg_Title: _xlfn.LAMBDA("Factor to convert elemental mass of N2O to molecular mass")
Name Common_SourceData.Common_SourceData_ConvertN2oElementalToMolecularCg_Unit: _xlfn.LAMBDA("factor")
Name Common_SourceData.Common_SourceData_ConvertN2oElementalToMolecularCg_Variable: _xlfn.LAMBDA("CgN2O")
Name Common_SourceData.Common_SourceData_DataScores_Scope3_Source: _xlfn.LAMBDA("VEERG 2026: XXXXXXXX")
Name Common_SourceData.Common_SourceData_DataScores_Scope3_Title: _xlfn.LAMBDA("Australian data scores for scope 3")
Name Common_SourceData.Common_SourceData_DataScores_Scope3_Unit: _xlfn.LAMBDA("")
Name Common_SourceData.Common_SourceData_DataScores_Scope3_Variable: _xlfn.LAMBDA("")
Name Common_SourceData.Common_SourceData_DataScores_Scope3_Variation: _xlfn.LAMBDA("")
Name Common_SourceData.Common_SourceData_DensityOfMethane_Data: _xlfn.LAMBDA(0.6784)
Name Common_SourceData.Common_SourceData_DensityOfMethane_Source: _xlfn.LAMBDA("National Inventory Report 2023 Volume 1: Equations 3.B.1a_2, 3.B.1c_2, 3.B.3_1, 3.B.4g_2")
Name Common_SourceData.Common_SourceData_DensityOfMethane_Title: _xlfn.LAMBDA("p = density of methane")
Name Common_SourceData.Common_SourceData_DensityOfMethane_Unit: _xlfn.LAMBDA("kg/m3")
Name Common_SourceData.Common_SourceData_EFleach_Data: _xlfn.LAMBDA(_xlfn.MAKEARRAY(1, 2, _xlfn.LAMBDA(_xlpm.r,_xlpm.c, INDEX({"EFleach",0.011}, _xlpm.r, _xlpm.c))))
Name Common_SourceData.Common_SourceData_EFleach_NIRReference: _xlfn.LAMBDA("National Inventory Report Volume 1: Equation 3.D.B_10")
Name Common_SourceData.Common_SourceData_EFleach_Source: _xlfn.LAMBDA("VEERG 2026:5.5.2.3 Constant Parameters")
Name Common_SourceData.Common_SourceData_EFleach_Title: _xlfn.LAMBDA("Emission factor for nitrogen leaching and runoff")
Name Common_SourceData.Common_SourceData_EFleach_Unit: _xlfn.LAMBDA("(kg N2O-N / kg N")
Name Common_SourceData.Common_SourceData_EFleach_Variation: _xlfn.LAMBDA((""))
Name Common_SourceData.Common_SourceData_EFN2O_NIRReference: _xlfn.LAMBDA("")
Name Common_SourceData.Common_SourceData_EFN2O_Source: _xlfn.LAMBDA("VEERG 2026: Table A.2.2.1")
Name Common_SourceData.Common_SourceData_EFN2O_Title: _xlfn.LAMBDA("Nitrous oxide emission factors for inorganic fertiliser application")
Name Common_SourceData.Common_SourceData_EFN2O_Unit: _xlfn.LAMBDA("(kg N2O-N / kg N")
Name Common_SourceData.Common_SourceData_EFOrganicFertiliserAndCropResidues_Data: _xlfn.LAMBDA(_xlfn.MAKEARRAY(3, 2, _xlfn.LAMBDA(_xlpm.r,_xlpm.c, INDEX({"Climate zone","EFNi & EFN2O";"Wet climate zone",0.006;"Dry climate zone",0.005}, _xlpm.r, _xlpm.c))))
Name Common_SourceData.Common_SourceData_EFOrganicFertiliserAndCropResidues_NIRReference: _xlfn.LAMBDA("")
Name Common_SourceData.Common_SourceData_EFOrganicFertiliserAndCropResidues_Source: _xlfn.LAMBDA("VEERG 2026: Table A.2.1.4")

Sheet Home
A1: Home

Sheet Overview
A1: #VALUE! | C1: 5: Fertiliser Use: Overview
A3: =HYPERLINK("#'Home'!A1", "Home") -> Home
A4: =HYPERLINK("#'Overview'!A1", "Overview") -> Overview
A5: =HYPERLINK("#'Results'!A1", "Results") -> Results | D5: 💡 Below is a diagram that maps the equations used to calculate emissions, and how they interact with each other.
D6: Click on a box to go to the corresponding calculation.
A7: INPUTS
A8: =HYPERLINK("#'Input - Site'!A1", "Site") -> Site
A9: =HYPERLINK("#'Input - Fertiliser'!A1", "Fertiliser") -> Fertiliser
A11: CALCULATIONS
A12: =HYPERLINK("#'5.1.1.1-2 Inorganic Fert N2O'!A1", "5.1.1.1-2 Inorganic Fert N2O") -> 5.1.1.1-2 Inorganic Fert N2O
A13: =HYPERLINK("#'5.1.1.3-4 Inorganic fert CO2'!A1", "5.1.1.3-4 Inorganic fert CO2") -> 5.1.1.3-4 Inorganic fert CO2
A14: =HYPERLINK("#'5.2.1.1-2 Organic Fert N2O'!A1", "5.2.1.1-2 Organic Fert N2O") -> 5.2.1.1-2 Organic Fert N2O
A15: =HYPERLINK("#'5.3.1.1-2 Lime CO2'!A1", "5.3.1.1-2 Lime CO2") -> 5.3.1.1-2 Lime CO2
A16: =HYPERLINK("#'5.4.1.1-4 Atmos deposition'!A1", "5.4.1.1-4 Atmos deposition") -> 5.4.1.1-4 Atmos deposition
A17: =HYPERLINK("#'5.5.1.1-2 Leaching and runoff'!A1", "5.5.1.1-2 Leaching and runoff") -> 5.5.1.1-2 Leaching and runoff
A19: APPENDICES
A20: =HYPERLINK("#'Constants - Fertiliser'!A1", "Constants - Fertiliser") -> Constants - Fertiliser
A21: =HYPERLINK("#'Constants - Common'!A1", "Constants - Common") -> Constants - Common
L37: `

Sheet Results
A1: #VALUE! | C1: 5: Fertiliser Use: Results
A3: =HYPERLINK("#'Home'!A1", "Home") -> Home
A4: =HYPERLINK("#'Overview'!A1", "Overview") -> Overview | D4: Emissions breakdown
A5: =HYPERLINK("#'Results'!A1", "Results") -> Results
D6: 💡 NOTE: When there is no Method 2, the Method 2 result are the same as Method 1
A7: INPUTS
A8: =HYPERLINK("#'Input - Site'!A1", "Site") -> Site | D8: Scope 1 source | E8: GHG emissions method 1 | F8: GHG emissions method 2 | G8: GHG Unit | H8: CO2-e emissions method 1 | I8: CO2-e emissions method 2 | J8: CO2-e unit
A9: =HYPERLINK("#'Input - Fertiliser'!A1", "Fertiliser") -> Fertiliser | D9: 5.1.1.1-2 Inorganic fertiliser N2O | E9: ='8.1.1.1-2 Transport fuel'!$E$80 -> 0 | F9: ='8.1.1.1-2 Transport fuel'!$N$88 -> 0 | G9: t N2O | H9: ='8.1.1.1-2 Transport fuel'!E85 -> 0 | I9: ='8.1.1.1-2 Transport fuel'!N93 -> 0 | J9: t CO2e
D10: 5.1.1.3-4 Inorganic fertiliser CO2 | E10: ='8.2.1.1-2 Stationary fuel'!$E$77 -> 0 | F10: =E10 -> 0 | G10: t CO2 | H10: ='8.2.1.1-2 Stationary fuel'!$E$77 -> 0 | I10: =H10 -> 0 | J10: t CO2e
A11: CALCULATIONS | D11: 5.2.1.1-2 Organic fertiliser N2O | E11: =#REF! -> #REF! | F11: =E11 -> #REF! | G11: t N2O | H11: =#REF! -> #REF! | I11: =H11 -> #REF! | J11: t CO2e
A12: =HYPERLINK("#'5.1.1.1-2 Inorganic Fert N2O'!A1", "5.1.1.1-2 Inorganic Fert N2O") -> 5.1.1.1-2 Inorganic Fert N2O | D12: 5.3.1.1-3 Lime CO2 | E12: =#REF! -> #REF! | F12: =E12 -> #REF! | G12: t CO2 | H12: =#REF! -> #REF! | I12: =H12 -> #REF! | J12: t CO2e
A13: =HYPERLINK("#'5.1.1.3-4 Inorganic fert CO2'!A1", "5.1.1.3-4 Inorganic fert CO2") -> 5.1.1.3-4 Inorganic fert CO2 | D13: 5.4.1.1-5 Atmospheric deposition | E13: =#REF! -> #REF! | F13: =E13 -> #REF! | G13: t N2O | H13: =#REF! -> #REF! | I13: =H13 -> #REF! | J13: t CO2e
A14: =HYPERLINK("#'5.2.1.1-2 Organic Fert N2O'!A1", "5.2.1.1-2 Organic Fert N2O") -> 5.2.1.1-2 Organic Fert N2O | D14: 5.5.1.1-2 Leaching and runoff | E14: =#REF! -> #REF! | F14: =E14 -> #REF! | G14: t N2O | H14: =#REF! -> #REF! | I14: =H14 -> #REF! | J14: t CO2e
A15: =HYPERLINK("#'5.3.1.1-2 Lime CO2'!A1", "5.3.1.1-2 Lime CO2") -> 5.3.1.1-2 Lime CO2 | D15: Total | H15: =SUM(H9:H14) -> #REF! | I15: =SUM(I9:I14) -> #REF! | J15: t CO2e
A16: =HYPERLINK("#'5.4.1.1-4 Atmos deposition'!A1", "5.4.1.1-4 Atmos deposition") -> 5.4.1.1-4 Atmos deposition
A17: =HYPERLINK("#'5.5.1.1-2 Leaching and runoff'!A1", "5.5.1.1-2 Leaching and runoff") -> 5.5.1.1-2 Leaching and runoff
A19: APPENDICES
A20: =HYPERLINK("#'Constants - Fertiliser'!A1", "Constants - Fertiliser") -> Constants - Fertiliser
A21: =HYPERLINK("#'Constants - Common'!A1", "Constants - Common") -> Constants - Common

Sheet Input - Site
A1: #VALUE! | C1: Input - Site
A3: =HYPERLINK("#'Home'!A1", "Home") -> Home
A4: =HYPERLINK("#'Overview'!A1", "Overview") -> Overview
A5: =HYPERLINK("#'Results'!A1", "Results") -> Results | D5: Your business
A7: INPUTS | D7: Farm name | E7: Test Farms
A8: =HYPERLINK("#'Input - Site'!A1", "Site") -> Site | D8: Reporting entity name | E8: Test Farms Pty Ltd
A9: =HYPERLINK("#'Input - Fertiliser'!A1", "Fertiliser") -> Fertiliser
D10: 💡An 'Emissions accounting period' is a 12 month period where the business can report on the emissions, and is typically the same as the business' financial accounting period.
A11: CALCULATIONS
A12: =HYPERLINK("#'5.1.1.1-2 Inorganic Fert N2O'!A1", "5.1.1.1-2 Inorganic Fert N2O") -> 5.1.1.1-2 Inorganic Fert N2O | D12: Emissions calculation period start date | E12: 45292 | F12: ← DD/MM/YYYY or DD Month YYYY
A13: =HYPERLINK("#'5.1.1.3-4 Inorganic fert CO2'!A1", "5.1.1.3-4 Inorganic fert CO2") -> 5.1.1.3-4 Inorganic fert CO2 | D13: Emissions calculation period end date | E13: =DATE(YEAR(E12)+1,MONTH(E12),DAY(E12))-1 -> 45657 | F13: ← Automatically calculated, 12 months after start date
A14: =HYPERLINK("#'5.2.1.1-2 Organic Fert N2O'!A1", "5.2.1.1-2 Organic Fert N2O") -> 5.2.1.1-2 Organic Fert N2O
A15: =HYPERLINK("#'5.3.1.1-2 Lime CO2'!A1", "5.3.1.1-2 Lime CO2") -> 5.3.1.1-2 Lime CO2
A16: =HYPERLINK("#'5.4.1.1-4 Atmos deposition'!A1", "5.4.1.1-4 Atmos deposition") -> 5.4.1.1-4 Atmos deposition | D16: Location and climate
A17: =HYPERLINK("#'5.5.1.1-2 Leaching and runoff'!A1", "5.5.1.1-2 Leaching and runoff") -> 5.5.1.1-2 Leaching and runoff
D18: Location information is used to reference some region and climate-specific emission factors
A19: APPENDICES | D19: Tip: Use the web-based GAF Location Helper tool to easily get region and climate information. You will need an internet connection to use the GAF Location Helper.
A20: =HYPERLINK("#'Constants - Fertiliser'!A1", "Constants - Fertiliser") -> Constants - Fertiliser
A21: =HYPERLINK("#'Constants - Common'!A1", "Constants - Common") -> Constants - Common | D21: State | E21: Western Australia | F21: ← Please select
D22: Region (ABS Statistical area level 4) if state is WA | E22: Western Australia - Outback (South) | F22: ← Please select
D23: Leaching zone | E23: NO - Not in leaching zone | F23: ← Please select
D24: Elevation | E24: 307.7 | F24: Meters
D25: Average temperature for reporting period | E25: 18 | F25: Degrees celsius
D26: Total rainfall for reporting period | E26: 599 | F26: Millimetres
D27: Potential evapotranspiration for reporting period | E27: 1326 | F27: Millimetres
D28: Number of frost days for reporting period | E28: 7 | F28: Days
D29: MAP:PET ratio | E29: =E26/E27 -> 0.45173454
D30: Rainfall zone | E30: =Common_InputFunctions.Utility_LookupItemFromMinMax(E26,Table_SourceData_RainfallZones[Min rainfall],Table_SourceData_RainfallZones[Max rainfall],Table_SourceData_RainfallZones[Rainfall Zone]) -> Low rainfall
D31: Climate zone | E31: =Common_InputFunctions.Utility_GetClimateZone(E25,E26,E28,E24,E29,Table_SourceData_ClimateZones[Min temp],Table_SourceData_ClimateZones[Max temp],Table_SourceData_ClimateZones[Min rainfall],Table_SourceData_ClimateZones[Max rainfall],Table_SourceData_ClimateZones[Min frost days],Table_SourceData_ClimateZones[Max frost days],Table_SourceData_ClimateZones[Min elevation],Table_SourceData_ClimateZones[Max elevation],Table_SourceData_ClimateZones[Min MAP:PET],Table_SourceData_ClimateZones[Max MAP:PET],Table_SourceData_ClimateZones[Climate zone]) -> Warm temperate dry
D32: Wet or dry climate zone | E32: =Common_InputFunctions.Utility_LookupValueInTable($E$31,Table_SourceData_WetDryZones[Climate zone],Table_SourceData_WetDryZones[Wet or Dry Zone]) -> Dry climate zone
D33: Temperature zone | E33: =Common_InputFunctions.Utility_LookupItemFromMinMax(E25,Table_SourceData_TemperatureZones[Min MAT],Table_SourceData_TemperatureZones[Max MAT],Table_SourceData_TemperatureZones[Temperature Zone]) -> Temperate

Sheet Input - Fuel
A1: #VALUE! | C1: Input - Fuel
D5: Fuel purchases and consumption
D7: 💡 You can add more rows to the table by right-clicking on the table and selecting "Insert > Table rows above/below"
D8: 💡 'Percent consumed" is 100% by default. If you purchased more fuel than was consumed you can edit this field.
D10: Fuel use (select) | E10: Fuel type (select) | F10: Amount purchased | G10: Amount unit | H10: Percent consumed | I10: Amount consumed
D11: General use | E11: Petrol | F11: 100 | G11: {=Common_InputFunctions.Utility_LookupValueInTable(Table_Input_Fuel[[#This Row],[Fuel type (select)]],[1]!Table_FuelTypes_Units[Fuel type], [1]!Table_FuelTypes_Units[Unit])} -> kL | H11: =1 -> 1 | I11: =Table_Input_Fuel[[#This Row],[Amount purchased]]*Table_Input_Fuel[[#This Row],[Percent consumed]]*10^-3 -> 0.1
D12: General use | E12: Diesel | F12: 100 | G12: {=Common_InputFunctions.Utility_LookupValueInTable(Table_Input_Fuel[[#This Row],[Fuel type (select)]],[1]!Table_FuelTypes_Units[Fuel type], [1]!Table_FuelTypes_Units[Unit])} -> kL | H12: =1 -> 1 | I12: =Table_Input_Fuel[[#This Row],[Amount purchased]]*Table_Input_Fuel[[#This Row],[Percent consumed]]*10^-3 -> 0.1
D13: General use | E13: Biodiesel | F13: 100 | G13: {=Common_InputFunctions.Utility_LookupValueInTable(Table_Input_Fuel[[#This Row],[Fuel type (select)]],[1]!Table_FuelTypes_Units[Fuel type], [1]!Table_FuelTypes_Units[Unit])} -> kL | H13: =1 -> 1 | I13: =Table_Input_Fuel[[#This Row],[Amount purchased]]*Table_Input_Fuel[[#This Row],[Percent consumed]]*10^-3 -> 0.1
D14: General use | E14: Ethanol | F14: 100 | G14: {=Common_InputFunctions.Utility_LookupValueInTable(Table_Input_Fuel[[#This Row],[Fuel type (select)]],[1]!Table_FuelTypes_Units[Fuel type], [1]!Table_FuelTypes_Units[Unit])} -> kL | H14: =1 -> 1 | I14: =Table_Input_Fuel[[#This Row],[Amount purchased]]*Table_Input_Fuel[[#This Row],[Percent consumed]]*10^-3 -> 0.1
D15: General use | E15: Other biofuels | F15: 100 | G15: {=Common_InputFunctions.Utility_LookupValueInTable(Table_Input_Fuel[[#This Row],[Fuel type (select)]],[1]!Table_FuelTypes_Units[Fuel type], [1]!Table_FuelTypes_Units[Unit])} -> kL | H15: =1 -> 1 | I15: =Table_Input_Fuel[[#This Row],[Amount purchased]]*Table_Input_Fuel[[#This Row],[Percent consumed]]*10^-3 -> 0.1
D16: General use | E16: Biodiesel | F16: 100 | G16: {=Common_InputFunctions.Utility_LookupValueInTable(Table_Input_Fuel[[#This Row],[Fuel type (select)]],[1]!Table_FuelTypes_Units[Fuel type], [1]!Table_FuelTypes_Units[Unit])} -> kL | H16: =1 -> 1 | I16: =Table_Input_Fuel[[#This Row],[Amount purchased]]*Table_Input_Fuel[[#This Row],[Percent consumed]]*10^-3 -> 0.1
D17: General use | E17: Liquefied petroleum gas (LPG) | F17: 100 | G17: {=Common_InputFunctions.Utility_LookupValueInTable(Table_Input_Fuel[[#This Row],[Fuel type (select)]],[1]!Table_FuelTypes_Units[Fuel type], [1]!Table_FuelTypes_Units[Unit])} -> kL | H17: =1 -> 1 | I17: =Table_Input_Fuel[[#This Row],[Amount purchased]]*Table_Input_Fuel[[#This Row],[Percent consumed]]*10^-3 -> 0.1
D18: General use | E18: Petrol | F18: 100 | G18: {=Common_InputFunctions.Utility_LookupValueInTable(Table_Input_Fuel[[#This Row],[Fuel type (select)]],[1]!Table_FuelTypes_Units[Fuel type], [1]!Table_FuelTypes_Units[Unit])} -> kL | H18: =1 -> 1 | I18: =Table_Input_Fuel[[#This Row],[Amount purchased]]*Table_Input_Fuel[[#This Row],[Percent consumed]]*10^-3 -> 0.1
D19: General use | E19: Petrol | F19: 100 | G19: {=Common_InputFunctions.Utility_LookupValueInTable(Table_Input_Fuel[[#This Row],[Fuel type (select)]],[1]!Table_FuelTypes_Units[Fuel type], [1]!Table_FuelTypes_Units[Unit])} -> kL | H19: =1 -> 1 | I19: =Table_Input_Fuel[[#This Row],[Amount purchased]]*Table_Input_Fuel[[#This Row],[Percent consumed]]*10^-3 -> 0.1
D20: General use | E20: Renewable diesel | F20: 100 | G20: {=Common_InputFunctions.Utility_LookupValueInTable(Table_Input_Fuel[[#This Row],[Fuel type (select)]],[1]!Table_FuelTypes_Units[Fuel type], [1]!Table_FuelTypes_Units[Unit])} -> kL | H20: =1 -> 1 | I20: =Table_Input_Fuel[[#This Row],[Amount purchased]]*Table_Input_Fuel[[#This Row],[Percent consumed]]*10^-3 -> 0.1
D21: General use | E21: Natural gas (via pipeline) in GJ | F21: 100 | G21: {=Common_InputFunctions.Utility_LookupValueInTable(Table_Input_Fuel[[#This Row],[Fuel type (select)]],[1]!Table_FuelTypes_Units[Fuel type], [1]!Table_FuelTypes_Units[Unit])} -> GJ | H21: =1 -> 1 | I21: =Table_Input_Fuel[[#This Row],[Amount purchased]]*Table_Input_Fuel[[#This Row],[Percent consumed]]*10^-3 -> 0.1
D22: General use | E22: Town gas in GJ | F22: 100 | G22: {=Common_InputFunctions.Utility_LookupValueInTable(Table_Input_Fuel[[#This Row],[Fuel type (select)]],[1]!Table_FuelTypes_Units[Fuel type], [1]!Table_FuelTypes_Units[Unit])} -> GJ | H22: =1 -> 1 | I22: =Table_Input_Fuel[[#This Row],[Amount purchased]]*Table_Input_Fuel[[#This Row],[Percent consumed]]*10^-3 -> 0.1

Sheet 8.1.1.1-2 Transport fuel
A1: #VALUE! | C1: 8.1.1.1-2 Transport fuel combustion
D3: Method 1
D5: {=Fuel_Equations.VEERG_8_1_1_1__1_FuelCombustionTransport_Title()} -> Emissions for each GHG from the combustion of fuels for transport energy purposes
D6: {=Fuel_Equations.VEERG_8_1_1_1__1_FuelCombustionTransport_Source()} -> VEERG 2026: 8.1.1.1, Equation (1)
D7: Function name | E7: {=Common_InputFunctions.Utility_DisplayFunctionName(M25)} -> =Fuel_Equations.VEERG_8_1_1_1__1_FuelCombustionTransport
D11: Variable | E11: {=Fuel_Equations.VEERG_8_1_1_1__1_FuelCombustionTransport_Variable()} -> E_g
D12: Unit | E12: {=Fuel_Equations.VEERG_8_1_1_1__1_FuelCombustionTransport_Unit()} -> t CO2-e
D14: {=_xlfn.CHOOSECOLS(Fuel_Equations.VEERG_8_1_1_1__1_FuelCombustionTransport_Arguments(), 1,2)} -> Q_Transtq | E14: Amount of fuel type q combusted for transport energy purposes | G14: {=_xlfn.CHOOSECOLS(Fuel_Equations.VEERG_8_1_1_1__1_FuelCombustionTransport_Arguments(), 3,4)} -> Varies based on fuel type: kL, m3, GJ | H14: Input | I14: {=HYPERLINK(Common_InputFunctions.Utility_SourceHyperlink($D$22), $D$22)} -> Table_E_g
D15: EC_Transq | E15: Energy content factor for transport energy purposes | G15: GJ / unit of fuel | H15: Constant | I15: {=HYPERLINK(Common_InputFunctions.Utility_SourceHyperlink($D$22), $D$22)} -> Table_E_g
D16: EF_Trans1tqg | E16: Scope 1 emission factor for transport energy purposes for each greenhouse gas | G16: kg CO2e / GJ | H16: Constant | I16: {=HYPERLINK(Common_InputFunctions.Utility_SourceHyperlink($D$22), $D$22)} -> Table_E_g
D17: q | E17: Fuel type | H17: Constant
D18: Trans | E18: Transport combustion | H18: Constant
D19: g | E19: Greenhouse gas | H19: Constant
D20: 1 | E20: Scope 1 | H20: Constant
D22: Table_E_g
D23: Emissions for transport fuel combustion
D24: Fuel use | E24: Fuel type (NGAF terminology) | F24: Fuel type (q) | G24: ECTrans,q | H24: EFTrans,1,q,g=CO2 | I24: EFTrans,1,q,g=CH4 | J24: EFTrans,1,q,g=N20 | K24: QTrans,q | L24: Q unit | M24: Eg=CO2 | N24: Eg=CH4 | O24: Eg=N20
D25: =Table_FuelTypesPerUse[[#Headers],[Cars and light commercial vehicles]] -> Cars and light commercial vehicles | E25: ='Constants - Fuel'!$E$10 -> Gasoline | F25: ='Constants - Fuel'!G131 -> Petrol | G25: {=IFERROR(_xlfn.XLOOKUP(1, (Table_Fuel_EFs_Transport[Fuel combusted]=$E25)*(Table_Fuel_EFs_Transport[Transport type]=$D$25), Table_Fuel_EFs_Transport[Energy Content Factor (GJ per unit of fuel)]), 0)} -> 34.2 | H25: {=IFERROR(_xlfn.XLOOKUP(1, (Table_Fuel_EFs_Transport[Fuel combusted]=$E25)*(Table_Fuel_EFs_Transport[Transport type]=$D$25), Table_Fuel_EFs_Transport[Scope 1 Emission Factor (kg CO2 - e / GJ) CO2]), 0)} -> 67.4 | I25: {=IFERROR(_xlfn.XLOOKUP(1, (Table_Fuel_EFs_Transport[Fuel combusted]=$E25)*(Table_Fuel_EFs_Transport[Transport type]=$D$25), Table_Fuel_EFs_Transport[Scope 1 Emission Factor (kg CO2 - e / GJ) CH4]), 0)} -> 0.02 | J25: {=IFERROR(_xlfn.XLOOKUP(1, (Table_Fuel_EFs_Transport[Fuel combusted]=$E25)*(Table_Fuel_EFs_Transport[Transport type]=$D$25), Table_Fuel_EFs_Transport[Scope 1 Emission Factor (kg CO2 - e / GJ) N2O]), 0)} -> 0.2 | K25: {=Fuel_InputFunctions.Fuel_TotalConsumption(Table_Input_Fuel[Amount consumed], Table_Input_Fuel[Fuel use (select)], D25, Table_Input_Fuel[Fuel type (select)],F25)} -> 0 | L25: {=Common_InputFunctions.Utility_LookupValueInTable(F25,Table_FuelTypes_Units[Fuel type],Table_FuelTypes_Units[Unit])} -> kL | M25: {=Fuel_Equations.VEERG_8_1_1_1__1_FuelCombustionTransport($K25,$G25,$H25)} -> 0 | N25: {=Fuel_Equations.VEERG_8_1_1_1__1_FuelCombustionTransport($K25,$G25,$I25)} -> 0 | O25: {=Fuel_Equations.VEERG_8_1_1_1__1_FuelCombustionTransport($K25,$G25,$J25)} -> 0
D26: =$D$25 -> Cars and light commercial vehicles | E26: ='Constants - Fuel'!$E$11 -> Diesel oil | F26: ='Constants - Fuel'!G132 -> Diesel | G26: {=IFERROR(_xlfn.XLOOKUP(1, (Table_Fuel_EFs_Transport[Fuel combusted]=$E26)*(Table_Fuel_EFs_Transport[Transport type]=$D$25), Table_Fuel_EFs_Transport[Energy Content Factor (GJ per unit of fuel)]), 0)} -> 38.6 | H26: {=IFERROR(_xlfn.XLOOKUP(1, (Table_Fuel_EFs_Transport[Fuel combusted]=$E26)*(Table_Fuel_EFs_Transport[Transport type]=$D$25), Table_Fuel_EFs_Transport[Scope 1 Emission Factor (kg CO2 - e / GJ) CO2]), 0)} -> 69.9 | I26: {=IFERROR(_xlfn.XLOOKUP(1, (Table_Fuel_EFs_Transport[Fuel combusted]=$E26)*(Table_Fuel_EFs_Transport[Transport type]=$D$25), Table_Fuel_EFs_Transport[Scope 1 Emission Factor (kg CO2 - e / GJ) CH4]), 0)} -> 0.01 | J26: {=IFERROR(_xlfn.XLOOKUP(1, (Table_Fuel_EFs_Transport[Fuel combusted]=$E26)*(Table_Fuel_EFs_Transport[Transport type]=$D$25), Table_Fuel_EFs_Transport[Scope 1 Emission Factor (kg CO2 - e / GJ) N2O]), 0)} -> 0.5 | K26: {=Fuel_InputFunctions.Fuel_TotalConsumption(Table_Input_Fuel[Amount consumed], Table_Input_Fuel[Fuel use (select)], D26, Table_Input_Fuel[Fuel type (select)],F26)} -> 0 | L26: {=Common_InputFunctions.Utility_LookupValueInTable(F26,Table_FuelTypes_Units[Fuel type],Table_FuelTypes_Units[Unit])} -> kL | M26: {=Fuel_Equations.VEERG_8_1_1_1__1_FuelCombustionTransport($K26,$G26,$H26)} -> 0 | N26: {=Fuel_Equations.VEERG_8_1_1_1__1_FuelCombustionTransport($K26,$G26,$I26)} -> 0 | O26: {=Fuel_Equations.VEERG_8_1_1_1__1_FuelCombustionTransport($K26,$G26,$J26)} -> 0
D27: =$D$25 -> Cars and light commercial vehicles | E27: ='Constants - Fuel'!$E$12 -> Liquefied petroleum gas (LPG) | F27: ='Constants - Fuel'!G133 -> Liquefied petroleum gas (LPG) | G27: {=IFERROR(_xlfn.XLOOKUP(1, (Table_Fuel_EFs_Transport[Fuel combusted]=$E27)*(Table_Fuel_EFs_Transport[Transport type]=$D$25), Table_Fuel_EFs_Transport[Energy Content Factor (GJ per unit of fuel)]), 0)} -> 26.2 | H27: {=IFERROR(_xlfn.XLOOKUP(1, (Table_Fuel_EFs_Transport[Fuel combusted]=$E27)*(Table_Fuel_EFs_Transport[Transport type]=$D$25), Table_Fuel_EFs_Transport[Scope 1 Emission Factor (kg CO2 - e / GJ) CO2]), 0)} -> 60.2 | I27: {=IFERROR(_xlfn.XLOOKUP(1, (Table_Fuel_EFs_Transport[Fuel combusted]=$E27)*(Table_Fuel_EFs_Transport[Transport type]=$D$25), Table_Fuel_EFs_Transport[Scope 1 Emission Factor (kg CO2 - e / GJ) CH4]), 0)} -> 0.5 | J27: {=IFERROR(_xlfn.XLOOKUP(1, (Table_Fuel_EFs_Transport[Fuel combusted]=$E27)*(Table_Fuel_EFs_Transport[Transport type]=$D$25), Table_Fuel_EFs_Transport[Scope 1 Emission Factor (kg CO2 - e / GJ) N2O]), 0)} -> 0.3 | K27: {=Fuel_InputFunctions.Fuel_TotalConsumption(Table_Input_Fuel[Amount consumed], Table_Input_Fuel[Fuel use (select)], D27, Table_Input_Fuel[Fuel type (select)],F27)} -> 0 | L27: {=Common_InputFunctions.Utility_LookupValueInTable(F27,Table_FuelTypes_Units[Fuel type],Table_FuelTypes_Units[Unit])} -> kL | M27: {=Fuel_Equations.VEERG_8_1_1_1__1_FuelCombustionTransport($K27,$G27,$H27)} -> 0 | N27: {=Fuel_Equations.VEERG_8_1_1_1__1_FuelCombustionTransport($K27,$G27,$I27)} -> 0 | O27: {=Fuel_Equations.VEERG_8_1_1_1__1_FuelCombustionTransport($K27,$G27,$J27)} -> 0
D28: =$D$25 -> Cars and light commercial vehicles | E28: ='Constants - Fuel'!$E$13 -> Fuel oil | F28: ='Constants - Fuel'!G134 -> Fuel oil | G28: {=IFERROR(_xlfn.XLOOKUP(1, (Table_Fuel_EFs_Transport[Fuel combusted]=$E28)*(Table_Fuel_EFs_Transport[Transport type]=$D$25), Table_Fuel_EFs_Transport[Energy Content Factor (GJ per unit of fuel)]), 0)} -> 39.7 | H28: {=IFERROR(_xlfn.XLOOKUP(1, (Table_Fuel_EFs_Transport[Fuel combusted]=$E28)*(Table_Fuel_EFs_Transport[Transport type]=$D$25), Table_Fuel_EFs_Transport[Scope 1 Emission Factor (kg CO2 - e / GJ) CO2]), 0)} -> 73.6 | I28: {=IFERROR(_xlfn.XLOOKUP(1, (Table_Fuel_EFs_Transport[Fuel combusted]=$E28)*(Table_Fuel_EFs_Transport[Transport type]=$D$25), Table_Fuel_EFs_Transport[Scope 1 Emission Factor (kg CO2 - e / GJ) CH4]), 0)} -> 0.08 | J28: {=IFERROR(_xlfn.XLOOKUP(1, (Table_Fuel_EFs_Transport[Fuel combusted]=$E28)*(Table_Fuel_EFs_Transport[Transport type]=$D$25), Table_Fuel_EFs_Transport[Scope 1 Emission Factor (kg CO2 - e / GJ) N2O]), 0)} -> 0.5 | K28: {=Fuel_InputFunctions.Fuel_TotalConsumption(Table_Input_Fuel[Amount consumed], Table_Input_Fuel[Fuel use (select)], D28, Table_Input_Fuel[Fuel type (select)],F28)} -> 0 | L28: {=Common_InputFunctions.Utility_LookupValueInTable(F28,Table_FuelTypes_Units[Fuel type],Table_FuelTypes_Units[Unit])} -> kL | M28: {=Fuel_Equations.VEERG_8_1_1_1__1_FuelCombustionTransport($K28,$G28,$H28)} -> 0 | N28: {=Fuel_Equations.VEERG_8_1_1_1__1_FuelCombustionTransport($K28,$G28,$I28)} -> 0 | O28: {=Fuel_Equations.VEERG_8_1_1_1__1_FuelCombustionTransport($K28,$G28,$J28)} -> 0
D29: =$D$25 -> Cars and light commercial vehicles | E29: ='Constants - Fuel'!$E$14 -> Ethanol | F29: ='Constants - Fuel'!G135 -> Ethanol | G29: {=IFERROR(_xlfn.XLOOKUP(1, (Table_Fuel_EFs_Transport[Fuel combusted]=$E29)*(Table_Fuel_EFs_Transport[Transport type]=$D$25), Table_Fuel_EFs_Transport[Energy Content Factor (GJ per unit of fuel)]), 0)} -> 23.4 | H29: {=IFERROR(_xlfn.XLOOKUP(1, (Table_Fuel_EFs_Transport[Fuel combusted]=$E29)*(Table_Fuel_EFs_Transport[Transport type]=$D$25), Table_Fuel_EFs_Transport[Scope 1 Emission Factor (kg CO2 - e / GJ) CO2]), 0)} -> 0 | I29: {=IFERROR(_xlfn.XLOOKUP(1, (Table_Fuel_EFs_Transport[Fuel combusted]=$E29)*(Table_Fuel_EFs_Transport[Transport type]=$D$25), Table_Fuel_EFs_Transport[Scope 1 Emission Factor (kg CO2 - e / GJ) CH4]), 0)} -> 0.2 | J29: {=IFERROR(_xlfn.XLOOKUP(1, (Table_Fuel_EFs_Transport[Fuel combusted]=$E29)*(Table_Fuel_EFs_Transport[Transport type]=$D$25), Table_Fuel_EFs_Transport[Scope 1 Emission Factor (kg CO2 - e / GJ) N2O]), 0)} -> 0.2 | K29: {=Fuel_InputFunctions.Fuel_TotalConsumption(Table_Input_Fuel[Amount consumed], Table_Input_Fuel[Fuel use (select)], D29, Table_Input_Fuel[Fuel type (select)],F29)} -> 0 | L29: {=Common_InputFunctions.Utility_LookupValueInTable(F29,Table_FuelTypes_Units[Fuel type],Table_FuelTypes_Units[Unit])} -> kL | M29: {=Fuel_Equations.VEERG_8_1_1_1__1_FuelCombustionTransport($K29,$G29,$H29)} -> 0 | N29: {=Fuel_Equations.VEERG_8_1_1_1__1_FuelCombustionTransport($K29,$G29,$I29)} -> 0 | O29: {=Fuel_Equations.VEERG_8_1_1_1__1_FuelCombustionTransport($K29,$G29,$J29)} -> 0
D30: =$D$25 -> Cars and light commercial vehicles | E30: ='Constants - Fuel'!$E$15 -> Biodiesel | F30: ='Constants - Fuel'!G136 -> Biodiesel | G30: {=IFERROR(_xlfn.XLOOKUP(1, (Table_Fuel_EFs_Transport[Fuel combusted]=$E30)*(Table_Fuel_EFs_Transport[Transport type]=$D$25), Table_Fuel_EFs_Transport[Energy Content Factor (GJ per unit of fuel)]), 0)} -> 34.6 | H30: {=IFERROR(_xlfn.XLOOKUP(1, (Table_Fuel_EFs_Transport[Fuel combusted]=$E30)*(Table_Fuel_EFs_Transport[Transport type]=$D$25), Table_Fuel_EFs_Transport[Scope 1 Emission Factor (kg CO2 - e / GJ) CO2]), 0)} -> 0 | I30: {=IFERROR(_xlfn.XLOOKUP(1, (Table_Fuel_EFs_Transport[Fuel combusted]=$E30)*(Table_Fuel_EFs_Transport[Transport type]=$D$25), Table_Fuel_EFs_Transport[Scope 1 Emission Factor (kg CO2 - e / GJ) CH4]), 0)} -> 0.8 | J30: {=IFERROR(_xlfn.XLOOKUP(1, (Table_Fuel_EFs_Transport[Fuel combusted]=$E30)*(Table_Fuel_EFs_Transport[Transport type]=$D$25), Table_Fuel_EFs_Transport[Scope 1 Emission Factor (kg CO2 - e / GJ) N2O]), 0)} -> 1.7 | K30: {=Fuel_InputFunctions.Fuel_TotalConsumption(Table_Input_Fuel[Amount consumed], Table_Input_Fuel[Fuel use (select)], D30, Table_Input_Fuel[Fuel type (select)],F30)} -> 0 | L30: {=Common_InputFunctions.Utility_LookupValueInTable(F30,Table_FuelTypes_Units[Fuel type],Table_FuelTypes_Units[Unit])} -> kL | M30: {=Fuel_Equations.VEERG_8_1_1_1__1_FuelCombustionTransport($K30,$G30,$H30)} -> 0 | N30: {=Fuel_Equations.VEERG_8_1_1_1__1_FuelCombustionTransport($K30,$G30,$I30)} -> 0 | O30: {=Fuel_Equations.VEERG_8_1_1_1__1_FuelCombustionTransport($K30,$G30,$J30)} -> 0
D31: =$D$25 -> Cars and light commercial vehicles | E31: ='Constants - Fuel'!$E$16 -> Renewable diesel | F31: ='Constants - Fuel'!G137 -> Renewable diesel | G31: {=IFERROR(_xlfn.XLOOKUP(1, (Table_Fuel_EFs_Transport[Fuel combusted]=$E31)*(Table_Fuel_EFs_Transport[Transport type]=$D$25), Table_Fuel_EFs_Transport[Energy Content Factor (GJ per unit of fuel)]), 0)} -> 38.6 | H31: {=IFERROR(_xlfn.XLOOKUP(1, (Table_Fuel_EFs_Transport[Fuel combusted]=$E31)*(Table_Fuel_EFs_Transport[Transport type]=$D$25), Table_Fuel_EFs_Transport[Scope 1 Emission Factor (kg CO2 - e / GJ) CO2]), 0)} -> 0 | I31: {=IFERROR(_xlfn.XLOOKUP(1, (Table_Fuel_EFs_Transport[Fuel combusted]=$E31)*(Table_Fuel_EFs_Transport[Transport type]=$D$25), Table_Fuel_EFs_Transport[Scope 1 Emission Factor (kg CO2 - e / GJ) CH4]), 0)} -> 0.01 | J31: {=IFERROR(_xlfn.XLOOKUP(1, (Table_Fuel_EFs_Transport[Fuel combusted]=$E31)*(Table_Fuel_EFs_Transport[Transport type]=$D$25), Table_Fuel_EFs_Transport[Scope 1 Emission Factor (kg CO2 - e / GJ) N2O]), 0)} -> 0.5 | K31: {=Fuel_InputFunctions.Fuel_TotalConsumption(Table_Input_Fuel[Amount consumed], Table_Input_Fuel[Fuel use (select)], D31, Table_Input_Fuel[Fuel type (select)],F31)} -> 0 | L31: {=Common_InputFunctions.Utility_LookupValueInTable(F31,Table_FuelTypes_Units[Fuel type],Table_FuelTypes_Units[Unit])} -> kL | M31: {=Fuel_Equations.VEERG_8_1_1_1__1_FuelCombustionTransport($K31,$G31,$H31)} -> 0 | N31: {=Fuel_Equations.VEERG_8_1_1_1__1_FuelCombustionTransport($K31,$G31,$I31)} -> 0 | O31: {=Fuel_Equations.VEERG_8_1_1_1__1_FuelCombustionTransport($K31,$G31,$J31)} -> 0
D32: =$D$25 -> Cars and light commercial vehicles | E32: ='Constants - Fuel'!$E$17 -> Other biofuels | F32: ='Constants - Fuel'!G138 -> Other biofuels | G32: {=IFERROR(_xlfn.XLOOKUP(1, (Table_Fuel_EFs_Transport[Fuel combusted]=$E32)*(Table_Fuel_EFs_Transport[Transport type]=$D$25), Table_Fuel_EFs_Transport[Energy Content Factor (GJ per unit of fuel)]), 0)} -> 23.4 | H32: {=IFERROR(_xlfn.XLOOKUP(1, (Table_Fuel_EFs_Transport[Fuel combusted]=$E32)*(Table_Fuel_EFs_Transport[Transport type]=$D$25), Table_Fuel_EFs_Transport[Scope 1 Emission Factor (kg CO2 - e / GJ) CO2]), 0)} -> 0 | I32: {=IFERROR(_xlfn.XLOOKUP(1, (Table_Fuel_EFs_Transport[Fuel combusted]=$E32)*(Table_Fuel_EFs_Transport[Transport type]=$D$25), Table_Fuel_EFs_Transport[Scope 1 Emission Factor (kg CO2 - e / GJ) CH4]), 0)} -> 0.8 | J32: {=IFERROR(_xlfn.XLOOKUP(1, (Table_Fuel_EFs_Transport[Fuel combusted]=$E32)*(Table_Fuel_EFs_Transport[Transport type]=$D$25), Table_Fuel_EFs_Transport[Scope 1 Emission Factor (kg CO2 - e / GJ) N2O]), 0)} -> 1.7 | K32: {=Fuel_InputFunctions.Fuel_TotalConsumption(Table_Input_Fuel[Amount consumed], Table_Input_Fuel[Fuel use (select)], D32, Table_Input_Fuel[Fuel type (select)],F32)} -> 0 | L32: {=Common_InputFunctions.Utility_LookupValueInTable(F32,Table_FuelTypes_Units[Fuel type],Table_FuelTypes_Units[Unit])} -> kL | M32: {=Fuel_Equations.VEERG_8_1_1_1__1_FuelCombustionTransport($K32,$G32,$H32)} -> 0 | N32: {=Fuel_Equations.VEERG_8_1_1_1__1_FuelCombustionTransport($K32,$G32,$I32)} -> 0 | O32: {=Fuel_Equations.VEERG_8_1_1_1__1_FuelCombustionTransport($K32,$G32,$J32)} -> 0
D33: =Table_FuelTypesPerUse[[#Headers],[Off-road Agriculture and forestry equipment]] -> Off-road Agriculture and forestry equipment | E33: ='Constants - Fuel'!$E$11 -> Diesel oil | F33: ='Constants - Fuel'!H131 -> Diesel | G33: {=IFERROR(_xlfn.XLOOKUP(1, (Table_Fuel_EFs_Transport[Fuel combusted]=$E33)*(Table_Fuel_EFs_Transport[Transport type]=$D$33), Table_Fuel_EFs_Transport[Energy Content Factor (GJ per unit of fuel)]), 0)} -> 38.6 | H33: {=IFERROR(_xlfn.XLOOKUP(1, (Table_Fuel_EFs_Transport[Fuel combusted]=$E33)*(Table_Fuel_EFs_Transport[Transport type]=$D$33), Table_Fuel_EFs_Transport[Scope 1 Emission Factor (kg CO2 - e / GJ) CO2]), 0)} -> 69.9 | I33: {=IFERROR(_xlfn.XLOOKUP(1, (Table_Fuel_EFs_Transport[Fuel combusted]=$E33)*(Table_Fuel_EFs_Transport[Transport type]=$D$33), Table_Fuel_EFs_Transport[Scope 1 Emission Factor (kg CO2 - e / GJ) CH4]), 0)} -> 0.3 | J33: {=IFERROR(_xlfn.XLOOKUP(1, (Table_Fuel_EFs_Transport[Fuel combusted]=$E33)*(Table_Fuel_EFs_Transport[Transport type]=$D$33), Table_Fuel_EFs_Transport[Scope 1 Emission Factor (kg CO2 - e / GJ) N2O]), 0)} -> 0.5 | K33: {=Fuel_InputFunctions.Fuel_TotalConsumption(Table_Input_Fuel[Amount consumed], Table_Input_Fuel[Fuel use (select)], D33, Table_Input_Fuel[Fuel type (select)],F33)} -> 0 | L33: {=Common_InputFunctions.Utility_LookupValueInTable(F33,Table_FuelTypes_Units[Fuel type],Table_FuelTypes_Units[Unit])} -> kL | M33: {=Fuel_Equations.VEERG_8_1_1_1__1_FuelCombustionTransport($K33,$G33,$H33)} -> 0 | N33: {=Fuel_Equations.VEERG_8_1_1_1__1_FuelCombustionTransport($K33,$G33,$I33)} -> 0 | O33: {=Fuel_Equations.VEERG_8_1_1_1__1_FuelCombustionTransport($K33,$G33,$J33)} -> 0
D34: =Table_FuelTypesPerUse[[#Headers],[Aviation]] -> Aviation | E34: ='Constants - Fuel'!$E$28 -> Gasoline for use as fuel in an aircraft | F34: ='Constants - Fuel'!$F$131 -> Avgas | G34: {=IFERROR(_xlfn.XLOOKUP(1, (Table_Fuel_EFs_Transport[Fuel combusted]=$E34)*(Table_Fuel_EFs_Transport[Transport type]=$D$34), Table_Fuel_EFs_Transport[Energy Content Factor (GJ per unit of fuel)]), 0)} -> 33.1 | H34: {=IFERROR(_xlfn.XLOOKUP(1, (Table_Fuel_EFs_Transport[Fuel combusted]=$E34)*(Table_Fuel_EFs_Transport[Transport type]=$D$34), Table_Fuel_EFs_Transport[Scope 1 Emission Factor (kg CO2 - e / GJ) CO2]), 0)} -> 67 | I34: {=IFERROR(_xlfn.XLOOKUP(1, (Table_Fuel_EFs_Transport[Fuel combusted]=$E34)*(Table_Fuel_EFs_Transport[Transport type]=$D$34), Table_Fuel_EFs_Transport[Scope 1 Emission Factor (kg CO2 - e / GJ) CH4]), 0)} -> 0.06 | J34: {=IFERROR(_xlfn.XLOOKUP(1, (Table_Fuel_EFs_Transport[Fuel combusted]=$E34)*(Table_Fuel_EFs_Transport[Transport type]=$D$34), Table_Fuel_EFs_Transport[Scope 1 Emission Factor (kg CO2 - e / GJ) N2O]), 0)} -> 0.6 | K34: {=Fuel_InputFunctions.Fuel_TotalConsumption(Table_Input_Fuel[Amount consumed], Table_Input_Fuel[Fuel use (select)], D34, Table_Input_Fuel[Fuel type (select)],F34)} -> 0 | L34: {=Common_InputFunctions.Utility_LookupValueInTable(F34,Table_FuelTypes_Units[Fuel type],Table_FuelTypes_Units[Unit])} -> kL | M34: {=Fuel_Equations.VEERG_8_1_1_1__1_FuelCombustionTransport($K34,$G34,$H34)} -> 0 | N34: {=Fuel_Equations.VEERG_8_1_1_1__1_FuelCombustionTransport($K34,$G34,$I34)} -> 0 | O34: {=Fuel_Equations.VEERG_8_1_1_1__1_FuelCombustionTransport($K34,$G34,$J34)} -> 0
D35: =$D$34 -> Aviation | E35: ='Constants - Fuel'!$E$29 -> Kerosene for use as fuel in an aircraft | F35: ='Constants - Fuel'!$F$132 -> Jet A1, Jet B | G35: {=IFERROR(_xlfn.XLOOKUP(1, (Table_Fuel_EFs_Transport[Fuel combusted]=$E35)*(Table_Fuel_EFs_Transport[Transport type]=$D$34), Table_Fuel_EFs_Transport[Energy Content Factor (GJ per unit of fuel)]), 0)} -> 36.8 | H35: {=IFERROR(_xlfn.XLOOKUP(1, (Table_Fuel_EFs_Transport[Fuel combusted]=$E35)*(Table_Fuel_EFs_Transport[Transport type]=$D$34), Table_Fuel_EFs_Transport[Scope 1 Emission Factor (kg CO2 - e / GJ) CO2]), 0)} -> 69.6 | I35: {=IFERROR(_xlfn.XLOOKUP(1, (Table_Fuel_EFs_Transport[Fuel combusted]=$E35)*(Table_Fuel_EFs_Transport[Transport type]=$D$34), Table_Fuel_EFs_Transport[Scope 1 Emission Factor (kg CO2 - e / GJ) CH4]), 0)} -> 0.01 | J35: {=IFERROR(_xlfn.XLOOKUP(1, (Table_Fuel_EFs_Transport[Fuel combusted]=$E35)*(Table_Fuel_EFs_Transport[Transport type]=$D$34), Table_Fuel_EFs_Transport[Scope 1 Emission Factor (kg CO2 - e / GJ) N2O]), 0)} -> 0.6 | K35: {=Fuel_InputFunctions.Fuel_TotalConsumption(Table_Input_Fuel[Amount consumed], Table_Input_Fuel[Fuel use (select)], D35, Table_Input_Fuel[Fuel type (select)],F35)} -> 0 | L35: {=Common_InputFunctions.Utility_LookupValueInTable(F35,Table_FuelTypes_Units[Fuel type],Table_FuelTypes_Units[Unit])} -> kL | M35: {=Fuel_Equations.VEERG_8_1_1_1__1_FuelCombustionTransport($K35,$G35,$H35)} -> 0 | N35: {=Fuel_Equations.VEERG_8_1_1_1__1_FuelCombustionTransport($K35,$G35,$I35)} -> 0 | O35: {=Fuel_Equations.VEERG_8_1_1_1__1_FuelCombustionTransport($K35,$G35,$J35)} -> 0
D36: =$D$34 -> Aviation | E36: ='Constants - Fuel'!$E$30 -> Renewable aviation kerosene | F36: ='Constants - Fuel'!$F$133 -> Renewable aviation kerosene | G36: {=IFERROR(_xlfn.XLOOKUP(1, (Table_Fuel_EFs_Transport[Fuel combusted]=$E36)*(Table_Fuel_EFs_Transport[Transport type]=$D$34), Table_Fuel_EFs_Transport[Energy Content Factor (GJ per unit of fuel)]), 0)} -> 36.8 | H36: {=IFERROR(_xlfn.XLOOKUP(1, (Table_Fuel_EFs_Transport[Fuel combusted]=$E36)*(Table_Fuel_EFs_Transport[Transport type]=$D$34), Table_Fuel_EFs_Transport[Scope 1 Emission Factor (kg CO2 - e / GJ) CO2]), 0)} -> 0 | I36: {=IFERROR(_xlfn.XLOOKUP(1, (Table_Fuel_EFs_Transport[Fuel combusted]=$E36)*(Table_Fuel_EFs_Transport[Transport type]=$D$34), Table_Fuel_EFs_Transport[Scope 1 Emission Factor (kg CO2 - e / GJ) CH4]), 0)} -> 0.01 | J36: {=IFERROR(_xlfn.XLOOKUP(1, (Table_Fuel_EFs_Transport[Fuel combusted]=$E36)*(Table_Fuel_EFs_Transport[Transport type]=$D$34), Table_Fuel_EFs_Transport[Scope 1 Emission Factor (kg CO2 - e / GJ) N2O]), 0)} -> 0.6 | K36: {=Fuel_InputFunctions.Fuel_TotalConsumption(Table_Input_Fuel[Amount consumed], Table_Input_Fuel[Fuel use (select)], D36, Table_Input_Fuel[Fuel type (select)],F36)} -> 0 | L36: {=Common_InputFunctions.Utility_LookupValueInTable(F36,Table_FuelTypes_Units[Fuel type],Table_FuelTypes_Units[Unit])} -> kL | M36: {=Fuel_Equations.VEERG_8_1_1_1__1_FuelCombustionTransport($K36,$G36,$H36)} -> 0 | N36: {=Fuel_Equations.VEERG_8_1_1_1__1_FuelCombustionTransport($K36,$G36,$I36)} -> 0 | O36: {=Fuel_Equations.VEERG_8_1_1_1__1_FuelCombustionTransport($K36,$G36,$J36)} -> 0
A37: =HYPERLINK("#A1", "▲ Back to top") -> ▲ Back to top | D37: =Table_FuelTypesPerUse[[#Headers],[Vessels]] -> Vessels | E37: ='Constants - Fuel'!$E$10 -> Gasoline | F37: ='Constants - Fuel'!$I$131 -> Petrol | G37: {=IFERROR(_xlfn.XLOOKUP(1, (Table_Fuel_EFs_Transport[Fuel combusted]=$E37)*(Table_Fuel_EFs_Transport[Transport type]=$D$37), Table_Fuel_EFs_Transport[Energy Content Factor (GJ per unit of fuel)]), 0)} -> 34.2 | H37: {=IFERROR(_xlfn.XLOOKUP(1, (Table_Fuel_EFs_Transport[Fuel combusted]=$E37)*(Table_Fuel_EFs_Transport[Transport type]=$D$37), Table_Fuel_EFs_Transport[Scope 1 Emission Factor (kg CO2 - e / GJ) CO2]), 0)} -> 67.4 | I37: {=IFERROR(_xlfn.XLOOKUP(1, (Table_Fuel_EFs_Transport[Fuel combusted]=$E37)*(Table_Fuel_EFs_Transport[Transport type]=$D$37), Table_Fuel_EFs_Transport[Scope 1 Emission Factor (kg CO2 - e / GJ) CH4]), 0)} -> 10.1 | J37: {=IFERROR(_xlfn.XLOOKUP(1, (Table_Fuel_EFs_Transport[Fuel combusted]=$E37)*(Table_Fuel_EFs_Transport[Transport type]=$D$37), Table_Fuel_EFs_Transport[Scope 1 Emission Factor (kg CO2 - e / GJ) N2O]), 0)} -> 0.3 | K37: {=Fuel_InputFunctions.Fuel_TotalConsumption(Table_Input_Fuel[Amount consumed], Table_Input_Fuel[Fuel use (select)], D37, Table_Input_Fuel[Fuel type (select)],F37)} -> 0 | L37: {=Common_InputFunctions.Utility_LookupValueInTable(F37,Table_FuelTypes_Units[Fuel type],Table_FuelTypes_Units[Unit])} -> kL | M37: {=Fuel_Equations.VEERG_8_1_1_1__1_FuelCombustionTransport($K37,$G37,$H37)} -> 0 | N37: {=Fuel_Equations.VEERG_8_1_1_1__1_FuelCombustionTransport($K37,$G37,$I37)} -> 0 | O37: {=Fuel_Equations.VEERG_8_1_1_1__1_FuelCombustionTransport($K37,$G37,$J37)} -> 0
D38: =D37 -> Vessels | E38: ='Constants - Fuel'!$E$11 -> Diesel oil | F38: ='Constants - Fuel'!$I$132 -> Diesel | G38: {=IFERROR(_xlfn.XLOOKUP(1, (Table_Fuel_EFs_Transport[Fuel combusted]=$E38)*(Table_Fuel_EFs_Transport[Transport type]=$D$37), Table_Fuel_EFs_Transport[Energy Content Factor (GJ per unit of fuel)]), 0)} -> 38.6 | H38: {=IFERROR(_xlfn.XLOOKUP(1, (Table_Fuel_EFs_Transport[Fuel combusted]=$E38)*(Table_Fuel_EFs_Transport[Transport type]=$D$37), Table_Fuel_EFs_Transport[Scope 1 Emission Factor (kg CO2 - e / GJ) CO2]), 0)} -> 69.9 | I38: {=IFERROR(_xlfn.XLOOKUP(1, (Table_Fuel_EFs_Transport[Fuel combusted]=$E38)*(Table_Fuel_EFs_Transport[Transport type]=$D$37), Table_Fuel_EFs_Transport[Scope 1 Emission Factor (kg CO2 - e / GJ) CH4]), 0)} -> 0.2 | J38: {=IFERROR(_xlfn.XLOOKUP(1, (Table_Fuel_EFs_Transport[Fuel combusted]=$E38)*(Table_Fuel_EFs_Transport[Transport type]=$D$37), Table_Fuel_EFs_Transport[Scope 1 Emission Factor (kg CO2 - e / GJ) N2O]), 0)} -> 0.5 | K38: {=Fuel_InputFunctions.Fuel_TotalConsumption(Table_Input_Fuel[Amount consumed], Table_Input_Fuel[Fuel use (select)], D38, Table_Input_Fuel[Fuel type (select)],F38)} -> 0 | L38: {=Common_InputFunctions.Utility_LookupValueInTable(F38,Table_FuelTypes_Units[Fuel type],Table_FuelTypes_Units[Unit])} -> kL | M38: {=Fuel_Equations.VEERG_8_1_1_1__1_FuelCombustionTransport($K38,$G38,$H38)} -> 0 | N38: {=Fuel_Equations.VEERG_8_1_1_1__1_FuelCombustionTransport($K38,$G38,$I38)} -> 0 | O38: {=Fuel_Equations.VEERG_8_1_1_1__1_FuelCombustionTransport($K38,$G38,$J38)} -> 0
D39: =D37 -> Vessels | E39: ='Constants - Fuel'!E33 -> Fuel Oil | F39: ='Constants - Fuel'!$I$133 -> Fuel oil | G39: {=IFERROR(_xlfn.XLOOKUP(1, (Table_Fuel_EFs_Transport[Fuel combusted]=$E39)*(Table_Fuel_EFs_Transport[Transport type]=$D$37), Table_Fuel_EFs_Transport[Energy Content Factor (GJ per unit of fuel)]), 0)} -> 39.7 | H39: {=IFERROR(_xlfn.XLOOKUP(1, (Table_Fuel_EFs_Transport[Fuel combusted]=$E39)*(Table_Fuel_EFs_Transport[Transport type]=$D$37), Table_Fuel_EFs_Transport[Scope 1 Emission Factor (kg CO2 - e / GJ) CO2]), 0)} -> 73.6 | I39: {=IFERROR(_xlfn.XLOOKUP(1, (Table_Fuel_EFs_Transport[Fuel combusted]=$E39)*(Table_Fuel_EFs_Transport[Transport type]=$D$37), Table_Fuel_EFs_Transport[Scope 1 Emission Factor (kg CO2 - e / GJ) CH4]), 0)} -> 0.2 | J39: {=IFERROR(_xlfn.XLOOKUP(1, (Table_Fuel_EFs_Transport[Fuel combusted]=$E39)*(Table_Fuel_EFs_Transport[Transport type]=$D$37), Table_Fuel_EFs_Transport[Scope 1 Emission Factor (kg CO2 - e / GJ) N2O]), 0)} -> 0.5 | K39: {=Fuel_InputFunctions.Fuel_TotalConsumption(Table_Input_Fuel[Amount consumed], Table_Input_Fuel[Fuel use (select)], D39, Table_Input_Fuel[Fuel type (select)],F39)} -> 0 | L39: {=Common_InputFunctions.Utility_LookupValueInTable(F39,Table_FuelTypes_Units[Fuel type],Table_FuelTypes_Units[Unit])} -> kL | M39: {=Fuel_Equations.VEERG_8_1_1_1__1_FuelCombustionTransport($K39,$G39,$H39)} -> 0 | N39: {=Fuel_Equations.VEERG_8_1_1_1__1_FuelCombustionTransport($K39,$G39,$I39)} -> 0 | O39: {=Fuel_Equations.VEERG_8_1_1_1__1_FuelCombustionTransport($K39,$G39,$J39)} -> 0
D42: ="Total scope 1 - " & D25 -> Total scope 1 - Cars and light commercial vehicles
D43: CO2 | E43: =SUM(M25:M32) -> 0 | F43: =$E$12 -> t CO2-e
D44: CH4 | E44: =SUM(N25:N32) -> 0 | F44: =$E$12 -> t CO2-e
D45: N2O | E45: =SUM(O25:O32) -> 0 | F45: =$E$12 -> t CO2-e
D48: ="Total - " & D33 -> Total - Off-road Agriculture and forestry equipment
D49: CO2 | E49: =SUM(M33:M33) -> 0 | F49: =$E$12 -> t CO2-e
D50: CH4 | E50: =SUM(N33:N33) -> 0 | F50: =$E$12 -> t CO2-e
D51: N2O | E51: =SUM(O33:O33) -> 0 | F51: =$E$12 -> t CO2-e
...

Sheet 8.2.1.1-2 Stationary fuel
A1: #VALUE! | C1: 8.2.1.1-2 Stationary fuel combustion
A3: =HYPERLINK("#'Home'!A1", "Home") -> Home | D3: Method 1
A4: =HYPERLINK("#'Overview'!A1", "Overview") -> Overview
A5: =HYPERLINK("#'Results'!A1", "Results") -> Results | D5: {=Fuel_Equations.VEERG_8_2_1_1__1_FuelCombustionStationary_Title()} -> Emissions for each GHG from the stationary combustion of fuels
D6: {=Fuel_Equations.VEERG_8_2_1_1__1_FuelCombustionStationary_Source()} -> VEERG 2026: 8.2.1.1, Equation (1)
A7: INPUTS | D7: Function name | E7: {=Common_InputFunctions.Utility_DisplayFunctionName(M25)} -> =Fuel_Equations.VEERG_8_2_1_1__1_FuelCombustionStationary
A8: =HYPERLINK("#'Input - Site'!A1", "Site") -> Site
A9: =HYPERLINK("#'Input - Fertiliser'!A1", "Fertiliser") -> Fertiliser
A11: CALCULATIONS | D11: Variable | E11: {=Fuel_Equations.VEERG_8_2_1_1__1_FuelCombustionStationary_Variable()} -> E_g
A12: =HYPERLINK("#'5.1.1.1-2 Inorganic Fert N2O'!A1", "5.1.1.1-2 Inorganic Fert N2O") -> 5.1.1.1-2 Inorganic Fert N2O | D12: Unit | E12: {=Fuel_Equations.VEERG_8_2_1_1__1_FuelCombustionStationary_Unit()} -> t CO2-e
A13: =HYPERLINK("#'5.1.1.3-4 Inorganic fert CO2'!A1", "5.1.1.3-4 Inorganic fert CO2") -> 5.1.1.3-4 Inorganic fert CO2
A14: =HYPERLINK("#'5.2.1.1-2 Organic Fert N2O'!A1", "5.2.1.1-2 Organic Fert N2O") -> 5.2.1.1-2 Organic Fert N2O | D14: {=_xlfn.CHOOSECOLS(Fuel_Equations.VEERG_8_2_1_1__1_FuelCombustionStationary_Arguments(), 1,2)} -> Q_SCq | E14: Amount of fuel type q used for stationary combustion operations | G14: {=_xlfn.CHOOSECOLS(Fuel_Equations.VEERG_8_2_1_1__1_FuelCombustionStationary_Arguments(), 3,4)} -> Varies based on fuel type: kL, m3, GJ | H14: Input | I14: {=HYPERLINK(Common_InputFunctions.Utility_SourceHyperlink($D$22), $D$22)} -> Table_E_g
A15: =HYPERLINK("#'5.3.1.1-2 Lime CO2'!A1", "5.3.1.1-2 Lime CO2") -> 5.3.1.1-2 Lime CO2 | D15: EC_SCq | E15: Energy content factor for stationary combustion operations | G15: GJ / unit of fuel | H15: Constant | I15: {=HYPERLINK(Common_InputFunctions.Utility_SourceHyperlink($D$22), $D$22)} -> Table_E_g
A16: =HYPERLINK("#'5.4.1.1-4 Atmos deposition'!A1", "5.4.1.1-4 Atmos deposition") -> 5.4.1.1-4 Atmos deposition | D16: EF_SC1qg | E16: Scope 1 emission factor for stationary combustion for each greenhouse gas | G16: kg CO2e / GJ | H16: Constant | I16: {=HYPERLINK(Common_InputFunctions.Utility_SourceHyperlink($D$22), $D$22)} -> Table_E_g
A17: =HYPERLINK("#'5.5.1.1-2 Leaching and runoff'!A1", "5.5.1.1-2 Leaching and runoff") -> 5.5.1.1-2 Leaching and runoff | D17: q | E17: Fuel type | H17: Constant
D18: SC | E18: Stationary combustion | H18: Constant
A19: APPENDICES | D19: g | E19: Greenhouse gas | H19: Constant
A20: =HYPERLINK("#'Constants - Fertiliser'!A1", "Constants - Fertiliser") -> Constants - Fertiliser | D20: 1 | E20: Scope 1 | H20: Constant
A21: =HYPERLINK("#'Constants - Common'!A1", "Constants - Common") -> Constants - Common
D22: Table_E_g
D23: Emissions for stationary fuel combustion
D24: Fuel use | E24: Fuel type (NGAF terminology) | F24: Fuel type (q) | G24: ECSC,q | H24: EFSC,1,q,g=CO2 | I24: EFSC,1,q,g=CH4 | J24: EFSC,1,q,g=N20 | K24: QSC,q | L24: Q unit | M24: Eg=CO2 | N24: Eg=CH4 | O24: Eg=N20
D25: =Table_FuelTypesPerUse[[#Headers],[Generators]] -> Generators | E25: ='Constants - Fuel'!$D$58 -> Automotive gasoline / petrol (other than for use as fuel in an aircraft) | F25: ='Constants - Fuel'!D131 -> Petrol | G25: =IFERROR(_xlfn.XLOOKUP($E25, Table_Fuel_EFs_StationaryLiquid[Fuel combusted], Table_Fuel_EFs_StationaryLiquid[Energy Content Factor (GJ per unit of fuel)]),0) -> 34.2 | H25: =IFERROR(_xlfn.XLOOKUP($E25, Table_Fuel_EFs_StationaryLiquid[Fuel combusted], Table_Fuel_EFs_StationaryLiquid[Scope 1 Emission Factor (kg CO2 - e / GJ) CO2]),0) -> 67.4 | I25: =IFERROR(_xlfn.XLOOKUP($E25, Table_Fuel_EFs_StationaryLiquid[Fuel combusted], Table_Fuel_EFs_StationaryLiquid[Scope 1 Emission Factor (kg CO2 - e / GJ) CH4]),0) -> 0.2 | J25: =IFERROR(_xlfn.XLOOKUP($E25, Table_Fuel_EFs_StationaryLiquid[Fuel combusted], Table_Fuel_EFs_StationaryLiquid[Scope 1 Emission Factor (kg CO2 - e / GJ) N2O]),0) -> 0.2 | K25: {=Fuel_InputFunctions.Fuel_TotalConsumption(Table_Input_Fuel[Amount consumed], Table_Input_Fuel[Fuel use (select)], D25, Table_Input_Fuel[Fuel type (select)],F25)} -> 0 | L25: {=Common_InputFunctions.Utility_LookupValueInTable(F25,Table_FuelTypes_Units[Fuel type],Table_FuelTypes_Units[Unit])} -> kL | M25: {=Fuel_Equations.VEERG_8_2_1_1__1_FuelCombustionStationary($K25,$G25,H25)} -> 0 | N25: {=Fuel_Equations.VEERG_8_2_1_1__1_FuelCombustionStationary($K25,$G25,I25)} -> 0 | O25: {=Fuel_Equations.VEERG_8_2_1_1__1_FuelCombustionStationary($K25,$G25,J25)} -> 0
D26: =$D$25 -> Generators | E26: ='Constants - Fuel'!$D$63 -> Diesel oil | F26: ='Constants - Fuel'!D132 -> Diesel | G26: =IFERROR(_xlfn.XLOOKUP($E26, Table_Fuel_EFs_StationaryLiquid[Fuel combusted], Table_Fuel_EFs_StationaryLiquid[Energy Content Factor (GJ per unit of fuel)]),0) -> 38.6 | H26: =IFERROR(_xlfn.XLOOKUP($E26, Table_Fuel_EFs_StationaryLiquid[Fuel combusted], Table_Fuel_EFs_StationaryLiquid[Scope 1 Emission Factor (kg CO2 - e / GJ) CO2]),0) -> 69.9 | I26: =IFERROR(_xlfn.XLOOKUP($E26, Table_Fuel_EFs_StationaryLiquid[Fuel combusted], Table_Fuel_EFs_StationaryLiquid[Scope 1 Emission Factor (kg CO2 - e / GJ) CH4]),0) -> 0.1 | J26: =IFERROR(_xlfn.XLOOKUP($E26, Table_Fuel_EFs_StationaryLiquid[Fuel combusted], Table_Fuel_EFs_StationaryLiquid[Scope 1 Emission Factor (kg CO2 - e / GJ) N2O]),0) -> 0.2 | K26: {=Fuel_InputFunctions.Fuel_TotalConsumption(Table_Input_Fuel[Amount consumed], Table_Input_Fuel[Fuel use (select)], D26, Table_Input_Fuel[Fuel type (select)],F26)} -> 0 | L26: {=Common_InputFunctions.Utility_LookupValueInTable(F26,Table_FuelTypes_Units[Fuel type],Table_FuelTypes_Units[Unit])} -> kL | M26: {=Fuel_Equations.VEERG_8_2_1_1__1_FuelCombustionStationary($K26,$G26,H26)} -> 0 | N26: {=Fuel_Equations.VEERG_8_2_1_1__1_FuelCombustionStationary($K26,$G26,I26)} -> 0 | O26: {=Fuel_Equations.VEERG_8_2_1_1__1_FuelCombustionStationary($K26,$G26,J26)} -> 0
D27: =$D$25 -> Generators | E27: ='Constants - Fuel'!$D$67 -> Liquefied petroleum gas (LPG) | F27: ='Constants - Fuel'!D133 -> Liquefied petroleum gas (LPG) | G27: =IFERROR(_xlfn.XLOOKUP($E27, Table_Fuel_EFs_StationaryLiquid[Fuel combusted], Table_Fuel_EFs_StationaryLiquid[Energy Content Factor (GJ per unit of fuel)]),0) -> 25.7 | H27: =IFERROR(_xlfn.XLOOKUP($E27, Table_Fuel_EFs_StationaryLiquid[Fuel combusted], Table_Fuel_EFs_StationaryLiquid[Scope 1 Emission Factor (kg CO2 - e / GJ) CO2]),0) -> 60.2 | I27: =IFERROR(_xlfn.XLOOKUP($E27, Table_Fuel_EFs_StationaryLiquid[Fuel combusted], Table_Fuel_EFs_StationaryLiquid[Scope 1 Emission Factor (kg CO2 - e / GJ) CH4]),0) -> 0.2 | J27: =IFERROR(_xlfn.XLOOKUP($E27, Table_Fuel_EFs_StationaryLiquid[Fuel combusted], Table_Fuel_EFs_StationaryLiquid[Scope 1 Emission Factor (kg CO2 - e / GJ) N2O]),0) -> 0.2 | K27: {=Fuel_InputFunctions.Fuel_TotalConsumption(Table_Input_Fuel[Amount consumed], Table_Input_Fuel[Fuel use (select)], D27, Table_Input_Fuel[Fuel type (select)],F27)} -> 0 | L27: {=Common_InputFunctions.Utility_LookupValueInTable(F27,Table_FuelTypes_Units[Fuel type],Table_FuelTypes_Units[Unit])} -> kL | M27: {=Fuel_Equations.VEERG_8_2_1_1__1_FuelCombustionStationary($K27,$G27,H27)} -> 0 | N27: {=Fuel_Equations.VEERG_8_2_1_1__1_FuelCombustionStationary($K27,$G27,I27)} -> 0 | O27: {=Fuel_Equations.VEERG_8_2_1_1__1_FuelCombustionStationary($K27,$G27,J27)} -> 0
D28: =$D$25 -> Generators | E28: ='Constants - Fuel'!$D$73 -> Biodiesel | F28: ='Constants - Fuel'!D134 -> Biodiesel | G28: =IFERROR(_xlfn.XLOOKUP($E28, Table_Fuel_EFs_StationaryLiquid[Fuel combusted], Table_Fuel_EFs_StationaryLiquid[Energy Content Factor (GJ per unit of fuel)]),0) -> 34.6 | H28: =IFERROR(_xlfn.XLOOKUP($E28, Table_Fuel_EFs_StationaryLiquid[Fuel combusted], Table_Fuel_EFs_StationaryLiquid[Scope 1 Emission Factor (kg CO2 - e / GJ) CO2]),0) -> 0 | I28: =IFERROR(_xlfn.XLOOKUP($E28, Table_Fuel_EFs_StationaryLiquid[Fuel combusted], Table_Fuel_EFs_StationaryLiquid[Scope 1 Emission Factor (kg CO2 - e / GJ) CH4]),0) -> 0.08 | J28: =IFERROR(_xlfn.XLOOKUP($E28, Table_Fuel_EFs_StationaryLiquid[Fuel combusted], Table_Fuel_EFs_StationaryLiquid[Scope 1 Emission Factor (kg CO2 - e / GJ) N2O]),0) -> 0.2 | K28: {=Fuel_InputFunctions.Fuel_TotalConsumption(Table_Input_Fuel[Amount consumed], Table_Input_Fuel[Fuel use (select)], D28, Table_Input_Fuel[Fuel type (select)],F28)} -> 0 | L28: {=Common_InputFunctions.Utility_LookupValueInTable(F28,Table_FuelTypes_Units[Fuel type],Table_FuelTypes_Units[Unit])} -> kL | M28: {=Fuel_Equations.VEERG_8_2_1_1__1_FuelCombustionStationary($K28,$G28,H28)} -> 0 | N28: {=Fuel_Equations.VEERG_8_2_1_1__1_FuelCombustionStationary($K28,$G28,I28)} -> 0 | O28: {=Fuel_Equations.VEERG_8_2_1_1__1_FuelCombustionStationary($K28,$G28,J28)} -> 0
D29: =$D$25 -> Generators | E29: ='Constants - Fuel'!$D$74 -> Ethanol for use as a fuel in an internal combustion engine | F29: ='Constants - Fuel'!D135 -> Ethanol | G29: =IFERROR(_xlfn.XLOOKUP($E29, Table_Fuel_EFs_StationaryLiquid[Fuel combusted], Table_Fuel_EFs_StationaryLiquid[Energy Content Factor (GJ per unit of fuel)]),0) -> 23.4 | H29: =IFERROR(_xlfn.XLOOKUP($E29, Table_Fuel_EFs_StationaryLiquid[Fuel combusted], Table_Fuel_EFs_StationaryLiquid[Scope 1 Emission Factor (kg CO2 - e / GJ) CO2]),0) -> 0 | I29: =IFERROR(_xlfn.XLOOKUP($E29, Table_Fuel_EFs_StationaryLiquid[Fuel combusted], Table_Fuel_EFs_StationaryLiquid[Scope 1 Emission Factor (kg CO2 - e / GJ) CH4]),0) -> 0.08 | J29: =IFERROR(_xlfn.XLOOKUP($E29, Table_Fuel_EFs_StationaryLiquid[Fuel combusted], Table_Fuel_EFs_StationaryLiquid[Scope 1 Emission Factor (kg CO2 - e / GJ) N2O]),0) -> 0.2 | K29: {=Fuel_InputFunctions.Fuel_TotalConsumption(Table_Input_Fuel[Amount consumed], Table_Input_Fuel[Fuel use (select)], D29, Table_Input_Fuel[Fuel type (select)],F29)} -> 0 | L29: {=Common_InputFunctions.Utility_LookupValueInTable(F29,Table_FuelTypes_Units[Fuel type],Table_FuelTypes_Units[Unit])} -> kL | M29: {=Fuel_Equations.VEERG_8_2_1_1__1_FuelCombustionStationary($K29,$G29,H29)} -> 0 | N29: {=Fuel_Equations.VEERG_8_2_1_1__1_FuelCombustionStationary($K29,$G29,I29)} -> 0 | O29: {=Fuel_Equations.VEERG_8_2_1_1__1_FuelCombustionStationary($K29,$G29,J29)} -> 0
D30: =$D$25 -> Generators | E30: ='Constants - Fuel'!$D$75 -> Biofuels other than those mentioned in the items above and below | F30: ='Constants - Fuel'!D136 -> Other biofuels | G30: =IFERROR(_xlfn.XLOOKUP($E30, Table_Fuel_EFs_StationaryLiquid[Fuel combusted], Table_Fuel_EFs_StationaryLiquid[Energy Content Factor (GJ per unit of fuel)]),0) -> 23.4 | H30: =IFERROR(_xlfn.XLOOKUP($E30, Table_Fuel_EFs_StationaryLiquid[Fuel combusted], Table_Fuel_EFs_StationaryLiquid[Scope 1 Emission Factor (kg CO2 - e / GJ) CO2]),0) -> 0 | I30: =IFERROR(_xlfn.XLOOKUP($E30, Table_Fuel_EFs_StationaryLiquid[Fuel combusted], Table_Fuel_EFs_StationaryLiquid[Scope 1 Emission Factor (kg CO2 - e / GJ) CH4]),0) -> 0.08 | J30: =IFERROR(_xlfn.XLOOKUP($E30, Table_Fuel_EFs_StationaryLiquid[Fuel combusted], Table_Fuel_EFs_StationaryLiquid[Scope 1 Emission Factor (kg CO2 - e / GJ) N2O]),0) -> 0.2 | K30: {=Fuel_InputFunctions.Fuel_TotalConsumption(Table_Input_Fuel[Amount consumed], Table_Input_Fuel[Fuel use (select)], D30, Table_Input_Fuel[Fuel type (select)],F30)} -> 0 | L30: {=Common_InputFunctions.Utility_LookupValueInTable(F30,Table_FuelTypes_Units[Fuel type],Table_FuelTypes_Units[Unit])} -> kL | M30: {=Fuel_Equations.VEERG_8_2_1_1__1_FuelCombustionStationary($K30,$G30,H30)} -> 0 | N30: {=Fuel_Equations.VEERG_8_2_1_1__1_FuelCombustionStationary($K30,$G30,I30)} -> 0 | O30: {=Fuel_Equations.VEERG_8_2_1_1__1_FuelCombustionStationary($K30,$G30,J30)} -> 0
D31: =$D$25 -> Generators | E31: ='Constants - Fuel'!$D$77 -> Renewable diesel | F31: ='Constants - Fuel'!D137 -> Renewable diesel | G31: =IFERROR(_xlfn.XLOOKUP($E31, Table_Fuel_EFs_StationaryLiquid[Fuel combusted], Table_Fuel_EFs_StationaryLiquid[Energy Content Factor (GJ per unit of fuel)]),0) -> 38.6 | H31: =IFERROR(_xlfn.XLOOKUP($E31, Table_Fuel_EFs_StationaryLiquid[Fuel combusted], Table_Fuel_EFs_StationaryLiquid[Scope 1 Emission Factor (kg CO2 - e / GJ) CO2]),0) -> 0 | I31: =IFERROR(_xlfn.XLOOKUP($E31, Table_Fuel_EFs_StationaryLiquid[Fuel combusted], Table_Fuel_EFs_StationaryLiquid[Scope 1 Emission Factor (kg CO2 - e / GJ) CH4]),0) -> 0.1 | J31: =IFERROR(_xlfn.XLOOKUP($E31, Table_Fuel_EFs_StationaryLiquid[Fuel combusted], Table_Fuel_EFs_StationaryLiquid[Scope 1 Emission Factor (kg CO2 - e / GJ) N2O]),0) -> 0.2 | K31: {=Fuel_InputFunctions.Fuel_TotalConsumption(Table_Input_Fuel[Amount consumed], Table_Input_Fuel[Fuel use (select)], D31, Table_Input_Fuel[Fuel type (select)],F31)} -> 0 | L31: {=Common_InputFunctions.Utility_LookupValueInTable(F31,Table_FuelTypes_Units[Fuel type],Table_FuelTypes_Units[Unit])} -> kL | M31: {=Fuel_Equations.VEERG_8_2_1_1__1_FuelCombustionStationary($K31,$G31,H31)} -> 0 | N31: {=Fuel_Equations.VEERG_8_2_1_1__1_FuelCombustionStationary($K31,$G31,I31)} -> 0 | O31: {=Fuel_Equations.VEERG_8_2_1_1__1_FuelCombustionStationary($K31,$G31,J31)} -> 0
