Workbook
Name Common_Equations.Common_ConvertCH4ToCO2e: _xlfn.LAMBDA(_xlpm.E_CH4,_xlpm.GWP_CH4, _xlpm.E_CH4 * _xlpm.GWP_CH4)
Name Common_Equations.Common_ConvertCH4ToCO2e_Arguments: _xlfn.LAMBDA(_xlfn.MAKEARRAY(2, 2, _xlfn.LAMBDA(_xlpm.r,_xlpm.c, INDEX({"ECH4","Methane emissions (t CH4)";"GWPCH4","Global warming potential for methane (t CO2-e / t CH4)"}, _xlpm.r, _xlpm.c))))
Name Common_Equations.Common_ConvertCH4ToCO2e_LatexEquation: _xlfn.LAMBDA("CO2_e = E_{CH4} \times GWP_{CH4}")
Name Common_Equations.Common_ConvertCH4ToCO2e_NIRReference: _xlfn.LAMBDA("")
Name Common_Equations.Common_ConvertCH4ToCO2e_Title: _xlfn.LAMBDA("Convert methane emissions to carbon dioxide equivalent emissions")
Name Common_Equations.Common_ConvertCH4ToCO2e_Unit: _xlfn.LAMBDA("t CO2e")
Name Common_Equations.Common_ConvertCH4ToCO2e_Variable: _xlfn.LAMBDA("ECH4 CO2e")
Name Common_Equations.Common_ConvertN2OToCO2e: _xlfn.LAMBDA(_xlpm.E_N2O,_xlpm.GWP_N2O, _xlpm.E_N2O * _xlpm.GWP_N2O)
Name Common_Equations.Common_ConvertN2OToCO2e_LatexEquation: _xlfn.LAMBDA("CO2_e = E_{N2O} \times GWP_{N2O}")
Name Common_Equations.Common_ConvertN2OToCO2e_NIRReference: _xlfn.LAMBDA("")
Name Common_Equations.Common_ConvertN2OToCO2e_Title: _xlfn.LAMBDA("Convert nitrous oxide emissions to carbon dioxide equivalent emissions")
Name Common_Equations.Common_ConvertN2OToCO2e_Unit: _xlfn.LAMBDA("t CO2e")
Name Common_Equations.Common_ConvertN2OToCO2e_Variable: _xlfn.LAMBDA("EN2O CO2e")
Name Common_InputFunctions.Utility_ConvertStateCommonNameToAbbreviation: _xlfn.LAMBDA(_xlpm.StateCommonName,_xlpm.StateCommonNameArray,_xlpm.StateAbbreviationArray, _xlfn.XLOOKUP(_xlpm.StateCommonName, _xlpm.StateCommonNameArray, _xlpm.StateAbbreviationArray, ""))
Name Common_InputFunctions.Utility_DisplayArguments_1_2: _xlfn.LAMBDA(_xlpm.ArgumentsArray, _xlfn.CHOOSECOLS(_xlpm.ArgumentsArray, 1, 2))
Name Common_InputFunctions.Utility_DisplayArguments_3_4: _xlfn.LAMBDA(_xlpm.ArgumentsArray, _xlfn.CHOOSECOLS(_xlpm.ArgumentsArray, 3, 4))
Name Common_InputFunctions.Utility_DisplayFunctionName: _xlfn.LAMBDA(_xlpm.Function, _xlfn.TEXTBEFORE(_xlfn.FORMULATEXT(_xlpm.Function), "("))
Name Common_InputFunctions.Utility_GetArrayTableColumnStartNumber: _xlfn.LAMBDA(_xlpm.TableHeaderCell, COLUMN(_xlpm.TableHeaderCell))
Name Common_InputFunctions.Utility_GetArrayTableRowStartNumber: _xlfn.LAMBDA(_xlpm.TableheaderCell,_xlpm.RowsBetweenHeaderandArray, ROW(_xlpm.TableheaderCell) + _xlpm.RowsBetweenHeaderandArray - 1)
Name Common_InputFunctions.Utility_LookupValueInTable: _xlfn.LAMBDA(_xlpm.LookupValue,_xlpm.LookupArray,_xlpm.ReturnArray, _xlfn.XLOOKUP(_xlpm.LookupValue, _xlpm.LookupArray, _xlpm.ReturnArray, ""))
Name Common_InputFunctions.Utility_SourceHyperlink: _xlfn.LAMBDA(_xlpm.TargetCell, _xlfn.LET(_xlpm.sh, _xlfn.TEXTAFTER(CELL("filename", _xlpm.TargetCell), "]"), _xlpm.addr, CELL("address", _xlpm.TargetCell), "#'" & _xlpm.sh & "'!" & _xlpm.addr))
Name Common_SourceData.Common_SourceData_AustralianStatesTerritories_Source: _xlfn.LAMBDA("")
Name Common_SourceData.Common_SourceData_AustralianStatesTerritories_Title: _xlfn.LAMBDA("Australian states and territories")
Name Common_SourceData.Common_SourceData_AustralianStatesTerritories_Unit: _xlfn.LAMBDA("")
Name Common_SourceData.Common_SourceData_AustralianStatesTerritories_Variable: _xlfn.LAMBDA("")
Name Common_SourceData.Common_SourceData_ClimateZones_Source: _xlfn.LAMBDA("VEERG 2026: Table 1.3: Climate and Rainfall zone classifications and definitions")
Name Common_SourceData.Common_SourceData_ClimateZones_Title: _xlfn.LAMBDA("VEERG Australian climate zones")
Name Common_SourceData.Common_SourceData_ClimateZones_Unit: _xlfn.LAMBDA("")
Name Common_SourceData.Common_SourceData_ClimateZones_Variable: _xlfn.LAMBDA("")
Name Common_SourceData.Common_SourceData_ConvertGasElementalToMolecular_Source: _xlfn.LAMBDA("XXXXXXX")
Name Common_SourceData.Common_SourceData_ConvertGasElementalToMolecular_Title: _xlfn.LAMBDA("Factor to convert elemental mass of gas to molecular mass")
Name Common_SourceData.Common_SourceData_ConvertGasElementalToMolecular_Unit: _xlfn.LAMBDA("factor")
Name Common_SourceData.Common_SourceData_ConvertGasElementalToMolecular_Variable: _xlfn.LAMBDA("Cg")
Name Common_SourceData.Common_SourceData_ConvertN2oElementalToMolecularCg_Data: _xlfn.LAMBDA(44 / 28)
Name Common_SourceData.Common_SourceData_ConvertN2oElementalToMolecularCg_Source: _xlfn.LAMBDA("National Inventory Report 2023 Volume 1")
Name Common_SourceData.Common_SourceData_ConvertN2oElementalToMolecularCg_Title: _xlfn.LAMBDA("Factor to convert elemental mass of N2O to molecular mass")
Name Common_SourceData.Common_SourceData_ConvertN2oElementalToMolecularCg_Unit: _xlfn.LAMBDA("factor")
Name Common_SourceData.Common_SourceData_ConvertN2oElementalToMolecularCg_Variable: _xlfn.LAMBDA("CgN2O")
Name Common_SourceData.Common_SourceData_DataScores_Scope3_Source: _xlfn.LAMBDA("VEERG 2026: XXXXXXXX")
Name Common_SourceData.Common_SourceData_DataScores_Scope3_Title: _xlfn.LAMBDA("Australian data scores for scope 3")
Name Common_SourceData.Common_SourceData_DataScores_Scope3_Unit: _xlfn.LAMBDA("")
Name Common_SourceData.Common_SourceData_DataScores_Scope3_Variable: _xlfn.LAMBDA("")
Name Common_SourceData.Common_SourceData_DataScores_Scope3_Variation: _xlfn.LAMBDA("")
Name Common_SourceData.Common_SourceData_DensityOfMethane_Data: _xlfn.LAMBDA(0.6784)
Name Common_SourceData.Common_SourceData_DensityOfMethane_Source: _xlfn.LAMBDA("National Inventory Report 2023 Volume 1: Equations 3.B.1a_2, 3.B.1c_2, 3.B.3_1, 3.B.4g_2")
Name Common_SourceData.Common_SourceData_DensityOfMethane_Title: _xlfn.LAMBDA("p = density of methane")
Name Common_SourceData.Common_SourceData_DensityOfMethane_Unit: _xlfn.LAMBDA("kg/m3")
Name Common_SourceData.Common_SourceData_EFleach_Data: _xlfn.LAMBDA(_xlfn.MAKEARRAY(1, 2, _xlfn.LAMBDA(_xlpm.r,_xlpm.c, INDEX({"EFleach",0.011}, _xlpm.r, _xlpm.c))))
Name Common_SourceData.Common_SourceData_EFleach_NIRReference: _xlfn.LAMBDA("National Inventory Report Volume 1: Equation 3.D.B_10")
Name Common_SourceData.Common_SourceData_EFleach_Source: _xlfn.LAMBDA("VEERG 2026:5.5.2.3 Constant Parameters")
Name Common_SourceData.Common_SourceData_EFleach_Title: _xlfn.LAMBDA("Emission factor for nitrogen leaching and runoff")
Name Common_SourceData.Common_SourceData_EFleach_Unit: _xlfn.LAMBDA("(kg N2O-N / kg N")
Name Common_SourceData.Common_SourceData_EFleach_Variation: _xlfn.LAMBDA((""))
Name Common_SourceData.Common_SourceData_EFN2O_NIRReference: _xlfn.LAMBDA("")
Name Common_SourceData.Common_SourceData_EFN2O_Source: _xlfn.LAMBDA("VEERG 2026: Table A.2.2.1")
Name Common_SourceData.Common_SourceData_EFN2O_Title: _xlfn.LAMBDA("Nitrous oxide emission factors for inorganic fertiliser application")
Name Common_SourceData.Common_SourceData_EFN2O_Unit: _xlfn.LAMBDA("(kg N2O-N / kg N")
Name Common_SourceData.Common_SourceData_EFOrganicFertiliserAndCropResidues_Data: _xlfn.LAMBDA(_xlfn.MAKEARRAY(3, 2, _xlfn.LAMBDA(_xlpm.r,_xlpm.c, INDEX({"Climate zone","EFNi & EFN2O";"Wet climate zone",0.006;"Dry climate zone",0.005}, _xlpm.r, _xlpm.c))))
Name Common_SourceData.Common_SourceData_EFOrganicFertiliserAndCropResidues_NIRReference: _xlfn.LAMBDA("")
Name Common_SourceData.Common_SourceData_EFOrganicFertiliserAndCropResidues_Source: _xlfn.LAMBDA("VEERG 2026: Table A.2.1.4")

Sheet Home
A1: Home

Sheet Overview
A1: #VALUE! | C1: 9: Refrigerant use: Overview
A3: =HYPERLINK("#'Home'!A1", "Home") -> Home
A4: =HYPERLINK("#'Overview'!A1", "Overview") -> Overview
A5: =HYPERLINK("#'Results'!A1", "Results") -> Results | D5: 💡 Below is a diagram that maps the equations used to calculate emissions, and how they interact with each other.
D6: Click on a box to go to the corresponding calculation.
A7: INPUTS
A8: =HYPERLINK("#'Input - Refrigerants'!A1", "Refrigerants") -> Refrigerants
A10: CALCULATIONS
A11: =HYPERLINK("#'9.1.1.1-2 Refrigerant use'!A1", "9.1.1.1-2 Refrigerant use") -> 9.1.1.1-2 Refrigerant use
A13: APPENDICES
A14: =HYPERLINK("#'Constants - Refrigerants'!A1", "Constants - Refrigerants") -> Constants - Refrigerants
A15: =HYPERLINK("#'Constants - Common'!A1", "Constants - Common") -> Constants - Common
L37: `

Sheet Results
A1: #VALUE! | C1: 9: Refrigerant use: Results
A3: =HYPERLINK("#'Home'!A1", "Home") -> Home
A4: =HYPERLINK("#'Overview'!A1", "Overview") -> Overview | D4: Emissions breakdown
A5: =HYPERLINK("#'Results'!A1", "Results") -> Results
D6: 💡 NOTE: When there is no Method 2, the Method 2 result are the same as Method 1
A7: INPUTS
A8: =HYPERLINK("#'Input - Refrigerants'!A1", "Refrigerants") -> Refrigerants | D8: Scope 1 source | E8: GHG emissions method 1 | F8: GHG emissions method 2 | G8: GHG Unit | H8: CO2-e emissions method 1 | I8: CO2-e emissions method 2
D9: 9.1.1.1-2 Refrigerant leakage | E9: ='9.1.1.1-2 Refrigerant use'!E36 -> 0.00085 | F9: =E9 -> 0.00085 | G9: =IF(ISBLANK('9.1.1.1-2 Refrigerant use'!D36), "", "t " & '9.1.1.1-2 Refrigerant use'!D36) -> t R-402A | H9: ='9.1.1.1-2 Refrigerant use'!G62 -> 1.1860424 | I9: =H9 -> 1.1860424 | J9: =IF(ISBLANK('9.1.1.1-2 Refrigerant use'!D36), "", "t CO2e") -> t CO2e
A10: CALCULATIONS | E10: ='9.1.1.1-2 Refrigerant use'!E37 -> 0.00175 | F10: =E10 -> 0.00175 | G10: =IF(ISBLANK('9.1.1.1-2 Refrigerant use'!D37), "", "t " & '9.1.1.1-2 Refrigerant use'!D37) -> t R-422B | H10: ='9.1.1.1-2 Refrigerant use'!G63 -> 2.0794288 | I10: =H10 -> 2.0794288 | J10: =IF(ISBLANK('9.1.1.1-2 Refrigerant use'!D37), "", "t CO2e") -> t CO2e
A11: =HYPERLINK("#'9.1.1.1-2 Refrigerant use'!A1", "9.1.1.1-2 Refrigerant use") -> 9.1.1.1-2 Refrigerant use | E11: ='9.1.1.1-2 Refrigerant use'!E38 -> 0.01221 | F11: =E11 -> 0.01221 | G11: =IF(ISBLANK('9.1.1.1-2 Refrigerant use'!D38), "", "t " & '9.1.1.1-2 Refrigerant use'!D38) -> t R-400 60/40 | H11: ='9.1.1.1-2 Refrigerant use'!G64 -> 70.007256 | I11: =H11 -> 70.007256 | J11: =IF(ISBLANK('9.1.1.1-2 Refrigerant use'!D38), "", "t CO2e") -> t CO2e
E12: ='9.1.1.1-2 Refrigerant use'!E39 -> 0.0157 | F12: =E12 -> 0.0157 | G12: =IF(ISBLANK('9.1.1.1-2 Refrigerant use'!D39), "", "t " & '9.1.1.1-2 Refrigerant use'!D39) -> t R-504 | H12: ='9.1.1.1-2 Refrigerant use'!G65 -> 34.780656 | I12: =H12 -> 34.780656 | J12: =IF(ISBLANK('9.1.1.1-2 Refrigerant use'!D39), "", "t CO2e") -> t CO2e
A13: APPENDICES | E13: ='9.1.1.1-2 Refrigerant use'!E40 -> 0 | F13: =E13 -> 0 | G13: =IF(ISBLANK('9.1.1.1-2 Refrigerant use'!D40), "", "t " & '9.1.1.1-2 Refrigerant use'!D40) | H13: ='9.1.1.1-2 Refrigerant use'!G66 -> 0 | I13: =H13 -> 0 | J13: =IF(ISBLANK('9.1.1.1-2 Refrigerant use'!D40), "", "t CO2e")
A14: =HYPERLINK("#'Constants - Refrigerants'!A1", "Constants - Refrigerants") -> Constants - Refrigerants | E14: ='9.1.1.1-2 Refrigerant use'!E41 -> 0 | F14: =E14 -> 0 | G14: =IF(ISBLANK('9.1.1.1-2 Refrigerant use'!D41), "", "t " & '9.1.1.1-2 Refrigerant use'!D41) | H14: ='9.1.1.1-2 Refrigerant use'!G67 -> 0 | I14: =H14 -> 0 | J14: =IF(ISBLANK('9.1.1.1-2 Refrigerant use'!D41), "", "t CO2e")
A15: =HYPERLINK("#'Constants - Common'!A1", "Constants - Common") -> Constants - Common | E15: ='9.1.1.1-2 Refrigerant use'!E42 -> 0 | F15: =E15 -> 0 | G15: =IF(ISBLANK('9.1.1.1-2 Refrigerant use'!D42), "", "t " & '9.1.1.1-2 Refrigerant use'!D42) | H15: ='9.1.1.1-2 Refrigerant use'!G68 -> 0 | I15: =H15 -> 0 | J15: =IF(ISBLANK('9.1.1.1-2 Refrigerant use'!D42), "", "t CO2e")
E16: ='9.1.1.1-2 Refrigerant use'!E43 -> 0 | F16: =E16 -> 0 | G16: =IF(ISBLANK('9.1.1.1-2 Refrigerant use'!D43), "", "t " & '9.1.1.1-2 Refrigerant use'!D43) | H16: ='9.1.1.1-2 Refrigerant use'!G69 -> 0 | I16: =H16 -> 0 | J16: =IF(ISBLANK('9.1.1.1-2 Refrigerant use'!D43), "", "t CO2e")
E17: ='9.1.1.1-2 Refrigerant use'!E44 -> 0 | F17: =E17 -> 0 | G17: =IF(ISBLANK('9.1.1.1-2 Refrigerant use'!D44), "", "t " & '9.1.1.1-2 Refrigerant use'!D44) | H17: ='9.1.1.1-2 Refrigerant use'!G70 -> 0 | I17: =H17 -> 0 | J17: =IF(ISBLANK('9.1.1.1-2 Refrigerant use'!D44), "", "t CO2e")
E18: ='9.1.1.1-2 Refrigerant use'!E45 -> 0 | F18: =E18 -> 0 | G18: =IF(ISBLANK('9.1.1.1-2 Refrigerant use'!D45), "", "t " & '9.1.1.1-2 Refrigerant use'!D45) | H18: ='9.1.1.1-2 Refrigerant use'!G71 -> 0 | I18: =H18 -> 0 | J18: =IF(ISBLANK('9.1.1.1-2 Refrigerant use'!D45), "", "t CO2e")
D19: Total | H19: =SUM(H9:H18) -> 108.05338 | I19: =SUM(I9:I18) -> 108.05338 | J19: t CO2e

Sheet Input - Refrigerants
A1: #VALUE! | C1: Input - Refrigerants
A3: =HYPERLINK("#'Home'!A1", "Home") -> Home
A4: =HYPERLINK("#'Overview'!A1", "Overview") -> Overview
A5: =HYPERLINK("#'Results'!A1", "Results") -> Results | D5: Refrigerants
A7: INPUTS | D7: 💡 You can add more rows to the table by right-clicking on the table and selecting "Insert > Table rows above/below"
A8: =HYPERLINK("#'Input - Refrigerants'!A1", "Refrigerants") -> Refrigerants
D9: Refrigeration unit name | E9: Appliance type (select) | F9: Refrigerant used (select) | G9: Unit refrigerant gas capacity (kg) | H9: Number of units in use
A10: CALCULATIONS | D10: Cool room | E10: Domestic refrigerators | F10: R-402A | G10: 10 | H10: 5
A11: =HYPERLINK("#'9.1.1.1-2 Refrigerant use'!A1", "9.1.1.1-2 Refrigerant use") -> 9.1.1.1-2 Refrigerant use | D11: Office air con units | E11: Domestic A/C split | F11: R-422B | G11: 10 | H11: 5
D12: Car AC | E12: Light vehicle A/C | F12: R-400 60/40 | G12: 10 | H12: 13
A13: APPENDICES | D13: Storage AC | E13: Domestic A/C split | F13: R-400 60/40 | G13: 10 | H13: 10
A14: =HYPERLINK("#'Constants - Refrigerants'!A1", "Constants - Refrigerants") -> Constants - Refrigerants | D14: Refrigerated trucks | E14: Transport refrigeration | F14: R-504 | G14: 10 | H14: 10
A15: =HYPERLINK("#'Constants - Common'!A1", "Constants - Common") -> Constants - Common

Sheet 9.1.1.1-2 Refrigerant use
A1: #VALUE! | C1: 9.1.1.1-2 Refrigerant use
A3: =HYPERLINK("#'Home'!A1", "Home") -> Home | D3: Method 1
A4: =HYPERLINK("#'Overview'!A1", "Overview") -> Overview
A5: =HYPERLINK("#'Results'!A1", "Results") -> Results | D5: {=Refrigerants_Equations.VEERG_9_1_1__1_RefrigerantLeaking_Title()} -> The total emissions of refrigerant leaking during operation (not during installation or disposal)
D6: {=Refrigerants_Equations.VEERG_9_1_1__1_RefrigerantLeaking_Source()} -> VEERG 2026: 9.1.1, Equation (1)
A7: INPUTS | D7: {=Refrigerants_Equations.VEERG_9_1_1__1_RefrigerantLeaking_Variation()} -> VARIATION ON SOURCE: Added equation to convert refrigerant R to CO2-e using the refrigerant's global warming potential (GWP).
A8: =HYPERLINK("#'Input - Refrigerants'!A1", "Refrigerants") -> Refrigerants | D8: Function name | E8: {=Common_InputFunctions.Utility_DisplayFunctionName(K22)} -> =Refrigerants_Equations.VEERG_9_1_1__1_RefrigerantLeaking
A10: CALCULATIONS
A11: =HYPERLINK("#'9.1.1.1-2 Refrigerant use'!A1", "9.1.1.1-2 Refrigerant use") -> 9.1.1.1-2 Refrigerant use | D11: Variable | E11: {=Refrigerants_Equations.VEERG_9_1_1__1_RefrigerantLeaking_Variable()} -> E_R
D12: Unit | E12: {=Refrigerants_Equations.VEERG_9_1_1__1_RefrigerantLeaking_Unit()} -> t refrigerant gas
A13: APPENDICES
A14: =HYPERLINK("#'Constants - Refrigerants'!A1", "Constants - Refrigerants") -> Constants - Refrigerants | D14: {=_xlfn.CHOOSECOLS(Refrigerants_Equations.VEERG_9_1_1__1_RefrigerantLeaking_Arguments(), 1, 2)} -> charge_Ra | E14: Amount of refrigerant R contained in appliance a | G14: {=_xlfn.CHOOSECOLS(Refrigerants_Equations.VEERG_9_1_1__1_RefrigerantLeaking_Arguments(), 3,4)} -> kg | H14: Input
A15: =HYPERLINK("#'Constants - Common'!A1", "Constants - Common") -> Constants - Common | D15: leakagerate_a | E15: Prcentage of total charge leaked from appliance a each year | G15: Percent | H15: Constant
D16: a | E16: Appliance type | H16: Input
D17: R | E17: Refrigerant | H17: Input
D19: Table_E_R_Appliance
D20: Refrigerant leakage emissions by appliance
D21: Refrigeration unit name | E21: Appliance type a | F21: Refrigerant blend R | G21: Unit refrigerant gas capacity (kg) | H21: Number of units in use | I21: Total capacity | J21: Leakage rate (percent) | K21: ERa | L21: ER
D22: {=IFERROR(INDEX(Table_Input_Refrigerant[Refrigeration unit name], _xlfn.SEQUENCE(10)),"")} -> Cool room | E22: {=IFERROR(INDEX(Table_Input_Refrigerant[Appliance type (select)], _xlfn.SEQUENCE(10)),"")} -> Domestic refrigerators | F22: {=IFERROR(INDEX(Table_Input_Refrigerant[Refrigerant used (select)], _xlfn.SEQUENCE(10)),"")} -> R-402A | G22: {=IFERROR(INDEX(Table_Input_Refrigerant[Unit refrigerant gas capacity (kg)], _xlfn.SEQUENCE(10)),0)} -> 10 | H22: {=IFERROR(INDEX(Table_Input_Refrigerant[Number of units in use], _xlfn.SEQUENCE(10)),0)} -> 5 | I22: =G22*H22 -> 50 | J22: {=Common_InputFunctions.Utility_LookupValueInTableNumber(E22,Table_Refrigerants_LeakageRates[Product],Table_Refrigerants_LeakageRates[Annual leakage rate (%)])} -> 1.7 | K22: {=Refrigerants_Equations.VEERG_9_1_1__1_RefrigerantLeaking(G22,J22)} -> 0.00017 | L22: =K22*H22 -> 0.00085
D23: Office air con units | E23: Domestic A/C split | F23: R-422B | G23: 10 | H23: 5 | I23: =G23*H23 -> 50 | J23: {=Common_InputFunctions.Utility_LookupValueInTableNumber(E23,Table_Refrigerants_LeakageRates[Product],Table_Refrigerants_LeakageRates[Annual leakage rate (%)])} -> 3.5 | K23: {=Refrigerants_Equations.VEERG_9_1_1__1_RefrigerantLeaking(G23,J23)} -> 0.00035 | L23: =K23*H23 -> 0.00175
D24: Car AC | E24: Light vehicle A/C | F24: R-400 60/40 | G24: 10 | H24: 13 | I24: =G24*H24 -> 130 | J24: {=Common_InputFunctions.Utility_LookupValueInTableNumber(E24,Table_Refrigerants_LeakageRates[Product],Table_Refrigerants_LeakageRates[Annual leakage rate (%)])} -> 6.7 | K24: {=Refrigerants_Equations.VEERG_9_1_1__1_RefrigerantLeaking(G24,J24)} -> 0.00067 | L24: =K24*H24 -> 0.00871
D25: Storage AC | E25: Domestic A/C split | F25: R-400 60/40 | G25: 10 | H25: 10 | I25: =G25*H25 -> 100 | J25: {=Common_InputFunctions.Utility_LookupValueInTableNumber(E25,Table_Refrigerants_LeakageRates[Product],Table_Refrigerants_LeakageRates[Annual leakage rate (%)])} -> 3.5 | K25: {=Refrigerants_Equations.VEERG_9_1_1__1_RefrigerantLeaking(G25,J25)} -> 0.00035 | L25: =K25*H25 -> 0.0035
D26: Refrigerated trucks | E26: Transport refrigeration | F26: R-504 | G26: 10 | H26: 10 | I26: =G26*H26 -> 100 | J26: {=Common_InputFunctions.Utility_LookupValueInTableNumber(E26,Table_Refrigerants_LeakageRates[Product],Table_Refrigerants_LeakageRates[Annual leakage rate (%)])} -> 15.7 | K26: {=Refrigerants_Equations.VEERG_9_1_1__1_RefrigerantLeaking(G26,J26)} -> 0.00157 | L26: =K26*H26 -> 0.0157
D27: 0 | E27: 0 | F27: 0 | G27: 0 | H27: 0 | I27: =G27*H27 -> 0 | J27: {=Common_InputFunctions.Utility_LookupValueInTableNumber(E27,Table_Refrigerants_LeakageRates[Product],Table_Refrigerants_LeakageRates[Annual leakage rate (%)])} -> 0 | K27: {=Refrigerants_Equations.VEERG_9_1_1__1_RefrigerantLeaking(G27,J27)} -> 0 | L27: =K27*H27 -> 0
D28: 0 | E28: 0 | F28: 0 | G28: 0 | H28: 0 | I28: =G28*H28 -> 0 | J28: {=Common_InputFunctions.Utility_LookupValueInTableNumber(E28,Table_Refrigerants_LeakageRates[Product],Table_Refrigerants_LeakageRates[Annual leakage rate (%)])} -> 0 | K28: {=Refrigerants_Equations.VEERG_9_1_1__1_RefrigerantLeaking(G28,J28)} -> 0 | L28: =K28*H28 -> 0
D29: 0 | E29: 0 | F29: 0 | G29: 0 | H29: 0 | I29: =G29*H29 -> 0 | J29: {=Common_InputFunctions.Utility_LookupValueInTableNumber(E29,Table_Refrigerants_LeakageRates[Product],Table_Refrigerants_LeakageRates[Annual leakage rate (%)])} -> 0 | K29: {=Refrigerants_Equations.VEERG_9_1_1__1_RefrigerantLeaking(G29,J29)} -> 0 | L29: =K29*H29 -> 0
D30: 0 | E30: 0 | F30: 0 | G30: 0 | H30: 0 | I30: =G30*H30 -> 0 | J30: {=Common_InputFunctions.Utility_LookupValueInTableNumber(E30,Table_Refrigerants_LeakageRates[Product],Table_Refrigerants_LeakageRates[Annual leakage rate (%)])} -> 0 | K30: {=Refrigerants_Equations.VEERG_9_1_1__1_RefrigerantLeaking(G30,J30)} -> 0 | L30: =K30*H30 -> 0
D31: 0 | E31: 0 | F31: 0 | G31: 0 | H31: 0 | I31: =G31*H31 -> 0 | J31: {=Common_InputFunctions.Utility_LookupValueInTableNumber(E31,Table_Refrigerants_LeakageRates[Product],Table_Refrigerants_LeakageRates[Annual leakage rate (%)])} -> 0 | K31: {=Refrigerants_Equations.VEERG_9_1_1__1_RefrigerantLeaking(G31,J31)} -> 0 | L31: =K31*H31 -> 0
D33: Table_E_R
D34: Refrigerant leakage emisssions
D35: Refrigerant blend R | E35: ER
D36: {=_xlfn.UNIQUE(_xlfn._xlws.FILTER(F22:F31, (F22:F31<>"") * (F22:F31<>0)))} -> R-402A | E36: =SUMIF($F$22:$F$31,D36,$L$22:$L$31) -> 0.00085
D37: R-422B | E37: =SUMIF($F$22:$F$31,D37,$L$22:$L$31) -> 0.00175
D38: R-400 60/40 | E38: =SUMIF($F$22:$F$31,D38,$L$22:$L$31) -> 0.01221
D39: R-504 | E39: =SUMIF($F$22:$F$31,D39,$L$22:$L$31) -> 0.0157
E40: =SUMIF($F$22:$F$31,D40,$L$22:$L$31) -> 0
E41: =SUMIF($F$22:$F$31,D41,$L$22:$L$31) -> 0
E42: =SUMIF($F$22:$F$31,D42,$L$22:$L$31) -> 0
E43: =SUMIF($F$22:$F$31,D43,$L$22:$L$31) -> 0
E44: =SUMIF($F$22:$F$31,D44,$L$22:$L$31) -> 0
...

Sheet Constants - Refrigerants
A1: #VALUE! | C1: Constants - Refrigerants
A3: =HYPERLINK("#'Home'!A1", "Home") -> Home
A4: =HYPERLINK("#'Overview'!A1", "Overview") -> Overview
A5: =HYPERLINK("#'Results'!A1", "Results") -> Results | D5: {=Refrigerants_SourceData.Refrigerants_ChemicalGWP_Title()} -> Global Warming Potentials
D6: {=Refrigerants_SourceData.Refrigerants_ChemicalGWP_Source()} -> Australian National Greenhouse Accounts Factors 2025 - Appendix 2 - Table 23
A7: INPUTS | D7: {="⚠️" & Refrigerants_SourceData.Refrigerants_ChemicalGWP_Variation()} -> ⚠️VARIATION OF SOURCE DATA: Added 'GAS - FC name' column with truncated gas name to allow matching with other tables. Added extra gases from IPCC Global Warming Potential Values v2.0 - (AR5). Added 'Additional data source' column.
A8: =HYPERLINK("#'Input - Refrigerants'!A1", "Refrigerants") -> Refrigerants | D8: Gas | E8: Chemical formula | F8: Global warming potential (AR5) | G8: Gas - FC name | H8: Aditional data source
D9: {=Common_InputFunctions.Utility_DisplayArrayInTable(Refrigerants_SourceData.Refrigerants_ChemicalGWP_Data(), Table_RefrigerantChemicalGWP[[#Headers],[Gas]], 0)} -> Carbon dioxide | E9: {=Common_InputFunctions.Utility_DisplayArrayInTable(Refrigerants_SourceData.Refrigerants_ChemicalGWP_Data(), Table_RefrigerantChemicalGWP[[#Headers],[Gas]], 0)} -> CO2 | F9: {=Common_InputFunctions.Utility_DisplayArrayInTable(Refrigerants_SourceData.Refrigerants_ChemicalGWP_Data(), Table_RefrigerantChemicalGWP[[#Headers],[Gas]], 0)} -> 1 | G9: {=Common_InputFunctions.Utility_DisplayArrayInTable(Refrigerants_SourceData.Refrigerants_ChemicalGWP_Data(), Table_RefrigerantChemicalGWP[[#Headers],[Gas]], 0)} -> CO2 | H9: {=Common_InputFunctions.Utility_DisplayArrayInTable(Refrigerants_SourceData.Refrigerants_ChemicalGWP_Data(), Table_RefrigerantChemicalGWP[[#Headers],[Gas]], 0)}
A10: CALCULATIONS | D10: {=Common_InputFunctions.Utility_DisplayArrayInTable(Refrigerants_SourceData.Refrigerants_ChemicalGWP_Data(), Table_RefrigerantChemicalGWP[[#Headers],[Gas]], 0)} -> Methane | E10: {=Common_InputFunctions.Utility_DisplayArrayInTable(Refrigerants_SourceData.Refrigerants_ChemicalGWP_Data(), Table_RefrigerantChemicalGWP[[#Headers],[Gas]], 0)} -> CH4 | F10: {=Common_InputFunctions.Utility_DisplayArrayInTable(Refrigerants_SourceData.Refrigerants_ChemicalGWP_Data(), Table_RefrigerantChemicalGWP[[#Headers],[Gas]], 0)} -> 28 | G10: {=Common_InputFunctions.Utility_DisplayArrayInTable(Refrigerants_SourceData.Refrigerants_ChemicalGWP_Data(), Table_RefrigerantChemicalGWP[[#Headers],[Gas]], 0)} -> CH4 | H10: {=Common_InputFunctions.Utility_DisplayArrayInTable(Refrigerants_SourceData.Refrigerants_ChemicalGWP_Data(), Table_RefrigerantChemicalGWP[[#Headers],[Gas]], 0)}
A11: =HYPERLINK("#'9.1.1.1-2 Refrigerant use'!A1", "9.1.1.1-2 Refrigerant use") -> 9.1.1.1-2 Refrigerant use | D11: {=Common_InputFunctions.Utility_DisplayArrayInTable(Refrigerants_SourceData.Refrigerants_ChemicalGWP_Data(), Table_RefrigerantChemicalGWP[[#Headers],[Gas]], 0)} -> Nitrous oxide | E11: {=Common_InputFunctions.Utility_DisplayArrayInTable(Refrigerants_SourceData.Refrigerants_ChemicalGWP_Data(), Table_RefrigerantChemicalGWP[[#Headers],[Gas]], 0)} -> N2O | F11: {=Common_InputFunctions.Utility_DisplayArrayInTable(Refrigerants_SourceData.Refrigerants_ChemicalGWP_Data(), Table_RefrigerantChemicalGWP[[#Headers],[Gas]], 0)} -> 265 | G11: {=Common_InputFunctions.Utility_DisplayArrayInTable(Refrigerants_SourceData.Refrigerants_ChemicalGWP_Data(), Table_RefrigerantChemicalGWP[[#Headers],[Gas]], 0)} -> N2O | H11: {=Common_InputFunctions.Utility_DisplayArrayInTable(Refrigerants_SourceData.Refrigerants_ChemicalGWP_Data(), Table_RefrigerantChemicalGWP[[#Headers],[Gas]], 0)}
D12: {=Common_InputFunctions.Utility_DisplayArrayInTable(Refrigerants_SourceData.Refrigerants_ChemicalGWP_Data(), Table_RefrigerantChemicalGWP[[#Headers],[Gas]], 0)} -> Sulphur hexafluoride | E12: {=Common_InputFunctions.Utility_DisplayArrayInTable(Refrigerants_SourceData.Refrigerants_ChemicalGWP_Data(), Table_RefrigerantChemicalGWP[[#Headers],[Gas]], 0)} -> SF6 | F12: {=Common_InputFunctions.Utility_DisplayArrayInTable(Refrigerants_SourceData.Refrigerants_ChemicalGWP_Data(), Table_RefrigerantChemicalGWP[[#Headers],[Gas]], 0)} -> 23500 | G12: {=Common_InputFunctions.Utility_DisplayArrayInTable(Refrigerants_SourceData.Refrigerants_ChemicalGWP_Data(), Table_RefrigerantChemicalGWP[[#Headers],[Gas]], 0)} -> SF6 | H12: {=Common_InputFunctions.Utility_DisplayArrayInTable(Refrigerants_SourceData.Refrigerants_ChemicalGWP_Data(), Table_RefrigerantChemicalGWP[[#Headers],[Gas]], 0)}
A13: APPENDICES | D13: {=Common_InputFunctions.Utility_DisplayArrayInTable(Refrigerants_SourceData.Refrigerants_ChemicalGWP_Data(), Table_RefrigerantChemicalGWP[[#Headers],[Gas]], 0)} -> HFC-23 (R-23) | E13: {=Common_InputFunctions.Utility_DisplayArrayInTable(Refrigerants_SourceData.Refrigerants_ChemicalGWP_Data(), Table_RefrigerantChemicalGWP[[#Headers],[Gas]], 0)} -> CHF3 | F13: {=Common_InputFunctions.Utility_DisplayArrayInTable(Refrigerants_SourceData.Refrigerants_ChemicalGWP_Data(), Table_RefrigerantChemicalGWP[[#Headers],[Gas]], 0)} -> 12400 | G13: {=Common_InputFunctions.Utility_DisplayArrayInTable(Refrigerants_SourceData.Refrigerants_ChemicalGWP_Data(), Table_RefrigerantChemicalGWP[[#Headers],[Gas]], 0)} -> HFC-23 | H13: {=Common_InputFunctions.Utility_DisplayArrayInTable(Refrigerants_SourceData.Refrigerants_ChemicalGWP_Data(), Table_RefrigerantChemicalGWP[[#Headers],[Gas]], 0)}
A14: =HYPERLINK("#'Constants - Refrigerants'!A1", "Constants - Refrigerants") -> Constants - Refrigerants | D14: {=Common_InputFunctions.Utility_DisplayArrayInTable(Refrigerants_SourceData.Refrigerants_ChemicalGWP_Data(), Table_RefrigerantChemicalGWP[[#Headers],[Gas]], 0)} -> HFC-32 (R-32) | E14: {=Common_InputFunctions.Utility_DisplayArrayInTable(Refrigerants_SourceData.Refrigerants_ChemicalGWP_Data(), Table_RefrigerantChemicalGWP[[#Headers],[Gas]], 0)} -> CH2F2 | F14: {=Common_InputFunctions.Utility_DisplayArrayInTable(Refrigerants_SourceData.Refrigerants_ChemicalGWP_Data(), Table_RefrigerantChemicalGWP[[#Headers],[Gas]], 0)} -> 677 | G14: {=Common_InputFunctions.Utility_DisplayArrayInTable(Refrigerants_SourceData.Refrigerants_ChemicalGWP_Data(), Table_RefrigerantChemicalGWP[[#Headers],[Gas]], 0)} -> HFC-32 | H14: {=Common_InputFunctions.Utility_DisplayArrayInTable(Refrigerants_SourceData.Refrigerants_ChemicalGWP_Data(), Table_RefrigerantChemicalGWP[[#Headers],[Gas]], 0)}
A15: =HYPERLINK("#'Constants - Common'!A1", "Constants - Common") -> Constants - Common | D15: {=Common_InputFunctions.Utility_DisplayArrayInTable(Refrigerants_SourceData.Refrigerants_ChemicalGWP_Data(), Table_RefrigerantChemicalGWP[[#Headers],[Gas]], 0)} -> HFC-41 (R-41) | E15: {=Common_InputFunctions.Utility_DisplayArrayInTable(Refrigerants_SourceData.Refrigerants_ChemicalGWP_Data(), Table_RefrigerantChemicalGWP[[#Headers],[Gas]], 0)} -> CH3F | F15: {=Common_InputFunctions.Utility_DisplayArrayInTable(Refrigerants_SourceData.Refrigerants_ChemicalGWP_Data(), Table_RefrigerantChemicalGWP[[#Headers],[Gas]], 0)} -> 116 | G15: {=Common_InputFunctions.Utility_DisplayArrayInTable(Refrigerants_SourceData.Refrigerants_ChemicalGWP_Data(), Table_RefrigerantChemicalGWP[[#Headers],[Gas]], 0)} -> HFC-41 | H15: {=Common_InputFunctions.Utility_DisplayArrayInTable(Refrigerants_SourceData.Refrigerants_ChemicalGWP_Data(), Table_RefrigerantChemicalGWP[[#Headers],[Gas]], 0)}
D16: {=Common_InputFunctions.Utility_DisplayArrayInTable(Refrigerants_SourceData.Refrigerants_ChemicalGWP_Data(), Table_RefrigerantChemicalGWP[[#Headers],[Gas]], 0)} -> HFC-43-10mee (R-4310mee) | E16: {=Common_InputFunctions.Utility_DisplayArrayInTable(Refrigerants_SourceData.Refrigerants_ChemicalGWP_Data(), Table_RefrigerantChemicalGWP[[#Headers],[Gas]], 0)} -> C5H2F10 | F16: {=Common_InputFunctions.Utility_DisplayArrayInTable(Refrigerants_SourceData.Refrigerants_ChemicalGWP_Data(), Table_RefrigerantChemicalGWP[[#Headers],[Gas]], 0)} -> 1650 | G16: {=Common_InputFunctions.Utility_DisplayArrayInTable(Refrigerants_SourceData.Refrigerants_ChemicalGWP_Data(), Table_RefrigerantChemicalGWP[[#Headers],[Gas]], 0)} -> HFC-43-10mee | H16: {=Common_InputFunctions.Utility_DisplayArrayInTable(Refrigerants_SourceData.Refrigerants_ChemicalGWP_Data(), Table_RefrigerantChemicalGWP[[#Headers],[Gas]], 0)}
D17: {=Common_InputFunctions.Utility_DisplayArrayInTable(Refrigerants_SourceData.Refrigerants_ChemicalGWP_Data(), Table_RefrigerantChemicalGWP[[#Headers],[Gas]], 0)} -> HFC-125 (R-125) | E17: {=Common_InputFunctions.Utility_DisplayArrayInTable(Refrigerants_SourceData.Refrigerants_ChemicalGWP_Data(), Table_RefrigerantChemicalGWP[[#Headers],[Gas]], 0)} -> C2HF5 | F17: {=Common_InputFunctions.Utility_DisplayArrayInTable(Refrigerants_SourceData.Refrigerants_ChemicalGWP_Data(), Table_RefrigerantChemicalGWP[[#Headers],[Gas]], 0)} -> 3170 | G17: {=Common_InputFunctions.Utility_DisplayArrayInTable(Refrigerants_SourceData.Refrigerants_ChemicalGWP_Data(), Table_RefrigerantChemicalGWP[[#Headers],[Gas]], 0)} -> HFC-125 | H17: {=Common_InputFunctions.Utility_DisplayArrayInTable(Refrigerants_SourceData.Refrigerants_ChemicalGWP_Data(), Table_RefrigerantChemicalGWP[[#Headers],[Gas]], 0)}
D18: {=Common_InputFunctions.Utility_DisplayArrayInTable(Refrigerants_SourceData.Refrigerants_ChemicalGWP_Data(), Table_RefrigerantChemicalGWP[[#Headers],[Gas]], 0)} -> HFC-134 (R-134) | E18: {=Common_InputFunctions.Utility_DisplayArrayInTable(Refrigerants_SourceData.Refrigerants_ChemicalGWP_Data(), Table_RefrigerantChemicalGWP[[#Headers],[Gas]], 0)} -> C2H2F4 (CHF2CHF2) | F18: {=Common_InputFunctions.Utility_DisplayArrayInTable(Refrigerants_SourceData.Refrigerants_ChemicalGWP_Data(), Table_RefrigerantChemicalGWP[[#Headers],[Gas]], 0)} -> 1120 | G18: {=Common_InputFunctions.Utility_DisplayArrayInTable(Refrigerants_SourceData.Refrigerants_ChemicalGWP_Data(), Table_RefrigerantChemicalGWP[[#Headers],[Gas]], 0)} -> HFC-134 | H18: {=Common_InputFunctions.Utility_DisplayArrayInTable(Refrigerants_SourceData.Refrigerants_ChemicalGWP_Data(), Table_RefrigerantChemicalGWP[[#Headers],[Gas]], 0)}
D19: {=Common_InputFunctions.Utility_DisplayArrayInTable(Refrigerants_SourceData.Refrigerants_ChemicalGWP_Data(), Table_RefrigerantChemicalGWP[[#Headers],[Gas]], 0)} -> HFC-134a (R-134a) | E19: {=Common_InputFunctions.Utility_DisplayArrayInTable(Refrigerants_SourceData.Refrigerants_ChemicalGWP_Data(), Table_RefrigerantChemicalGWP[[#Headers],[Gas]], 0)} -> C2H2F4 (CH2FCF3) | F19: {=Common_InputFunctions.Utility_DisplayArrayInTable(Refrigerants_SourceData.Refrigerants_ChemicalGWP_Data(), Table_RefrigerantChemicalGWP[[#Headers],[Gas]], 0)} -> 1300 | G19: {=Common_InputFunctions.Utility_DisplayArrayInTable(Refrigerants_SourceData.Refrigerants_ChemicalGWP_Data(), Table_RefrigerantChemicalGWP[[#Headers],[Gas]], 0)} -> HFC-134a | H19: {=Common_InputFunctions.Utility_DisplayArrayInTable(Refrigerants_SourceData.Refrigerants_ChemicalGWP_Data(), Table_RefrigerantChemicalGWP[[#Headers],[Gas]], 0)}
D20: {=Common_InputFunctions.Utility_DisplayArrayInTable(Refrigerants_SourceData.Refrigerants_ChemicalGWP_Data(), Table_RefrigerantChemicalGWP[[#Headers],[Gas]], 0)} -> HFC-143 (R-143) | E20: {=Common_InputFunctions.Utility_DisplayArrayInTable(Refrigerants_SourceData.Refrigerants_ChemicalGWP_Data(), Table_RefrigerantChemicalGWP[[#Headers],[Gas]], 0)} -> C2H3F3 (CHF2CH2F) | F20: {=Common_InputFunctions.Utility_DisplayArrayInTable(Refrigerants_SourceData.Refrigerants_ChemicalGWP_Data(), Table_RefrigerantChemicalGWP[[#Headers],[Gas]], 0)} -> 328 | G20: {=Common_InputFunctions.Utility_DisplayArrayInTable(Refrigerants_SourceData.Refrigerants_ChemicalGWP_Data(), Table_RefrigerantChemicalGWP[[#Headers],[Gas]], 0)} -> HFC-143 | H20: {=Common_InputFunctions.Utility_DisplayArrayInTable(Refrigerants_SourceData.Refrigerants_ChemicalGWP_Data(), Table_RefrigerantChemicalGWP[[#Headers],[Gas]], 0)}
D21: {=Common_InputFunctions.Utility_DisplayArrayInTable(Refrigerants_SourceData.Refrigerants_ChemicalGWP_Data(), Table_RefrigerantChemicalGWP[[#Headers],[Gas]], 0)} -> HFC-143a (R-143a) | E21: {=Common_InputFunctions.Utility_DisplayArrayInTable(Refrigerants_SourceData.Refrigerants_ChemicalGWP_Data(), Table_RefrigerantChemicalGWP[[#Headers],[Gas]], 0)} -> C2H3F3 (CF3CH3) | F21: {=Common_InputFunctions.Utility_DisplayArrayInTable(Refrigerants_SourceData.Refrigerants_ChemicalGWP_Data(), Table_RefrigerantChemicalGWP[[#Headers],[Gas]], 0)} -> 4800 | G21: {=Common_InputFunctions.Utility_DisplayArrayInTable(Refrigerants_SourceData.Refrigerants_ChemicalGWP_Data(), Table_RefrigerantChemicalGWP[[#Headers],[Gas]], 0)} -> HFC-143a | H21: {=Common_InputFunctions.Utility_DisplayArrayInTable(Refrigerants_SourceData.Refrigerants_ChemicalGWP_Data(), Table_RefrigerantChemicalGWP[[#Headers],[Gas]], 0)}
D22: {=Common_InputFunctions.Utility_DisplayArrayInTable(Refrigerants_SourceData.Refrigerants_ChemicalGWP_Data(), Table_RefrigerantChemicalGWP[[#Headers],[Gas]], 0)} -> HFC-152a (R-152a) | E22: {=Common_InputFunctions.Utility_DisplayArrayInTable(Refrigerants_SourceData.Refrigerants_ChemicalGWP_Data(), Table_RefrigerantChemicalGWP[[#Headers],[Gas]], 0)} -> C2H4F2 (CH3CHF2) | F22: {=Common_InputFunctions.Utility_DisplayArrayInTable(Refrigerants_SourceData.Refrigerants_ChemicalGWP_Data(), Table_RefrigerantChemicalGWP[[#Headers],[Gas]], 0)} -> 138 | G22: {=Common_InputFunctions.Utility_DisplayArrayInTable(Refrigerants_SourceData.Refrigerants_ChemicalGWP_Data(), Table_RefrigerantChemicalGWP[[#Headers],[Gas]], 0)} -> HFC-152a | H22: {=Common_InputFunctions.Utility_DisplayArrayInTable(Refrigerants_SourceData.Refrigerants_ChemicalGWP_Data(), Table_RefrigerantChemicalGWP[[#Headers],[Gas]], 0)}
D23: {=Common_InputFunctions.Utility_DisplayArrayInTable(Refrigerants_SourceData.Refrigerants_ChemicalGWP_Data(), Table_RefrigerantChemicalGWP[[#Headers],[Gas]], 0)} -> HFC-227ea (R-227ea) | E23: {=Common_InputFunctions.Utility_DisplayArrayInTable(Refrigerants_SourceData.Refrigerants_ChemicalGWP_Data(), Table_RefrigerantChemicalGWP[[#Headers],[Gas]], 0)} -> C3HF7 | F23: {=Common_InputFunctions.Utility_DisplayArrayInTable(Refrigerants_SourceData.Refrigerants_ChemicalGWP_Data(), Table_RefrigerantChemicalGWP[[#Headers],[Gas]], 0)} -> 3350 | G23: {=Common_InputFunctions.Utility_DisplayArrayInTable(Refrigerants_SourceData.Refrigerants_ChemicalGWP_Data(), Table_RefrigerantChemicalGWP[[#Headers],[Gas]], 0)} -> HFC-227ea | H23: {=Common_InputFunctions.Utility_DisplayArrayInTable(Refrigerants_SourceData.Refrigerants_ChemicalGWP_Data(), Table_RefrigerantChemicalGWP[[#Headers],[Gas]], 0)}
D24: {=Common_InputFunctions.Utility_DisplayArrayInTable(Refrigerants_SourceData.Refrigerants_ChemicalGWP_Data(), Table_RefrigerantChemicalGWP[[#Headers],[Gas]], 0)} -> HFC-236fa (R-236fa) | E24: {=Common_InputFunctions.Utility_DisplayArrayInTable(Refrigerants_SourceData.Refrigerants_ChemicalGWP_Data(), Table_RefrigerantChemicalGWP[[#Headers],[Gas]], 0)} -> C3H2F6 | F24: {=Common_InputFunctions.Utility_DisplayArrayInTable(Refrigerants_SourceData.Refrigerants_ChemicalGWP_Data(), Table_RefrigerantChemicalGWP[[#Headers],[Gas]], 0)} -> 8060 | G24: {=Common_InputFunctions.Utility_DisplayArrayInTable(Refrigerants_SourceData.Refrigerants_ChemicalGWP_Data(), Table_RefrigerantChemicalGWP[[#Headers],[Gas]], 0)} -> HFC-236fa | H24: {=Common_InputFunctions.Utility_DisplayArrayInTable(Refrigerants_SourceData.Refrigerants_ChemicalGWP_Data(), Table_RefrigerantChemicalGWP[[#Headers],[Gas]], 0)}
D25: {=Common_InputFunctions.Utility_DisplayArrayInTable(Refrigerants_SourceData.Refrigerants_ChemicalGWP_Data(), Table_RefrigerantChemicalGWP[[#Headers],[Gas]], 0)} -> HFC-245ca (R-245ca) | E25: {=Common_InputFunctions.Utility_DisplayArrayInTable(Refrigerants_SourceData.Refrigerants_ChemicalGWP_Data(), Table_RefrigerantChemicalGWP[[#Headers],[Gas]], 0)} -> C3H3F5 | F25: {=Common_InputFunctions.Utility_DisplayArrayInTable(Refrigerants_SourceData.Refrigerants_ChemicalGWP_Data(), Table_RefrigerantChemicalGWP[[#Headers],[Gas]], 0)} -> 716 | G25: {=Common_InputFunctions.Utility_DisplayArrayInTable(Refrigerants_SourceData.Refrigerants_ChemicalGWP_Data(), Table_RefrigerantChemicalGWP[[#Headers],[Gas]], 0)} -> HFC-245ca | H25: {=Common_InputFunctions.Utility_DisplayArrayInTable(Refrigerants_SourceData.Refrigerants_ChemicalGWP_Data(), Table_RefrigerantChemicalGWP[[#Headers],[Gas]], 0)}
D26: {=Common_InputFunctions.Utility_DisplayArrayInTable(Refrigerants_SourceData.Refrigerants_ChemicalGWP_Data(), Table_RefrigerantChemicalGWP[[#Headers],[Gas]], 0)} -> HFC-245fa (R-245fa) | E26: {=Common_InputFunctions.Utility_DisplayArrayInTable(Refrigerants_SourceData.Refrigerants_ChemicalGWP_Data(), Table_RefrigerantChemicalGWP[[#Headers],[Gas]], 0)} -> CHF2CH2CF3 | F26: {=Common_InputFunctions.Utility_DisplayArrayInTable(Refrigerants_SourceData.Refrigerants_ChemicalGWP_Data(), Table_RefrigerantChemicalGWP[[#Headers],[Gas]], 0)} -> 858 | G26: {=Common_InputFunctions.Utility_DisplayArrayInTable(Refrigerants_SourceData.Refrigerants_ChemicalGWP_Data(), Table_RefrigerantChemicalGWP[[#Headers],[Gas]], 0)} -> HFC-245fa | H26: {=Common_InputFunctions.Utility_DisplayArrayInTable(Refrigerants_SourceData.Refrigerants_ChemicalGWP_Data(), Table_RefrigerantChemicalGWP[[#Headers],[Gas]], 0)}
D27: {=Common_InputFunctions.Utility_DisplayArrayInTable(Refrigerants_SourceData.Refrigerants_ChemicalGWP_Data(), Table_RefrigerantChemicalGWP[[#Headers],[Gas]], 0)} -> HFC-365mfc (R-365mfc) | E27: {=Common_InputFunctions.Utility_DisplayArrayInTable(Refrigerants_SourceData.Refrigerants_ChemicalGWP_Data(), Table_RefrigerantChemicalGWP[[#Headers],[Gas]], 0)} -> CH3CF2CH2CF3 | F27: {=Common_InputFunctions.Utility_DisplayArrayInTable(Refrigerants_SourceData.Refrigerants_ChemicalGWP_Data(), Table_RefrigerantChemicalGWP[[#Headers],[Gas]], 0)} -> 804 | G27: {=Common_InputFunctions.Utility_DisplayArrayInTable(Refrigerants_SourceData.Refrigerants_ChemicalGWP_Data(), Table_RefrigerantChemicalGWP[[#Headers],[Gas]], 0)} -> HFC-365mfc | H27: {=Common_InputFunctions.Utility_DisplayArrayInTable(Refrigerants_SourceData.Refrigerants_ChemicalGWP_Data(), Table_RefrigerantChemicalGWP[[#Headers],[Gas]], 0)}
... D46: {=Common_InputFunctions.Utility_DisplayArrayInTable(Refrigerants_SourceData.Refrigerants_ChemicalGWP_Data(), Table_RefrigerantChemicalGWP[[#Headers],[Gas]], 0)} -> CFC-115 | E46: {=Common_InputFunctions.Utility_DisplayArrayInTable(Refrigerants_SourceData.Refrigerants_ChemicalGWP_Data(), Table_RefrigerantChemicalGWP[[#Headers],[Gas]], 0)} -> CClF2CF3 | F46: {=Common_InputFunctions.Utility_DisplayArrayInTable(Refrigerants_SourceData.Refrigerants_ChemicalGWP_Data(), Table_RefrigerantChemicalGWP[[#Headers],[Gas]], 0)} -> 7670 | G46: {=Common_InputFunctions.Utility_DisplayArrayInTable(Refrigerants_SourceData.Refrigerants_ChemicalGWP_Data(), Table_RefrigerantChemicalGWP[[#Headers],[Gas]], 0)} -> CFC-115 | H46: {=Common_InputFunctions.Utility_DisplayArrayInTable(Refrigerants_SourceData.Refrigerants_ChemicalGWP_Data(), Table_RefrigerantChemicalGWP[[#Headers],[Gas]], 0)} -> IPCC Global Warming Potential Values v2.0 - (AR5)
D49: {=Refrigerants_SourceData.Refrigerants_ChemicalBlends_Title()} -> Blended refrigerants (many containing HFCS and/or PFCS)
D50: {=Refrigerants_SourceData.Refrigerants_ChemicalBlends_Source()} -> Australian National Greenhouse Accounts Factors 2025 - Appendix 2 - Table 24
D51: {="⚠️" & Refrigerants_SourceData.Refrigerants_ChemicalBlends_Variation()} -> ⚠️VARIATION OF SOURCE DATA: Fixed typo - changed HC600a to HC-600a for blend R-414B. Fixed typo for blend R-405A - Changed HCFC142b to HCFC-142b.
D52: Blend | E52: Constituents | F52: Composition (%)
D53: {=Common_InputFunctions.Utility_DisplayArrayInTable(Refrigerants_SourceData.Refrigerants_ChemicalBlends_Data(), Table_RefrigerantBlends[[#Headers],[Blend]], 0)} -> R-400 | E53: {=Common_InputFunctions.Utility_DisplayArrayInTable(Refrigerants_SourceData.Refrigerants_ChemicalBlends_Data(), Table_RefrigerantBlends[[#Headers],[Blend]], 0)} -> CFC-12/CFC-114 | F53: {=Common_InputFunctions.Utility_DisplayArrayInTable(Refrigerants_SourceData.Refrigerants_ChemicalBlends_Data(), Table_RefrigerantBlends[[#Headers],[Blend]], 0)} -> R-400 can have various proportions of CFC-12 and CFC-114. The exact composition needs to be specified, e.g., R-400 (60/40).
D54: {=Common_InputFunctions.Utility_DisplayArrayInTable(Refrigerants_SourceData.Refrigerants_ChemicalBlends_Data(), Table_RefrigerantBlends[[#Headers],[Blend]], 0)} -> R-401A | E54: {=Common_InputFunctions.Utility_DisplayArrayInTable(Refrigerants_SourceData.Refrigerants_ChemicalBlends_Data(), Table_RefrigerantBlends[[#Headers],[Blend]], 0)} -> HCFC-22/HFC-152a/HCFC-124 | F54: {=Common_InputFunctions.Utility_DisplayArrayInTable(Refrigerants_SourceData.Refrigerants_ChemicalBlends_Data(), Table_RefrigerantBlends[[#Headers],[Blend]], 0)} -> (53.0/13.0/34.0)
D55: {=Common_InputFunctions.Utility_DisplayArrayInTable(Refrigerants_SourceData.Refrigerants_ChemicalBlends_Data(), Table_RefrigerantBlends[[#Headers],[Blend]], 0)} -> R-401B | E55: {=Common_InputFunctions.Utility_DisplayArrayInTable(Refrigerants_SourceData.Refrigerants_ChemicalBlends_Data(), Table_RefrigerantBlends[[#Headers],[Blend]], 0)} -> HCFC-22/HFC-152a/HCFC-124 | F55: {=Common_InputFunctions.Utility_DisplayArrayInTable(Refrigerants_SourceData.Refrigerants_ChemicalBlends_Data(), Table_RefrigerantBlends[[#Headers],[Blend]], 0)} -> (61.0/11.0/28.0)
D56: {=Common_InputFunctions.Utility_DisplayArrayInTable(Refrigerants_SourceData.Refrigerants_ChemicalBlends_Data(), Table_RefrigerantBlends[[#Headers],[Blend]], 0)} -> R-401C | E56: {=Common_InputFunctions.Utility_DisplayArrayInTable(Refrigerants_SourceData.Refrigerants_ChemicalBlends_Data(), Table_RefrigerantBlends[[#Headers],[Blend]], 0)} -> HCFC-22/HFC-152a/HCFC-124 | F56: {=Common_InputFunctions.Utility_DisplayArrayInTable(Refrigerants_SourceData.Refrigerants_ChemicalBlends_Data(), Table_RefrigerantBlends[[#Headers],[Blend]], 0)} -> (33.0/15.0/52.0)
D57: {=Common_InputFunctions.Utility_DisplayArrayInTable(Refrigerants_SourceData.Refrigerants_ChemicalBlends_Data(), Table_RefrigerantBlends[[#Headers],[Blend]], 0)} -> R-402A | E57: {=Common_InputFunctions.Utility_DisplayArrayInTable(Refrigerants_SourceData.Refrigerants_ChemicalBlends_Data(), Table_RefrigerantBlends[[#Headers],[Blend]], 0)} -> HFC-125/HC-290/HCFC-22 | F57: {=Common_InputFunctions.Utility_DisplayArrayInTable(Refrigerants_SourceData.Refrigerants_ChemicalBlends_Data(), Table_RefrigerantBlends[[#Headers],[Blend]], 0)} -> (60.0/2.0/38.0)
D58: {=Common_InputFunctions.Utility_DisplayArrayInTable(Refrigerants_SourceData.Refrigerants_ChemicalBlends_Data(), Table_RefrigerantBlends[[#Headers],[Blend]], 0)} -> R-402B | E58: {=Common_InputFunctions.Utility_DisplayArrayInTable(Refrigerants_SourceData.Refrigerants_ChemicalBlends_Data(), Table_RefrigerantBlends[[#Headers],[Blend]], 0)} -> HFC-125/HC-290/HCFC-22 | F58: {=Common_InputFunctions.Utility_DisplayArrayInTable(Refrigerants_SourceData.Refrigerants_ChemicalBlends_Data(), Table_RefrigerantBlends[[#Headers],[Blend]], 0)} -> (38.0/2.0/60.0)
D59: {=Common_InputFunctions.Utility_DisplayArrayInTable(Refrigerants_SourceData.Refrigerants_ChemicalBlends_Data(), Table_RefrigerantBlends[[#Headers],[Blend]], 0)} -> R-403A | E59: {=Common_InputFunctions.Utility_DisplayArrayInTable(Refrigerants_SourceData.Refrigerants_ChemicalBlends_Data(), Table_RefrigerantBlends[[#Headers],[Blend]], 0)} -> HC-290/HCFC-22/PFC-218 | F59: {=Common_InputFunctions.Utility_DisplayArrayInTable(Refrigerants_SourceData.Refrigerants_ChemicalBlends_Data(), Table_RefrigerantBlends[[#Headers],[Blend]], 0)} -> (5.0/75.0/20.0)
D60: {=Common_InputFunctions.Utility_DisplayArrayInTable(Refrigerants_SourceData.Refrigerants_ChemicalBlends_Data(), Table_RefrigerantBlends[[#Headers],[Blend]], 0)} -> R-403B | E60: {=Common_InputFunctions.Utility_DisplayArrayInTable(Refrigerants_SourceData.Refrigerants_ChemicalBlends_Data(), Table_RefrigerantBlends[[#Headers],[Blend]], 0)} -> HC-290/HCFC-22/PFC-218 | F60: {=Common_InputFunctions.Utility_DisplayArrayInTable(Refrigerants_SourceData.Refrigerants_ChemicalBlends_Data(), Table_RefrigerantBlends[[#Headers],[Blend]], 0)} -> (5.0/56.0/39.0)
D61: {=Common_InputFunctions.Utility_DisplayArrayInTable(Refrigerants_SourceData.Refrigerants_ChemicalBlends_Data(), Table_RefrigerantBlends[[#Headers],[Blend]], 0)} -> R-404A | E61: {=Common_InputFunctions.Utility_DisplayArrayInTable(Refrigerants_SourceData.Refrigerants_ChemicalBlends_Data(), Table_RefrigerantBlends[[#Headers],[Blend]], 0)} -> HFC-125/HFC-143a/HFC-134a | F61: {=Common_InputFunctions.Utility_DisplayArrayInTable(Refrigerants_SourceData.Refrigerants_ChemicalBlends_Data(), Table_RefrigerantBlends[[#Headers],[Blend]], 0)} -> (44.0/52.0/4.0)
...

Sheet Constants - Common
A1: #VALUE! | C1: Constants - Common
D5: {=Common_SourceData.Common_SourceData_AustralianStatesTerritories_Title()} -> Australian states and territories
D6: State/Territory | E6: Common Name | F6: Abbreviation
D7: {=Common_InputFunctions.Utility_DisplayArrayInTable(Common_SourceData.Common_SourceData_AustralianStatesTerritories_Data(),Table_AustralianStates[[#Headers],[State/Territory]],0)} -> New South Wales | E7: {=Common_InputFunctions.Utility_DisplayArrayInTable(Common_SourceData.Common_SourceData_AustralianStatesTerritories_Data(),Table_AustralianStates[[#Headers],[State/Territory]],0)} -> New South Wales | F7: {=Common_InputFunctions.Utility_DisplayArrayInTable(Common_SourceData.Common_SourceData_AustralianStatesTerritories_Data(),Table_AustralianStates[[#Headers],[State/Territory]],0)} -> NSW
D8: {=Common_InputFunctions.Utility_DisplayArrayInTable(Common_SourceData.Common_SourceData_AustralianStatesTerritories_Data(),Table_AustralianStates[[#Headers],[State/Territory]],0)} -> Australian Capital Territory | E8: {=Common_InputFunctions.Utility_DisplayArrayInTable(Common_SourceData.Common_SourceData_AustralianStatesTerritories_Data(),Table_AustralianStates[[#Headers],[State/Territory]],0)} -> ACT | F8: {=Common_InputFunctions.Utility_DisplayArrayInTable(Common_SourceData.Common_SourceData_AustralianStatesTerritories_Data(),Table_AustralianStates[[#Headers],[State/Territory]],0)} -> ACT
D9: {=Common_InputFunctions.Utility_DisplayArrayInTable(Common_SourceData.Common_SourceData_AustralianStatesTerritories_Data(),Table_AustralianStates[[#Headers],[State/Territory]],0)} -> Victoria | E9: {=Common_InputFunctions.Utility_DisplayArrayInTable(Common_SourceData.Common_SourceData_AustralianStatesTerritories_Data(),Table_AustralianStates[[#Headers],[State/Territory]],0)} -> Victoria | F9: {=Common_InputFunctions.Utility_DisplayArrayInTable(Common_SourceData.Common_SourceData_AustralianStatesTerritories_Data(),Table_AustralianStates[[#Headers],[State/Territory]],0)} -> VIC
D10: {=Common_InputFunctions.Utility_DisplayArrayInTable(Common_SourceData.Common_SourceData_AustralianStatesTerritories_Data(),Table_AustralianStates[[#Headers],[State/Territory]],0)} -> Queensland | E10: {=Common_InputFunctions.Utility_DisplayArrayInTable(Common_SourceData.Common_SourceData_AustralianStatesTerritories_Data(),Table_AustralianStates[[#Headers],[State/Territory]],0)} -> Queensland | F10: {=Common_InputFunctions.Utility_DisplayArrayInTable(Common_SourceData.Common_SourceData_AustralianStatesTerritories_Data(),Table_AustralianStates[[#Headers],[State/Territory]],0)} -> QLD
D11: {=Common_InputFunctions.Utility_DisplayArrayInTable(Common_SourceData.Common_SourceData_AustralianStatesTerritories_Data(),Table_AustralianStates[[#Headers],[State/Territory]],0)} -> South Australia | E11: {=Common_InputFunctions.Utility_DisplayArrayInTable(Common_SourceData.Common_SourceData_AustralianStatesTerritories_Data(),Table_AustralianStates[[#Headers],[State/Territory]],0)} -> South Australia | F11: {=Common_InputFunctions.Utility_DisplayArrayInTable(Common_SourceData.Common_SourceData_AustralianStatesTerritories_Data(),Table_AustralianStates[[#Headers],[State/Territory]],0)} -> SA
D12: {=Common_InputFunctions.Utility_DisplayArrayInTable(Common_SourceData.Common_SourceData_AustralianStatesTerritories_Data(),Table_AustralianStates[[#Headers],[State/Territory]],0)} -> Western Australia | E12: {=Common_InputFunctions.Utility_DisplayArrayInTable(Common_SourceData.Common_SourceData_AustralianStatesTerritories_Data(),Table_AustralianStates[[#Headers],[State/Territory]],0)} -> Western Australia | F12: {=Common_InputFunctions.Utility_DisplayArrayInTable(Common_SourceData.Common_SourceData_AustralianStatesTerritories_Data(),Table_AustralianStates[[#Headers],[State/Territory]],0)} -> WA
D13: {=Common_InputFunctions.Utility_DisplayArrayInTable(Common_SourceData.Common_SourceData_AustralianStatesTerritories_Data(),Table_AustralianStates[[#Headers],[State/Territory]],0)} -> Tasmania | E13: {=Common_InputFunctions.Utility_DisplayArrayInTable(Common_SourceData.Common_SourceData_AustralianStatesTerritories_Data(),Table_AustralianStates[[#Headers],[State/Territory]],0)} -> Tasmania | F13: {=Common_InputFunctions.Utility_DisplayArrayInTable(Common_SourceData.Common_SourceData_AustralianStatesTerritories_Data(),Table_AustralianStates[[#Headers],[State/Territory]],0)} -> TAS
D14: {=Common_InputFunctions.Utility_DisplayArrayInTable(Common_SourceData.Common_SourceData_AustralianStatesTerritories_Data(),Table_AustralianStates[[#Headers],[State/Territory]],0)} -> Northern Territory | E14: {=Common_InputFunctions.Utility_DisplayArrayInTable(Common_SourceData.Common_SourceData_AustralianStatesTerritories_Data(),Table_AustralianStates[[#Headers],[State/Territory]],0)} -> Northern Territory | F14: {=Common_InputFunctions.Utility_DisplayArrayInTable(Common_SourceData.Common_SourceData_AustralianStatesTerritories_Data(),Table_AustralianStates[[#Headers],[State/Territory]],0)} -> NT
D18: {=Common_SourceData.Common_SourceData_WASA4Areas_Title()} -> ABS Statistcal Areas Level 4 - Western Australia
D19: {=Common_SourceData.Common_SourceData_WASA4Areas_Source()} -> Australian Bureau of Statistics (ABS) - Statistical Areas Level 2 - 2021 - Shapefile
D20: SA 4 Name
D21: {=Common_InputFunctions.Utility_DisplayArrayInTable(Common_SourceData.Common_SourceData_WASA4Areas_Data(), Table_WASA4Areas[[#Headers],[SA 4 Name]], 0)} -> Bunbury
D22: {=Common_InputFunctions.Utility_DisplayArrayInTable(Common_SourceData.Common_SourceData_WASA4Areas_Data(), Table_WASA4Areas[[#Headers],[SA 4 Name]], 0)} -> Mandurah
D23: {=Common_InputFunctions.Utility_DisplayArrayInTable(Common_SourceData.Common_SourceData_WASA4Areas_Data(), Table_WASA4Areas[[#Headers],[SA 4 Name]], 0)} -> Perth - Inner
D24: {=Common_InputFunctions.Utility_DisplayArrayInTable(Common_SourceData.Common_SourceData_WASA4Areas_Data(), Table_WASA4Areas[[#Headers],[SA 4 Name]], 0)} -> Perth - North East
D25: {=Common_InputFunctions.Utility_DisplayArrayInTable(Common_SourceData.Common_SourceData_WASA4Areas_Data(), Table_WASA4Areas[[#Headers],[SA 4 Name]], 0)} -> Perth - North West
D26: {=Common_InputFunctions.Utility_DisplayArrayInTable(Common_SourceData.Common_SourceData_WASA4Areas_Data(), Table_WASA4Areas[[#Headers],[SA 4 Name]], 0)} -> Perth - South East
D27: {=Common_InputFunctions.Utility_DisplayArrayInTable(Common_SourceData.Common_SourceData_WASA4Areas_Data(), Table_WASA4Areas[[#Headers],[SA 4 Name]], 0)} -> Perth - South West
D28: {=Common_InputFunctions.Utility_DisplayArrayInTable(Common_SourceData.Common_SourceData_WASA4Areas_Data(), Table_WASA4Areas[[#Headers],[SA 4 Name]], 0)} -> Western Australia - Wheat Belt
D29: {=Common_InputFunctions.Utility_DisplayArrayInTable(Common_SourceData.Common_SourceData_WASA4Areas_Data(), Table_WASA4Areas[[#Headers],[SA 4 Name]], 0)} -> Western Australia - Outback (North)
D30: {=Common_InputFunctions.Utility_DisplayArrayInTable(Common_SourceData.Common_SourceData_WASA4Areas_Data(), Table_WASA4Areas[[#Headers],[SA 4 Name]], 0)} -> Western Australia - Outback (South)
D34: {=Common_SourceData.Common_SourceData_GWP_Title()} -> Global warming potential for greenhouse gases
D35: {=Common_SourceData.Common_SourceData_GWP_Source()} -> XXXXXXX
D36: Gas | E36: CO2-e factor
D37: {=Common_InputFunctions.Utility_DisplayArrayInTable(Common_SourceData.Common_SourceData_GWP_Data(), Table_GWPData[[#Headers],[Gas]], 0)} -> CO2 | E37: {=Common_InputFunctions.Utility_DisplayArrayInTable(Common_SourceData.Common_SourceData_GWP_Data(), Table_GWPData[[#Headers],[Gas]], 0)} -> 1
D38: {=Common_InputFunctions.Utility_DisplayArrayInTable(Common_SourceData.Common_SourceData_GWP_Data(), Table_GWPData[[#Headers],[Gas]], 0)} -> CH4 | E38: {=Common_InputFunctions.Utility_DisplayArrayInTable(Common_SourceData.Common_SourceData_GWP_Data(), Table_GWPData[[#Headers],[Gas]], 0)} -> 28
D39: {=Common_InputFunctions.Utility_DisplayArrayInTable(Common_SourceData.Common_SourceData_GWP_Data(), Table_GWPData[[#Headers],[Gas]], 0)} -> N2O | E39: {=Common_InputFunctions.Utility_DisplayArrayInTable(Common_SourceData.Common_SourceData_GWP_Data(), Table_GWPData[[#Headers],[Gas]], 0)} -> 265
D40: {=Common_InputFunctions.Utility_DisplayArrayInTable(Common_SourceData.Common_SourceData_GWP_Data(), Table_GWPData[[#Headers],[Gas]], 0)} -> CF4 | E40: {=Common_InputFunctions.Utility_DisplayArrayInTable(Common_SourceData.Common_SourceData_GWP_Data(), Table_GWPData[[#Headers],[Gas]], 0)} -> 6630
D41: {=Common_InputFunctions.Utility_DisplayArrayInTable(Common_SourceData.Common_SourceData_GWP_Data(), Table_GWPData[[#Headers],[Gas]], 0)} -> C2F6 | E41: {=Common_InputFunctions.Utility_DisplayArrayInTable(Common_SourceData.Common_SourceData_GWP_Data(), Table_GWPData[[#Headers],[Gas]], 0)} -> 12200
D42: {=Common_InputFunctions.Utility_DisplayArrayInTable(Common_SourceData.Common_SourceData_GWP_Data(), Table_GWPData[[#Headers],[Gas]], 0)} -> SF6 | E42: {=Common_InputFunctions.Utility_DisplayArrayInTable(Common_SourceData.Common_SourceData_GWP_Data(), Table_GWPData[[#Headers],[Gas]], 0)} -> 22800
D43: {=Common_InputFunctions.Utility_DisplayArrayInTable(Common_SourceData.Common_SourceData_GWP_Data(), Table_GWPData[[#Headers],[Gas]], 0)} -> NF3 | E43: {=Common_InputFunctions.Utility_DisplayArrayInTable(Common_SourceData.Common_SourceData_GWP_Data(), Table_GWPData[[#Headers],[Gas]], 0)} -> 17200
D45: {=Common_SourceData.Common_SourceData_ConvertGasElementalToMolecular_Title()} -> Factor to convert elemental mass of gas to molecular mass
D46: {=Common_SourceData.Common_SourceData_ConvertGasElementalToMolecular_Source()} -> XXXXXXX
D47: Gas | E47: Conversion factor | F47: Conversion factor 1 | G47: Conversion factor 2 | H47: Conversion factor combined
D48: {=Common_InputFunctions.Utility_DisplayArrayInTable(Common_SourceData.Common_SourceData_ConvertGasElementalToMolecular_Data(),Table_GasToMolecularConversionFactor[[#Headers],[Gas]], 0)} -> CO2 | E48: {=Common_InputFunctions.Utility_DisplayArrayInTable(Common_SourceData.Common_SourceData_ConvertGasElementalToMolecular_Data(),Table_GasToMolecularConversionFactor[[#Headers],[Gas]], 0)} -> 44/12 | F48: {=Common_InputFunctions.Utility_DisplayArrayInTable(Common_SourceData.Common_SourceData_ConvertGasElementalToMolecular_Data(),Table_GasToMolecularConversionFactor[[#Headers],[Gas]], 0)} -> 44 | G48: {=Common_InputFunctions.Utility_DisplayArrayInTable(Common_SourceData.Common_SourceData_ConvertGasElementalToMolecular_Data(),Table_GasToMolecularConversionFactor[[#Headers],[Gas]], 0)} -> 12 | H48: =Table_GasToMolecularConversionFactor[[#This Row],[Conversion factor 1]]/Table_GasToMolecularConversionFactor[[#This Row],[Conversion factor 2]] -> 3.6666667
D49: {=Common_InputFunctions.Utility_DisplayArrayInTable(Common_SourceData.Common_SourceData_ConvertGasElementalToMolecular_Data(),Table_GasToMolecularConversionFactor[[#Headers],[Gas]], 0)} -> CH4 | E49: {=Common_InputFunctions.Utility_DisplayArrayInTable(Common_SourceData.Common_SourceData_ConvertGasElementalToMolecular_Data(),Table_GasToMolecularConversionFactor[[#Headers],[Gas]], 0)} -> 16/12 | F49: {=Common_InputFunctions.Utility_DisplayArrayInTable(Common_SourceData.Common_SourceData_ConvertGasElementalToMolecular_Data(),Table_GasToMolecularConversionFactor[[#Headers],[Gas]], 0)} -> 16 | G49: {=Common_InputFunctions.Utility_DisplayArrayInTable(Common_SourceData.Common_SourceData_ConvertGasElementalToMolecular_Data(),Table_GasToMolecularConversionFactor[[#Headers],[Gas]], 0)} -> 12 | H49: =Table_GasToMolecularConversionFactor[[#This Row],[Conversion factor 1]]/Table_GasToMolecularConversionFactor[[#This Row],[Conversion factor 2]] -> 1.3333333
D50: {=Common_InputFunctions.Utility_DisplayArrayInTable(Common_SourceData.Common_SourceData_ConvertGasElementalToMolecular_Data(),Table_GasToMolecularConversionFactor[[#Headers],[Gas]], 0)} -> N2O | E50: {=Common_InputFunctions.Utility_DisplayArrayInTable(Common_SourceData.Common_SourceData_ConvertGasElementalToMolecular_Data(),Table_GasToMolecularConversionFactor[[#Headers],[Gas]], 0)} -> 44/28 | F50: {=Common_InputFunctions.Utility_DisplayArrayInTable(Common_SourceData.Common_SourceData_ConvertGasElementalToMolecular_Data(),Table_GasToMolecularConversionFactor[[#Headers],[Gas]], 0)} -> 44 | G50: {=Common_InputFunctions.Utility_DisplayArrayInTable(Common_SourceData.Common_SourceData_ConvertGasElementalToMolecular_Data(),Table_GasToMolecularConversionFactor[[#Headers],[Gas]], 0)} -> 28 | H50: =Table_GasToMolecularConversionFactor[[#This Row],[Conversion factor 1]]/Table_GasToMolecularConversionFactor[[#This Row],[Conversion factor 2]] -> 1.5714286
...
