Workbook
Name AgResidue_Equations_FieldBurning.VEERG_6_4_1_1__1__MethaneEmissionsFromBurningOfCropResidues: _xlfn.LAMBDA(_xlpm.Mburnc,_xlpm.CCc,_xlpm.EFCH4,_xlpm.C_CH4, _xlpm.Mburnc * _xlpm.CCc * _xlpm.EFCH4 * _xlpm.C_CH4 * 10 ^ (-3))
Name AgResidue_Equations_FieldBurning.VEERG_6_4_1_1__1__MethaneEmissionsFromBurningOfCropResidues_FunctionName: _xlfn.LAMBDA("VEERG_6_4_1_1__1__MethaneEmissionsFromBurningOfCropResidues")
Name AgResidue_Equations_FieldBurning.VEERG_6_4_1_1__1__MethaneEmissionsFromBurningOfCropResidues_LatexEquation: _xlfn.LAMBDA("E_{CH4}=\sum_{c}(M_{burn,c}\times CC_{c}\times EF_{CH4}\times C_{CH4}\times 10^{-3})")
Name AgResidue_Equations_FieldBurning.VEERG_6_4_1_1__1__MethaneEmissionsFromBurningOfCropResidues_NIRReference: _xlfn.LAMBDA("")
Name AgResidue_Equations_FieldBurning.VEERG_6_4_1_1__1__MethaneEmissionsFromBurningOfCropResidues_Source: _xlfn.LAMBDA("VEERG 2026: 6.4.1.1, Equation (1)")
Name AgResidue_Equations_FieldBurning.VEERG_6_4_1_1__1__MethaneEmissionsFromBurningOfCropResidues_Title: _xlfn.LAMBDA("Methane emissions from the burning of crop residues")
Name AgResidue_Equations_FieldBurning.VEERG_6_4_1_1__1__MethaneEmissionsFromBurningOfCropResidues_Unit: _xlfn.LAMBDA("t CH4")
Name AgResidue_Equations_FieldBurning.VEERG_6_4_1_1__1__MethaneEmissionsFromBurningOfCropResidues_Variable: _xlfn.LAMBDA("ECH4")
Name AgResidue_Equations_FieldBurning.VEERG_6_4_1_1__2__NitrousOxideEmissionsFromBurningOfCropResidues: _xlfn.LAMBDA(_xlpm.Mburnc,_xlpm.NCAGc,_xlpm.EFN2O,_xlpm.CN2O, _xlpm.Mburnc * _xlpm.NCAGc * _xlpm.EFN2O * _xlpm.CN2O * 10 ^ (-3))
Name AgResidue_Equations_FieldBurning.VEERG_6_4_1_1__2__NitrousOxideEmissionsFromBurningOfCropResidues_FunctionName: _xlfn.LAMBDA("VEERG_6_4_1_1__2__NitrousOxideEmissionsFromBurningOfCropResidues")
Name AgResidue_Equations_FieldBurning.VEERG_6_4_1_1__2__NitrousOxideEmissionsFromBurningOfCropResidues_LatexEquation: _xlfn.LAMBDA("E_{N2O}=\sum_{c}(M_{burn,c}\times NC_{AGc}\times EF_{N2O}\times C_{N2O}\times 10^{-3})")
Name AgResidue_Equations_FieldBurning.VEERG_6_4_1_1__2__NitrousOxideEmissionsFromBurningOfCropResidues_NIRReference: _xlfn.LAMBDA("")
Name AgResidue_Equations_FieldBurning.VEERG_6_4_1_1__2__NitrousOxideEmissionsFromBurningOfCropResidues_Source: _xlfn.LAMBDA("VEERG 2026: 6.4.1.1, Equation (2)")
Name AgResidue_Equations_FieldBurning.VEERG_6_4_1_1__2__NitrousOxideEmissionsFromBurningOfCropResidues_Title: _xlfn.LAMBDA("Nitrous oxide emissions from the burning of crop residues")
Name AgResidue_Equations_FieldBurning.VEERG_6_4_1_1__2__NitrousOxideEmissionsFromBurningOfCropResidues_Unit: _xlfn.LAMBDA("t N2O")
Name AgResidue_Equations_FieldBurning.VEERG_6_4_1_1__2__NitrousOxideEmissionsFromBurningOfCropResidues_Variable: _xlfn.LAMBDA("EN2O")
Name AgResidue_Equations_FieldBurning.VEERG_6_4_1_1__3__MassOfCropResidueBurnt: _xlfn.LAMBDA(_xlpm.Pc,_xlpm.RAGc,_xlpm.Sc,_xlpm.DMc,_xlpm.Zc,_xlpm.Fc, _xlpm.Pc * _xlpm.RAGc * _xlpm.Sc * _xlpm.DMc * _xlpm.Zc * _xlpm.Fc)
Name AgResidue_Equations_FieldBurning.VEERG_6_4_1_1__3__MassOfCropResidueBurnt_FunctionName: _xlfn.LAMBDA("VEERG_6_4_1_1__3__MassOfCropResidueBurnt")
Name AgResidue_Equations_FieldBurning.VEERG_6_4_1_1__3__MassOfCropResidueBurnt_LatexEquation: _xlfn.LAMBDA("M_{burn,c}=P_{c}\times R_{AGc}\times S_{c}\times DM_{c}\times Z_{c}\times F_{c}")
Name AgResidue_Equations_FieldBurning.VEERG_6_4_1_1__3__MassOfCropResidueBurnt_NIRReference: _xlfn.LAMBDA("")
Name AgResidue_Equations_FieldBurning.VEERG_6_4_1_1__3__MassOfCropResidueBurnt_Source: _xlfn.LAMBDA("VEERG 2026: 6.4.1.1, Equation (3)")
Name AgResidue_Equations_FieldBurning.VEERG_6_4_1_1__3__MassOfCropResidueBurnt_Title: _xlfn.LAMBDA("Mass of residue of crop c burnt")
Name AgResidue_Equations_FieldBurning.VEERG_6_4_1_1__3__MassOfCropResidueBurnt_Unit: _xlfn.LAMBDA("kg")
Name AgResidue_Equations_FieldBurning.VEERG_6_4_1_1__3__MassOfCropResidueBurnt_Variable: _xlfn.LAMBDA("Mburnc")
Name AgResidues_Equations_CropResidues.VEERG_6_1_1_1__1__NitrousOxideEmissionsFromCropResidues: _xlfn.LAMBDA(_xlpm.Mc,_xlpm.EFNi,_xlpm.CgN2O, _xlpm.Mc * _xlpm.EFNi * _xlpm.CgN2O * 10 ^ (-3))
Name AgResidues_Equations_CropResidues.VEERG_6_1_1_1__1__NitrousOxideEmissionsFromCropResidues_FunctionName: _xlfn.LAMBDA("VEERG_6_1_1_1__1__NitrousOxideEmissionsFromCropResidues")
Name AgResidues_Equations_CropResidues.VEERG_6_1_1_1__1__NitrousOxideEmissionsFromCropResidues_LatexEquation: _xlfn.LAMBDA("E=\sum_{c}{M_{c}\times EF_{N}\times C_{g,N2O}\times 10^{-3}}")
Name AgResidues_Equations_CropResidues.VEERG_6_1_1_1__1__NitrousOxideEmissionsFromCropResidues_NIRReference: _xlfn.LAMBDA("")
Name AgResidues_Equations_CropResidues.VEERG_6_1_1_1__1__NitrousOxideEmissionsFromCropResidues_Source: _xlfn.LAMBDA("VEERG 2026: 6.1.1.1, Equation (1)")
Name AgResidues_Equations_CropResidues.VEERG_6_1_1_1__1__NitrousOxideEmissionsFromCropResidues_Title: _xlfn.LAMBDA("Nitrous oxide emissions from the return of crop residues across all crops c to the soil")
Name AgResidues_Equations_CropResidues.VEERG_6_1_1_1__1__NitrousOxideEmissionsFromCropResidues_Unit: _xlfn.LAMBDA("t N2O")
Name AgResidues_Equations_CropResidues.VEERG_6_1_1_1__1__NitrousOxideEmissionsFromCropResidues_Variable: _xlfn.LAMBDA("E")
Name AgResidues_Equations_CropResidues.VEERG_6_1_1_1__2__MassOfNitrogenInCropResidues_LatexEquation: _xlfn.LAMBDA("M_{c}=(P_{c}\times R_{AGc}\times(1-F_{c}-FFOD_{c})\times DM_{c}\times NC_{AGc})+(P_{c}\times R_{AGc}\times R_{BGc}\times DM_{c}\times NC_{BGc})")
Name AgResidues_Equations_CropResidues.VEERG_6_1_1_1__2__MassOfNitrogenInCropResidues_NIRReference: _xlfn.LAMBDA("")
Name AgResidues_Equations_CropResidues.VEERG_6_1_1_1__2__MassOfNitrogenInCropResidues_Source: _xlfn.LAMBDA("VEERG 2026: 6.1.1.1, Equation (2)")
Name AgResidues_Equations_CropResidues.VEERG_6_1_1_1__2__MassOfNitrogenInCropResidues_Title: _xlfn.LAMBDA("Mass of nitrogen in crop residues returned to the soil")
Name AgResidues_Equations_CropResidues.VEERG_6_1_1_1__2__MassOfNitrogenInCropResidues_Unit: _xlfn.LAMBDA("kg N")
Name AgResidues_Equations_CropResidues.VEERG_6_1_1_1__2__MassOfNitrogenInCropResidues_Variable: _xlfn.LAMBDA("Mc")
Name AgResidues_Equations_CropResidues.VEERG_6_1_1_2__1__FractionOfCropResidueRemovedBaled: _xlfn.LAMBDA(_xlpm.B,_xlpm.MB,_xlpm.Pc,_xlpm.RAGc, IFERROR((_xlpm.B * _xlpm.MB) / (_xlpm.Pc * _xlpm.RAGc), 0))
Name AgResidues_Equations_CropResidues.VEERG_6_1_1_2__1__FractionOfCropResidueRemovedBaled_LatexEquation: _xlfn.LAMBDA("FFOD_{c,baled}=\frac{B\times M_{B}}{P_{c}\times R_{AG,c}}")
Name AgResidues_Equations_CropResidues.VEERG_6_1_1_2__1__FractionOfCropResidueRemovedBaled_NIRReference: _xlfn.LAMBDA("")
Name AgResidues_Equations_CropResidues.VEERG_6_1_1_2__1__FractionOfCropResidueRemovedBaled_Source: _xlfn.LAMBDA("VEERG 2026: 6.1.1.2, Equation (1)")
Name AgResidues_Equations_CropResidues.VEERG_6_1_1_2__1__FractionOfCropResidueRemovedBaled_Title: _xlfn.LAMBDA("Fraction of crop residue that is removed for crop c, calculated where residues are baled")
Name AgResidues_Equations_CropResidues.VEERG_6_1_1_2__1__FractionOfCropResidueRemovedBaled_Unit: _xlfn.LAMBDA("dimensionless")
Name AgResidues_Equations_CropResidues.VEERG_6_1_1_2__1__FractionOfCropResidueRemovedBaled_Variable: _xlfn.LAMBDA("FFODcbaled")
Name AgResidues_Equations_CropResidues.VEERG_6_1_1_2__1__FractionOfCropResidueRemovedBaled_Variation: _xlfn.LAMBDA("VARIATION FROM SOURCE: Added 'baled' to variable subscript")
Name AgResidues_Equations_CropResidues.VEERG_6_1_1_2__1a__FractionOfCropResidueRemoved: _xlfn.LAMBDA(_xlpm.FFODcbaled,_xlpm.FFODcother, _xlpm.FFODcbaled + _xlpm.FFODcother)
Name AgResidues_Equations_CropResidues.VEERG_6_1_1_2__1a__FractionOfCropResidueRemoved_LatexEquation: _xlfn.LAMBDA("FFOD_{c} = FFOD_{c,baled} + FFOD_{c,other}")
Name AgResidues_Equations_CropResidues.VEERG_6_1_1_2__1a__FractionOfCropResidueRemoved_NIRReference: _xlfn.LAMBDA("")
Name AgResidues_Equations_CropResidues.VEERG_6_1_1_2__1a__FractionOfCropResidueRemoved_Source: _xlfn.LAMBDA("")
Name AgResidues_Equations_CropResidues.VEERG_6_1_1_2__1a__FractionOfCropResidueRemoved_Title: _xlfn.LAMBDA("Fraction of crop residue that is removed for crop c")
Name AgResidues_Equations_CropResidues.VEERG_6_1_1_2__1a__FractionOfCropResidueRemoved_Unit: _xlfn.LAMBDA("dimensionless")
Name AgResidues_Equations_CropResidues.VEERG_6_1_1_2__1a__FractionOfCropResidueRemoved_Variable: _xlfn.LAMBDA("FFODc")
Name AgResidues_Equations_CropResidues.VEERG_6_1_1_2__1a__FractionOfCropResidueRemoved_Variation: _xlfn.LAMBDA("VARIATION FROM SOURCE: Added this equation to accommodate user-defined residue removal other than baling.")
Name AgResidues_Equations_Leaching.VEERG_6_3_1_1__1__LeachingAndRunoffEmissionsCropAndPastureResidue: _xlfn.LAMBDA(_xlpm.Mleachcp,_xlpm.EFleach,_xlpm.CgN2O, _xlpm.Mleachcp * _xlpm.EFleach * _xlpm.CgN2O * 10 ^ (-3))
Name AgResidues_Equations_Leaching.VEERG_6_3_1_1__1__LeachingAndRunoffEmissionsCropAndPastureResidue_LatexEquation: _xlfn.LAMBDA("E_{N2O}=\sum_{c}\sum_{p}(M_{leach,cp}\times EF_{leach}\times Cg_{N2O}\times 10^{-3})")
Name AgResidues_Equations_Leaching.VEERG_6_3_1_1__1__LeachingAndRunoffEmissionsCropAndPastureResidue_NIRReference: _xlfn.LAMBDA("")
Name AgResidues_Equations_Leaching.VEERG_6_3_1_1__1__LeachingAndRunoffEmissionsCropAndPastureResidue_Source: _xlfn.LAMBDA("VEERG 2026: 6.3.1.1, Equation (1)")
Name AgResidues_Equations_Leaching.VEERG_6_3_1_1__1__LeachingAndRunoffEmissionsCropAndPastureResidue_Title: _xlfn.LAMBDA("Nitrous oxide leaching and runoff emissions from crop and pasture residues returned to the soil")
Name AgResidues_Equations_Leaching.VEERG_6_3_1_1__1__LeachingAndRunoffEmissionsCropAndPastureResidue_Unit: _xlfn.LAMBDA("t N2O")

Sheet Input - MMS - Feedlot
A1: #VALUE! | C1: Input - MMS - Feedlot
A3: Home
A4: =HYPERLINK("#'Results'!A1", "Results") -> Results
D5: Intake
A6: INPUTS
A7: =HYPERLINK("#'Input - Site'!A1", "Site") -> Site | E7: Domestic (70-80 days) | F7: Export mid fed (80-200 days) | G7: Export long fed (200+ days)
A8: =HYPERLINK("#'Input - Production'!A1", "Production and outputs") -> Production and outputs | D8: Dry matter intake | E8: 10.4 | F8: 10.8 | G8: 8.2 | H8: kg dry matter / head day
A9: =HYPERLINK("#'Input - Herd - Dairy'!A1", "Herd - Dairy") -> Herd - Dairy | D9: Dry matter digestibility | E9: 0.81 | F9: 0.81 | G9: 0.79 | H9: Percent
A10: =HYPERLINK("#'Input - Feed - Dairy'!A1", "Purchased feed - Livestock") -> Purchased feed - Livestock
A11: =HYPERLINK("#'Input - Herd - Feedlot'!A1", "Herd - Feedlot") -> Herd - Feedlot
A12: =HYPERLINK("#'Input - Pasture'!A1", "Pasture") -> Pasture | D12: Manure management systems
A13: =HYPERLINK("#'Input - Grains'!A1", "Crop - Grains") -> Crop - Grains
A14: =HYPERLINK("#'Input - Fert Lime Chem'!A1", "Fertiliser, Lime & Chemicals") -> Fertiliser, Lime & Chemicals | D14: Production system 1: Stage 1
A15: =HYPERLINK("#'Input - Fuel & Energy'!A1", "Electricity and fuel") -> Electricity and fuel | D15: Stage 1 MMS | E15: Domestic (70-80 days) | F15: Export mid fed (80-200 days) | G15: Export long fed (200+ days)
A16: Waste | D16: Drylot (feed pad) | E16: 1 | F16: 1 | G16: 1 | H16: Percent
A17: Freight and transport
A18: =HYPERLINK("#'Input - Other Farm Inputs'!A1", "Other farm inputs") -> Other farm inputs
A19: =HYPERLINK("#'Input - Data quality'!A1", "Data quality") -> Data quality | D19: Production system 1: Stage 2
D20: Stage 2 MMS | E20: Domestic (70-80 days) | F20: Export mid fed (80-200 days) | G20: Export long fed (200+ days)
A21: CALCULATIONS | D21: ="Sent from " & $D$16 -> Sent from Drylot (feed pad) | E21: =IF($D$24="Pasture range and paddock", "⚠️ ALERT: Manure sent to 'pasture range and paddock do not go to stage 2. Select 'No MMS'.", "")
A22: N2O MMS | D22: ='Calcs - CH4 MMS Feedlot'!O44 -> Solid storage | E22: 0.2 | F22: 0.2 | G22: 0.2 | H22: Percent
A23: Enteric methane | D23: ='Calcs - CH4 MMS Feedlot'!O45 -> Composting (passive windrow) | E23: 0.2 | F23: 0.2 | G23: 0.2 | H23: Percent
A24: =HYPERLINK("#'Calcs - Fert Lime'!A1", "Fertiliser & soil amendments") -> Fertiliser & soil amendments | D24: ='Calcs - CH4 MMS Feedlot'!O46 -> Direct application | E24: 0.6 | F24: 0.6 | G24: 0.6 | H24: Percent
A25: =HYPERLINK("#'Calcs - Residue mgmt - Crop'!A1", "Residue management - Crop") -> Residue management - Crop | D25: Total (must equal 100%) | E25: =IF($D$24="Pasture range and paddock", "N/A", SUM(E22:E24)) -> 1 | F25: =IF($D$24="Pasture range and paddock", "N/A", SUM(F22:F24)) -> 1 | G25: =IF($D$24="Pasture range and paddock", "N/A", SUM(G22:G24)) -> 1 | H25: Percent
A26: =HYPERLINK("#'Calcs - Residue mgmt - Pasture'!A1", "Residue management - Pasture") -> Residue management - Pasture
A27: =HYPERLINK("#'Calcs - Field burning'!A1", "Field burning - Crop") -> Field burning - Crop
A28: =HYPERLINK("#'Calcs - Fuel'!A1", "Fuel") -> Fuel | D28: Production system 1: Post-treatment destinations
A29: =HYPERLINK("#'Calcs - Electricity'!A1", "Electricity") -> Electricity | D29: ="Sent from " & $D$16 -> Sent from Drylot (feed pad) | E29: =IF($D$24="Pasture range and paddock", "⚠️ ALERT Manure sent to 'pasture range and paddock do not go to stage 2, or post-treatment destinations.", "")
A30: =HYPERLINK("#'Calcs - Refrigerants'!A1", "Refrigerants") -> Refrigerants | D30: ="Percent sold from " & $D$22 -> Percent sold from Solid storage | E30: 0.25 | F30: 0.25 | G30: 0.25 | H30: Percent
A31: Waste | D31: ="Percent deposited on farm soils from " & $D$22 -> Percent deposited on farm soils from Solid storage | E31: =1-E30 -> 0.75 | F31: =1-F30 -> 0.75 | G31: =1-G30 -> 0.75 | H31: Percent
A32: Freight and transport
A33: =HYPERLINK("#'Calcs - Scope 3'!A1", "Purchased goods scope 3") -> Purchased goods scope 3 | D33: ="Percent sold from " & $D$23 -> Percent sold from Composting (passive windrow) | E33: 0.25 | F33: 0.25 | G33: 0.25 | H33: Percent
D34: ="Percent deposited on farm soils from " & $D$23 -> Percent deposited on farm soils from Composting (passive windrow) | E34: =1-E33 -> 0.75 | F34: =1-F33 -> 0.75 | G34: =1-G33 -> 0.75 | H34: Percent
A35: APPENDICES
A36: =HYPERLINK("#'Constants - Common'!A1", "Constants - Common") -> Constants - Common | D36: ="Percent sold from " & $D$24 & " for sale" -> Percent sold from Direct application for sale | E36: 0.25 | F36: 0.25 | G36: 0.25 | H36: Percent
A37: =HYPERLINK("#'Constants - Cropping'!A1", "Constants - Cropping") -> Constants - Cropping | D37: ="Percent deposited on farm soils from " & $D$24 -> Percent deposited on farm soils from Direct application | E37: =1-E36 -> 0.75 | F37: =1-F36 -> 0.75 | G37: =1-G36 -> 0.75 | H37: Percent
A38: =HYPERLINK("#'Constants - Livestock'!A1", "Constants - Livestock") -> Constants - Livestock
A39: =HYPERLINK("#'Constants - Dairy'!A1", "Constants - Dairy") -> Constants - Dairy
A40: Sources & acknowledgements

Sheet Calcs - CH4 MMS Feedlot
A1: #VALUE! | C1: Calculations - Manure management - Feedlot
A3: Home | D3: Equations | O3: Source data
A4: =HYPERLINK("#'Results'!A1", "Results") -> Results
D5: {=ManureManagement_Feedlot_Methane.VEERG_4_1_1_1__5_VolatileSolidProduction_Title()} -> Volatile solid production | O5: {=SourceData_Feedlot.SourceData_Feedlot_VSL_Title()} -> Feedlot - Fraction of volatile solids lost during storage in the primary system
A6: INPUTS | D6: {=ManureManagement_Feedlot_Methane.VEERG_4_1_1_1__5_VolatileSolidProduction_Source()} -> VEERG 2026: 4.1.1.1, Equation (5) | O6: {=SourceData_Feedlot.SourceData_Feedlot_VSL_Source()} -> VEERG 2026: 4.1.2.3 CONSTANTS
A7: =HYPERLINK("#'Input - Site'!A1", "Site") -> Site | D7: Function name | E7: {=Common_InputFunctions.Utility_DisplayFunctionName(D30)} -> =ManureManagement_Feedlot_Methane.VEERG_4_1_1_1__5_VolatileSolidProduction(D20,D25,$G$15) | O7: {=SourceData_Feedlot.SourceData_Feedlot_VSL_Variable()} -> VSL | P7: {=SourceData_Feedlot.SourceData_Feedlot_VSL_Data()} -> 0.5 | Q7: {=SourceData_Feedlot.SourceData_Feedlot_VSL_Unit()} -> Fraction
A8: =HYPERLINK("#'Input - Production'!A1", "Production and outputs") -> Production and outputs
A9: =HYPERLINK("#'Input - Herd - Dairy'!A1", "Herd - Dairy") -> Herd - Dairy
A10: =HYPERLINK("#'Input - Feed - Dairy'!A1", "Purchased feed - Livestock") -> Purchased feed - Livestock | D10: Variable | E10: {=ManureManagement_Feedlot_Methane.VEERG_4_1_1_1__5_VolatileSolidProduction_Variable()} -> VSj | O10: {=SourceData_Feedlot.SourceData_Feedlot_MMSm1T3_Title()} -> Fraction of volatile solids to each tertiary system assumed that 2 per cent is run - off from the feed pad.
A11: =HYPERLINK("#'Input - Herd - Feedlot'!A1", "Herd - Feedlot") -> Herd - Feedlot | D11: Unit | E11: {=ManureManagement_Feedlot_Methane.VEERG_4_1_1_1__5_VolatileSolidProduction_Unit()} -> kg/head/day | O11: {=SourceData_Feedlot.SourceData_Feedlot_MMSm1T3_Source()} -> VEERG 2026: 4.1.2.3 CONSTANTS
A12: =HYPERLINK("#'Input - Pasture'!A1", "Pasture") -> Pasture | O12: {=SourceData_Feedlot.SourceData_Feedlot_MMSm1T3_Variable()} -> MMSm1T3 | P12: {=SourceData_Feedlot.SourceData_Feedlot_MMSm1T3_Data()} -> 0.02 | Q12: {=SourceData_Feedlot.SourceData_Feedlot_MMSm1T3_Unit()} -> Fraction
A13: =HYPERLINK("#'Input - Grains'!A1", "Crop - Grains") -> Crop - Grains | D13: {=ManureManagement_Feedlot_Methane.VEERG_4_1_1_1__5_VolatileSolidProduction_Arguments()} -> Ij | E13: dry matter intake for each group : kg DM/head/day | G13: See Table_I_j
A14: =HYPERLINK("#'Input - Fert Lime Chem'!A1", "Fertiliser, Lime & Chemicals") -> Fertiliser, Lime & Chemicals | D14: DMDj | E14: dry matter digestibility for each group : fraction | G14: See Table_DMD_j
A15: =HYPERLINK("#'Input - Fuel & Energy'!A1", "Electricity and fuel") -> Electricity and fuel | D15: A | E15: ash content of manure : fraction | G15: =$P$17 -> 0.16 | O15: {=SourceData_Feedlot.SourceData_Feedlot_AshContent_Title()} -> Ash content of manure.
A16: Waste | O16: {=SourceData_Feedlot.SourceData_Feedlot_AshContent_Source()} -> VEERG 2026: 4.1.2.3 CONSTANTS
A17: Freight and transport | D17: Table_I_j | O17: {=SourceData_Feedlot.SourceData_Feedlot_AshContent_Variable()} -> A | P17: {=SourceData_Feedlot.SourceData_Feedlot_AshContent_Data()} -> 0.16 | Q17: {=SourceData_Feedlot.SourceData_Feedlot_AshContent_Unit()} -> Fraction
A18: =HYPERLINK("#'Input - Other Farm Inputs'!A1", "Other farm inputs") -> Other farm inputs | D18: Dry matter intake
A19: =HYPERLINK("#'Input - Data quality'!A1", "Data quality") -> Data quality | D19: Domestic (70-80 days) | E19: Export mid fed (80-200 days) | F19: Export long fed (200+ days)
D20: ='Input - MMS - Feedlot'!$E$8 -> 10.4 | E20: ='Input - MMS - Feedlot'!$F$8 -> 10.8 | F20: ='Input - MMS - Feedlot'!$G$8 -> 8.2 | G20: kg DM/head/day | O20: {=SourceData_Feedlot.SourceData_Feedlot_MethaneEmissionsPotential_Title()} -> Methane emissions potential.
A21: CALCULATIONS | O21: {=SourceData_Feedlot.SourceData_Feedlot_MethaneEmissionsPotential_Source()} -> VEERG 2026: 4.1.2.3 CONSTANTS
A22: N2O MMS | D22: Table_DMD_j | O22: {=SourceData_Feedlot.SourceData_Feedlot_MethaneEmissionsPotential_Variable()} -> B0 | P22: {=SourceData_Feedlot.SourceData_Feedlot_MethaneEmissionsPotential_Data()} -> 0.19 | Q22: {=SourceData_Feedlot.SourceData_Feedlot_MethaneEmissionsPotential_Unit()} -> m3 CH4 / kg VS
A23: Enteric methane | D23: Dry matter digestibility
A24: =HYPERLINK("#'Calcs - Fert Lime'!A1", "Fertiliser & soil amendments") -> Fertiliser & soil amendments | D24: Domestic (70-80 days) | E24: Export mid fed (80-200 days) | F24: Export long fed (200+ days)
A25: =HYPERLINK("#'Calcs - Residue mgmt - Crop'!A1", "Residue management - Crop") -> Residue management - Crop | D25: ='Input - MMS - Feedlot'!$E$9 -> 0.81 | E25: ='Input - MMS - Feedlot'!$F$9 -> 0.81 | F25: ='Input - MMS - Feedlot'!$G$9 -> 0.79 | G25: Fraction | O25: {=SourceData_Feedlot.SourceData_Feedlot_MCF_Title()} -> Feedlot - MCFs
A26: =HYPERLINK("#'Calcs - Residue mgmt - Pasture'!A1", "Residue management - Pasture") -> Residue management - Pasture | O26: {=SourceData_Feedlot.SourceData_Feedlot_MCF_Source()} -> VEERG 2026: Table A.1.7.4: Feedlot - MCFs
A27: =HYPERLINK("#'Calcs - Field burning'!A1", "Field burning - Crop") -> Field burning - Crop | D27: Table_VS_j | O27: {=SourceData_Feedlot.SourceData_Feedlot_MCF_Variation()} -> VARIATION ON SOURCE:
A28: =HYPERLINK("#'Calcs - Fuel'!A1", "Fuel") -> Fuel | D28: Volatile solid production | O28: Duplicated NSW values for ACT
A29: =HYPERLINK("#'Calcs - Electricity'!A1", "Electricity") -> Electricity | D29: Domestic (70-80 days) | E29: Export mid fed (80-200 days) | F29: Export long fed (200+ days) | O29: Added NT and TAS columns with 'no data' values
A30: =HYPERLINK("#'Calcs - Refrigerants'!A1", "Refrigerants") -> Refrigerants | D30: {=ManureManagement_Feedlot_Methane.VEERG_4_1_1_1__5_VolatileSolidProduction(D20,D25,$G$15)} -> 1.65984 | E30: {=ManureManagement_Feedlot_Methane.VEERG_4_1_1_1__5_VolatileSolidProduction(E20,E25,$G$15)} -> 1.72368 | F30: {=ManureManagement_Feedlot_Methane.VEERG_4_1_1_1__5_VolatileSolidProduction(F20,F25,$G$15)} -> 1.44648 | G30: =E11 -> kg/head/day | O30: Added 'NIR definition' column with MMS names that match NIR definitions.
A31: Waste
A32: Freight and transport | O32: Treatment stage T | P32: MMS m | Q32: NSW | R32: ACT | S32: QLD | T32: NT | U32: SA | V32: VIC | W32: WA | X32: TAS | Y32: NIR definition
A33: =HYPERLINK("#'Calcs - Scope 3'!A1", "Purchased goods scope 3") -> Purchased goods scope 3 | O33: {=Common_InputFunctions.Utility_DisplayArrayInTable(SourceData_Feedlot.SourceData_Feedlot_MCF_Data(), Table_SourceData_Feedlot_MCF[[#Headers],[Treatment stage T]], 0)} -> Primary | P33: {=Common_InputFunctions.Utility_DisplayArrayInTable(SourceData_Feedlot.SourceData_Feedlot_MCF_Data(), Table_SourceData_Feedlot_MCF[[#Headers],[Treatment stage T]], 0)} -> Dry lot (Feedpad) | Q33: {=Common_InputFunctions.Utility_DisplayArrayInTable(SourceData_Feedlot.SourceData_Feedlot_MCF_Data(), Table_SourceData_Feedlot_MCF[[#Headers],[Treatment stage T]], 0)} -> 0.01 | R33: {=Common_InputFunctions.Utility_DisplayArrayInTable(SourceData_Feedlot.SourceData_Feedlot_MCF_Data(), Table_SourceData_Feedlot_MCF[[#Headers],[Treatment stage T]], 0)} -> 0.01 | S33: {=Common_InputFunctions.Utility_DisplayArrayInTable(SourceData_Feedlot.SourceData_Feedlot_MCF_Data(), Table_SourceData_Feedlot_MCF[[#Headers],[Treatment stage T]], 0)} -> 0.03 | T33: {=Common_InputFunctions.Utility_DisplayArrayInTable(SourceData_Feedlot.SourceData_Feedlot_MCF_Data(), Table_SourceData_Feedlot_MCF[[#Headers],[Treatment stage T]], 0)} -> No data | U33: {=Common_InputFunctions.Utility_DisplayArrayInTable(SourceData_Feedlot.SourceData_Feedlot_MCF_Data(), Table_SourceData_Feedlot_MCF[[#Headers],[Treatment stage T]], 0)} -> 0.01 | V33: {=Common_InputFunctions.Utility_DisplayArrayInTable(SourceData_Feedlot.SourceData_Feedlot_MCF_Data(), Table_SourceData_Feedlot_MCF[[#Headers],[Treatment stage T]], 0)} -> 0.01 | ... Y33: {=Common_InputFunctions.Utility_DisplayArrayInTable(SourceData_Feedlot.SourceData_Feedlot_MCF_Data(), Table_SourceData_Feedlot_MCF[[#Headers],[Treatment stage T]], 0)} -> Drylot (feed pad)
D34: {=ManureManagement_Feedlot_Methane.VEERG_4_1_1_1__2_Stage1MethaneProductionDrylot_Title()} -> Production of methane in treatment stage 1 MMS | O34: {=Common_InputFunctions.Utility_DisplayArrayInTable(SourceData_Feedlot.SourceData_Feedlot_MCF_Data(), Table_SourceData_Feedlot_MCF[[#Headers],[Treatment stage T]], 0)} -> Secondary | P34: {=Common_InputFunctions.Utility_DisplayArrayInTable(SourceData_Feedlot.SourceData_Feedlot_MCF_Data(), Table_SourceData_Feedlot_MCF[[#Headers],[Treatment stage T]], 0)} -> Solid Storage (Stockpile) | Q34: {=Common_InputFunctions.Utility_DisplayArrayInTable(SourceData_Feedlot.SourceData_Feedlot_MCF_Data(), Table_SourceData_Feedlot_MCF[[#Headers],[Treatment stage T]], 0)} -> 0.02 | R34: {=Common_InputFunctions.Utility_DisplayArrayInTable(SourceData_Feedlot.SourceData_Feedlot_MCF_Data(), Table_SourceData_Feedlot_MCF[[#Headers],[Treatment stage T]], 0)} -> 0.02 | S34: {=Common_InputFunctions.Utility_DisplayArrayInTable(SourceData_Feedlot.SourceData_Feedlot_MCF_Data(), Table_SourceData_Feedlot_MCF[[#Headers],[Treatment stage T]], 0)} -> 0.02 | T34: {=Common_InputFunctions.Utility_DisplayArrayInTable(SourceData_Feedlot.SourceData_Feedlot_MCF_Data(), Table_SourceData_Feedlot_MCF[[#Headers],[Treatment stage T]], 0)} -> No data | U34: {=Common_InputFunctions.Utility_DisplayArrayInTable(SourceData_Feedlot.SourceData_Feedlot_MCF_Data(), Table_SourceData_Feedlot_MCF[[#Headers],[Treatment stage T]], 0)} -> 0.02 | V34: {=Common_InputFunctions.Utility_DisplayArrayInTable(SourceData_Feedlot.SourceData_Feedlot_MCF_Data(), Table_SourceData_Feedlot_MCF[[#Headers],[Treatment stage T]], 0)} -> 0.02 | ... Y34: {=Common_InputFunctions.Utility_DisplayArrayInTable(SourceData_Feedlot.SourceData_Feedlot_MCF_Data(), Table_SourceData_Feedlot_MCF[[#Headers],[Treatment stage T]], 0)} -> Solid storage
A35: APPENDICES | D35: {=ManureManagement_Feedlot_Methane.VEERG_4_1_1_1__2_Stage1MethaneProductionDrylot_Source()} -> VEERG 2026: 4.1.1.1, Equation (2) | O35: {=Common_InputFunctions.Utility_DisplayArrayInTable(SourceData_Feedlot.SourceData_Feedlot_MCF_Data(), Table_SourceData_Feedlot_MCF[[#Headers],[Treatment stage T]], 0)} -> Secondary | P35: {=Common_InputFunctions.Utility_DisplayArrayInTable(SourceData_Feedlot.SourceData_Feedlot_MCF_Data(), Table_SourceData_Feedlot_MCF[[#Headers],[Treatment stage T]], 0)} -> Composting (Passive Windrow) | Q35: {=Common_InputFunctions.Utility_DisplayArrayInTable(SourceData_Feedlot.SourceData_Feedlot_MCF_Data(), Table_SourceData_Feedlot_MCF[[#Headers],[Treatment stage T]], 0)} -> 0.01 | R35: {=Common_InputFunctions.Utility_DisplayArrayInTable(SourceData_Feedlot.SourceData_Feedlot_MCF_Data(), Table_SourceData_Feedlot_MCF[[#Headers],[Treatment stage T]], 0)} -> 0.01 | S35: {=Common_InputFunctions.Utility_DisplayArrayInTable(SourceData_Feedlot.SourceData_Feedlot_MCF_Data(), Table_SourceData_Feedlot_MCF[[#Headers],[Treatment stage T]], 0)} -> 0.01 | T35: {=Common_InputFunctions.Utility_DisplayArrayInTable(SourceData_Feedlot.SourceData_Feedlot_MCF_Data(), Table_SourceData_Feedlot_MCF[[#Headers],[Treatment stage T]], 0)} -> No data | U35: {=Common_InputFunctions.Utility_DisplayArrayInTable(SourceData_Feedlot.SourceData_Feedlot_MCF_Data(), Table_SourceData_Feedlot_MCF[[#Headers],[Treatment stage T]], 0)} -> 0.01 | V35: {=Common_InputFunctions.Utility_DisplayArrayInTable(SourceData_Feedlot.SourceData_Feedlot_MCF_Data(), Table_SourceData_Feedlot_MCF[[#Headers],[Treatment stage T]], 0)} -> 0.01 | ... Y35: {=Common_InputFunctions.Utility_DisplayArrayInTable(SourceData_Feedlot.SourceData_Feedlot_MCF_Data(), Table_SourceData_Feedlot_MCF[[#Headers],[Treatment stage T]], 0)} -> Composting (passive windrow)
A36: =HYPERLINK("#'Constants - Common'!A1", "Constants - Common") -> Constants - Common | D36: Function name | E36: {=Common_InputFunctions.Utility_DisplayFunctionName(E57)} -> =ManureManagement_Feedlot_Methane.VEERG_4_1_1_1__2_Stage1MethaneProductionDrylot(D30,$G$43,E52,$G$45,$G$46) | O36: {=Common_InputFunctions.Utility_DisplayArrayInTable(SourceData_Feedlot.SourceData_Feedlot_MCF_Data(), Table_SourceData_Feedlot_MCF[[#Headers],[Treatment stage T]], 0)} -> Secondary | P36: {=Common_InputFunctions.Utility_DisplayArrayInTable(SourceData_Feedlot.SourceData_Feedlot_MCF_Data(), Table_SourceData_Feedlot_MCF[[#Headers],[Treatment stage T]], 0)} -> Direct Application to soil | Q36: {=Common_InputFunctions.Utility_DisplayArrayInTable(SourceData_Feedlot.SourceData_Feedlot_MCF_Data(), Table_SourceData_Feedlot_MCF[[#Headers],[Treatment stage T]], 0)} -> 0 | R36: {=Common_InputFunctions.Utility_DisplayArrayInTable(SourceData_Feedlot.SourceData_Feedlot_MCF_Data(), Table_SourceData_Feedlot_MCF[[#Headers],[Treatment stage T]], 0)} -> 0 | S36: {=Common_InputFunctions.Utility_DisplayArrayInTable(SourceData_Feedlot.SourceData_Feedlot_MCF_Data(), Table_SourceData_Feedlot_MCF[[#Headers],[Treatment stage T]], 0)} -> 0 | T36: {=Common_InputFunctions.Utility_DisplayArrayInTable(SourceData_Feedlot.SourceData_Feedlot_MCF_Data(), Table_SourceData_Feedlot_MCF[[#Headers],[Treatment stage T]], 0)} -> No data | U36: {=Common_InputFunctions.Utility_DisplayArrayInTable(SourceData_Feedlot.SourceData_Feedlot_MCF_Data(), Table_SourceData_Feedlot_MCF[[#Headers],[Treatment stage T]], 0)} -> 0 | V36: {=Common_InputFunctions.Utility_DisplayArrayInTable(SourceData_Feedlot.SourceData_Feedlot_MCF_Data(), Table_SourceData_Feedlot_MCF[[#Headers],[Treatment stage T]], 0)} -> 0 | ... Y36: {=Common_InputFunctions.Utility_DisplayArrayInTable(SourceData_Feedlot.SourceData_Feedlot_MCF_Data(), Table_SourceData_Feedlot_MCF[[#Headers],[Treatment stage T]], 0)} -> Direct application
A37: =HYPERLINK("#'Constants - Cropping'!A1", "Constants - Cropping") -> Constants - Cropping | O37: {=Common_InputFunctions.Utility_DisplayArrayInTable(SourceData_Feedlot.SourceData_Feedlot_MCF_Data(), Table_SourceData_Feedlot_MCF[[#Headers],[Treatment stage T]], 0)} -> Tertiary | P37: {=Common_InputFunctions.Utility_DisplayArrayInTable(SourceData_Feedlot.SourceData_Feedlot_MCF_Data(), Table_SourceData_Feedlot_MCF[[#Headers],[Treatment stage T]], 0)} -> Uncovered anaerobic lagoon (Effluent pond) | Q37: {=Common_InputFunctions.Utility_DisplayArrayInTable(SourceData_Feedlot.SourceData_Feedlot_MCF_Data(), Table_SourceData_Feedlot_MCF[[#Headers],[Treatment stage T]], 0)} -> 0.75 | R37: {=Common_InputFunctions.Utility_DisplayArrayInTable(SourceData_Feedlot.SourceData_Feedlot_MCF_Data(), Table_SourceData_Feedlot_MCF[[#Headers],[Treatment stage T]], 0)} -> 0.75 | S37: {=Common_InputFunctions.Utility_DisplayArrayInTable(SourceData_Feedlot.SourceData_Feedlot_MCF_Data(), Table_SourceData_Feedlot_MCF[[#Headers],[Treatment stage T]], 0)} -> 0.77 | T37: {=Common_InputFunctions.Utility_DisplayArrayInTable(SourceData_Feedlot.SourceData_Feedlot_MCF_Data(), Table_SourceData_Feedlot_MCF[[#Headers],[Treatment stage T]], 0)} -> No data | U37: {=Common_InputFunctions.Utility_DisplayArrayInTable(SourceData_Feedlot.SourceData_Feedlot_MCF_Data(), Table_SourceData_Feedlot_MCF[[#Headers],[Treatment stage T]], 0)} -> 0.75 | V37: {=Common_InputFunctions.Utility_DisplayArrayInTable(SourceData_Feedlot.SourceData_Feedlot_MCF_Data(), Table_SourceData_Feedlot_MCF[[#Headers],[Treatment stage T]], 0)} -> 0.75 | ... Y37: {=Common_InputFunctions.Utility_DisplayArrayInTable(SourceData_Feedlot.SourceData_Feedlot_MCF_Data(), Table_SourceData_Feedlot_MCF[[#Headers],[Treatment stage T]], 0)} -> Anaerobic lagoon
A38: =HYPERLINK("#'Constants - Livestock'!A1", "Constants - Livestock") -> Constants - Livestock
A39: =HYPERLINK("#'Constants - Dairy'!A1", "Constants - Dairy") -> Constants - Dairy | D39: Variable | E39: {=ManureManagement_Feedlot_Methane.VEERG_4_1_1_1__2_Stage1MethaneProductionDrylot_Variable()} -> Mjm5T1
A40: Sources & acknowledgements | D40: Unit | E40: {=ManureManagement_Feedlot_Methane.VEERG_4_1_1_1__2_Stage1MethaneProductionDrylot_Unit()} -> kg CH4/head/day | O40: Feedlot manure management systems
D42: {=ManureManagement_Feedlot_Methane.VEERG_4_1_1_1__2_Stage1MethaneProductionDrylot_Arguments()} -> VSj | E42: volatile solid production from feedlot cattle in each group : kg/head/day | G42: See Table_VS_j | O42: MMS | P42: Symbol and MMS
...

Sheet Input - MMS - Poultry
A1: #VALUE! | C1: Input - MMS - Poultry
A3: Home
A4: =HYPERLINK("#'Results'!A1", "Results") -> Results
D5: This tool demostrates inputs for two production system combinations.
A6: INPUTS | D6: Each production system has two primary manure management systems, and three possible secondary manure management systems.
A7: =HYPERLINK("#'Input - Site'!A1", "Site") -> Site
A8: =HYPERLINK("#'Input - Production'!A1", "Production and outputs") -> Production and outputs | D8: Intake
A9: =HYPERLINK("#'Input - Herd - Dairy'!A1", "Herd - Dairy") -> Herd - Dairy | E9: Layers | F9: Meat chicken growers | G9: Meat chicken breeders | H9: Other
A10: =HYPERLINK("#'Input - Feed - Dairy'!A1", "Purchased feed - Livestock") -> Purchased feed - Livestock | D10: Dry matter intake | E10: 10 | F10: 10 | G10: 10 | H10: 10 | I10: kg DM/head/day
A11: =HYPERLINK("#'Input - Herd - Feedlot'!A1", "Herd - Feedlot") -> Herd - Feedlot | D11: Dry matter digestibility | E11: 0.1 | F11: 0.1 | G11: 0.1 | H11: 0.1 | I11: Percent
A12: =HYPERLINK("#'Input - Pasture'!A1", "Pasture") -> Pasture
A13: =HYPERLINK("#'Input - Grains'!A1", "Crop - Grains") -> Crop - Grains
A14: =HYPERLINK("#'Input - Fert Lime Chem'!A1", "Fertiliser, Lime & Chemicals") -> Fertiliser, Lime & Chemicals | D14: Production systems
A15: =HYPERLINK("#'Input - Fuel & Energy'!A1", "Electricity and fuel") -> Electricity and fuel
A16: Waste | D16: Production system (select) | E16: Layers | F16: Meat chicken growers | G16: Meat chicken breeders | H16: Other
A17: Freight and transport | D17: Free range | E17: 0.5 | F17: 0.5 | G17: 0.5 | H17: 0.5 | I17: Percent
A18: =HYPERLINK("#'Input - Other Farm Inputs'!A1", "Other farm inputs") -> Other farm inputs | D18: Cage | E18: 0.5 | F18: 0.5 | G18: 0.5 | H18: 0.5 | I18: Percent
A19: =HYPERLINK("#'Input - Data quality'!A1", "Data quality") -> Data quality | D19: Total (must equal 100%) | E19: =SUM(E17:E18) -> 1 | F19: =SUM(F17:F18) -> 1 | G19: =SUM(G17:G18) -> 1 | H19: =SUM(H17:H18) -> 1 | I19: Percent
A21: CALCULATIONS
A22: N2O MMS | D22: Production system 1 of 2
A23: Enteric methane
A24: =HYPERLINK("#'Calcs - Fert Lime'!A1", "Fertiliser & soil amendments") -> Fertiliser & soil amendments | D24: Production system 1 | E24: =$D$17 -> Free range
A25: =HYPERLINK("#'Calcs - Residue mgmt - Crop'!A1", "Residue management - Crop") -> Residue management - Crop
A26: =HYPERLINK("#'Calcs - Residue mgmt - Pasture'!A1", "Residue management - Pasture") -> Residue management - Pasture | D26: Production system 1: Stage 1
A27: =HYPERLINK("#'Calcs - Field burning'!A1", "Field burning - Crop") -> Field burning - Crop | D27: =IF($E$24="Free range", "⚠️ ALERT: Because this production system is free range, one stage 1 MMS must be 'Pasture, range and paddock.'", "") -> ⚠️ ALERT: Because this production system is free range, one stage 1 MMS must be 'Pasture, range and paddock.'
A28: =HYPERLINK("#'Calcs - Fuel'!A1", "Fuel") -> Fuel | D28: Stage 1 MMS (select) | E28: Layers | F28: Meat chicken growers | G28: Meat chicken breeders | H28: Other
A29: =HYPERLINK("#'Calcs - Electricity'!A1", "Electricity") -> Electricity | D29: Pasture range and paddock | E29: 0.5 | F29: 0.5 | G29: 0.5 | H29: 0.5 | I29: Percent
A30: =HYPERLINK("#'Calcs - Refrigerants'!A1", "Refrigerants") -> Refrigerants | D30: Belt manure removal | E30: 0.5 | F30: 0.5 | G30: 0.5 | H30: 0.5 | I30: Percent
A31: Waste | D31: Total (must equal 100%) | E31: =SUM(E29:E30) -> 1 | F31: =SUM(F29:F30) -> 1 | G31: =SUM(G29:G30) -> 1 | H31: =SUM(H29:H30) -> 1 | I31: Percent
A32: Freight and transport
A33: =HYPERLINK("#'Calcs - Scope 3'!A1", "Purchased goods scope 3") -> Purchased goods scope 3 | D33: Production system 1: Stage 2
A35: APPENDICES | D35: Stage 2 MMS (select) | E35: Layers | F35: Meat chicken growers | G35: Meat chicken breeders | H35: Other
A36: =HYPERLINK("#'Constants - Common'!A1", "Constants - Common") -> Constants - Common | D36: ="Sent from " & $D$29 -> Sent from Pasture range and paddock | E36: =IF($D$29="Pasture range and paddock", "⚠️ ALERT: Manure sent to 'pasture range and paddock do not go to stage 2. Select 'No MMS'.", "") -> ⚠️ ALERT: Manure sent to 'pasture range and paddock do not go to stage 2. Select 'No MMS'.
A37: =HYPERLINK("#'Constants - Cropping'!A1", "Constants - Cropping") -> Constants - Cropping | D37: No MMS | E37: 0.2 | F37: 0.2 | G37: 0.2 | H37: 0.2 | I37: Percent
A38: =HYPERLINK("#'Constants - Livestock'!A1", "Constants - Livestock") -> Constants - Livestock | D38: No MMS | E38: 0.2 | F38: 0.2 | G38: 0.2 | H38: 0.2 | I38: Percent
A39: =HYPERLINK("#'Constants - Dairy'!A1", "Constants - Dairy") -> Constants - Dairy | D39: No MMS | E39: 0.6 | F39: 0.6 | G39: 0.6 | H39: 0.6 | I39: Percent
A40: Sources & acknowledgements | D40: Total (must equal 100%) | E40: =IF($D$29="Pasture range and paddock", "N/A", SUM(E37:E39)) -> N/A | F40: =IF($D$29="Pasture range and paddock", "N/A", SUM(F37:F39)) -> N/A | G40: =IF($D$29="Pasture range and paddock", "N/A", SUM(G37:G39)) -> N/A | H40: =IF($D$29="Pasture range and paddock", "N/A", SUM(H37:H39)) -> N/A | I40: Percent
D42: ="Sent from " & $D$30 -> Sent from Belt manure removal | E42: =IF($D$30="Pasture range and paddock", "Manure sent to 'pasture range and paddock do not go to stage 2. Select 'No MMS'.", "")
D43: Direct processing | E43: 0.2 | F43: 0.2 | G43: 0.2 | H43: 0.2 | I43: Percent
D44: Composting (passive windrow) | E44: 0.2 | F44: 0.2 | G44: 0.2 | H44: 0.2 | I44: Percent
...

Sheet Calcs - CH4 MMS Poultry
A1: #VALUE! | C1: Calculations - Manure management - Poultry
A3: Home | D3: Equations | O3: Source data
A4: =HYPERLINK("#'Results'!A1", "Results") -> Results
D5: {=ManureManagement_Poultry_Methane.VEERG_4_6_1_1__6_VolatileSolidProduction_Title()} -> Volatile solid production | O5: {=SourceData_Poultry.SourceData_Poultry_DietProperties_Title()} -> Poultry - Diet properties
A6: INPUTS | D6: {=ManureManagement_Poultry_Methane.VEERG_4_6_1_1__6_VolatileSolidProduction_Source()} -> VEERG 2026: 4.6.1.1, Equation (6) | O6: {=SourceData_Poultry.SourceData_Poultry_DietProperties_Source()} -> VEERG 2026: Table A.1.7.1: Poultry - Diet properties
A7: =HYPERLINK("#'Input - Site'!A1", "Site") -> Site | D7: Function name | E7: {=Common_InputFunctions.Utility_DisplayFunctionName(D35)} -> =ManureManagement_Poultry_Methane.VEERG_4_6_1_1__6_VolatileSolidProduction(D20,D25,D30)
A8: =HYPERLINK("#'Input - Production'!A1", "Production and outputs") -> Production and outputs | O8: Nutrient analysis | P8: Layers | Q8: Meat chicken growers | R8: Meat chicken breeder | S8: Meat other
A9: =HYPERLINK("#'Input - Herd - Dairy'!A1", "Herd - Dairy") -> Herd - Dairy | O9: {=Common_InputFunctions.Utility_DisplayArrayInTable(SourceData_Poultry.SourceData_Poultry_DietProperties_Data(), Table_SourceData_Poultry_DietProperties[[#Headers],[Nutrient analysis]], 0)} -> Dry matter intake (kg/head/day) | P9: {=Common_InputFunctions.Utility_DisplayArrayInTable(SourceData_Poultry.SourceData_Poultry_DietProperties_Data(), Table_SourceData_Poultry_DietProperties[[#Headers],[Nutrient analysis]], 0)} -> 0.086 | Q9: {=Common_InputFunctions.Utility_DisplayArrayInTable(SourceData_Poultry.SourceData_Poultry_DietProperties_Data(), Table_SourceData_Poultry_DietProperties[[#Headers],[Nutrient analysis]], 0)} -> 0.093 | R9: {=Common_InputFunctions.Utility_DisplayArrayInTable(SourceData_Poultry.SourceData_Poultry_DietProperties_Data(), Table_SourceData_Poultry_DietProperties[[#Headers],[Nutrient analysis]], 0)} -> 0.103 | S9: {=Common_InputFunctions.Utility_DisplayArrayInTable(SourceData_Poultry.SourceData_Poultry_DietProperties_Data(), Table_SourceData_Poultry_DietProperties[[#Headers],[Nutrient analysis]], 0)} -> 0.093
A10: =HYPERLINK("#'Input - Feed - Dairy'!A1", "Purchased feed - Livestock") -> Purchased feed - Livestock | D10: Variable | E10: {=ManureManagement_Poultry_Methane.VEERG_4_6_1_1__6_VolatileSolidProduction_Variable()} -> VSjk | O10: {=Common_InputFunctions.Utility_DisplayArrayInTable(SourceData_Poultry.SourceData_Poultry_DietProperties_Data(), Table_SourceData_Poultry_DietProperties[[#Headers],[Nutrient analysis]], 0)} -> Dry matter digestibility | P10: {=Common_InputFunctions.Utility_DisplayArrayInTable(SourceData_Poultry.SourceData_Poultry_DietProperties_Data(), Table_SourceData_Poultry_DietProperties[[#Headers],[Nutrient analysis]], 0)} -> 0.8 | Q10: {=Common_InputFunctions.Utility_DisplayArrayInTable(SourceData_Poultry.SourceData_Poultry_DietProperties_Data(), Table_SourceData_Poultry_DietProperties[[#Headers],[Nutrient analysis]], 0)} -> 0.8 | R10: {=Common_InputFunctions.Utility_DisplayArrayInTable(SourceData_Poultry.SourceData_Poultry_DietProperties_Data(), Table_SourceData_Poultry_DietProperties[[#Headers],[Nutrient analysis]], 0)} -> 0.8 | S10: {=Common_InputFunctions.Utility_DisplayArrayInTable(SourceData_Poultry.SourceData_Poultry_DietProperties_Data(), Table_SourceData_Poultry_DietProperties[[#Headers],[Nutrient analysis]], 0)} -> 0.8
A11: =HYPERLINK("#'Input - Herd - Feedlot'!A1", "Herd - Feedlot") -> Herd - Feedlot | D11: Unit | E11: {=ManureManagement_Poultry_Methane.VEERG_4_6_1_1__6_VolatileSolidProduction_Unit()} -> kg/head/day | O11: {=Common_InputFunctions.Utility_DisplayArrayInTable(SourceData_Poultry.SourceData_Poultry_DietProperties_Data(), Table_SourceData_Poultry_DietProperties[[#Headers],[Nutrient analysis]], 0)} -> Crude protein | P11: {=Common_InputFunctions.Utility_DisplayArrayInTable(SourceData_Poultry.SourceData_Poultry_DietProperties_Data(), Table_SourceData_Poultry_DietProperties[[#Headers],[Nutrient analysis]], 0)} -> 0.19 | Q11: {=Common_InputFunctions.Utility_DisplayArrayInTable(SourceData_Poultry.SourceData_Poultry_DietProperties_Data(), Table_SourceData_Poultry_DietProperties[[#Headers],[Nutrient analysis]], 0)} -> 0.23 | R11: {=Common_InputFunctions.Utility_DisplayArrayInTable(SourceData_Poultry.SourceData_Poultry_DietProperties_Data(), Table_SourceData_Poultry_DietProperties[[#Headers],[Nutrient analysis]], 0)} -> 0.19 | S11: {=Common_InputFunctions.Utility_DisplayArrayInTable(SourceData_Poultry.SourceData_Poultry_DietProperties_Data(), Table_SourceData_Poultry_DietProperties[[#Headers],[Nutrient analysis]], 0)} -> 0.23
A12: =HYPERLINK("#'Input - Pasture'!A1", "Pasture") -> Pasture | O12: {=Common_InputFunctions.Utility_DisplayArrayInTable(SourceData_Poultry.SourceData_Poultry_DietProperties_Data(), Table_SourceData_Poultry_DietProperties[[#Headers],[Nutrient analysis]], 0)} -> Nitrogen retention rate | P12: {=Common_InputFunctions.Utility_DisplayArrayInTable(SourceData_Poultry.SourceData_Poultry_DietProperties_Data(), Table_SourceData_Poultry_DietProperties[[#Headers],[Nutrient analysis]], 0)} -> 0.35 | Q12: {=Common_InputFunctions.Utility_DisplayArrayInTable(SourceData_Poultry.SourceData_Poultry_DietProperties_Data(), Table_SourceData_Poultry_DietProperties[[#Headers],[Nutrient analysis]], 0)} -> 0.47 | R12: {=Common_InputFunctions.Utility_DisplayArrayInTable(SourceData_Poultry.SourceData_Poultry_DietProperties_Data(), Table_SourceData_Poultry_DietProperties[[#Headers],[Nutrient analysis]], 0)} -> 0.32 | S12: {=Common_InputFunctions.Utility_DisplayArrayInTable(SourceData_Poultry.SourceData_Poultry_DietProperties_Data(), Table_SourceData_Poultry_DietProperties[[#Headers],[Nutrient analysis]], 0)} -> 0.47
A13: =HYPERLINK("#'Input - Grains'!A1", "Crop - Grains") -> Crop - Grains | D13: {=ManureManagement_Poultry_Methane.VEERG_4_6_1_1__6_VolatileSolidProduction_Arguments()} -> Ijk | E13: dry matter intake for each class and subclass : kg DM/head/day | G13: see Table_I_j_k | O13: {=Common_InputFunctions.Utility_DisplayArrayInTable(SourceData_Poultry.SourceData_Poultry_DietProperties_Data(), Table_SourceData_Poultry_DietProperties[[#Headers],[Nutrient analysis]], 0)} -> Manure ash | P13: {=Common_InputFunctions.Utility_DisplayArrayInTable(SourceData_Poultry.SourceData_Poultry_DietProperties_Data(), Table_SourceData_Poultry_DietProperties[[#Headers],[Nutrient analysis]], 0)} -> 0.18 | Q13: {=Common_InputFunctions.Utility_DisplayArrayInTable(SourceData_Poultry.SourceData_Poultry_DietProperties_Data(), Table_SourceData_Poultry_DietProperties[[#Headers],[Nutrient analysis]], 0)} -> 0.15 | R13: {=Common_InputFunctions.Utility_DisplayArrayInTable(SourceData_Poultry.SourceData_Poultry_DietProperties_Data(), Table_SourceData_Poultry_DietProperties[[#Headers],[Nutrient analysis]], 0)} -> 0.18 | S13: {=Common_InputFunctions.Utility_DisplayArrayInTable(SourceData_Poultry.SourceData_Poultry_DietProperties_Data(), Table_SourceData_Poultry_DietProperties[[#Headers],[Nutrient analysis]], 0)} -> 0.15
A14: =HYPERLINK("#'Input - Fert Lime Chem'!A1", "Fertiliser, Lime & Chemicals") -> Fertiliser, Lime & Chemicals | D14: DMDjk | E14: dry matter digestibility for each class and subclass : fraction | G14: see Table_DMD_j_k
A15: =HYPERLINK("#'Input - Fuel & Energy'!A1", "Electricity and fuel") -> Electricity and fuel | D15: Aj | E15: ash content of manure for each class and subclass : fraction | G15: see Table_A_j
A16: Waste
A17: Freight and transport | D17: Table_I_j_k | O17: {=SourceData_Poultry.SourceData_Poultry_MethaneEmissionsPotential_Title()} -> Poultry - Methane emissions potential per class
A18: =HYPERLINK("#'Input - Other Farm Inputs'!A1", "Other farm inputs") -> Other farm inputs | D18: Dry matter intake | O18: {=SourceData_Poultry.SourceData_Poultry_MethaneEmissionsPotential_Source()} -> VEERG 2026: 4.6.2.3 CONSTANT: Poultry - Methane emissions potential per class
A19: =HYPERLINK("#'Input - Data quality'!A1", "Data quality") -> Data quality | D19: Layers | E19: Meat chicken growers | F19: Meat chicken breeders | G19: Other | O19: Poultry class | P19: B0
D20: ='Input - MMS - Poultry'!$E$10 -> 10 | E20: ='Input - MMS - Poultry'!$F$10 -> 10 | F20: ='Input - MMS - Poultry'!$G$10 -> 10 | G20: ='Input - MMS - Poultry'!$H$10 -> 10 | H20: kg/head/day | O20: {=Common_InputFunctions.Utility_DisplayArrayInTable(SourceData_Poultry.SourceData_Poultry_MethaneEmissionsPotential_Data(), Table_SourceData_Poultry_MethaneEmissionsPotential[[#Headers],[Poultry class]], 0)} -> Layers | P20: {=Common_InputFunctions.Utility_DisplayArrayInTable(SourceData_Poultry.SourceData_Poultry_MethaneEmissionsPotential_Data(), Table_SourceData_Poultry_MethaneEmissionsPotential[[#Headers],[Poultry class]], 0)} -> 0.39
A21: CALCULATIONS | O21: {=Common_InputFunctions.Utility_DisplayArrayInTable(SourceData_Poultry.SourceData_Poultry_MethaneEmissionsPotential_Data(), Table_SourceData_Poultry_MethaneEmissionsPotential[[#Headers],[Poultry class]], 0)} -> Meat chickens | P21: {=Common_InputFunctions.Utility_DisplayArrayInTable(SourceData_Poultry.SourceData_Poultry_MethaneEmissionsPotential_Data(), Table_SourceData_Poultry_MethaneEmissionsPotential[[#Headers],[Poultry class]], 0)} -> 0.36
A22: N2O MMS | D22: Table_DMD_j_k
A23: Enteric methane | D23: Dry matter digestibility
A24: =HYPERLINK("#'Calcs - Fert Lime'!A1", "Fertiliser & soil amendments") -> Fertiliser & soil amendments | D24: Layers | E24: Meat chicken growers | F24: Meat chicken breeders | G24: Other
A25: =HYPERLINK("#'Calcs - Residue mgmt - Crop'!A1", "Residue management - Crop") -> Residue management - Crop | D25: ='Input - MMS - Poultry'!$E$11 -> 0.1 | E25: ='Input - MMS - Poultry'!$F$11 -> 0.1 | F25: ='Input - MMS - Poultry'!$G$11 -> 0.1 | G25: ='Input - MMS - Poultry'!$H$11 -> 0.1 | H25: Fraction
A26: =HYPERLINK("#'Calcs - Residue mgmt - Pasture'!A1", "Residue management - Pasture") -> Residue management - Pasture | O26: Poultry manure management systems | R26: Poultry manure management systems - Stage 1 | U26: Poultry manure management systems - Stage 2
A27: =HYPERLINK("#'Calcs - Field burning'!A1", "Field burning - Crop") -> Field burning - Crop | D27: Table_A_j
A28: =HYPERLINK("#'Calcs - Fuel'!A1", "Fuel") -> Fuel | D28: Ash content of manure | O28: MMS | P28: Symbol and MMS | R28: MMS | S28: Symbol and MMS | U28: MMS | V28: Symbol and MMS
A29: =HYPERLINK("#'Calcs - Electricity'!A1", "Electricity") -> Electricity | D29: Layers | E29: Meat chicken growers | F29: Meat chicken breeders | G29: Other | O29: ='Constants - Livestock'!$E$21 -> Poultry manure with bedding | P29: ='Constants - Livestock'!$F$21 -> Poultry manure with bedding (m=10) | R29: ='Constants - Livestock'!$E$21 -> Poultry manure with bedding | S29: ='Constants - Livestock'!$F$21 -> Poultry manure with bedding (m=10) | U29: ='Constants - Livestock'!$E$15 -> Solid storage | V29: ='Constants - Livestock'!$F$15 -> Solid storage (m=4)
A30: =HYPERLINK("#'Calcs - Refrigerants'!A1", "Refrigerants") -> Refrigerants | D30: =$P$13 -> 0.18 | E30: =$Q$13 -> 0.15 | F30: =$R$13 -> 0.18 | G30: =$S$13 -> 0.15 | H30: Fraction | O30: ='Constants - Livestock'!$E$23 -> Belt manure removal | P30: ='Constants - Livestock'!$F$23 -> Belt manure removal (m=11a) | R30: ='Constants - Livestock'!$E$23 -> Belt manure removal | S30: ='Constants - Livestock'!$F$23 -> Belt manure removal (m=11a) | U30: ='Constants - Livestock'!$E$17 -> Composting (passive windrow) | V30: ='Constants - Livestock'!$F$17 -> Composting (passive windrow) (m=6)
A31: Waste | O31: ='Constants - Livestock'!$E$24 -> Manure stored in house | P31: ='Constants - Livestock'!$F$24 -> Manure stored in house (m=11b) | R31: ='Constants - Livestock'!$E$24 -> Manure stored in house | S31: ='Constants - Livestock'!$F$24 -> Manure stored in house (m=11b) | U31: ='Constants - Livestock'!$E$18 -> Digester / covered lagoons | V31: ='Constants - Livestock'!$F$18 -> Digester / covered lagoons (m=7)
A32: Freight and transport | D32: Table_VS_j_k | O32: ='Constants - Livestock'!$E$27 -> Pasture range and paddock | P32: ='Constants - Livestock'!$F$27 -> Pasture range and paddock (m=14) | R32: ='Constants - Livestock'!$E$27 -> Pasture range and paddock | S32: ='Constants - Livestock'!$F$27 -> Pasture range and paddock (m=14) | U32: ='Constants - Livestock'!$E$25 -> Direct processing | V32: ='Constants - Livestock'!$F$25 -> Direct processing (m=12)
A33: =HYPERLINK("#'Calcs - Scope 3'!A1", "Purchased goods scope 3") -> Purchased goods scope 3 | D33: Volatile solid production | O33: ='Constants - Livestock'!$E$15 -> Solid storage | P33: ='Constants - Livestock'!$F$15 -> Solid storage (m=4) | R33: No MMS | S33: No MMS | U33: ='Constants - Livestock'!$E$26 -> Direct application | V33: ='Constants - Livestock'!$F$26 -> Direct application (m=13)
D34: Layers | E34: Meat chicken growers | F34: Meat chicken breeders | G34: Other | O34: ='Constants - Livestock'!$E$17 -> Composting (passive windrow) | P34: ='Constants - Livestock'!$F$17 -> Composting (passive windrow) (m=6) | U34: No MMS | V34: No MMS
A35: APPENDICES | D35: {=ManureManagement_Poultry_Methane.VEERG_4_6_1_1__6_VolatileSolidProduction(D20,D25,D30)} -> 7.38 | E35: {=ManureManagement_Poultry_Methane.VEERG_4_6_1_1__6_VolatileSolidProduction(E20,E25,E30)} -> 7.65 | F35: {=ManureManagement_Poultry_Methane.VEERG_4_6_1_1__6_VolatileSolidProduction(F20,F25,F30)} -> 7.38 | G35: {=ManureManagement_Poultry_Methane.VEERG_4_6_1_1__6_VolatileSolidProduction(G20,G25,G30)} -> 7.65 | H35: =E11 -> kg/head/day | O35: ='Constants - Livestock'!$E$18 -> Digester / covered lagoons | P35: ='Constants - Livestock'!$F$18 -> Digester / covered lagoons (m=7)
A36: =HYPERLINK("#'Constants - Common'!A1", "Constants - Common") -> Constants - Common | O36: ='Constants - Livestock'!$E$25 -> Direct processing | P36: ='Constants - Livestock'!$F$25 -> Direct processing (m=12)
A37: =HYPERLINK("#'Constants - Cropping'!A1", "Constants - Cropping") -> Constants - Cropping | O37: ='Constants - Livestock'!$E$26 -> Direct application | P37: ='Constants - Livestock'!$F$26 -> Direct application (m=13)
A38: =HYPERLINK("#'Constants - Livestock'!A1", "Constants - Livestock") -> Constants - Livestock | O38: No MMS | P38: No MMS
A39: =HYPERLINK("#'Constants - Dairy'!A1", "Constants - Dairy") -> Constants - Dairy | D39: {=ManureManagement_Poultry_Methane.VEERG_4_6_1_1__3_Stage1MethaneProduction_Title()} -> Production of methane in treatment stage 1 MMS
A40: Sources & acknowledgements | D40: {=ManureManagement_Poultry_Methane.VEERG_4_6_1_1__3_Stage1MethaneProduction_Source()} -> VEERG 2026: 4.6.1.1, Equation (3)
D41: Function name | E41: {=Common_InputFunctions.Utility_DisplayFunctionName(F86)} -> =ManureManagement_Poultry_Methane.VEERG_4_6_1_1__3_Stage1MethaneProduction(D$35,D$59,F64,VLOOKUP($E86, $D$72:$E$80, 2, FALSE), $G$52)
...

Sheet Input - Herd - Swine
A1: #VALUE! | C1: Input - Herd - Swine
A3: Home
A4: =HYPERLINK("#'Results'!A1", "Results") -> Results
D5: Head count
A6: INPUTS
A7: =HYPERLINK("#'Input - Site'!A1", "Site") -> Site | E7: Boars | F7: Sows | G7: Gilts | H7: Suckers | I7: Weaners | J7: Growers | K7: Slaughter pigs
A8: =HYPERLINK("#'Input - Production'!A1", "Production and outputs") -> Production and outputs | D8: Month | E8: Dj=1 | F8: Dj=2 | G8: Dj=3 | H8: Dj=4 | I8: Dj=4 | J8: Dj=4 | K8: Dj=4
A9: =HYPERLINK("#'Input - Herd - Dairy'!A1", "Herd - Dairy") -> Herd - Dairy | D9: =TEXT('Input - Site'!$E$12,"mmmm yyyy") -> January 2024 | E9: 120 | F9: 220 | G9: 320 | H9: 420 | I9: 520 | J9: 620 | K9: 720 | L9: Head
A10: =HYPERLINK("#'Input - Feed - Dairy'!A1", "Purchased feed - Livestock") -> Purchased feed - Livestock | D10: =TEXT(EDATE('Input - Site'!$E$12, 1),"mmmm yyyy") -> February 2024 | E10: 120 | F10: 220 | G10: 320 | H10: 420 | I10: 520 | J10: 620 | K10: 720 | L10: Head
A11: =HYPERLINK("#'Input - Herd - Feedlot'!A1", "Herd - Feedlot") -> Herd - Feedlot | D11: =TEXT(EDATE('Input - Site'!$E$12, 2),"mmmm yyyy") -> March 2024 | E11: 130 | F11: 230 | G11: 330 | H11: 430 | I11: 530 | J11: 630 | K11: 730 | L11: Head
A12: =HYPERLINK("#'Input - Pasture'!A1", "Pasture") -> Pasture | D12: =TEXT(EDATE('Input - Site'!$E$12, 3),"mmmm yyyy") -> April 2024 | E12: 130 | F12: 230 | G12: 330 | H12: 430 | I12: 530 | J12: 630 | K12: 730 | L12: Head
A13: =HYPERLINK("#'Input - Grains'!A1", "Crop - Grains") -> Crop - Grains | D13: =TEXT(EDATE('Input - Site'!$E$12, 4),"mmmm yyyy") -> May 2024 | E13: 130 | F13: 230 | G13: 330 | H13: 430 | I13: 530 | J13: 630 | K13: 730 | L13: Head
A14: =HYPERLINK("#'Input - Fert Lime Chem'!A1", "Fertiliser, Lime & Chemicals") -> Fertiliser, Lime & Chemicals | D14: =TEXT(EDATE('Input - Site'!$E$12, 5),"mmmm yyyy") -> June 2024 | E14: 140 | F14: 240 | G14: 340 | H14: 440 | I14: 540 | J14: 640 | K14: 740 | L14: Head
A15: =HYPERLINK("#'Input - Fuel & Energy'!A1", "Electricity and fuel") -> Electricity and fuel | D15: =TEXT(EDATE('Input - Site'!$E$12, 6),"mmmm yyyy") -> July 2024 | E15: 140 | F15: 230 | G15: 340 | H15: 440 | I15: 540 | J15: 640 | K15: 740 | L15: Head
A16: Waste | D16: =TEXT(EDATE('Input - Site'!$E$12, 7),"mmmm yyyy") -> August 2024 | E16: 140 | F16: 240 | G16: 340 | H16: 440 | I16: 540 | J16: 640 | K16: 740 | L16: Head
A17: Freight and transport | D17: =TEXT(EDATE('Input - Site'!$E$12, 8),"mmmm yyyy") -> September 2024 | E17: 110 | F17: 210 | G17: 310 | H17: 410 | I17: 510 | J17: 610 | K17: 710 | L17: Head
A18: =HYPERLINK("#'Input - Other Farm Inputs'!A1", "Other farm inputs") -> Other farm inputs | D18: =TEXT(EDATE('Input - Site'!$E$12, 9),"mmmm yyyy") -> October 2024 | E18: 110 | F18: 210 | G18: 310 | H18: 410 | I18: 510 | J18: 610 | K18: 710 | L18: Head
A19: =HYPERLINK("#'Input - Data quality'!A1", "Data quality") -> Data quality | D19: =TEXT(EDATE('Input - Site'!$E$12, 10),"mmmm yyyy") -> November 2024 | E19: 110 | F19: 210 | G19: 310 | H19: 410 | I19: 510 | J19: 610 | K19: 710 | L19: Head
D20: =TEXT(EDATE('Input - Site'!$E$12, 11),"mmmm yyyy") -> December 2024 | E20: 120 | F20: 220 | G20: 320 | H20: 420 | I20: 520 | J20: 620 | K20: 720 | L20: Head
A21: CALCULATIONS
A22: N2O MMS
A23: Enteric methane | D23: Duration of stay
A24: =HYPERLINK("#'Calcs - Fert Lime'!A1", "Fertiliser & soil amendments") -> Fertiliser & soil amendments
A25: =HYPERLINK("#'Calcs - Residue mgmt - Crop'!A1", "Residue management - Crop") -> Residue management - Crop | E25: Boars | F25: Sows | G25: Gilts | H25: Suckers | I25: Weaners | J25: Growers | K25: Slaughter pigs
A26: =HYPERLINK("#'Calcs - Residue mgmt - Pasture'!A1", "Residue management - Pasture") -> Residue management - Pasture | D26: Month | E26: Dj=1 | F26: Dj=2 | G26: Dj=3 | H26: Dj=4 | I26: Dj=4 | J26: Dj=4 | K26: Dj=4
A27: =HYPERLINK("#'Calcs - Field burning'!A1", "Field burning - Crop") -> Field burning - Crop | D27: =TEXT('Input - Site'!$E$12,"mmmm yyyy") -> January 2024 | E27: =DAY(EOMONTH($D27, 0)) -> 31 | F27: =DAY(EOMONTH($D27, 0)) -> 31 | G27: =DAY(EOMONTH($D27, 0)) -> 31 | H27: =DAY(EOMONTH($D27, 0)) -> 31 | I27: =DAY(EOMONTH($D27, 0)) -> 31 | J27: =DAY(EOMONTH($D27, 0)) -> 31 | K27: =DAY(EOMONTH($D27, 0)) -> 31 | L27: Days
A28: =HYPERLINK("#'Calcs - Fuel'!A1", "Fuel") -> Fuel | D28: =TEXT(EDATE('Input - Site'!$E$12, 1),"mmmm yyyy") -> February 2024 | E28: =DAY(EOMONTH($D28, 0)) -> 29 | F28: =DAY(EOMONTH($D28, 0)) -> 29 | G28: =DAY(EOMONTH($D28, 0)) -> 29 | H28: =DAY(EOMONTH($D28, 0)) -> 29 | I28: =DAY(EOMONTH($D28, 0)) -> 29 | J28: =DAY(EOMONTH($D28, 0)) -> 29 | K28: =DAY(EOMONTH($D28, 0)) -> 29 | L28: Days
A29: =HYPERLINK("#'Calcs - Electricity'!A1", "Electricity") -> Electricity | D29: =TEXT(EDATE('Input - Site'!$E$12, 2),"mmmm yyyy") -> March 2024 | E29: =DAY(EOMONTH($D29, 0)) -> 31 | F29: =DAY(EOMONTH($D29, 0)) -> 31 | G29: =DAY(EOMONTH($D29, 0)) -> 31 | H29: =DAY(EOMONTH($D29, 0)) -> 31 | I29: =DAY(EOMONTH($D29, 0)) -> 31 | J29: =DAY(EOMONTH($D29, 0)) -> 31 | K29: =DAY(EOMONTH($D29, 0)) -> 31 | L29: Days
A30: =HYPERLINK("#'Calcs - Refrigerants'!A1", "Refrigerants") -> Refrigerants | D30: =TEXT(EDATE('Input - Site'!$E$12, 3),"mmmm yyyy") -> April 2024 | E30: =DAY(EOMONTH($D30, 0)) -> 30 | F30: =DAY(EOMONTH($D30, 0)) -> 30 | G30: =DAY(EOMONTH($D30, 0)) -> 30 | H30: =DAY(EOMONTH($D30, 0)) -> 30 | I30: =DAY(EOMONTH($D30, 0)) -> 30 | J30: =DAY(EOMONTH($D30, 0)) -> 30 | K30: =DAY(EOMONTH($D30, 0)) -> 30 | L30: Days
A31: Waste | D31: =TEXT(EDATE('Input - Site'!$E$12, 4),"mmmm yyyy") -> May 2024 | E31: =DAY(EOMONTH($D31, 0)) -> 31 | F31: =DAY(EOMONTH($D31, 0)) -> 31 | G31: =DAY(EOMONTH($D31, 0)) -> 31 | H31: =DAY(EOMONTH($D31, 0)) -> 31 | I31: =DAY(EOMONTH($D31, 0)) -> 31 | J31: =DAY(EOMONTH($D31, 0)) -> 31 | K31: =DAY(EOMONTH($D31, 0)) -> 31 | L31: Days
A32: Freight and transport | D32: =TEXT(EDATE('Input - Site'!$E$12, 5),"mmmm yyyy") -> June 2024 | E32: =DAY(EOMONTH($D32, 0)) -> 30 | F32: =DAY(EOMONTH($D32, 0)) -> 30 | G32: =DAY(EOMONTH($D32, 0)) -> 30 | H32: =DAY(EOMONTH($D32, 0)) -> 30 | I32: =DAY(EOMONTH($D32, 0)) -> 30 | J32: =DAY(EOMONTH($D32, 0)) -> 30 | K32: =DAY(EOMONTH($D32, 0)) -> 30 | L32: Days
A33: =HYPERLINK("#'Calcs - Scope 3'!A1", "Purchased goods scope 3") -> Purchased goods scope 3 | D33: =TEXT(EDATE('Input - Site'!$E$12, 6),"mmmm yyyy") -> July 2024 | E33: =DAY(EOMONTH($D33, 0)) -> 31 | F33: =DAY(EOMONTH($D33, 0)) -> 31 | G33: =DAY(EOMONTH($D33, 0)) -> 31 | H33: =DAY(EOMONTH($D33, 0)) -> 31 | I33: =DAY(EOMONTH($D33, 0)) -> 31 | J33: =DAY(EOMONTH($D33, 0)) -> 31 | K33: =DAY(EOMONTH($D33, 0)) -> 31 | L33: Days
D34: =TEXT(EDATE('Input - Site'!$E$12, 7),"mmmm yyyy") -> August 2024 | E34: =DAY(EOMONTH($D34, 0)) -> 31 | F34: =DAY(EOMONTH($D34, 0)) -> 31 | G34: =DAY(EOMONTH($D34, 0)) -> 31 | H34: =DAY(EOMONTH($D34, 0)) -> 31 | I34: =DAY(EOMONTH($D34, 0)) -> 31 | J34: =DAY(EOMONTH($D34, 0)) -> 31 | K34: =DAY(EOMONTH($D34, 0)) -> 31 | L34: Days
A35: APPENDICES | D35: =TEXT(EDATE('Input - Site'!$E$12, 8),"mmmm yyyy") -> September 2024 | E35: =DAY(EOMONTH($D35, 0)) -> 30 | F35: =DAY(EOMONTH($D35, 0)) -> 30 | G35: =DAY(EOMONTH($D35, 0)) -> 30 | H35: =DAY(EOMONTH($D35, 0)) -> 30 | I35: =DAY(EOMONTH($D35, 0)) -> 30 | J35: =DAY(EOMONTH($D35, 0)) -> 30 | K35: =DAY(EOMONTH($D35, 0)) -> 30 | L35: Days
A36: =HYPERLINK("#'Constants - Common'!A1", "Constants - Common") -> Constants - Common | D36: =TEXT(EDATE('Input - Site'!$E$12, 9),"mmmm yyyy") -> October 2024 | E36: =DAY(EOMONTH($D36, 0)) -> 31 | F36: =DAY(EOMONTH($D36, 0)) -> 31 | G36: =DAY(EOMONTH($D36, 0)) -> 31 | H36: =DAY(EOMONTH($D36, 0)) -> 31 | I36: =DAY(EOMONTH($D36, 0)) -> 31 | J36: =DAY(EOMONTH($D36, 0)) -> 31 | K36: =DAY(EOMONTH($D36, 0)) -> 31 | L36: Days
A37: =HYPERLINK("#'Constants - Cropping'!A1", "Constants - Cropping") -> Constants - Cropping | D37: =TEXT(EDATE('Input - Site'!$E$12, 10),"mmmm yyyy") -> November 2024 | E37: =DAY(EOMONTH($D37, 0)) -> 30 | F37: =DAY(EOMONTH($D37, 0)) -> 30 | G37: =DAY(EOMONTH($D37, 0)) -> 30 | H37: =DAY(EOMONTH($D37, 0)) -> 30 | I37: =DAY(EOMONTH($D37, 0)) -> 30 | J37: =DAY(EOMONTH($D37, 0)) -> 30 | K37: =DAY(EOMONTH($D37, 0)) -> 30 | L37: Days
