Workbook
Name AgResidue_Equations_FieldBurning.VEERG_6_4_1_1__1__MethaneEmissionsFromBurningOfCropResidues: _xlfn.LAMBDA(_xlpm.Mburnc,_xlpm.CCc,_xlpm.EFCH4,_xlpm.C_CH4, _xlpm.Mburnc * _xlpm.CCc * _xlpm.EFCH4 * _xlpm.C_CH4 * 10 ^ (-3))
Name AgResidue_Equations_FieldBurning.VEERG_6_4_1_1__1__MethaneEmissionsFromBurningOfCropResidues_FunctionName: _xlfn.LAMBDA("VEERG_6_4_1_1__1__MethaneEmissionsFromBurningOfCropResidues")
Name AgResidue_Equations_FieldBurning.VEERG_6_4_1_1__1__MethaneEmissionsFromBurningOfCropResidues_LatexEquation: _xlfn.LAMBDA("E_{CH4}=\sum_{c}(M_{burn,c}\times CC_{c}\times EF_{CH4}\times C_{CH4}\times 10^{-3})")
Name AgResidue_Equations_FieldBurning.VEERG_6_4_1_1__1__MethaneEmissionsFromBurningOfCropResidues_NIRReference: _xlfn.LAMBDA("")
Name AgResidue_Equations_FieldBurning.VEERG_6_4_1_1__1__MethaneEmissionsFromBurningOfCropResidues_Source: _xlfn.LAMBDA("VEERG 2026: 6.4.1.1, Equation (1)")
Name AgResidue_Equations_FieldBurning.VEERG_6_4_1_1__1__MethaneEmissionsFromBurningOfCropResidues_Title: _xlfn.LAMBDA("Methane emissions from the burning of crop residues")
Name AgResidue_Equations_FieldBurning.VEERG_6_4_1_1__1__MethaneEmissionsFromBurningOfCropResidues_Unit: _xlfn.LAMBDA("t CH4")
Name AgResidue_Equations_FieldBurning.VEERG_6_4_1_1__1__MethaneEmissionsFromBurningOfCropResidues_Variable: _xlfn.LAMBDA("ECH4")
Name AgResidue_Equations_FieldBurning.VEERG_6_4_1_1__2__NitrousOxideEmissionsFromBurningOfCropResidues: _xlfn.LAMBDA(_xlpm.Mburnc,_xlpm.NCAGc,_xlpm.EFN2O,_xlpm.CN2O, _xlpm.Mburnc * _xlpm.NCAGc * _xlpm.EFN2O * _xlpm.CN2O * 10 ^ (-3))
Name AgResidue_Equations_FieldBurning.VEERG_6_4_1_1__2__NitrousOxideEmissionsFromBurningOfCropResidues_FunctionName: _xlfn.LAMBDA("VEERG_6_4_1_1__2__NitrousOxideEmissionsFromBurningOfCropResidues")
Name AgResidue_Equations_FieldBurning.VEERG_6_4_1_1__2__NitrousOxideEmissionsFromBurningOfCropResidues_LatexEquation: _xlfn.LAMBDA("E_{N2O}=\sum_{c}(M_{burn,c}\times NC_{AGc}\times EF_{N2O}\times C_{N2O}\times 10^{-3})")
Name AgResidue_Equations_FieldBurning.VEERG_6_4_1_1__2__NitrousOxideEmissionsFromBurningOfCropResidues_NIRReference: _xlfn.LAMBDA("")
Name AgResidue_Equations_FieldBurning.VEERG_6_4_1_1__2__NitrousOxideEmissionsFromBurningOfCropResidues_Source: _xlfn.LAMBDA("VEERG 2026: 6.4.1.1, Equation (2)")
Name AgResidue_Equations_FieldBurning.VEERG_6_4_1_1__2__NitrousOxideEmissionsFromBurningOfCropResidues_Title: _xlfn.LAMBDA("Nitrous oxide emissions from the burning of crop residues")
Name AgResidue_Equations_FieldBurning.VEERG_6_4_1_1__2__NitrousOxideEmissionsFromBurningOfCropResidues_Unit: _xlfn.LAMBDA("t N2O")
Name AgResidue_Equations_FieldBurning.VEERG_6_4_1_1__2__NitrousOxideEmissionsFromBurningOfCropResidues_Variable: _xlfn.LAMBDA("EN2O")
Name AgResidue_Equations_FieldBurning.VEERG_6_4_1_1__3__MassOfCropResidueBurnt: _xlfn.LAMBDA(_xlpm.Pc,_xlpm.RAGc,_xlpm.Sc,_xlpm.DMc,_xlpm.Zc,_xlpm.Fc, _xlpm.Pc * _xlpm.RAGc * _xlpm.Sc * _xlpm.DMc * _xlpm.Zc * _xlpm.Fc)
Name AgResidue_Equations_FieldBurning.VEERG_6_4_1_1__3__MassOfCropResidueBurnt_FunctionName: _xlfn.LAMBDA("VEERG_6_4_1_1__3__MassOfCropResidueBurnt")
Name AgResidue_Equations_FieldBurning.VEERG_6_4_1_1__3__MassOfCropResidueBurnt_LatexEquation: _xlfn.LAMBDA("M_{burn,c}=P_{c}\times R_{AGc}\times S_{c}\times DM_{c}\times Z_{c}\times F_{c}")
Name AgResidue_Equations_FieldBurning.VEERG_6_4_1_1__3__MassOfCropResidueBurnt_NIRReference: _xlfn.LAMBDA("")
Name AgResidue_Equations_FieldBurning.VEERG_6_4_1_1__3__MassOfCropResidueBurnt_Source: _xlfn.LAMBDA("VEERG 2026: 6.4.1.1, Equation (3)")
Name AgResidue_Equations_FieldBurning.VEERG_6_4_1_1__3__MassOfCropResidueBurnt_Title: _xlfn.LAMBDA("Mass of residue of crop c burnt")
Name AgResidue_Equations_FieldBurning.VEERG_6_4_1_1__3__MassOfCropResidueBurnt_Unit: _xlfn.LAMBDA("kg")
Name AgResidue_Equations_FieldBurning.VEERG_6_4_1_1__3__MassOfCropResidueBurnt_Variable: _xlfn.LAMBDA("Mburnc")
Name AgResidues_Equations_CropResidues.VEERG_6_1_1_1__1__NitrousOxideEmissionsFromCropResidues: _xlfn.LAMBDA(_xlpm.Mc,_xlpm.EFNi,_xlpm.CgN2O, _xlpm.Mc * _xlpm.EFNi * _xlpm.CgN2O * 10 ^ (-3))
Name AgResidues_Equations_CropResidues.VEERG_6_1_1_1__1__NitrousOxideEmissionsFromCropResidues_FunctionName: _xlfn.LAMBDA("VEERG_6_1_1_1__1__NitrousOxideEmissionsFromCropResidues")
Name AgResidues_Equations_CropResidues.VEERG_6_1_1_1__1__NitrousOxideEmissionsFromCropResidues_LatexEquation: _xlfn.LAMBDA("E=\sum_{c}{M_{c}\times EF_{N}\times C_{g,N2O}\times 10^{-3}}")
Name AgResidues_Equations_CropResidues.VEERG_6_1_1_1__1__NitrousOxideEmissionsFromCropResidues_NIRReference: _xlfn.LAMBDA("")
Name AgResidues_Equations_CropResidues.VEERG_6_1_1_1__1__NitrousOxideEmissionsFromCropResidues_Source: _xlfn.LAMBDA("VEERG 2026: 6.1.1.1, Equation (1)")
Name AgResidues_Equations_CropResidues.VEERG_6_1_1_1__1__NitrousOxideEmissionsFromCropResidues_Title: _xlfn.LAMBDA("Nitrous oxide emissions from the return of crop residues across all crops c to the soil")
Name AgResidues_Equations_CropResidues.VEERG_6_1_1_1__1__NitrousOxideEmissionsFromCropResidues_Unit: _xlfn.LAMBDA("t N2O")
Name AgResidues_Equations_CropResidues.VEERG_6_1_1_1__1__NitrousOxideEmissionsFromCropResidues_Variable: _xlfn.LAMBDA("E")
Name AgResidues_Equations_CropResidues.VEERG_6_1_1_1__2__MassOfNitrogenInCropResidues_LatexEquation: _xlfn.LAMBDA("M_{c}=(P_{c}\times R_{AGc}\times(1-F_{c}-FFOD_{c})\times DM_{c}\times NC_{AGc})+(P_{c}\times R_{AGc}\times R_{BGc}\times DM_{c}\times NC_{BGc})")
Name AgResidues_Equations_CropResidues.VEERG_6_1_1_1__2__MassOfNitrogenInCropResidues_NIRReference: _xlfn.LAMBDA("")
Name AgResidues_Equations_CropResidues.VEERG_6_1_1_1__2__MassOfNitrogenInCropResidues_Source: _xlfn.LAMBDA("VEERG 2026: 6.1.1.1, Equation (2)")
Name AgResidues_Equations_CropResidues.VEERG_6_1_1_1__2__MassOfNitrogenInCropResidues_Title: _xlfn.LAMBDA("Mass of nitrogen in crop residues returned to the soil")
Name AgResidues_Equations_CropResidues.VEERG_6_1_1_1__2__MassOfNitrogenInCropResidues_Unit: _xlfn.LAMBDA("kg N")
Name AgResidues_Equations_CropResidues.VEERG_6_1_1_1__2__MassOfNitrogenInCropResidues_Variable: _xlfn.LAMBDA("Mc")
Name AgResidues_Equations_CropResidues.VEERG_6_1_1_2__1__FractionOfCropResidueRemovedBaled: _xlfn.LAMBDA(_xlpm.B,_xlpm.MB,_xlpm.Pc,_xlpm.RAGc, IFERROR((_xlpm.B * _xlpm.MB) / (_xlpm.Pc * _xlpm.RAGc), 0))
Name AgResidues_Equations_CropResidues.VEERG_6_1_1_2__1__FractionOfCropResidueRemovedBaled_LatexEquation: _xlfn.LAMBDA("FFOD_{c,baled}=\frac{B\times M_{B}}{P_{c}\times R_{AG,c}}")
Name AgResidues_Equations_CropResidues.VEERG_6_1_1_2__1__FractionOfCropResidueRemovedBaled_NIRReference: _xlfn.LAMBDA("")
Name AgResidues_Equations_CropResidues.VEERG_6_1_1_2__1__FractionOfCropResidueRemovedBaled_Source: _xlfn.LAMBDA("VEERG 2026: 6.1.1.2, Equation (1)")
Name AgResidues_Equations_CropResidues.VEERG_6_1_1_2__1__FractionOfCropResidueRemovedBaled_Title: _xlfn.LAMBDA("Fraction of crop residue that is removed for crop c, calculated where residues are baled")
Name AgResidues_Equations_CropResidues.VEERG_6_1_1_2__1__FractionOfCropResidueRemovedBaled_Unit: _xlfn.LAMBDA("dimensionless")
Name AgResidues_Equations_CropResidues.VEERG_6_1_1_2__1__FractionOfCropResidueRemovedBaled_Variable: _xlfn.LAMBDA("FFODcbaled")
Name AgResidues_Equations_CropResidues.VEERG_6_1_1_2__1__FractionOfCropResidueRemovedBaled_Variation: _xlfn.LAMBDA("VARIATION FROM SOURCE: Added 'baled' to variable subscript")
Name AgResidues_Equations_CropResidues.VEERG_6_1_1_2__1a__FractionOfCropResidueRemoved: _xlfn.LAMBDA(_xlpm.FFODcbaled,_xlpm.FFODcother, _xlpm.FFODcbaled + _xlpm.FFODcother)
Name AgResidues_Equations_CropResidues.VEERG_6_1_1_2__1a__FractionOfCropResidueRemoved_LatexEquation: _xlfn.LAMBDA("FFOD_{c} = FFOD_{c,baled} + FFOD_{c,other}")
Name AgResidues_Equations_CropResidues.VEERG_6_1_1_2__1a__FractionOfCropResidueRemoved_NIRReference: _xlfn.LAMBDA("")
Name AgResidues_Equations_CropResidues.VEERG_6_1_1_2__1a__FractionOfCropResidueRemoved_Source: _xlfn.LAMBDA("")
Name AgResidues_Equations_CropResidues.VEERG_6_1_1_2__1a__FractionOfCropResidueRemoved_Title: _xlfn.LAMBDA("Fraction of crop residue that is removed for crop c")
Name AgResidues_Equations_CropResidues.VEERG_6_1_1_2__1a__FractionOfCropResidueRemoved_Unit: _xlfn.LAMBDA("dimensionless")
Name AgResidues_Equations_CropResidues.VEERG_6_1_1_2__1a__FractionOfCropResidueRemoved_Variable: _xlfn.LAMBDA("FFODc")
Name AgResidues_Equations_CropResidues.VEERG_6_1_1_2__1a__FractionOfCropResidueRemoved_Variation: _xlfn.LAMBDA("VARIATION FROM SOURCE: Added this equation to accommodate user-defined residue removal other than baling.")
Name AgResidues_Equations_Leaching.VEERG_6_3_1_1__1__LeachingAndRunoffEmissionsCropAndPastureResidue: _xlfn.LAMBDA(_xlpm.Mleachcp,_xlpm.EFleach,_xlpm.CgN2O, _xlpm.Mleachcp * _xlpm.EFleach * _xlpm.CgN2O * 10 ^ (-3))
Name AgResidues_Equations_Leaching.VEERG_6_3_1_1__1__LeachingAndRunoffEmissionsCropAndPastureResidue_LatexEquation: _xlfn.LAMBDA("E_{N2O}=\sum_{c}\sum_{p}(M_{leach,cp}\times EF_{leach}\times Cg_{N2O}\times 10^{-3})")
Name AgResidues_Equations_Leaching.VEERG_6_3_1_1__1__LeachingAndRunoffEmissionsCropAndPastureResidue_NIRReference: _xlfn.LAMBDA("")
Name AgResidues_Equations_Leaching.VEERG_6_3_1_1__1__LeachingAndRunoffEmissionsCropAndPastureResidue_Source: _xlfn.LAMBDA("VEERG 2026: 6.3.1.1, Equation (1)")
Name AgResidues_Equations_Leaching.VEERG_6_3_1_1__1__LeachingAndRunoffEmissionsCropAndPastureResidue_Title: _xlfn.LAMBDA("Nitrous oxide leaching and runoff emissions from crop and pasture residues returned to the soil")
Name AgResidues_Equations_Leaching.VEERG_6_3_1_1__1__LeachingAndRunoffEmissionsCropAndPastureResidue_Unit: _xlfn.LAMBDA("t N2O")

Sheet Overview
C1: 13: Sope 3 emissions: Overview

Sheet Results
C1: 13: Sope 3 emissions: Results
D5: Emissions breakdown
D7: 💡 NOTE: When there is no Method 2, the Method 2 result are the same as Method 1
D9: Scope 1 source | E9: CO2-e emissions method 1 | F9: CO2-e emissions method 2
C10: {=Common_InputFunctions.Utility_ResultsItemFromEquationTitleAndSource('15 Scope 3'!D5,'15 Scope 3'!D6)} -> 15.1.1.1 Total emissions from purchased livestock | D10: {=HYPERLINK(Common_InputFunctions.Utility_SourceHyperlinkDifferentSheet('15 Scope 3'!D5), C10)} -> 15.1.1.1 Total emissions from purchased livestock | G10: t CO2e
D11: ='15 Scope 3'!D21 -> Beef cattle | E11: ='15 Scope 3'!E34 -> 1052.5 | F11: ='15 Scope 3'!E35 -> 1014.5 | G11: t CO2e
D12: ='15 Scope 3'!D38 -> Dairy cattle | E12: ='15 Scope 3'!E53 -> 441 | F12: ='15 Scope 3'!E54 -> 415.625 | G12: t CO2e
D13: ='15 Scope 3'!D57 -> Pigs | E13: ='15 Scope 3'!E72 -> 76.726 | F13: ='15 Scope 3'!E73 -> 73.38 | G13: t CO2e
D14: ='15 Scope 3'!D75 -> Poultry | E14: ='15 Scope 3'!E90 -> 0.3672 | F14: ='15 Scope 3'!E91 -> 0.3594 | G14: t CO2e
C15: {=Common_InputFunctions.Utility_ResultsItemFromEquationTitleAndSource('15 Scope 3'!D98,'15 Scope 3'!D99)} -> 15.2.1.1 Emissions from purchased feed | D15: {=HYPERLINK(Common_InputFunctions.Utility_SourceHyperlinkDifferentSheet('15 Scope 3'!D98), C15)} -> 15.2.1.1 Emissions from purchased feed | E15: ='15 Scope 3'!E144 -> 523.1968 | F15: ='15 Scope 3'!E145 -> 512.78 | G15: t CO2e
C16: {=Common_InputFunctions.Utility_ResultsItemFromEquationTitleAndSource('15 Scope 3'!D149,'15 Scope 3'!D150)} -> 15.3.1.1 Total emissions from purchased mineral supplements | D16: {=HYPERLINK(Common_InputFunctions.Utility_SourceHyperlinkDifferentSheet('15 Scope 3'!D149), C16)} -> 15.3.1.1 Total emissions from purchased mineral supplements | E16: ='15 Scope 3'!E166 -> 178.9 | F16: ='15 Scope 3'!E167 -> 160 | G16: t CO2e
D17: {=HYPERLINK('15 Scope 3'!D171, Common_InputFunctions.Utility_ResultsItemFromEquationTitleAndSource('15 Scope 3'!D186,'15 Scope 3'!D187))} -> 15.4.1.1 Emissions from purchased fertiliser | E17: ='15 Scope 3'!E251 -> 39.11947 | F17: ='15 Scope 3'!E252 -> 38.326092 | G17: t CO2e
D18: {=Common_InputFunctions.Utility_ResultsItemFromEquationTitleAndSource('15 Scope 3'!D256,'15 Scope 3'!D257)} -> 15.5.1.1 Total emissions from purchased agrichemicals | E18: ='15 Scope 3'!E283 -> 7.516 | F18: ='15 Scope 3'!E284 -> 7.496 | G18: t CO2e
D19: {=Common_InputFunctions.Utility_ResultsItemFromEquationTitleAndSource('15 Scope 3'!D288,'15 Scope 3'!D289)} -> 15.6.1.1 Embedded emissions for purchased lime | E19: ='15 Scope 3'!E316 -> 1.0376 | F19: ='15 Scope 3'!E317 -> 0.89 | G19: t CO2e
D20: {=Common_InputFunctions.Utility_ResultsItemFromEquationTitleAndSource('15 Scope 3'!D321,'15 Scope 3'!D322)} -> 15.7.1.1 Emissions of purchased services and contractor operations | E20: No data | F20: ='15 Scope 3'!E348 -> 42 | G20: t CO2e | H20: {=HYPERLINK(Common_InputFunctions.Utility_SourceHyperlinkDifferentSheet('15 Scope 3'!D149), "test")} -> test
D21: {=Common_InputFunctions.Utility_ResultsItemFromEquationTitleAndSource('15 Scope 3'!D352,'15 Scope 3'!D353)} -> 15.8.1.1 Embedded emissions from use of packaging materials | E21: ='15 Scope 3'!E378 -> 7.44 | F21: ='15 Scope 3'!E379 -> 6 | G21: t CO2e
D22: {=Common_InputFunctions.Utility_ResultsItemFromEquationTitleAndSource('15 Scope 3'!D383,'15 Scope 3'!D384)} -> 15.9.1.1 Embedded emissions from use of grow media products | E22: ='15 Scope 3'!E410 -> No data | F22: ='15 Scope 3'!E411 -> 40.2 | G22: t CO2e
D23: {=Common_InputFunctions.Utility_ResultsItemFromEquationTitleAndSource('15 Scope 3'!D415,'15 Scope 3'!D416)} -> 15.10 Other purchased goods and services generic estimate | G23: t CO2e
D24: ='15 Scope 3'!D427 -> Cleaning chemical purchases | E24: ='15 Scope 3'!E441 -> 0.5051 | F24: ='15 Scope 3'!E442 -> 2.73 | G24: t CO2e
D25: ='15 Scope 3'!D445 -> Pharmacy chemical purchases | E25: ='15 Scope 3'!E459 -> 0.015636 | F25: ='15 Scope 3'!E460 -> 0.0134 | G25: t CO2e
D26: ='15 Scope 3'!D463 -> Seed | E26: ='15 Scope 3'!E472 -> 0.8439 | F26: ='15 Scope 3'!E473 -> 0.7142 | G26: t CO2e
D27: ='15 Scope 3'!D476 -> Miscellaneous Inputs | E27: ='15 Scope 3'!E483 -> 2.9531 | F27: ='15 Scope 3'!E484 -> 0.08586 | G27: t CO2e
D28: ='15 Scope 3'!D487 -> Uncategorised products with no Method 1 EF data | E28: ='15 Scope 3'!E501 -> No data | F28: ='15 Scope 3'!E502 -> 4000 | G28: t CO2e
D29: {=Common_InputFunctions.Utility_ResultsItemFromEquationTitleAndSource('15 Scope 3'!D506,'15 Scope 3'!D507)} -> 15.11.1.1 Total upstream emissions from scope 1 fuel consumption | E29: ='15 Scope 3'!E518 -> 0.00262 | F29: =E29 -> 0.00262 | G29: t CO2e
D30: {=Common_InputFunctions.Utility_ResultsItemFromEquationTitleAndSource('15 Scope 3'!D521,'15 Scope 3'!D522)} -> 15.12.1.1 Scope 3 emissions from purchased electricity location based | E30: ='15 Scope 3'!E533 -> 0.03 | F30: =E30 -> 0.03 | G30: t CO2e
D31: {=Common_InputFunctions.Utility_ResultsItemFromEquationTitleAndSource('15 Scope 3'!D537,'15 Scope 3'!D538)} -> 15.12.1.2 Scope 3 emissions from purchased electricity market based | E31: ='15 Scope 3'!E555 -> 12.15 | F31: =E31 -> 12.15 | G31: t CO2e
D32: {=Common_InputFunctions.Utility_ResultsItemFromEquationTitleAndSource('15 Scope 3'!D559,'15 Scope 3'!D560)} -> 15.13.1.1 Emissions from manure sent off site applied to soils in another farming system or enterprise | E32: ='15 Scope 3'!E576 -> 3.7936643 | F32: =E32 -> 3.7936643 | G32: t CO2e
D33: {=Common_InputFunctions.Utility_ResultsItemFromEquationTitleAndSource('15 Scope 3'!D580,'15 Scope 3'!D581&",")} -> 15.13.1.3 Emissions from solid waste sent to a treatment facility | E33: ='15 Scope 3'!E586 -> 330.8421 | F33: =E33 -> 330.8421 | G33: t CO2e
D34: {=Common_InputFunctions.Utility_ResultsItemFromEquationTitleAndSource('15 Scope 3'!D590,'15 Scope 3'!D591)} -> 15.14.1.1 Embedded emissions from upstream freight | G34: t CO2e
D35: ='15 Scope 3'!D604 -> Incoming freight | E35: ='15 Scope 3'!E618 -> No data | F35: ='15 Scope 3'!E619 -> 5146700 | G35: t CO2e
D36: ='15 Scope 3'!D622 -> Outgoing freight | E36: ='15 Scope 3'!E636 -> No data | F36: ='15 Scope 3'!E637 -> 432640 | G36: t CO2e
D37: Total | E37: =SUM(E10:E36) -> 2678.9392 | F37: =SUM(F10:F36) -> 5586001.9 | G37: t CO2e

Sheet Input - Site
A1: #VALUE! | C1: Input - Site
A3: =HYPERLINK("#'Home'!A1", "Home") -> Home
A4: =HYPERLINK("#'Overview'!A1", "Overview") -> Overview
A5: =HYPERLINK("#'Results'!A1", "Results") -> Results | D5: Your business
A7: INPUTS | D7: Farm name | E7: Test Farms
A8: =HYPERLINK("#'Input - Electricity'!A1", "Electricity") -> Electricity | D8: Reporting entity name | E8: Test Farms Pty Ltd
A10: CALCULATIONS | D10: 💡An 'Emissions accounting period' is a 12 month period where the business can report on the emissions, and is typically the same as the business' financial accounting period.
A11: =HYPERLINK("#'14.1.1-2 Purchased electricity'!A1", "14.1.1-2 Purchased electricity") -> 14.1.1-2 Purchased electricity
D12: Emissions calculation period start date | E12: 45292 | F12: ← DD/MM/YYYY or DD Month YYYY
A13: APPENDICES | D13: Emissions calculation period end date | E13: =DATE(YEAR(E12)+1,MONTH(E12),DAY(E12))-1 -> 45657 | F13: ← Automatically calculated, 12 months after start date
A14: =HYPERLINK("#'Constants - Electricity'!A1", "Constants - Electricity") -> Constants - Electricity
A15: =HYPERLINK("#'Constants - Common'!A1", "Constants - Common") -> Constants - Common
D16: Location and climate
D18: Location information is used to reference some region and climate-specific emission factors
D19: Tip: Use the web-based GAF Location Helper tool to easily get region and climate information. You will need an internet connection to use the GAF Location Helper.
D21: State | E21: ACT | F21: ← Please select
D22: Region (ABS Statistical area level 4) if state is WA | E22: Western Australia - Outback (South) | F22: ← Please select
D23: Leaching zone | E23: NO - Not in leaching zone | F23: ← Please select
D24: Elevation | E24: 307.7 | F24: Meters
D25: Average temperature for reporting period | E25: 18 | F25: Degrees celsius
D26: Total rainfall for reporting period | E26: 599 | F26: Millimetres
D27: Potential evapotranspiration for reporting period | E27: 1326 | F27: Millimetres
D28: Number of frost days for reporting period | E28: 7 | F28: Days
D29: MAP:PET ratio | E29: =E26/E27 -> 0.45173454
D30: Rainfall zone | E30: =Common_InputFunctions.Utility_LookupItemFromMinMax(E26,Table_SourceData_RainfallZones[Min rainfall],Table_SourceData_RainfallZones[Max rainfall],Table_SourceData_RainfallZones[Rainfall Zone]) -> Low rainfall
D31: Climate zone | E31: =Common_InputFunctions.Utility_GetClimateZone(E25,E26,E28,E24,E29,Table_SourceData_ClimateZones[Min temp],Table_SourceData_ClimateZones[Max temp],Table_SourceData_ClimateZones[Min rainfall],Table_SourceData_ClimateZones[Max rainfall],Table_SourceData_ClimateZones[Min frost days],Table_SourceData_ClimateZones[Max frost days],Table_SourceData_ClimateZones[Min elevation],Table_SourceData_ClimateZones[Max elevation],Table_SourceData_ClimateZones[Min MAP:PET],Table_SourceData_ClimateZones[Max MAP:PET],Table_SourceData_ClimateZones[Climate zone]) -> Warm temperate dry
D32: Wet or dry climate zone | E32: =Common_InputFunctions.Utility_LookupValueInTable($E$31,Table_SourceData_WetDryZones[Climate zone],Table_SourceData_WetDryZones[Wet or Dry Zone]) -> Dry climate zone
D33: Temperature zone | E33: =Common_InputFunctions.Utility_LookupItemFromMinMax(E25,Table_SourceData_TemperatureZones[Min MAT],Table_SourceData_TemperatureZones[Max MAT],Table_SourceData_TemperatureZones[Temperature Zone]) -> Temperate

Sheet Input - Fuel
A1: #VALUE! | C1: Input - Fuel
A3: =HYPERLINK("#'Home'!A1", "Home") -> Home
A4: =HYPERLINK("#'Overview'!A1", "Overview") -> Overview
A5: =HYPERLINK("#'Results'!A1", "Results") -> Results | D5: Fuel purchases and consumption
A7: INPUTS | D7: A 'Metropolitan' location is:
A8: =HYPERLINK("#'Input - Fuel'!A1", "Fuel") -> Fuel | D8: ● On or east of the dividing range in NSW (including Canberra and Queanbeyan)
D9: ● In Melbourne, Brisbane, Adelaide or Perth
A10: CALCULATIONS
A11: =HYPERLINK("#'8.1.1.1-2 Transport fuel'!A1", "8.1.1.1-2 Transport fuel") -> 8.1.1.1-2 Transport fuel | D11: Is the property in a Metropolitan location? | E11: Metro | F11: ← Please select
A12: =HYPERLINK("#'8.2.1.1-2 Stationary fuel'!A1", "8.2.1.1-2 Stationary fuel") -> 8.2.1.1-2 Stationary fuel
A13: =HYPERLINK("#'8.X.1.1-2 General use fuel'!A1", "8.X.1.1-2 General use fuel") -> 8.X.1.1-2 General use fuel | D13: 💡 You can add more rows to the table by right-clicking on the table and selecting "Insert > Table rows above/below"
D14: 💡 'Percent consumed" is 100% by default. If you purchased more fuel than was consumed you can edit this field.
A15: APPENDICES
A16: =HYPERLINK("#'Constants - Fuel'!A1", "Constants - Fuel") -> Constants - Fuel | D16: Fuel use (select) | E16: Fuel type (select) | F16: Amount purchased | G16: Amount unit | H16: Percent consumed | I16: Amount consumed
A17: =HYPERLINK("#'Constants - Common'!A1", "Constants - Common") -> Constants - Common | D17: Power standalone machinery or heating | E17: Town gas in GJ | F17: 100 | G17: {=Common_InputFunctions.Utility_LookupValueInTable(Table_Input_Fuel[[#This Row],[Fuel type (select)]],Table_FuelTypes_Units[Fuel type], Table_FuelTypes_Units[Unit])} -> GJ | H17: =1 -> 1 | I17: =Table_Input_Fuel[[#This Row],[Amount purchased]]*Table_Input_Fuel[[#This Row],[Percent consumed]]*10^-3 -> 0.1
D18: Aviation | E18: Avgas | F18: 100 | G18: {=Common_InputFunctions.Utility_LookupValueInTable(Table_Input_Fuel[[#This Row],[Fuel type (select)]],Table_FuelTypes_Units[Fuel type], Table_FuelTypes_Units[Unit])} -> kL | H18: =1 -> 1 | I18: =Table_Input_Fuel[[#This Row],[Amount purchased]]*Table_Input_Fuel[[#This Row],[Percent consumed]]*10^-3 -> 0.1
D19: Vessels | E19: Diesel | F19: 100 | G19: {=Common_InputFunctions.Utility_LookupValueInTable(Table_Input_Fuel[[#This Row],[Fuel type (select)]],Table_FuelTypes_Units[Fuel type], Table_FuelTypes_Units[Unit])} -> kL | H19: =1 -> 1 | I19: =Table_Input_Fuel[[#This Row],[Amount purchased]]*Table_Input_Fuel[[#This Row],[Percent consumed]]*10^-3 -> 0.1
D20: Power standalone machinery or heating | E20: Town gas in GJ | F20: 100 | G20: {=Common_InputFunctions.Utility_LookupValueInTable(Table_Input_Fuel[[#This Row],[Fuel type (select)]],Table_FuelTypes_Units[Fuel type], Table_FuelTypes_Units[Unit])} -> GJ | H20: =1 -> 1 | I20: =Table_Input_Fuel[[#This Row],[Amount purchased]]*Table_Input_Fuel[[#This Row],[Percent consumed]]*10^-3 -> 0.1
D21: Cars and light commercial vehicles | E21: Diesel | F21: 100 | G21: {=Common_InputFunctions.Utility_LookupValueInTable(Table_Input_Fuel[[#This Row],[Fuel type (select)]],Table_FuelTypes_Units[Fuel type], Table_FuelTypes_Units[Unit])} -> kL | H21: =1 -> 1 | I21: =Table_Input_Fuel[[#This Row],[Amount purchased]]*Table_Input_Fuel[[#This Row],[Percent consumed]]*10^-3 -> 0.1

Sheet Input - Fertiliser
A1: #VALUE! | C1: Input - Fertiliser
A3: =HYPERLINK("#'Home'!A1", "Home") -> Home
A4: =HYPERLINK("#'Overview'!A1", "Overview") -> Overview
A5: =HYPERLINK("#'Results'!A1", "Results") -> Results
D6: Production system | E6: Crop | F6: ← Please select
A7: INPUTS | D7: Crop type | E7: Grains | F7: ← Please select
A8: =HYPERLINK("#'Input - Site'!A1", "Site") -> Site | D8: Irrigation method | E8: Drip irrigation | F8: ← Please select
A9: =HYPERLINK("#'Input - Fertiliser'!A1", "Fertiliser") -> Fertiliser | D9: Area under cropping | E9: 100 | F9: hectares
A11: CALCULATIONS | D11: Inorganic fertiliser applied
A12: =HYPERLINK("#'5.1.1.1-2 Inorganic Fert N2O'!A1", "5.1.1.1-2 Inorganic Fert N2O") -> 5.1.1.1-2 Inorganic Fert N2O
A13: =HYPERLINK("#'5.1.1.3-4 Inorganic fert CO2'!A1", "5.1.1.3-4 Inorganic fert CO2") -> 5.1.1.3-4 Inorganic fert CO2 | D13: 💡You can add more rows to tables by right-clicking on the table and selecting "Insert > Table rows above/below".
A14: =HYPERLINK("#'5.2.1.1-2 Organic Fert N2O'!A1", "5.2.1.1-2 Organic Fert N2O") -> 5.2.1.1-2 Organic Fert N2O | D14: 💡The application area is the same as the area under pasture / cropping by default. You can edit it if the application area is different.
A15: =HYPERLINK("#'5.3.1.1-2 Lime CO2'!A1", "5.3.1.1-2 Lime CO2") -> 5.3.1.1-2 Lime CO2
A16: =HYPERLINK("#'5.4.1.1-4 Atmos deposition'!A1", "5.4.1.1-4 Atmos deposition") -> 5.4.1.1-4 Atmos deposition | D16: Branded fertiliser products
A17: =HYPERLINK("#'5.5.1.1-2 Leaching and runoff'!A1", "5.5.1.1-2 Leaching and runoff") -> 5.5.1.1-2 Leaching and runoff | D17: Product (select) | E17: Amount applied per hectare | F17: Application unit | G17: Density | H17: Application area (ha) | I17: Total applied (kg) | J17: Ingredient 1 | K17: Ingredient 1 percent | L17: Ingredient 2 | M17: Ingredient 2 percent | N17: Ingredient 3 | O17: Ingredient 3 percent | P17: Ingredient 4 | Q17: Ingredient 4 percent | R17: Ingredient 5 | S17: Ingredient 5 percent | T17: Ingredient 6 | U17: Ingredient 6 percent | V17: N application rate (kg/ha) | W17: Urea source | X17: Ammonia source
D18: CoRoN 12-0-10 | E18: 100 | F18: =_xlfn.XLOOKUP(Table_Input_InorganicFertiliser_Brands[[#This Row],[Product (select)]],FertiliserProducts[Product name],FertiliserProducts[Unit]) -> L | G18: =_xlfn.XLOOKUP(Table_Input_InorganicFertiliser_Brands[[#This Row],[Product (select)]],FertiliserProducts[Product name],FertiliserProducts[Density / gravity]) -> 1.215 | H18: =$E$9 -> 100 | I18: =(Table_Input_InorganicFertiliser_Brands[[#This Row],[Amount applied per hectare]]*Table_Input_InorganicFertiliser_Brands[[#This Row],[Density]])*Table_Input_InorganicFertiliser_Brands[[#This Row],[Application area (ha)]] -> 12150 | J18: {=Fertiliser_InputFunctions.Fertiliser_FertiliserProductLookup(Table_Input_InorganicFertiliser_Brands[[#This Row],[Product (select)]], Table_Input_InorganicFertiliser_Brands[[#Headers],[Ingredient 1]], FertiliserProducts[#Data], FertiliserProducts[Product name], FertiliserProducts[#Headers])} -> Urea | K18: {=Fertiliser_InputFunctions.Fertiliser_FertiliserProductLookup(Table_Input_InorganicFertiliser_Brands[[#This Row],[Product (select)]], Table_Input_InorganicFertiliser_Brands[[#Headers],[Ingredient 1 percent]], FertiliserProducts[#Data], FertiliserProducts[Product name], FertiliserProducts[#Headers])} -> 0.19565217 | L18: {=Fertiliser_InputFunctions.Fertiliser_FertiliserProductLookup(Table_Input_InorganicFertiliser_Brands[[#This Row],[Product (select)]], Table_Input_InorganicFertiliser_Brands[[#Headers],[Ingredient 2]], FertiliserProducts[#Data], FertiliserProducts[Product name], FertiliserProducts[#Headers])} -> Potassium - Generic | M18: {=Fertiliser_InputFunctions.Fertiliser_FertiliserProductLookup(Table_Input_InorganicFertiliser_Brands[[#This Row],[Product (select)]], Table_Input_InorganicFertiliser_Brands[[#Headers],[Ingredient 2 percent]], FertiliserProducts[#Data], FertiliserProducts[Product name], FertiliserProducts[#Headers])} -> 0.1 | N18: {=Fertiliser_InputFunctions.Fertiliser_FertiliserProductLookup(Table_Input_InorganicFertiliser_Brands[[#This Row],[Product (select)]], Table_Input_InorganicFertiliser_Brands[[#Headers],[Ingredient 3]], FertiliserProducts[#Data], FertiliserProducts[Product name], FertiliserProducts[#Headers])} -> Nitrogen - Generic | O18: {=Fertiliser_InputFunctions.Fertiliser_FertiliserProductLookup(Table_Input_InorganicFertiliser_Brands[[#This Row],[Product (select)]], Table_Input_InorganicFertiliser_Brands[[#Headers],[Ingredient 3 percent]], FertiliserProducts[#Data], FertiliserProducts[Product name], FertiliserProducts[#Headers])} -> 0.03 | P18: {=Fertiliser_InputFunctions.Fertiliser_FertiliserProductLookup(Table_Input_InorganicFertiliser_Brands[[#This Row],[Product (select)]], Table_Input_InorganicFertiliser_Brands[[#Headers],[Ingredient 4]], FertiliserProducts[#Data], FertiliserProducts[Product name], FertiliserProducts[#Headers])} -> Boron | Q18: {=Fertiliser_InputFunctions.Fertiliser_FertiliserProductLookup(Table_Input_InorganicFertiliser_Brands[[#This Row],[Product (select)]], Table_Input_InorganicFertiliser_Brands[[#Headers],[Ingredient 4 percent]], FertiliserProducts[#Data], FertiliserProducts[Product name], FertiliserProducts[#Headers])} -> 0.005 | R18: {=Fertiliser_InputFunctions.Fertiliser_FertiliserProductLookup(Table_Input_InorganicFertiliser_Brands[[#This Row],[Product (select)]], Table_Input_InorganicFertiliser_Brands[[#Headers],[Ingredient 5]], FertiliserProducts[#Data], FertiliserProducts[Product name], FertiliserProducts[#Headers])} -> 0 | S18: {=Fertiliser_InputFunctions.Fertiliser_FertiliserProductLookup(Table_Input_InorganicFertiliser_Brands[[#This Row],[Product (select)]], Table_Input_InorganicFertiliser_Brands[[#Headers],[Ingredient 5 percent]], FertiliserProducts[#Data], FertiliserProducts[Product name], FertiliserProducts[#Headers])} -> 0 | T18: {=Fertiliser_InputFunctions.Fertiliser_FertiliserProductLookup(Table_Input_InorganicFertiliser_Brands[[#This Row],[Product (select)]], Table_Input_InorganicFertiliser_Brands[[#Headers],[Ingredient 6]], FertiliserProducts[#Data], FertiliserProducts[Product name], FertiliserProducts[#Headers])} -> 0 | U18: {=Fertiliser_InputFunctions.Fertiliser_FertiliserProductLookup(Table_Input_InorganicFertiliser_Brands[[#This Row],[Product (select)]], Table_Input_InorganicFertiliser_Brands[[#Headers],[Ingredient 6 percent]], FertiliserProducts[#Data], FertiliserProducts[Product name], FertiliserProducts[#Headers])} -> 0 | V18: =(Table_Input_InorganicFertiliser_Brands[[#This Row],[Amount applied per hectare]]*Table_Input_InorganicFertiliser_Brands[[#This Row],[Density]])*(IFERROR((_xlfn.XLOOKUP(Table_Input_InorganicFertiliser_Brands[[#This Row],[Ingredient 1]], Table_Fertiliser_ChemicalCompounds[Fertiliser type f],Table_Fertiliser_ChemicalCompounds[FNinorganic f])*Table_Input_InorganicFertiliser_Brands[[#This Row],[Ingredient 1 percent]]), 0)+ IFERROR((_xlfn.XLOOKUP(Table_Input_InorganicFertiliser_Brands[[#This Row],[Ingredient 2]],Table_Fertiliser_ChemicalCompounds[Fertiliser type f],Table_Fertiliser_ChemicalCompounds[FNinorganic f])*Table_Input_InorganicFertiliser_Brands[[#This Row],[Ingredient 2 percent]]), 0)+ IFERROR((_xlfn.XLOOKUP(Table_Input_InorganicFertiliser_Brands[[#This Row],[Ingredient 3]],Table_Fertiliser_ChemicalCompounds[Fertiliser type f],Table_Fertiliser_ChemicalCompounds[FNinorganic f])*Table_Input_InorganicFertiliser_Brands[[#This Row],[Ingredient 3 percent]]), 0)+ IFERROR((_xlfn.XLOOKUP(Table_Input_InorganicFertiliser_Brands[[#This Row],[Ingredient 4]],Table_Fertiliser_ChemicalCompounds[Fertiliser type f],Table_Fertiliser_ChemicalCompounds[FNinorganic f])*Table_Input_InorganicFertiliser_Brands[[#This Row],[Ingredient 4 percent]]), 0)+ IFERROR((_xlfn.XLOOKUP(Table_Input_InorganicFertiliser_Brands[[#This Row],[Ingredient 5]],Table_Fertiliser_ChemicalCompounds[Fertiliser type f],Table_Fertiliser_ChemicalCompounds[FNinorganic f])*Table_Input_InorganicFertiliser_Brands[[#This Row],[Ingredient 5 percent]]), 0)+ IFERROR((_xlfn.XLOOKUP(Table_Input_InorganicFertiliser_Brands[[#This Row],[Ingredient 6]],Table_Fertiliser_ChemicalCompounds[Fertiliser type f],Table_Fertiliser_ChemicalCompounds[FNinorganic f])*Table_Input_InorganicFertiliser_Brands[[#This Row],[Ingredient 6 percent]]), 0)) -> 14.58 | W18: =_xlfn.XLOOKUP(Table_Input_InorganicFertiliser_Brands[[#This Row],[Product (select)]],FertiliserProducts[Product name],FertiliserProducts[Urea source]) -> 0 | X18: =_xlfn.XLOOKUP(Table_Input_InorganicFertiliser_Brands[[#This Row],[Product (select)]],FertiliserProducts[Product name],FertiliserProducts[Ammonia source]) -> 0
A19: APPENDICES | D19: Boost-It | E19: 200 | F19: =_xlfn.XLOOKUP(Table_Input_InorganicFertiliser_Brands[[#This Row],[Product (select)]],FertiliserProducts[Product name],FertiliserProducts[Unit]) -> kg | G19: =_xlfn.XLOOKUP(Table_Input_InorganicFertiliser_Brands[[#This Row],[Product (select)]],FertiliserProducts[Product name],FertiliserProducts[Density / gravity]) -> 1 | H19: =$E$9 -> 100 | I19: =(Table_Input_InorganicFertiliser_Brands[[#This Row],[Amount applied per hectare]]*Table_Input_InorganicFertiliser_Brands[[#This Row],[Density]])*Table_Input_InorganicFertiliser_Brands[[#This Row],[Application area (ha)]] -> 20000 | J19: {=Fertiliser_InputFunctions.Fertiliser_FertiliserProductLookup(Table_Input_InorganicFertiliser_Brands[[#This Row],[Product (select)]], Table_Input_InorganicFertiliser_Brands[[#Headers],[Ingredient 1]], FertiliserProducts[#Data], FertiliserProducts[Product name], FertiliserProducts[#Headers])} -> Urea | K19: {=Fertiliser_InputFunctions.Fertiliser_FertiliserProductLookup(Table_Input_InorganicFertiliser_Brands[[#This Row],[Product (select)]], Table_Input_InorganicFertiliser_Brands[[#Headers],[Ingredient 1 percent]], FertiliserProducts[#Data], FertiliserProducts[Product name], FertiliserProducts[#Headers])} -> 0.52173913 | L19: {=Fertiliser_InputFunctions.Fertiliser_FertiliserProductLookup(Table_Input_InorganicFertiliser_Brands[[#This Row],[Product (select)]], Table_Input_InorganicFertiliser_Brands[[#Headers],[Ingredient 2]], FertiliserProducts[#Data], FertiliserProducts[Product name], FertiliserProducts[#Headers])} -> Potassium - Generic | M19: {=Fertiliser_InputFunctions.Fertiliser_FertiliserProductLookup(Table_Input_InorganicFertiliser_Brands[[#This Row],[Product (select)]], Table_Input_InorganicFertiliser_Brands[[#Headers],[Ingredient 2 percent]], FertiliserProducts[#Data], FertiliserProducts[Product name], FertiliserProducts[#Headers])} -> 0.08 | N19: {=Fertiliser_InputFunctions.Fertiliser_FertiliserProductLookup(Table_Input_InorganicFertiliser_Brands[[#This Row],[Product (select)]], Table_Input_InorganicFertiliser_Brands[[#Headers],[Ingredient 3]], FertiliserProducts[#Data], FertiliserProducts[Product name], FertiliserProducts[#Headers])} -> Sulfur - Generic | O19: {=Fertiliser_InputFunctions.Fertiliser_FertiliserProductLookup(Table_Input_InorganicFertiliser_Brands[[#This Row],[Product (select)]], Table_Input_InorganicFertiliser_Brands[[#Headers],[Ingredient 3 percent]], FertiliserProducts[#Data], FertiliserProducts[Product name], FertiliserProducts[#Headers])} -> 0.053 | P19: {=Fertiliser_InputFunctions.Fertiliser_FertiliserProductLookup(Table_Input_InorganicFertiliser_Brands[[#This Row],[Product (select)]], Table_Input_InorganicFertiliser_Brands[[#Headers],[Ingredient 4]], FertiliserProducts[#Data], FertiliserProducts[Product name], FertiliserProducts[#Headers])} -> Phosphorus - Generic | Q19: {=Fertiliser_InputFunctions.Fertiliser_FertiliserProductLookup(Table_Input_InorganicFertiliser_Brands[[#This Row],[Product (select)]], Table_Input_InorganicFertiliser_Brands[[#Headers],[Ingredient 4 percent]], FertiliserProducts[#Data], FertiliserProducts[Product name], FertiliserProducts[#Headers])} -> 0.052 | R19: {=Fertiliser_InputFunctions.Fertiliser_FertiliserProductLookup(Table_Input_InorganicFertiliser_Brands[[#This Row],[Product (select)]], Table_Input_InorganicFertiliser_Brands[[#Headers],[Ingredient 5]], FertiliserProducts[#Data], FertiliserProducts[Product name], FertiliserProducts[#Headers])} -> Magnesium | S19: {=Fertiliser_InputFunctions.Fertiliser_FertiliserProductLookup(Table_Input_InorganicFertiliser_Brands[[#This Row],[Product (select)]], Table_Input_InorganicFertiliser_Brands[[#Headers],[Ingredient 5 percent]], FertiliserProducts[#Data], FertiliserProducts[Product name], FertiliserProducts[#Headers])} -> 0.013 | T19: {=Fertiliser_InputFunctions.Fertiliser_FertiliserProductLookup(Table_Input_InorganicFertiliser_Brands[[#This Row],[Product (select)]], Table_Input_InorganicFertiliser_Brands[[#Headers],[Ingredient 6]], FertiliserProducts[#Data], FertiliserProducts[Product name], FertiliserProducts[#Headers])} -> Zinc | U19: {=Fertiliser_InputFunctions.Fertiliser_FertiliserProductLookup(Table_Input_InorganicFertiliser_Brands[[#This Row],[Product (select)]], Table_Input_InorganicFertiliser_Brands[[#Headers],[Ingredient 6 percent]], FertiliserProducts[#Data], FertiliserProducts[Product name], FertiliserProducts[#Headers])} -> 0.002 | V19: =(Table_Input_InorganicFertiliser_Brands[[#This Row],[Amount applied per hectare]]*Table_Input_InorganicFertiliser_Brands[[#This Row],[Density]])*(IFERROR((_xlfn.XLOOKUP(Table_Input_InorganicFertiliser_Brands[[#This Row],[Ingredient 1]], Table_Fertiliser_ChemicalCompounds[Fertiliser type f],Table_Fertiliser_ChemicalCompounds[FNinorganic f])*Table_Input_InorganicFertiliser_Brands[[#This Row],[Ingredient 1 percent]]), 0)+ IFERROR((_xlfn.XLOOKUP(Table_Input_InorganicFertiliser_Brands[[#This Row],[Ingredient 2]],Table_Fertiliser_ChemicalCompounds[Fertiliser type f],Table_Fertiliser_ChemicalCompounds[FNinorganic f])*Table_Input_InorganicFertiliser_Brands[[#This Row],[Ingredient 2 percent]]), 0)+ IFERROR((_xlfn.XLOOKUP(Table_Input_InorganicFertiliser_Brands[[#This Row],[Ingredient 3]],Table_Fertiliser_ChemicalCompounds[Fertiliser type f],Table_Fertiliser_ChemicalCompounds[FNinorganic f])*Table_Input_InorganicFertiliser_Brands[[#This Row],[Ingredient 3 percent]]), 0)+ IFERROR((_xlfn.XLOOKUP(Table_Input_InorganicFertiliser_Brands[[#This Row],[Ingredient 4]],Table_Fertiliser_ChemicalCompounds[Fertiliser type f],Table_Fertiliser_ChemicalCompounds[FNinorganic f])*Table_Input_InorganicFertiliser_Brands[[#This Row],[Ingredient 4 percent]]), 0)+ IFERROR((_xlfn.XLOOKUP(Table_Input_InorganicFertiliser_Brands[[#This Row],[Ingredient 5]],Table_Fertiliser_ChemicalCompounds[Fertiliser type f],Table_Fertiliser_ChemicalCompounds[FNinorganic f])*Table_Input_InorganicFertiliser_Brands[[#This Row],[Ingredient 5 percent]]), 0)+ IFERROR((_xlfn.XLOOKUP(Table_Input_InorganicFertiliser_Brands[[#This Row],[Ingredient 6]],Table_Fertiliser_ChemicalCompounds[Fertiliser type f],Table_Fertiliser_ChemicalCompounds[FNinorganic f])*Table_Input_InorganicFertiliser_Brands[[#This Row],[Ingredient 6 percent]]), 0)) -> 48 | W19: =_xlfn.XLOOKUP(Table_Input_InorganicFertiliser_Brands[[#This Row],[Product (select)]],FertiliserProducts[Product name],FertiliserProducts[Urea source]) -> 0 | X19: =_xlfn.XLOOKUP(Table_Input_InorganicFertiliser_Brands[[#This Row],[Product (select)]],FertiliserProducts[Product name],FertiliserProducts[Ammonia source]) -> 0
A20: =HYPERLINK("#'Constants - Fertiliser'!A1", "Constants - Fertiliser") -> Constants - Fertiliser | D20: CoRoN 12-0-10 | E20: 100 | F20: =_xlfn.XLOOKUP(Table_Input_InorganicFertiliser_Brands[[#This Row],[Product (select)]],FertiliserProducts[Product name],FertiliserProducts[Unit]) -> L | G20: =_xlfn.XLOOKUP(Table_Input_InorganicFertiliser_Brands[[#This Row],[Product (select)]],FertiliserProducts[Product name],FertiliserProducts[Density / gravity]) -> 1.215 | H20: =$E$9 -> 100 | I20: =(Table_Input_InorganicFertiliser_Brands[[#This Row],[Amount applied per hectare]]*Table_Input_InorganicFertiliser_Brands[[#This Row],[Density]])*Table_Input_InorganicFertiliser_Brands[[#This Row],[Application area (ha)]] -> 12150 | J20: {=Fertiliser_InputFunctions.Fertiliser_FertiliserProductLookup(Table_Input_InorganicFertiliser_Brands[[#This Row],[Product (select)]], Table_Input_InorganicFertiliser_Brands[[#Headers],[Ingredient 1]], FertiliserProducts[#Data], FertiliserProducts[Product name], FertiliserProducts[#Headers])} -> Urea | K20: {=Fertiliser_InputFunctions.Fertiliser_FertiliserProductLookup(Table_Input_InorganicFertiliser_Brands[[#This Row],[Product (select)]], Table_Input_InorganicFertiliser_Brands[[#Headers],[Ingredient 1 percent]], FertiliserProducts[#Data], FertiliserProducts[Product name], FertiliserProducts[#Headers])} -> 0.19565217 | L20: {=Fertiliser_InputFunctions.Fertiliser_FertiliserProductLookup(Table_Input_InorganicFertiliser_Brands[[#This Row],[Product (select)]], Table_Input_InorganicFertiliser_Brands[[#Headers],[Ingredient 2]], FertiliserProducts[#Data], FertiliserProducts[Product name], FertiliserProducts[#Headers])} -> Potassium - Generic | M20: {=Fertiliser_InputFunctions.Fertiliser_FertiliserProductLookup(Table_Input_InorganicFertiliser_Brands[[#This Row],[Product (select)]], Table_Input_InorganicFertiliser_Brands[[#Headers],[Ingredient 2 percent]], FertiliserProducts[#Data], FertiliserProducts[Product name], FertiliserProducts[#Headers])} -> 0.1 | N20: {=Fertiliser_InputFunctions.Fertiliser_FertiliserProductLookup(Table_Input_InorganicFertiliser_Brands[[#This Row],[Product (select)]], Table_Input_InorganicFertiliser_Brands[[#Headers],[Ingredient 3]], FertiliserProducts[#Data], FertiliserProducts[Product name], FertiliserProducts[#Headers])} -> Nitrogen - Generic | O20: {=Fertiliser_InputFunctions.Fertiliser_FertiliserProductLookup(Table_Input_InorganicFertiliser_Brands[[#This Row],[Product (select)]], Table_Input_InorganicFertiliser_Brands[[#Headers],[Ingredient 3 percent]], FertiliserProducts[#Data], FertiliserProducts[Product name], FertiliserProducts[#Headers])} -> 0.03 | P20: {=Fertiliser_InputFunctions.Fertiliser_FertiliserProductLookup(Table_Input_InorganicFertiliser_Brands[[#This Row],[Product (select)]], Table_Input_InorganicFertiliser_Brands[[#Headers],[Ingredient 4]], FertiliserProducts[#Data], FertiliserProducts[Product name], FertiliserProducts[#Headers])} -> Boron | Q20: {=Fertiliser_InputFunctions.Fertiliser_FertiliserProductLookup(Table_Input_InorganicFertiliser_Brands[[#This Row],[Product (select)]], Table_Input_InorganicFertiliser_Brands[[#Headers],[Ingredient 4 percent]], FertiliserProducts[#Data], FertiliserProducts[Product name], FertiliserProducts[#Headers])} -> 0.005 | R20: {=Fertiliser_InputFunctions.Fertiliser_FertiliserProductLookup(Table_Input_InorganicFertiliser_Brands[[#This Row],[Product (select)]], Table_Input_InorganicFertiliser_Brands[[#Headers],[Ingredient 5]], FertiliserProducts[#Data], FertiliserProducts[Product name], FertiliserProducts[#Headers])} -> 0 | S20: {=Fertiliser_InputFunctions.Fertiliser_FertiliserProductLookup(Table_Input_InorganicFertiliser_Brands[[#This Row],[Product (select)]], Table_Input_InorganicFertiliser_Brands[[#Headers],[Ingredient 5 percent]], FertiliserProducts[#Data], FertiliserProducts[Product name], FertiliserProducts[#Headers])} -> 0 | T20: {=Fertiliser_InputFunctions.Fertiliser_FertiliserProductLookup(Table_Input_InorganicFertiliser_Brands[[#This Row],[Product (select)]], Table_Input_InorganicFertiliser_Brands[[#Headers],[Ingredient 6]], FertiliserProducts[#Data], FertiliserProducts[Product name], FertiliserProducts[#Headers])} -> 0 | U20: {=Fertiliser_InputFunctions.Fertiliser_FertiliserProductLookup(Table_Input_InorganicFertiliser_Brands[[#This Row],[Product (select)]], Table_Input_InorganicFertiliser_Brands[[#Headers],[Ingredient 6 percent]], FertiliserProducts[#Data], FertiliserProducts[Product name], FertiliserProducts[#Headers])} -> 0 | V20: =(Table_Input_InorganicFertiliser_Brands[[#This Row],[Amount applied per hectare]]*Table_Input_InorganicFertiliser_Brands[[#This Row],[Density]])*(IFERROR((_xlfn.XLOOKUP(Table_Input_InorganicFertiliser_Brands[[#This Row],[Ingredient 1]], Table_Fertiliser_ChemicalCompounds[Fertiliser type f],Table_Fertiliser_ChemicalCompounds[FNinorganic f])*Table_Input_InorganicFertiliser_Brands[[#This Row],[Ingredient 1 percent]]), 0)+ IFERROR((_xlfn.XLOOKUP(Table_Input_InorganicFertiliser_Brands[[#This Row],[Ingredient 2]],Table_Fertiliser_ChemicalCompounds[Fertiliser type f],Table_Fertiliser_ChemicalCompounds[FNinorganic f])*Table_Input_InorganicFertiliser_Brands[[#This Row],[Ingredient 2 percent]]), 0)+ IFERROR((_xlfn.XLOOKUP(Table_Input_InorganicFertiliser_Brands[[#This Row],[Ingredient 3]],Table_Fertiliser_ChemicalCompounds[Fertiliser type f],Table_Fertiliser_ChemicalCompounds[FNinorganic f])*Table_Input_InorganicFertiliser_Brands[[#This Row],[Ingredient 3 percent]]), 0)+ IFERROR((_xlfn.XLOOKUP(Table_Input_InorganicFertiliser_Brands[[#This Row],[Ingredient 4]],Table_Fertiliser_ChemicalCompounds[Fertiliser type f],Table_Fertiliser_ChemicalCompounds[FNinorganic f])*Table_Input_InorganicFertiliser_Brands[[#This Row],[Ingredient 4 percent]]), 0)+ IFERROR((_xlfn.XLOOKUP(Table_Input_InorganicFertiliser_Brands[[#This Row],[Ingredient 5]],Table_Fertiliser_ChemicalCompounds[Fertiliser type f],Table_Fertiliser_ChemicalCompounds[FNinorganic f])*Table_Input_InorganicFertiliser_Brands[[#This Row],[Ingredient 5 percent]]), 0)+ IFERROR((_xlfn.XLOOKUP(Table_Input_InorganicFertiliser_Brands[[#This Row],[Ingredient 6]],Table_Fertiliser_ChemicalCompounds[Fertiliser type f],Table_Fertiliser_ChemicalCompounds[FNinorganic f])*Table_Input_InorganicFertiliser_Brands[[#This Row],[Ingredient 6 percent]]), 0)) -> 14.58 | W20: =_xlfn.XLOOKUP(Table_Input_InorganicFertiliser_Brands[[#This Row],[Product (select)]],FertiliserProducts[Product name],FertiliserProducts[Urea source]) -> 0 | X20: =_xlfn.XLOOKUP(Table_Input_InorganicFertiliser_Brands[[#This Row],[Product (select)]],FertiliserProducts[Product name],FertiliserProducts[Ammonia source]) -> 0
A21: =HYPERLINK("#'Constants - Common'!A1", "Constants - Common") -> Constants - Common
D22: Custom fertiliser blends
D23: Custom blend name | E23: Amount applied (kg / ha) | F23: Application area (ha) | G23: Total applied (kg) | H23: Ingredient 1 (select) | I23: Ingredient 1 percent | J23: Ingredient 2 | K23: Ingredient 2 percent | L23: Ingredient 3 | M23: Ingredient 3 percent | N23: Ingredient 4 | O23: Ingredient 4 percent | P23: N application rate (kg/ha) | Q23: Urea source | R23: Ammonia source
D24: My first custom blend | E24: 100 | F24: =$E$9 -> 100 | G24: =Table_Input_InorganicFertiliser_Custom[[#This Row],[Amount applied (kg / ha)]]*Table_Input_InorganicFertiliser_Custom[[#This Row],[Application area (ha)]] -> 10000 | H24: Ammonia | I24: 0.45 | J24: Calcium nitrate | K24: 0.3 | L24: Potassium - Generic | M24: 0.1 | N24: Sulfur - Generic | O24: 0.1 | P24: =Table_Input_InorganicFertiliser_Custom[[#This Row],[Amount applied (kg / ha)]]* (IFERROR((_xlfn.XLOOKUP(Table_Input_InorganicFertiliser_Custom[[#This Row],[Ingredient 1 (select)]], Table_Fertiliser_ChemicalCompounds[Fertiliser type f],Table_Fertiliser_ChemicalCompounds[FNinorganic f])*Table_Input_InorganicFertiliser_Custom[[#This Row],[Ingredient 1 percent]]), 0) + IFERROR((_xlfn.XLOOKUP(Table_Input_InorganicFertiliser_Custom[[#This Row],[Ingredient 2]], Table_Fertiliser_ChemicalCompounds[Fertiliser type f],Table_Fertiliser_ChemicalCompounds[FNinorganic f])*Table_Input_InorganicFertiliser_Custom[[#This Row],[Ingredient 2 percent]]), 0) + IFERROR((_xlfn.XLOOKUP(Table_Input_InorganicFertiliser_Custom[[#This Row],[Ingredient 3]], Table_Fertiliser_ChemicalCompounds[Fertiliser type f],Table_Fertiliser_ChemicalCompounds[FNinorganic f])*Table_Input_InorganicFertiliser_Custom[[#This Row],[Ingredient 3 percent]]), 0) + IFERROR((_xlfn.XLOOKUP(Table_Input_InorganicFertiliser_Custom[[#This Row],[Ingredient 4]], Table_Fertiliser_ChemicalCompounds[Fertiliser type f],Table_Fertiliser_ChemicalCompounds[FNinorganic f])*Table_Input_InorganicFertiliser_Custom[[#This Row],[Ingredient 4 percent]]), 0) ) -> 41.7075 | Q24: Canada | R24: Global
E25: 100 | F25: =$E$9 -> 100 | G25: =Table_Input_InorganicFertiliser_Custom[[#This Row],[Amount applied (kg / ha)]]*Table_Input_InorganicFertiliser_Custom[[#This Row],[Application area (ha)]] -> 10000 | H25: Urea | I25: 0.9 | J25: Ammonia | K25: 0.1 | P25: =Table_Input_InorganicFertiliser_Custom[[#This Row],[Amount applied (kg / ha)]]* (IFERROR((_xlfn.XLOOKUP(Table_Input_InorganicFertiliser_Custom[[#This Row],[Ingredient 1 (select)]], Table_Fertiliser_ChemicalCompounds[Fertiliser type f],Table_Fertiliser_ChemicalCompounds[FNinorganic f])*Table_Input_InorganicFertiliser_Custom[[#This Row],[Ingredient 1 percent]]), 0) + IFERROR((_xlfn.XLOOKUP(Table_Input_InorganicFertiliser_Custom[[#This Row],[Ingredient 2]], Table_Fertiliser_ChemicalCompounds[Fertiliser type f],Table_Fertiliser_ChemicalCompounds[FNinorganic f])*Table_Input_InorganicFertiliser_Custom[[#This Row],[Ingredient 2 percent]]), 0) + IFERROR((_xlfn.XLOOKUP(Table_Input_InorganicFertiliser_Custom[[#This Row],[Ingredient 3]], Table_Fertiliser_ChemicalCompounds[Fertiliser type f],Table_Fertiliser_ChemicalCompounds[FNinorganic f])*Table_Input_InorganicFertiliser_Custom[[#This Row],[Ingredient 3 percent]]), 0) + IFERROR((_xlfn.XLOOKUP(Table_Input_InorganicFertiliser_Custom[[#This Row],[Ingredient 4]], Table_Fertiliser_ChemicalCompounds[Fertiliser type f],Table_Fertiliser_ChemicalCompounds[FNinorganic f])*Table_Input_InorganicFertiliser_Custom[[#This Row],[Ingredient 4 percent]]), 0) ) -> 49.635 | Q25: Canada | R25: Canada
D27: Soil ameliorants (lime)
D29: 💡 You can add more rows to the table by right-clicking on the table and selecting "Insert > Table rows above/below".
D30: 💡 'Lime' refers to calcium carbonate - CaCO3. 'Dolomite' refers to calcium magnesium carbonate - CaMg(CO3)2
D31: 💡The application area is the same as the area under pasture / cropping by default. You can edit it if the application area is different.
D32: =IF(MAX(Table_Input_SoilAmeliorants[Total]) > 1, "There can not be more than 100% ingredients in a product. Check the table below.", "")
D33: Product | E33: Amount applied (t/hectare) | F33: Application area (ha) | G33: Total amount applied (t) | H33: Percent Lime CaCO3 | I33: Percent Dolomite CaMg(CO3)2 | J33: Percent Gypsum | K33: Total
D34: Lime product 1 | E34: 100 | F34: =$E$9 -> 100 | G34: =IFERROR(Table_Input_SoilAmeliorants[[#This Row],[Amount applied (t/hectare)]]*Table_Input_SoilAmeliorants[[#This Row],[Application area (ha)]], 0) -> 10000 | H34: 0.4 | I34: 0.3 | J34: 0.25 | K34: =SUM(Table_Input_SoilAmeliorants[[#This Row],[Percent Lime CaCO3]:[Percent Gypsum]]) -> 0.95
D35: Lime product 2 | E35: 100 | F35: =$E$9 -> 100 | G35: =IFERROR(Table_Input_SoilAmeliorants[[#This Row],[Amount applied (t/hectare)]]*Table_Input_SoilAmeliorants[[#This Row],[Application area (ha)]], 0) -> 10000 | H35: 1 | K35: =SUM(Table_Input_SoilAmeliorants[[#This Row],[Percent Lime CaCO3]:[Percent Gypsum]]) -> 1
A44: =HYPERLINK("#A1", "▲ Back to top") -> ▲ Back to top

Sheet Input - Farm Inputs
A1: #VALUE! | C1: Input - Farm inputs
D5: Chemicals
D6: Pesticides
D7: 💡You can find specific product information in the Australian Government's 'PubCRIS' database search.
D8: Click here to find instructions on how to use the PubCRIS database
K9: {=IF( SUMPRODUCT((Table_Input_Pesticides[Constituent unit (select)]="fraction of product")*(Table_Input_Pesticides[Active ingredient 1 amount]>1)*(Table_Input_Pesticides[Active ingredient 2 amount]<>""))>0, "Alert: If constituent unit is fraction of product, amount cannot exceed 1", IF( SUMPRODUCT((Table_Input_Pesticides[Constituent unit (select)]="grams/litre or grams/kg")*(Table_Input_Pesticides[Active ingredient 1 amount]<1)*(Table_Input_Pesticides[Active ingredient 2 amount]<>""))>0, "Alert: If constituent unit is grams/kg or litre, amount cannot be less than 1", "" ) )} | N9: {=IF( SUMPRODUCT((Table_Input_Pesticides[Constituent unit (select)]="fraction of product")*(Table_Input_Pesticides[Active ingredient 2 amount]>1)*(Table_Input_Pesticides[Active ingredient 2 amount]<>""))>0, "Alert: If constituent unit is fraction of product, amount cannot exceed 1", IF( SUMPRODUCT((Table_Input_Pesticides[Constituent unit (select)]="grams/litre or grams/kg")*(Table_Input_Pesticides[Active ingredient 2 amount]<1)*(Table_Input_Pesticides[Active ingredient 2 amount]<>""))>0, "Alert: If constituent unit is grams/kg or litre, amount cannot be less than 1", "" ) )} | Q9: {=IF( SUMPRODUCT((Table_Input_Pesticides[Constituent unit (select)]="fraction of product")*(Table_Input_Pesticides[Active ingredient 3 amount]>1)*(Table_Input_Pesticides[Active ingredient 3 amount]<>""))>0, "Alert: If constituent unit is fraction of product, amount cannot exceed 1", IF( SUMPRODUCT((Table_Input_Pesticides[Constituent unit (select)]="grams/litre or grams/kg")*(Table_Input_Pesticides[Active ingredient 3 amount]<1)*(Table_Input_Pesticides[Active ingredient 3 amount]<>""))>0, "Alert: If constituent unit is grams/kg or litre, amount cannot be less than 1", "" ) )}
D10: Product name | E10: Amount applied per ha | F10: Application unit (select) | G10: Application area (ha) | H10: Total applied | I10: Constituent unit (select) | J10: Active ingredient 1 (select) | K10: Active ingredient 1 amount | L10: Total active ingredient 1 (kg) | M10: Active ingredient 2 (select) | N10: Active ingredient 2 amount | O10: Total active ingredient 2 (kg) | P10: Active ingredient 3 (select) | Q10: Active ingredient 3 amount | R10: Total active ingredient 3 (kg)
D11: QA MCPA + Picloram SL Herbicide | E11: 10 | F11: kg / hectare | G11: 100 | H11: =Table_Input_Pesticides[[#This Row],[Amount applied per ha]]*Table_Input_Pesticides[[#This Row],[Application area (ha)]] -> 1000 | I11: grams/litre or grams/kg | J11: Pesticides (generic) | K11: 100 | L11: =Table_Input_Pesticides[[#This Row],[Total applied]]*Table_Input_Pesticides[[#This Row],[Active ingredient 1 amount]]*IF(Table_Input_Pesticides[[#This Row],[Constituent unit (select)]]="fraction of product", 1, 10^-3) -> 100 | M11: Pesticides (generic) | N11: 100 | O11: =Table_Input_Pesticides[[#This Row],[Total applied]]*Table_Input_Pesticides[[#This Row],[Active ingredient 2 amount]]*IF(Table_Input_Pesticides[[#This Row],[Constituent unit (select)]]="fraction of product", 1, 10^-3) -> 100 | P11: Glyphosate | Q11: 100 | R11: =Table_Input_Pesticides[[#This Row],[Total applied]]*Table_Input_Pesticides[[#This Row],[Active ingredient 3 amount]]*IF(Table_Input_Pesticides[[#This Row],[Constituent unit (select)]]="fraction of product", 1, 10^-3) -> 100
D12: Heben Propiconazole 550EC Fungicide | E12: 10 | F12: litre / hectare | G12: 100 | H12: =Table_Input_Pesticides[[#This Row],[Amount applied per ha]]*Table_Input_Pesticides[[#This Row],[Application area (ha)]] -> 1000 | I12: grams/litre or grams/kg | J12: Pesticides (generic) | K12: 100 | L12: =Table_Input_Pesticides[[#This Row],[Total applied]]*Table_Input_Pesticides[[#This Row],[Active ingredient 1 amount]]*IF(Table_Input_Pesticides[[#This Row],[Constituent unit (select)]]="fraction of product", 1, 10^-3) -> 100 | M12: 2,4-D | N12: 100 | O12: =Table_Input_Pesticides[[#This Row],[Total applied]]*Table_Input_Pesticides[[#This Row],[Active ingredient 2 amount]]*IF(Table_Input_Pesticides[[#This Row],[Constituent unit (select)]]="fraction of product", 1, 10^-3) -> 100 | P12: Tribenuron methyl | Q12: 100 | R12: =Table_Input_Pesticides[[#This Row],[Total applied]]*Table_Input_Pesticides[[#This Row],[Active ingredient 3 amount]]*IF(Table_Input_Pesticides[[#This Row],[Constituent unit (select)]]="fraction of product", 1, 10^-3) -> 100
D13: NovaGuard Boscalid 500 WG Fungicide | E13: 10 | F13: kg / hectare | G13: 100 | H13: =Table_Input_Pesticides[[#This Row],[Amount applied per ha]]*Table_Input_Pesticides[[#This Row],[Application area (ha)]] -> 1000 | I13: grams/litre or grams/kg | J13: Pesticides (generic) | K13: 100 | L13: =Table_Input_Pesticides[[#This Row],[Total applied]]*Table_Input_Pesticides[[#This Row],[Active ingredient 1 amount]]*IF(Table_Input_Pesticides[[#This Row],[Constituent unit (select)]]="fraction of product", 1, 10^-3) -> 100 | M13: Metolachlor | N13: 100 | O13: =Table_Input_Pesticides[[#This Row],[Total applied]]*Table_Input_Pesticides[[#This Row],[Active ingredient 2 amount]]*IF(Table_Input_Pesticides[[#This Row],[Constituent unit (select)]]="fraction of product", 1, 10^-3) -> 100 | P13: Trifluralin | Q13: 100 | R13: =Table_Input_Pesticides[[#This Row],[Total applied]]*Table_Input_Pesticides[[#This Row],[Active ingredient 3 amount]]*IF(Table_Input_Pesticides[[#This Row],[Constituent unit (select)]]="fraction of product", 1, 10^-3) -> 100
H14: =Table_Input_Pesticides[[#This Row],[Amount applied per ha]]*Table_Input_Pesticides[[#This Row],[Application area (ha)]] -> 0 | L14: =Table_Input_Pesticides[[#This Row],[Total applied]]*Table_Input_Pesticides[[#This Row],[Active ingredient 1 amount]]*IF(Table_Input_Pesticides[[#This Row],[Constituent unit (select)]]="fraction of product", 1, 10^-3) -> 0 | O14: =Table_Input_Pesticides[[#This Row],[Total applied]]*Table_Input_Pesticides[[#This Row],[Active ingredient 2 amount]]*IF(Table_Input_Pesticides[[#This Row],[Constituent unit (select)]]="fraction of product", 1, 10^-3) -> 0 | R14: =Table_Input_Pesticides[[#This Row],[Total applied]]*Table_Input_Pesticides[[#This Row],[Active ingredient 3 amount]]*IF(Table_Input_Pesticides[[#This Row],[Constituent unit (select)]]="fraction of product", 1, 10^-3) -> 0
H15: =Table_Input_Pesticides[[#This Row],[Amount applied per ha]]*Table_Input_Pesticides[[#This Row],[Application area (ha)]] -> 0 | L15: =Table_Input_Pesticides[[#This Row],[Total applied]]*Table_Input_Pesticides[[#This Row],[Active ingredient 1 amount]]*IF(Table_Input_Pesticides[[#This Row],[Constituent unit (select)]]="fraction of product", 1, 10^-3) -> 0 | O15: =Table_Input_Pesticides[[#This Row],[Total applied]]*Table_Input_Pesticides[[#This Row],[Active ingredient 2 amount]]*IF(Table_Input_Pesticides[[#This Row],[Constituent unit (select)]]="fraction of product", 1, 10^-3) -> 0 | R15: =Table_Input_Pesticides[[#This Row],[Total applied]]*Table_Input_Pesticides[[#This Row],[Active ingredient 3 amount]]*IF(Table_Input_Pesticides[[#This Row],[Constituent unit (select)]]="fraction of product", 1, 10^-3) -> 0
H16: =Table_Input_Pesticides[[#This Row],[Amount applied per ha]]*Table_Input_Pesticides[[#This Row],[Application area (ha)]] -> 0 | L16: =Table_Input_Pesticides[[#This Row],[Total applied]]*Table_Input_Pesticides[[#This Row],[Active ingredient 1 amount]]*IF(Table_Input_Pesticides[[#This Row],[Constituent unit (select)]]="fraction of product", 1, 10^-3) -> 0 | O16: =Table_Input_Pesticides[[#This Row],[Total applied]]*Table_Input_Pesticides[[#This Row],[Active ingredient 2 amount]]*IF(Table_Input_Pesticides[[#This Row],[Constituent unit (select)]]="fraction of product", 1, 10^-3) -> 0 | R16: =Table_Input_Pesticides[[#This Row],[Total applied]]*Table_Input_Pesticides[[#This Row],[Active ingredient 3 amount]]*IF(Table_Input_Pesticides[[#This Row],[Constituent unit (select)]]="fraction of product", 1, 10^-3) -> 0
H17: =Table_Input_Pesticides[[#This Row],[Amount applied per ha]]*Table_Input_Pesticides[[#This Row],[Application area (ha)]] -> 0 | L17: =Table_Input_Pesticides[[#This Row],[Total applied]]*Table_Input_Pesticides[[#This Row],[Active ingredient 1 amount]]*IF(Table_Input_Pesticides[[#This Row],[Constituent unit (select)]]="fraction of product", 1, 10^-3) -> 0 | O17: =Table_Input_Pesticides[[#This Row],[Total applied]]*Table_Input_Pesticides[[#This Row],[Active ingredient 2 amount]]*IF(Table_Input_Pesticides[[#This Row],[Constituent unit (select)]]="fraction of product", 1, 10^-3) -> 0 | R17: =Table_Input_Pesticides[[#This Row],[Total applied]]*Table_Input_Pesticides[[#This Row],[Active ingredient 3 amount]]*IF(Table_Input_Pesticides[[#This Row],[Constituent unit (select)]]="fraction of product", 1, 10^-3) -> 0
H18: =Table_Input_Pesticides[[#This Row],[Amount applied per ha]]*Table_Input_Pesticides[[#This Row],[Application area (ha)]] -> 0 | L18: =Table_Input_Pesticides[[#This Row],[Total applied]]*Table_Input_Pesticides[[#This Row],[Active ingredient 1 amount]]*IF(Table_Input_Pesticides[[#This Row],[Constituent unit (select)]]="fraction of product", 1, 10^-3) -> 0 | O18: =Table_Input_Pesticides[[#This Row],[Total applied]]*Table_Input_Pesticides[[#This Row],[Active ingredient 2 amount]]*IF(Table_Input_Pesticides[[#This Row],[Constituent unit (select)]]="fraction of product", 1, 10^-3) -> 0 | R18: =Table_Input_Pesticides[[#This Row],[Total applied]]*Table_Input_Pesticides[[#This Row],[Active ingredient 3 amount]]*IF(Table_Input_Pesticides[[#This Row],[Constituent unit (select)]]="fraction of product", 1, 10^-3) -> 0
