Workbook
Name AgResidue_Equations_CropResidue.VEERG_6_1_1_1__1__NitrousOxideEmissionsFromCropResidues: _xlfn.LAMBDA(_xlpm.M_c,_xlpm.EF_Ni,_xlpm.C_N2O, _xlpm.M_c * _xlpm.EF_Ni * _xlpm.C_N2O * 10 ^ (-3))
Name AgResidue_Equations_CropResidue.VEERG_6_1_1_1__1__NitrousOxideEmissionsFromCropResidues_FunctionName: _xlfn.LAMBDA("VEERG_6_1_1_1__1__NitrousOxideEmissionsFromCropResidues")
Name AgResidue_Equations_CropResidue.VEERG_6_1_1_1__1__NitrousOxideEmissionsFromCropResidues_LatexEquation: _xlfn.LAMBDA("E=\sum\nolimits_c\left(M_{c}\times EF_{N}\right)\times C_{g,N2O}\times 10^{-3}")
Name AgResidue_Equations_CropResidue.VEERG_6_1_1_1__1__NitrousOxideEmissionsFromCropResidues_NIRReference: _xlfn.LAMBDA("")
Name AgResidue_Equations_CropResidue.VEERG_6_1_1_1__1__NitrousOxideEmissionsFromCropResidues_Source: _xlfn.LAMBDA("VEERG 2026: 6.1.1.1, Equation (1)")
Name AgResidue_Equations_CropResidue.VEERG_6_1_1_1__1__NitrousOxideEmissionsFromCropResidues_Title: _xlfn.LAMBDA("Nitrous oxide emissions from the return of crop residues across all crops c to the soil")
Name AgResidue_Equations_CropResidue.VEERG_6_1_1_1__1__NitrousOxideEmissionsFromCropResidues_Unit: _xlfn.LAMBDA("t N2O")
Name AgResidue_Equations_CropResidue.VEERG_6_1_1_1__1__NitrousOxideEmissionsFromCropResidues_Variable: _xlfn.LAMBDA("E")
Name AgResidue_Equations_CropResidue.VEERG_6_1_1_1__2__MassOfNitrogenInCropResidues_LatexEquation: _xlfn.LAMBDA("M_{c}=(P_{c}\times R_{AGc}\times(1-F_{c}-FFOD_{c})\times DM_{c}\times NC_{AGc})+(P_{c}\times R_{AGc}\times R_{BGc}\times DM_{c}\times NC_{BGc})")
Name AgResidue_Equations_CropResidue.VEERG_6_1_1_1__2__MassOfNitrogenInCropResidues_NIRReference: _xlfn.LAMBDA("")
Name AgResidue_Equations_CropResidue.VEERG_6_1_1_1__2__MassOfNitrogenInCropResidues_Source: _xlfn.LAMBDA("VEERG 2026: 6.1.1.1, Equation (2)")
Name AgResidue_Equations_CropResidue.VEERG_6_1_1_1__2__MassOfNitrogenInCropResidues_Title: _xlfn.LAMBDA("Mass of nitrogen in crop residues returned to the soil")
Name AgResidue_Equations_CropResidue.VEERG_6_1_1_1__2__MassOfNitrogenInCropResidues_Unit: _xlfn.LAMBDA("kg N")
Name AgResidue_Equations_CropResidue.VEERG_6_1_1_1__2__MassOfNitrogenInCropResidues_Variable: _xlfn.LAMBDA("M_c")
Name AgResidue_Equations_CropResidue.VEERG_6_1_1_2__1__FractionOfCropResidueRemovedBaled: _xlfn.LAMBDA(_xlpm.B,_xlpm.M_B,_xlpm.P_c,_xlpm.R_AGc, IFERROR((_xlpm.B * _xlpm.M_B) / (_xlpm.P_c * _xlpm.R_AGc), 0))
Name AgResidue_Equations_CropResidue.VEERG_6_1_1_2__1__FractionOfCropResidueRemovedBaled_LatexEquation: _xlfn.LAMBDA("FFOD_{c,baled}=\frac{B\times M_{B}}{P_{c}\times R_{AG,c}}")
Name AgResidue_Equations_CropResidue.VEERG_6_1_1_2__1__FractionOfCropResidueRemovedBaled_NIRReference: _xlfn.LAMBDA("")
Name AgResidue_Equations_CropResidue.VEERG_6_1_1_2__1__FractionOfCropResidueRemovedBaled_Source: _xlfn.LAMBDA("VEERG 2026: 6.1.1.2, Equation (1)")
Name AgResidue_Equations_CropResidue.VEERG_6_1_1_2__1__FractionOfCropResidueRemovedBaled_Title: _xlfn.LAMBDA("Fraction of crop residue that is removed for crop c, calculated where residues are baled")
Name AgResidue_Equations_CropResidue.VEERG_6_1_1_2__1__FractionOfCropResidueRemovedBaled_Unit: _xlfn.LAMBDA("dimensionless")
Name AgResidue_Equations_CropResidue.VEERG_6_1_1_2__1__FractionOfCropResidueRemovedBaled_Variable: _xlfn.LAMBDA("FFOD_cbaled")
Name AgResidue_Equations_CropResidue.VEERG_6_1_1_2__1__FractionOfCropResidueRemovedBaled_Variation: _xlfn.LAMBDA("VARIATION FROM SOURCE: Added 'baled' to variable subscript")
Name AgResidue_Equations_CropResidue.VEERG_6_1_1_2__1a__FractionOfCropResidueRemoved: _xlfn.LAMBDA(_xlpm.FFOD_cbaled,_xlpm.FFOD_cother, _xlpm.FFOD_cbaled + _xlpm.FFOD_cother)
Name AgResidue_Equations_CropResidue.VEERG_6_1_1_2__1a__FractionOfCropResidueRemoved_LatexEquation: _xlfn.LAMBDA("FFOD_{c} = FFOD_{c,baled} + FFOD_{c,other}")
Name AgResidue_Equations_CropResidue.VEERG_6_1_1_2__1a__FractionOfCropResidueRemoved_NIRReference: _xlfn.LAMBDA("")
Name AgResidue_Equations_CropResidue.VEERG_6_1_1_2__1a__FractionOfCropResidueRemoved_Source: _xlfn.LAMBDA("")
Name AgResidue_Equations_CropResidue.VEERG_6_1_1_2__1a__FractionOfCropResidueRemoved_Title: _xlfn.LAMBDA("Fraction of crop residue that is removed for crop c")
Name AgResidue_Equations_CropResidue.VEERG_6_1_1_2__1a__FractionOfCropResidueRemoved_Unit: _xlfn.LAMBDA("dimensionless")
Name AgResidue_Equations_CropResidue.VEERG_6_1_1_2__1a__FractionOfCropResidueRemoved_Variable: _xlfn.LAMBDA("FFOD_c")
Name AgResidue_Equations_CropResidue.VEERG_6_1_1_2__1a__FractionOfCropResidueRemoved_Variation: _xlfn.LAMBDA("VARIATION FROM SOURCE: Added this equation to accommodate user-defined residue removal other than baling.")
Name AgResidue_Equations_FieldBurning.VEERG_6_4_1_1__1__MethaneEmissionsFromBurningOfCropResidues: _xlfn.LAMBDA(_xlpm.M_burnc,_xlpm.CC_c,_xlpm.EF_CH4,_xlpm.C_CH4, (_xlpm.M_burnc * _xlpm.CC_c) * _xlpm.EF_CH4 * _xlpm.C_CH4 * 10 ^ (-3))
Name AgResidue_Equations_FieldBurning.VEERG_6_4_1_1__1__MethaneEmissionsFromBurningOfCropResidues_FunctionName: _xlfn.LAMBDA("VEERG_6_4_1_1__1__MethaneEmissionsFromBurningOfCropResidues")
Name AgResidue_Equations_FieldBurning.VEERG_6_4_1_1__1__MethaneEmissionsFromBurningOfCropResidues_LatexEquation: _xlfn.LAMBDA("E_{CH4}=\sum\nolimits_c(M_{burn,c}\times CC_{c})\times EF_{CH4}\times C_{CH4}\times 10^{-3}")
Name AgResidue_Equations_FieldBurning.VEERG_6_4_1_1__1__MethaneEmissionsFromBurningOfCropResidues_NIRReference: _xlfn.LAMBDA("")
Name AgResidue_Equations_FieldBurning.VEERG_6_4_1_1__1__MethaneEmissionsFromBurningOfCropResidues_Source: _xlfn.LAMBDA("VEERG 2026: 6.4.1.1, Equation (1)")
Name AgResidue_Equations_FieldBurning.VEERG_6_4_1_1__1__MethaneEmissionsFromBurningOfCropResidues_Title: _xlfn.LAMBDA("Methane emissions from the burning of crop residues")
Name AgResidue_Equations_FieldBurning.VEERG_6_4_1_1__1__MethaneEmissionsFromBurningOfCropResidues_Unit: _xlfn.LAMBDA("t CH4")
Name AgResidue_Equations_FieldBurning.VEERG_6_4_1_1__1__MethaneEmissionsFromBurningOfCropResidues_Variable: _xlfn.LAMBDA("ECH4")
Name AgResidue_Equations_FieldBurning.VEERG_6_4_1_1__2__NitrousOxideEmissionsFromBurningOfCropResidues: _xlfn.LAMBDA(_xlpm.M_burnc,_xlpm.NC_AGc,_xlpm.EF_N2O,_xlpm.C_N2O, (_xlpm.M_burnc * _xlpm.NC_AGc) * _xlpm.EF_N2O * _xlpm.C_N2O * 10 ^ (-3))
Name AgResidue_Equations_FieldBurning.VEERG_6_4_1_1__2__NitrousOxideEmissionsFromBurningOfCropResidues_FunctionName: _xlfn.LAMBDA("VEERG_6_4_1_1__2__NitrousOxideEmissionsFromBurningOfCropResidues")
Name AgResidue_Equations_FieldBurning.VEERG_6_4_1_1__2__NitrousOxideEmissionsFromBurningOfCropResidues_LatexEquation: _xlfn.LAMBDA("E_{N2O}=\sum\nolimits_c(M_{burn,c}\times NC_{AGc})\times EF_{N2O}\times C_{N2O}\times 10^{-3}")
Name AgResidue_Equations_FieldBurning.VEERG_6_4_1_1__2__NitrousOxideEmissionsFromBurningOfCropResidues_NIRReference: _xlfn.LAMBDA("")
Name AgResidue_Equations_FieldBurning.VEERG_6_4_1_1__2__NitrousOxideEmissionsFromBurningOfCropResidues_Source: _xlfn.LAMBDA("VEERG 2026: 6.4.1.1, Equation (2)")
Name AgResidue_Equations_FieldBurning.VEERG_6_4_1_1__2__NitrousOxideEmissionsFromBurningOfCropResidues_Title: _xlfn.LAMBDA("Nitrous oxide emissions from the burning of crop residues")
Name AgResidue_Equations_FieldBurning.VEERG_6_4_1_1__2__NitrousOxideEmissionsFromBurningOfCropResidues_Unit: _xlfn.LAMBDA("t N2O")
Name AgResidue_Equations_FieldBurning.VEERG_6_4_1_1__2__NitrousOxideEmissionsFromBurningOfCropResidues_Variable: _xlfn.LAMBDA("EN2O")
Name AgResidue_Equations_FieldBurning.VEERG_6_4_1_1__3__MassOfCropResidueBurnt: _xlfn.LAMBDA(_xlpm.P_c,_xlpm.R_AGc,_xlpm.S_c,_xlpm.DM_c,_xlpm.Z_c,_xlpm.F_c, _xlpm.P_c * _xlpm.R_AGc * _xlpm.S_c * _xlpm.DM_c * _xlpm.Z_c * _xlpm.F_c)
Name AgResidue_Equations_FieldBurning.VEERG_6_4_1_1__3__MassOfCropResidueBurnt_FunctionName: _xlfn.LAMBDA("VEERG_6_4_1_1__3__MassOfCropResidueBurnt")
Name AgResidue_Equations_FieldBurning.VEERG_6_4_1_1__3__MassOfCropResidueBurnt_LatexEquation: _xlfn.LAMBDA("M_{burn,c}=P_{c}\times R_{AGc}\times S_{c}\times DM_{c}\times Z_{c}\times F_{c}")
Name AgResidue_Equations_FieldBurning.VEERG_6_4_1_1__3__MassOfCropResidueBurnt_NIRReference: _xlfn.LAMBDA("")
Name AgResidue_Equations_FieldBurning.VEERG_6_4_1_1__3__MassOfCropResidueBurnt_Source: _xlfn.LAMBDA("VEERG 2026: 6.4.1.1, Equation (3)")
Name AgResidue_Equations_FieldBurning.VEERG_6_4_1_1__3__MassOfCropResidueBurnt_Title: _xlfn.LAMBDA("Mass of residue of crop c burnt")
Name AgResidue_Equations_FieldBurning.VEERG_6_4_1_1__3__MassOfCropResidueBurnt_Unit: _xlfn.LAMBDA("kg")
Name AgResidue_Equations_FieldBurning.VEERG_6_4_1_1__3__MassOfCropResidueBurnt_Variable: _xlfn.LAMBDA("M_burnc")
Name AgResidue_Equations_Leaching.VEERG_6_3_1_1__1__LeachingAndRunoffEmissionsCropAndPastureResidue: _xlfn.LAMBDA(_xlpm.M_leachcp,_xlpm.EF_leach,_xlpm.C_N2O, _xlpm.M_leachcp * _xlpm.EF_leach * _xlpm.C_N2O * 10 ^ (-3))
Name AgResidue_Equations_Leaching.VEERG_6_3_1_1__1__LeachingAndRunoffEmissionsCropAndPastureResidue_LatexEquation: _xlfn.LAMBDA("E_{N2O}=\sum\nolimits_c\sum\nolimits_p(M_{leach,cp}\times EF_{leach}\times C_{N2O}\times 10^{-3})")
Name AgResidue_Equations_Leaching.VEERG_6_3_1_1__1__LeachingAndRunoffEmissionsCropAndPastureResidue_NIRReference: _xlfn.LAMBDA("")
Name AgResidue_Equations_Leaching.VEERG_6_3_1_1__1__LeachingAndRunoffEmissionsCropAndPastureResidue_Source: _xlfn.LAMBDA("VEERG 2026: 6.3.1.1, Equation (1)")
Name AgResidue_Equations_Leaching.VEERG_6_3_1_1__1__LeachingAndRunoffEmissionsCropAndPastureResidue_Title: _xlfn.LAMBDA("Nitrous oxide leaching and runoff emissions from crop and pasture residues returned to the soil")
Name AgResidue_Equations_Leaching.VEERG_6_3_1_1__1__LeachingAndRunoffEmissionsCropAndPastureResidue_Unit: _xlfn.LAMBDA("t N2O")

Sheet Home
A1: Home

Sheet Overview
A1: #VALUE! | C1: 6: Agricultural Residue Management: Overview
A3: =HYPERLINK("#'Home'!A1", "Home") -> Home
A4: =HYPERLINK("#'Overview'!A1", "Overview") -> Overview
A5: =HYPERLINK("#'Results'!A1", "Results") -> Results | D5: 💡 Below is a diagram that maps the equations used to calculate emissions, and how they interact with each other.
D6: Click on a box to go to the corresponding calculation.
A7: INPUTS
A8: =HYPERLINK("#'Input - Site'!A1", "Site") -> Site
A9: =HYPERLINK("#'Input - Crop'!A1", "Crop") -> Crop
A10: =HYPERLINK("#'Input - Pasture'!A1", "Pasture") -> Pasture
A12: CALCULATIONS
A13: =HYPERLINK("#'6.1.1.1-2 Crop residue N2O'!A1", "6.1.1.1-2 Crop residue N2O") -> 6.1.1.1-2 Crop residue N2O
A14: =HYPERLINK("#'6.2.1.1-2 Pasture residue N2O'!A1", "6.2.1.1-2 Pasture residue N2O") -> 6.2.1.1-2 Pasture residue N2O
A15: =HYPERLINK("#'6.3.1.1-2 Leaching and runoff'!A1", "6.3.1.1-2 Leaching and runoff") -> 6.3.1.1-2 Leaching and runoff
A16: =HYPERLINK("#'6.4.1.1-2 Residue burning'!A1", "6.4.1.1-2 Residue burning") -> 6.4.1.1-2 Residue burning
A18: APPENDICES
A19: =HYPERLINK("#'Constants - Ag Residue'!A1", "Constants - Ag Residue") -> Constants - Ag Residue
A20: =HYPERLINK("#'Constants - Common'!A1", "Constants - Common") -> Constants - Common
L37: `

Sheet Results
A1: #VALUE! | C1: 6: Agricultural Residue Management: Results
A3: =HYPERLINK("#'Home'!A1", "Home") -> Home
A4: =HYPERLINK("#'Overview'!A1", "Overview") -> Overview | D4: Emissions breakdown
A5: =HYPERLINK("#'Results'!A1", "Results") -> Results
D6: 💡 NOTE: When there is no Method 2, the Method 2 result are the same as Method 1
A7: INPUTS
A8: =HYPERLINK("#'Input - Site'!A1", "Site") -> Site | D8: Scope 1 source | E8: GHG emissions method 1 | F8: GHG emissions method 2 | G8: GHG Unit | H8: CO2-e emissions method 1 | I8: CO2-e emissions method 2 | J8: CO2-e unit
A9: =HYPERLINK("#'Input - Crop'!A1", "Crop") -> Crop | D9: 6.1.1.1-2 Crop residue N2O | E9: ='6.1.1.1-2 Crop residue N2O'!E42 -> 0.00066792 | F9: ='6.1.1.1-2 Crop residue N2O'!N77 -> 0.00066792 | G9: t N2O | H9: ='6.1.1.1-2 Crop residue N2O'!E47 -> 0.1769988 | I9: ='6.1.1.1-2 Crop residue N2O'!N82 -> 0.1769988 | J9: t CO2e
A10: =HYPERLINK("#'Input - Pasture'!A1", "Pasture") -> Pasture | D10: 6.2.1.1-2 Pasture residue N2O | E10: ='6.2.1.1-2 Pasture residue N2O'!E40 -> 5.8320429e-07 | F10: ='6.2.1.1-2 Pasture residue N2O'!O40 -> 5.8320429e-07 | G10: t N2O | H10: ='6.2.1.1-2 Pasture residue N2O'!E45 -> 0.00015454914 | I10: ='6.2.1.1-2 Pasture residue N2O'!O45 -> 0.00015454914 | J10: t CO2e
D11: 6.3.1.1-2 Leaching and runoff | E11: ='6.3.1.1-2 Leaching and runoff'!E48 -> 0 | F11: ='6.3.1.1-2 Leaching and runoff'!O48 -> 0 | G11: t N2O | H11: ='6.3.1.1-2 Leaching and runoff'!E53 -> 0 | I11: ='6.3.1.1-2 Leaching and runoff'!O53 -> 0 | J11: t CO2e
A12: CALCULATIONS | D12: 6.4.1.1-2 Residue burning | E12: ='6.4.1.1-2 Residue burning'!E39 -> 0.00012769303 | F12: =E12 -> 0.00012769303 | G12: t N2O | H12: ='6.4.1.1-2 Residue burning'!E44 -> 0.033838653 | I12: =H12 -> 0.033838653 | J12: t CO2e
A13: =HYPERLINK("#'6.1.1.1-2 Crop residue N2O'!A1", "6.1.1.1-2 Crop residue N2O") -> 6.1.1.1-2 Crop residue N2O | D13: 6.4.1.1-2 Residue burning | E13: ='6.4.1.1-2 Residue burning'!E62 -> 0.0033264 | F13: =E13 -> 0.0033264 | G13: t CH4 | H13: ='6.4.1.1-2 Residue burning'!E67 -> 0.0931392 | I13: =H13 -> 0.0931392 | J13: t CO2e
A14: =HYPERLINK("#'6.2.1.1-2 Pasture residue N2O'!A1", "6.2.1.1-2 Pasture residue N2O") -> 6.2.1.1-2 Pasture residue N2O | D14: Total | H14: =SUM(H9:H13) -> 0.3041312 | I14: =SUM(I9:I13) -> 0.3041312 | J14: t CO2e
A15: =HYPERLINK("#'6.3.1.1-2 Leaching and runoff'!A1", "6.3.1.1-2 Leaching and runoff") -> 6.3.1.1-2 Leaching and runoff
A16: =HYPERLINK("#'6.4.1.1-2 Residue burning'!A1", "6.4.1.1-2 Residue burning") -> 6.4.1.1-2 Residue burning
A18: APPENDICES
A19: =HYPERLINK("#'Constants - Ag Residue'!A1", "Constants - Ag Residue") -> Constants - Ag Residue
A20: =HYPERLINK("#'Constants - Common'!A1", "Constants - Common") -> Constants - Common

Sheet Input - Site
A1: #VALUE! | C1: Input - Site
A3: =HYPERLINK("#'Home'!A1", "Home") -> Home
A4: =HYPERLINK("#'Overview'!A1", "Overview") -> Overview
A5: =HYPERLINK("#'Results'!A1", "Results") -> Results | D5: Your business
A7: INPUTS | D7: Farm name | E7: Test Farms
A8: =HYPERLINK("#'Input - Site'!A1", "Site") -> Site | D8: Reporting entity name | E8: Test Farms Pty Ltd
A9: =HYPERLINK("#'Input - Crop'!A1", "Crop") -> Crop
A10: =HYPERLINK("#'Input - Pasture'!A1", "Pasture") -> Pasture | D10: 💡An 'Emissions accounting period' is a 12 month period where the business can report on the emissions, and is typically the same as the business' financial accounting period.
A12: CALCULATIONS | D12: Emissions calculation period start date | E12: 45292 | F12: ← DD/MM/YYYY or DD Month YYYY
A13: =HYPERLINK("#'6.1.1.1-2 Crop residue N2O'!A1", "6.1.1.1-2 Crop residue N2O") -> 6.1.1.1-2 Crop residue N2O | D13: Emissions calculation period end date | E13: =DATE(YEAR(E12)+1,MONTH(E12),DAY(E12))-1 -> 45657 | F13: ← Automatically calculated, 12 months after start date
A14: =HYPERLINK("#'6.2.1.1-2 Pasture residue N2O'!A1", "6.2.1.1-2 Pasture residue N2O") -> 6.2.1.1-2 Pasture residue N2O
A15: =HYPERLINK("#'6.3.1.1-2 Leaching and runoff'!A1", "6.3.1.1-2 Leaching and runoff") -> 6.3.1.1-2 Leaching and runoff
A16: =HYPERLINK("#'6.4.1.1-2 Residue burning'!A1", "6.4.1.1-2 Residue burning") -> 6.4.1.1-2 Residue burning | D16: Location and climate
A18: APPENDICES | D18: Location information is used to reference some region and climate-specific emission factors
A19: =HYPERLINK("#'Constants - Ag Residue'!A1", "Constants - Ag Residue") -> Constants - Ag Residue | D19: Tip: Use the web-based GAF Location Helper tool to easily get region and climate information. You will need an internet connection to use the GAF Location Helper.
A20: =HYPERLINK("#'Constants - Common'!A1", "Constants - Common") -> Constants - Common
D21: State | E21: Western Australia | F21: ← Please select
D22: Region (ABS Statistical area level 4) if state is WA | E22: Western Australia - Outback (South) | F22: ← Please select
D23: Leaching zone | E23: NO - Not in leaching zone | F23: ← Please select
D24: Elevation | E24: 307.7 | F24: Meters
D25: Average temperature for reporting period | E25: 18 | F25: Degrees celsius
D26: Total rainfall for reporting period | E26: 599 | F26: Millimetres
D27: Potential evapotranspiration for reporting period | E27: 1326 | F27: Millimetres
D28: Number of frost days for reporting period | E28: 7 | F28: Days
D29: MAP:PET ratio | E29: =E26/E27 -> 0.45173454
D30: Rainfall zone | E30: =Common_InputFunctions.Utility_LookupItemFromMinMax(E26,Table_SourceData_RainfallZones[Min rainfall],Table_SourceData_RainfallZones[Max rainfall],Table_SourceData_RainfallZones[Rainfall Zone]) -> Low rainfall
D31: Climate zone | E31: =Common_InputFunctions.Utility_GetClimateZone(E25,E26,E28,E24,E29,Table_SourceData_ClimateZones[Min temp],Table_SourceData_ClimateZones[Max temp],Table_SourceData_ClimateZones[Min rainfall],Table_SourceData_ClimateZones[Max rainfall],Table_SourceData_ClimateZones[Min frost days],Table_SourceData_ClimateZones[Max frost days],Table_SourceData_ClimateZones[Min elevation],Table_SourceData_ClimateZones[Max elevation],Table_SourceData_ClimateZones[Min MAP:PET],Table_SourceData_ClimateZones[Max MAP:PET],Table_SourceData_ClimateZones[Climate zone]) -> Warm temperate dry
D32: Wet or dry climate zone | E32: =Common_InputFunctions.Utility_LookupValueInTable($E$31,Table_SourceData_WetDryZones[Climate zone],Table_SourceData_WetDryZones[Wet or Dry Zone]) -> Dry climate zone
D33: Temperature zone | E33: =Common_InputFunctions.Utility_LookupItemFromMinMax(E25,Table_SourceData_TemperatureZones[Min MAT],Table_SourceData_TemperatureZones[Max MAT],Table_SourceData_TemperatureZones[Temperature Zone]) -> Temperate

Sheet Input - Crop
A1: #VALUE! | C1: Input - Crop
A3: =HYPERLINK("#'Home'!A1", "Home") -> Home
A4: =HYPERLINK("#'Overview'!A1", "Overview") -> Overview
A5: =HYPERLINK("#'Results'!A1", "Results") -> Results | D5: Area
A7: INPUTS | D7: If multiple paddocks were managed in the same way at the same time, you can enter information for them all together.
A8: =HYPERLINK("#'Input - Site'!A1", "Site") -> Site
A9: =HYPERLINK("#'Input - Crop'!A1", "Crop") -> Crop | D9: Crop type | E9: Wheat | F9: ← Please select
A10: =HYPERLINK("#'Input - Pasture'!A1", "Pasture") -> Pasture | D10: Crop purpose | E10: Cash grain crop | F10: ← Please select
D11: Irrigation method | E11: Sprinkler irrigation | F11: ← Please select
A12: CALCULATIONS
A13: =HYPERLINK("#'6.1.1.1-2 Crop residue N2O'!A1", "6.1.1.1-2 Crop residue N2O") -> 6.1.1.1-2 Crop residue N2O | D13: Area under cropping | E13: 1000 | F13: Hectares
A14: =HYPERLINK("#'6.2.1.1-2 Pasture residue N2O'!A1", "6.2.1.1-2 Pasture residue N2O") -> 6.2.1.1-2 Pasture residue N2O
A15: =HYPERLINK("#'6.3.1.1-2 Leaching and runoff'!A1", "6.3.1.1-2 Leaching and runoff") -> 6.3.1.1-2 Leaching and runoff | D15: Yield
A16: =HYPERLINK("#'6.4.1.1-2 Residue burning'!A1", "6.4.1.1-2 Residue burning") -> 6.4.1.1-2 Residue burning
D17: =E10 & " " & _xlfn.XLOOKUP(E10,Table_SourceData_CropPurposeAndYields[Purpose], Table_SourceData_CropPurposeAndYields[harvest term]) & " per hectare¹" -> Cash grain crop yield per hectare¹ | E17: 10 | F17: ="Tonnes " & _xlfn.XLOOKUP(E10, Table_SourceData_CropPurposeAndYields[Purpose], Table_SourceData_CropPurposeAndYields[Per hectare unit], FALSE) & " per hectare" -> Tonnes grain per hectare
A18: APPENDICES | D18: Residue:crop ratio² | E18: {=_xlfn.IFS(E10="Cash grain crop", Common_InputFunctions.Utility_LookupValueInTableNumber(E9, Table_SourceData_CropAttributes[Crop type],Table_SourceData_CropAttributes[Residue: Crop ratio]), E10="Cash crop for hay/silage", 0, E10="Cover crop", 1)} -> 1.5
A19: =HYPERLINK("#'Constants - Ag Residue'!A1", "Constants - Ag Residue") -> Constants - Ag Residue | D19: Crop residue biomass | E19: =E17*E18 -> 15 | F19: Tonnes per hectare
A20: =HYPERLINK("#'Constants - Common'!A1", "Constants - Common") -> Constants - Common | D20: Whole plant above ground biomass | E20: =E17+E19 -> 25 | F20: Tonnes per hectare
D22: Total production of crop³ | E22: =E17*E13 -> 10000 | F22: ="Tonnes " & _xlfn.XLOOKUP(E10, Table_SourceData_CropPurposeAndYields[Purpose], Table_SourceData_CropPurposeAndYields[Harvest uit], FALSE) -> Tonnes grain
D24: ="¹ " & _xlfn.XLOOKUP(E10, Table_SourceData_CropPurposeAndYields[Purpose],Table_SourceData_CropPurposeAndYields[Yield note]) -> ¹ Yield is the grain harvested from the plant
D25: ="² " & _xlfn.XLOOKUP(E10, Table_SourceData_CropPurposeAndYields[Purpose],Table_SourceData_CropPurposeAndYields[Residue crop ratio note]) -> ² Residue to crop ratio is provided from default values
D26: ="³ " & _xlfn.XLOOKUP(E10,Table_SourceData_CropPurposeAndYields[Purpose],Table_SourceData_CropPurposeAndYields[Total production note]) -> ³ Total production is the total grain harvested
D28: Residue management
D30: ="Residue after " & VLOOKUP(E10,'Constants - Ag Residue'!D8:G10, 4, FALSE) -> Residue after harvest | E30: =E19*E13 -> 15000 | F30: Tonnes
D32: Baled residue
D33: Percentage of residue that was baled | E33: 0.1 | F33: Percent
D34: Average weight per bale | E34: 60 | F34: Kilograms
D35: Number of bales | E35: =IFERROR((E36*10^3)/E34, 0) -> 25000 | F35: Bales
D36: Total residue baled | E36: =E30*E33 -> 1500 | F36: Tonnes
D38: Grazed residue
D39: Percentage of residue that was grazed | E39: 0.01 | F39: Percent
D40: Total residue grazed | E40: =E30*E39 -> 150 | F40: Tonnes
D42: Burned residue
D43: Percentage of residue that was burned | E43: 0.3 | F43: Percent
A44: =HYPERLINK("#A1", "▲ Back to top") -> ▲ Back to top | D44: Total residue burned | E44: =E30*E43 -> 4500 | F44: Tonnes
D46: Residue retained on paddocks | E46: =E30-E36-E40-E44 -> 8850 | F46: Tonnes

Sheet Input - Pasture
A1: #VALUE! | C1: Input - Pasture
A3: =HYPERLINK("#'Home'!A1", "Home") -> Home
A4: =HYPERLINK("#'Overview'!A1", "Overview") -> Overview
A5: =HYPERLINK("#'Results'!A1", "Results") -> Results | D5: Area
A7: INPUTS | D7: If multiple paddocks were managed in the same way at the same time, you can enter information for them all together.
A8: =HYPERLINK("#'Input - Site'!A1", "Site") -> Site
A9: =HYPERLINK("#'Input - Crop'!A1", "Crop") -> Crop | D9: Pasture type | E9: Grass clover mixture | F9: ← Please select
A10: =HYPERLINK("#'Input - Pasture'!A1", "Pasture") -> Pasture | D10: Irrigation method | E10: Surface irrigation | F10: ← Please select
A12: CALCULATIONS | D12: Area under pasture | E12: 1000 | F12: Hectares
A13: =HYPERLINK("#'6.1.1.1-2 Crop residue N2O'!A1", "6.1.1.1-2 Crop residue N2O") -> 6.1.1.1-2 Crop residue N2O
A14: =HYPERLINK("#'6.2.1.1-2 Pasture residue N2O'!A1", "6.2.1.1-2 Pasture residue N2O") -> 6.2.1.1-2 Pasture residue N2O | D14: Yield
A15: =HYPERLINK("#'6.3.1.1-2 Leaching and runoff'!A1", "6.3.1.1-2 Leaching and runoff") -> 6.3.1.1-2 Leaching and runoff
A16: =HYPERLINK("#'6.4.1.1-2 Residue burning'!A1", "6.4.1.1-2 Residue burning") -> 6.4.1.1-2 Residue burning | D16: 💡 'Pasture yield' is the average amount of dry matter that is grazed.
D17: A default value is provided based on pasture type. You can edit this if known.
A18: APPENDICES
A19: =HYPERLINK("#'Constants - Ag Residue'!A1", "Constants - Ag Residue") -> Constants - Ag Residue | D19: Pasture yield | E19: =_xlfn.XLOOKUP(E9, Table_SourceData_PastureAttributes[Pasture type],Table_SourceData_PastureAttributes[Average Yield (t DM ha) Yp]) -> 8.34 | F19: Tonnes dry matter / hectare
A20: =HYPERLINK("#'Constants - Common'!A1", "Constants - Common") -> Constants - Common | D20: Total pasture yield | E20: =E12*E19 -> 8340 | F20: Tonnes
D23: Residue management
D25: Area of pasture renewed or removed | E25: 500 | F25: Hectares

Sheet 6.1.1.1-2 Crop residue N2O
A1: #VALUE! | C1: 6.1.1.1-2 Crop residue N2O emissions
A3: =HYPERLINK("#'Home'!A1", "Home") -> Home | D3: Method 1 | M3: Method 2
A4: =HYPERLINK("#'Overview'!A1", "Overview") -> Overview
A5: =HYPERLINK("#'Results'!A1", "Results") -> Results | D5: Mass of nitrogen in crop residues returned to the soil | M5: Fraction of crop residue that is removed for crop c, calculated where residues are baled
D6: VEERG 2026: 6.1.1.1, Equation (2) | M6: VEERG 2026: 6.1.1.2, Equation (1)
A7: INPUTS | M7: ="⚠️" & ("VARIATION FROM SOURCE: Added 'baled' to variable subscript") -> ⚠️VARIATION FROM SOURCE: Added 'baled' to variable subscript
A8: =HYPERLINK("#'Input - Site'!A1", "Site") -> Site
A9: =HYPERLINK("#'Input - Crop'!A1", "Crop") -> Crop
A10: =HYPERLINK("#'Input - Pasture'!A1", "Pasture") -> Pasture | D10: Variable | E10: M_c
D11: Unit | E11: kg N
A12: CALCULATIONS | M12: Variable | N12: FFOD_cbaled
A13: =HYPERLINK("#'6.1.1.1-2 Crop residue N2O'!A1", "6.1.1.1-2 Crop residue N2O") -> 6.1.1.1-2 Crop residue N2O | D13: P_c | E13: annual production of crop c | G13: kg | H13: Input | I13: ='Input - Crop'!$E$17*10^3 -> 10000 | M13: Unit | N13: dimensionless
A14: =HYPERLINK("#'6.2.1.1-2 Pasture residue N2O'!A1", "6.2.1.1-2 Pasture residue N2O") -> 6.2.1.1-2 Pasture residue N2O | D14: R_AGc | E14: residue to crop ratio for crop c | G14: dimensionless | H14: Constant | I14: ='Input - Crop'!$E$18 -> 1.5
A15: =HYPERLINK("#'6.3.1.1-2 Leaching and runoff'!A1", "6.3.1.1-2 Leaching and runoff") -> 6.3.1.1-2 Leaching and runoff | D15: R_BGc | E15: below ground-residue to above ground residue ratio for crop c | G15: dimensionless | H15: Constant | I15: {=Common_InputFunctions.Utility_LookupValueInTableNumber($I$21,Table_SourceData_CropAttributes[Crop type],Table_SourceData_CropAttributes[Below-ground: above-ground residue ratio])} -> 0.29 | M15: B | N15: number of bales generated | O15: dimensionless | P15: Input | Q15: ='Input - Crop'!$E$35 -> 25000
A16: =HYPERLINK("#'6.4.1.1-2 Residue burning'!A1", "6.4.1.1-2 Residue burning") -> 6.4.1.1-2 Residue burning | D16: F_c | E16: fraction of crop residue that is burnt for crop c | G16: dimensionless | H16: Input | I16: ='Input - Crop'!$E$43 -> 0.3 | M16: M_B | N16: mass of each bale | O16: kg | P16: Input | Q16: ='Input - Crop'!$E$34 -> 60
D17: FFOD_c | E17: fraction of the crop residue that is removed for crop c | G17: dimensionless | H17: Constant | I17: {=IF(ISNUMBER(_xlfn.XLOOKUP(1, (Table77[Crop type c]=$I$21)*(Table77[State]=$I$22),Table77[Fraction removed])), _xlfn.XLOOKUP(1, (Table77[Crop type c]=$I$21)*(Table77[State]=$I$22),Table77[Fraction removed]), 0)} -> 0.11 | M17: P_c | N17: annual production of crop c | O17: kg | P17: Input | Q17: ='Input - Crop'!$E$22*10^3 -> 10000000
A18: APPENDICES | D18: DM_c | E18: dry matter content of crop c | G18: kg dry weight/kg crop residue | H18: Constant | I18: {=Common_InputFunctions.Utility_LookupValueInTableNumber($I$21,Table_SourceData_CropAttributes[Crop type],Table_SourceData_CropAttributes[Dry matter content])} -> 0.88 | M18: R_AGc | N18: residue to crop ratio for crop c | O18: dimensionless | P18: Input | Q18: ='Input - Crop'!$E$18 -> 1.5
A19: =HYPERLINK("#'Constants - Ag Residue'!A1", "Constants - Ag Residue") -> Constants - Ag Residue | D19: NC_AGc | E19: nitrogen content of above-ground crop residue of crop c | G19: kg N/kg DM | H19: Constant | I19: {=Common_InputFunctions.Utility_LookupValueInTableNumber($I$21,Table_SourceData_CropAttributes[Crop type],Table_SourceData_CropAttributes[N content above-ground])} -> 0.006 | M19: c | N19: Crop type | P19: Input | Q19: Wheat
A20: =HYPERLINK("#'Constants - Common'!A1", "Constants - Common") -> Constants - Common | D20: NC_BGc | E20: nitrogen content of below-ground crop residue of crop c | G20: kg N/kg DM | H20: Constant | I20: {=Common_InputFunctions.Utility_LookupValueInTableNumber($I$21,Table_SourceData_CropAttributes[Crop type],Table_SourceData_CropAttributes[N content below-ground])} -> 0.01
D21: c | E21: Crop type | H21: Input | I21: ='Input - Crop'!$E$9 -> Wheat | M21: FFODc,baled | N21: =(IFERROR((Q15 * Q16) / (Q17 * Q18), 0)) -> 0.1
D22: State | E22: State or territory | H22: Input | I22: =Common_InputFunctions.Utility_ConvertStateCommonNameToAbbreviation('Input - Site'!$E$21,Table_AustralianStates[Common Name],Table_AustralianStates[Abbreviation]) -> WA
D24: Mc | E24: =((I13 * I14 * (1 - I16 - I17) * I18 * I19) + (I13 * I14 * I15 * I18 * I20)) -> 85.008 | F24: =$E$11 -> kg N | M24: Fraction of crop residue that is removed for crop c
M26: ="⚠️" & ("VARIATION FROM SOURCE: Added this equation to accommodate user-defined residue removal other than baling.") -> ⚠️VARIATION FROM SOURCE: Added this equation to accommodate user-defined residue removal other than baling.
D28: Nitrous oxide emissions from the return of crop residues across all crops c to the soil
D29: VEERG 2026: 6.1.1.1, Equation (1)
M30: Variable | N30: FFOD_c
M31: Unit | N31: dimensionless
D33: Variable | E33: E | M33: FFOD_cbaled | N33: Fraction of crop residue that is removed for crop c, calculated where residues are baled | Q33: fraction | R33: Calculated from 6.1.1.2, (1) | S33: =$N$21 -> 0.1
D34: Unit | E34: t N2O | M34: FFOD_cother | N34: Fraction of crop residue that is removed for crop c, calculated where residues are removed by other means | Q34: fraction | R34: Input | S34: ='Input - Crop'!$E$39 -> 0.01
D36: M_c | E36: mass of nitrogen in crop c residues returned to the soil | G36: kg N | H36: Calculated from 6.1.1.1 (2) | I36: =E24 -> 85.008 | M36: FFODc | N36: =($S$33 + $S$34) -> 0.11
D37: EF_Ni | E37: emission factor for crop residues returned to the soil | G37: kg N2O-N/kg N | H37: Constant | I37: {=Common_InputFunctions.Utility_LookupValueInTableNumber(I40,Table_SourceData_N2OEFOrganicFert[Climate zone type i],Table_SourceData_N2OEFOrganicFert[EF i N2O])} -> 0.005
D38: C_N2O | E38: factor to convert elemental mass of nitrous oxide to molecular mass | G38: dimensionless | H38: Constant | I38: =Common_InputFunctions.Utility_LookupValueInTableNumber("N2O",Table_GasToMolecularConversionFactor[Gas],Table_GasToMolecularConversionFactor[Conversion factor combined]) -> 1.5714286
D39: c | E39: Crop type | H39: Input | I39: ='Input - Crop'!$E$9 -> Wheat
D40: i | E40: Wet or dry climate zone | H40: Input | I40: ='Input - Site'!$E$32 -> Dry climate zone | M40: Mass of nitrogen in crop residues returned to the soil
M41: VEERG 2026: 6.1.1.1, Equation (2)
D42: EN2O | E42: =(I36 * I37 * I38 * 10 ^ (-3)) -> 0.00066792 | F42: =$E$34 -> t N2O
D44: {=Common_Equations.Common_ConvertN2OToCO2e_Arguments()} -> EN2O | E44: Nitrous oxide emissions (t N2O) | G44: =E42 -> 0.00066792
D45: GWPN2O | E45: Global warming potential for nitrous oxide (t CO2-e / t N2O) | G45: =Common_InputFunctions.Utility_LookupValueInTableNumber("N2O",Table_GWPData[Gas],Table_GWPData[CO2-e factor]) -> 265 | M45: Variable | N45: M_c
M46: Unit | N46: kg N
A47: =HYPERLINK("#A1", "▲ Back to top") -> ▲ Back to top | D47: ECO2e | E47: {=Common_Equations.Common_ConvertN2OToCO2e(G44,G45)} -> 0.1769988 | F47: {=Common_Equations.Common_ConvertN2OToCO2e_Unit()} -> t CO2e
...

Sheet 6.2.1.1-2 Pasture residue N2O
A1: #VALUE! | C1: 6.2.1.1-2 Return of pasture residue to soils
A3: =HYPERLINK("#'Home'!A1", "Home") -> Home | D3: Method 1 | N3: Method 2
A4: =HYPERLINK("#'Overview'!A1", "Overview") -> Overview
A5: =HYPERLINK("#'Results'!A1", "Results") -> Results | D5: Mass of nitrogen in pasture residues returned to the soil
D6: VEERG 2026: 6.2.1.1, Equation (2)
A7: INPUTS
A8: =HYPERLINK("#'Input - Site'!A1", "Site") -> Site
A9: =HYPERLINK("#'Input - Crop'!A1", "Crop") -> Crop
A10: =HYPERLINK("#'Input - Pasture'!A1", "Pasture") -> Pasture | D10: Variable | E10: Mp
D11: Unit | E11: kg N
A12: CALCULATIONS
A13: =HYPERLINK("#'6.1.1.1-2 Crop residue N2O'!A1", "6.1.1.1-2 Crop residue N2O") -> 6.1.1.1-2 Crop residue N2O | D13: A_p | E13: area of pasture renewed or removed | H13: ha | I13: Input | J13: ='Input - Pasture'!$E$25 -> 500 | N13: A_p | O13: area of pasture renewed or removed | R13: ha | S13: Input
A14: =HYPERLINK("#'6.2.1.1-2 Pasture residue N2O'!A1", "6.2.1.1-2 Pasture residue N2O") -> 6.2.1.1-2 Pasture residue N2O | D14: Y_p | E14: average yield of pasture crop | H14: t DM/ha | I14: Constant | J14: {=Common_InputFunctions.Utility_LookupValueInTableNumber($J$19,Table_SourceData_PastureAttributes[Pasture type],Table_SourceData_PastureAttributes[Average Yield (t DM ha) Yp])} -> 8.34 | N14: Y_p | O14: average yield of pasture crop | R14: t DM/ha | S14: Input | T14: ='Input - Pasture'!$E$19 -> 8.34
A15: =HYPERLINK("#'6.3.1.1-2 Leaching and runoff'!A1", "6.3.1.1-2 Leaching and runoff") -> 6.3.1.1-2 Leaching and runoff | D15: NC_AGp | E15: N content of above-ground pasture residue | H15: kg N/kg DM | I15: Constant | J15: {=Common_InputFunctions.Utility_LookupValueInTableNumber($J$19,Table_SourceData_PastureAttributes[Pasture type],Table_SourceData_PastureAttributes[N content Above-ground NCAGp])} -> 0.025 | N15: NC_AGp | O15: N content of above-ground pasture residue | R15: kg N/kg DM | S15: Constant
A16: =HYPERLINK("#'6.4.1.1-2 Residue burning'!A1", "6.4.1.1-2 Residue burning") -> 6.4.1.1-2 Residue burning | D16: R_BGp | E16: below-ground residue to above-ground residue ratio for pasture crop | H16: dimensionless | I16: Constant | J16: {=Common_InputFunctions.Utility_LookupValueInTableNumber($J$19,Table_SourceData_PastureAttributes[Pasture type],Table_SourceData_PastureAttributes[Below-ground: above-ground residue ratio RBGp])} -> 0.8 | N16: R_BGp | O16: below-ground residue to above-ground residue ratio for pasture crop | R16: dimensionless | S16: Constant
D17: NC_BGp | E17: N content of below-ground pasture crop residue | H17: kg N/kg DM | I17: Constant | J17: {=Common_InputFunctions.Utility_LookupValueInTableNumber($J$19,Table_SourceData_PastureAttributes[Pasture type],Table_SourceData_PastureAttributes[N content Below-ground NCBGp])} -> 0.016 | N17: NC_BGp | O17: N content of below-ground pasture crop residue | R17: kg N/kg DM | S17: Constant
A18: APPENDICES | D18: FFOD_p | E18: fraction of pasture yield that is removed | H18: dimensionless | I18: Constant | J18: {=Common_InputFunctions.Utility_LookupValueInTableNumber($J$19,Table_SourceData_PastureAttributes[Pasture type],Table_SourceData_PastureAttributes[Fraction of pasture yield that is removed FFODp])} -> 0.8 | N18: FFOD_p | O18: fraction of pasture yield that is removed | R18: dimensionless | S18: Constant
A19: =HYPERLINK("#'Constants - Ag Residue'!A1", "Constants - Ag Residue") -> Constants - Ag Residue | D19: p | E19: Pasture type | I19: Input | J19: ='Input - Pasture'!$E$9 -> Grass clover mixture | N19: p | O19: Pasture type | S19: Input
A20: =HYPERLINK("#'Constants - Common'!A1", "Constants - Common") -> Constants - Common
D21: Mp | E21: =((J13 * (J14 * 10 ^ (-3)) * (1 - J18) * J15) + (J13 * (J14 * 10 ^ (-3)) * J16 * J17)) -> 0.074226 | F21: kg N | N21: Mp | O21: =((J13 * (T14 * 10 ^ (-3)) * (1 - J18) * J15) + (J13 * (T14 * 10 ^ (-3)) * J16 * J17)) -> 0.074226 | P21: kg N
D25: Nitrous oxide emissions from the return of pasture residues from all pasture types to the soil | N25: Nitrous oxide emissions from the return of pasture residues from all pasture types to the soil
D26: VEERG 2026: 6.2.1.1, Equation (1) | N26: VEERG 2026: 6.2.1.1, Equation (1)
D30: Variable | E30: EN2O | N30: Variable | O30: EN2O
D31: Unit | E31: t N2O | N31: Unit | O31: t N2O
D33: M_p | E33: mass of nitrogen in pasture p residues returned to the soil | H33: kg N | I33: Calculated from 6.2.1.1 (2) | J33: =$E$21 -> 0.074226 | N33: M_p | O33: mass of nitrogen in pasture p residues returned to the soil | R33: kg N | S33: Calculated from 6.2.1.1 (2) | T33: =$O$21 -> 0.074226
D34: EF_Ni | E34: emission factor for crop residues returned to the soil in climate zone i | H34: kg N2O-N/kg N | I34: Constant | J34: {=Common_InputFunctions.Utility_LookupValueInTableNumber(J37,Table_SourceData_N2OEFOrganicFert[Climate zone type i],Table_SourceData_N2OEFOrganicFert[EF i N2O])} -> 0.005 | N34: EF_Ni | O34: emission factor for crop residues returned to the soil in climate zone i | R34: kg N2O-N/kg N | S34: Constant
D35: C_N2O | E35: factor to convert elemental mass of nitrous oxide to molecular mass | H35: dimensionless | I35: Constant | J35: =Common_InputFunctions.Utility_LookupValueInTableNumber("N2O",Table_GasToMolecularConversionFactor[Gas],Table_GasToMolecularConversionFactor[Conversion factor combined]) -> 1.5714286 | N35: C_N2O | O35: factor to convert elemental mass of nitrous oxide to molecular mass | R35: dimensionless | S35: Constant
D36: p | E36: Pasture type | I36: Input | J36: ='Input - Pasture'!$E$9 -> Grass clover mixture | N36: p | O36: Pasture type | S36: Input
D37: i | E37: Wet or dry climate zone | I37: Input | J37: ='Input - Site'!$E$32 -> Dry climate zone | N37: i | O37: Wet or dry climate zone | S37: Input
D40: EN2O | E40: =((J33 * J34) * J35 * 10 ^ (-3)) -> 5.8320429e-07 | F40: t N2O | N40: EN2O | O40: =((T33 * J34) * J35 * 10 ^ (-3)) -> 5.8320429e-07 | P40: t N2O
D42: {=Common_Equations.Common_ConvertN2OToCO2e_Arguments()} -> EN2O | E42: Nitrous oxide emissions (t N2O) | G42: =E40 -> 5.8320429e-07 | N42: {=Common_Equations.Common_ConvertN2OToCO2e_Arguments()} -> EN2O | O42: Nitrous oxide emissions (t N2O) | Q42: =O40 -> 5.8320429e-07
D43: GWPN2O | E43: Global warming potential for nitrous oxide (t CO2-e / t N2O) | G43: =Common_InputFunctions.Utility_LookupValueInTableNumber("N2O",Table_GWPData[Gas],Table_GWPData[CO2-e factor]) -> 265 | N43: GWPN2O | O43: Global warming potential for nitrous oxide (t CO2-e / t N2O) | Q43: =Common_InputFunctions.Utility_LookupValueInTableNumber("N2O",Table_GWPData[Gas],Table_GWPData[CO2-e factor]) -> 265
A45: =HYPERLINK("#A1", "▲ Back to top") -> ▲ Back to top | D45: EN2O GWP | E45: {=Common_Equations.Common_ConvertN2OToCO2e(G42,G43)} -> 0.00015454914 | F45: {=Common_Equations.Common_ConvertN2OToCO2e_Unit()} -> t CO2e | N45: EN2O GWP | O45: {=Common_Equations.Common_ConvertN2OToCO2e(Q42,Q43)} -> 0.00015454914 | P45: {=Common_Equations.Common_ConvertN2OToCO2e_Unit()} -> t CO2e
A76: =HYPERLINK("#A1", "▲ Back to top") -> ▲ Back to top

Sheet 6.3.1.1-2 Leaching and runoff
A1: #VALUE! | C1: 6.3.1.1-2 Leaching and run-off from crop and pasture residues
A3: =HYPERLINK("#'Home'!A1", "Home") -> Home | D3: Method 1 | N3: Method 2
A4: =HYPERLINK("#'Overview'!A1", "Overview") -> Overview
A5: =HYPERLINK("#'Results'!A1", "Results") -> Results | D5: Mass of nitrogen lost through leaching and runoff
D6: VEERG 2026: 6.3.1.1, Equation (2)
A7: INPUTS
A8: =HYPERLINK("#'Input - Site'!A1", "Site") -> Site
A9: =HYPERLINK("#'Input - Crop'!A1", "Crop") -> Crop
A10: =HYPERLINK("#'Input - Pasture'!A1", "Pasture") -> Pasture | D10: Variable | E10: M_leachcp
D11: Unit | E11: kg N
A12: CALCULATIONS
A13: =HYPERLINK("#'6.1.1.1-2 Crop residue N2O'!A1", "6.1.1.1-2 Crop residue N2O") -> 6.1.1.1-2 Crop residue N2O | D13: M_cp | E13: mass of nitrogen in crop residues c or pasture residues p applied to soils | H13: kg N | I13: Calc from 6.1.1.1 (2) and 6.2.1.1 (2) | J13: {=HYPERLINK(Common_InputFunctions.Utility_SourceHyperlink($D$21), $D$21)} -> M1_Table_M_leach_cp
A14: =HYPERLINK("#'6.2.1.1-2 Pasture residue N2O'!A1", "6.2.1.1-2 Pasture residue N2O") -> 6.2.1.1-2 Pasture residue N2O | D14: FracWET_j | E14: fraction of N that is available for leaching and runoff from the leaching zone z and irrigation type ir | H14: dimensionless | I14: Constant | J14: {=HYPERLINK(Common_InputFunctions.Utility_SourceHyperlink($D$21), $D$21)} -> M1_Table_M_leach_cp
A15: =HYPERLINK("#'6.3.1.1-2 Leaching and runoff'!A1", "6.3.1.1-2 Leaching and runoff") -> 6.3.1.1-2 Leaching and runoff | D15: FracLEACH | E15: fraction of N that is lost through leaching and runoff | H15: dimensionless | I15: Constant | J15: ='Constants - Common'!$E$164 -> 0
A16: =HYPERLINK("#'6.4.1.1-2 Residue burning'!A1", "6.4.1.1-2 Residue burning") -> 6.4.1.1-2 Residue burning | D16: z | E16: Location in leaching zone | I16: Input | J16: {=HYPERLINK(Common_InputFunctions.Utility_SourceHyperlink($D$21), $D$21)} -> M1_Table_M_leach_cp
D17: c | E17: Crop residue type | I17: Input | J17: ='Input - Crop'!$E$9 -> Wheat
A18: APPENDICES | D18: p | E18: Pasture residue type | I18: Input | J18: ='Input - Pasture'!$E$9 -> Grass clover mixture
A19: =HYPERLINK("#'Constants - Ag Residue'!A1", "Constants - Ag Residue") -> Constants - Ag Residue | D19: ir | E19: Irrigation type | I19: Input | J19: {=HYPERLINK(Common_InputFunctions.Utility_SourceHyperlink($D$21), $D$21)} -> M1_Table_M_leach_cp
A20: =HYPERLINK("#'Constants - Common'!A1", "Constants - Common") -> Constants - Common
D21: M1_Table_M_leach_cp | N21: M1_Table_M_leach_cp
D22: Mass of nitrogen lost through leaching and runoff (Method 1) | N22: Mass of nitrogen lost through leaching and runoff (Method 1)
D23: Crop or pasture | E23: M_cp | F23: Irrigation | G23: Leaching zone | H23: FracWET_j | I23: M_leachcp | N23: Crop or pasture | O23: M_cp | P23: Irrigation | Q23: Leaching zone | R23: FracWET_j | S23: M_leachcp
D24: Crop | E24: ='6.1.1.1-2 Crop residue N2O'!$E$24 -> 85.008 | F24: ='Input - Crop'!$E$11 -> Sprinkler irrigation | G24: ='Input - Site'!E$23 -> NO - Not in leaching zone | H24: =CommonCropping_InputFunctions.CommonCropping_GetFracWET(G24,F24,#REF!,#REF!, Table_SourceData_FracWETIrrigation[Irrigation type i],Table_SourceData_FracWETIrrigation[FracWET]) -> 1 | I24: =(E24 * H24 * $J$15) -> 0 | O24: ='6.1.1.1-2 Crop residue N2O'!$N$59 -> 85.008 | S24: =(O24 * H24 * $J$15) -> 0
D25: Pasture | E25: ='6.2.1.1-2 Pasture residue N2O'!$E$21 -> 0.074226 | F25: ='Input - Pasture'!$E$10 -> Surface irrigation | G25: ='Input - Site'!E$23 -> NO - Not in leaching zone | H25: =CommonCropping_InputFunctions.CommonCropping_GetFracWET(G25,F25,#REF!,#REF!, Table_SourceData_FracWETIrrigation[Irrigation type i],Table_SourceData_FracWETIrrigation[FracWET]) -> 1 | I25: =(E25 * H25 * $J$15) -> 0 | O25: ='6.2.1.1-2 Pasture residue N2O'!$O$21 -> 0.074226 | S25: =(O25 * H25 * $J$15) -> 0
D28: Nitrous oxide leaching and runoff emissions from crop and pasture residues returned to the soil
D29: VEERG 2026: 6.3.1.1, Equation (1)
D33: Variable | E33: EN2O
A34: =HYPERLINK("#A1", "▲ Back to top") -> ▲ Back to top | D34: Unit | E34: t N2O
D36: M_leachcp | E36: mass of nitrogen lost through leaching and runoff from the crop residue c or pasture residue p | H36: kg N | I36: Calculated from 6.3.1.1 (2) | J36: {=HYPERLINK(Common_InputFunctions.Utility_SourceHyperlink($D$21), $D$21)} -> M1_Table_M_leach_cp
D37: EF_leach | E37: emission factor for leaching and runoff | H37: kg N2O-N/kg N | I37: Constant | J37: ='Constants - Common'!$E$170 -> 0
D38: C_N2O | E38: factor to convert elemental mass of nitrous oxide to molecular mass | H38: dimensionless | I38: Constant | J38: =Common_InputFunctions.Utility_LookupValueInTableNumber("N2O",Table_GasToMolecularConversionFactor[Gas],Table_GasToMolecularConversionFactor[Conversion factor combined]) -> 1.5714286
D39: c | E39: Crop residue type | I39: Input | J39: ='[1]Input - Grains'!$E$9 -> Wheat
D40: p | E40: Pasture residue type | I40: Input | J40: ='Input - Pasture'!$E$9 -> Grass clover mixture
D42: M1_Table_E_N2O | N42: M1_Table_E_N2O
D43: Nitrous oxide leaching and runoff emissions (Method 1) | N43: Nitrous oxide leaching and runoff emissions (Method 1)
D44: M_leachcp | E44: E_N2O | N44: M_leachcp | O44: E_N2O
D45: =I24 -> 0 | E45: =(D45 * $J$37 * $J$38 * 10 ^ (-3)) -> 0 | N45: =S24 -> 0 | O45: =(N45 * $J$37 * $J$38 * 10 ^ (-3)) -> 0
D46: =I25 -> 0 | E46: =(D46 * $J$37 * $J$38 * 10 ^ (-3)) -> 0 | N46: =S25 -> 0 | O46: =(N46 * $J$37 * $J$38 * 10 ^ (-3)) -> 0
D48: EN2O | E48: =SUM(E45:E46) -> 0 | F48: =$E$34 -> t N2O | N48: EN2O | O48: =SUM(O45:O46) -> 0 | P48: =$E$34 -> t N2O
D50: {=Common_Equations.Common_ConvertN2OToCO2e_Arguments()} -> EN2O | E50: Nitrous oxide emissions (t N2O) | G50: =E48 -> 0 | N50: {=Common_Equations.Common_ConvertN2OToCO2e_Arguments()} -> EN2O | O50: Nitrous oxide emissions (t N2O) | Q50: =O48 -> 0
...

Sheet 6.4.1.1-2 Residue burning
A1: #VALUE! | C1: 6.4.1.1-2 Field burning of crop residues
A3: =HYPERLINK("#'Home'!A1", "Home") -> Home | D3: Method 1 | M3: Method 2
A4: =HYPERLINK("#'Overview'!A1", "Overview") -> Overview
A5: =HYPERLINK("#'Results'!A1", "Results") -> Results | D5: Mass of residue of crop c burnt
D6: VEERG 2026: 6.4.1.1, Equation (3)
A7: INPUTS
A8: =HYPERLINK("#'Input - Site'!A1", "Site") -> Site
A9: =HYPERLINK("#'Input - Crop'!A1", "Crop") -> Crop
A10: =HYPERLINK("#'Input - Pasture'!A1", "Pasture") -> Pasture | D10: Variable | E10: M_burnc
D11: Unit | E11: kg
A12: CALCULATIONS
A13: =HYPERLINK("#'6.1.1.1-2 Crop residue N2O'!A1", "6.1.1.1-2 Crop residue N2O") -> 6.1.1.1-2 Crop residue N2O | D13: P_c | E13: annual production of crop type c | G13: kg | H13: Input | I13: ='Input - Crop'!$E$22 -> 10000
A14: =HYPERLINK("#'6.2.1.1-2 Pasture residue N2O'!A1", "6.2.1.1-2 Pasture residue N2O") -> 6.2.1.1-2 Pasture residue N2O | D14: R_AGc | E14: residue to crop ratio of crop type c | G14: kg crop residue/kg crop | H14: Constant | I14: ='Input - Crop'!$E$18 -> 1.5
A15: =HYPERLINK("#'6.3.1.1-2 Leaching and runoff'!A1", "6.3.1.1-2 Leaching and runoff") -> 6.3.1.1-2 Leaching and runoff | D15: S_c | E15: fraction of residues of crop type c remaining at burning | G15: dimensionless | H15: Constant | I15: {=Common_InputFunctions.Utility_LookupValueInTableNumber($I$19,Table_SourceData_CropAttributes[Crop type],Table_SourceData_CropAttributes[Fraction of residue remaining at time of burning (b)])} -> 0.5
A16: =HYPERLINK("#'6.4.1.1-2 Residue burning'!A1", "6.4.1.1-2 Residue burning") -> 6.4.1.1-2 Residue burning | D16: DM_c | E16: dry matter content of crop type c | G16: kg dry weight/kg crop residue | H16: Constant | I16: {=Common_InputFunctions.Utility_LookupValueInTableNumber($I$19,Table_SourceData_CropAttributes[Crop type],Table_SourceData_CropAttributes[Dry matter content])} -> 0.88
D17: Z_c | E17: burning efficiency (ratio of fuel burnt to fuel load) of crop type c | G17: dimensionless | H17: Constant | I17: {=Common_InputFunctions.Utility_LookupValueInTableNumber($I$19,Table_SourceData_CropAttributes[Crop type],Table_SourceData_CropAttributes[Fraction burnt])} -> 0.9
A18: APPENDICES | D18: F_c | E18: fraction of the annual production of crop type c that is burnt | G18: dimensionless | H18: Constant | I18: ='Input - Crop'!$E$43 -> 0.3
A19: =HYPERLINK("#'Constants - Ag Residue'!A1", "Constants - Ag Residue") -> Constants - Ag Residue | D19: c | E19: Crop type | H19: Input | I19: ='Input - Crop'!$E$9 -> Wheat
A20: =HYPERLINK("#'Constants - Common'!A1", "Constants - Common") -> Constants - Common
D21: Mburn,c | E21: =(I13 * I14 * I15 * I16 * I17 * I18) -> 1782 | F21: kg
D25: Nitrous oxide emissions from the burning of crop residues
D26: VEERG 2026: 6.4.1.1, Equation (2)
D30: Variable | E30: EN2O
D31: Unit | E31: t N2O
D33: M_burnc | E33: mass of residue burnt for crop type c | G33: kg | H33: Calculated from 6.4.1.1 (3) | I33: =$E$21 -> 1782
D34: NC_AGc | E34: nitrogen content in the above-ground residue of crop type c | G34: kg N/kg DM | H34: Constant | I34: {=Common_InputFunctions.Utility_LookupValueInTableNumber($I$37,Table_SourceData_CropAttributes[Crop type],Table_SourceData_CropAttributes[N content above-ground])} -> 0.006
D35: EF_N2O | E35: emission factor for nitrous oxide from burning of crop residues | G35: kg N2O/kg N2O burnt | H35: Constant | I35: {=Common_InputFunctions.Utility_LookupValueInTableNumber("N2O", Table_SourceData_BurningResidueEFs[Gas species],Table_SourceData_BurningResidueEFs[Emission factor EFg (Gg element in species/ Gg element in fuel burnt)])} -> 0.0076
D36: C_N2O | E36: factor to convert elemental mass of nitrous oxide to molecular mass | G36: dimensionless | H36: Constant | I36: =Common_InputFunctions.Utility_LookupValueInTableNumber("N2O",Table_GasToMolecularConversionFactor[Gas],Table_GasToMolecularConversionFactor[Conversion factor combined]) -> 1.5714286
D37: c | E37: Crop type | H37: Input | I37: ='Input - Crop'!$E$9 -> Wheat
D39: EN2O | E39: =((I33 * I34) * I35 * I36 * 10 ^ (-3)) -> 0.00012769303 | F39: t N2O
D41: {=Common_Equations.Common_ConvertN2OToCO2e_Arguments()} -> EN2O | E41: Nitrous oxide emissions (t N2O) | H41: =E39 -> 0.00012769303
D42: GWPN2O | E42: Global warming potential for nitrous oxide (t CO2-e / t N2O) | H42: =Common_InputFunctions.Utility_LookupValueInTableNumber("N2O",Table_GWPData[Gas],Table_GWPData[CO2-e factor]) -> 265
D44: ECO2e | E44: {=Common_Equations.Common_ConvertN2OToCO2e(H41,H42)} -> 0.033838653 | F44: {=Common_Equations.Common_ConvertN2OToCO2e_Unit()} -> t CO2e
A46: =HYPERLINK("#A1", "▲ Back to top") -> ▲ Back to top
D48: Methane emissions from the burning of crop residues
D49: VEERG 2026: 6.4.1.1, Equation (1)
D53: Variable | E53: ECH4
D54: Unit | E54: t CH4
D56: M_burnc | E56: mass of residue burnt for crop type c | G56: kg | H56: Calculated from 6.4.1.1 (3) | I56: =$E$21 -> 1782
D57: CC_c | E57: carbon mass fraction in the residues of crop type c | G57: dimensionless | H57: Constant | I57: {=Common_InputFunctions.Utility_LookupValueInTableNumber($I$60,Table_SourceData_CropAttributes[Crop type],Table_SourceData_CropAttributes[Carbon fraction in dry matter])} -> 0.4
...

Sheet Constants - Ag Residue
A1: #VALUE! | C1: Constants - Agricultural residue
A3: =HYPERLINK("#'Home'!A1", "Home") -> Home
A4: =HYPERLINK("#'Overview'!A1", "Overview") -> Overview
A5: =HYPERLINK("#'Results'!A1", "Results") -> Results | D5: Crop purpose and yield
A7: INPUTS | D7: Purpose | E7: Per hectare unit | F7: harvest term | G7: harvest endpoint | H7: Harvest uit | I7: Yield note | J7: Residue crop ratio note | K7: Total production note
A8: =HYPERLINK("#'Input - Site'!A1", "Site") -> Site | D8: Cash grain crop | E8: grain | F8: yield | G8: harvest | H8: grain | I8: Yield is the grain harvested from the plant | J8: Residue to crop ratio is provided from default values | K8: Total production is the total grain harvested
A9: =HYPERLINK("#'Input - Crop'!A1", "Crop") -> Crop | D9: Cash crop for hay/silage | E9: above ground biomass | F9: yield | G9: harvest | H9: plant biomass | I9: Yield is the whole plant harvested for hay/silage | J9: Residue to crop ratio is 0 assuming the whole plant is harvested for hay/silage | K9: Total production is the total whole plant biomass harvested as hay/silage
A10: =HYPERLINK("#'Input - Pasture'!A1", "Pasture") -> Pasture | D10: Cover crop | E10: above ground biomass | F10: mass | G10: end of crop cycle | H10: above ground biomass | I10: Yield is the whole plant kept as cover crop | J10: Residue to crop ratio is 1 assuming the whole plant is kept as cover crop | K10: Total production is the total whole plant biomass kept as cover crop
A12: CALCULATIONS
A13: =HYPERLINK("#'6.1.1.1-2 Crop residue N2O'!A1", "6.1.1.1-2 Crop residue N2O") -> 6.1.1.1-2 Crop residue N2O
A14: =HYPERLINK("#'6.2.1.1-2 Pasture residue N2O'!A1", "6.2.1.1-2 Pasture residue N2O") -> 6.2.1.1-2 Pasture residue N2O
A15: =HYPERLINK("#'6.3.1.1-2 Leaching and runoff'!A1", "6.3.1.1-2 Leaching and runoff") -> 6.3.1.1-2 Leaching and runoff | D15: Table A.2.1.1: Crop attributes
A16: =HYPERLINK("#'6.4.1.1-2 Residue burning'!A1", "6.4.1.1-2 Residue burning") -> 6.4.1.1-2 Residue burning | D16: VEERG 2026: Table A.2.1.1: Crop attributes
D17: {="⚠️" & Agresidue_SourceData.CropAttributes_Variation()} -> ⚠️VARIATION FROM SOURCE: 'N/A' values passed as zero for calculations.
A18: APPENDICES
A19: =HYPERLINK("#'Constants - Ag Residue'!A1", "Constants - Ag Residue") -> Constants - Ag Residue | D19: Crop type | E19: Residue: Crop ratio | F19: Below-ground: above-ground residue ratio | G19: Dry matter content | H19: Carbon fraction in dry matter | I19: N content above-ground | J19: N content below-ground | K19: Fraction of residue remaining at time of burning (b) | L19: Fraction burnt | N19: Irrigation methods
A20: =HYPERLINK("#'Constants - Common'!A1", "Constants - Common") -> Constants - Common | D20: Wheat | E20: 1.5 | F20: 0.29 | G20: 0.88 | H20: 0.4 | I20: 0.006 | J20: 0.01 | K20: 0.5 | L20: 0.9
D21: Barley | E21: 1.24 | F21: 0.32 | G21: 0.88 | H21: 0.4 | I21: 0.007 | J21: 0.01 | K21: 0.5 | L21: 0.85 | N21: Irrigation method
D22: Maize | E22: 0.81 | F22: 0.39 | G22: 0.85 | H22: 0.42 | I22: 0.005 | J22: 0.007 | K22: 1 | L22: 0.8 | N22: Not irrigated
D23: Oats | E23: 1.42 | F23: 0.43 | G23: 0.88 | H23: 0.4 | I23: 0.006 | J23: 0.01 | K23: 0.5 | L23: 0.85 | N23: Drip irrigation
D24: Rice | E24: 1.31 | F24: 0.16 | G24: 0.8 | H24: 0.42 | I24: 0.007 | J24: 0.01 | K24: 1 | L24: 0.8 | N24: Sprinkler irrigation
D25: Sorghum | E25: 1.5 | F25: 0.22 | G25: 0.8 | H25: 0.4 | I25: 0.008 | J25: 0.007 | K25: 0.5 | L25: 0.85 | N25: Surface irrigation
D26: Triticale | E26: 1.5 | F26: 0.42 | G26: 0.88 | H26: 0.4 | I26: 0.006 | J26: 0.01 | K26: 0.5 | L26: 0.85 | N26: Other irrigation
D27: Other cereals | E27: 1.46 | F27: 0.36 | G27: 0.88 | H27: 0.4 | I27: 0.006 | J27: 0.01 | K27: 0.5 | L27: 0.85
D28: Pulses | E28: 1.37 | F28: 0.51 | G28: 0.87 | H28: 0.4 | I28: 0.009 | J28: 0.01 | K28: 0.5 | L28: 0.85
D29: Tubers and roots | E29: 0.34 | F29: 0.43 | G29: 0.25 | H29: 0.4 | I29: 0.02 | J29: 0.01 | K29: n/a | L29: 0.85
D30: Peanuts | E30: 1.07 | F30: 0.2 | G30: 0.8 | H30: 0.42 | I30: 0.016 | J30: 0.014 | K30: 0.5 | L30: 0.85
D31: Sugar cane | E31: 0.25 | F31: 0.45 | G31: 0.2 | H31: 0.4 | I31: 0.005 | J31: 0.007 | K31: 1 | L31: 0.8
D32: Cotton | E32: 1.9 | F32: 0.3 | G32: 0.9 | H32: 0.4 | I32: 0.01 | J32: 0.01 | K32: n/a | L32: 0.85
D33: Hops | E33: 1.5 | F33: 0.29 | G33: 0.88 | H33: 0.4 | I33: 0.006 | J33: n/a | K33: n/a | L33: 0.85
D34: Oilseeds | E34: 2.08 | F34: 0.33 | G34: 0.96 | H34: 0.4 | I34: 0.009 | J34: 0.01 | K34: 0.5 | L34: 0.85
D35: Forage crops | E35: 1.34 | F35: 0.37 | G35: 0.88 | H35: 0.4 | I35: 0.006 | J35: 0.01 | K35: n/a | L35: 0.85
D36: Other annual crops | E36: 1 | F36: 0.22 | G36: 0.85 | H36: 0.4 | I36: 0.008 | J36: 0.009 | K36: n/a | L36: n/a
D37: Other perennial crops | E37: 1.5 | F37: 0.29 | G37: 0.88 | H37: 0.4 | I37: 0.006 | J37: n/a | K37: n/a | L37: n/a
D40: Emission factor for organic fertiliser and crop residues returned to the soil
D41: VEERG 2026: Table A.2.1.4
D43: Climate zone type i | E43: EF i N2O
D44: Wet climate zone | E44: 0.006
D45: Dry climate zone | E45: 0.005
D48: Table A.2.1.3 Pasture attributes
...

Sheet Constants - Common
A1: #VALUE! | C1: Constants - Common
D5: Australian states and territories
D6: State/Territory | E6: Common Name | F6: Abbreviation
D7: New South Wales | E7: New South Wales | F7: NSW
D8: Australian Capital Territory | E8: ACT | F8: ACT
D9: Victoria | E9: Victoria | F9: VIC
D10: Queensland | E10: Queensland | F10: QLD
D11: South Australia | E11: South Australia | F11: SA
D12: Western Australia | E12: Western Australia | F12: WA
D13: Tasmania | E13: Tasmania | F13: TAS
D14: Northern Territory | E14: Northern Territory | F14: NT
D18: ABS Statistcal Areas Level 4 - Western Australia
D19: Australian Bureau of Statistics (ABS) - Statistical Areas Level 2 - 2021 - Shapefile
D20: SA 4 Name
D21: Bunbury
D22: Mandurah
D23: Perth - Inner
D24: Perth - North East
D25: Perth - North West
D26: Perth - South East
D27: Perth - South West
D28: Western Australia - Wheat Belt
D29: Western Australia - Outback (North)
... D35: XXXXXXX
D36: Gas | E36: CO2-e factor
D37: CO2 | E37: 1
D38: CH4 | E38: 28
D39: N2O | E39: 265
D40: CF4 | E40: 6630
D41: C2F6 | E41: 12200
D42: SF6 | E42: 22800
D43: NF3 | E43: 17200
D45: Factor to convert elemental mass of gas to molecular mass
D46: XXXXXXX
D47: Gas | E47: Conversion factor | F47: Conversion factor 1 | G47: Conversion factor 2 | H47: Conversion factor combined
D48: CO2 | E48: 44/12 | F48: 44 | G48: 12 | H48: =Table_GasToMolecularConversionFactor[[#This Row],[Conversion factor 1]]/Table_GasToMolecularConversionFactor[[#This Row],[Conversion factor 2]] -> 3.6666667
D49: CH4 | E49: 16/12 | F49: 16 | G49: 12 | H49: =Table_GasToMolecularConversionFactor[[#This Row],[Conversion factor 1]]/Table_GasToMolecularConversionFactor[[#This Row],[Conversion factor 2]] -> 1.3333333
D50: N2O | E50: 44/28 | F50: 44 | G50: 28 | H50: =Table_GasToMolecularConversionFactor[[#This Row],[Conversion factor 1]]/Table_GasToMolecularConversionFactor[[#This Row],[Conversion factor 2]] -> 1.5714286
D51: Nox | E51: 46/14 | F51: 46 | G51: 14 | H51: =Table_GasToMolecularConversionFactor[[#This Row],[Conversion factor 1]]/Table_GasToMolecularConversionFactor[[#This Row],[Conversion factor 2]] -> 3.2857143
D52: CO | E52: 28/12 | F52: 28 | G52: 12 | H52: =Table_GasToMolecularConversionFactor[[#This Row],[Conversion factor 1]]/Table_GasToMolecularConversionFactor[[#This Row],[Conversion factor 2]] -> 2.3333333
...
