Workbook
Name Common_Equations.Common_ConvertCH4ToCO2e: _xlfn.LAMBDA(_xlpm.E_CH4,_xlpm.GWP_CH4, _xlpm.E_CH4 * _xlpm.GWP_CH4)
Name Common_Equations.Common_ConvertCH4ToCO2e_Arguments: _xlfn.LAMBDA(_xlfn.MAKEARRAY(2, 2, _xlfn.LAMBDA(_xlpm.r,_xlpm.c, INDEX({"ECH4","Methane emissions (t CH4)";"GWPCH4","Global warming potential for methane (t CO2-e / t CH4)"}, _xlpm.r, _xlpm.c))))
Name Common_Equations.Common_ConvertCH4ToCO2e_LatexEquation: _xlfn.LAMBDA("CO2_e = E_{CH4} \times GWP_{CH4}")
Name Common_Equations.Common_ConvertCH4ToCO2e_NIRReference: _xlfn.LAMBDA("")
Name Common_Equations.Common_ConvertCH4ToCO2e_Title: _xlfn.LAMBDA("Convert methane emissions to carbon dioxide equivalent emissions")
Name Common_Equations.Common_ConvertCH4ToCO2e_Unit: _xlfn.LAMBDA("t CO2e")
Name Common_Equations.Common_ConvertCH4ToCO2e_Variable: _xlfn.LAMBDA("ECH4 CO2e")
Name Common_Equations.Common_ConvertN2OToCO2e: _xlfn.LAMBDA(_xlpm.E_N2O,_xlpm.GWP_N2O, _xlpm.E_N2O * _xlpm.GWP_N2O)
Name Common_Equations.Common_ConvertN2OToCO2e_LatexEquation: _xlfn.LAMBDA("CO2_e = E_{N2O} \times GWP_{N2O}")
Name Common_Equations.Common_ConvertN2OToCO2e_NIRReference: _xlfn.LAMBDA("")
Name Common_Equations.Common_ConvertN2OToCO2e_Title: _xlfn.LAMBDA("Convert nitrous oxide emissions to carbon dioxide equivalent emissions")
Name Common_Equations.Common_ConvertN2OToCO2e_Unit: _xlfn.LAMBDA("t CO2e")
Name Common_Equations.Common_ConvertN2OToCO2e_Variable: _xlfn.LAMBDA("EN2O CO2e")
Name Common_InputFunctions.Utility_ConvertStateCommonNameToAbbreviation: _xlfn.LAMBDA(_xlpm.StateCommonName,_xlpm.StateCommonNameArray,_xlpm.StateAbbreviationArray, _xlfn.XLOOKUP(_xlpm.StateCommonName, _xlpm.StateCommonNameArray, _xlpm.StateAbbreviationArray, ""))
Name Common_InputFunctions.Utility_DisplayArguments_1_2: _xlfn.LAMBDA(_xlpm.ArgumentsArray, _xlfn.CHOOSECOLS(_xlpm.ArgumentsArray, 1, 2))
Name Common_InputFunctions.Utility_DisplayArguments_3_4: _xlfn.LAMBDA(_xlpm.ArgumentsArray, _xlfn.CHOOSECOLS(_xlpm.ArgumentsArray, 3, 4))
Name Common_InputFunctions.Utility_DisplayFunctionName: _xlfn.LAMBDA(_xlpm.Function, _xlfn.TEXTBEFORE(_xlfn.FORMULATEXT(_xlpm.Function), "("))
Name Common_InputFunctions.Utility_GetArrayTableColumnStartNumber: _xlfn.LAMBDA(_xlpm.TableHeaderCell, COLUMN(_xlpm.TableHeaderCell))
Name Common_InputFunctions.Utility_GetArrayTableRowStartNumber: _xlfn.LAMBDA(_xlpm.TableheaderCell,_xlpm.RowsBetweenHeaderandArray, ROW(_xlpm.TableheaderCell) + _xlpm.RowsBetweenHeaderandArray - 1)
Name Common_InputFunctions.Utility_LookupValueInTable: _xlfn.LAMBDA(_xlpm.LookupValue,_xlpm.LookupArray,_xlpm.ReturnArray, _xlfn.XLOOKUP(_xlpm.LookupValue, _xlpm.LookupArray, _xlpm.ReturnArray, ""))
Name Common_InputFunctions.Utility_SourceHyperlink: _xlfn.LAMBDA(_xlpm.TargetCell, _xlfn.LET(_xlpm.sh, _xlfn.TEXTAFTER(CELL("filename", _xlpm.TargetCell), "]"), _xlpm.addr, CELL("address", _xlpm.TargetCell), "#'" & _xlpm.sh & "'!" & _xlpm.addr))
Name Common_SourceData.Common_SourceData_AustralianStatesTerritories_Source: _xlfn.LAMBDA("")
Name Common_SourceData.Common_SourceData_AustralianStatesTerritories_Title: _xlfn.LAMBDA("Australian states and territories")
Name Common_SourceData.Common_SourceData_AustralianStatesTerritories_Unit: _xlfn.LAMBDA("")
Name Common_SourceData.Common_SourceData_AustralianStatesTerritories_Variable: _xlfn.LAMBDA("")
Name Common_SourceData.Common_SourceData_ClimateZones_Source: _xlfn.LAMBDA("VEERG 2026: Table 1.3: Climate and Rainfall zone classifications and definitions")
Name Common_SourceData.Common_SourceData_ClimateZones_Title: _xlfn.LAMBDA("VEERG Australian climate zones")
Name Common_SourceData.Common_SourceData_ClimateZones_Unit: _xlfn.LAMBDA("")
Name Common_SourceData.Common_SourceData_ClimateZones_Variable: _xlfn.LAMBDA("")
Name Common_SourceData.Common_SourceData_ConvertGasElementalToMolecular_Source: _xlfn.LAMBDA("XXXXXXX")
Name Common_SourceData.Common_SourceData_ConvertGasElementalToMolecular_Title: _xlfn.LAMBDA("Factor to convert elemental mass of gas to molecular mass")
Name Common_SourceData.Common_SourceData_ConvertGasElementalToMolecular_Unit: _xlfn.LAMBDA("factor")
Name Common_SourceData.Common_SourceData_ConvertGasElementalToMolecular_Variable: _xlfn.LAMBDA("Cg")
Name Common_SourceData.Common_SourceData_ConvertN2oElementalToMolecularCg_Data: _xlfn.LAMBDA(44 / 28)
Name Common_SourceData.Common_SourceData_ConvertN2oElementalToMolecularCg_Source: _xlfn.LAMBDA("National Inventory Report 2023 Volume 1")
Name Common_SourceData.Common_SourceData_ConvertN2oElementalToMolecularCg_Title: _xlfn.LAMBDA("Factor to convert elemental mass of N2O to molecular mass")
Name Common_SourceData.Common_SourceData_ConvertN2oElementalToMolecularCg_Unit: _xlfn.LAMBDA("factor")
Name Common_SourceData.Common_SourceData_ConvertN2oElementalToMolecularCg_Variable: _xlfn.LAMBDA("CgN2O")
Name Common_SourceData.Common_SourceData_DataScores_Scope3_Source: _xlfn.LAMBDA("VEERG 2026: XXXXXXXX")
Name Common_SourceData.Common_SourceData_DataScores_Scope3_Title: _xlfn.LAMBDA("Australian data scores for scope 3")
Name Common_SourceData.Common_SourceData_DataScores_Scope3_Unit: _xlfn.LAMBDA("")
Name Common_SourceData.Common_SourceData_DataScores_Scope3_Variable: _xlfn.LAMBDA("")
Name Common_SourceData.Common_SourceData_DataScores_Scope3_Variation: _xlfn.LAMBDA("")
Name Common_SourceData.Common_SourceData_DensityOfMethane_Data: _xlfn.LAMBDA(0.6784)
Name Common_SourceData.Common_SourceData_DensityOfMethane_Source: _xlfn.LAMBDA("National Inventory Report 2023 Volume 1: Equations 3.B.1a_2, 3.B.1c_2, 3.B.3_1, 3.B.4g_2")
Name Common_SourceData.Common_SourceData_DensityOfMethane_Title: _xlfn.LAMBDA("p = density of methane")
Name Common_SourceData.Common_SourceData_DensityOfMethane_Unit: _xlfn.LAMBDA("kg/m3")
Name Common_SourceData.Common_SourceData_EFleach_Data: _xlfn.LAMBDA(_xlfn.MAKEARRAY(1, 2, _xlfn.LAMBDA(_xlpm.r,_xlpm.c, INDEX({"EFleach",0.011}, _xlpm.r, _xlpm.c))))
Name Common_SourceData.Common_SourceData_EFleach_NIRReference: _xlfn.LAMBDA("National Inventory Report Volume 1: Equation 3.D.B_10")
Name Common_SourceData.Common_SourceData_EFleach_Source: _xlfn.LAMBDA("VEERG 2026:5.5.2.3 Constant Parameters")
Name Common_SourceData.Common_SourceData_EFleach_Title: _xlfn.LAMBDA("Emission factor for nitrogen leaching and runoff")
Name Common_SourceData.Common_SourceData_EFleach_Unit: _xlfn.LAMBDA("(kg N2O-N / kg N")
Name Common_SourceData.Common_SourceData_EFleach_Variation: _xlfn.LAMBDA((""))
Name Common_SourceData.Common_SourceData_EFN2O_NIRReference: _xlfn.LAMBDA("")
Name Common_SourceData.Common_SourceData_EFN2O_Source: _xlfn.LAMBDA("VEERG 2026: Table A.2.2.1")
Name Common_SourceData.Common_SourceData_EFN2O_Title: _xlfn.LAMBDA("Nitrous oxide emission factors for inorganic fertiliser application")
Name Common_SourceData.Common_SourceData_EFN2O_Unit: _xlfn.LAMBDA("(kg N2O-N / kg N")
Name Common_SourceData.Common_SourceData_EFOrganicFertiliserAndCropResidues_Data: _xlfn.LAMBDA(_xlfn.MAKEARRAY(3, 2, _xlfn.LAMBDA(_xlpm.r,_xlpm.c, INDEX({"Climate zone","EFNi & EFN2O";"Wet climate zone",0.006;"Dry climate zone",0.005}, _xlpm.r, _xlpm.c))))
Name Common_SourceData.Common_SourceData_EFOrganicFertiliserAndCropResidues_NIRReference: _xlfn.LAMBDA("")
Name Common_SourceData.Common_SourceData_EFOrganicFertiliserAndCropResidues_Source: _xlfn.LAMBDA("VEERG 2026: Table A.2.1.4")

Sheet Home
A1: Home

Sheet Overview
A1: #VALUE! | C1: 8: Fuel use: Overview
A3: =HYPERLINK("#'Home'!A1", "Home") -> Home
A4: =HYPERLINK("#'Overview'!A1", "Overview") -> Overview
A5: =HYPERLINK("#'Results'!A1", "Results") -> Results | D5: 💡 Below is a diagram that maps the equations used to calculate emissions, and how they interact with each other.
D6: Click on a box to go to the corresponding calculation.
A7: INPUTS
A8: =HYPERLINK("#'Input - Fuel'!A1", "Fuel") -> Fuel
A10: CALCULATIONS
A11: =HYPERLINK("#'8.1.1.1-2 Transport fuel'!A1", "8.1.1.1-2 Transport fuel") -> 8.1.1.1-2 Transport fuel
A12: =HYPERLINK("#'8.2.1.1-2 Stationary fuel'!A1", "8.2.1.1-2 Stationary fuel") -> 8.2.1.1-2 Stationary fuel
A13: =HYPERLINK("#'8.X.1.1-2 General use fuel'!A1", "8.X.1.1-2 General use fuel") -> 8.X.1.1-2 General use fuel
A15: APPENDICES
A16: =HYPERLINK("#'Constants - Fuel'!A1", "Constants - Fuel") -> Constants - Fuel
A17: =HYPERLINK("#'Constants - Common'!A1", "Constants - Common") -> Constants - Common
L37: `

Sheet Results
A1: #VALUE! | C1: 8: Fuel use: Results
A3: =HYPERLINK("#'Home'!A1", "Home") -> Home
A4: =HYPERLINK("#'Overview'!A1", "Overview") -> Overview | D4: Emissions breakdown
A5: =HYPERLINK("#'Results'!A1", "Results") -> Results
D6: 💡 NOTE: When there is no Method 2, the Method 2 result are the same as Method 1
A7: INPUTS
A8: =HYPERLINK("#'Input - Fuel'!A1", "Fuel") -> Fuel | D8: Scope 1 source | E8: GHG emissions method 1 | F8: GHG emissions method 2 | G8: GHG Unit
D9: 8.1.1.1-2 Transport fuel: CO2 | E9: ='8.1.1.1-2 Transport fuel'!E67 -> 0 | F9: =E9 -> 0 | G9: t CO2e
A10: CALCULATIONS | D10: 8.1.1.1-2 Transport fuel: CH4 | E10: ='8.1.1.1-2 Transport fuel'!E68 -> 0 | F10: =E10 -> 0 | G10: t CO2e
A11: =HYPERLINK("#'8.1.1.1-2 Transport fuel'!A1", "8.1.1.1-2 Transport fuel") -> 8.1.1.1-2 Transport fuel | D11: 8.1.1.1-2 Transport fuel: N2O | E11: ='8.1.1.1-2 Transport fuel'!E69 -> 0 | F11: =E11 -> 0 | G11: t CO2e
A12: =HYPERLINK("#'8.2.1.1-2 Stationary fuel'!A1", "8.2.1.1-2 Stationary fuel") -> 8.2.1.1-2 Stationary fuel | D12: 8.2.1.1-2 Stationary fuel: CO2 | E12: ='8.2.1.1-2 Stationary fuel'!E55 -> 0.00602 | F12: =E12 -> 0.00602 | G12: t CO2e
A13: =HYPERLINK("#'8.X.1.1-2 General use fuel'!A1", "8.X.1.1-2 General use fuel") -> 8.X.1.1-2 General use fuel | D13: 8.2.1.1-2 Stationary fuel: CH4 | E13: ='8.2.1.1-2 Stationary fuel'!E56 -> 4e-06 | F13: =E13 -> 4e-06 | G13: t CO2e
D14: 8.2.1.1-2 Stationary fuel: N2O | E14: ='8.2.1.1-2 Stationary fuel'!E57 -> 3e-06 | F14: =E14 -> 3e-06 | G14: t CO2e
A15: APPENDICES | D15: Total | E15: =SUM(E9:E14) -> 0.006027 | F15: =SUM(F9:F14) -> 0.006027 | G15: t CO2e
A16: =HYPERLINK("#'Constants - Fuel'!A1", "Constants - Fuel") -> Constants - Fuel
A17: =HYPERLINK("#'Constants - Common'!A1", "Constants - Common") -> Constants - Common

Sheet Input - Site
A1: #VALUE! | C1: Input - Site
A3: =HYPERLINK("#'Home'!A1", "Home") -> Home
A4: =HYPERLINK("#'Overview'!A1", "Overview") -> Overview
A5: =HYPERLINK("#'Results'!A1", "Results") -> Results | D5: Your business
A7: INPUTS | D7: Farm name | E7: Test Farms
A8: =HYPERLINK("#'Input - Electricity'!A1", "Electricity") -> Electricity | D8: Reporting entity name | E8: Test Farms Pty Ltd
A10: CALCULATIONS | D10: 💡An 'Emissions accounting period' is a 12 month period where the business can report on the emissions, and is typically the same as the business' financial accounting period.
A11: =HYPERLINK("#'14.1.1-2 Purchased electricity'!A1", "14.1.1-2 Purchased electricity") -> 14.1.1-2 Purchased electricity
D12: Emissions calculation period start date | E12: 45292 | F12: ← DD/MM/YYYY or DD Month YYYY
A13: APPENDICES | D13: Emissions calculation period end date | E13: =DATE(YEAR(E12)+1,MONTH(E12),DAY(E12))-1 -> 45657 | F13: ← Automatically calculated, 12 months after start date
A14: =HYPERLINK("#'Constants - Electricity'!A1", "Constants - Electricity") -> Constants - Electricity
A15: =HYPERLINK("#'Constants - Common'!A1", "Constants - Common") -> Constants - Common
D16: Location and climate
D18: Location information is used to reference some region and climate-specific emission factors
D19: Tip: Use the web-based GAF Location Helper tool to easily get region and climate information. You will need an internet connection to use the GAF Location Helper.
D21: State | E21: Western Australia | F21: ← Please select
D22: Region (ABS Statistical area level 4) if state is WA | E22: Western Australia - Outback (South) | F22: ← Please select

Sheet Input - Fuel
A1: #VALUE! | C1: Input - Fuel
A3: =HYPERLINK("#'Home'!A1", "Home") -> Home
A4: =HYPERLINK("#'Overview'!A1", "Overview") -> Overview
A5: =HYPERLINK("#'Results'!A1", "Results") -> Results | D5: Fuel purchases and consumption
A7: INPUTS | D7: A 'Metropolitan' location is:
A8: =HYPERLINK("#'Input - Fuel'!A1", "Fuel") -> Fuel | D8: ● On or east of the dividing range in NSW (including Canberra and Queanbeyan)
D9: ● In Melbourne, Brisbane, Adelaide or Perth
A10: CALCULATIONS
A11: =HYPERLINK("#'8.1.1.1-2 Transport fuel'!A1", "8.1.1.1-2 Transport fuel") -> 8.1.1.1-2 Transport fuel | D11: Is the property in a Metropolitan location? | E11: Metro | F11: ← Please select
A12: =HYPERLINK("#'8.2.1.1-2 Stationary fuel'!A1", "8.2.1.1-2 Stationary fuel") -> 8.2.1.1-2 Stationary fuel
A13: =HYPERLINK("#'8.X.1.1-2 General use fuel'!A1", "8.X.1.1-2 General use fuel") -> 8.X.1.1-2 General use fuel | D13: 💡 You can add more rows to the table by right-clicking on the table and selecting "Insert > Table rows above/below"
D14: 💡 'Percent consumed" is 100% by default. If you purchased more fuel than was consumed you can edit this field.
A15: APPENDICES
A16: =HYPERLINK("#'Constants - Fuel'!A1", "Constants - Fuel") -> Constants - Fuel | D16: Fuel use (select) | E16: Fuel type (select) | F16: Amount purchased | G16: Amount unit | H16: Percent consumed | I16: Amount consumed
A17: =HYPERLINK("#'Constants - Common'!A1", "Constants - Common") -> Constants - Common | D17: Power standalone machinery or heating | E17: Town gas in GJ | F17: 100 | G17: {=Common_InputFunctions.Utility_LookupValueInTable(Table_Input_Fuel[[#This Row],[Fuel type (select)]],Table_FuelTypes_Units[Fuel type], Table_FuelTypes_Units[Unit])} -> GJ | H17: =1 -> 1 | I17: =Table_Input_Fuel[[#This Row],[Amount purchased]]*Table_Input_Fuel[[#This Row],[Percent consumed]]*10^-3 -> 0.1

Sheet 8.1.1.1-2 Transport fuel
A1: #VALUE! | C1: 8.1.1.1-2 Transport fuel combustion
A3: =HYPERLINK("#'Home'!A1", "Home") -> Home | D3: Method 1
A4: =HYPERLINK("#'Overview'!A1", "Overview") -> Overview
A5: =HYPERLINK("#'Results'!A1", "Results") -> Results | D5: Emissions for each GHG from the combustion of fuels for transport energy purposes | K5: Upstream emissions from scope 1 fuel use for transport purposes
D6: VEERG 2026: 8.1.1.1, Equation (1) | K6: VEERG 2026: 15.11.1.1, Equation (2)
A7: INPUTS
A8: =HYPERLINK("#'Input - Fuel'!A1", "Fuel") -> Fuel
A10: CALCULATIONS
A11: =HYPERLINK("#'8.1.1.1-2 Transport fuel'!A1", "8.1.1.1-2 Transport fuel") -> 8.1.1.1-2 Transport fuel | D11: Variable | E11: E_g | K11: Variable | L11: E_WTTtransq
A12: =HYPERLINK("#'8.2.1.1-2 Stationary fuel'!A1", "8.2.1.1-2 Stationary fuel") -> 8.2.1.1-2 Stationary fuel | D12: Unit | E12: t CO2-e | K12: Unit | L12: t CO2e
A13: =HYPERLINK("#'8.X.1.1-2 General use fuel'!A1", "8.X.1.1-2 General use fuel") -> 8.X.1.1-2 General use fuel
D14: Q_Transtq | E14: Amount of fuel type q combusted for transport energy purposes | G14: Varies based on fuel type: kL, m3, GJ | H14: Input | I14: {=HYPERLINK(Common_InputFunctions.Utility_SourceHyperlink($D$22), $D$22)} -> Table_E_g | K14: Q_Transq | L14: amount of fuel q combusted for transport energy purposes | N14: kL | O14: Input | P14: {=HYPERLINK(Common_InputFunctions.Utility_SourceHyperlink($D$22), $D$22)} -> Table_E_g
A15: APPENDICES | D15: EC_Transq | E15: Energy content factor for transport energy purposes | G15: GJ / unit of fuel | H15: Constant | I15: {=HYPERLINK(Common_InputFunctions.Utility_SourceHyperlink($D$22), $D$22)} -> Table_E_g | K15: EC_Transq | L15: energy content factor for transport energy purposes | N15: GJ/kL or GJ/m3 | O15: Constant | P15: {=HYPERLINK(Common_InputFunctions.Utility_SourceHyperlink($D$22), $D$22)} -> Table_E_g
A16: =HYPERLINK("#'Constants - Fuel'!A1", "Constants - Fuel") -> Constants - Fuel | D16: EF_Trans1tqg | E16: Scope 1 emission factor for transport energy purposes for each greenhouse gas | G16: kg CO2e / GJ | H16: Constant | I16: {=HYPERLINK(Common_InputFunctions.Utility_SourceHyperlink($D$22), $D$22)} -> Table_E_g | K16: EF_Trans3q | L16: scope 3 emission factor for transport energy purposes | N16: kg CO2e/GJ | O16: Constant | P16: {=HYPERLINK(Common_InputFunctions.Utility_SourceHyperlink($D$22), $D$22)} -> Table_E_g
A17: =HYPERLINK("#'Constants - Common'!A1", "Constants - Common") -> Constants - Common | D17: q | E17: Fuel type | H17: Constant
D18: Trans | E18: Transport combustion | H18: Constant
D19: g | E19: Greenhouse gas | H19: Constant
D20: 1 | E20: Scope 1 | H20: Constant
D22: Table_E_g
D23: Emissions for transport fuel combustion
D24: Fuel use | E24: Fuel type (NGAF terminology) | F24: Fuel type (q) | G24: ECTrans,q | H24: EFTrans,1,q,g=CO2 | I24: EFTrans,1,q,g=CH4 | J24: EFTrans,1,q,g=N20 | K24: EFTrans,3,q | L24: QTrans,q | M24: Q unit | N24: Eg=CO2 | O24: Eg=CH4 | P24: Eg=N20 | Q24: E3WTT,trans,q
D25: =Table_FuelTypesPerUse[[#Headers],[from the use of a limited number of NGER data inputs. It is suggested that for Tasmania the use of the Victorian emission factors is appropriate,]] -> from the use of a limited number of NGER data inputs. It is suggested that for Tasmania the use of the Victorian emission factors is appropriate, | E25: ='Constants - Fuel'!$E$10 -> Gasoline | F25: ='Constants - Fuel'!G131 -> 0 | G25: {=IFERROR(_xlfn.XLOOKUP(1, (Table_Fuel_EFs_Transport[Fuel combusted]=$E25)*(Table_Fuel_EFs_Transport[Transport type]=$D$25), Table_Fuel_EFs_Transport[Energy Content Factor (GJ per unit of fuel)]), 0)} -> 0 | H25: {=IFERROR(_xlfn.XLOOKUP(1, (Table_Fuel_EFs_Transport[Fuel combusted]=$E25)*(Table_Fuel_EFs_Transport[Transport type]=$D$25), Table_Fuel_EFs_Transport[Scope 1 Emission Factor (kg CO2 - e / GJ) CO2]), 0)} -> 0 | I25: {=IFERROR(_xlfn.XLOOKUP(1, (Table_Fuel_EFs_Transport[Fuel combusted]=$E25)*(Table_Fuel_EFs_Transport[Transport type]=$D$25), Table_Fuel_EFs_Transport[Scope 1 Emission Factor (kg CO2 - e / GJ) CH4]), 0)} -> 0 | J25: {=IFERROR(_xlfn.XLOOKUP(1, (Table_Fuel_EFs_Transport[Fuel combusted]=$E25)*(Table_Fuel_EFs_Transport[Transport type]=$D$25), Table_Fuel_EFs_Transport[Scope 1 Emission Factor (kg CO2 - e / GJ) N2O]), 0)} -> 0 | K25: {=IFERROR(_xlfn.XLOOKUP(1, (Table_Fuel_EFs_Transport[Fuel combusted]=$E25)*(Table_Fuel_EFs_Transport[Transport type]=$D$25), Table_Fuel_EFs_Transport[Scope 3 Emission Factor (kg CO2 - e / GJ)]), 0)} -> 0 | L25: {=Fuel_InputFunctions.Fuel_TotalConsumption(Table_Input_Fuel[Amount consumed], Table_Input_Fuel[Fuel use (select)], D25, Table_Input_Fuel[Fuel type (select)],F25)} -> 0 | M25: {=Common_InputFunctions.Utility_LookupValueInTable(F25,Table_FuelTypes_Units[Fuel type],Table_FuelTypes_Units[Unit])} | N25: =((($L25 * $G25 * $H25) * 10 ^ -3)) -> 0 | O25: =((($L25 * $G25 * $I25) * 10 ^ -3)) -> 0 | P25: =((($L25 * $G25 * $J25) * 10 ^ -3)) -> 0 | Q25: =((L25 * G25 * K25) * 10 ^ -3) -> 0
D26: =$D$25 -> from the use of a limited number of NGER data inputs. It is suggested that for Tasmania the use of the Victorian emission factors is appropriate, | E26: ='Constants - Fuel'!$E$11 -> Diesel oil | F26: ='Constants - Fuel'!G132 -> while for Northern Territory the use of the Western Australian emission factors is appropriate. | G26: {=IFERROR(_xlfn.XLOOKUP(1, (Table_Fuel_EFs_Transport[Fuel combusted]=$E26)*(Table_Fuel_EFs_Transport[Transport type]=$D$25), Table_Fuel_EFs_Transport[Energy Content Factor (GJ per unit of fuel)]), 0)} -> 0 | H26: {=IFERROR(_xlfn.XLOOKUP(1, (Table_Fuel_EFs_Transport[Fuel combusted]=$E26)*(Table_Fuel_EFs_Transport[Transport type]=$D$25), Table_Fuel_EFs_Transport[Scope 1 Emission Factor (kg CO2 - e / GJ) CO2]), 0)} -> 0 | I26: {=IFERROR(_xlfn.XLOOKUP(1, (Table_Fuel_EFs_Transport[Fuel combusted]=$E26)*(Table_Fuel_EFs_Transport[Transport type]=$D$25), Table_Fuel_EFs_Transport[Scope 1 Emission Factor (kg CO2 - e / GJ) CH4]), 0)} -> 0 | J26: {=IFERROR(_xlfn.XLOOKUP(1, (Table_Fuel_EFs_Transport[Fuel combusted]=$E26)*(Table_Fuel_EFs_Transport[Transport type]=$D$25), Table_Fuel_EFs_Transport[Scope 1 Emission Factor (kg CO2 - e / GJ) N2O]), 0)} -> 0 | K26: {=IFERROR(_xlfn.XLOOKUP(1, (Table_Fuel_EFs_Transport[Fuel combusted]=$E26)*(Table_Fuel_EFs_Transport[Transport type]=$D$25), Table_Fuel_EFs_Transport[Scope 3 Emission Factor (kg CO2 - e / GJ)]), 0)} -> 0 | L26: {=Fuel_InputFunctions.Fuel_TotalConsumption(Table_Input_Fuel[Amount consumed], Table_Input_Fuel[Fuel use (select)], D26, Table_Input_Fuel[Fuel type (select)],F26)} -> 0 | M26: {=Common_InputFunctions.Utility_LookupValueInTable(F26,Table_FuelTypes_Units[Fuel type],Table_FuelTypes_Units[Unit])} | N26: =((($L26 * $G26 * $H26) * 10 ^ -3)) -> 0 | O26: =((($L26 * $G26 * $I26) * 10 ^ -3)) -> 0 | P26: =((($L26 * $G26 * $J26) * 10 ^ -3)) -> 0 | Q26: =((L26 * G26 * K26) * 10 ^ -3) -> 0
D27: =$D$25 -> from the use of a limited number of NGER data inputs. It is suggested that for Tasmania the use of the Victorian emission factors is appropriate, | E27: ='Constants - Fuel'!$E$12 -> Liquefied petroleum gas (LPG) | F27: ='Constants - Fuel'!G133 -> - | G27: {=IFERROR(_xlfn.XLOOKUP(1, (Table_Fuel_EFs_Transport[Fuel combusted]=$E27)*(Table_Fuel_EFs_Transport[Transport type]=$D$25), Table_Fuel_EFs_Transport[Energy Content Factor (GJ per unit of fuel)]), 0)} -> 0 | H27: {=IFERROR(_xlfn.XLOOKUP(1, (Table_Fuel_EFs_Transport[Fuel combusted]=$E27)*(Table_Fuel_EFs_Transport[Transport type]=$D$25), Table_Fuel_EFs_Transport[Scope 1 Emission Factor (kg CO2 - e / GJ) CO2]), 0)} -> 0 | I27: {=IFERROR(_xlfn.XLOOKUP(1, (Table_Fuel_EFs_Transport[Fuel combusted]=$E27)*(Table_Fuel_EFs_Transport[Transport type]=$D$25), Table_Fuel_EFs_Transport[Scope 1 Emission Factor (kg CO2 - e / GJ) CH4]), 0)} -> 0 | J27: {=IFERROR(_xlfn.XLOOKUP(1, (Table_Fuel_EFs_Transport[Fuel combusted]=$E27)*(Table_Fuel_EFs_Transport[Transport type]=$D$25), Table_Fuel_EFs_Transport[Scope 1 Emission Factor (kg CO2 - e / GJ) N2O]), 0)} -> 0 | K27: {=IFERROR(_xlfn.XLOOKUP(1, (Table_Fuel_EFs_Transport[Fuel combusted]=$E27)*(Table_Fuel_EFs_Transport[Transport type]=$D$25), Table_Fuel_EFs_Transport[Scope 3 Emission Factor (kg CO2 - e / GJ)]), 0)} -> 0 | L27: {=Fuel_InputFunctions.Fuel_TotalConsumption(Table_Input_Fuel[Amount consumed], Table_Input_Fuel[Fuel use (select)], D27, Table_Input_Fuel[Fuel type (select)],F27)} -> 0 | M27: {=Common_InputFunctions.Utility_LookupValueInTable(F27,Table_FuelTypes_Units[Fuel type],Table_FuelTypes_Units[Unit])} | N27: =((($L27 * $G27 * $H27) * 10 ^ -3)) -> 0 | O27: =((($L27 * $G27 * $I27) * 10 ^ -3)) -> 0 | P27: =((($L27 * $G27 * $J27) * 10 ^ -3)) -> 0 | Q27: =((L27 * G27 * K27) * 10 ^ -3) -> 0
D28: =$D$25 -> from the use of a limited number of NGER data inputs. It is suggested that for Tasmania the use of the Victorian emission factors is appropriate, | E28: ='Constants - Fuel'!$E$13 -> Fuel oil | F28: ='Constants - Fuel'!G134 -> Scope 3 emission factors do not include fugitive emission leakage from low pressure natural gas distribution pipeline networks while those from high pressure | G28: {=IFERROR(_xlfn.XLOOKUP(1, (Table_Fuel_EFs_Transport[Fuel combusted]=$E28)*(Table_Fuel_EFs_Transport[Transport type]=$D$25), Table_Fuel_EFs_Transport[Energy Content Factor (GJ per unit of fuel)]), 0)} -> 0 | H28: {=IFERROR(_xlfn.XLOOKUP(1, (Table_Fuel_EFs_Transport[Fuel combusted]=$E28)*(Table_Fuel_EFs_Transport[Transport type]=$D$25), Table_Fuel_EFs_Transport[Scope 1 Emission Factor (kg CO2 - e / GJ) CO2]), 0)} -> 0 | I28: {=IFERROR(_xlfn.XLOOKUP(1, (Table_Fuel_EFs_Transport[Fuel combusted]=$E28)*(Table_Fuel_EFs_Transport[Transport type]=$D$25), Table_Fuel_EFs_Transport[Scope 1 Emission Factor (kg CO2 - e / GJ) CH4]), 0)} -> 0 | J28: {=IFERROR(_xlfn.XLOOKUP(1, (Table_Fuel_EFs_Transport[Fuel combusted]=$E28)*(Table_Fuel_EFs_Transport[Transport type]=$D$25), Table_Fuel_EFs_Transport[Scope 1 Emission Factor (kg CO2 - e / GJ) N2O]), 0)} -> 0 | K28: {=IFERROR(_xlfn.XLOOKUP(1, (Table_Fuel_EFs_Transport[Fuel combusted]=$E28)*(Table_Fuel_EFs_Transport[Transport type]=$D$25), Table_Fuel_EFs_Transport[Scope 3 Emission Factor (kg CO2 - e / GJ)]), 0)} -> 0 | L28: {=Fuel_InputFunctions.Fuel_TotalConsumption(Table_Input_Fuel[Amount consumed], Table_Input_Fuel[Fuel use (select)], D28, Table_Input_Fuel[Fuel type (select)],F28)} -> 0 | M28: {=Common_InputFunctions.Utility_LookupValueInTable(F28,Table_FuelTypes_Units[Fuel type],Table_FuelTypes_Units[Unit])} | N28: =((($L28 * $G28 * $H28) * 10 ^ -3)) -> 0 | O28: =((($L28 * $G28 * $I28) * 10 ^ -3)) -> 0 | P28: =((($L28 * $G28 * $J28) * 10 ^ -3)) -> 0 | Q28: =((L28 * G28 * K28) * 10 ^ -3) -> 0
D29: =$D$25 -> from the use of a limited number of NGER data inputs. It is suggested that for Tasmania the use of the Victorian emission factors is appropriate, | E29: ='Constants - Fuel'!$E$14 -> Ethanol | F29: ='Constants - Fuel'!G135 -> 0 | G29: {=IFERROR(_xlfn.XLOOKUP(1, (Table_Fuel_EFs_Transport[Fuel combusted]=$E29)*(Table_Fuel_EFs_Transport[Transport type]=$D$25), Table_Fuel_EFs_Transport[Energy Content Factor (GJ per unit of fuel)]), 0)} -> 0 | H29: {=IFERROR(_xlfn.XLOOKUP(1, (Table_Fuel_EFs_Transport[Fuel combusted]=$E29)*(Table_Fuel_EFs_Transport[Transport type]=$D$25), Table_Fuel_EFs_Transport[Scope 1 Emission Factor (kg CO2 - e / GJ) CO2]), 0)} -> 0 | I29: {=IFERROR(_xlfn.XLOOKUP(1, (Table_Fuel_EFs_Transport[Fuel combusted]=$E29)*(Table_Fuel_EFs_Transport[Transport type]=$D$25), Table_Fuel_EFs_Transport[Scope 1 Emission Factor (kg CO2 - e / GJ) CH4]), 0)} -> 0 | J29: {=IFERROR(_xlfn.XLOOKUP(1, (Table_Fuel_EFs_Transport[Fuel combusted]=$E29)*(Table_Fuel_EFs_Transport[Transport type]=$D$25), Table_Fuel_EFs_Transport[Scope 1 Emission Factor (kg CO2 - e / GJ) N2O]), 0)} -> 0 | K29: {=IFERROR(_xlfn.XLOOKUP(1, (Table_Fuel_EFs_Transport[Fuel combusted]=$E29)*(Table_Fuel_EFs_Transport[Transport type]=$D$25), Table_Fuel_EFs_Transport[Scope 3 Emission Factor (kg CO2 - e / GJ)]), 0)} -> 0 | L29: {=Fuel_InputFunctions.Fuel_TotalConsumption(Table_Input_Fuel[Amount consumed], Table_Input_Fuel[Fuel use (select)], D29, Table_Input_Fuel[Fuel type (select)],F29)} -> 0 | M29: {=Common_InputFunctions.Utility_LookupValueInTable(F29,Table_FuelTypes_Units[Fuel type],Table_FuelTypes_Units[Unit])} | N29: =((($L29 * $G29 * $H29) * 10 ^ -3)) -> 0 | O29: =((($L29 * $G29 * $I29) * 10 ^ -3)) -> 0 | P29: =((($L29 * $G29 * $J29) * 10 ^ -3)) -> 0 | Q29: =((L29 * G29 * (IF(ISNUMBER(K29),K29,0))) * 10 ^ -3) -> 0
D30: =$D$25 -> from the use of a limited number of NGER data inputs. It is suggested that for Tasmania the use of the Victorian emission factors is appropriate, | E30: ='Constants - Fuel'!$E$15 -> Biodiesel | F30: ='Constants - Fuel'!G136 -> gas networks are considered negligible. | G30: {=IFERROR(_xlfn.XLOOKUP(1, (Table_Fuel_EFs_Transport[Fuel combusted]=$E30)*(Table_Fuel_EFs_Transport[Transport type]=$D$25), Table_Fuel_EFs_Transport[Energy Content Factor (GJ per unit of fuel)]), 0)} -> 0 | H30: {=IFERROR(_xlfn.XLOOKUP(1, (Table_Fuel_EFs_Transport[Fuel combusted]=$E30)*(Table_Fuel_EFs_Transport[Transport type]=$D$25), Table_Fuel_EFs_Transport[Scope 1 Emission Factor (kg CO2 - e / GJ) CO2]), 0)} -> 0 | I30: {=IFERROR(_xlfn.XLOOKUP(1, (Table_Fuel_EFs_Transport[Fuel combusted]=$E30)*(Table_Fuel_EFs_Transport[Transport type]=$D$25), Table_Fuel_EFs_Transport[Scope 1 Emission Factor (kg CO2 - e / GJ) CH4]), 0)} -> 0 | J30: {=IFERROR(_xlfn.XLOOKUP(1, (Table_Fuel_EFs_Transport[Fuel combusted]=$E30)*(Table_Fuel_EFs_Transport[Transport type]=$D$25), Table_Fuel_EFs_Transport[Scope 1 Emission Factor (kg CO2 - e / GJ) N2O]), 0)} -> 0 | K30: {=IFERROR(_xlfn.XLOOKUP(1, (Table_Fuel_EFs_Transport[Fuel combusted]=$E30)*(Table_Fuel_EFs_Transport[Transport type]=$D$25), Table_Fuel_EFs_Transport[Scope 3 Emission Factor (kg CO2 - e / GJ)]), 0)} -> 0 | L30: {=Fuel_InputFunctions.Fuel_TotalConsumption(Table_Input_Fuel[Amount consumed], Table_Input_Fuel[Fuel use (select)], D30, Table_Input_Fuel[Fuel type (select)],F30)} -> 0 | M30: {=Common_InputFunctions.Utility_LookupValueInTable(F30,Table_FuelTypes_Units[Fuel type],Table_FuelTypes_Units[Unit])} | N30: =((($L30 * $G30 * $H30) * 10 ^ -3)) -> 0 | O30: =((($L30 * $G30 * $I30) * 10 ^ -3)) -> 0 | P30: =((($L30 * $G30 * $J30) * 10 ^ -3)) -> 0 | Q30: =((L30 * G30 * (IF(ISNUMBER(K30),K30,0))) * 10 ^ -3) -> 0
D31: =$D$25 -> from the use of a limited number of NGER data inputs. It is suggested that for Tasmania the use of the Victorian emission factors is appropriate, | E31: ='Constants - Fuel'!$E$16 -> Renewable diesel | F31: ='Constants - Fuel'!G137 -> Renewable diesel | G31: {=IFERROR(_xlfn.XLOOKUP(1, (Table_Fuel_EFs_Transport[Fuel combusted]=$E31)*(Table_Fuel_EFs_Transport[Transport type]=$D$25), Table_Fuel_EFs_Transport[Energy Content Factor (GJ per unit of fuel)]), 0)} -> 0 | H31: {=IFERROR(_xlfn.XLOOKUP(1, (Table_Fuel_EFs_Transport[Fuel combusted]=$E31)*(Table_Fuel_EFs_Transport[Transport type]=$D$25), Table_Fuel_EFs_Transport[Scope 1 Emission Factor (kg CO2 - e / GJ) CO2]), 0)} -> 0 | I31: {=IFERROR(_xlfn.XLOOKUP(1, (Table_Fuel_EFs_Transport[Fuel combusted]=$E31)*(Table_Fuel_EFs_Transport[Transport type]=$D$25), Table_Fuel_EFs_Transport[Scope 1 Emission Factor (kg CO2 - e / GJ) CH4]), 0)} -> 0 | J31: {=IFERROR(_xlfn.XLOOKUP(1, (Table_Fuel_EFs_Transport[Fuel combusted]=$E31)*(Table_Fuel_EFs_Transport[Transport type]=$D$25), Table_Fuel_EFs_Transport[Scope 1 Emission Factor (kg CO2 - e / GJ) N2O]), 0)} -> 0 | K31: {=IFERROR(_xlfn.XLOOKUP(1, (Table_Fuel_EFs_Transport[Fuel combusted]=$E31)*(Table_Fuel_EFs_Transport[Transport type]=$D$25), Table_Fuel_EFs_Transport[Scope 3 Emission Factor (kg CO2 - e / GJ)]), 0)} -> 0 | L31: {=Fuel_InputFunctions.Fuel_TotalConsumption(Table_Input_Fuel[Amount consumed], Table_Input_Fuel[Fuel use (select)], D31, Table_Input_Fuel[Fuel type (select)],F31)} -> 0 | M31: {=Common_InputFunctions.Utility_LookupValueInTable(F31,Table_FuelTypes_Units[Fuel type],Table_FuelTypes_Units[Unit])} -> kL | N31: =((($L31 * $G31 * $H31) * 10 ^ -3)) -> 0 | O31: =((($L31 * $G31 * $I31) * 10 ^ -3)) -> 0 | P31: =((($L31 * $G31 * $J31) * 10 ^ -3)) -> 0 | Q31: =((L31 * G31 * (IF(ISNUMBER(K31),K31,0))) * 10 ^ -3) -> 0
D32: =$D$25 -> from the use of a limited number of NGER data inputs. It is suggested that for Tasmania the use of the Victorian emission factors is appropriate, | E32: ='Constants - Fuel'!$E$17 -> Other biofuels | F32: ='Constants - Fuel'!G138 -> Other biofuels | G32: {=IFERROR(_xlfn.XLOOKUP(1, (Table_Fuel_EFs_Transport[Fuel combusted]=$E32)*(Table_Fuel_EFs_Transport[Transport type]=$D$25), Table_Fuel_EFs_Transport[Energy Content Factor (GJ per unit of fuel)]), 0)} -> 0 | H32: {=IFERROR(_xlfn.XLOOKUP(1, (Table_Fuel_EFs_Transport[Fuel combusted]=$E32)*(Table_Fuel_EFs_Transport[Transport type]=$D$25), Table_Fuel_EFs_Transport[Scope 1 Emission Factor (kg CO2 - e / GJ) CO2]), 0)} -> 0 | I32: {=IFERROR(_xlfn.XLOOKUP(1, (Table_Fuel_EFs_Transport[Fuel combusted]=$E32)*(Table_Fuel_EFs_Transport[Transport type]=$D$25), Table_Fuel_EFs_Transport[Scope 1 Emission Factor (kg CO2 - e / GJ) CH4]), 0)} -> 0 | J32: {=IFERROR(_xlfn.XLOOKUP(1, (Table_Fuel_EFs_Transport[Fuel combusted]=$E32)*(Table_Fuel_EFs_Transport[Transport type]=$D$25), Table_Fuel_EFs_Transport[Scope 1 Emission Factor (kg CO2 - e / GJ) N2O]), 0)} -> 0 | K32: {=IFERROR(_xlfn.XLOOKUP(1, (Table_Fuel_EFs_Transport[Fuel combusted]=$E32)*(Table_Fuel_EFs_Transport[Transport type]=$D$25), Table_Fuel_EFs_Transport[Scope 3 Emission Factor (kg CO2 - e / GJ)]), 0)} -> 0 | L32: {=Fuel_InputFunctions.Fuel_TotalConsumption(Table_Input_Fuel[Amount consumed], Table_Input_Fuel[Fuel use (select)], D32, Table_Input_Fuel[Fuel type (select)],F32)} -> 0 | M32: {=Common_InputFunctions.Utility_LookupValueInTable(F32,Table_FuelTypes_Units[Fuel type],Table_FuelTypes_Units[Unit])} -> kL | N32: =((($L32 * $G32 * $H32) * 10 ^ -3)) -> 0 | O32: =((($L32 * $G32 * $I32) * 10 ^ -3)) -> 0 | P32: =((($L32 * $G32 * $J32) * 10 ^ -3)) -> 0 | Q32: =((L32 * G32 * (IF(ISNUMBER(K32),K32,0))) * 10 ^ -3) -> 0
D33: =Table_FuelTypesPerUse[[#Headers],[Off-road Agriculture and forestry equipment]] -> Off-road Agriculture and forestry equipment | E33: ='Constants - Fuel'!$E$11 -> Diesel oil | F33: ='Constants - Fuel'!H131 -> Diesel | G33: {=IFERROR(_xlfn.XLOOKUP(1, (Table_Fuel_EFs_Transport[Fuel combusted]=$E33)*(Table_Fuel_EFs_Transport[Transport type]=$D$33), Table_Fuel_EFs_Transport[Energy Content Factor (GJ per unit of fuel)]), 0)} -> 38.6 | H33: {=IFERROR(_xlfn.XLOOKUP(1, (Table_Fuel_EFs_Transport[Fuel combusted]=$E33)*(Table_Fuel_EFs_Transport[Transport type]=$D$33), Table_Fuel_EFs_Transport[Scope 1 Emission Factor (kg CO2 - e / GJ) CO2]), 0)} -> 69.9 | I33: {=IFERROR(_xlfn.XLOOKUP(1, (Table_Fuel_EFs_Transport[Fuel combusted]=$E33)*(Table_Fuel_EFs_Transport[Transport type]=$D$33), Table_Fuel_EFs_Transport[Scope 1 Emission Factor (kg CO2 - e / GJ) CH4]), 0)} -> 0.3 | J33: {=IFERROR(_xlfn.XLOOKUP(1, (Table_Fuel_EFs_Transport[Fuel combusted]=$E33)*(Table_Fuel_EFs_Transport[Transport type]=$D$33), Table_Fuel_EFs_Transport[Scope 1 Emission Factor (kg CO2 - e / GJ) N2O]), 0)} -> 0.5 | K33: {=IFERROR(_xlfn.XLOOKUP(1, (Table_Fuel_EFs_Transport[Fuel combusted]=$E33)*(Table_Fuel_EFs_Transport[Transport type]=$D$25), Table_Fuel_EFs_Transport[Scope 3 Emission Factor (kg CO2 - e / GJ)]), 0)} -> 0 | L33: {=Fuel_InputFunctions.Fuel_TotalConsumption(Table_Input_Fuel[Amount consumed], Table_Input_Fuel[Fuel use (select)], D33, Table_Input_Fuel[Fuel type (select)],F33)} -> 0 | M33: {=Common_InputFunctions.Utility_LookupValueInTable(F33,Table_FuelTypes_Units[Fuel type],Table_FuelTypes_Units[Unit])} -> kL | N33: =((($L33 * $G33 * $H33) * 10 ^ -3)) -> 0 | O33: =((($L33 * $G33 * $I33) * 10 ^ -3)) -> 0 | P33: =((($L33 * $G33 * $J33) * 10 ^ -3)) -> 0 | Q33: =((L33 * G33 * K33) * 10 ^ -3) -> 0
D34: =Table_FuelTypesPerUse[[#Headers],[Aviation]] -> Aviation | E34: ='Constants - Fuel'!$E$28 -> Gasoline for use as fuel in an aircraft | F34: ='Constants - Fuel'!$F$131 -> Avgas | G34: {=IFERROR(_xlfn.XLOOKUP(1, (Table_Fuel_EFs_Transport[Fuel combusted]=$E34)*(Table_Fuel_EFs_Transport[Transport type]=$D$34), Table_Fuel_EFs_Transport[Energy Content Factor (GJ per unit of fuel)]), 0)} -> 33.1 | H34: {=IFERROR(_xlfn.XLOOKUP(1, (Table_Fuel_EFs_Transport[Fuel combusted]=$E34)*(Table_Fuel_EFs_Transport[Transport type]=$D$34), Table_Fuel_EFs_Transport[Scope 1 Emission Factor (kg CO2 - e / GJ) CO2]), 0)} -> 67 | I34: {=IFERROR(_xlfn.XLOOKUP(1, (Table_Fuel_EFs_Transport[Fuel combusted]=$E34)*(Table_Fuel_EFs_Transport[Transport type]=$D$34), Table_Fuel_EFs_Transport[Scope 1 Emission Factor (kg CO2 - e / GJ) CH4]), 0)} -> 0.06 | J34: {=IFERROR(_xlfn.XLOOKUP(1, (Table_Fuel_EFs_Transport[Fuel combusted]=$E34)*(Table_Fuel_EFs_Transport[Transport type]=$D$34), Table_Fuel_EFs_Transport[Scope 1 Emission Factor (kg CO2 - e / GJ) N2O]), 0)} -> 0.6 | K34: {=IFERROR(_xlfn.XLOOKUP(1, (Table_Fuel_EFs_Transport[Fuel combusted]=$E34)*(Table_Fuel_EFs_Transport[Transport type]=$D$25), Table_Fuel_EFs_Transport[Scope 3 Emission Factor (kg CO2 - e / GJ)]), 0)} -> 0 | L34: {=Fuel_InputFunctions.Fuel_TotalConsumption(Table_Input_Fuel[Amount consumed], Table_Input_Fuel[Fuel use (select)], D34, Table_Input_Fuel[Fuel type (select)],F34)} -> 0 | M34: {=Common_InputFunctions.Utility_LookupValueInTable(F34,Table_FuelTypes_Units[Fuel type],Table_FuelTypes_Units[Unit])} -> kL | N34: =((($L34 * $G34 * $H34) * 10 ^ -3)) -> 0 | O34: =((($L34 * $G34 * $I34) * 10 ^ -3)) -> 0 | P34: =((($L34 * $G34 * $J34) * 10 ^ -3)) -> 0 | Q34: =((L34 * G34 * K34) * 10 ^ -3) -> 0
D35: =$D$34 -> Aviation | E35: ='Constants - Fuel'!$E$29 -> Kerosene for use as fuel in an aircraft | F35: ='Constants - Fuel'!$F$132 -> Jet A1, Jet B | G35: {=IFERROR(_xlfn.XLOOKUP(1, (Table_Fuel_EFs_Transport[Fuel combusted]=$E35)*(Table_Fuel_EFs_Transport[Transport type]=$D$34), Table_Fuel_EFs_Transport[Energy Content Factor (GJ per unit of fuel)]), 0)} -> 36.8 | H35: {=IFERROR(_xlfn.XLOOKUP(1, (Table_Fuel_EFs_Transport[Fuel combusted]=$E35)*(Table_Fuel_EFs_Transport[Transport type]=$D$34), Table_Fuel_EFs_Transport[Scope 1 Emission Factor (kg CO2 - e / GJ) CO2]), 0)} -> 69.6 | I35: {=IFERROR(_xlfn.XLOOKUP(1, (Table_Fuel_EFs_Transport[Fuel combusted]=$E35)*(Table_Fuel_EFs_Transport[Transport type]=$D$34), Table_Fuel_EFs_Transport[Scope 1 Emission Factor (kg CO2 - e / GJ) CH4]), 0)} -> 0.01 | J35: {=IFERROR(_xlfn.XLOOKUP(1, (Table_Fuel_EFs_Transport[Fuel combusted]=$E35)*(Table_Fuel_EFs_Transport[Transport type]=$D$34), Table_Fuel_EFs_Transport[Scope 1 Emission Factor (kg CO2 - e / GJ) N2O]), 0)} -> 0.6 | K35: {=IFERROR(_xlfn.XLOOKUP(1, (Table_Fuel_EFs_Transport[Fuel combusted]=$E35)*(Table_Fuel_EFs_Transport[Transport type]=$D$25), Table_Fuel_EFs_Transport[Scope 3 Emission Factor (kg CO2 - e / GJ)]), 0)} -> 0 | L35: {=Fuel_InputFunctions.Fuel_TotalConsumption(Table_Input_Fuel[Amount consumed], Table_Input_Fuel[Fuel use (select)], D35, Table_Input_Fuel[Fuel type (select)],F35)} -> 0 | M35: {=Common_InputFunctions.Utility_LookupValueInTable(F35,Table_FuelTypes_Units[Fuel type],Table_FuelTypes_Units[Unit])} -> kL | N35: =((($L35 * $G35 * $H35) * 10 ^ -3)) -> 0 | O35: =((($L35 * $G35 * $I35) * 10 ^ -3)) -> 0 | P35: =((($L35 * $G35 * $J35) * 10 ^ -3)) -> 0 | Q35: =((L35 * G35 * K35) * 10 ^ -3) -> 0
D36: =$D$34 -> Aviation | E36: ='Constants - Fuel'!$E$30 -> Renewable aviation kerosene | F36: ='Constants - Fuel'!$F$133 -> Renewable aviation kerosene | G36: {=IFERROR(_xlfn.XLOOKUP(1, (Table_Fuel_EFs_Transport[Fuel combusted]=$E36)*(Table_Fuel_EFs_Transport[Transport type]=$D$34), Table_Fuel_EFs_Transport[Energy Content Factor (GJ per unit of fuel)]), 0)} -> 36.8 | H36: {=IFERROR(_xlfn.XLOOKUP(1, (Table_Fuel_EFs_Transport[Fuel combusted]=$E36)*(Table_Fuel_EFs_Transport[Transport type]=$D$34), Table_Fuel_EFs_Transport[Scope 1 Emission Factor (kg CO2 - e / GJ) CO2]), 0)} -> 0 | I36: {=IFERROR(_xlfn.XLOOKUP(1, (Table_Fuel_EFs_Transport[Fuel combusted]=$E36)*(Table_Fuel_EFs_Transport[Transport type]=$D$34), Table_Fuel_EFs_Transport[Scope 1 Emission Factor (kg CO2 - e / GJ) CH4]), 0)} -> 0.01 | J36: {=IFERROR(_xlfn.XLOOKUP(1, (Table_Fuel_EFs_Transport[Fuel combusted]=$E36)*(Table_Fuel_EFs_Transport[Transport type]=$D$34), Table_Fuel_EFs_Transport[Scope 1 Emission Factor (kg CO2 - e / GJ) N2O]), 0)} -> 0.6 | K36: {=IFERROR(_xlfn.XLOOKUP(1, (Table_Fuel_EFs_Transport[Fuel combusted]=$E36)*(Table_Fuel_EFs_Transport[Transport type]=$D$25), Table_Fuel_EFs_Transport[Scope 3 Emission Factor (kg CO2 - e / GJ)]), 0)} -> 0 | L36: {=Fuel_InputFunctions.Fuel_TotalConsumption(Table_Input_Fuel[Amount consumed], Table_Input_Fuel[Fuel use (select)], D36, Table_Input_Fuel[Fuel type (select)],F36)} -> 0 | M36: {=Common_InputFunctions.Utility_LookupValueInTable(F36,Table_FuelTypes_Units[Fuel type],Table_FuelTypes_Units[Unit])} -> kL | N36: =((($L36 * $G36 * $H36) * 10 ^ -3)) -> 0 | O36: =((($L36 * $G36 * $I36) * 10 ^ -3)) -> 0 | P36: =((($L36 * $G36 * $J36) * 10 ^ -3)) -> 0 | Q36: =((L36 * G36 * K36) * 10 ^ -3) -> 0
A37: =HYPERLINK("#A1", "▲ Back to top") -> ▲ Back to top | D37: =Table_FuelTypesPerUse[[#Headers],[Vessels]] -> Vessels | E37: ='Constants - Fuel'!$E$10 -> Gasoline | F37: ='Constants - Fuel'!$I$131 -> Petrol | G37: {=IFERROR(_xlfn.XLOOKUP(1, (Table_Fuel_EFs_Transport[Fuel combusted]=$E37)*(Table_Fuel_EFs_Transport[Transport type]=$D$37), Table_Fuel_EFs_Transport[Energy Content Factor (GJ per unit of fuel)]), 0)} -> 34.2 | H37: {=IFERROR(_xlfn.XLOOKUP(1, (Table_Fuel_EFs_Transport[Fuel combusted]=$E37)*(Table_Fuel_EFs_Transport[Transport type]=$D$37), Table_Fuel_EFs_Transport[Scope 1 Emission Factor (kg CO2 - e / GJ) CO2]), 0)} -> 67.4 | I37: {=IFERROR(_xlfn.XLOOKUP(1, (Table_Fuel_EFs_Transport[Fuel combusted]=$E37)*(Table_Fuel_EFs_Transport[Transport type]=$D$37), Table_Fuel_EFs_Transport[Scope 1 Emission Factor (kg CO2 - e / GJ) CH4]), 0)} -> 10.1 | J37: {=IFERROR(_xlfn.XLOOKUP(1, (Table_Fuel_EFs_Transport[Fuel combusted]=$E37)*(Table_Fuel_EFs_Transport[Transport type]=$D$37), Table_Fuel_EFs_Transport[Scope 1 Emission Factor (kg CO2 - e / GJ) N2O]), 0)} -> 0.3 | K37: {=IFERROR(_xlfn.XLOOKUP(1, (Table_Fuel_EFs_Transport[Fuel combusted]=$E37)*(Table_Fuel_EFs_Transport[Transport type]=$D$25), Table_Fuel_EFs_Transport[Scope 3 Emission Factor (kg CO2 - e / GJ)]), 0)} -> 0 | L37: {=Fuel_InputFunctions.Fuel_TotalConsumption(Table_Input_Fuel[Amount consumed], Table_Input_Fuel[Fuel use (select)], D37, Table_Input_Fuel[Fuel type (select)],F37)} -> 0 | M37: {=Common_InputFunctions.Utility_LookupValueInTable(F37,Table_FuelTypes_Units[Fuel type],Table_FuelTypes_Units[Unit])} -> kL | N37: =((($L37 * $G37 * $H37) * 10 ^ -3)) -> 0 | O37: =((($L37 * $G37 * $I37) * 10 ^ -3)) -> 0 | P37: =((($L37 * $G37 * $J37) * 10 ^ -3)) -> 0 | Q37: =((L37 * G37 * K37) * 10 ^ -3) -> 0
D38: =$D$37 -> Vessels | E38: ='Constants - Fuel'!$E$11 -> Diesel oil | F38: ='Constants - Fuel'!$I$132 -> Diesel | G38: {=IFERROR(_xlfn.XLOOKUP(1, (Table_Fuel_EFs_Transport[Fuel combusted]=$E38)*(Table_Fuel_EFs_Transport[Transport type]=$D$37), Table_Fuel_EFs_Transport[Energy Content Factor (GJ per unit of fuel)]), 0)} -> 38.6 | H38: {=IFERROR(_xlfn.XLOOKUP(1, (Table_Fuel_EFs_Transport[Fuel combusted]=$E38)*(Table_Fuel_EFs_Transport[Transport type]=$D$37), Table_Fuel_EFs_Transport[Scope 1 Emission Factor (kg CO2 - e / GJ) CO2]), 0)} -> 69.9 | I38: {=IFERROR(_xlfn.XLOOKUP(1, (Table_Fuel_EFs_Transport[Fuel combusted]=$E38)*(Table_Fuel_EFs_Transport[Transport type]=$D$37), Table_Fuel_EFs_Transport[Scope 1 Emission Factor (kg CO2 - e / GJ) CH4]), 0)} -> 0.2 | J38: {=IFERROR(_xlfn.XLOOKUP(1, (Table_Fuel_EFs_Transport[Fuel combusted]=$E38)*(Table_Fuel_EFs_Transport[Transport type]=$D$37), Table_Fuel_EFs_Transport[Scope 1 Emission Factor (kg CO2 - e / GJ) N2O]), 0)} -> 0.5 | K38: {=IFERROR(_xlfn.XLOOKUP(1, (Table_Fuel_EFs_Transport[Fuel combusted]=$E38)*(Table_Fuel_EFs_Transport[Transport type]=$D$25), Table_Fuel_EFs_Transport[Scope 3 Emission Factor (kg CO2 - e / GJ)]), 0)} -> 0 | L38: {=Fuel_InputFunctions.Fuel_TotalConsumption(Table_Input_Fuel[Amount consumed], Table_Input_Fuel[Fuel use (select)], D38, Table_Input_Fuel[Fuel type (select)],F38)} -> 0 | M38: {=Common_InputFunctions.Utility_LookupValueInTable(F38,Table_FuelTypes_Units[Fuel type],Table_FuelTypes_Units[Unit])} -> kL | N38: =((($L38 * $G38 * $H38) * 10 ^ -3)) -> 0 | O38: =((($L38 * $G38 * $I38) * 10 ^ -3)) -> 0 | P38: =((($L38 * $G38 * $J38) * 10 ^ -3)) -> 0 | Q38: =((L38 * G38 * K38) * 10 ^ -3) -> 0
D39: =$D$37 -> Vessels | E39: ='Constants - Fuel'!E33 -> Fuel Oil | F39: ='Constants - Fuel'!$I$133 -> Fuel oil | G39: {=IFERROR(_xlfn.XLOOKUP(1, (Table_Fuel_EFs_Transport[Fuel combusted]=$E39)*(Table_Fuel_EFs_Transport[Transport type]=$D$37), Table_Fuel_EFs_Transport[Energy Content Factor (GJ per unit of fuel)]), 0)} -> 39.7 | H39: {=IFERROR(_xlfn.XLOOKUP(1, (Table_Fuel_EFs_Transport[Fuel combusted]=$E39)*(Table_Fuel_EFs_Transport[Transport type]=$D$37), Table_Fuel_EFs_Transport[Scope 1 Emission Factor (kg CO2 - e / GJ) CO2]), 0)} -> 73.6 | I39: {=IFERROR(_xlfn.XLOOKUP(1, (Table_Fuel_EFs_Transport[Fuel combusted]=$E39)*(Table_Fuel_EFs_Transport[Transport type]=$D$37), Table_Fuel_EFs_Transport[Scope 1 Emission Factor (kg CO2 - e / GJ) CH4]), 0)} -> 0.2 | J39: {=IFERROR(_xlfn.XLOOKUP(1, (Table_Fuel_EFs_Transport[Fuel combusted]=$E39)*(Table_Fuel_EFs_Transport[Transport type]=$D$37), Table_Fuel_EFs_Transport[Scope 1 Emission Factor (kg CO2 - e / GJ) N2O]), 0)} -> 0.5 | K39: {=IFERROR(_xlfn.XLOOKUP(1, (Table_Fuel_EFs_Transport[Fuel combusted]=$E39)*(Table_Fuel_EFs_Transport[Transport type]=$D$25), Table_Fuel_EFs_Transport[Scope 3 Emission Factor (kg CO2 - e / GJ)]), 0)} -> 0 | L39: {=Fuel_InputFunctions.Fuel_TotalConsumption(Table_Input_Fuel[Amount consumed], Table_Input_Fuel[Fuel use (select)], D39, Table_Input_Fuel[Fuel type (select)],F39)} -> 0 | M39: {=Common_InputFunctions.Utility_LookupValueInTable(F39,Table_FuelTypes_Units[Fuel type],Table_FuelTypes_Units[Unit])} -> kL | N39: =((($L39 * $G39 * $H39) * 10 ^ -3)) -> 0 | O39: =((($L39 * $G39 * $I39) * 10 ^ -3)) -> 0 | P39: =((($L39 * $G39 * $J39) * 10 ^ -3)) -> 0 | Q39: =((L39 * G39 * K39) * 10 ^ -3) -> 0
D42: ="Total scope 1 - " & D25 -> Total scope 1 - from the use of a limited number of NGER data inputs. It is suggested that for Tasmania the use of the Victorian emission factors is appropriate,
D43: CO2 | E43: =SUM(N25:N32) -> 0 | F43: =$E$12 -> t CO2-e
D44: CH4 | E44: =SUM(O25:O32) -> 0 | F44: =$E$12 -> t CO2-e
D45: N2O | E45: =SUM(P25:P32) -> 0 | F45: =$E$12 -> t CO2-e
...

Sheet 8.2.1.1-2 Stationary fuel
A1: #VALUE! | C1: 8.2.1.1-2 Stationary fuel combustion
A3: =HYPERLINK("#'Home'!A1", "Home") -> Home | D3: Method 1
A4: =HYPERLINK("#'Overview'!A1", "Overview") -> Overview
A5: =HYPERLINK("#'Results'!A1", "Results") -> Results | D5: Emissions for each GHG from the stationary combustion of fuels | K5: Upstream emissions from scope 1 stationary combustion fuel use
D6: VEERG 2026: 8.2.1.1, Equation (1) | K6: VEERG 2026: 15.11.1.1, Equation (3)
A7: INPUTS | K7: VARIATION ON SOURCE: Added 'state' and 'metro/non-metro' arguments as gaseous scope 3 EFs are state and metro/non-metro location-based.
A8: =HYPERLINK("#'Input - Fuel'!A1", "Fuel") -> Fuel
A10: CALCULATIONS
A11: =HYPERLINK("#'8.1.1.1-2 Transport fuel'!A1", "8.1.1.1-2 Transport fuel") -> 8.1.1.1-2 Transport fuel | D11: Variable | E11: E_g | K11: Variable | L11: E_WTTSCq
A12: =HYPERLINK("#'8.2.1.1-2 Stationary fuel'!A1", "8.2.1.1-2 Stationary fuel") -> 8.2.1.1-2 Stationary fuel | D12: Unit | E12: t CO2-e | K12: Unit | L12: t CO2e
A13: =HYPERLINK("#'8.X.1.1-2 General use fuel'!A1", "8.X.1.1-2 General use fuel") -> 8.X.1.1-2 General use fuel
D14: Q_SCq | E14: Amount of fuel type q used for stationary combustion operations | G14: Varies based on fuel type: kL, m3, GJ | H14: Input | I14: {=HYPERLINK(Common_InputFunctions.Utility_SourceHyperlink($D$22), $D$22)} -> Table_E_g | K14: Q_SCq | L14: amount of fuel q used for stationary combustion operations | N14: kL | O14: Input | P14: {=HYPERLINK(Common_InputFunctions.Utility_SourceHyperlink($D$22), $D$22)} -> Table_E_g
A15: APPENDICES | D15: EC_SCq | E15: Energy content factor for stationary combustion operations | G15: GJ / unit of fuel | H15: Constant | I15: {=HYPERLINK(Common_InputFunctions.Utility_SourceHyperlink($D$22), $D$22)} -> Table_E_g | K15: EC_SCq | L15: energy content factor for stationary combustion operations | N15: GJ/kL | O15: Constant | P15: {=HYPERLINK(Common_InputFunctions.Utility_SourceHyperlink($D$22), $D$22)} -> Table_E_g
A16: =HYPERLINK("#'Constants - Fuel'!A1", "Constants - Fuel") -> Constants - Fuel | D16: EF_SC1qg | E16: Scope 1 emission factor for stationary combustion for each greenhouse gas | G16: kg CO2e / GJ | H16: Constant | I16: {=HYPERLINK(Common_InputFunctions.Utility_SourceHyperlink($D$22), $D$22)} -> Table_E_g | K16: EF_SC3q | L16: scope 3 emission factor for stationary combustion operations | N16: kg CO2e/GJ | O16: Constant | P16: {=HYPERLINK(Common_InputFunctions.Utility_SourceHyperlink($D$22), $D$22)} -> Table_E_g
A17: =HYPERLINK("#'Constants - Common'!A1", "Constants - Common") -> Constants - Common | D17: q | E17: Fuel type | H17: Constant | K17: i | L17: state | O17: Input | P17: ='Input - Site'!$E$21 -> Western Australia
D18: SC | E18: Stationary combustion | H18: Constant | K18: m | L18: metropolitan/non-metropolitan location | O18: Input | P18: ='Input - Fuel'!E11 -> Metro
D19: g | E19: Greenhouse gas | H19: Constant
D20: 1 | E20: Scope 1 | H20: Constant
D22: Table_E_g
D23: Emissions for stationary fuel combustion
D24: Fuel use | E24: Fuel type (NGAF terminology) | F24: Fuel type (q) | G24: ECSC,q | H24: EFSC,1,q,g=CO2 | I24: EFSC,1,q,g=CH4 | J24: EFSC,1,q,g=N20 | K24: EFSC,3,q | L24: QSC,q | M24: Q unit | N24: Eg=CO2 | O24: Eg=CH4 | P24: Eg=N20 | Q24: EWTT,SC,q=N20
D25: =Table_FuelTypesPerUse[[#Headers],[Generators]] -> Generators | E25: ='Constants - Fuel'!$D$58 -> Automotive gasoline / petrol (other than for use as fuel in an aircraft) | F25: ='Constants - Fuel'!D131 -> Petrol | G25: =IFERROR(_xlfn.XLOOKUP($E25, Table_Fuel_EFs_StationaryLiquid[Fuel combusted], Table_Fuel_EFs_StationaryLiquid[Energy Content Factor (GJ per unit of fuel)]),0) -> 34.2 | H25: =IFERROR(_xlfn.XLOOKUP($E25, Table_Fuel_EFs_StationaryLiquid[Fuel combusted], Table_Fuel_EFs_StationaryLiquid[Scope 1 Emission Factor (kg CO2 - e / GJ) CO2]),0) -> 67.4 | I25: =IFERROR(_xlfn.XLOOKUP($E25, Table_Fuel_EFs_StationaryLiquid[Fuel combusted], Table_Fuel_EFs_StationaryLiquid[Scope 1 Emission Factor (kg CO2 - e / GJ) CH4]),0) -> 0.2 | J25: =IFERROR(_xlfn.XLOOKUP($E25, Table_Fuel_EFs_StationaryLiquid[Fuel combusted], Table_Fuel_EFs_StationaryLiquid[Scope 1 Emission Factor (kg CO2 - e / GJ) N2O]),0) -> 0.2 | K25: =IFERROR(_xlfn.XLOOKUP($E25, Table_Fuel_EFs_StationaryLiquid[Fuel combusted], Table_Fuel_EFs_StationaryLiquid[Scope 3 Emission Factor (kg CO2 - e / GJ)]),0) -> 17.2 | L25: {=Fuel_InputFunctions.Fuel_TotalConsumption(Table_Input_Fuel[Amount consumed], Table_Input_Fuel[Fuel use (select)], D25, Table_Input_Fuel[Fuel type (select)],F25)} -> 0 | M25: {=Common_InputFunctions.Utility_LookupValueInTable(F25,Table_FuelTypes_Units[Fuel type],Table_FuelTypes_Units[Unit])} -> kL | N25: =((($L25 * $G25 * H25) * 10 ^ -3)) -> 0 | O25: =((($L25 * $G25 * I25) * 10 ^ -3)) -> 0 | P25: =((($L25 * $G25 * J25) * 10 ^ -3)) -> 0 | Q25: =((($L25 * $G25 * ((IF(ISNUMBER(K25), K25, 0)))) * 10 ^ -3)) -> 0
D26: =$D$25 -> Generators | E26: ='Constants - Fuel'!$D$63 -> Diesel oil | F26: ='Constants - Fuel'!D132 -> Diesel | G26: =IFERROR(_xlfn.XLOOKUP($E26, Table_Fuel_EFs_StationaryLiquid[Fuel combusted], Table_Fuel_EFs_StationaryLiquid[Energy Content Factor (GJ per unit of fuel)]),0) -> 38.6 | H26: =IFERROR(_xlfn.XLOOKUP($E26, Table_Fuel_EFs_StationaryLiquid[Fuel combusted], Table_Fuel_EFs_StationaryLiquid[Scope 1 Emission Factor (kg CO2 - e / GJ) CO2]),0) -> 69.9 | I26: =IFERROR(_xlfn.XLOOKUP($E26, Table_Fuel_EFs_StationaryLiquid[Fuel combusted], Table_Fuel_EFs_StationaryLiquid[Scope 1 Emission Factor (kg CO2 - e / GJ) CH4]),0) -> 0.1 | J26: =IFERROR(_xlfn.XLOOKUP($E26, Table_Fuel_EFs_StationaryLiquid[Fuel combusted], Table_Fuel_EFs_StationaryLiquid[Scope 1 Emission Factor (kg CO2 - e / GJ) N2O]),0) -> 0.2 | K26: =IFERROR(_xlfn.XLOOKUP($E26, Table_Fuel_EFs_StationaryLiquid[Fuel combusted], Table_Fuel_EFs_StationaryLiquid[Scope 3 Emission Factor (kg CO2 - e / GJ)]),0) -> 17.3 | L26: {=Fuel_InputFunctions.Fuel_TotalConsumption(Table_Input_Fuel[Amount consumed], Table_Input_Fuel[Fuel use (select)], D26, Table_Input_Fuel[Fuel type (select)],F26)} -> 0 | M26: {=Common_InputFunctions.Utility_LookupValueInTable(F26,Table_FuelTypes_Units[Fuel type],Table_FuelTypes_Units[Unit])} -> kL | N26: =((($L26 * $G26 * H26) * 10 ^ -3)) -> 0 | O26: =((($L26 * $G26 * I26) * 10 ^ -3)) -> 0 | P26: =((($L26 * $G26 * J26) * 10 ^ -3)) -> 0 | Q26: =((($L26 * $G26 * ((IF(ISNUMBER(K26), K26, 0)))) * 10 ^ -3)) -> 0
D27: =$D$25 -> Generators | E27: ='Constants - Fuel'!$D$67 -> Liquefied petroleum gas (LPG) | F27: ='Constants - Fuel'!D133 -> Liquefied petroleum gas (LPG) | G27: =IFERROR(_xlfn.XLOOKUP($E27, Table_Fuel_EFs_StationaryLiquid[Fuel combusted], Table_Fuel_EFs_StationaryLiquid[Energy Content Factor (GJ per unit of fuel)]),0) -> 25.7 | H27: =IFERROR(_xlfn.XLOOKUP($E27, Table_Fuel_EFs_StationaryLiquid[Fuel combusted], Table_Fuel_EFs_StationaryLiquid[Scope 1 Emission Factor (kg CO2 - e / GJ) CO2]),0) -> 60.2 | I27: =IFERROR(_xlfn.XLOOKUP($E27, Table_Fuel_EFs_StationaryLiquid[Fuel combusted], Table_Fuel_EFs_StationaryLiquid[Scope 1 Emission Factor (kg CO2 - e / GJ) CH4]),0) -> 0.2 | J27: =IFERROR(_xlfn.XLOOKUP($E27, Table_Fuel_EFs_StationaryLiquid[Fuel combusted], Table_Fuel_EFs_StationaryLiquid[Scope 1 Emission Factor (kg CO2 - e / GJ) N2O]),0) -> 0.2 | K27: =IFERROR(_xlfn.XLOOKUP($E27, Table_Fuel_EFs_StationaryLiquid[Fuel combusted], Table_Fuel_EFs_StationaryLiquid[Scope 3 Emission Factor (kg CO2 - e / GJ)]),0) -> 20.2 | L27: {=Fuel_InputFunctions.Fuel_TotalConsumption(Table_Input_Fuel[Amount consumed], Table_Input_Fuel[Fuel use (select)], D27, Table_Input_Fuel[Fuel type (select)],F27)} -> 0 | M27: {=Common_InputFunctions.Utility_LookupValueInTable(F27,Table_FuelTypes_Units[Fuel type],Table_FuelTypes_Units[Unit])} -> kL | N27: =((($L27 * $G27 * H27) * 10 ^ -3)) -> 0 | O27: =((($L27 * $G27 * I27) * 10 ^ -3)) -> 0 | P27: =((($L27 * $G27 * J27) * 10 ^ -3)) -> 0 | Q27: =((($L27 * $G27 * ((IF(ISNUMBER(K27), K27, 0)))) * 10 ^ -3)) -> 0
D28: =$D$25 -> Generators | E28: ='Constants - Fuel'!$D$73 -> Biodiesel | F28: ='Constants - Fuel'!D134 -> Biodiesel | G28: =IFERROR(_xlfn.XLOOKUP($E28, Table_Fuel_EFs_StationaryLiquid[Fuel combusted], Table_Fuel_EFs_StationaryLiquid[Energy Content Factor (GJ per unit of fuel)]),0) -> 34.6 | H28: =IFERROR(_xlfn.XLOOKUP($E28, Table_Fuel_EFs_StationaryLiquid[Fuel combusted], Table_Fuel_EFs_StationaryLiquid[Scope 1 Emission Factor (kg CO2 - e / GJ) CO2]),0) -> 0 | I28: =IFERROR(_xlfn.XLOOKUP($E28, Table_Fuel_EFs_StationaryLiquid[Fuel combusted], Table_Fuel_EFs_StationaryLiquid[Scope 1 Emission Factor (kg CO2 - e / GJ) CH4]),0) -> 0.08 | J28: =IFERROR(_xlfn.XLOOKUP($E28, Table_Fuel_EFs_StationaryLiquid[Fuel combusted], Table_Fuel_EFs_StationaryLiquid[Scope 1 Emission Factor (kg CO2 - e / GJ) N2O]),0) -> 0.2 | K28: =IFERROR(_xlfn.XLOOKUP($E28, Table_Fuel_EFs_StationaryLiquid[Fuel combusted], Table_Fuel_EFs_StationaryLiquid[Scope 3 Emission Factor (kg CO2 - e / GJ)]),0) -> NE | L28: {=Fuel_InputFunctions.Fuel_TotalConsumption(Table_Input_Fuel[Amount consumed], Table_Input_Fuel[Fuel use (select)], D28, Table_Input_Fuel[Fuel type (select)],F28)} -> 0 | M28: {=Common_InputFunctions.Utility_LookupValueInTable(F28,Table_FuelTypes_Units[Fuel type],Table_FuelTypes_Units[Unit])} -> kL | N28: =((($L28 * $G28 * H28) * 10 ^ -3)) -> 0 | O28: =((($L28 * $G28 * I28) * 10 ^ -3)) -> 0 | P28: =((($L28 * $G28 * J28) * 10 ^ -3)) -> 0 | Q28: =((($L28 * $G28 * ((IF(ISNUMBER(K28), K28, 0)))) * 10 ^ -3)) -> 0
D29: =$D$25 -> Generators | E29: ='Constants - Fuel'!$D$74 -> Ethanol for use as a fuel in an internal combustion engine | F29: ='Constants - Fuel'!D135 -> Ethanol | G29: =IFERROR(_xlfn.XLOOKUP($E29, Table_Fuel_EFs_StationaryLiquid[Fuel combusted], Table_Fuel_EFs_StationaryLiquid[Energy Content Factor (GJ per unit of fuel)]),0) -> 23.4 | H29: =IFERROR(_xlfn.XLOOKUP($E29, Table_Fuel_EFs_StationaryLiquid[Fuel combusted], Table_Fuel_EFs_StationaryLiquid[Scope 1 Emission Factor (kg CO2 - e / GJ) CO2]),0) -> 0 | I29: =IFERROR(_xlfn.XLOOKUP($E29, Table_Fuel_EFs_StationaryLiquid[Fuel combusted], Table_Fuel_EFs_StationaryLiquid[Scope 1 Emission Factor (kg CO2 - e / GJ) CH4]),0) -> 0.08 | J29: =IFERROR(_xlfn.XLOOKUP($E29, Table_Fuel_EFs_StationaryLiquid[Fuel combusted], Table_Fuel_EFs_StationaryLiquid[Scope 1 Emission Factor (kg CO2 - e / GJ) N2O]),0) -> 0.2 | K29: =IFERROR(_xlfn.XLOOKUP($E29, Table_Fuel_EFs_StationaryLiquid[Fuel combusted], Table_Fuel_EFs_StationaryLiquid[Scope 3 Emission Factor (kg CO2 - e / GJ)]),0) -> NE | L29: {=Fuel_InputFunctions.Fuel_TotalConsumption(Table_Input_Fuel[Amount consumed], Table_Input_Fuel[Fuel use (select)], D29, Table_Input_Fuel[Fuel type (select)],F29)} -> 0 | M29: {=Common_InputFunctions.Utility_LookupValueInTable(F29,Table_FuelTypes_Units[Fuel type],Table_FuelTypes_Units[Unit])} -> kL | N29: =((($L29 * $G29 * H29) * 10 ^ -3)) -> 0 | O29: =((($L29 * $G29 * I29) * 10 ^ -3)) -> 0 | P29: =((($L29 * $G29 * J29) * 10 ^ -3)) -> 0 | Q29: =((($L29 * $G29 * ((IF(ISNUMBER(K29), K29, 0)))) * 10 ^ -3)) -> 0
D30: =$D$25 -> Generators | E30: ='Constants - Fuel'!$D$75 -> Biofuels other than those mentioned in the items above and below | F30: ='Constants - Fuel'!D136 -> Other biofuels | G30: =IFERROR(_xlfn.XLOOKUP($E30, Table_Fuel_EFs_StationaryLiquid[Fuel combusted], Table_Fuel_EFs_StationaryLiquid[Energy Content Factor (GJ per unit of fuel)]),0) -> 23.4 | H30: =IFERROR(_xlfn.XLOOKUP($E30, Table_Fuel_EFs_StationaryLiquid[Fuel combusted], Table_Fuel_EFs_StationaryLiquid[Scope 1 Emission Factor (kg CO2 - e / GJ) CO2]),0) -> 0 | I30: =IFERROR(_xlfn.XLOOKUP($E30, Table_Fuel_EFs_StationaryLiquid[Fuel combusted], Table_Fuel_EFs_StationaryLiquid[Scope 1 Emission Factor (kg CO2 - e / GJ) CH4]),0) -> 0.08 | J30: =IFERROR(_xlfn.XLOOKUP($E30, Table_Fuel_EFs_StationaryLiquid[Fuel combusted], Table_Fuel_EFs_StationaryLiquid[Scope 1 Emission Factor (kg CO2 - e / GJ) N2O]),0) -> 0.2 | K30: =IFERROR(_xlfn.XLOOKUP($E30, Table_Fuel_EFs_StationaryLiquid[Fuel combusted], Table_Fuel_EFs_StationaryLiquid[Scope 3 Emission Factor (kg CO2 - e / GJ)]),0) -> NE | L30: {=Fuel_InputFunctions.Fuel_TotalConsumption(Table_Input_Fuel[Amount consumed], Table_Input_Fuel[Fuel use (select)], D30, Table_Input_Fuel[Fuel type (select)],F30)} -> 0 | M30: {=Common_InputFunctions.Utility_LookupValueInTable(F30,Table_FuelTypes_Units[Fuel type],Table_FuelTypes_Units[Unit])} -> kL | N30: =((($L30 * $G30 * H30) * 10 ^ -3)) -> 0 | O30: =((($L30 * $G30 * I30) * 10 ^ -3)) -> 0 | P30: =((($L30 * $G30 * J30) * 10 ^ -3)) -> 0 | Q30: =((($L30 * $G30 * ((IF(ISNUMBER(K30), K30, 0)))) * 10 ^ -3)) -> 0
D31: =$D$25 -> Generators | E31: ='Constants - Fuel'!$D$77 -> Renewable diesel | F31: ='Constants - Fuel'!D137 -> Renewable diesel | G31: =IFERROR(_xlfn.XLOOKUP($E31, Table_Fuel_EFs_StationaryLiquid[Fuel combusted], Table_Fuel_EFs_StationaryLiquid[Energy Content Factor (GJ per unit of fuel)]),0) -> 38.6 | H31: =IFERROR(_xlfn.XLOOKUP($E31, Table_Fuel_EFs_StationaryLiquid[Fuel combusted], Table_Fuel_EFs_StationaryLiquid[Scope 1 Emission Factor (kg CO2 - e / GJ) CO2]),0) -> 0 | I31: =IFERROR(_xlfn.XLOOKUP($E31, Table_Fuel_EFs_StationaryLiquid[Fuel combusted], Table_Fuel_EFs_StationaryLiquid[Scope 1 Emission Factor (kg CO2 - e / GJ) CH4]),0) -> 0.1 | J31: =IFERROR(_xlfn.XLOOKUP($E31, Table_Fuel_EFs_StationaryLiquid[Fuel combusted], Table_Fuel_EFs_StationaryLiquid[Scope 1 Emission Factor (kg CO2 - e / GJ) N2O]),0) -> 0.2 | K31: =IFERROR(_xlfn.XLOOKUP($E31, Table_Fuel_EFs_StationaryLiquid[Fuel combusted], Table_Fuel_EFs_StationaryLiquid[Scope 3 Emission Factor (kg CO2 - e / GJ)]),0) -> NE | L31: {=Fuel_InputFunctions.Fuel_TotalConsumption(Table_Input_Fuel[Amount consumed], Table_Input_Fuel[Fuel use (select)], D31, Table_Input_Fuel[Fuel type (select)],F31)} -> 0 | M31: {=Common_InputFunctions.Utility_LookupValueInTable(F31,Table_FuelTypes_Units[Fuel type],Table_FuelTypes_Units[Unit])} -> kL | N31: =((($L31 * $G31 * H31) * 10 ^ -3)) -> 0 | O31: =((($L31 * $G31 * I31) * 10 ^ -3)) -> 0 | P31: =((($L31 * $G31 * J31) * 10 ^ -3)) -> 0 | Q31: =((($L31 * $G31 * ((IF(ISNUMBER(K31), K31, 0)))) * 10 ^ -3)) -> 0
