Workbook
Name AgResidue_Equations_FieldBurning.VEERG_6_4_1_1__1__MethaneEmissionsFromBurningOfCropResidues: _xlfn.LAMBDA(_xlpm.Mburnc,_xlpm.CCc,_xlpm.EFCH4,_xlpm.C_CH4, _xlpm.Mburnc * _xlpm.CCc * _xlpm.EFCH4 * _xlpm.C_CH4 * 10 ^ (-3))
Name AgResidue_Equations_FieldBurning.VEERG_6_4_1_1__1__MethaneEmissionsFromBurningOfCropResidues_FunctionName: _xlfn.LAMBDA("VEERG_6_4_1_1__1__MethaneEmissionsFromBurningOfCropResidues")
Name AgResidue_Equations_FieldBurning.VEERG_6_4_1_1__1__MethaneEmissionsFromBurningOfCropResidues_LatexEquation: _xlfn.LAMBDA("E_{CH4}=\sum_{c}(M_{burn,c}\times CC_{c}\times EF_{CH4}\times C_{CH4}\times 10^{-3})")
Name AgResidue_Equations_FieldBurning.VEERG_6_4_1_1__1__MethaneEmissionsFromBurningOfCropResidues_NIRReference: _xlfn.LAMBDA("")
Name AgResidue_Equations_FieldBurning.VEERG_6_4_1_1__1__MethaneEmissionsFromBurningOfCropResidues_Source: _xlfn.LAMBDA("VEERG 2026: 6.4.1.1, Equation (1)")
Name AgResidue_Equations_FieldBurning.VEERG_6_4_1_1__1__MethaneEmissionsFromBurningOfCropResidues_Title: _xlfn.LAMBDA("Methane emissions from the burning of crop residues")
Name AgResidue_Equations_FieldBurning.VEERG_6_4_1_1__1__MethaneEmissionsFromBurningOfCropResidues_Unit: _xlfn.LAMBDA("t CH4")
Name AgResidue_Equations_FieldBurning.VEERG_6_4_1_1__1__MethaneEmissionsFromBurningOfCropResidues_Variable: _xlfn.LAMBDA("ECH4")
Name AgResidue_Equations_FieldBurning.VEERG_6_4_1_1__2__NitrousOxideEmissionsFromBurningOfCropResidues: _xlfn.LAMBDA(_xlpm.Mburnc,_xlpm.NCAGc,_xlpm.EFN2O,_xlpm.CN2O, _xlpm.Mburnc * _xlpm.NCAGc * _xlpm.EFN2O * _xlpm.CN2O * 10 ^ (-3))
Name AgResidue_Equations_FieldBurning.VEERG_6_4_1_1__2__NitrousOxideEmissionsFromBurningOfCropResidues_FunctionName: _xlfn.LAMBDA("VEERG_6_4_1_1__2__NitrousOxideEmissionsFromBurningOfCropResidues")
Name AgResidue_Equations_FieldBurning.VEERG_6_4_1_1__2__NitrousOxideEmissionsFromBurningOfCropResidues_LatexEquation: _xlfn.LAMBDA("E_{N2O}=\sum_{c}(M_{burn,c}\times NC_{AGc}\times EF_{N2O}\times C_{N2O}\times 10^{-3})")
Name AgResidue_Equations_FieldBurning.VEERG_6_4_1_1__2__NitrousOxideEmissionsFromBurningOfCropResidues_NIRReference: _xlfn.LAMBDA("")
Name AgResidue_Equations_FieldBurning.VEERG_6_4_1_1__2__NitrousOxideEmissionsFromBurningOfCropResidues_Source: _xlfn.LAMBDA("VEERG 2026: 6.4.1.1, Equation (2)")
Name AgResidue_Equations_FieldBurning.VEERG_6_4_1_1__2__NitrousOxideEmissionsFromBurningOfCropResidues_Title: _xlfn.LAMBDA("Nitrous oxide emissions from the burning of crop residues")
Name AgResidue_Equations_FieldBurning.VEERG_6_4_1_1__2__NitrousOxideEmissionsFromBurningOfCropResidues_Unit: _xlfn.LAMBDA("t N2O")
Name AgResidue_Equations_FieldBurning.VEERG_6_4_1_1__2__NitrousOxideEmissionsFromBurningOfCropResidues_Variable: _xlfn.LAMBDA("EN2O")
Name AgResidue_Equations_FieldBurning.VEERG_6_4_1_1__3__MassOfCropResidueBurnt: _xlfn.LAMBDA(_xlpm.Pc,_xlpm.RAGc,_xlpm.Sc,_xlpm.DMc,_xlpm.Zc,_xlpm.Fc, _xlpm.Pc * _xlpm.RAGc * _xlpm.Sc * _xlpm.DMc * _xlpm.Zc * _xlpm.Fc)
Name AgResidue_Equations_FieldBurning.VEERG_6_4_1_1__3__MassOfCropResidueBurnt_FunctionName: _xlfn.LAMBDA("VEERG_6_4_1_1__3__MassOfCropResidueBurnt")
Name AgResidue_Equations_FieldBurning.VEERG_6_4_1_1__3__MassOfCropResidueBurnt_LatexEquation: _xlfn.LAMBDA("M_{burn,c}=P_{c}\times R_{AGc}\times S_{c}\times DM_{c}\times Z_{c}\times F_{c}")
Name AgResidue_Equations_FieldBurning.VEERG_6_4_1_1__3__MassOfCropResidueBurnt_NIRReference: _xlfn.LAMBDA("")
Name AgResidue_Equations_FieldBurning.VEERG_6_4_1_1__3__MassOfCropResidueBurnt_Source: _xlfn.LAMBDA("VEERG 2026: 6.4.1.1, Equation (3)")
Name AgResidue_Equations_FieldBurning.VEERG_6_4_1_1__3__MassOfCropResidueBurnt_Title: _xlfn.LAMBDA("Mass of residue of crop c burnt")
Name AgResidue_Equations_FieldBurning.VEERG_6_4_1_1__3__MassOfCropResidueBurnt_Unit: _xlfn.LAMBDA("kg")
Name AgResidue_Equations_FieldBurning.VEERG_6_4_1_1__3__MassOfCropResidueBurnt_Variable: _xlfn.LAMBDA("Mburnc")
Name AgResidues_Equations_CropResidues.VEERG_6_1_1_1__1__NitrousOxideEmissionsFromCropResidues: _xlfn.LAMBDA(_xlpm.Mc,_xlpm.EFNi,_xlpm.CgN2O, _xlpm.Mc * _xlpm.EFNi * _xlpm.CgN2O * 10 ^ (-3))
Name AgResidues_Equations_CropResidues.VEERG_6_1_1_1__1__NitrousOxideEmissionsFromCropResidues_FunctionName: _xlfn.LAMBDA("VEERG_6_1_1_1__1__NitrousOxideEmissionsFromCropResidues")
Name AgResidues_Equations_CropResidues.VEERG_6_1_1_1__1__NitrousOxideEmissionsFromCropResidues_LatexEquation: _xlfn.LAMBDA("E=\sum_{c}{M_{c}\times EF_{N}\times C_{g,N2O}\times 10^{-3}}")
Name AgResidues_Equations_CropResidues.VEERG_6_1_1_1__1__NitrousOxideEmissionsFromCropResidues_NIRReference: _xlfn.LAMBDA("")
Name AgResidues_Equations_CropResidues.VEERG_6_1_1_1__1__NitrousOxideEmissionsFromCropResidues_Source: _xlfn.LAMBDA("VEERG 2026: 6.1.1.1, Equation (1)")
Name AgResidues_Equations_CropResidues.VEERG_6_1_1_1__1__NitrousOxideEmissionsFromCropResidues_Title: _xlfn.LAMBDA("Nitrous oxide emissions from the return of crop residues across all crops c to the soil")
Name AgResidues_Equations_CropResidues.VEERG_6_1_1_1__1__NitrousOxideEmissionsFromCropResidues_Unit: _xlfn.LAMBDA("t N2O")
Name AgResidues_Equations_CropResidues.VEERG_6_1_1_1__1__NitrousOxideEmissionsFromCropResidues_Variable: _xlfn.LAMBDA("E")
Name AgResidues_Equations_CropResidues.VEERG_6_1_1_1__2__MassOfNitrogenInCropResidues_LatexEquation: _xlfn.LAMBDA("M_{c}=(P_{c}\times R_{AGc}\times(1-F_{c}-FFOD_{c})\times DM_{c}\times NC_{AGc})+(P_{c}\times R_{AGc}\times R_{BGc}\times DM_{c}\times NC_{BGc})")
Name AgResidues_Equations_CropResidues.VEERG_6_1_1_1__2__MassOfNitrogenInCropResidues_NIRReference: _xlfn.LAMBDA("")
Name AgResidues_Equations_CropResidues.VEERG_6_1_1_1__2__MassOfNitrogenInCropResidues_Source: _xlfn.LAMBDA("VEERG 2026: 6.1.1.1, Equation (2)")
Name AgResidues_Equations_CropResidues.VEERG_6_1_1_1__2__MassOfNitrogenInCropResidues_Title: _xlfn.LAMBDA("Mass of nitrogen in crop residues returned to the soil")
Name AgResidues_Equations_CropResidues.VEERG_6_1_1_1__2__MassOfNitrogenInCropResidues_Unit: _xlfn.LAMBDA("kg N")
Name AgResidues_Equations_CropResidues.VEERG_6_1_1_1__2__MassOfNitrogenInCropResidues_Variable: _xlfn.LAMBDA("Mc")
Name AgResidues_Equations_CropResidues.VEERG_6_1_1_2__1__FractionOfCropResidueRemovedBaled: _xlfn.LAMBDA(_xlpm.B,_xlpm.MB,_xlpm.Pc,_xlpm.RAGc, IFERROR((_xlpm.B * _xlpm.MB) / (_xlpm.Pc * _xlpm.RAGc), 0))
Name AgResidues_Equations_CropResidues.VEERG_6_1_1_2__1__FractionOfCropResidueRemovedBaled_LatexEquation: _xlfn.LAMBDA("FFOD_{c,baled}=\frac{B\times M_{B}}{P_{c}\times R_{AG,c}}")
Name AgResidues_Equations_CropResidues.VEERG_6_1_1_2__1__FractionOfCropResidueRemovedBaled_NIRReference: _xlfn.LAMBDA("")
Name AgResidues_Equations_CropResidues.VEERG_6_1_1_2__1__FractionOfCropResidueRemovedBaled_Source: _xlfn.LAMBDA("VEERG 2026: 6.1.1.2, Equation (1)")
Name AgResidues_Equations_CropResidues.VEERG_6_1_1_2__1__FractionOfCropResidueRemovedBaled_Title: _xlfn.LAMBDA("Fraction of crop residue that is removed for crop c, calculated where residues are baled")
Name AgResidues_Equations_CropResidues.VEERG_6_1_1_2__1__FractionOfCropResidueRemovedBaled_Unit: _xlfn.LAMBDA("dimensionless")
Name AgResidues_Equations_CropResidues.VEERG_6_1_1_2__1__FractionOfCropResidueRemovedBaled_Variable: _xlfn.LAMBDA("FFODcbaled")
Name AgResidues_Equations_CropResidues.VEERG_6_1_1_2__1__FractionOfCropResidueRemovedBaled_Variation: _xlfn.LAMBDA("VARIATION FROM SOURCE: Added 'baled' to variable subscript")
Name AgResidues_Equations_CropResidues.VEERG_6_1_1_2__1a__FractionOfCropResidueRemoved: _xlfn.LAMBDA(_xlpm.FFODcbaled,_xlpm.FFODcother, _xlpm.FFODcbaled + _xlpm.FFODcother)
Name AgResidues_Equations_CropResidues.VEERG_6_1_1_2__1a__FractionOfCropResidueRemoved_LatexEquation: _xlfn.LAMBDA("FFOD_{c} = FFOD_{c,baled} + FFOD_{c,other}")
Name AgResidues_Equations_CropResidues.VEERG_6_1_1_2__1a__FractionOfCropResidueRemoved_NIRReference: _xlfn.LAMBDA("")
Name AgResidues_Equations_CropResidues.VEERG_6_1_1_2__1a__FractionOfCropResidueRemoved_Source: _xlfn.LAMBDA("")
Name AgResidues_Equations_CropResidues.VEERG_6_1_1_2__1a__FractionOfCropResidueRemoved_Title: _xlfn.LAMBDA("Fraction of crop residue that is removed for crop c")
Name AgResidues_Equations_CropResidues.VEERG_6_1_1_2__1a__FractionOfCropResidueRemoved_Unit: _xlfn.LAMBDA("dimensionless")
Name AgResidues_Equations_CropResidues.VEERG_6_1_1_2__1a__FractionOfCropResidueRemoved_Variable: _xlfn.LAMBDA("FFODc")
Name AgResidues_Equations_CropResidues.VEERG_6_1_1_2__1a__FractionOfCropResidueRemoved_Variation: _xlfn.LAMBDA("VARIATION FROM SOURCE: Added this equation to accommodate user-defined residue removal other than baling.")
Name AgResidues_Equations_Leaching.VEERG_6_3_1_1__1__LeachingAndRunoffEmissionsCropAndPastureResidue: _xlfn.LAMBDA(_xlpm.Mleachcp,_xlpm.EFleach,_xlpm.CgN2O, _xlpm.Mleachcp * _xlpm.EFleach * _xlpm.CgN2O * 10 ^ (-3))
Name AgResidues_Equations_Leaching.VEERG_6_3_1_1__1__LeachingAndRunoffEmissionsCropAndPastureResidue_LatexEquation: _xlfn.LAMBDA("E_{N2O}=\sum_{c}\sum_{p}(M_{leach,cp}\times EF_{leach}\times Cg_{N2O}\times 10^{-3})")
Name AgResidues_Equations_Leaching.VEERG_6_3_1_1__1__LeachingAndRunoffEmissionsCropAndPastureResidue_NIRReference: _xlfn.LAMBDA("")
Name AgResidues_Equations_Leaching.VEERG_6_3_1_1__1__LeachingAndRunoffEmissionsCropAndPastureResidue_Source: _xlfn.LAMBDA("VEERG 2026: 6.3.1.1, Equation (1)")
Name AgResidues_Equations_Leaching.VEERG_6_3_1_1__1__LeachingAndRunoffEmissionsCropAndPastureResidue_Title: _xlfn.LAMBDA("Nitrous oxide leaching and runoff emissions from crop and pasture residues returned to the soil")
Name AgResidues_Equations_Leaching.VEERG_6_3_1_1__1__LeachingAndRunoffEmissionsCropAndPastureResidue_Unit: _xlfn.LAMBDA("t N2O")

Sheet Overview
C1: 13: Sope 3 emissions: Overview

Sheet Results
C1: 13: Sope 3 emissions: Results
D5: Emissions breakdown
D7: 💡 NOTE: When there is no Method 2, the Method 2 result are the same as Method 1
D9: Scope 1 source | E9: CO2-e emissions method 1 | F9: CO2-e emissions method 2
D10: {=Common_InputFunctions.Utility_ResultsItemFromEquationTitleAndSource('15 Scope 3'!D5,'15 Scope 3'!D6)} -> 15.1.1.1 Total emissions from purchased livestock | E10: - | F10: - | G10: t CO2e
D11: ='15 Scope 3'!D21 -> Beef cattle | E11: =VEERG_15_1_1_1__1_EmissionsFromPurchasedLivestock_BeefCattle_Result_Method1 -> 1052.5 | F11: =VEERG_15_1_1_1__1_EmissionsFromPurchasedLivestock_BeefCattle_Result_Method2 -> 1014.5 | G11: t CO2e
D12: ='15 Scope 3'!D38 -> Dairy cattle | E12: =VEERG_15_1_1_1__1_EmissionsFromPurchasedLivestock_DairyCattle_Result_Method1 -> 295.47 | F12: =VEERG_15_1_1_1__1_EmissionsFromPurchasedLivestock_DairyCattle_Result_Method2 -> 415.625 | G12: t CO2e
D13: ='15 Scope 3'!D57 -> Pigs | E13: =VEERG_15_1_1_1__1_EmissionsFromPurchasedLivestock_Pigs_Result_Method1 -> 0 | F13: =VEERG_15_1_1_1__1_EmissionsFromPurchasedLivestock_Pigs_Result_Method2 -> 73.38 | G13: t CO2e
D14: ='15 Scope 3'!D75 -> Poultry | E14: =VEERG_15_1_1_1__1_EmissionsFromPurchasedLivestock_Poultry_Result_Method1 -> 0.3672 | F14: =VEERG_15_1_1_1__1_EmissionsFromPurchasedLivestock_Poultry_Result_Method2 -> 0.3594 | G14: t CO2e
D15: {=Common_InputFunctions.Utility_ResultsItemFromEquationTitleAndSource('15 Scope 3'!D98,'15 Scope 3'!D99)} -> 15.2.1.1 Emissions from purchased feed | E15: =VEERG_15_2_1_1__1_EmissionsFromPurchasedFeed_Result_Method1 -> 377.052 | F15: =VEERG_15_2_1_1__1_EmissionsFromPurchasedFeed_Result_Method2 -> 529.78 | G15: t CO2e
D16: {=Common_InputFunctions.Utility_ResultsItemFromEquationTitleAndSource('15 Scope 3'!D149,'15 Scope 3'!D150)} -> 15.3.1.1 Total emissions from purchased mineral supplements | E16: =VEERG_15_3_1_1__1_EmissionsFromPurchasedMineralSupplements_Result_Method1 -> 178.9 | F16: =VEERG_15_3_1_1__1_EmissionsFromPurchasedMineralSupplements_Result_Method2 -> 160 | G16: t CO2e
D17: {=Common_InputFunctions.Utility_ResultsItemFromEquationTitleAndSource('15 Scope 3'!D186,'15 Scope 3'!D187)} -> 15.4.1.1 Emissions from purchased fertiliser | E17: =VEERG_15_4_1_1__2_EmissionsFromPurchasedFertiliserComponentsVariation_Result_Method1 -> 78.284322 | F17: =VEERG_15_4_1_1__2_EmissionsFromPurchasedFertiliserComponentsVariation_Result_Method2 -> 75.743047 | G17: t CO2e
D18: {=Common_InputFunctions.Utility_ResultsItemFromEquationTitleAndSource('15 Scope 3'!D256,'15 Scope 3'!D257)} -> 15.5.1.1 Total emissions from purchased agrichemicals | E18: =VEERG_15_5_1_1__1_EmissionsFromPurchasedAgrichemicals_Result_Method1 -> 7.516 | F18: =VEERG_15_5_1_1__1_EmissionsFromPurchasedAgrichemicals_Result_Method2 -> 7.496 | G18: t CO2e
D19: {=Common_InputFunctions.Utility_ResultsItemFromEquationTitleAndSource('15 Scope 3'!D288,'15 Scope 3'!D289)} -> 15.6.1.1 Embedded emissions for purchased lime | E19: =VEERG_15_6_1_1__1_EmissionsFromPurchasedLime_Result_Method1 -> 0 | F19: =VEERG_15_6_1_1__1_EmissionsFromPurchasedLime_Result_Method2 -> 0 | G19: t CO2e
D20: {=Common_InputFunctions.Utility_ResultsItemFromEquationTitleAndSource('15 Scope 3'!D321,'15 Scope 3'!D322)} -> 15.7.1.1 Emissions of purchased services and contractor operations | E20: =VEERG_15_7_1_1__1_EmissionsFromPurchasedServices_Result_Method1 -> No data | F20: =VEERG_15_7_1_1__1_EmissionsFromPurchasedServices_Result_Method2 -> 42 | G20: t CO2e
D21: {=Common_InputFunctions.Utility_ResultsItemFromEquationTitleAndSource('15 Scope 3'!D352,'15 Scope 3'!D353)} -> 15.8.1.1 Embedded emissions from use of packaging materials | E21: =VEERG_15_8_1_1__1_EmissionsFromPurchasedPackaging_Result_Method1 -> 7.44 | F21: =VEERG_15_8_1_1__1_EmissionsFromPurchasedPackaging_Result_Method2 -> 6 | G21: t CO2e
D22: {=Common_InputFunctions.Utility_ResultsItemFromEquationTitleAndSource('15 Scope 3'!D383,'15 Scope 3'!D384)} -> 15.9.1.1 Embedded emissions from use of grow media products | E22: =VEERG_15_9_1_1__1_EmissionsFromPurchasedGrowMedia_Result_Method1 -> No data | F22: =VEERG_15_9_1_1__1_EmissionsFromPurchasedGrowMedia_Result_Method2 -> 40.2 | G22: t CO2e
D23: {=Common_InputFunctions.Utility_ResultsItemFromEquationTitleAndSource('15 Scope 3'!D415,'15 Scope 3'!D416)} -> 15.10 Other purchased goods and services generic estimate | E23: - | F23: - | G23: t CO2e
D24: ='15 Scope 3'!D427 -> Cleaning chemical purchases | E24: =VEERG_15_10_1_1__1_OtherPurchasedGoodsAndServices_CleaningChemicals_Result_Method1 -> 0.5051 | F24: =VEERG_15_10_1_1__1_OtherPurchasedGoodsAndServices_CleaningChemicals_Result_Method2 -> 2.73 | G24: t CO2e
D25: ='15 Scope 3'!D445 -> Pharmacy chemical purchases | E25: =VEERG_15_10_1_1__1_OtherPurchasedGoodsAndServices_PharmacyChemicals_Result_Method1 -> 0.015636 | F25: =VEERG_15_10_1_1__1_OtherPurchasedGoodsAndServices_PharmacyChemicals_Result_Method2 -> 0.0134 | G25: t CO2e
D26: ='15 Scope 3'!D463 -> Seed | E26: =VEERG_15_10_1_1__1_OtherPurchasedGoodsAndServices_Seed_Result_Method1 -> 0.8439 | F26: =VEERG_15_10_1_1__1_OtherPurchasedGoodsAndServices_Seed_Result_Method2 -> 0.7142 | G26: t CO2e
D27: ='15 Scope 3'!D476 -> Miscellaneous Inputs | E27: =VEERG_15_10_1_1__1_OtherPurchasedGoodsAndServices_Misc_Result_Method1 -> 2.9531 | F27: =VEERG_15_10_1_1__1_OtherPurchasedGoodsAndServices_Misc_Result_Method2 -> 0.08586 | G27: t CO2e
D28: ='15 Scope 3'!D487 -> Uncategorised products with no Method 1 EF data | E28: =VEERG_15_10_1_1__1_OtherPurchasedGoodsAndServices_Uncategorised_Result_Method1 -> No data | F28: =VEERG_15_10_1_1__1_OtherPurchasedGoodsAndServices_Uncategorised_Result_Method2 -> 4000 | G28: t CO2e
D29: {=Common_InputFunctions.Utility_ResultsItemFromEquationTitleAndSource('15 Scope 3'!D506,'15 Scope 3'!D507)} -> 15.11.1.1 Total upstream emissions from scope 1 fuel consumption | E29: =VEERG_15_11_1_1__1_TotalUpstreamEmissionsFromFuel_Result -> 26.794 | F29: =E29 -> 26.794 | G29: t CO2e
D30: {=Common_InputFunctions.Utility_ResultsItemFromEquationTitleAndSource('15 Scope 3'!D521,'15 Scope 3'!D522)} -> 15.12.1.1 Scope 3 emissions from purchased electricity location based | E30: =VEERG_15_12_1_1__1_UpstreamPurchasedElectricityLocationBased_Result -> 2.7 | F30: =E30 -> 2.7 | G30: t CO2e
D31: {=Common_InputFunctions.Utility_ResultsItemFromEquationTitleAndSource('15 Scope 3'!D537,'15 Scope 3'!D538)} -> 15.12.1.2 Scope 3 emissions from purchased electricity market based | E31: =VEERG_15_12_1_2__1_UpstreamPurchasedElectricityMarketBasedVariation_Result -> 1.5 | F31: =E31 -> 1.5 | G31: t CO2e
D32: {=Common_InputFunctions.Utility_ResultsItemFromEquationTitleAndSource('15 Scope 3'!D559,'15 Scope 3'!D560)} -> 15.13.1.1 Emissions from manure sent off site applied to soils in another farming system or enterprise | E32: =VEERG_15_13_1_1__1_EmissionsFromManureSentOffSite_Result_Method1_CO2e -> 3.7936643 | F32: =VEERG_15_13_1_1__1_EmissionsFromManureSentOffSite_Result_Method2_CO2e -> 7.5873286 | G32: t CO2e
D33: {=Common_InputFunctions.Utility_ResultsItemFromEquationTitleAndSource('15 Scope 3'!D582,'15 Scope 3'!D583&",")} -> 15.13.1.3 Emissions from solid waste sent to a treatment facility | E33: =VEERG_10_1_1_1__1_EmissionsFromWasteManagement_Scope3_Result_Method1 -> 441.15 | F33: =E33 -> 441.15 | G33: t CO2e
D34: {=Common_InputFunctions.Utility_ResultsItemFromEquationTitleAndSource('15 Scope 3'!D592,'15 Scope 3'!D593)} -> 15.14.1.1 Embedded emissions from upstream freight | E34: - | F34: - | G34: t CO2e
D35: ='15 Scope 3'!D606 -> Incoming freight | E35: =VEERG_15_14_1_1__1_EmbeddedEmissionsFromUpstreamFreight_Incoming_Result_Method1 -> No data | F35: =VEERG_15_14_1_1__1_EmbeddedEmissionsFromUpstreamFreight_Incoming_Result_Method2 -> 5146700 | G35: t CO2e
D36: ='15 Scope 3'!D624 -> Outgoing freight | E36: =VEERG_15_14_1_1__1_EmbeddedEmissionsFromUpstreamFreight_Outgoing_Result_Method1 -> No data | F36: =VEERG_15_14_1_1__1_EmbeddedEmissionsFromUpstreamFreight_Outgoing_Result_Method2 -> 432640 | G36: t CO2e
D37: Total | E37: =SUM(E10:E36) -> 2477.7849 | F37: =SUM(F10:F36) -> 5586188.4 | G37: t CO2e

Sheet Input - Site
A1: #VALUE! | C1: Input - Site
A3: =HYPERLINK("#'Home'!A1", "Home") -> Home
A4: =HYPERLINK("#'Overview'!A1", "Overview") -> Overview
A5: =HYPERLINK("#'Results'!A1", "Results") -> Results | D5: Your business
A7: INPUTS | D7: Farm name | E7: Test Farms
A8: =HYPERLINK("#'Input - Site'!A1", "Site") -> Site | D8: Reporting entity name | E8: Test Farms Pty Ltd
A9: =HYPERLINK("#'Input - Fertiliser'!A1", "Fertiliser") -> Fertiliser
D10: 💡An 'Emissions accounting period' is a 12 month period where the business can report on the emissions, and is typically the same as the business' financial accounting period.
A11: CALCULATIONS
A12: =HYPERLINK("#'5.1.1.1-2 Inorganic Fert N2O'!A1", "5.1.1.1-2 Inorganic Fert N2O") -> 5.1.1.1-2 Inorganic Fert N2O | D12: Emissions calculation period start date | E12: 45292 | F12: ← DD/MM/YYYY or DD Month YYYY
A13: =HYPERLINK("#'5.1.1.3-4 Inorganic fert CO2'!A1", "5.1.1.3-4 Inorganic fert CO2") -> 5.1.1.3-4 Inorganic fert CO2 | D13: Emissions calculation period end date | E13: =DATE(YEAR(E12)+1,MONTH(E12),DAY(E12))-1 -> 45657 | F13: ← Automatically calculated, 12 months after start date
A14: =HYPERLINK("#'5.2.1.1-2 Organic Fert N2O'!A1", "5.2.1.1-2 Organic Fert N2O") -> 5.2.1.1-2 Organic Fert N2O
A15: =HYPERLINK("#'5.3.1.1-2 Lime CO2'!A1", "5.3.1.1-2 Lime CO2") -> 5.3.1.1-2 Lime CO2
A16: =HYPERLINK("#'5.4.1.1-4 Atmos deposition'!A1", "5.4.1.1-4 Atmos deposition") -> 5.4.1.1-4 Atmos deposition | D16: Location and climate
A17: =HYPERLINK("#'5.5.1.1-2 Leaching and runoff'!A1", "5.5.1.1-2 Leaching and runoff") -> 5.5.1.1-2 Leaching and runoff
D18: Location information is used to reference some region and climate-specific emission factors
A19: APPENDICES | D19: Tip: Use the web-based GAF Location Helper tool to easily get region and climate information. You will need an internet connection to use the GAF Location Helper.
A20: =HYPERLINK("#'Constants - Fertiliser'!A1", "Constants - Fertiliser") -> Constants - Fertiliser
A21: =HYPERLINK("#'Constants - Common'!A1", "Constants - Common") -> Constants - Common | D21: State | E21: Western Australia | F21: ← Please select
D22: Region (ABS Statistical area level 4) if state is WA | E22: Western Australia - Outback (South) | F22: ← Please select
D23: Leaching zone | E23: NO - Not in leaching zone | F23: ← Please select
D24: Elevation | E24: 307.7 | F24: Meters
D25: Average temperature for reporting period | E25: 18 | F25: Degrees celsius
D26: Total rainfall for reporting period | E26: 599 | F26: Millimetres
D27: Potential evapotranspiration for reporting period | E27: 1326 | F27: Millimetres
D28: Number of frost days for reporting period | E28: 7 | F28: Days
D29: MAP:PET ratio | E29: =E26/E27 -> 0.45173454
D30: Rainfall zone | E30: =Common_InputFunctions.Utility_LookupItemFromMinMax(E26,Table_SourceData_RainfallZones[Min rainfall],Table_SourceData_RainfallZones[Max rainfall],Table_SourceData_RainfallZones[Rainfall Zone]) -> Low rainfall
D31: Climate zone | E31: =Common_InputFunctions.Utility_GetClimateZone(E25,E26,E28,E24,E29,Table_SourceData_ClimateZones[Min temp],Table_SourceData_ClimateZones[Max temp],Table_SourceData_ClimateZones[Min rainfall],Table_SourceData_ClimateZones[Max rainfall],Table_SourceData_ClimateZones[Min frost days],Table_SourceData_ClimateZones[Max frost days],Table_SourceData_ClimateZones[Min elevation],Table_SourceData_ClimateZones[Max elevation],Table_SourceData_ClimateZones[Min MAP:PET],Table_SourceData_ClimateZones[Max MAP:PET],Table_SourceData_ClimateZones[Climate zone]) -> Warm temperate dry
D32: Wet or dry climate zone | E32: =Common_InputFunctions.Utility_LookupValueInTable($E$31,Table_SourceData_WetDryZones[Climate zone],Table_SourceData_WetDryZones[Wet or Dry Zone]) -> Dry climate zone
D33: Temperature zone | E33: =Common_InputFunctions.Utility_LookupItemFromMinMax(E25,Table_SourceData_TemperatureZones[Min MAT],Table_SourceData_TemperatureZones[Max MAT],Table_SourceData_TemperatureZones[Temperature Zone]) -> Temperate

Sheet Input - Fuel
A1: #VALUE! | C1: Input - Fuel
A3: =HYPERLINK("#'Home'!A1", "Home") -> Home
A4: =HYPERLINK("#'Overview'!A1", "Overview") -> Overview
A5: =HYPERLINK("#'Results'!A1", "Results") -> Results | D5: Fuel purchases and consumption
A7: INPUTS | D7: A 'Metropolitan' location is:
A8: =HYPERLINK("#'Input - Fuel'!A1", "Fuel") -> Fuel | D8: ● On or east of the dividing range in NSW (including Canberra and Queanbeyan)
D9: ● In Melbourne, Brisbane, Adelaide or Perth
A10: CALCULATIONS
A11: =HYPERLINK("#'8.1.1.1-2 Transport fuel'!A1", "8.1.1.1-2 Transport fuel") -> 8.1.1.1-2 Transport fuel | D11: Is the property in a Metropolitan location? | E11: Metro | F11: ← Please select
A12: =HYPERLINK("#'8.2.1.1-2 Stationary fuel'!A1", "8.2.1.1-2 Stationary fuel") -> 8.2.1.1-2 Stationary fuel
A13: =HYPERLINK("#'8.X.1.1-2 General use fuel'!A1", "8.X.1.1-2 General use fuel") -> 8.X.1.1-2 General use fuel | D13: 💡 You can add more rows to the table by right-clicking on the table and selecting "Insert > Table rows above/below"
D14: 💡 'Percent consumed" is 100% by default. If you purchased more fuel than was consumed you can edit this field.
A15: APPENDICES
A16: =HYPERLINK("#'Constants - Fuel'!A1", "Constants - Fuel") -> Constants - Fuel | D16: Fuel use (select) | E16: Fuel type (select) | F16: Amount purchased | G16: Amount unit | H16: Percent consumed | I16: Amount consumed | J16: Amount consumed unit
A17: =HYPERLINK("#'Constants - Common'!A1", "Constants - Common") -> Constants - Common | D17: Power standalone machinery or heating | E17: Town gas in GJ | F17: 100 | G17: {=Common_InputFunctions.Utility_LookupValueInTable(Table_Input_Fuel[[#This Row],[Fuel type (select)]],Table_FuelTypes_Units[Fuel type], Table_FuelTypes_Units[Input Unit])} -> GJ | H17: =1 -> 1 | I17: =Table_Input_Fuel[[#This Row],[Amount purchased]]*Table_Input_Fuel[[#This Row],[Percent consumed]]*IF(Table_Input_Fuel[[#This Row],[Amount unit]]="L", 10^-3, 1) -> 100 | J17: {=Common_InputFunctions.Utility_LookupValueInTable(Table_Input_Fuel[[#This Row],[Fuel type (select)]],Table_FuelTypes_Units[Fuel type], Table_FuelTypes_Units[Unit])} -> GJ
D18: Power standalone machinery or heating | E18: Petrol | F18: 10000 | G18: {=Common_InputFunctions.Utility_LookupValueInTable(Table_Input_Fuel[[#This Row],[Fuel type (select)]],Table_FuelTypes_Units[Fuel type], Table_FuelTypes_Units[Input Unit])} -> L | H18: =1 -> 1 | I18: =Table_Input_Fuel[[#This Row],[Amount purchased]]*Table_Input_Fuel[[#This Row],[Percent consumed]]*IF(Table_Input_Fuel[[#This Row],[Amount unit]]="L", 10^-3, 1) -> 10 | J18: {=Common_InputFunctions.Utility_LookupValueInTable(Table_Input_Fuel[[#This Row],[Fuel type (select)]],Table_FuelTypes_Units[Fuel type], Table_FuelTypes_Units[Unit])} -> kL
D19: Cars and light commercial vehicles | E19: Diesel | F19: 10000 | G19: {=Common_InputFunctions.Utility_LookupValueInTable(Table_Input_Fuel[[#This Row],[Fuel type (select)]],Table_FuelTypes_Units[Fuel type], Table_FuelTypes_Units[Input Unit])} -> L | H19: =1 -> 1 | I19: =Table_Input_Fuel[[#This Row],[Amount purchased]]*Table_Input_Fuel[[#This Row],[Percent consumed]]*IF(Table_Input_Fuel[[#This Row],[Amount unit]]="L", 10^-3, 1) -> 10 | J19: {=Common_InputFunctions.Utility_LookupValueInTable(Table_Input_Fuel[[#This Row],[Fuel type (select)]],Table_FuelTypes_Units[Fuel type], Table_FuelTypes_Units[Unit])} -> kL
D20: Off-road Agriculture and forestry equipment | E20: Diesel | F20: 10000 | G20: {=Common_InputFunctions.Utility_LookupValueInTable(Table_Input_Fuel[[#This Row],[Fuel type (select)]],Table_FuelTypes_Units[Fuel type], Table_FuelTypes_Units[Input Unit])} -> L | H20: =1 -> 1 | I20: =Table_Input_Fuel[[#This Row],[Amount purchased]]*Table_Input_Fuel[[#This Row],[Percent consumed]]*IF(Table_Input_Fuel[[#This Row],[Amount unit]]="L", 10^-3, 1) -> 10 | J20: {=Common_InputFunctions.Utility_LookupValueInTable(Table_Input_Fuel[[#This Row],[Fuel type (select)]],Table_FuelTypes_Units[Fuel type], Table_FuelTypes_Units[Unit])} -> kL
D21: Vessels | E21: Fuel oil | F21: 10000 | G21: {=Common_InputFunctions.Utility_LookupValueInTable(Table_Input_Fuel[[#This Row],[Fuel type (select)]],Table_FuelTypes_Units[Fuel type], Table_FuelTypes_Units[Input Unit])} -> L | H21: =1 -> 1 | I21: =Table_Input_Fuel[[#This Row],[Amount purchased]]*Table_Input_Fuel[[#This Row],[Percent consumed]]*IF(Table_Input_Fuel[[#This Row],[Amount unit]]="L", 10^-3, 1) -> 10 | J21: {=Common_InputFunctions.Utility_LookupValueInTable(Table_Input_Fuel[[#This Row],[Fuel type (select)]],Table_FuelTypes_Units[Fuel type], Table_FuelTypes_Units[Unit])} -> kL

Sheet Input - Fertiliser
A1: #VALUE! | C1: Input - Fertiliser
A3: =HYPERLINK("#'Home'!A1", "Home") -> Home
A4: =HYPERLINK("#'Overview'!A1", "Overview") -> Overview
A5: =HYPERLINK("#'Results'!A1", "Results") -> Results
D6: Production system | E6: Crop | F6: ← Please select
A7: INPUTS | D7: Crop type | E7: Grains | F7: ← Please select
A8: =HYPERLINK("#'Input - Site'!A1", "Site") -> Site | D8: Irrigation method | E8: Sprinkler irrigation | F8: ← Please select
A9: =HYPERLINK("#'Input - Fertiliser'!A1", "Fertiliser") -> Fertiliser | D9: Area under cropping | E9: 100 | F9: hectares
A11: CALCULATIONS | D11: Inorganic fertiliser applied
A12: =HYPERLINK("#'5.1.1.1-2 Inorganic Fert N2O'!A1", "5.1.1.1-2 Inorganic Fert N2O") -> 5.1.1.1-2 Inorganic Fert N2O
A13: =HYPERLINK("#'5.1.1.3-4 Inorganic fert CO2'!A1", "5.1.1.3-4 Inorganic fert CO2") -> 5.1.1.3-4 Inorganic fert CO2 | D13: 💡You can add more rows to tables by right-clicking on the table and selecting "Insert > Table rows above/below".
A14: =HYPERLINK("#'5.2.1.1-2 Organic Fert N2O'!A1", "5.2.1.1-2 Organic Fert N2O") -> 5.2.1.1-2 Organic Fert N2O | D14: 💡The application area is the same as the area under pasture / cropping by default. You can edit it if the application area is different.
A15: =HYPERLINK("#'5.3.1.1-2 Lime CO2'!A1", "5.3.1.1-2 Lime CO2") -> 5.3.1.1-2 Lime CO2
A16: =HYPERLINK("#'5.4.1.1-4 Atmos deposition'!A1", "5.4.1.1-4 Atmos deposition") -> 5.4.1.1-4 Atmos deposition | D16: Branded fertiliser products
A17: =HYPERLINK("#'5.5.1.1-2 Leaching and runoff'!A1", "5.5.1.1-2 Leaching and runoff") -> 5.5.1.1-2 Leaching and runoff | D17: Product (select) | E17: Amount applied per hectare | F17: Application unit | G17: Density | H17: Application area (ha) | I17: Total applied (kg) | J17: Ingredient 1 | K17: Ingredient 1 percent | L17: Ingredient 2 | M17: Ingredient 2 percent | N17: Ingredient 3 | O17: Ingredient 3 percent | P17: Ingredient 4 | Q17: Ingredient 4 percent | R17: Ingredient 5 | S17: Ingredient 5 percent | T17: Ingredient 6 | U17: Ingredient 6 percent | V17: N application rate (kg/ha) | W17: Urea source | X17: Ammonia source
D18: Aqua Finish | E18: 100 | F18: =_xlfn.XLOOKUP(Table_Input_InorganicFertiliser_Brands[[#This Row],[Product (select)]],FertiliserProducts[Product name],FertiliserProducts[Unit]) -> L | G18: =_xlfn.XLOOKUP(Table_Input_InorganicFertiliser_Brands[[#This Row],[Product (select)]],FertiliserProducts[Product name],FertiliserProducts[Density / gravity]) -> 1.26 | H18: =$E$9 -> 100 | I18: =(Table_Input_InorganicFertiliser_Brands[[#This Row],[Amount applied per hectare]]*Table_Input_InorganicFertiliser_Brands[[#This Row],[Density]])*Table_Input_InorganicFertiliser_Brands[[#This Row],[Application area (ha)]] -> 12600 | J18: {=Fertiliser_InputFunctions.Fertiliser_FertiliserProductLookup(Table_Input_InorganicFertiliser_Brands[[#This Row],[Product (select)]], Table_Input_InorganicFertiliser_Brands[[#Headers],[Ingredient 1]], FertiliserProducts[#Data], FertiliserProducts[Product name], FertiliserProducts[#Headers])} -> Potassium - Generic | K18: {=Fertiliser_InputFunctions.Fertiliser_FertiliserProductLookup(Table_Input_InorganicFertiliser_Brands[[#This Row],[Product (select)]], Table_Input_InorganicFertiliser_Brands[[#Headers],[Ingredient 1 percent]], FertiliserProducts[#Data], FertiliserProducts[Product name], FertiliserProducts[#Headers])} -> 0.225 | L18: {=Fertiliser_InputFunctions.Fertiliser_FertiliserProductLookup(Table_Input_InorganicFertiliser_Brands[[#This Row],[Product (select)]], Table_Input_InorganicFertiliser_Brands[[#Headers],[Ingredient 2]], FertiliserProducts[#Data], FertiliserProducts[Product name], FertiliserProducts[#Headers])} -> Phosphorus - Generic | M18: {=Fertiliser_InputFunctions.Fertiliser_FertiliserProductLookup(Table_Input_InorganicFertiliser_Brands[[#This Row],[Product (select)]], Table_Input_InorganicFertiliser_Brands[[#Headers],[Ingredient 2 percent]], FertiliserProducts[#Data], FertiliserProducts[Product name], FertiliserProducts[#Headers])} -> 0.04 | N18: {=Fertiliser_InputFunctions.Fertiliser_FertiliserProductLookup(Table_Input_InorganicFertiliser_Brands[[#This Row],[Product (select)]], Table_Input_InorganicFertiliser_Brands[[#Headers],[Ingredient 3]], FertiliserProducts[#Data], FertiliserProducts[Product name], FertiliserProducts[#Headers])} -> Nitrogen - Generic | O18: {=Fertiliser_InputFunctions.Fertiliser_FertiliserProductLookup(Table_Input_InorganicFertiliser_Brands[[#This Row],[Product (select)]], Table_Input_InorganicFertiliser_Brands[[#Headers],[Ingredient 3 percent]], FertiliserProducts[#Data], FertiliserProducts[Product name], FertiliserProducts[#Headers])} -> 0.026 | P18: {=Fertiliser_InputFunctions.Fertiliser_FertiliserProductLookup(Table_Input_InorganicFertiliser_Brands[[#This Row],[Product (select)]], Table_Input_InorganicFertiliser_Brands[[#Headers],[Ingredient 4]], FertiliserProducts[#Data], FertiliserProducts[Product name], FertiliserProducts[#Headers])} | Q18: {=Fertiliser_InputFunctions.Fertiliser_FertiliserProductLookup(Table_Input_InorganicFertiliser_Brands[[#This Row],[Product (select)]], Table_Input_InorganicFertiliser_Brands[[#Headers],[Ingredient 4 percent]], FertiliserProducts[#Data], FertiliserProducts[Product name], FertiliserProducts[#Headers])} | R18: {=Fertiliser_InputFunctions.Fertiliser_FertiliserProductLookup(Table_Input_InorganicFertiliser_Brands[[#This Row],[Product (select)]], Table_Input_InorganicFertiliser_Brands[[#Headers],[Ingredient 5]], FertiliserProducts[#Data], FertiliserProducts[Product name], FertiliserProducts[#Headers])} | S18: {=Fertiliser_InputFunctions.Fertiliser_FertiliserProductLookup(Table_Input_InorganicFertiliser_Brands[[#This Row],[Product (select)]], Table_Input_InorganicFertiliser_Brands[[#Headers],[Ingredient 5 percent]], FertiliserProducts[#Data], FertiliserProducts[Product name], FertiliserProducts[#Headers])} | T18: {=Fertiliser_InputFunctions.Fertiliser_FertiliserProductLookup(Table_Input_InorganicFertiliser_Brands[[#This Row],[Product (select)]], Table_Input_InorganicFertiliser_Brands[[#Headers],[Ingredient 6]], FertiliserProducts[#Data], FertiliserProducts[Product name], FertiliserProducts[#Headers])} | U18: {=Fertiliser_InputFunctions.Fertiliser_FertiliserProductLookup(Table_Input_InorganicFertiliser_Brands[[#This Row],[Product (select)]], Table_Input_InorganicFertiliser_Brands[[#Headers],[Ingredient 6 percent]], FertiliserProducts[#Data], FertiliserProducts[Product name], FertiliserProducts[#Headers])} | V18: =(Table_Input_InorganicFertiliser_Brands[[#This Row],[Amount applied per hectare]]*Table_Input_InorganicFertiliser_Brands[[#This Row],[Density]])*(IFERROR((_xlfn.XLOOKUP(Table_Input_InorganicFertiliser_Brands[[#This Row],[Ingredient 1]], Table_Fertiliser_ChemicalCompounds[Fertiliser type f],Table_Fertiliser_ChemicalCompounds[FNinorganic f])*Table_Input_InorganicFertiliser_Brands[[#This Row],[Ingredient 1 percent]]), 0)+ IFERROR((_xlfn.XLOOKUP(Table_Input_InorganicFertiliser_Brands[[#This Row],[Ingredient 2]],Table_Fertiliser_ChemicalCompounds[Fertiliser type f],Table_Fertiliser_ChemicalCompounds[FNinorganic f])*Table_Input_InorganicFertiliser_Brands[[#This Row],[Ingredient 2 percent]]), 0)+ IFERROR((_xlfn.XLOOKUP(Table_Input_InorganicFertiliser_Brands[[#This Row],[Ingredient 3]],Table_Fertiliser_ChemicalCompounds[Fertiliser type f],Table_Fertiliser_ChemicalCompounds[FNinorganic f])*Table_Input_InorganicFertiliser_Brands[[#This Row],[Ingredient 3 percent]]), 0)+ IFERROR((_xlfn.XLOOKUP(Table_Input_InorganicFertiliser_Brands[[#This Row],[Ingredient 4]],Table_Fertiliser_ChemicalCompounds[Fertiliser type f],Table_Fertiliser_ChemicalCompounds[FNinorganic f])*Table_Input_InorganicFertiliser_Brands[[#This Row],[Ingredient 4 percent]]), 0)+ IFERROR((_xlfn.XLOOKUP(Table_Input_InorganicFertiliser_Brands[[#This Row],[Ingredient 5]],Table_Fertiliser_ChemicalCompounds[Fertiliser type f],Table_Fertiliser_ChemicalCompounds[FNinorganic f])*Table_Input_InorganicFertiliser_Brands[[#This Row],[Ingredient 5 percent]]), 0)+ IFERROR((_xlfn.XLOOKUP(Table_Input_InorganicFertiliser_Brands[[#This Row],[Ingredient 6]],Table_Fertiliser_ChemicalCompounds[Fertiliser type f],Table_Fertiliser_ChemicalCompounds[FNinorganic f])*Table_Input_InorganicFertiliser_Brands[[#This Row],[Ingredient 6 percent]]), 0)) -> 3.276 | W18: =_xlfn.XLOOKUP(Table_Input_InorganicFertiliser_Brands[[#This Row],[Product (select)]],FertiliserProducts[Product name],FertiliserProducts[Urea source]) | X18: =_xlfn.XLOOKUP(Table_Input_InorganicFertiliser_Brands[[#This Row],[Product (select)]],FertiliserProducts[Product name],FertiliserProducts[Ammonia source])
A19: APPENDICES | D19: CalPhos | E19: 100 | F19: =_xlfn.XLOOKUP(Table_Input_InorganicFertiliser_Brands[[#This Row],[Product (select)]],FertiliserProducts[Product name],FertiliserProducts[Unit]) -> L | G19: =_xlfn.XLOOKUP(Table_Input_InorganicFertiliser_Brands[[#This Row],[Product (select)]],FertiliserProducts[Product name],FertiliserProducts[Density / gravity]) -> 1.285 | H19: =$E$9 -> 100 | I19: =(Table_Input_InorganicFertiliser_Brands[[#This Row],[Amount applied per hectare]]*Table_Input_InorganicFertiliser_Brands[[#This Row],[Density]])*Table_Input_InorganicFertiliser_Brands[[#This Row],[Application area (ha)]] -> 12850 | J19: {=Fertiliser_InputFunctions.Fertiliser_FertiliserProductLookup(Table_Input_InorganicFertiliser_Brands[[#This Row],[Product (select)]], Table_Input_InorganicFertiliser_Brands[[#Headers],[Ingredient 1]], FertiliserProducts[#Data], FertiliserProducts[Product name], FertiliserProducts[#Headers])} -> Phosphorus - Generic | K19: {=Fertiliser_InputFunctions.Fertiliser_FertiliserProductLookup(Table_Input_InorganicFertiliser_Brands[[#This Row],[Product (select)]], Table_Input_InorganicFertiliser_Brands[[#Headers],[Ingredient 1 percent]], FertiliserProducts[#Data], FertiliserProducts[Product name], FertiliserProducts[#Headers])} -> 0.135 | L19: {=Fertiliser_InputFunctions.Fertiliser_FertiliserProductLookup(Table_Input_InorganicFertiliser_Brands[[#This Row],[Product (select)]], Table_Input_InorganicFertiliser_Brands[[#Headers],[Ingredient 2]], FertiliserProducts[#Data], FertiliserProducts[Product name], FertiliserProducts[#Headers])} -> Calcium - Generic | M19: {=Fertiliser_InputFunctions.Fertiliser_FertiliserProductLookup(Table_Input_InorganicFertiliser_Brands[[#This Row],[Product (select)]], Table_Input_InorganicFertiliser_Brands[[#Headers],[Ingredient 2 percent]], FertiliserProducts[#Data], FertiliserProducts[Product name], FertiliserProducts[#Headers])} -> 0.04 | N19: {=Fertiliser_InputFunctions.Fertiliser_FertiliserProductLookup(Table_Input_InorganicFertiliser_Brands[[#This Row],[Product (select)]], Table_Input_InorganicFertiliser_Brands[[#Headers],[Ingredient 3]], FertiliserProducts[#Data], FertiliserProducts[Product name], FertiliserProducts[#Headers])} | O19: {=Fertiliser_InputFunctions.Fertiliser_FertiliserProductLookup(Table_Input_InorganicFertiliser_Brands[[#This Row],[Product (select)]], Table_Input_InorganicFertiliser_Brands[[#Headers],[Ingredient 3 percent]], FertiliserProducts[#Data], FertiliserProducts[Product name], FertiliserProducts[#Headers])} | P19: {=Fertiliser_InputFunctions.Fertiliser_FertiliserProductLookup(Table_Input_InorganicFertiliser_Brands[[#This Row],[Product (select)]], Table_Input_InorganicFertiliser_Brands[[#Headers],[Ingredient 4]], FertiliserProducts[#Data], FertiliserProducts[Product name], FertiliserProducts[#Headers])} | Q19: {=Fertiliser_InputFunctions.Fertiliser_FertiliserProductLookup(Table_Input_InorganicFertiliser_Brands[[#This Row],[Product (select)]], Table_Input_InorganicFertiliser_Brands[[#Headers],[Ingredient 4 percent]], FertiliserProducts[#Data], FertiliserProducts[Product name], FertiliserProducts[#Headers])} | R19: {=Fertiliser_InputFunctions.Fertiliser_FertiliserProductLookup(Table_Input_InorganicFertiliser_Brands[[#This Row],[Product (select)]], Table_Input_InorganicFertiliser_Brands[[#Headers],[Ingredient 5]], FertiliserProducts[#Data], FertiliserProducts[Product name], FertiliserProducts[#Headers])} | S19: {=Fertiliser_InputFunctions.Fertiliser_FertiliserProductLookup(Table_Input_InorganicFertiliser_Brands[[#This Row],[Product (select)]], Table_Input_InorganicFertiliser_Brands[[#Headers],[Ingredient 5 percent]], FertiliserProducts[#Data], FertiliserProducts[Product name], FertiliserProducts[#Headers])} | T19: {=Fertiliser_InputFunctions.Fertiliser_FertiliserProductLookup(Table_Input_InorganicFertiliser_Brands[[#This Row],[Product (select)]], Table_Input_InorganicFertiliser_Brands[[#Headers],[Ingredient 6]], FertiliserProducts[#Data], FertiliserProducts[Product name], FertiliserProducts[#Headers])} | U19: {=Fertiliser_InputFunctions.Fertiliser_FertiliserProductLookup(Table_Input_InorganicFertiliser_Brands[[#This Row],[Product (select)]], Table_Input_InorganicFertiliser_Brands[[#Headers],[Ingredient 6 percent]], FertiliserProducts[#Data], FertiliserProducts[Product name], FertiliserProducts[#Headers])} | V19: =(Table_Input_InorganicFertiliser_Brands[[#This Row],[Amount applied per hectare]]*Table_Input_InorganicFertiliser_Brands[[#This Row],[Density]])*(IFERROR((_xlfn.XLOOKUP(Table_Input_InorganicFertiliser_Brands[[#This Row],[Ingredient 1]], Table_Fertiliser_ChemicalCompounds[Fertiliser type f],Table_Fertiliser_ChemicalCompounds[FNinorganic f])*Table_Input_InorganicFertiliser_Brands[[#This Row],[Ingredient 1 percent]]), 0)+ IFERROR((_xlfn.XLOOKUP(Table_Input_InorganicFertiliser_Brands[[#This Row],[Ingredient 2]],Table_Fertiliser_ChemicalCompounds[Fertiliser type f],Table_Fertiliser_ChemicalCompounds[FNinorganic f])*Table_Input_InorganicFertiliser_Brands[[#This Row],[Ingredient 2 percent]]), 0)+ IFERROR((_xlfn.XLOOKUP(Table_Input_InorganicFertiliser_Brands[[#This Row],[Ingredient 3]],Table_Fertiliser_ChemicalCompounds[Fertiliser type f],Table_Fertiliser_ChemicalCompounds[FNinorganic f])*Table_Input_InorganicFertiliser_Brands[[#This Row],[Ingredient 3 percent]]), 0)+ IFERROR((_xlfn.XLOOKUP(Table_Input_InorganicFertiliser_Brands[[#This Row],[Ingredient 4]],Table_Fertiliser_ChemicalCompounds[Fertiliser type f],Table_Fertiliser_ChemicalCompounds[FNinorganic f])*Table_Input_InorganicFertiliser_Brands[[#This Row],[Ingredient 4 percent]]), 0)+ IFERROR((_xlfn.XLOOKUP(Table_Input_InorganicFertiliser_Brands[[#This Row],[Ingredient 5]],Table_Fertiliser_ChemicalCompounds[Fertiliser type f],Table_Fertiliser_ChemicalCompounds[FNinorganic f])*Table_Input_InorganicFertiliser_Brands[[#This Row],[Ingredient 5 percent]]), 0)+ IFERROR((_xlfn.XLOOKUP(Table_Input_InorganicFertiliser_Brands[[#This Row],[Ingredient 6]],Table_Fertiliser_ChemicalCompounds[Fertiliser type f],Table_Fertiliser_ChemicalCompounds[FNinorganic f])*Table_Input_InorganicFertiliser_Brands[[#This Row],[Ingredient 6 percent]]), 0)) -> 0 | W19: =_xlfn.XLOOKUP(Table_Input_InorganicFertiliser_Brands[[#This Row],[Product (select)]],FertiliserProducts[Product name],FertiliserProducts[Urea source]) | X19: =_xlfn.XLOOKUP(Table_Input_InorganicFertiliser_Brands[[#This Row],[Product (select)]],FertiliserProducts[Product name],FertiliserProducts[Ammonia source])
A20: =HYPERLINK("#'Constants - Fertiliser'!A1", "Constants - Fertiliser") -> Constants - Fertiliser | D20: CalPhos | E20: 100 | F20: =_xlfn.XLOOKUP(Table_Input_InorganicFertiliser_Brands[[#This Row],[Product (select)]],FertiliserProducts[Product name],FertiliserProducts[Unit]) -> L | G20: =_xlfn.XLOOKUP(Table_Input_InorganicFertiliser_Brands[[#This Row],[Product (select)]],FertiliserProducts[Product name],FertiliserProducts[Density / gravity]) -> 1.285 | H20: =$E$9 -> 100 | I20: =(Table_Input_InorganicFertiliser_Brands[[#This Row],[Amount applied per hectare]]*Table_Input_InorganicFertiliser_Brands[[#This Row],[Density]])*Table_Input_InorganicFertiliser_Brands[[#This Row],[Application area (ha)]] -> 12850 | J20: {=Fertiliser_InputFunctions.Fertiliser_FertiliserProductLookup(Table_Input_InorganicFertiliser_Brands[[#This Row],[Product (select)]], Table_Input_InorganicFertiliser_Brands[[#Headers],[Ingredient 1]], FertiliserProducts[#Data], FertiliserProducts[Product name], FertiliserProducts[#Headers])} -> Phosphorus - Generic | K20: {=Fertiliser_InputFunctions.Fertiliser_FertiliserProductLookup(Table_Input_InorganicFertiliser_Brands[[#This Row],[Product (select)]], Table_Input_InorganicFertiliser_Brands[[#Headers],[Ingredient 1 percent]], FertiliserProducts[#Data], FertiliserProducts[Product name], FertiliserProducts[#Headers])} -> 0.135 | L20: {=Fertiliser_InputFunctions.Fertiliser_FertiliserProductLookup(Table_Input_InorganicFertiliser_Brands[[#This Row],[Product (select)]], Table_Input_InorganicFertiliser_Brands[[#Headers],[Ingredient 2]], FertiliserProducts[#Data], FertiliserProducts[Product name], FertiliserProducts[#Headers])} -> Calcium - Generic | M20: {=Fertiliser_InputFunctions.Fertiliser_FertiliserProductLookup(Table_Input_InorganicFertiliser_Brands[[#This Row],[Product (select)]], Table_Input_InorganicFertiliser_Brands[[#Headers],[Ingredient 2 percent]], FertiliserProducts[#Data], FertiliserProducts[Product name], FertiliserProducts[#Headers])} -> 0.04 | N20: {=Fertiliser_InputFunctions.Fertiliser_FertiliserProductLookup(Table_Input_InorganicFertiliser_Brands[[#This Row],[Product (select)]], Table_Input_InorganicFertiliser_Brands[[#Headers],[Ingredient 3]], FertiliserProducts[#Data], FertiliserProducts[Product name], FertiliserProducts[#Headers])} | O20: {=Fertiliser_InputFunctions.Fertiliser_FertiliserProductLookup(Table_Input_InorganicFertiliser_Brands[[#This Row],[Product (select)]], Table_Input_InorganicFertiliser_Brands[[#Headers],[Ingredient 3 percent]], FertiliserProducts[#Data], FertiliserProducts[Product name], FertiliserProducts[#Headers])} | P20: {=Fertiliser_InputFunctions.Fertiliser_FertiliserProductLookup(Table_Input_InorganicFertiliser_Brands[[#This Row],[Product (select)]], Table_Input_InorganicFertiliser_Brands[[#Headers],[Ingredient 4]], FertiliserProducts[#Data], FertiliserProducts[Product name], FertiliserProducts[#Headers])} | Q20: {=Fertiliser_InputFunctions.Fertiliser_FertiliserProductLookup(Table_Input_InorganicFertiliser_Brands[[#This Row],[Product (select)]], Table_Input_InorganicFertiliser_Brands[[#Headers],[Ingredient 4 percent]], FertiliserProducts[#Data], FertiliserProducts[Product name], FertiliserProducts[#Headers])} | R20: {=Fertiliser_InputFunctions.Fertiliser_FertiliserProductLookup(Table_Input_InorganicFertiliser_Brands[[#This Row],[Product (select)]], Table_Input_InorganicFertiliser_Brands[[#Headers],[Ingredient 5]], FertiliserProducts[#Data], FertiliserProducts[Product name], FertiliserProducts[#Headers])} | S20: {=Fertiliser_InputFunctions.Fertiliser_FertiliserProductLookup(Table_Input_InorganicFertiliser_Brands[[#This Row],[Product (select)]], Table_Input_InorganicFertiliser_Brands[[#Headers],[Ingredient 5 percent]], FertiliserProducts[#Data], FertiliserProducts[Product name], FertiliserProducts[#Headers])} | T20: {=Fertiliser_InputFunctions.Fertiliser_FertiliserProductLookup(Table_Input_InorganicFertiliser_Brands[[#This Row],[Product (select)]], Table_Input_InorganicFertiliser_Brands[[#Headers],[Ingredient 6]], FertiliserProducts[#Data], FertiliserProducts[Product name], FertiliserProducts[#Headers])} | U20: {=Fertiliser_InputFunctions.Fertiliser_FertiliserProductLookup(Table_Input_InorganicFertiliser_Brands[[#This Row],[Product (select)]], Table_Input_InorganicFertiliser_Brands[[#Headers],[Ingredient 6 percent]], FertiliserProducts[#Data], FertiliserProducts[Product name], FertiliserProducts[#Headers])} | V20: =(Table_Input_InorganicFertiliser_Brands[[#This Row],[Amount applied per hectare]]*Table_Input_InorganicFertiliser_Brands[[#This Row],[Density]])*(IFERROR((_xlfn.XLOOKUP(Table_Input_InorganicFertiliser_Brands[[#This Row],[Ingredient 1]], Table_Fertiliser_ChemicalCompounds[Fertiliser type f],Table_Fertiliser_ChemicalCompounds[FNinorganic f])*Table_Input_InorganicFertiliser_Brands[[#This Row],[Ingredient 1 percent]]), 0)+ IFERROR((_xlfn.XLOOKUP(Table_Input_InorganicFertiliser_Brands[[#This Row],[Ingredient 2]],Table_Fertiliser_ChemicalCompounds[Fertiliser type f],Table_Fertiliser_ChemicalCompounds[FNinorganic f])*Table_Input_InorganicFertiliser_Brands[[#This Row],[Ingredient 2 percent]]), 0)+ IFERROR((_xlfn.XLOOKUP(Table_Input_InorganicFertiliser_Brands[[#This Row],[Ingredient 3]],Table_Fertiliser_ChemicalCompounds[Fertiliser type f],Table_Fertiliser_ChemicalCompounds[FNinorganic f])*Table_Input_InorganicFertiliser_Brands[[#This Row],[Ingredient 3 percent]]), 0)+ IFERROR((_xlfn.XLOOKUP(Table_Input_InorganicFertiliser_Brands[[#This Row],[Ingredient 4]],Table_Fertiliser_ChemicalCompounds[Fertiliser type f],Table_Fertiliser_ChemicalCompounds[FNinorganic f])*Table_Input_InorganicFertiliser_Brands[[#This Row],[Ingredient 4 percent]]), 0)+ IFERROR((_xlfn.XLOOKUP(Table_Input_InorganicFertiliser_Brands[[#This Row],[Ingredient 5]],Table_Fertiliser_ChemicalCompounds[Fertiliser type f],Table_Fertiliser_ChemicalCompounds[FNinorganic f])*Table_Input_InorganicFertiliser_Brands[[#This Row],[Ingredient 5 percent]]), 0)+ IFERROR((_xlfn.XLOOKUP(Table_Input_InorganicFertiliser_Brands[[#This Row],[Ingredient 6]],Table_Fertiliser_ChemicalCompounds[Fertiliser type f],Table_Fertiliser_ChemicalCompounds[FNinorganic f])*Table_Input_InorganicFertiliser_Brands[[#This Row],[Ingredient 6 percent]]), 0)) -> 0 | W20: =_xlfn.XLOOKUP(Table_Input_InorganicFertiliser_Brands[[#This Row],[Product (select)]],FertiliserProducts[Product name],FertiliserProducts[Urea source]) | X20: =_xlfn.XLOOKUP(Table_Input_InorganicFertiliser_Brands[[#This Row],[Product (select)]],FertiliserProducts[Product name],FertiliserProducts[Ammonia source])
A21: =HYPERLINK("#'Constants - Common'!A1", "Constants - Common") -> Constants - Common | D21: Aqua Grow | E21: 100 | F21: =_xlfn.XLOOKUP(Table_Input_InorganicFertiliser_Brands[[#This Row],[Product (select)]],FertiliserProducts[Product name],FertiliserProducts[Unit]) -> L | G21: =_xlfn.XLOOKUP(Table_Input_InorganicFertiliser_Brands[[#This Row],[Product (select)]],FertiliserProducts[Product name],FertiliserProducts[Density / gravity]) -> 1.26 | H21: =$E$9 -> 100 | I21: =(Table_Input_InorganicFertiliser_Brands[[#This Row],[Amount applied per hectare]]*Table_Input_InorganicFertiliser_Brands[[#This Row],[Density]])*Table_Input_InorganicFertiliser_Brands[[#This Row],[Application area (ha)]] -> 12600 | J21: {=Fertiliser_InputFunctions.Fertiliser_FertiliserProductLookup(Table_Input_InorganicFertiliser_Brands[[#This Row],[Product (select)]], Table_Input_InorganicFertiliser_Brands[[#Headers],[Ingredient 1]], FertiliserProducts[#Data], FertiliserProducts[Product name], FertiliserProducts[#Headers])} -> Potassium - Generic | K21: {=Fertiliser_InputFunctions.Fertiliser_FertiliserProductLookup(Table_Input_InorganicFertiliser_Brands[[#This Row],[Product (select)]], Table_Input_InorganicFertiliser_Brands[[#Headers],[Ingredient 1 percent]], FertiliserProducts[#Data], FertiliserProducts[Product name], FertiliserProducts[#Headers])} -> 0.105 | L21: {=Fertiliser_InputFunctions.Fertiliser_FertiliserProductLookup(Table_Input_InorganicFertiliser_Brands[[#This Row],[Product (select)]], Table_Input_InorganicFertiliser_Brands[[#Headers],[Ingredient 2]], FertiliserProducts[#Data], FertiliserProducts[Product name], FertiliserProducts[#Headers])} -> Nitrogen - Generic | M21: {=Fertiliser_InputFunctions.Fertiliser_FertiliserProductLookup(Table_Input_InorganicFertiliser_Brands[[#This Row],[Product (select)]], Table_Input_InorganicFertiliser_Brands[[#Headers],[Ingredient 2 percent]], FertiliserProducts[#Data], FertiliserProducts[Product name], FertiliserProducts[#Headers])} -> 0.096 | N21: {=Fertiliser_InputFunctions.Fertiliser_FertiliserProductLookup(Table_Input_InorganicFertiliser_Brands[[#This Row],[Product (select)]], Table_Input_InorganicFertiliser_Brands[[#Headers],[Ingredient 3]], FertiliserProducts[#Data], FertiliserProducts[Product name], FertiliserProducts[#Headers])} -> Phosphorus - Generic | O21: {=Fertiliser_InputFunctions.Fertiliser_FertiliserProductLookup(Table_Input_InorganicFertiliser_Brands[[#This Row],[Product (select)]], Table_Input_InorganicFertiliser_Brands[[#Headers],[Ingredient 3 percent]], FertiliserProducts[#Data], FertiliserProducts[Product name], FertiliserProducts[#Headers])} -> 0.05 | P21: {=Fertiliser_InputFunctions.Fertiliser_FertiliserProductLookup(Table_Input_InorganicFertiliser_Brands[[#This Row],[Product (select)]], Table_Input_InorganicFertiliser_Brands[[#Headers],[Ingredient 4]], FertiliserProducts[#Data], FertiliserProducts[Product name], FertiliserProducts[#Headers])} | Q21: {=Fertiliser_InputFunctions.Fertiliser_FertiliserProductLookup(Table_Input_InorganicFertiliser_Brands[[#This Row],[Product (select)]], Table_Input_InorganicFertiliser_Brands[[#Headers],[Ingredient 4 percent]], FertiliserProducts[#Data], FertiliserProducts[Product name], FertiliserProducts[#Headers])} | R21: {=Fertiliser_InputFunctions.Fertiliser_FertiliserProductLookup(Table_Input_InorganicFertiliser_Brands[[#This Row],[Product (select)]], Table_Input_InorganicFertiliser_Brands[[#Headers],[Ingredient 5]], FertiliserProducts[#Data], FertiliserProducts[Product name], FertiliserProducts[#Headers])} | S21: {=Fertiliser_InputFunctions.Fertiliser_FertiliserProductLookup(Table_Input_InorganicFertiliser_Brands[[#This Row],[Product (select)]], Table_Input_InorganicFertiliser_Brands[[#Headers],[Ingredient 5 percent]], FertiliserProducts[#Data], FertiliserProducts[Product name], FertiliserProducts[#Headers])} | T21: {=Fertiliser_InputFunctions.Fertiliser_FertiliserProductLookup(Table_Input_InorganicFertiliser_Brands[[#This Row],[Product (select)]], Table_Input_InorganicFertiliser_Brands[[#Headers],[Ingredient 6]], FertiliserProducts[#Data], FertiliserProducts[Product name], FertiliserProducts[#Headers])} | U21: {=Fertiliser_InputFunctions.Fertiliser_FertiliserProductLookup(Table_Input_InorganicFertiliser_Brands[[#This Row],[Product (select)]], Table_Input_InorganicFertiliser_Brands[[#Headers],[Ingredient 6 percent]], FertiliserProducts[#Data], FertiliserProducts[Product name], FertiliserProducts[#Headers])} | V21: =(Table_Input_InorganicFertiliser_Brands[[#This Row],[Amount applied per hectare]]*Table_Input_InorganicFertiliser_Brands[[#This Row],[Density]])*(IFERROR((_xlfn.XLOOKUP(Table_Input_InorganicFertiliser_Brands[[#This Row],[Ingredient 1]], Table_Fertiliser_ChemicalCompounds[Fertiliser type f],Table_Fertiliser_ChemicalCompounds[FNinorganic f])*Table_Input_InorganicFertiliser_Brands[[#This Row],[Ingredient 1 percent]]), 0)+ IFERROR((_xlfn.XLOOKUP(Table_Input_InorganicFertiliser_Brands[[#This Row],[Ingredient 2]],Table_Fertiliser_ChemicalCompounds[Fertiliser type f],Table_Fertiliser_ChemicalCompounds[FNinorganic f])*Table_Input_InorganicFertiliser_Brands[[#This Row],[Ingredient 2 percent]]), 0)+ IFERROR((_xlfn.XLOOKUP(Table_Input_InorganicFertiliser_Brands[[#This Row],[Ingredient 3]],Table_Fertiliser_ChemicalCompounds[Fertiliser type f],Table_Fertiliser_ChemicalCompounds[FNinorganic f])*Table_Input_InorganicFertiliser_Brands[[#This Row],[Ingredient 3 percent]]), 0)+ IFERROR((_xlfn.XLOOKUP(Table_Input_InorganicFertiliser_Brands[[#This Row],[Ingredient 4]],Table_Fertiliser_ChemicalCompounds[Fertiliser type f],Table_Fertiliser_ChemicalCompounds[FNinorganic f])*Table_Input_InorganicFertiliser_Brands[[#This Row],[Ingredient 4 percent]]), 0)+ IFERROR((_xlfn.XLOOKUP(Table_Input_InorganicFertiliser_Brands[[#This Row],[Ingredient 5]],Table_Fertiliser_ChemicalCompounds[Fertiliser type f],Table_Fertiliser_ChemicalCompounds[FNinorganic f])*Table_Input_InorganicFertiliser_Brands[[#This Row],[Ingredient 5 percent]]), 0)+ IFERROR((_xlfn.XLOOKUP(Table_Input_InorganicFertiliser_Brands[[#This Row],[Ingredient 6]],Table_Fertiliser_ChemicalCompounds[Fertiliser type f],Table_Fertiliser_ChemicalCompounds[FNinorganic f])*Table_Input_InorganicFertiliser_Brands[[#This Row],[Ingredient 6 percent]]), 0)) -> 12.096 | W21: =_xlfn.XLOOKUP(Table_Input_InorganicFertiliser_Brands[[#This Row],[Product (select)]],FertiliserProducts[Product name],FertiliserProducts[Urea source]) | X21: =_xlfn.XLOOKUP(Table_Input_InorganicFertiliser_Brands[[#This Row],[Product (select)]],FertiliserProducts[Product name],FertiliserProducts[Ammonia source])
