Workbook
Name Common_Equations.Common_ConvertCH4ToCO2e: _xlfn.LAMBDA(_xlpm.E_CH4,_xlpm.GWP_CH4, _xlpm.E_CH4 * _xlpm.GWP_CH4)
Name Common_Equations.Common_ConvertCH4ToCO2e_Arguments: _xlfn.LAMBDA(_xlfn.MAKEARRAY(2, 2, _xlfn.LAMBDA(_xlpm.r,_xlpm.c, INDEX({"ECH4","Methane emissions (t CH4)";"GWPCH4","Global warming potential for methane (t CO2-e / t CH4)"}, _xlpm.r, _xlpm.c))))
Name Common_Equations.Common_ConvertCH4ToCO2e_LatexEquation: _xlfn.LAMBDA("CO2_e = E_{CH4} \times GWP_{CH4}")
Name Common_Equations.Common_ConvertCH4ToCO2e_NIRReference: _xlfn.LAMBDA("")
Name Common_Equations.Common_ConvertCH4ToCO2e_Title: _xlfn.LAMBDA("Convert methane emissions to carbon dioxide equivalent emissions")
Name Common_Equations.Common_ConvertCH4ToCO2e_Unit: _xlfn.LAMBDA("t CO2e")
Name Common_Equations.Common_ConvertCH4ToCO2e_Variable: _xlfn.LAMBDA("ECH4 CO2e")
Name Common_Equations.Common_ConvertN2OToCO2e: _xlfn.LAMBDA(_xlpm.E_N2O,_xlpm.GWP_N2O, _xlpm.E_N2O * _xlpm.GWP_N2O)
Name Common_Equations.Common_ConvertN2OToCO2e_LatexEquation: _xlfn.LAMBDA("CO2_e = E_{N2O} \times GWP_{N2O}")
Name Common_Equations.Common_ConvertN2OToCO2e_NIRReference: _xlfn.LAMBDA("")
Name Common_Equations.Common_ConvertN2OToCO2e_Title: _xlfn.LAMBDA("Convert nitrous oxide emissions to carbon dioxide equivalent emissions")
Name Common_Equations.Common_ConvertN2OToCO2e_Unit: _xlfn.LAMBDA("t CO2e")
Name Common_Equations.Common_ConvertN2OToCO2e_Variable: _xlfn.LAMBDA("EN2O CO2e")
Name Common_InputFunctions.Utility_ConvertStateCommonNameToAbbreviation: _xlfn.LAMBDA(_xlpm.StateCommonName,_xlpm.StateCommonNameArray,_xlpm.StateAbbreviationArray, _xlfn.XLOOKUP(_xlpm.StateCommonName, _xlpm.StateCommonNameArray, _xlpm.StateAbbreviationArray, ""))
Name Common_InputFunctions.Utility_DisplayArguments_1_2: _xlfn.LAMBDA(_xlpm.ArgumentsArray, _xlfn.CHOOSECOLS(_xlpm.ArgumentsArray, 1, 2))
Name Common_InputFunctions.Utility_DisplayArguments_3_4: _xlfn.LAMBDA(_xlpm.ArgumentsArray, _xlfn.CHOOSECOLS(_xlpm.ArgumentsArray, 3, 4))
Name Common_InputFunctions.Utility_DisplayFunctionName: _xlfn.LAMBDA(_xlpm.Function, _xlfn.TEXTBEFORE(_xlfn.FORMULATEXT(_xlpm.Function), "("))
Name Common_InputFunctions.Utility_GetArrayTableColumnStartNumber: _xlfn.LAMBDA(_xlpm.TableHeaderCell, COLUMN(_xlpm.TableHeaderCell))
Name Common_InputFunctions.Utility_GetArrayTableRowStartNumber: _xlfn.LAMBDA(_xlpm.TableheaderCell,_xlpm.RowsBetweenHeaderandArray, ROW(_xlpm.TableheaderCell) + _xlpm.RowsBetweenHeaderandArray - 1)
Name Common_InputFunctions.Utility_LookupValueInTable: _xlfn.LAMBDA(_xlpm.LookupValue,_xlpm.LookupArray,_xlpm.ReturnArray, _xlfn.XLOOKUP(_xlpm.LookupValue, _xlpm.LookupArray, _xlpm.ReturnArray, ""))
Name Common_InputFunctions.Utility_ResultsItemFromEquationTitleAndSource: _xlfn.LAMBDA(_xlpm.TitleCell,_xlpm.SourceCell, SUBSTITUTE(LEFT(_xlpm.SourceCell, FIND(",", _xlpm.SourceCell) - 1), "VEERG 2026: ", "") & " " & _xlpm.TitleCell)
Name Common_InputFunctions.Utility_SourceHyperlink: _xlfn.LAMBDA(_xlpm.TargetCell, _xlfn.LET(_xlpm.sh, _xlfn.TEXTAFTER(CELL("filename", _xlpm.TargetCell), "]"), _xlpm.addr, CELL("address", _xlpm.TargetCell), "#'" & _xlpm.sh & "'!" & _xlpm.addr))
Name Common_InputFunctions.Utility_SourceHyperlinkDifferentSheet: _xlfn.LAMBDA(_xlpm.TargetCell, _xlfn.LET(_xlpm.sh, _xlfn.TEXTAFTER(CELL("filename", _xlpm.TargetCell), "]"), _xlpm.addr, CELL("address", _xlpm.TargetCell), "#" & _xlpm.addr))
Name Common_SourceData.Common_SourceData_AustralianStatesTerritories_Source: _xlfn.LAMBDA("")
Name Common_SourceData.Common_SourceData_AustralianStatesTerritories_Title: _xlfn.LAMBDA("Australian states and territories")
Name Common_SourceData.Common_SourceData_AustralianStatesTerritories_Unit: _xlfn.LAMBDA("")
Name Common_SourceData.Common_SourceData_AustralianStatesTerritories_Variable: _xlfn.LAMBDA("")
Name Common_SourceData.Common_SourceData_ClimateZones_Source: _xlfn.LAMBDA("VEERG 2026: Table 1.3: Climate and Rainfall zone classifications and definitions")
Name Common_SourceData.Common_SourceData_ClimateZones_Title: _xlfn.LAMBDA("VEERG Australian climate zones")
Name Common_SourceData.Common_SourceData_ClimateZones_Unit: _xlfn.LAMBDA("")
Name Common_SourceData.Common_SourceData_ClimateZones_Variable: _xlfn.LAMBDA("")
Name Common_SourceData.Common_SourceData_ConvertGasElementalToMolecular_Source: _xlfn.LAMBDA("XXXXXXX")
Name Common_SourceData.Common_SourceData_ConvertGasElementalToMolecular_Title: _xlfn.LAMBDA("Factor to convert elemental mass of gas to molecular mass")
Name Common_SourceData.Common_SourceData_ConvertGasElementalToMolecular_Unit: _xlfn.LAMBDA("factor")
Name Common_SourceData.Common_SourceData_ConvertGasElementalToMolecular_Variable: _xlfn.LAMBDA("Cg")
Name Common_SourceData.Common_SourceData_ConvertN2oElementalToMolecularCg_Data: _xlfn.LAMBDA(44 / 28)
Name Common_SourceData.Common_SourceData_ConvertN2oElementalToMolecularCg_Source: _xlfn.LAMBDA("National Inventory Report 2023 Volume 1")
Name Common_SourceData.Common_SourceData_ConvertN2oElementalToMolecularCg_Title: _xlfn.LAMBDA("Factor to convert elemental mass of N2O to molecular mass")
Name Common_SourceData.Common_SourceData_ConvertN2oElementalToMolecularCg_Unit: _xlfn.LAMBDA("factor")
Name Common_SourceData.Common_SourceData_ConvertN2oElementalToMolecularCg_Variable: _xlfn.LAMBDA("CgN2O")
Name Common_SourceData.Common_SourceData_DataScores_Scope3_Source: _xlfn.LAMBDA("VEERG 2026: XXXXXXXX")
Name Common_SourceData.Common_SourceData_DataScores_Scope3_Title: _xlfn.LAMBDA("Australian data scores for scope 3")
Name Common_SourceData.Common_SourceData_DataScores_Scope3_Unit: _xlfn.LAMBDA("")
Name Common_SourceData.Common_SourceData_DataScores_Scope3_Variable: _xlfn.LAMBDA("")
Name Common_SourceData.Common_SourceData_DataScores_Scope3_Variation: _xlfn.LAMBDA("")
Name Common_SourceData.Common_SourceData_DensityOfMethane_Data: _xlfn.LAMBDA(0.6784)
Name Common_SourceData.Common_SourceData_DensityOfMethane_Source: _xlfn.LAMBDA("National Inventory Report 2023 Volume 1: Equations 3.B.1a_2, 3.B.1c_2, 3.B.3_1, 3.B.4g_2")
Name Common_SourceData.Common_SourceData_DensityOfMethane_Title: _xlfn.LAMBDA("p = density of methane")
Name Common_SourceData.Common_SourceData_DensityOfMethane_Unit: _xlfn.LAMBDA("kg/m3")
Name Common_SourceData.Common_SourceData_EFleach_Data: _xlfn.LAMBDA(_xlfn.MAKEARRAY(1, 2, _xlfn.LAMBDA(_xlpm.r,_xlpm.c, INDEX({"EFleach",0.011}, _xlpm.r, _xlpm.c))))
Name Common_SourceData.Common_SourceData_EFleach_NIRReference: _xlfn.LAMBDA("National Inventory Report Volume 1: Equation 3.D.B_10")
Name Common_SourceData.Common_SourceData_EFleach_Source: _xlfn.LAMBDA("VEERG 2026:5.5.2.3 Constant Parameters")
Name Common_SourceData.Common_SourceData_EFleach_Title: _xlfn.LAMBDA("Emission factor for nitrogen leaching and runoff")
Name Common_SourceData.Common_SourceData_EFleach_Unit: _xlfn.LAMBDA("(kg N2O-N / kg N")
Name Common_SourceData.Common_SourceData_EFleach_Variation: _xlfn.LAMBDA((""))
Name Common_SourceData.Common_SourceData_EFN2O_NIRReference: _xlfn.LAMBDA("")
Name Common_SourceData.Common_SourceData_EFN2O_Source: _xlfn.LAMBDA("VEERG 2026: Table A.2.2.1")
Name Common_SourceData.Common_SourceData_EFN2O_Title: _xlfn.LAMBDA("Nitrous oxide emission factors for inorganic fertiliser application")
Name Common_SourceData.Common_SourceData_EFN2O_Unit: _xlfn.LAMBDA("(kg N2O-N / kg N")
Name Common_SourceData.Common_SourceData_EFOrganicFertiliserAndCropResidues_Data: _xlfn.LAMBDA(_xlfn.MAKEARRAY(3, 2, _xlfn.LAMBDA(_xlpm.r,_xlpm.c, INDEX({"Climate zone","EFNi & EFN2O";"Wet climate zone",0.006;"Dry climate zone",0.005}, _xlpm.r, _xlpm.c))))

Sheet Home
A1: Home

Sheet Overview
A1: #VALUE! | C1: 4.3: Manure Management: Dairy: Overview
A3: =HYPERLINK("#'Home'!A1", "Home") -> Home
A4: =HYPERLINK("#'Overview'!A1", "Overview") -> Overview
A5: =HYPERLINK("#'Results'!A1", "Results") -> Results | D5: 💡 Below is a diagram that maps the equations used to calculate emissions, how they interact with each other and how they align with dairy manure management processes.
D6: Click on a box to go to the corresponding calculation.
A7: INPUTS
A8: =HYPERLINK("#'Input - Site'!A1", "Site") -> Site
A9: =HYPERLINK("#'Input - Dairy'!A1", "Dairy") -> Dairy
A11: CALCULATIONS
A12: =HYPERLINK("#'4.3.1.1-2 Methane'!A1", "4.3.1.1-2 Methane") -> 4.3.1.1-2 Methane
A13: =HYPERLINK("#'4.3.1.3-4 Direct N20'!A1", "4.3.1.3-4 Direct N2O") -> 4.3.1.3-4 Direct N2O
A14: =HYPERLINK("#'4.3.1.5 Atmos Deposition'!A1", "4.3.1.5 Atmospheric deposition") -> 4.3.1.5 Atmospheric deposition
A15: =HYPERLINK("#'4.3.1.6-7 Leaching and runoff'!A1", "4.3.1.6-7 Leaching and runoff") -> 4.3.1.6-7 Leaching and runoff
A16: =HYPERLINK("#'4.3.1.8 Manure applied to soils'!A1", "4.3.1.8 Manure applied to soils") -> 4.3.1.8 Manure applied to soils
A17: =HYPERLINK("#'4.3.1.9 Soil direct N2O'!A1", "4.3.1.9 Soil direct N2O") -> 4.3.1.9 Soil direct N2O
A18: =HYPERLINK("#'4.3.1.10-11 Soil Atmos Dep'!A1", "4.3.1.10-11 Soil atm. deposition") -> 4.3.1.10-11 Soil atm. deposition
A19: =HYPERLINK("#'4.3.1.12-13 Soil leach runoff'!A1", "4.3.1.12-13 Soil leach & runoff") -> 4.3.1.12-13 Soil leach & runoff
A21: APPENDICES
A22: =HYPERLINK("#'Constants - Dairy'!A1", "Constants - Dairy") -> Constants - Dairy
A23: =HYPERLINK("#'Constants - Livestock'!A1", "Constants - Livestock") -> Constants - Livestock
A24: =HYPERLINK("#'Constants - Common'!A1", "Constants - Common") -> Constants - Common
A25: =HYPERLINK("#'Acknowledgements'!A1", "Acknowledgements") -> Acknowledgements

Sheet Results
A1: #VALUE! | C1: 4.3 Manure management: Dairy: Results
A3: =HYPERLINK("#'Home'!A1", "Home") -> Home
A4: =HYPERLINK("#'Overview'!A1", "Overview") -> Overview | D4: Emissions breakdown
A5: =HYPERLINK("#'Results'!A1", "Results") -> Results
D6: Scope 1 source | E6: GHG emissions method 1 | F6: GHG emissions method 2 | G6: GHG Unit | H6: CO2-e emissions method 1 | I6: CO2-e emissions method 2 | J6: CO2-e unit
A7: INPUTS | D7: 4.3.1.1-2 Manure methane | E7: =VEERG_4_3_1_1__1_TotalAnnualMethaneFromManureManagement_Result_Method1 -> 10.314346 | F7: =VEERG_4_3_1_1__1_TotalAnnualMethaneFromManureManagement_Result_Method2 -> 10.640707 | G7: ='4.3.1.1-2 Methane'!$F$300 -> t CH4 | H7: ='4.3.1.1-2 Methane'!$E$305 -> 288.80168 | I7: ='4.3.1.1-2 Methane'!$P$305 -> 297.93979 | J7: ='4.3.1.1-2 Methane'!$F$305 -> t CO2e
A8: =HYPERLINK("#'Input - Site'!A1", "Site") -> Site | D8: 4.3.1.3-4 Manure direct N2O | E8: =VEERG_4_3_1_3__1_TotalAnnualDirectNitrousOxideEmissionsFromMMS_Result_Method1 -> 0.063172161 | F8: =VEERG_4_3_1_3__1_TotalAnnualDirectNitrousOxideEmissionsFromMMS_Result_Method2 -> 0.063172161 | G8: ='4.3.1.3-4 Direct N20'!$F$287 -> t N2O | H8: ='4.3.1.3-4 Direct N20'!$E$292 -> 16.740623 | I8: ='4.3.1.3-4 Direct N20'!$O$292 -> 16.740623 | J8: ='4.3.1.3-4 Direct N20'!$F$292 -> t CO2e
A9: =HYPERLINK("#'Input - Dairy'!A1", "Dairy") -> Dairy | D9: 4.3.1.5 Manure atmospheric deposition | E9: =VEERG_4_3_1_5__1_AnnualAtmosphericDepositionEmissionsFromMMS_Result_Method1 -> 0.050665467 | F9: =VEERG_4_3_1_5__1_AnnualAtmosphericDepositionEmissionsFromMMS_Result_Method2 -> 0.050665467 | G9: ='4.3.1.5 Atmos deposition'!$F$68 -> t N2O | H9: ='4.3.1.5 Atmos deposition'!$E$73 -> 13.426349 | I9: ='4.3.1.5 Atmos deposition'!$P$73 -> 13.426349 | J9: ='4.3.1.5 Atmos deposition'!$F$73 -> t CO2e
D10: 4.3.1.6-7 Manure leaching and runoff | E10: =VEERG_4_3_1_6__2_MassOfNitrogenLostToLeachingAndRunoffFromSolidStorage_Result_Method1 -> 0.0027795751 | F10: =VEERG_4_3_1_6__2_MassOfNitrogenLostToLeachingAndRunoffFromSolidStorage_Result_Method2 -> 0.0027795751 | G10: ='4.3.1.6-7 Leaching and runoff'!$F$52 -> t N2O | H10: ='4.3.1.6-7 Leaching and runoff'!$E$57 -> 0.7365874 | I10: ='4.3.1.6-7 Leaching and runoff'!$P$57 -> 0.7365874 | J10: ='4.3.1.6-7 Leaching and runoff'!$F$57 -> t CO2e
A11: CALCULATIONS | D11: 4.3.1.9 Soil direct N2O | E11: =VEERG_4_3_1_9__1_DirectNitrousOxideEmissionsOnPasture_Result_Method1 -> 0.080033058 | F11: =VEERG_4_3_1_9__1_DirectNitrousOxideEmissionsOnPasture_Result_Method2 -> 0.080033058 | G11: ='4.3.1.9 Soil direct N2O'!$F$53 -> t N2O | H11: ='4.3.1.9 Soil direct N2O'!$E$58 -> 21.20876 | I11: ='4.3.1.9 Soil direct N2O'!$P$58 -> 21.20876 | J11: ='4.3.1.9 Soil direct N2O'!$F$58 -> t CO2e
A12: =HYPERLINK("#'4.3.1.1-2 Methane'!A1", "4.3.1.1-2 Methane") -> 4.3.1.1-2 Methane | D12: 4.3.1.10-11 Soil atmospheric deposition | E12: =VEERG_4_3_1_10__1_AtmosphericDepositionEmissionsFromUrineAndDungOnPasture_Result_Method1 -> 0.04958048 | F12: =VEERG_4_3_1_10__1_AtmosphericDepositionEmissionsFromUrineAndDungOnPasture_Result_Method2 -> 0.04958048 | G12: ='4.3.1.10-11 Soil Atmos Dep'!$F$45 -> t N2O | H12: ='4.3.1.10-11 Soil Atmos Dep'!$E$50 -> 13.138827 | I12: ='4.3.1.10-11 Soil Atmos Dep'!$P$50 -> 13.138827 | J12: ='4.3.1.10-11 Soil Atmos Dep'!$F$50 -> t CO2e
A13: =HYPERLINK("#'4.3.1.3-4 Direct N20'!A1", "4.3.1.3-4 Direct N2O") -> 4.3.1.3-4 Direct N2O | D13: 4.3.1.12-13 Soil leaching and runoff | E13: =VEERG_4_3_1_12__1_LeachingAndRunoffEmissionsFromUrineAndDungOnPasture_Result_Method1 -> 0.10564364 | F13: =VEERG_4_3_1_12__1_LeachingAndRunoffEmissionsFromUrineAndDungOnPasture_Result_Method2 -> 0.10564364 | G13: ='4.3.1.12-13 Soil leach runoff'!$F$47 -> t N2O | H13: ='4.3.1.12-13 Soil leach runoff'!$E$52 -> 27.995564 | I13: ='4.3.1.12-13 Soil leach runoff'!$P$52 -> 27.995564 | J13: ='4.3.1.12-13 Soil leach runoff'!$F$52 -> t CO2e
A14: =HYPERLINK("#'4.3.1.5 Atmos Deposition'!A1", "4.3.1.5 Atmospheric deposition") -> 4.3.1.5 Atmospheric deposition | D14: Total | H14: =SUM(H7:H13) -> 382.04839 | I14: =SUM(I7:I13) -> 391.1865 | J14: t CO2e
A15: =HYPERLINK("#'4.3.1.6-7 Leaching and runoff'!A1", "4.3.1.6-7 Leaching and runoff") -> 4.3.1.6-7 Leaching and runoff
A16: =HYPERLINK("#'4.3.1.8 Manure applied to soils'!A1", "4.3.1.8 Manure applied to soils") -> 4.3.1.8 Manure applied to soils | D16: 4.3.1.8 Manure applied to soils
A17: =HYPERLINK("#'4.3.1.9 Soil direct N2O'!A1", "4.3.1.9 Soil direct N2O") -> 4.3.1.9 Soil direct N2O | D17: WARNING: Manure nitrogen that was applied to soils must be accounted for
A18: =HYPERLINK("#'4.3.1.10-11 Soil Atmos Dep'!A1", "4.3.1.10-11 Soil atm. deposition") -> 4.3.1.10-11 Soil atm. deposition | D18: See the table below for how to account for manure applied to soils for scope 1 and 3.
A19: =HYPERLINK("#'4.3.1.12-13 Soil leach runoff'!A1", "4.3.1.12-13 Soil leach & runoff") -> 4.3.1.12-13 Soil leach & runoff | D19: Manure nitrogen use | E19: N in manure (Method 1) | F19: N in manure (Method 2) | G19: N unit | H19: Emissions allocated to | I19: VEERG Calculation method
D20: Manure nitrogen deposited on farm soils (including use as fertiliser for other enterprises on own farm eg crops) | E20: =VEERG_4_3_1_8__1_MassOfNitrogenAppliedToSoilsScope1_Result_Method1 -> 12417.473 | F20: =VEERG_4_3_1_8__1_MassOfNitrogenAppliedToSoilsScope1_Result_Method2 -> 12417.473 | G20: kg N | H20: Scope 1 - This dairy | I20: 5.2.2.1 (1), 5.4.1.3 (1, 2), 5.5.1.1 (1, 3)
A21: APPENDICES | D21: Manure nitrogen deposited on farm soils as fertiliser for other farm enterpsies (eg crops) | E21: ='4.3.1.8 Manure applied to soils'!$E$148 -> 4139.1578 | F21: ='4.3.1.8 Manure applied to soils'!$P$148 -> 4139.1578 | G21: kg N | H21: Scope 1 - This dairy | I21: 5.2.2.1 (1), 5.4.1.3 (1, 2), 5.5.1.1 (1, 3)
A22: =HYPERLINK("#'Constants - Dairy'!A1", "Constants - Dairy") -> Constants - Dairy | D22: Manure nitrogen sold | E22: =VEERG_4_3_1_8__2_MassOfNitrogenAppliedToSoilsScope3_Result_Method1 -> 4139.1578 | F22: =VEERG_4_3_1_8__2_MassOfNitrogenAppliedToSoilsScope3_Result_Method2 -> 4139.1578 | G22: kg N | H22: Scope 3 (downstream) | I22: 15.13.1.1 (1), 5.2.2.1 (1), 5.4.1.3 (1, 2), 5.5.1.1 (1, 3)
A23: =HYPERLINK("#'Constants - Livestock'!A1", "Constants - Livestock") -> Constants - Livestock
A24: =HYPERLINK("#'Constants - Common'!A1", "Constants - Common") -> Constants - Common
A25: =HYPERLINK("#'Acknowledgements'!A1", "Acknowledgements") -> Acknowledgements

Sheet Input - Site
A1: #VALUE! | C1: Input - Site
A3: =HYPERLINK("#'Home'!A1", "Home") -> Home
A4: =HYPERLINK("#'Overview'!A1", "Overview") -> Overview
A5: =HYPERLINK("#'Results'!A1", "Results") -> Results | D5: Your business
A7: INPUTS | D7: Farm name | E7: My test farm
A8: =HYPERLINK("#'Input - Site'!A1", "Site") -> Site | D8: Reporting entity name | E8: My test Farms Pty Ltd
A9: =HYPERLINK("#'Input - Dairy'!A1", "Dairy") -> Dairy
D10: 💡An 'Emissions accounting period' is a 12 month period where the business can report on the emissions, and is typically the same as the business' financial accounting period.
A11: CALCULATIONS
A12: =HYPERLINK("#'4.3.1.1-2 Methane'!A1", "4.3.1.1-2 Methane") -> 4.3.1.1-2 Methane | D12: Emissions calculation period start date | E12: 45658 | F12: ← DD/MM/YYYY or DD Month YYYY
A13: =HYPERLINK("#'4.3.1.3-4 Direct N20'!A1", "4.3.1.3-4 Direct N2O") -> 4.3.1.3-4 Direct N2O | D13: Emissions calculation period end date | E13: =DATE(YEAR(E12)+1,MONTH(E12),DAY(E12))-1 -> 46022 | F13: ← Automatically calculated, 12 months after start date
A14: =HYPERLINK("#'4.3.1.5 Atmos Deposition'!A1", "4.3.1.5 Atmospheric deposition") -> 4.3.1.5 Atmospheric deposition
A15: =HYPERLINK("#'4.3.1.6-7 Leaching and runoff'!A1", "4.3.1.6-7 Leaching and runoff") -> 4.3.1.6-7 Leaching and runoff
A16: =HYPERLINK("#'4.3.1.8 Manure applied to soils'!A1", "4.3.1.8 Manure applied to soils") -> 4.3.1.8 Manure applied to soils | D16: Location and climate
A17: =HYPERLINK("#'4.3.1.9 Soil direct N2O'!A1", "4.3.1.9 Soil direct N2O") -> 4.3.1.9 Soil direct N2O
A18: =HYPERLINK("#'4.3.1.10-11 Soil Atmos Dep'!A1", "4.3.1.10-11 Soil atm. deposition") -> 4.3.1.10-11 Soil atm. deposition | D18: Location information is used to reference some region and climate-specific emission factors
A19: =HYPERLINK("#'4.3.1.12-13 Soil leach runoff'!A1", "4.3.1.12-13 Soil leach & runoff") -> 4.3.1.12-13 Soil leach & runoff | D19: Tip: Use the web-based GAF Location Helper tool to easily get region and climate information. You will need an internet connection to use the GAF Location Helper.
A21: APPENDICES | D21: State | E21: Western Australia | F21: ← Please select
A22: =HYPERLINK("#'Constants - Dairy'!A1", "Constants - Dairy") -> Constants - Dairy | D22: Region (ABS Statistical area level 4) if state is WA | E22: Western Australia - Outback (South) | F22: ← Please select
A23: =HYPERLINK("#'Constants - Livestock'!A1", "Constants - Livestock") -> Constants - Livestock | D23: Leaching zone | E23: NO - Not in leaching zone | F23: ← Please select
A24: =HYPERLINK("#'Constants - Common'!A1", "Constants - Common") -> Constants - Common | D24: Elevation | E24: 307.7 | F24: Meters
A25: =HYPERLINK("#'Acknowledgements'!A1", "Acknowledgements") -> Acknowledgements | D25: Average temperature for reporting period | E25: 18 | F25: Degrees celsius
D26: Total rainfall for reporting period | E26: 601 | F26: Millimetres
D27: Potential evapotranspiration for reporting period | E27: 1326 | F27: Millimetres
D28: Number of frost days for reporting period | E28: 7 | F28: Days
D29: MAP:PET ratio | E29: =E26/E27 -> 0.45324284
D30: Rainfall zone | E30: =Common_InputFunctions.Utility_LookupItemFromMinMax(E26,Table_SourceData_RainfallZones[Min rainfall],Table_SourceData_RainfallZones[Max rainfall],Table_SourceData_RainfallZones[Rainfall Zone]) -> High rainfall
D31: Climate zone | E31: =Common_InputFunctions.Utility_GetClimateZone(E25,E26,E28,E24,E29,Table_SourceData_ClimateZones[Min temp],Table_SourceData_ClimateZones[Max temp],Table_SourceData_ClimateZones[Min rainfall],Table_SourceData_ClimateZones[Max rainfall],Table_SourceData_ClimateZones[Min frost days],Table_SourceData_ClimateZones[Max frost days],Table_SourceData_ClimateZones[Min elevation],Table_SourceData_ClimateZones[Max elevation],Table_SourceData_ClimateZones[Min MAP:PET],Table_SourceData_ClimateZones[Max MAP:PET],Table_SourceData_ClimateZones[Climate zone]) -> Warm temperate dry
D32: Wet or dry climate zone | E32: =Common_InputFunctions.Utility_LookupValueInTable($E$31,Table_SourceData_WetDryZones[Climate zone],Table_SourceData_WetDryZones[Wet or Dry Zone]) -> Dry climate zone
D33: Temperature zone | E33: =Common_InputFunctions.Utility_LookupItemFromMinMax(E25,Table_SourceData_TemperatureZones[Min MAT],Table_SourceData_TemperatureZones[Max MAT],Table_SourceData_TemperatureZones[Temperature Zone]) -> Temperate

Sheet Input - Dairy
A1: #VALUE! | C1: Input -Dairy
A3: =HYPERLINK("#'Home'!A1", "Home") -> Home
A4: =HYPERLINK("#'Overview'!A1", "Overview") -> Overview
A5: =HYPERLINK("#'Results'!A1", "Results") -> Results | D5: Herd movement
A7: INPUTS | D7: Breed | E7: Medium Friesian | F7: ← Please select
A8: =HYPERLINK("#'Input - Site'!A1", "Site") -> Site
A9: =HYPERLINK("#'Input - Dairy'!A1", "Dairy") -> Dairy | E9: Milking cows | F9: Heifers > 1 year | G9: Heifers < 1 year | H9: Bulls > 1 year | I9: Bulls < 1 year
D10: ="Average number of head between " & TEXT('Input - Site'!$E$12, "dd mmm yy") & " and " & TEXT('Input - Site'!$E$13, "dd mmm yy") -> Average number of head between 01 Jan 25 and 31 Dec 25 | E10: 100 | F10: 100 | G10: 100 | H10: 100 | I10: 100 | J10: head
A11: CALCULATIONS
A12: =HYPERLINK("#'4.3.1.1-2 Methane'!A1", "4.3.1.1-2 Methane") -> 4.3.1.1-2 Methane | D12: Liveweight
A13: =HYPERLINK("#'4.3.1.3-4 Direct N20'!A1", "4.3.1.3-4 Direct N2O") -> 4.3.1.3-4 Direct N2O | D13: Method 1 default values (Do not edit) | E13: Milking cows | F13: Heifers > 1 year | G13: Heifers < 1 year | H13: Bulls > 1 year | I13: Bulls < 1 year
A14: =HYPERLINK("#'4.3.1.5 Atmos Deposition'!A1", "4.3.1.5 Atmospheric deposition") -> 4.3.1.5 Atmospheric deposition | D14: Average liveweight | E14: 550 | F14: 380 | G14: 155 | H14: 600 | I14: 225 | J14: kg/head
A15: =HYPERLINK("#'4.3.1.6-7 Leaching and runoff'!A1", "4.3.1.6-7 Leaching and runoff") -> 4.3.1.6-7 Leaching and runoff | D15: Average liveweight gain | E15: 0.016 | F15: 0.6 | G15: 0.57 | H15: 0.1 | I15: 0.8 | J15: kg/head/day
A16: =HYPERLINK("#'4.3.1.8 Manure applied to soils'!A1", "4.3.1.8 Manure applied to soils") -> 4.3.1.8 Manure applied to soils
A17: =HYPERLINK("#'4.3.1.9 Soil direct N2O'!A1", "4.3.1.9 Soil direct N2O") -> 4.3.1.9 Soil direct N2O | D17: Method 2 custom values (Edit if known) | E17: Milking cows | F17: Heifers > 1 year | G17: Heifers < 1 year | H17: Bulls > 1 year | I17: Bulls < 1 year
A18: =HYPERLINK("#'4.3.1.10-11 Soil Atmos Dep'!A1", "4.3.1.10-11 Soil atm. deposition") -> 4.3.1.10-11 Soil atm. deposition | D18: Average liveweight | E18: 550 | F18: 380 | G18: 155 | H18: 600 | I18: 225 | J18: kg/head
A19: =HYPERLINK("#'4.3.1.12-13 Soil leach runoff'!A1", "4.3.1.12-13 Soil leach & runoff") -> 4.3.1.12-13 Soil leach & runoff | D19: Average liveweight gain | E19: 0.016 | F19: 0.6 | G19: 0.57 | H19: 0.1 | I19: 0.8 | J19: kg/head/day
A21: APPENDICES | D21: Duration of stay
A22: =HYPERLINK("#'Constants - Dairy'!A1", "Constants - Dairy") -> Constants - Dairy
A23: =HYPERLINK("#'Constants - Livestock'!A1", "Constants - Livestock") -> Constants - Livestock | D23: Method 1 default values (Do not edit) | E23: Milking cows | F23: Heifers > 1 year | G23: Heifers < 1 year | H23: Bulls > 1 year | I23: Bulls < 1 year
A24: =HYPERLINK("#'Constants - Common'!A1", "Constants - Common") -> Constants - Common | D24: ="Average duration of stay between " & TEXT('Input - Site'!$E$12, "dd mmm yy") & " and " & TEXT('Input - Site'!$E$13, "dd mmm yy") & " weaned livestock" -> Average duration of stay between 01 Jan 25 and 31 Dec 25 weaned livestock | E24: 365 | F24: 365 | G24: 281 | H24: 365 | I24: 281 | J24: Days
A25: =HYPERLINK("#'Acknowledgements'!A1", "Acknowledgements") -> Acknowledgements | D25: ="Average duration of stay between " & TEXT('Input - Site'!$E$12, "dd mmm yy") & " and " & TEXT('Input - Site'!$E$13, "dd mmm yy") & " pre-weaned livestock" -> Average duration of stay between 01 Jan 25 and 31 Dec 25 pre-weaned livestock | E25: 0 | F25: 0 | G25: 84 | H25: 0 | I25: 84 | J25: Days
D27: Method 2 custom values (Edit if known) | E27: Milking cows | F27: Heifers > 1 year | G27: Heifers < 1 year | H27: Bulls > 1 year | I27: Bulls < 1 year
D28: ="Average duration of stay between " & TEXT('Input - Site'!$E$12, "dd mmm yy") & " and " & TEXT('Input - Site'!$E$13, "dd mmm yy") & " weaned livestock" -> Average duration of stay between 01 Jan 25 and 31 Dec 25 weaned livestock | E28: 365 | F28: 365 | G28: 281 | H28: 365 | I28: 281 | J28: Days
D29: ="Average duration of stay between " & TEXT('Input - Site'!$E$12, "dd mmm yy") & " and " & TEXT('Input - Site'!$E$13, "dd mmm yy") & " pre-weaned livestock" -> Average duration of stay between 01 Jan 25 and 31 Dec 25 pre-weaned livestock | E29: 0 | F29: 0 | G29: 84 | H29: 0 | I29: 84 | J29: Days
D33: Diet
D35: Method 1 default values (Do not edit) | E35: Milking cows | F35: Heifers > 1 year | G35: Heifers < 1 year | H35: Bulls > 1 year | I35: Bulls < 1 year
D36: Dry matter digestibility | E36: 0.75 | F36: 0.75 | G36: 0.75 | H36: 0.75 | I36: 0.75 | J36: Fraction
D37: Crude protein | E37: 0.2 | F37: 0.2 | G37: 0.2 | H37: 0.2 | I37: 0.2 | J37: Fraction
D39: Method 2 custom values (Edit if known) | E39: Milking cows | F39: Heifers > 1 year | G39: Heifers < 1 year | H39: Bulls > 1 year | I39: Bulls < 1 year
D40: Dry matter digestibility | E40: 0.75 | F40: 0.75 | G40: 0.75 | H40: 0.75 | I40: 0.75 | J40: Fraction
D41: Crude protein | E41: 0.2 | F41: 0.2 | G41: 0.2 | H41: 0.2 | I41: 0.2 | J41: Fraction
D48: Milk production
D49: Milk production for the full 365 days of the year
D50: Milk production unit | E50: Litres of milk | F50: ← Please select
E52: Milking cows
D53: Average daily milk production | E53: 20 | F53: =IF(E50="Litres of milk", "litres/head/day", "kg milk solids/head/day") -> litres/head/day
D55: For milk solids only: | E55: Method 1 (don't edit) | F55: Method 2 (edit if known)
D56: Fat content in fat and protein corrected milk | E56: 0.04 | F56: 0.04 | G56: percent
D57: Protein content in fat and protein corrected milk | E57: 0.033 | F57: 0.033 | G57: percent
...

Sheet 4.3.1.1-2 Methane
A1: #VALUE! | C1: 4.3.1.1-2 Manure Methane
A3: =HYPERLINK("#'Home'!A1", "Home") -> Home | D3: Method 1 | O3: Method 2
A4: =HYPERLINK("#'Overview'!A1", "Overview") -> Overview
A5: =HYPERLINK("#'Results'!A1", "Results") -> Results | D5: {=EntericMethane_Dairy_Equations.VEERG_3_3_1_1__6_MetabolisabilityOfDiet_Title()} -> Metabolisability of diet
D6: {=EntericMethane_Dairy_Equations.VEERG_3_3_1_1__6_MetabolisabilityOfDiet_Source()} -> VEERG 2026: 3.3.1.1, Equation (6)
A7: INPUTS | D7: {=EntericMethane_Dairy_Equations.VEERG_3_3_1_1__6_MetabolisabilityOfDiet_Variation()} -> VARIATION ON SOURCE: changed 0.795 to 0.00795 which is the value used in the National Inventory Report
A8: =HYPERLINK("#'Input - Site'!A1", "Site") -> Site | D8: Function name | E8: {=Common_InputFunctions.Utility_DisplayFunctionName(D24)} -> =EntericMethane_Dairy_Equations.VEERG_3_3_1_1__6_MetabolisabilityOfDietVariation
A9: =HYPERLINK("#'Input - Dairy'!A1", "Dairy") -> Dairy
A11: CALCULATIONS | D11: Variable | E11: {=EntericMethane_Dairy_Equations.VEERG_3_3_1_1__6_MetabolisabilityOfDiet_Variable()} -> qm_j
A12: =HYPERLINK("#'4.3.1.1-2 Methane'!A1", "4.3.1.1-2 Methane") -> 4.3.1.1-2 Methane | D12: Unit | E12: {=EntericMethane_Dairy_Equations.VEERG_3_3_1_1__6_MetabolisabilityOfDiet_Unit()} -> fraction
A13: =HYPERLINK("#'4.3.1.3-4 Direct N20'!A1", "4.3.1.3-4 Direct N2O") -> 4.3.1.3-4 Direct N2O
A14: =HYPERLINK("#'4.3.1.5 Atmos Deposition'!A1", "4.3.1.5 Atmospheric deposition") -> 4.3.1.5 Atmospheric deposition | D14: {=_xlfn.CHOOSECOLS(EntericMethane_Dairy_Equations.VEERG_3_3_1_1__6_MetabolisabilityOfDiet_Arguments(), 1,2)} -> DMD_j | E14: dry matter digestibility expressed as a fraction | G14: {=_xlfn.CHOOSECOLS(EntericMethane_Dairy_Equations.VEERG_3_3_1_1__6_MetabolisabilityOfDiet_Arguments(), 3,4)} -> fraction | H14: Input | I14: ="See " & D16 -> See M1_Table_DMD_j
A15: =HYPERLINK("#'4.3.1.6-7 Leaching and runoff'!A1", "4.3.1.6-7 Leaching and runoff") -> 4.3.1.6-7 Leaching and runoff
A16: =HYPERLINK("#'4.3.1.8 Manure applied to soils'!A1", "4.3.1.8 Manure applied to soils") -> 4.3.1.8 Manure applied to soils | D16: M1_Table_DMD_j | O16: M2_Table_DMD_j
A17: =HYPERLINK("#'4.3.1.9 Soil direct N2O'!A1", "4.3.1.9 Soil direct N2O") -> 4.3.1.9 Soil direct N2O | D17: Dry matter digestibility (Method 1) | O17: Dry matter digestibility (Method 2)
A18: =HYPERLINK("#'4.3.1.10-11 Soil Atmos Dep'!A1", "4.3.1.10-11 Soil atm. deposition") -> 4.3.1.10-11 Soil atm. deposition | D18: Milking cows | E18: Heifers > 1 year | F18: Heifers < 1 year | G18: Bulls > 1 year | H18: Bulls < 1 year | O18: Milking cows | P18: Heifers > 1 year | Q18: Heifers < 1 year | R18: Bulls > 1 year | S18: Bulls < 1 year
A19: =HYPERLINK("#'4.3.1.12-13 Soil leach runoff'!A1", "4.3.1.12-13 Soil leach & runoff") -> 4.3.1.12-13 Soil leach & runoff | D19: =INDEX(X_Table_Dairy_Diet_Method1,2,2) -> 0.75 | E19: =INDEX(X_Table_Dairy_Diet_Method1,2,3) -> 0.75 | F19: =INDEX(X_Table_Dairy_Diet_Method1,2,4) -> 0.75 | G19: =INDEX(X_Table_Dairy_Diet_Method1,2,5) -> 0.75 | H19: =INDEX(X_Table_Dairy_Diet_Method1,2,6) -> 0.75 | I19: fraction | O19: =INDEX(X_Table_Dairy_Diet_Method2,2,2) -> 0.75 | P19: =INDEX(X_Table_Dairy_Diet_Method2,2,3) -> 0.75 | Q19: =INDEX(X_Table_Dairy_Diet_Method2,2,4) -> 0.75 | R19: =INDEX(X_Table_Dairy_Diet_Method2,2,5) -> 0.75 | S19: =INDEX(X_Table_Dairy_Diet_Method2,2,6) -> 0.75 | T19: fraction
A21: APPENDICES | D21: M1_Table_qm_j | O21: M2_Table_qm_j
A22: =HYPERLINK("#'Constants - Dairy'!A1", "Constants - Dairy") -> Constants - Dairy | D22: Metabolisability of diet (Method 1) | O22: Metabolisability of diet (Method 2)
A23: =HYPERLINK("#'Constants - Livestock'!A1", "Constants - Livestock") -> Constants - Livestock | D23: Milking cows | E23: Heifers > 1 year | F23: Heifers < 1 year | G23: Bulls > 1 year | H23: Bulls < 1 year | O23: Milking cows | P23: Heifers > 1 year | Q23: Heifers < 1 year | R23: Bulls > 1 year | S23: Bulls < 1 year
A24: =HYPERLINK("#'Constants - Common'!A1", "Constants - Common") -> Constants - Common | D24: {=EntericMethane_Dairy_Equations.VEERG_3_3_1_1__6_MetabolisabilityOfDietVariation(D19)} -> 0.59485 | E24: {=EntericMethane_Dairy_Equations.VEERG_3_3_1_1__6_MetabolisabilityOfDietVariation(E19)} -> 0.59485 | F24: {=EntericMethane_Dairy_Equations.VEERG_3_3_1_1__6_MetabolisabilityOfDietVariation(F19)} -> 0.59485 | G24: {=EntericMethane_Dairy_Equations.VEERG_3_3_1_1__6_MetabolisabilityOfDietVariation(G19)} -> 0.59485 | H24: {=EntericMethane_Dairy_Equations.VEERG_3_3_1_1__6_MetabolisabilityOfDietVariation(H19)} -> 0.59485 | I24: =$E$12 -> fraction | O24: {=EntericMethane_Dairy_Equations.VEERG_3_3_1_1__6_MetabolisabilityOfDietVariation(O19)} -> 0.59485 | P24: {=EntericMethane_Dairy_Equations.VEERG_3_3_1_1__6_MetabolisabilityOfDietVariation(P19)} -> 0.59485 | Q24: {=EntericMethane_Dairy_Equations.VEERG_3_3_1_1__6_MetabolisabilityOfDietVariation(Q19)} -> 0.59485 | R24: {=EntericMethane_Dairy_Equations.VEERG_3_3_1_1__6_MetabolisabilityOfDietVariation(R19)} -> 0.59485 | S24: {=EntericMethane_Dairy_Equations.VEERG_3_3_1_1__6_MetabolisabilityOfDietVariation(S19)} -> 0.59485 | T24: =$E$12 -> fraction
A25: =HYPERLINK("#'Acknowledgements'!A1", "Acknowledgements") -> Acknowledgements
D28: {=EntericMethane_Dairy_Equations.VEERG_3_3_1_1__5_MilkProductionFromMilkSolids_Title()} -> Milk production converted from milk solids
D29: {=EntericMethane_Dairy_Equations.VEERG_3_3_1_1__5_MilkProductionFromMilkSolids_Source()} -> VEERG 2026: 3.3.1.1, Equation (5)
D30: {=EntericMethane_Dairy_Equations.VEERG_3_3_1_1__5_MilkProductionFromMilkSolids_Variation()} -> VARATION ON SOURCE: Added milk production unit variable to allow for use of either milk solids or litres of milk. Converted input FC and PC percent to integer.
D31: Function name | E31: {=Common_InputFunctions.Utility_DisplayFunctionName(D50)} -> =EntericMethane_Dairy_Equations.VEERG_3_3_1_1__5_MilkProductionFromMilkSolids
D34: Variable | E34: {=EntericMethane_Dairy_Equations.VEERG_3_3_1_1__5_MilkProductionFromMilkSolids_Variable()} -> MP_j
D35: Unit | E35: {=EntericMethane_Dairy_Equations.VEERG_3_3_1_1__5_MilkProductionFromMilkSolids_Unit()} -> L/head/day
D37: {=_xlfn.CHOOSECOLS(EntericMethane_Dairy_Equations.VEERG_3_3_1_1__5_MilkProductionFromMilkSolids_Arguments(),1,2)} -> MPU | E37: input milk production unit | G37: {=_xlfn.CHOOSECOLS(EntericMethane_Dairy_Equations.VEERG_3_3_1_1__5_MilkProductionFromMilkSolids_Arguments(),3,4)} | H37: Input | I37: =X_Cell_Dairy_MilkProductionUnit -> Litres of milk | O37: {=_xlfn.CHOOSECOLS(EntericMethane_Dairy_Equations.VEERG_3_3_1_1__5_MilkProductionFromMilkSolids_Arguments_Method2(),1,2)} -> MPU | P37: milk production unit | R37: {=_xlfn.CHOOSECOLS(EntericMethane_Dairy_Equations.VEERG_3_3_1_1__5_MilkProductionFromMilkSolids_Arguments_Method2(),3,4)} | S37: Input
D38: MS_j | E38: daily production of milk solids | G38: kg MS/head/day | H38: Input | I38: {=HYPERLINK(Common_InputFunctions.Utility_SourceHyperlink($D$42),$D$42)} -> M1_Table_MS_j | O38: MS_j | P38: daily production of milk solids | R38: kg MS/head/day | S38: Input
D39: FC_j | E39: fat content in fat and protein corrected milk | G39: per cent | H39: Input | I39: =INDEX(X_Table_Dairy_MilkSolidAttributes,2,2)*100 -> 4 | O39: FC_j | P39: fat content in fat and protein corrected milk | R39: per cent | S39: Input | T39: =INDEX(X_Table_Dairy_MilkSolidAttributes,2,3)*100 -> 4
D40: PC_j | E40: protein content in fat and protein corrected milk | G40: per cent | H40: Input | I40: =INDEX(X_Table_Dairy_MilkSolidAttributes,3,2)*100 -> 3.3 | O40: PC_j | P40: protein content in fat and protein corrected milk | R40: per cent | S40: Input | T40: =INDEX(X_Table_Dairy_MilkSolidAttributes,3,3)*100 -> 3.3
D42: M1_Table_MS_j
D43: Milk solids production (Method 1)
D44: Milking cows | E44: Heifers > 1 year | F44: Heifers < 1 year | G44: Bulls > 1 year | H44: Bulls < 1 year
D45: =IF($I$37="Milk solids", X_Cell_Dairy_MilkProductionAmount, 0) -> 0 | E45: 0 | F45: 0 | G45: 0 | H45: 0 | I45: =G38 -> kg MS/head/day
D47: M1_Table_MP_j_from_solids | O47: M2_Table_MP_j_from_solids
D48: Milk production from milk solids (Method 1) | O48: Milk production from milk solids (Method 2)
D49: Milking cows | E49: Heifers > 1 year | F49: Heifers < 1 year | G49: Bulls > 1 year | H49: Bulls < 1 year | O49: Milking cows | P49: Heifers > 1 year | Q49: Heifers < 1 year | R49: Bulls > 1 year | S49: Bulls < 1 year
D50: {=EntericMethane_Dairy_Equations.VEERG_3_3_1_1__5_MilkProductionFromMilkSolids(D45,$I$39,$I$40)} -> 0 | E50: 0 | F50: 0 | G50: 0 | H50: 0 | I50: L/head/day | O50: {=EntericMethane_Dairy_Equations.VEERG_3_3_1_1__5_MilkProductionFromMilkSolids(D45,$T$39,$T$40)} -> 0 | P50: 0 | Q50: 0 | R50: 0 | S50: 0 | T50: L/head/day
...

Sheet 4.3.1.3-4 Direct N20
A1: #VALUE! | C1: 4.3.1.3-4 Manure Direct N2O
A3: =HYPERLINK("#'Home'!A1", "Home") -> Home | D3: Method 1 | N3: Method 2
A4: =HYPERLINK("#'Overview'!A1", "Overview") -> Overview
A5: =HYPERLINK("#'Results'!A1", "Results") -> Results | D5: {=MMS_Dairy_N2ODirect_Equations.VEERG_4_3_1_3__8_RelativeSize_Title()} -> Relative size
D6: {=MMS_Dairy_N2ODirect_Equations.VEERG_4_3_1_3__8_RelativeSize_Source()} -> VEERG 2026: 4.3.1.3, Equation (8)
A7: INPUTS | D7: Function name | E7: {=Common_InputFunctions.Utility_DisplayFunctionName(D29)} -> =MMS_Dairy_N2ODirect_Equations.VEERG_4_3_1_3__8_RelativeSize
A8: =HYPERLINK("#'Input - Site'!A1", "Site") -> Site
A9: =HYPERLINK("#'Input - Dairy'!A1", "Dairy") -> Dairy
D10: Variable | E10: {=MMS_Dairy_N2ODirect_Equations.VEERG_4_3_1_3__8_RelativeSize_Variable()} -> Z_j
A11: CALCULATIONS | D11: Unit | E11: {=MMS_Dairy_N2ODirect_Equations.VEERG_4_3_1_3__8_RelativeSize_Unit()} -> ratio
A12: =HYPERLINK("#'4.3.1.1-2 Methane'!A1", "4.3.1.1-2 Methane") -> 4.3.1.1-2 Methane
A13: =HYPERLINK("#'4.3.1.3-4 Direct N20'!A1", "4.3.1.3-4 Direct N2O") -> 4.3.1.3-4 Direct N2O | D13: {=_xlfn.CHOOSECOLS(MMS_Dairy_N2ODirect_Equations.VEERG_4_3_1_3__8_RelativeSize_Arguments(),1,2)} -> W_j | E13: liveweight | F13: {=_xlfn.CHOOSECOLS(MMS_Dairy_N2ODirect_Equations.VEERG_4_3_1_3__8_RelativeSize_Arguments(),3,4)} -> kg/head | G13: Input | H13: {=HYPERLINK(Common_InputFunctions.Utility_SourceHyperlink($D$16),$D$16)} -> M1_Table_W_j
A14: =HYPERLINK("#'4.3.1.5 Atmos Deposition'!A1", "4.3.1.5 Atmospheric deposition") -> 4.3.1.5 Atmospheric deposition | D14: WR_j | E14: reference weight | F14: kg/head | G14: Constant | H14: {=HYPERLINK(Common_InputFunctions.Utility_SourceHyperlink($D$21),$D$21)} -> Table_WR_j
A15: =HYPERLINK("#'4.3.1.6-7 Leaching and runoff'!A1", "4.3.1.6-7 Leaching and runoff") -> 4.3.1.6-7 Leaching and runoff
A16: =HYPERLINK("#'4.3.1.8 Manure applied to soils'!A1", "4.3.1.8 Manure applied to soils") -> 4.3.1.8 Manure applied to soils | D16: M1_Table_W_j | N16: M2_Table_W_j
A17: =HYPERLINK("#'4.3.1.9 Soil direct N2O'!A1", "4.3.1.9 Soil direct N2O") -> 4.3.1.9 Soil direct N2O | D17: Liveweight for each animal class j (Method 1) | N17: Liveweight for each animal class j (Method 2)
A18: =HYPERLINK("#'4.3.1.10-11 Soil Atmos Dep'!A1", "4.3.1.10-11 Soil atm. deposition") -> 4.3.1.10-11 Soil atm. deposition | D18: Milking cows | E18: Heifers > 1 year | F18: Heifers < 1 year | G18: Bulls > 1 year | H18: Bulls < 1 year | N18: Milking cows | O18: Heifers > 1 year | P18: Heifers < 1 year | Q18: Bulls > 1 year | R18: Bulls < 1 year
A19: =HYPERLINK("#'4.3.1.12-13 Soil leach runoff'!A1", "4.3.1.12-13 Soil leach & runoff") -> 4.3.1.12-13 Soil leach & runoff | D19: =INDEX(X_Table_Dairy_Liveweight_Method1,2,2) -> 550 | E19: =INDEX(X_Table_Dairy_Liveweight_Method1,2,3) -> 380 | F19: =INDEX(X_Table_Dairy_Liveweight_Method1,2,4) -> 155 | G19: =INDEX(X_Table_Dairy_Liveweight_Method1,2,5) -> 600 | H19: =INDEX(X_Table_Dairy_Liveweight_Method1,2,6) -> 225 | I19: kg/head | N19: =INDEX(X_Table_Dairy_Liveweight_Method2,2,2) -> 550 | O19: =INDEX(X_Table_Dairy_Liveweight_Method2,2,3) -> 380 | P19: =INDEX(X_Table_Dairy_Liveweight_Method2,2,4) -> 155 | Q19: =INDEX(X_Table_Dairy_Liveweight_Method2,2,5) -> 600 | R19: =INDEX(X_Table_Dairy_Liveweight_Method2,2,6) -> 225 | S19: kg/head
A21: APPENDICES | D21: Table_WR_j
A22: =HYPERLINK("#'Constants - Dairy'!A1", "Constants - Dairy") -> Constants - Dairy | D22: Reference weight for each animal class
A23: =HYPERLINK("#'Constants - Livestock'!A1", "Constants - Livestock") -> Constants - Livestock | D23: Milking cows | E23: Heifers > 1 year | F23: Heifers < 1 year | G23: Bulls > 1 year | H23: Bulls < 1 year
A24: =HYPERLINK("#'Constants - Common'!A1", "Constants - Common") -> Constants - Common | D24: {=Table_SourceData_Dairy_WRj[Milking cows]} -> 590 | E24: {=Table_SourceData_Dairy_WRj[Heifers > 1]} -> 590 | F24: {=Table_SourceData_Dairy_WRj[Heifers < 1 (weaned)]} -> 590 | G24: {=Table_SourceData_Dairy_WRj[Bulls > 1]} -> 770 | H24: {=Table_SourceData_Dairy_WRj[Bulls < 1 (weaned)]} -> 770 | I24: kg/head
A25: =HYPERLINK("#'Acknowledgements'!A1", "Acknowledgements") -> Acknowledgements
D26: M1_Table_Z_j | N26: M1_Table_Z_j
D27: Relative size for each animal class (Method 1) | N27: Relative size for each animal class (Method 2)
D28: Milking cows | E28: Heifers > 1 year | F28: Heifers < 1 year | G28: Bulls > 1 year | H28: Bulls < 1 year | N28: Milking cows | O28: Heifers > 1 year | P28: Heifers < 1 year | Q28: Bulls > 1 year | R28: Bulls < 1 year
D29: {=MMS_Dairy_N2ODirect_Equations.VEERG_4_3_1_3__8_RelativeSize(D19,D24)} -> 0.93220339 | E29: {=MMS_Dairy_N2ODirect_Equations.VEERG_4_3_1_3__8_RelativeSize(E19,E24)} -> 0.6440678 | F29: {=MMS_Dairy_N2ODirect_Equations.VEERG_4_3_1_3__8_RelativeSize(F19,F24)} -> 0.26271186 | G29: {=MMS_Dairy_N2ODirect_Equations.VEERG_4_3_1_3__8_RelativeSize(G19,G24)} -> 0.77922078 | H29: {=MMS_Dairy_N2ODirect_Equations.VEERG_4_3_1_3__8_RelativeSize(H19,H24)} -> 0.29220779 | I29: =$E$11 -> ratio | N29: {=MMS_Dairy_N2ODirect_Equations.VEERG_4_3_1_3__8_RelativeSize(N19,D24)} -> 0.93220339 | O29: {=MMS_Dairy_N2ODirect_Equations.VEERG_4_3_1_3__8_RelativeSize(O19,E24)} -> 0.6440678 | P29: {=MMS_Dairy_N2ODirect_Equations.VEERG_4_3_1_3__8_RelativeSize(P19,F24)} -> 0.26271186 | Q29: {=MMS_Dairy_N2ODirect_Equations.VEERG_4_3_1_3__8_RelativeSize(Q19,G24)} -> 0.77922078 | R29: {=MMS_Dairy_N2ODirect_Equations.VEERG_4_3_1_3__8_RelativeSize(R19,H24)} -> 0.29220779 | S29: =$E$11 -> ratio
D33: {=MMS_Dairy_N2ODirect_Equations.VEERG_4_3_1_3__7_IntakeRelativeToMaintenance_Title()} -> Intake relative to maintenance
D34: {=MMS_Dairy_N2ODirect_Equations.VEERG_4_3_1_3__7_IntakeRelativeToMaintenance_Source()} -> VEERG 2026: 4.3.1.3, Equation (7)
D35: Function name | E35: {=Common_InputFunctions.Utility_DisplayFunctionName(D65)} -> =MMS_Dairy_N2ODirect_Equations.VEERG_4_3_1_3__7_IntakeRelativeToMaintenance
D39: Variable | E39: {=MMS_Dairy_N2ODirect_Equations.VEERG_4_3_1_3__7_IntakeRelativeToMaintenance_Variable()} -> L_j
D40: Unit | E40: {=MMS_Dairy_N2ODirect_Equations.VEERG_4_3_1_3__7_IntakeRelativeToMaintenance_Unit()} -> ratio
D42: {=_xlfn.CHOOSECOLS(MMS_Dairy_N2ODirect_Equations.VEERG_4_3_1_3__7_IntakeRelativeToMaintenance_Arguments(),1,2)} -> I_j | E42: dry matter intake | G42: {=_xlfn.CHOOSECOLS(MMS_Dairy_N2ODirect_Equations.VEERG_4_3_1_3__7_IntakeRelativeToMaintenance_Arguments(),3,4)} -> kgDM/head/day | H42: Calculated from 3.3.1.1 (3) | I42: {=HYPERLINK(Common_InputFunctions.Utility_SourceHyperlink($D$47),$D$47)} -> M1_Table_I_j
D43: W_j | E43: liveweight | G43: kg/head | H43: Input | I43: {=HYPERLINK(Common_InputFunctions.Utility_SourceHyperlink($D$16),$D$16)} -> M1_Table_W_j
D44: MR_j | E44: increase in metabolic rate when producing milk | H44: Constant | I44: {=HYPERLINK(Common_InputFunctions.Utility_SourceHyperlink($D$52),$D$52)} -> Table_MR_j
D45: MI_j | E45: additional intake required for milk production | G45: kgDM/head/day | H45: Calculated from 3.3.1.1 (4) | I45: {=HYPERLINK(Common_InputFunctions.Utility_SourceHyperlink($D$57),$D$57)} -> M1_Table_MI_j
D47: M1_Table_I_j | N47: M2_Table_I_j
D48: Feed intake (Method 1) | N48: Feed intake (Method 2)
D49: Milking cows | E49: Heifers > 1 year | F49: Heifers < 1 year | G49: Bulls > 1 year | H49: Bulls < 1 year | N49: Milking cows | O49: Heifers > 1 year | P49: Heifers < 1 year | Q49: Bulls > 1 year | R49: Bulls < 1 year
D50: =INDEX(M1_Table_I_j,2,1) -> 18.834318 | E50: =INDEX(M1_Table_I_j,2,2) -> 7.4188685 | F50: =INDEX(M1_Table_I_j,2,3) -> 4.0231735 | G50: =INDEX(M1_Table_I_j,2,4) -> 9.0270202 | H50: =INDEX(M1_Table_I_j,2,5) -> 5.4143473 | I50: =G42 -> kgDM/head/day | N50: =INDEX(M2_Table_I_j,2,1) -> 18.834318 | O50: =INDEX(M2_Table_I_j,2,2) -> 7.4188685 | P50: =INDEX(M2_Table_I_j,2,3) -> 4.0231735 | Q50: =INDEX(M2_Table_I_j,2,4) -> 9.0270202 | R50: =INDEX(M2_Table_I_j,2,5) -> 5.4143473 | S50: ='4.3.1.1-2 Methane'!T114 -> kg DM/head/day
...

Sheet 4.3.1.5 Atmos deposition
A1: #VALUE! | C1: 4.3.1.5 Manure Atmospheric Deposition
A3: =HYPERLINK("#'Home'!A1", "Home") -> Home | D3: Method 1 | O3: Method 2
A4: =HYPERLINK("#'Overview'!A1", "Overview") -> Overview
A5: =HYPERLINK("#'Results'!A1", "Results") -> Results | D5: {=MMS_Dairy_AtmosphericDeposition_Equations.VEERG_4_3_1_5__2_TotalNitrogenVolatilisedFromMMS_Title()} -> Total nitrogen volatilised from MMS
D6: {=MMS_Dairy_AtmosphericDeposition_Equations.VEERG_4_3_1_5__2_TotalNitrogenVolatilisedFromMMS_Source()} -> VEERG 2026: 4.3.1.5, Equation (2)
A7: INPUTS | D7: Function name | E7: {=Common_InputFunctions.Utility_DisplayFunctionName(F40)} -> =MMS_Dairy_AtmosphericDeposition_Equations.VEERG_4_3_1_5__2_TotalNitrogenVolatilisedFromMMS
A8: =HYPERLINK("#'Input - Site'!A1", "Site") -> Site
A9: =HYPERLINK("#'Input - Dairy'!A1", "Dairy") -> Dairy
D10: Variable | E10: {=MMS_Dairy_AtmosphericDeposition_Equations.VEERG_4_3_1_5__2_TotalNitrogenVolatilisedFromMMS_Variable()} -> MN_ATMOS
A11: CALCULATIONS | D11: Unit | E11: {=MMS_Dairy_AtmosphericDeposition_Equations.VEERG_4_3_1_5__2_TotalNitrogenVolatilisedFromMMS_Unit()} -> kg N
A12: =HYPERLINK("#'4.3.1.1-2 Methane'!A1", "4.3.1.1-2 Methane") -> 4.3.1.1-2 Methane
A13: =HYPERLINK("#'4.3.1.3-4 Direct N20'!A1", "4.3.1.3-4 Direct N2O") -> 4.3.1.3-4 Direct N2O | D13: {=_xlfn.CHOOSECOLS(MMS_Dairy_AtmosphericDeposition_Equations.VEERG_4_3_1_5__2_TotalNitrogenVolatilisedFromMMS_Arguments(),1,2)} -> MN_jm | E13: total nitrogen in each MMS for dairy cattle classes | G13: {=_xlfn.CHOOSECOLS(MMS_Dairy_AtmosphericDeposition_Equations.VEERG_4_3_1_5__2_TotalNitrogenVolatilisedFromMMS_Arguments(),3,4)} -> kg N | H13: Calculated from 4.3.1.3 (2) | I13: {=HYPERLINK(Common_InputFunctions.Utility_SourceHyperlink(D$16),D$16)} -> M1_Table_MN_j_m
A14: =HYPERLINK("#'4.3.1.5 Atmos Deposition'!A1", "4.3.1.5 Atmospheric deposition") -> 4.3.1.5 Atmospheric deposition | D14: FracGASM_m | E14: fraction of N volatilised from MMS | G14: fraction | H14: Constant | I14: {=HYPERLINK(Common_InputFunctions.Utility_SourceHyperlink($D$28),$D$28)} -> Table_FracGASM_m
A15: =HYPERLINK("#'4.3.1.6-7 Leaching and runoff'!A1", "4.3.1.6-7 Leaching and runoff") -> 4.3.1.6-7 Leaching and runoff
A16: =HYPERLINK("#'4.3.1.8 Manure applied to soils'!A1", "4.3.1.8 Manure applied to soils") -> 4.3.1.8 Manure applied to soils | D16: M1_Table_MN_j_m | O16: M2_Table_MN_j_m
A17: =HYPERLINK("#'4.3.1.9 Soil direct N2O'!A1", "4.3.1.9 Soil direct N2O") -> 4.3.1.9 Soil direct N2O | D17: Total nitrogen in each MMS (Method 1) | O17: Total nitrogen in each MMS (Method 2)
A18: =HYPERLINK("#'4.3.1.10-11 Soil Atmos Dep'!A1", "4.3.1.10-11 Soil atm. deposition") -> 4.3.1.10-11 Soil atm. deposition | D18: Production system | E18: MMS | F18: Milking cows | G18: Heifers > 1 year | H18: Heifers < 1 year | I18: Bulls > 1 year | J18: Bulls < 1 year | O18: Production system | P18: MMS | Q18: Milking cows | R18: Heifers > 1 year | S18: Heifers < 1 year | T18: Bulls > 1 year | U18: Bulls < 1 year
A19: =HYPERLINK("#'4.3.1.12-13 Soil leach runoff'!A1", "4.3.1.12-13 Soil leach & runoff") -> 4.3.1.12-13 Soil leach & runoff | D19: =INDEX(X_Table_Dairy_ProductionSystems_Method1,3,1) -> Milking shed | E19: =INDEX(X_Table_Dairy_Stage1MMS_1_AnaerobicLagoon,2,1) -> Anaerobic lagoon | F19: =INDEX(M1_Table_MN_j_m,2,3) -> 468.93941 | G19: =INDEX(M1_Table_MN_j_m,2,4) -> 182.3579 | H19: =INDEX(M1_Table_MN_j_m,2,5) -> 72.631224 | I19: =INDEX(M1_Table_MN_j_m,2,6) -> 229.2311 | J19: =INDEX(M1_Table_MN_j_m,2,7) -> 95.962857 | K19: =$G$13 -> kg N | O19: =INDEX(X_Table_Dairy_ProductionSystems_Method1,3,1) -> Milking shed | P19: =INDEX(X_Table_Dairy_Stage1MMS_1_AnaerobicLagoon,2,1) -> Anaerobic lagoon | Q19: =INDEX(M2_Table_MN_j_m,2,3) -> 468.93941 | R19: =INDEX(M2_Table_MN_j_m,2,4) -> 182.3579 | S19: =INDEX(M2_Table_MN_j_m,2,5) -> 72.631224 | T19: =INDEX(M2_Table_MN_j_m,2,6) -> 229.2311 | U19: =INDEX(M2_Table_MN_j_m,2,7) -> 95.962857 | V19: =$G$13 -> kg N
D20: =INDEX(X_Table_Dairy_ProductionSystems_Method1,3,1) -> Milking shed | E20: =INDEX(X_Table_Dairy_Stage1MMS_1_SumpAndDispersal,2,1) -> Sump and dispersal system | F20: =INDEX(M1_Table_MN_j_m,3,3) -> 468.93941 | G20: =INDEX(M1_Table_MN_j_m,3,4) -> 182.3579 | H20: =INDEX(M1_Table_MN_j_m,3,5) -> 72.631224 | I20: =INDEX(M1_Table_MN_j_m,3,6) -> 229.2311 | J20: =INDEX(M1_Table_MN_j_m,3,7) -> 95.962857 | O20: =INDEX(X_Table_Dairy_ProductionSystems_Method1,3,1) -> Milking shed | P20: =INDEX(X_Table_Dairy_Stage1MMS_1_SumpAndDispersal,2,1) -> Sump and dispersal system | Q20: =INDEX(M2_Table_MN_j_m,3,3) -> 468.93941 | R20: =INDEX(M2_Table_MN_j_m,3,4) -> 182.3579 | S20: =INDEX(M2_Table_MN_j_m,3,5) -> 72.631224 | T20: =INDEX(M2_Table_MN_j_m,3,6) -> 229.2311 | U20: =INDEX(M2_Table_MN_j_m,3,7) -> 95.962857
A21: APPENDICES | D21: =INDEX(X_Table_Dairy_ProductionSystems_Method1,3,1) -> Milking shed | E21: =INDEX(X_Table_Dairy_Stage1MMS_1_DrainsToPaddock,2,1) -> Drains to paddock | F21: =INDEX(M1_Table_MN_j_m,4,3) -> 468.93941 | G21: =INDEX(M1_Table_MN_j_m,4,4) -> 182.3579 | H21: =INDEX(M1_Table_MN_j_m,4,5) -> 72.631224 | I21: =INDEX(M1_Table_MN_j_m,4,6) -> 229.2311 | J21: =INDEX(M1_Table_MN_j_m,4,7) -> 95.962857 | O21: =INDEX(X_Table_Dairy_ProductionSystems_Method1,3,1) -> Milking shed | P21: =INDEX(X_Table_Dairy_Stage1MMS_1_DrainsToPaddock,2,1) -> Drains to paddock | Q21: =INDEX(M2_Table_MN_j_m,4,3) -> 468.93941 | R21: =INDEX(M2_Table_MN_j_m,4,4) -> 182.3579 | S21: =INDEX(M2_Table_MN_j_m,4,5) -> 72.631224 | T21: =INDEX(M2_Table_MN_j_m,4,6) -> 229.2311 | U21: =INDEX(M2_Table_MN_j_m,4,7) -> 95.962857
A22: =HYPERLINK("#'Constants - Dairy'!A1", "Constants - Dairy") -> Constants - Dairy | D22: =INDEX(X_Table_Dairy_ProductionSystems_Method1,3,1) -> Milking shed | E22: Solid storage | F22: =INDEX(M1_Table_MN_j_m,5,3) -> 937.87882 | G22: =INDEX(M1_Table_MN_j_m,5,4) -> 364.71581 | H22: =INDEX(M1_Table_MN_j_m,5,5) -> 145.26245 | I22: =INDEX(M1_Table_MN_j_m,5,6) -> 458.46219 | J22: =INDEX(M1_Table_MN_j_m,5,7) -> 191.92571 | O22: =INDEX(X_Table_Dairy_ProductionSystems_Method1,3,1) -> Milking shed | P22: Solid storage | Q22: =INDEX(M2_Table_MN_j_m,5,3) -> 937.87882 | R22: =INDEX(M2_Table_MN_j_m,5,4) -> 364.71581 | S22: =INDEX(M2_Table_MN_j_m,5,5) -> 145.26245 | T22: =INDEX(M2_Table_MN_j_m,5,6) -> 458.46219 | U22: =INDEX(M2_Table_MN_j_m,5,7) -> 191.92571
A23: =HYPERLINK("#'Constants - Livestock'!A1", "Constants - Livestock") -> Constants - Livestock | D23: =INDEX(X_Table_Dairy_ProductionSystems_Method1,4,1) -> Feed pad | E23: =INDEX(X_Table_Dairy_Stage1MMS_2_AnaerobicLagoon,2,1) -> Anaerobic lagoon | F23: =INDEX(M1_Table_MN_j_m,6,3) -> 1897.0731 | G23: =INDEX(M1_Table_MN_j_m,6,4) -> 737.72061 | H23: =INDEX(M1_Table_MN_j_m,6,5) -> 293.82632 | I23: =INDEX(M1_Table_MN_j_m,6,6) -> 927.34398 | J23: =INDEX(M1_Table_MN_j_m,6,7) -> 388.21338 | O23: =INDEX(X_Table_Dairy_ProductionSystems_Method1,4,1) -> Feed pad | P23: =INDEX(X_Table_Dairy_Stage1MMS_2_AnaerobicLagoon,2,1) -> Anaerobic lagoon | Q23: =INDEX(M2_Table_MN_j_m,6,3) -> 1897.0731 | R23: =INDEX(M2_Table_MN_j_m,6,4) -> 737.72061 | S23: =INDEX(M2_Table_MN_j_m,6,5) -> 293.82632 | T23: =INDEX(M2_Table_MN_j_m,6,6) -> 927.34398 | U23: =INDEX(M2_Table_MN_j_m,6,7) -> 388.21338
A24: =HYPERLINK("#'Constants - Common'!A1", "Constants - Common") -> Constants - Common | D24: =INDEX(X_Table_Dairy_ProductionSystems_Method1,4,1) -> Feed pad | E24: =INDEX(X_Table_Dairy_Stage1MMS_2_SumpAndDispersal,2,1) -> Sump and dispersal system | F24: =INDEX(M1_Table_MN_j_m,7,3) -> 1517.6584 | G24: =INDEX(M1_Table_MN_j_m,7,4) -> 590.17649 | H24: =INDEX(M1_Table_MN_j_m,7,5) -> 235.06105 | I24: =INDEX(M1_Table_MN_j_m,7,6) -> 741.87518 | J24: =INDEX(M1_Table_MN_j_m,7,7) -> 310.5707 | O24: =INDEX(X_Table_Dairy_ProductionSystems_Method1,4,1) -> Feed pad | P24: =INDEX(X_Table_Dairy_Stage1MMS_2_SumpAndDispersal,2,1) -> Sump and dispersal system | Q24: =INDEX(M2_Table_MN_j_m,7,3) -> 1517.6584 | R24: =INDEX(M2_Table_MN_j_m,7,4) -> 590.17649 | S24: =INDEX(M2_Table_MN_j_m,7,5) -> 235.06105 | T24: =INDEX(M2_Table_MN_j_m,7,6) -> 741.87518 | U24: =INDEX(M2_Table_MN_j_m,7,7) -> 310.5707
A25: =HYPERLINK("#'Acknowledgements'!A1", "Acknowledgements") -> Acknowledgements | D25: =INDEX(X_Table_Dairy_ProductionSystems_Method1,4,1) -> Feed pad | E25: =INDEX(X_Table_Dairy_Stage1MMS_2_DrainsToPaddock,2,1) -> Drains to paddock | F25: =INDEX(M1_Table_MN_j_m,8,3) -> 1517.6584 | G25: =INDEX(M1_Table_MN_j_m,8,4) -> 590.17649 | H25: =INDEX(M1_Table_MN_j_m,8,5) -> 235.06105 | I25: =INDEX(M1_Table_MN_j_m,8,6) -> 741.87518 | J25: =INDEX(M1_Table_MN_j_m,8,7) -> 310.5707 | O25: =INDEX(X_Table_Dairy_ProductionSystems_Method1,4,1) -> Feed pad | P25: =INDEX(X_Table_Dairy_Stage1MMS_2_DrainsToPaddock,2,1) -> Drains to paddock | Q25: =INDEX(M2_Table_MN_j_m,8,3) -> 1517.6584 | R25: =INDEX(M2_Table_MN_j_m,8,4) -> 590.17649 | S25: =INDEX(M2_Table_MN_j_m,8,5) -> 235.06105 | T25: =INDEX(M2_Table_MN_j_m,8,6) -> 741.87518 | U25: =INDEX(M2_Table_MN_j_m,8,7) -> 310.5707
D26: =INDEX(X_Table_Dairy_ProductionSystems_Method1,4,1) -> Feed pad | E26: Solid storage | F26: =INDEX(M1_Table_MN_j_m,9,3) -> 2655.9023 | G26: =INDEX(M1_Table_MN_j_m,9,4) -> 1032.8088 | H26: =INDEX(M1_Table_MN_j_m,9,5) -> 411.35684 | I26: =INDEX(M1_Table_MN_j_m,9,6) -> 1298.2816 | J26: =INDEX(M1_Table_MN_j_m,9,7) -> 543.49873 | O26: =INDEX(X_Table_Dairy_ProductionSystems_Method1,4,1) -> Feed pad | P26: Solid storage | Q26: =INDEX(M2_Table_MN_j_m,9,3) -> 2655.9023 | R26: =INDEX(M2_Table_MN_j_m,9,4) -> 1032.8088 | S26: =INDEX(M2_Table_MN_j_m,9,5) -> 411.35684 | T26: =INDEX(M2_Table_MN_j_m,9,6) -> 1298.2816 | U26: =INDEX(M2_Table_MN_j_m,9,7) -> 543.49873
D28: Table_FracGASM_m
D29: Fraction N volatilised from each MS
D30: MMS | E30: FracGASMm
D31: {=Table_SourceData_Dairy_EFmFracGASM[NIR reference]} -> Pasture range and paddock | E31: {=Table_SourceData_Dairy_EFmFracGASM[FracGASMm]} -> 0 | F31: =G14 -> fraction
D32: Anaerobic lagoon | E32: 0.35
D33: Sump and dispersal system | E33: 0.07
D34: Drains to paddock | E34: 0.2
D35: Solid storage | E35: 0.3
D37: M1_Table_MN_atmos | O37: M2_Table_MN_atmos
D38: Total nitrogen volatilised from each MMS (Method 1) | O38: Total nitrogen volatilised from each MMS (Method 2)
D39: Production system | E39: MMS | F39: Milking cows | G39: Heifers > 1 year | H39: Heifers < 1 year | I39: Bulls > 1 year | J39: Bulls < 1 year | O39: Production system | P39: MMS | Q39: Milking cows | R39: Heifers > 1 year | S39: Heifers < 1 year | T39: Bulls > 1 year | U39: Bulls < 1 year
D40: =INDEX(X_Table_Dairy_ProductionSystems_Method1,3,1) -> Milking shed | E40: =INDEX(X_Table_Dairy_Stage1MMS_1_AnaerobicLagoon,2,1) -> Anaerobic lagoon | F40: {=MMS_Dairy_AtmosphericDeposition_Equations.VEERG_4_3_1_5__2_TotalNitrogenVolatilisedFromMMS(F19,$E32)} -> 164.12879 | G40: {=MMS_Dairy_AtmosphericDeposition_Equations.VEERG_4_3_1_5__2_TotalNitrogenVolatilisedFromMMS(G19,$E32)} -> 63.825266 | H40: {=MMS_Dairy_AtmosphericDeposition_Equations.VEERG_4_3_1_5__2_TotalNitrogenVolatilisedFromMMS(H19,$E32)} -> 25.420928 | I40: {=MMS_Dairy_AtmosphericDeposition_Equations.VEERG_4_3_1_5__2_TotalNitrogenVolatilisedFromMMS(I19,$E32)} -> 80.230884 | J40: {=MMS_Dairy_AtmosphericDeposition_Equations.VEERG_4_3_1_5__2_TotalNitrogenVolatilisedFromMMS(J19,$E32)} -> 33.587 | K40: =$E$11 -> kg N | O40: =INDEX(X_Table_Dairy_ProductionSystems_Method1,3,1) -> Milking shed | P40: =INDEX(X_Table_Dairy_Stage1MMS_1_AnaerobicLagoon,2,1) -> Anaerobic lagoon | Q40: {=MMS_Dairy_AtmosphericDeposition_Equations.VEERG_4_3_1_5__2_TotalNitrogenVolatilisedFromMMS(Q19,$E32)} -> 164.12879 | R40: {=MMS_Dairy_AtmosphericDeposition_Equations.VEERG_4_3_1_5__2_TotalNitrogenVolatilisedFromMMS(R19,$E32)} -> 63.825266 | S40: {=MMS_Dairy_AtmosphericDeposition_Equations.VEERG_4_3_1_5__2_TotalNitrogenVolatilisedFromMMS(S19,$E32)} -> 25.420928 | T40: {=MMS_Dairy_AtmosphericDeposition_Equations.VEERG_4_3_1_5__2_TotalNitrogenVolatilisedFromMMS(T19,$E32)} -> 80.230884 | U40: {=MMS_Dairy_AtmosphericDeposition_Equations.VEERG_4_3_1_5__2_TotalNitrogenVolatilisedFromMMS(U19,$E32)} -> 33.587 | V40: =$E$11 -> kg N
D41: =INDEX(X_Table_Dairy_ProductionSystems_Method1,3,1) -> Milking shed | E41: =INDEX(X_Table_Dairy_Stage1MMS_1_SumpAndDispersal,2,1) -> Sump and dispersal system | F41: {=MMS_Dairy_AtmosphericDeposition_Equations.VEERG_4_3_1_5__2_TotalNitrogenVolatilisedFromMMS(F20,$E33)} -> 32.825759 | G41: {=MMS_Dairy_AtmosphericDeposition_Equations.VEERG_4_3_1_5__2_TotalNitrogenVolatilisedFromMMS(G20,$E33)} -> 12.765053 | H41: {=MMS_Dairy_AtmosphericDeposition_Equations.VEERG_4_3_1_5__2_TotalNitrogenVolatilisedFromMMS(H20,$E33)} -> 5.0841857 | I41: {=MMS_Dairy_AtmosphericDeposition_Equations.VEERG_4_3_1_5__2_TotalNitrogenVolatilisedFromMMS(I20,$E33)} -> 16.046177 | J41: {=MMS_Dairy_AtmosphericDeposition_Equations.VEERG_4_3_1_5__2_TotalNitrogenVolatilisedFromMMS(J20,$E33)} -> 6.7174 | O41: =INDEX(X_Table_Dairy_ProductionSystems_Method1,3,1) -> Milking shed | P41: =INDEX(X_Table_Dairy_Stage1MMS_1_SumpAndDispersal,2,1) -> Sump and dispersal system | Q41: {=MMS_Dairy_AtmosphericDeposition_Equations.VEERG_4_3_1_5__2_TotalNitrogenVolatilisedFromMMS(Q20,$E33)} -> 32.825759 | R41: {=MMS_Dairy_AtmosphericDeposition_Equations.VEERG_4_3_1_5__2_TotalNitrogenVolatilisedFromMMS(R20,$E33)} -> 12.765053 | S41: {=MMS_Dairy_AtmosphericDeposition_Equations.VEERG_4_3_1_5__2_TotalNitrogenVolatilisedFromMMS(S20,$E33)} -> 5.0841857 | T41: {=MMS_Dairy_AtmosphericDeposition_Equations.VEERG_4_3_1_5__2_TotalNitrogenVolatilisedFromMMS(T20,$E33)} -> 16.046177 | U41: {=MMS_Dairy_AtmosphericDeposition_Equations.VEERG_4_3_1_5__2_TotalNitrogenVolatilisedFromMMS(U20,$E33)} -> 6.7174
D42: =INDEX(X_Table_Dairy_ProductionSystems_Method1,3,1) -> Milking shed | E42: =INDEX(X_Table_Dairy_Stage1MMS_1_DrainsToPaddock,2,1) -> Drains to paddock | F42: {=MMS_Dairy_AtmosphericDeposition_Equations.VEERG_4_3_1_5__2_TotalNitrogenVolatilisedFromMMS(F21,$E34)} -> 93.787882 | G42: {=MMS_Dairy_AtmosphericDeposition_Equations.VEERG_4_3_1_5__2_TotalNitrogenVolatilisedFromMMS(G21,$E34)} -> 36.471581 | H42: {=MMS_Dairy_AtmosphericDeposition_Equations.VEERG_4_3_1_5__2_TotalNitrogenVolatilisedFromMMS(H21,$E34)} -> 14.526245 | I42: {=MMS_Dairy_AtmosphericDeposition_Equations.VEERG_4_3_1_5__2_TotalNitrogenVolatilisedFromMMS(I21,$E34)} -> 45.846219 | J42: {=MMS_Dairy_AtmosphericDeposition_Equations.VEERG_4_3_1_5__2_TotalNitrogenVolatilisedFromMMS(J21,$E34)} -> 19.192571 | O42: =INDEX(X_Table_Dairy_ProductionSystems_Method1,3,1) -> Milking shed | P42: =INDEX(X_Table_Dairy_Stage1MMS_1_DrainsToPaddock,2,1) -> Drains to paddock | Q42: {=MMS_Dairy_AtmosphericDeposition_Equations.VEERG_4_3_1_5__2_TotalNitrogenVolatilisedFromMMS(Q21,$E34)} -> 93.787882 | R42: {=MMS_Dairy_AtmosphericDeposition_Equations.VEERG_4_3_1_5__2_TotalNitrogenVolatilisedFromMMS(R21,$E34)} -> 36.471581 | S42: {=MMS_Dairy_AtmosphericDeposition_Equations.VEERG_4_3_1_5__2_TotalNitrogenVolatilisedFromMMS(S21,$E34)} -> 14.526245 | T42: {=MMS_Dairy_AtmosphericDeposition_Equations.VEERG_4_3_1_5__2_TotalNitrogenVolatilisedFromMMS(T21,$E34)} -> 45.846219 | U42: {=MMS_Dairy_AtmosphericDeposition_Equations.VEERG_4_3_1_5__2_TotalNitrogenVolatilisedFromMMS(U21,$E34)} -> 19.192571
D43: =INDEX(X_Table_Dairy_ProductionSystems_Method1,3,1) -> Milking shed | E43: Solid storage | F43: {=MMS_Dairy_AtmosphericDeposition_Equations.VEERG_4_3_1_5__2_TotalNitrogenVolatilisedFromMMS(F22,$E35)} -> 281.36365 | G43: {=MMS_Dairy_AtmosphericDeposition_Equations.VEERG_4_3_1_5__2_TotalNitrogenVolatilisedFromMMS(G22,$E35)} -> 109.41474 | H43: {=MMS_Dairy_AtmosphericDeposition_Equations.VEERG_4_3_1_5__2_TotalNitrogenVolatilisedFromMMS(H22,$E35)} -> 43.578734 | I43: {=MMS_Dairy_AtmosphericDeposition_Equations.VEERG_4_3_1_5__2_TotalNitrogenVolatilisedFromMMS(I22,$E35)} -> 137.53866 | J43: {=MMS_Dairy_AtmosphericDeposition_Equations.VEERG_4_3_1_5__2_TotalNitrogenVolatilisedFromMMS(J22,$E35)} -> 57.577714 | O43: =INDEX(X_Table_Dairy_ProductionSystems_Method1,3,1) -> Milking shed | P43: Solid storage | Q43: {=MMS_Dairy_AtmosphericDeposition_Equations.VEERG_4_3_1_5__2_TotalNitrogenVolatilisedFromMMS(Q22,$E35)} -> 281.36365 | R43: {=MMS_Dairy_AtmosphericDeposition_Equations.VEERG_4_3_1_5__2_TotalNitrogenVolatilisedFromMMS(R22,$E35)} -> 109.41474 | S43: {=MMS_Dairy_AtmosphericDeposition_Equations.VEERG_4_3_1_5__2_TotalNitrogenVolatilisedFromMMS(S22,$E35)} -> 43.578734 | T43: {=MMS_Dairy_AtmosphericDeposition_Equations.VEERG_4_3_1_5__2_TotalNitrogenVolatilisedFromMMS(T22,$E35)} -> 137.53866 | U43: {=MMS_Dairy_AtmosphericDeposition_Equations.VEERG_4_3_1_5__2_TotalNitrogenVolatilisedFromMMS(U22,$E35)} -> 57.577714
...

Sheet 4.3.1.6-7 Leaching and runoff
A1: #VALUE! | C1: 4.1.1.6-7 Manure leaching and runoff
A3: =HYPERLINK("#'Home'!A1", "Home") -> Home | D3: Method 1 | O3: Method 2
A4: =HYPERLINK("#'Overview'!A1", "Overview") -> Overview
A5: =HYPERLINK("#'Results'!A1", "Results") -> Results | D5: {=MMS_Dairy_LeachingAndRunoff_Equations.VEERG_4_3_1_6__2_MassOfNitrogenLostToLeachingAndRunoffFromSolidStorage_Title()} -> Mass of nitrogen lost to leaching and runoff from solid storage systems
D6: {=MMS_Dairy_LeachingAndRunoff_Equations.VEERG_4_3_1_6__2_MassOfNitrogenLostToLeachingAndRunoffFromSolidStorage_Source()} -> VEERG 2026: 4.3.1.6, Equation (2)
