Workbook
Name _Toc225350871: '5.4.1.1-4 Atmos deposition'!$C$1
Name _Toc225350871: '5.5.1.1-2 Leaching and runoff'!$C$1
Name AgResidue_Equations_CropResidue.VEERG_6_1_1_1__1__NitrousOxideEmissionsFromCropResidues: _xlfn.LAMBDA(_xlpm.M_c,_xlpm.EF_Ni,_xlpm.C_N2O, _xlpm.M_c * _xlpm.EF_Ni * _xlpm.C_N2O * 10 ^ (-3))
Name AgResidue_Equations_CropResidue.VEERG_6_1_1_1__1__NitrousOxideEmissionsFromCropResidues_FunctionName: _xlfn.LAMBDA("VEERG_6_1_1_1__1__NitrousOxideEmissionsFromCropResidues")
Name AgResidue_Equations_CropResidue.VEERG_6_1_1_1__1__NitrousOxideEmissionsFromCropResidues_LatexEquation: _xlfn.LAMBDA("E=\sum\nolimits_c\left(M_{c}\times EF_{N}\right)\times C_{g,N2O}\times 10^{-3}")
Name AgResidue_Equations_CropResidue.VEERG_6_1_1_1__1__NitrousOxideEmissionsFromCropResidues_NIRReference: _xlfn.LAMBDA("")
Name AgResidue_Equations_CropResidue.VEERG_6_1_1_1__1__NitrousOxideEmissionsFromCropResidues_Source: _xlfn.LAMBDA("VEERG 2026: 6.1.1.1, Equation (1)")
Name AgResidue_Equations_CropResidue.VEERG_6_1_1_1__1__NitrousOxideEmissionsFromCropResidues_Title: _xlfn.LAMBDA("Nitrous oxide emissions from the return of crop residues across all crops c to the soil")
Name AgResidue_Equations_CropResidue.VEERG_6_1_1_1__1__NitrousOxideEmissionsFromCropResidues_Unit: _xlfn.LAMBDA("t N2O")
Name AgResidue_Equations_CropResidue.VEERG_6_1_1_1__1__NitrousOxideEmissionsFromCropResidues_Variable: _xlfn.LAMBDA("E")
Name AgResidue_Equations_CropResidue.VEERG_6_1_1_1__2__MassOfNitrogenInCropResidues_LatexEquation: _xlfn.LAMBDA("M_{c}=(P_{c}\times R_{AGc}\times(1-F_{c}-FFOD_{c})\times DM_{c}\times NC_{AGc})+(P_{c}\times R_{AGc}\times R_{BGc}\times DM_{c}\times NC_{BGc})")
Name AgResidue_Equations_CropResidue.VEERG_6_1_1_1__2__MassOfNitrogenInCropResidues_NIRReference: _xlfn.LAMBDA("")
Name AgResidue_Equations_CropResidue.VEERG_6_1_1_1__2__MassOfNitrogenInCropResidues_Source: _xlfn.LAMBDA("VEERG 2026: 6.1.1.1, Equation (2)")
Name AgResidue_Equations_CropResidue.VEERG_6_1_1_1__2__MassOfNitrogenInCropResidues_Title: _xlfn.LAMBDA("Mass of nitrogen in crop residues returned to the soil")
Name AgResidue_Equations_CropResidue.VEERG_6_1_1_1__2__MassOfNitrogenInCropResidues_Unit: _xlfn.LAMBDA("kg N")
Name AgResidue_Equations_CropResidue.VEERG_6_1_1_1__2__MassOfNitrogenInCropResidues_Variable: _xlfn.LAMBDA("M_c")
Name AgResidue_Equations_CropResidue.VEERG_6_1_1_2__1__FractionOfCropResidueRemovedBaled: _xlfn.LAMBDA(_xlpm.B,_xlpm.M_B,_xlpm.P_c,_xlpm.R_AGc, IFERROR((_xlpm.B * _xlpm.M_B) / (_xlpm.P_c * _xlpm.R_AGc), 0))
Name AgResidue_Equations_CropResidue.VEERG_6_1_1_2__1__FractionOfCropResidueRemovedBaled_LatexEquation: _xlfn.LAMBDA("FFOD_{c,baled}=\frac{B\times M_{B}}{P_{c}\times R_{AG,c}}")
Name AgResidue_Equations_CropResidue.VEERG_6_1_1_2__1__FractionOfCropResidueRemovedBaled_NIRReference: _xlfn.LAMBDA("")
Name AgResidue_Equations_CropResidue.VEERG_6_1_1_2__1__FractionOfCropResidueRemovedBaled_Source: _xlfn.LAMBDA("VEERG 2026: 6.1.1.2, Equation (1)")
Name AgResidue_Equations_CropResidue.VEERG_6_1_1_2__1__FractionOfCropResidueRemovedBaled_Title: _xlfn.LAMBDA("Fraction of crop residue that is removed for crop c, calculated where residues are baled")
Name AgResidue_Equations_CropResidue.VEERG_6_1_1_2__1__FractionOfCropResidueRemovedBaled_Unit: _xlfn.LAMBDA("dimensionless")
Name AgResidue_Equations_CropResidue.VEERG_6_1_1_2__1__FractionOfCropResidueRemovedBaled_Variable: _xlfn.LAMBDA("FFOD_cbaled")
Name AgResidue_Equations_CropResidue.VEERG_6_1_1_2__1__FractionOfCropResidueRemovedBaled_Variation: _xlfn.LAMBDA("VARIATION FROM SOURCE: Added 'baled' to variable subscript")
Name AgResidue_Equations_CropResidue.VEERG_6_1_1_2__1a__FractionOfCropResidueRemoved: _xlfn.LAMBDA(_xlpm.FFOD_cbaled,_xlpm.FFOD_cother, _xlpm.FFOD_cbaled + _xlpm.FFOD_cother)
Name AgResidue_Equations_CropResidue.VEERG_6_1_1_2__1a__FractionOfCropResidueRemoved_LatexEquation: _xlfn.LAMBDA("FFOD_{c} = FFOD_{c,baled} + FFOD_{c,other}")
Name AgResidue_Equations_CropResidue.VEERG_6_1_1_2__1a__FractionOfCropResidueRemoved_NIRReference: _xlfn.LAMBDA("")
Name AgResidue_Equations_CropResidue.VEERG_6_1_1_2__1a__FractionOfCropResidueRemoved_Source: _xlfn.LAMBDA("")
Name AgResidue_Equations_CropResidue.VEERG_6_1_1_2__1a__FractionOfCropResidueRemoved_Title: _xlfn.LAMBDA("Fraction of crop residue that is removed for crop c")
Name AgResidue_Equations_CropResidue.VEERG_6_1_1_2__1a__FractionOfCropResidueRemoved_Unit: _xlfn.LAMBDA("dimensionless")
Name AgResidue_Equations_CropResidue.VEERG_6_1_1_2__1a__FractionOfCropResidueRemoved_Variable: _xlfn.LAMBDA("FFOD_c")
Name AgResidue_Equations_CropResidue.VEERG_6_1_1_2__1a__FractionOfCropResidueRemoved_Variation: _xlfn.LAMBDA("VARIATION FROM SOURCE: Added this equation to accommodate user-defined residue removal other than baling.")
Name AgResidue_Equations_FieldBurning.VEERG_6_4_1_1__1__MethaneEmissionsFromBurningOfCropResidues: _xlfn.LAMBDA(_xlpm.M_burnc,_xlpm.CC_c,_xlpm.EF_CH4,_xlpm.C_CH4, (_xlpm.M_burnc * _xlpm.CC_c) * _xlpm.EF_CH4 * _xlpm.C_CH4 * 10 ^ (-3))
Name AgResidue_Equations_FieldBurning.VEERG_6_4_1_1__1__MethaneEmissionsFromBurningOfCropResidues: _xlfn.LAMBDA(_xlpm.M_burnc,_xlpm.CC_c,_xlpm.EF_CH4,_xlpm.C_CH4, (_xlpm.M_burnc * _xlpm.CC_c) * _xlpm.EF_CH4 * _xlpm.C_CH4 * 10 ^ (-3))
Name AgResidue_Equations_FieldBurning.VEERG_6_4_1_1__1__MethaneEmissionsFromBurningOfCropResidues: _xlfn.LAMBDA(_xlpm.M_burnc,_xlpm.CC_c,_xlpm.EF_CH4,_xlpm.C_CH4, (_xlpm.M_burnc * _xlpm.CC_c) * _xlpm.EF_CH4 * _xlpm.C_CH4 * 10 ^ (-3))
Name AgResidue_Equations_FieldBurning.VEERG_6_4_1_1__1__MethaneEmissionsFromBurningOfCropResidues: _xlfn.LAMBDA(_xlpm.M_burnc,_xlpm.CC_c,_xlpm.EF_CH4,_xlpm.C_CH4, (_xlpm.M_burnc * _xlpm.CC_c) * _xlpm.EF_CH4 * _xlpm.C_CH4 * 10 ^ (-3))
Name AgResidue_Equations_FieldBurning.VEERG_6_4_1_1__1__MethaneEmissionsFromBurningOfCropResidues: _xlfn.LAMBDA(_xlpm.Mburnc,_xlpm.CCc,_xlpm.EFCH4,_xlpm.C_CH4, _xlpm.Mburnc * _xlpm.CCc * _xlpm.EFCH4 * _xlpm.C_CH4 * 10 ^ (-3))
Name AgResidue_Equations_FieldBurning.VEERG_6_4_1_1__1__MethaneEmissionsFromBurningOfCropResidues_FunctionName: _xlfn.LAMBDA("VEERG_6_4_1_1__1__MethaneEmissionsFromBurningOfCropResidues")
Name AgResidue_Equations_FieldBurning.VEERG_6_4_1_1__1__MethaneEmissionsFromBurningOfCropResidues_LatexEquation: _xlfn.LAMBDA("E_{CH4}=\sum\nolimits_c(M_{burn,c}\times CC_{c})\times EF_{CH4}\times C_{CH4}\times 10^{-3}")
Name AgResidue_Equations_FieldBurning.VEERG_6_4_1_1__1__MethaneEmissionsFromBurningOfCropResidues_LatexEquation: _xlfn.LAMBDA("E_{CH4}=\sum\nolimits_c(M_{burn,c}\times CC_{c})\times EF_{CH4}\times C_{CH4}\times 10^{-3}")
Name AgResidue_Equations_FieldBurning.VEERG_6_4_1_1__1__MethaneEmissionsFromBurningOfCropResidues_LatexEquation: _xlfn.LAMBDA("E_{CH4}=\sum\nolimits_c(M_{burn,c}\times CC_{c})\times EF_{CH4}\times C_{CH4}\times 10^{-3}")
Name AgResidue_Equations_FieldBurning.VEERG_6_4_1_1__1__MethaneEmissionsFromBurningOfCropResidues_LatexEquation: _xlfn.LAMBDA("E_{CH4}=\sum\nolimits_c(M_{burn,c}\times CC_{c})\times EF_{CH4}\times C_{CH4}\times 10^{-3}")
Name AgResidue_Equations_FieldBurning.VEERG_6_4_1_1__1__MethaneEmissionsFromBurningOfCropResidues_LatexEquation: _xlfn.LAMBDA("E_{CH4}=\sum_{c}(M_{burn,c}\times CC_{c}\times EF_{CH4}\times C_{CH4}\times 10^{-3})")
Name AgResidue_Equations_FieldBurning.VEERG_6_4_1_1__1__MethaneEmissionsFromBurningOfCropResidues_NIRReference: _xlfn.LAMBDA("")
Name AgResidue_Equations_FieldBurning.VEERG_6_4_1_1__1__MethaneEmissionsFromBurningOfCropResidues_Source: _xlfn.LAMBDA("VEERG 2026: 6.4.1.1, Equation (1)")
Name AgResidue_Equations_FieldBurning.VEERG_6_4_1_1__1__MethaneEmissionsFromBurningOfCropResidues_Title: _xlfn.LAMBDA("Methane emissions from the burning of crop residues")
Name AgResidue_Equations_FieldBurning.VEERG_6_4_1_1__1__MethaneEmissionsFromBurningOfCropResidues_Unit: _xlfn.LAMBDA("t CH4")
Name AgResidue_Equations_FieldBurning.VEERG_6_4_1_1__1__MethaneEmissionsFromBurningOfCropResidues_Variable: _xlfn.LAMBDA("ECH4")
Name AgResidue_Equations_FieldBurning.VEERG_6_4_1_1__2__NitrousOxideEmissionsFromBurningOfCropResidues: _xlfn.LAMBDA(_xlpm.M_burnc,_xlpm.NC_AGc,_xlpm.EF_N2O,_xlpm.C_N2O, (_xlpm.M_burnc * _xlpm.NC_AGc) * _xlpm.EF_N2O * _xlpm.C_N2O * 10 ^ (-3))
Name AgResidue_Equations_FieldBurning.VEERG_6_4_1_1__2__NitrousOxideEmissionsFromBurningOfCropResidues: _xlfn.LAMBDA(_xlpm.M_burnc,_xlpm.NC_AGc,_xlpm.EF_N2O,_xlpm.C_N2O, (_xlpm.M_burnc * _xlpm.NC_AGc) * _xlpm.EF_N2O * _xlpm.C_N2O * 10 ^ (-3))
Name AgResidue_Equations_FieldBurning.VEERG_6_4_1_1__2__NitrousOxideEmissionsFromBurningOfCropResidues: _xlfn.LAMBDA(_xlpm.M_burnc,_xlpm.NC_AGc,_xlpm.EF_N2O,_xlpm.C_N2O, (_xlpm.M_burnc * _xlpm.NC_AGc) * _xlpm.EF_N2O * _xlpm.C_N2O * 10 ^ (-3))
Name AgResidue_Equations_FieldBurning.VEERG_6_4_1_1__2__NitrousOxideEmissionsFromBurningOfCropResidues: _xlfn.LAMBDA(_xlpm.M_burnc,_xlpm.NC_AGc,_xlpm.EF_N2O,_xlpm.C_N2O, (_xlpm.M_burnc * _xlpm.NC_AGc) * _xlpm.EF_N2O * _xlpm.C_N2O * 10 ^ (-3))
Name AgResidue_Equations_FieldBurning.VEERG_6_4_1_1__2__NitrousOxideEmissionsFromBurningOfCropResidues: _xlfn.LAMBDA(_xlpm.Mburnc,_xlpm.NCAGc,_xlpm.EFN2O,_xlpm.CN2O, _xlpm.Mburnc * _xlpm.NCAGc * _xlpm.EFN2O * _xlpm.CN2O * 10 ^ (-3))
Name AgResidue_Equations_FieldBurning.VEERG_6_4_1_1__2__NitrousOxideEmissionsFromBurningOfCropResidues_FunctionName: _xlfn.LAMBDA("VEERG_6_4_1_1__2__NitrousOxideEmissionsFromBurningOfCropResidues")
Name AgResidue_Equations_FieldBurning.VEERG_6_4_1_1__2__NitrousOxideEmissionsFromBurningOfCropResidues_LatexEquation: _xlfn.LAMBDA("E_{N2O}=\sum\nolimits_c(M_{burn,c}\times NC_{AGc})\times EF_{N2O}\times C_{N2O}\times 10^{-3}")
Name AgResidue_Equations_FieldBurning.VEERG_6_4_1_1__2__NitrousOxideEmissionsFromBurningOfCropResidues_LatexEquation: _xlfn.LAMBDA("E_{N2O}=\sum\nolimits_c(M_{burn,c}\times NC_{AGc})\times EF_{N2O}\times C_{N2O}\times 10^{-3}")
Name AgResidue_Equations_FieldBurning.VEERG_6_4_1_1__2__NitrousOxideEmissionsFromBurningOfCropResidues_LatexEquation: _xlfn.LAMBDA("E_{N2O}=\sum\nolimits_c(M_{burn,c}\times NC_{AGc})\times EF_{N2O}\times C_{N2O}\times 10^{-3}")
Name AgResidue_Equations_FieldBurning.VEERG_6_4_1_1__2__NitrousOxideEmissionsFromBurningOfCropResidues_LatexEquation: _xlfn.LAMBDA("E_{N2O}=\sum\nolimits_c(M_{burn,c}\times NC_{AGc})\times EF_{N2O}\times C_{N2O}\times 10^{-3}")
Name AgResidue_Equations_FieldBurning.VEERG_6_4_1_1__2__NitrousOxideEmissionsFromBurningOfCropResidues_LatexEquation: _xlfn.LAMBDA("E_{N2O}=\sum_{c}(M_{burn,c}\times NC_{AGc}\times EF_{N2O}\times C_{N2O}\times 10^{-3})")
Name AgResidue_Equations_FieldBurning.VEERG_6_4_1_1__2__NitrousOxideEmissionsFromBurningOfCropResidues_NIRReference: _xlfn.LAMBDA("")

Sheet Home
A1: #VALUE!
A3: =HYPERLINK("#'Home'!A1", "Home") -> Home
A4: =HYPERLINK("#'Results'!A1", "Results") -> Results
A7: INPUTS
A8: =HYPERLINK("#'Input - Enterprise'!A1", "Enterprise") -> Enterprise
A9: =HYPERLINK("#'Input - Site'!A1", "Site") -> Site
A10: =HYPERLINK("#'Input - Pasture Beef'!A1", "Pasture Beef") -> Pasture Beef
A11: =HYPERLINK("#'Input - Pasture Beef (Enteric)'!A1", "Pasture Beef (Enteric)") -> Pasture Beef (Enteric)
A12: =HYPERLINK("#'Input - Pasture'!A1", "Pasture") -> Pasture
A13: =HYPERLINK("#'Input - Fertiliser'!A1", "Fertiliser") -> Fertiliser
A14: =HYPERLINK("#'Input - Fuel'!A1", "Fuel") -> Fuel
A15: =HYPERLINK("#'Input - Electricity'!A1", "Electricity") -> Electricity
A18: CALCULATIONS
A19: =HYPERLINK("#'3.2.1.1-2 Enteric Methane'!A1", "3.2.1.1-2 Enteric methane") -> 3.2.1.1-2 Enteric methane
A20: =HYPERLINK("#'4.2.1.1-2 Methane'!A1", "4.2.1.1-2 Manure methane") -> 4.2.1.1-2 Manure methane
A21: =HYPERLINK("#'4.2.1.3-4 Soil direct N20'!A1", "4.2.1.3-4 Soil direct N2O") -> 4.2.1.3-4 Soil direct N2O
A22: =HYPERLINK("#'4.2.1.5-6 Soil Atmos Dep'!A1", "4.2.1.5-6 Soil atm. deposition") -> 4.2.1.5-6 Soil atm. deposition
A23: =HYPERLINK("#'4.2.1.7-8 Soil leach runoff'!A1", "4.2.1.7-8 Soil leach & runoff") -> 4.2.1.7-8 Soil leach & runoff
A24: =HYPERLINK("#'5.1.1.1-2 Inorganic fert N2O'!A1", "5.1.1.1-2 Inorganic fert N2O") -> 5.1.1.1-2 Inorganic fert N2O
A25: =HYPERLINK("#'5.1.1.3-4 Inorganic fert CO2'!A1", "5.1.1.3-4 Inorganic fert CO2") -> 5.1.1.3-4 Inorganic fert CO2
A26: =HYPERLINK("#'5.2.1.1-2 Organic Fert N2O'!A1", "5.2.1.1-2 Organic fert N2O") -> 5.2.1.1-2 Organic fert N2O
A27: =HYPERLINK("#'5.3.1.1-2 Lime CO2'!A1", "5.3.1.1-2 Lime CO2") -> 5.3.1.1-2 Lime CO2
A28: =HYPERLINK("#'5.4.1.1-4 Atmos deposition'!A1", "5.4.1.1-4 Atmos. deposition") -> 5.4.1.1-4 Atmos. deposition
A29: =HYPERLINK("#'5.5.1.1-2 Leaching and runoff'!A1", "5.5.1.1-2 Leaching & runoff") -> 5.5.1.1-2 Leaching & runoff
A30: =HYPERLINK("#'6.2.1.1-2 Pasture residue N2O'!A1", "6.2.1.1-2 Pasture residue N2O") -> 6.2.1.1-2 Pasture residue N2O
A31: =HYPERLINK("#'6.3.1.1-2 Leach runoff pasture'!A1", "6.3.1.1-2 Leach & runoff (pasture)") -> 6.3.1.1-2 Leach & runoff (pasture)
A32: =HYPERLINK("#'8.1.1.1-2 Transport fuel'!A1", "8.1.1.1-2 Transport fuel") -> 8.1.1.1-2 Transport fuel
A33: =HYPERLINK("#'8.2.1.1-2 Stationary fuel'!A1", "8.2.1.1-2 Stationary fuel") -> 8.2.1.1-2 Stationary fuel
A34: =HYPERLINK("#'14.1.1-2 Purchased electricity'!A1", "14.1.1-2 Purchased electricity") -> 14.1.1-2 Purchased electricity
A37: APPENDICES
A38: =HYPERLINK("#'Constants - Pasture Beef'!A1", "Constants - Pasture Beef") -> Constants - Pasture Beef
A39: =HYPERLINK("#'Constants - Ag Residue'!A1", "Constants - Ag residue") -> Constants - Ag residue
A40: =HYPERLINK("#'Constants - Common Livestock'!A1", "Constants - Common Livestock") -> Constants - Common Livestock
A41: =HYPERLINK("#'Constants - Electricity'!A1", "Constants - Electricity") -> Constants - Electricity
A42: =HYPERLINK("#'Constants - Fertiliser'!A1", "Constants - Fertiliser") -> Constants - Fertiliser
A43: =HYPERLINK("#'Constants - Fuel'!A1", "Constants - Fuel") -> Constants - Fuel
A44: =HYPERLINK("#'Constants - Common'!A1", "Constants - Common") -> Constants - Common
A45: =HYPERLINK("#'Acknowledgements'!A1", "Acknowledgements") -> Acknowledgements
A46: =HYPERLINK("#'Overview'!A1", "Overview") -> Overview

Sheet Results
A1: #VALUE! | C1: 4.2 Manure management: Pasture Beef: Results
A3: =HYPERLINK("#'Home'!A1", "Home") -> Home
A4: =HYPERLINK("#'Results'!A1", "Results") -> Results | D4: ="Emissions breakdown for activities running between " & TEXT(X_Cell_Site_StartDate, "dd mmmm yyyy") & " and " & TEXT('Input - Enterprise'!E13, "dd mmmm yyyy") -> Emissions breakdown for activities running between 01 January 2025 and 31 December 2025
D6: Scope 1 source | E6: GHG emissions method 1 | F6: GHG emissions method 2 | G6: GHG Unit | H6: CO2-e emissions method 1 | I6: CO2-e emissions method 2
A7: INPUTS | D7: 3.2.1.1-2 Enteric methane | E7: {=VEERG_3_2_1_1__1_TotalAnnualMethaneFromEntericFermentation_Result_Method1} -> 54.595755 | F7: {=VEERG_3_2_1_1__1_TotalAnnualMethaneFromEntericFermentation_Result_Method2} -> 54.699182 | G7: t CH4 | H7: {=Common_Equations.Common_ConvertCH4ToCO2e(E7,_xlfn.XLOOKUP("CH4", Table_GWPData[Gas],Table_GWPData[CO2-e factor]))} -> 1528.6812 | I7: {=Common_Equations.Common_ConvertCH4ToCO2e(F7,_xlfn.XLOOKUP("CH4", Table_GWPData[Gas],Table_GWPData[CO2-e factor]))} -> 1531.5771 | J7: t CO2e
A8: =HYPERLINK("#'Input - Enterprise'!A1", "Enterprise") -> Enterprise | D8: 4.2.1.1-2 Manure methane | E8: {=VEERG_4_2_1_1__1_TotalAnnualMethaneProductionFromManureManagement_Result_Method1} -> 0.88628531 | F8: {=VEERG_4_2_1_1__1_TotalAnnualMethaneProductionFromManureManagement_Result_Method2} -> 0.87215903 | G8: t CH4 | H8: {=Common_Equations.Common_ConvertCH4ToCO2e(E8,_xlfn.XLOOKUP("CH4", Table_GWPData[Gas],Table_GWPData[CO2-e factor]))} -> 24.815989 | I8: {=Common_Equations.Common_ConvertCH4ToCO2e(F8,_xlfn.XLOOKUP("CH4", Table_GWPData[Gas],Table_GWPData[CO2-e factor]))} -> 24.420453 | J8: t CO2e
A9: =HYPERLINK("#'Input - Site'!A1", "Site") -> Site | D9: 4.2.1.3-4 Soil direct N2O | E9: {=VEERG_4_2_1_3__1_DirectNitrousOxideEmissionsOnPasture_Result_Method1} -> 0.19011253 | F9: {=VEERG_4_2_1_3__1_DirectNitrousOxideEmissionsOnPasture_Result_Method2} -> 0.18099391 | G9: t N2O | H9: {=Common_Equations.Common_ConvertN2OToCO2e(E9,_xlfn.XLOOKUP("N2O", Table_GWPData[Gas],Table_GWPData[CO2-e factor]))} -> 50.37982 | I9: {=Common_Equations.Common_ConvertN2OToCO2e(F9,_xlfn.XLOOKUP("N2O", Table_GWPData[Gas],Table_GWPData[CO2-e factor]))} -> 47.963385 | J9: t CO2e
A10: =HYPERLINK("#'Input - Pasture Beef'!A1", "Pasture Beef") -> Pasture Beef | D10: 4.2.1.5-6 Soil atmospheric deposition | E10: {=VEERG_4_2_1_5__1_AtmosphericDepositionEmissionsFromUrineAndDungOnPasture_Result_Method1} -> 0.11777471 | F10: {=VEERG_4_2_1_5__1_AtmosphericDepositionEmissionsFromUrineAndDungOnPasture_Result_Method2} -> 0.11212572 | G10: t N2O | H10: {=Common_Equations.Common_ConvertN2OToCO2e(E10,_xlfn.XLOOKUP("N2O", Table_GWPData[Gas],Table_GWPData[CO2-e factor]))} -> 31.210298 | I10: {=Common_Equations.Common_ConvertN2OToCO2e(F10,_xlfn.XLOOKUP("N2O", Table_GWPData[Gas],Table_GWPData[CO2-e factor]))} -> 29.713317 | J10: t CO2e
A11: =HYPERLINK("#'Input - Pasture Beef (Enteric)'!A1", "Pasture Beef (Enteric)") -> Pasture Beef (Enteric) | D11: 4.2.1.7-8 Soil leaching and runoff | E11: {=VEERG_4_2_1_7__1_LeachingAndRunoffEmissionsFromUrineAndDungOnPasture_Result_Method1} -> 0.25094854 | F11: {=VEERG_4_2_1_7__1_LeachingAndRunoffEmissionsFromUrineAndDungOnPasture_Result_Method2} -> 0.23891196 | G11: t N2O | H11: {=Common_Equations.Common_ConvertN2OToCO2e(E11,_xlfn.XLOOKUP("N2O", Table_GWPData[Gas],Table_GWPData[CO2-e factor]))} -> 66.501362 | I11: {=Common_Equations.Common_ConvertN2OToCO2e(F11,_xlfn.XLOOKUP("N2O", Table_GWPData[Gas],Table_GWPData[CO2-e factor]))} -> 63.311668 | J11: t CO2e
A12: =HYPERLINK("#'Input - Pasture'!A1", "Pasture") -> Pasture | D12: 5.1.1.1-2 Inorganic fert N2O | E12: {=VEERG_5_1_1_1__1_InorganicFertiliserApplicationN2OEmissions_Result_Method1} -> 0.1431067 | F12: {=VEERG_5_1_1_1__1_InorganicFertiliserApplicationN2OEmissions_Result_Method2} -> 0.1431067 | G12: t N2O | H12: {=Common_Equations.Common_ConvertN2OToCO2e(E12,_xlfn.XLOOKUP("N2O", Table_GWPData[Gas],Table_GWPData[CO2-e factor]))} -> 37.923276 | I12: {=Common_Equations.Common_ConvertN2OToCO2e(F12,_xlfn.XLOOKUP("N2O", Table_GWPData[Gas],Table_GWPData[CO2-e factor]))} -> 37.923276 | J12: t CO2e
A13: =HYPERLINK("#'Input - Fertiliser'!A1", "Fertiliser") -> Fertiliser | D13: 5.1.1.3-4 Inorganic fert CO2 | E13: {=VEERG_5_1_1_3__1_InorganicFertiliserApplicationCO2Emissions_Result_Method1} -> 7.3333333 | F13: =E13 -> 7.3333333 | G13: t CO2 | H13: =E13 -> 7.3333333 | I13: =F13 -> 7.3333333 | J13: t CO2e
A14: =HYPERLINK("#'Input - Fuel'!A1", "Fuel") -> Fuel | D14: 5.2.1.1-2 Organic fert N2O | E14: {=VEERG_5_2_1_1__2_MassOfNitrogenInOrganicFertiliser_Result_Method1} -> 0.0055785714 | F14: =E14 -> 0.0055785714 | G14: t N2O | H14: {=Common_Equations.Common_ConvertN2OToCO2e(E14,_xlfn.XLOOKUP("N2O", Table_GWPData[Gas],Table_GWPData[CO2-e factor]))} -> 1.4783214 | I14: {=Common_Equations.Common_ConvertN2OToCO2e(F14,_xlfn.XLOOKUP("N2O", Table_GWPData[Gas],Table_GWPData[CO2-e factor]))} -> 1.4783214 | J14: t CO2e
A15: =HYPERLINK("#'Input - Electricity'!A1", "Electricity") -> Electricity | D15: 5.3.1.1-2 Lime CO2 | E15: {=VEERG_5_3_1_1__1_LimeApplicationCO2Emissions_Result_Method1} -> 75.808333 | F15: =E15 -> 75.808333 | G15: t CO2 | H15: =E15 -> 75.808333 | I15: =F15 -> 75.808333 | J15: t CO2e
D16: 5.4.1.1-4 Atmos. deposition | E16: {=VEERG_5_4_1_3__1_OrganicFertiliserAtmosphericDepositionN2OEmissions_Result_Method1} -> 0.0016401 | F16: =E16 -> 0.0016401 | G16: t N2O | H16: {=Common_Equations.Common_ConvertN2OToCO2e(E16,_xlfn.XLOOKUP("N2O", Table_GWPData[Gas],Table_GWPData[CO2-e factor]))} -> 0.4346265 | I16: {=Common_Equations.Common_ConvertN2OToCO2e(F16,_xlfn.XLOOKUP("N2O", Table_GWPData[Gas],Table_GWPData[CO2-e factor]))} -> 0.4346265 | J16: t CO2e
D17: 5.5.1.1-2 Leaching & runoff | E17: {=VEERG_5_5_1_1__1_FertiliserLeachingAndRunoffN2OEmissions_result_Method1} -> 0.056917155 | F17: =E17 -> 0.056917155 | G17: t N2O | H17: {=Common_Equations.Common_ConvertN2OToCO2e(E17,_xlfn.XLOOKUP("N2O", Table_GWPData[Gas],Table_GWPData[CO2-e factor]))} -> 15.083046 | I17: {=Common_Equations.Common_ConvertN2OToCO2e(F17,_xlfn.XLOOKUP("N2O", Table_GWPData[Gas],Table_GWPData[CO2-e factor]))} -> 15.083046 | J17: t CO2e
A18: CALCULATIONS | D18: 6.2.1.1-2 Pasture residue N2O | E18: {=VEERG_6_2_1_1__1__NitrousOxideEmissionsFromPastureResidues_Result_Method1} -> 5.8320429e-07 | F18: {=VEERG_6_2_1_1__1__NitrousOxideEmissionsFromPastureResidues_Result_Method2} -> 5.8320429e-07 | G18: t N2O | H18: {=Common_Equations.Common_ConvertN2OToCO2e(E18,_xlfn.XLOOKUP("N2O", Table_GWPData[Gas],Table_GWPData[CO2-e factor]))} -> 0.00015454914 | I18: {=Common_Equations.Common_ConvertN2OToCO2e(F18,_xlfn.XLOOKUP("N2O", Table_GWPData[Gas],Table_GWPData[CO2-e factor]))} -> 0.00015454914 | J18: t CO2e
A19: =HYPERLINK("#'3.2.1.1-2 Enteric Methane'!A1", "3.2.1.1-2 Enteric methane") -> 3.2.1.1-2 Enteric methane | D19: 6.3.1.1-2 Leach & runoff (pasture) | E19: {=VEERG_6_3_1_1__1__LeachingAndRunoffEmissionsCropAndPastureResidue_PastureOnly_Result_Method1} -> 3.0793186e-07 | F19: {=VEERG_6_3_1_1__1__LeachingAndRunoffEmissionsCropAndPastureResidue_PastureOnly_Result_Method2} -> 3.0793186e-07 | G19: t N2O | H19: {=Common_Equations.Common_ConvertN2OToCO2e(E19,_xlfn.XLOOKUP("N2O", Table_GWPData[Gas],Table_GWPData[CO2-e factor]))} -> 8.1601944e-05 | I19: {=Common_Equations.Common_ConvertN2OToCO2e(F19,_xlfn.XLOOKUP("N2O", Table_GWPData[Gas],Table_GWPData[CO2-e factor]))} -> 8.1601944e-05 | J19: t CO2e
A20: =HYPERLINK("#'4.2.1.1-2 Methane'!A1", "4.2.1.1-2 Manure methane") -> 4.2.1.1-2 Manure methane | D20: 8.1.1.1-2 Transport fuel CO2 | E20: {=VEERG_8_1_1_1__1_FuelCombustionTransport_Result_CO2} -> 83.182 | F20: =E20 -> 83.182 | G20: t CO2 | H20: =E20 -> 83.182 | I20: =F20 -> 83.182 | J20: t CO2e
A21: =HYPERLINK("#'4.2.1.3-4 Soil direct N20'!A1", "4.2.1.3-4 Soil direct N2O") -> 4.2.1.3-4 Soil direct N2O | D21: 8.1.1.1-2 Transport fuel CH4 | E21: {=VEERG_8_1_1_1__1_FuelCombustionTransport_Result_CH4} -> 0.19906 | F21: =E21 -> 0.19906 | G21: t CH4 | H21: {=Common_Equations.Common_ConvertCH4ToCO2e(E21,_xlfn.XLOOKUP("CH4", Table_GWPData[Gas],Table_GWPData[CO2-e factor]))} -> 5.57368 | I21: {=Common_Equations.Common_ConvertCH4ToCO2e(F21,_xlfn.XLOOKUP("CH4", Table_GWPData[Gas],Table_GWPData[CO2-e factor]))} -> 5.57368 | J21: t CO2e
A22: =HYPERLINK("#'4.2.1.5-6 Soil Atmos Dep'!A1", "4.2.1.5-6 Soil atm. deposition") -> 4.2.1.5-6 Soil atm. deposition | D22: 8.1.1.1-2 Transport fuel N2O | E22: {=VEERG_8_1_1_1__1_FuelCombustionTransport_Result_N2O} -> 0.5845 | F22: =E22 -> 0.5845 | G22: t N2O | H22: {=Common_Equations.Common_ConvertN2OToCO2e(E22,_xlfn.XLOOKUP("N2O", Table_GWPData[Gas],Table_GWPData[CO2-e factor]))} -> 154.8925 | I22: {=Common_Equations.Common_ConvertN2OToCO2e(F22,_xlfn.XLOOKUP("N2O", Table_GWPData[Gas],Table_GWPData[CO2-e factor]))} -> 154.8925 | J22: t CO2e
A23: =HYPERLINK("#'4.2.1.7-8 Soil leach runoff'!A1", "4.2.1.7-8 Soil leach & runoff") -> 4.2.1.7-8 Soil leach & runoff | D23: 8.2.1.1-2 Stationary fuel CO2 | E23: {=VEERG_8_2_1_1__1_FuelCombustionStationary_Result_CO2} -> 29.0708 | F23: =E23 -> 29.0708 | G23: t CO2 | H23: =E23 -> 29.0708 | I23: =F23 -> 29.0708 | J23: t CO2e
A24: =HYPERLINK("#'5.1.1.1-2 Inorganic fert N2O'!A1", "5.1.1.1-2 Inorganic fert N2O") -> 5.1.1.1-2 Inorganic fert N2O | D24: 8.2.1.1-2 Stationary fuel CH4 | E24: {=VEERG_8_2_1_1__1_FuelCombustionStationary_Result_CH4} -> 0.0724 | F24: =E24 -> 0.0724 | G24: t CH4 | H24: {=Common_Equations.Common_ConvertCH4ToCO2e(E24,_xlfn.XLOOKUP("CH4", Table_GWPData[Gas],Table_GWPData[CO2-e factor]))} -> 2.0272 | I24: {=Common_Equations.Common_ConvertCH4ToCO2e(F24,_xlfn.XLOOKUP("CH4", Table_GWPData[Gas],Table_GWPData[CO2-e factor]))} -> 2.0272 | J24: t CO2e
A25: =HYPERLINK("#'5.1.1.3-4 Inorganic fert CO2'!A1", "5.1.1.3-4 Inorganic fert CO2") -> 5.1.1.3-4 Inorganic fert CO2 | D25: 8.2.1.1-2 Stationary fuel N2O | E25: {=VEERG_8_2_1_1__1_FuelCombustionStationary_Result_N2O} -> 0.0714 | F25: =E25 -> 0.0714 | G25: t N2O | H25: {=Common_Equations.Common_ConvertN2OToCO2e(E25,_xlfn.XLOOKUP("N2O", Table_GWPData[Gas],Table_GWPData[CO2-e factor]))} -> 18.921 | I25: {=Common_Equations.Common_ConvertN2OToCO2e(F25,_xlfn.XLOOKUP("N2O", Table_GWPData[Gas],Table_GWPData[CO2-e factor]))} -> 18.921 | J25: t CO2e
A26: =HYPERLINK("#'5.2.1.1-2 Organic Fert N2O'!A1", "5.2.1.1-2 Organic fert N2O") -> 5.2.1.1-2 Organic fert N2O | D26: 14.1.1-2 Purchased electricity (Location-based) | E26: {=VEERG_14_1_1__1_LocationBasedScopeElectricityEmissions_Result_Method1} -> 16.8 | F26: =E26 -> 16.8 | G26: t CO2e | H26: =E26 -> 16.8 | I26: =F26 -> 16.8 | J26: t CO2e
A27: =HYPERLINK("#'5.3.1.1-2 Lime CO2'!A1", "5.3.1.1-2 Lime CO2") -> 5.3.1.1-2 Lime CO2 | D27: 14.1.1-2 Purchased electricity (Market-based) | E27: {=VEERG_14_1_2__1_MarketBasedScopeElectricityEmissionsVariation_Result_Method1} -> 13.77 | F27: =E27 -> 13.77 | G27: t CO2e | H27: =E27 -> 13.77 | I27: =F27 -> 13.77 | J27: t CO2e
A28: =HYPERLINK("#'5.4.1.1-4 Atmos deposition'!A1", "5.4.1.1-4 Atmos. deposition") -> 5.4.1.1-4 Atmos. deposition | D28: Total | H28: =SUM(H7:H27) -> 2163.887 | I28: =SUM(I7:I27) -> 2159.2843 | J28: t CO2e
A29: =HYPERLINK("#'5.5.1.1-2 Leaching and runoff'!A1", "5.5.1.1-2 Leaching & runoff") -> 5.5.1.1-2 Leaching & runoff
A30: =HYPERLINK("#'6.2.1.1-2 Pasture residue N2O'!A1", "6.2.1.1-2 Pasture residue N2O") -> 6.2.1.1-2 Pasture residue N2O
A31: =HYPERLINK("#'6.3.1.1-2 Leach runoff pasture'!A1", "6.3.1.1-2 Leach & runoff (pasture)") -> 6.3.1.1-2 Leach & runoff (pasture)
A32: =HYPERLINK("#'8.1.1.1-2 Transport fuel'!A1", "8.1.1.1-2 Transport fuel") -> 8.1.1.1-2 Transport fuel | D32: Emissions for whole production cycle
A33: =HYPERLINK("#'8.2.1.1-2 Stationary fuel'!A1", "8.2.1.1-2 Stationary fuel") -> 8.2.1.1-2 Stationary fuel | D33: {="There are " & Common_InputFunctions.getOverlappingReportingCycles(X_Cell_Enterprise_ProductionTimeframeStart,X_Cell_Enterprise_ProductionTimeframeEnd,X_Cell_Site_StartDate) & " emissions calculation periods that need to be completed before total product emissions can be determined."} -> There are 3 emissions calculation periods that need to be completed before total product emissions can be determined.
A34: =HYPERLINK("#'14.1.1-2 Purchased electricity'!A1", "14.1.1-2 Purchased electricity") -> 14.1.1-2 Purchased electricity | D34: Enter the method 1 and 2 CO2e emissions from prevoius emissions calculation periods if applicable.
D36: Emissions calculation cycle | E36: CO2-e emissions method 1 | F36: CO2-e emissions method 2
A37: APPENDICES | D37: {=Common_InputFunctions.getOverlappingReportingPeriods(X_Cell_Enterprise_ProductionTimeframeStart,X_Cell_Enterprise_ProductionTimeframeEnd,X_Cell_Site_StartDate)} -> 01 Jan 2023 to 31 Dec 2023 | E37: 01 Jan 2023 to 31 Dec 2023 | F37: Enter value | G37: t CO2e
A38: =HYPERLINK("#'Constants - Pasture Beef'!A1", "Constants - Pasture Beef") -> Constants - Pasture Beef | D38: 01 Jan 2024 to 31 Dec 2024 | E38: 01 Jan 2024 to 31 Dec 2024 (This reporting cycle) | F38: 2163.887 | G38: t CO2e
A39: =HYPERLINK("#'Constants - Ag Residue'!A1", "Constants - Ag residue") -> Constants - Ag residue | D39: 01 Jan 2025 to 31 Dec 2025 (This reporting cycle) | E39: 01 Jan 2025 to 31 Dec 2025 | F39: Enter value | G39: t CO2e
A40: =HYPERLINK("#'Constants - Common Livestock'!A1", "Constants - Common Livestock") -> Constants - Common Livestock | G40: t CO2e
A41: =HYPERLINK("#'Constants - Electricity'!A1", "Constants - Electricity") -> Constants - Electricity | G41: t CO2e
A42: =HYPERLINK("#'Constants - Fertiliser'!A1", "Constants - Fertiliser") -> Constants - Fertiliser | D42: Total emissions for production cycle | E42: =SUM(E37:E41) -> 0 | F42: =SUM(F37:F41) -> 2163.887
A43: =HYPERLINK("#'Constants - Fuel'!A1", "Constants - Fuel") -> Constants - Fuel
...

Sheet Input - Enterprise
A1: #VALUE! | C1: Input - Enterprise
A3: =HYPERLINK("#'Home'!A1", "Home") -> Home
A4: =HYPERLINK("#'Results'!A1", "Results") -> Results
D5: Your business
A7: INPUTS | D7: Farm name | E7: My test farm
A8: =HYPERLINK("#'Input - Enterprise'!A1", "Enterprise") -> Enterprise | D8: Reporting entity name | E8: My test Farms Pty Ltd
A9: =HYPERLINK("#'Input - Site'!A1", "Site") -> Site
A10: =HYPERLINK("#'Input - Pasture Beef'!A1", "Pasture Beef") -> Pasture Beef | D10: 💡An 'Emissions accounting period' is a 12 month period where the business can report on the emissions, and is typically the same as the business' financial accounting period.
A11: =HYPERLINK("#'Input - Pasture Beef (Enteric)'!A1", "Pasture Beef (Enteric)") -> Pasture Beef (Enteric)
A12: =HYPERLINK("#'Input - Pasture'!A1", "Pasture") -> Pasture | D12: Emissions calculation period start date | E12: 45658 | F12: ← DD/MM/YYYY or DD Month YYYY
A13: =HYPERLINK("#'Input - Fertiliser'!A1", "Fertiliser") -> Fertiliser | D13: Emissions calculation period end date | E13: =DATE(YEAR(E12)+1,MONTH(E12),DAY(E12))-1 -> 46022 | F13: ← Automatically calculated, 12 months after start date
A14: =HYPERLINK("#'Input - Fuel'!A1", "Fuel") -> Fuel
A15: =HYPERLINK("#'Input - Electricity'!A1", "Electricity") -> Electricity
D16: Production
A18: CALCULATIONS | D18: Production timeframe start | E18: 45231 | F18: ← DD/MM/YYYY or DD Month YYYY
A19: =HYPERLINK("#'3.2.1.1-2 Enteric Methane'!A1", "3.2.1.1-2 Enteric methane") -> 3.2.1.1-2 Enteric methane | D19: Production timeframe end | E19: 45747 | F19: ← DD/MM/YYYY or DD Month YYYY
A20: =HYPERLINK("#'4.2.1.1-2 Methane'!A1", "4.2.1.1-2 Manure methane") -> 4.2.1.1-2 Manure methane | D20: Production timeframe length | E20: =DATEDIF(E18,E19+1,"m") -> 17 | F20: Months
A21: =HYPERLINK("#'4.2.1.3-4 Soil direct N20'!A1", "4.2.1.3-4 Soil direct N2O") -> 4.2.1.3-4 Soil direct N2O
A22: =HYPERLINK("#'4.2.1.5-6 Soil Atmos Dep'!A1", "4.2.1.5-6 Soil atm. deposition") -> 4.2.1.5-6 Soil atm. deposition | D22: Liveweight sold | E22: =SUM(Table_Input_LivestockSales348[Total liveweight sold])*10^-3 | G22: tonnes
A23: =HYPERLINK("#'4.2.1.7-8 Soil leach runoff'!A1", "4.2.1.7-8 Soil leach & runoff") -> 4.2.1.7-8 Soil leach & runoff | D23: Liveweight grown - method 1 | E23: =SUM(Enterprise_PastureBeef_InputFunctions.multiplyCorrespondingCells('Input - Pasture Beef'!X_Table_PastureBeef_Head_Method1, 'Input - Pasture Beef'!X_Table_PastureBeef_Duration_Method1, 'Input - Pasture Beef'!X_Table_PastureBeef_LiveweightGain_Method1))*10^-3 | G23: tonnes
A24: =HYPERLINK("#'5.1.1.1-2 Inorganic fert N2O'!A1", "5.1.1.1-2 Inorganic fert N2O") -> 5.1.1.1-2 Inorganic fert N2O | D24: Liveweight grown - method 2 | E24: =SUM(Enterprise_PastureBeef_InputFunctions.multiplyCorrespondingCells('Input - Pasture Beef'!X_Table_PastureBeef_Head_Method2, 'Input - Pasture Beef'!X_Table_PastureBeef_Duration_Method2, 'Input - Pasture Beef'!X_Table_PastureBeef_LiveweightGain_Method2))*10^-3 | G24: tonnes
A25: =HYPERLINK("#'5.1.1.3-4 Inorganic fert CO2'!A1", "5.1.1.3-4 Inorganic fert CO2") -> 5.1.1.3-4 Inorganic fert CO2 | D25: Manure produced - method 1 | E25: =SUM(Enterprise_PastureBeef_InputFunctions.multiplyCorrespondingCells('Input - Pasture Beef'!X_Table_PastureBeef_Head_Method1, Input - Pasture Beef'!X_Table_PastureBeef_Duration_Method1, '4.2.1.1-2 Methane'!M1_Table_VS_j_k_l))*10^-3 | G25: tonnes
A26: =HYPERLINK("#'5.2.1.1-2 Organic Fert N2O'!A1", "5.2.1.1-2 Organic fert N2O") -> 5.2.1.1-2 Organic fert N2O | D26: Manure produced - method 2 | E26: =SUM(Enterprise_PastureBeef_InputFunctions.multiplyCorrespondingCells('Input - Pasture Beef'!X_Table_PastureBeef_Head_Method2, 'Input - Pasture Beef'!X_Table_PastureBeef_Duration_Method2, M2_Table_VS_j_k_l))*10^-3 | G26: tonnes
A27: =HYPERLINK("#'5.3.1.1-2 Lime CO2'!A1", "5.3.1.1-2 Lime CO2") -> 5.3.1.1-2 Lime CO2 | D27: Percent manure sold | E27: 0.1 | G27: percent
A28: =HYPERLINK("#'5.4.1.1-4 Atmos deposition'!A1", "5.4.1.1-4 Atmos. deposition") -> 5.4.1.1-4 Atmos. deposition | D28: Percent manure applied as fertiliser on own farm | E28: 0.2 | G28: percent
A29: =HYPERLINK("#'5.5.1.1-2 Leaching and runoff'!A1", "5.5.1.1-2 Leaching & runoff") -> 5.5.1.1-2 Leaching & runoff | D29: Percent manure applied to soil with no purpose (as waste) | E29: =100%-E27-E28 -> 0.7 | G29: percent
A30: =HYPERLINK("#'6.2.1.1-2 Pasture residue N2O'!A1", "6.2.1.1-2 Pasture residue N2O") -> 6.2.1.1-2 Pasture residue N2O
A31: =HYPERLINK("#'6.3.1.1-2 Leach runoff pasture'!A1", "6.3.1.1-2 Leach & runoff (pasture)") -> 6.3.1.1-2 Leach & runoff (pasture) | D31: Percentage of income from liveweight sold | E31: 0.8 | G31: percent
A32: =HYPERLINK("#'8.1.1.1-2 Transport fuel'!A1", "8.1.1.1-2 Transport fuel") -> 8.1.1.1-2 Transport fuel | D32: Percentage of income from manure sold | E32: 0.2 | G32: percent
A33: =HYPERLINK("#'8.2.1.1-2 Stationary fuel'!A1", "8.2.1.1-2 Stationary fuel") -> 8.2.1.1-2 Stationary fuel
A34: =HYPERLINK("#'14.1.1-2 Purchased electricity'!A1", "14.1.1-2 Purchased electricity") -> 14.1.1-2 Purchased electricity
A37: APPENDICES
A38: =HYPERLINK("#'Constants - Pasture Beef'!A1", "Constants - Pasture Beef") -> Constants - Pasture Beef
A39: =HYPERLINK("#'Constants - Ag Residue'!A1", "Constants - Ag residue") -> Constants - Ag residue
A40: =HYPERLINK("#'Constants - Common Livestock'!A1", "Constants - Common Livestock") -> Constants - Common Livestock
A41: =HYPERLINK("#'Constants - Electricity'!A1", "Constants - Electricity") -> Constants - Electricity
A42: =HYPERLINK("#'Constants - Fertiliser'!A1", "Constants - Fertiliser") -> Constants - Fertiliser
A43: =HYPERLINK("#'Constants - Fuel'!A1", "Constants - Fuel") -> Constants - Fuel
A44: =HYPERLINK("#'Constants - Common'!A1", "Constants - Common") -> Constants - Common
A45: =HYPERLINK("#'Acknowledgements'!A1", "Acknowledgements") -> Acknowledgements
...

Sheet Input - Site
A1: #VALUE! | C1: Input - Site
A3: =HYPERLINK("#'Home'!A1", "Home") -> Home
A4: =HYPERLINK("#'Results'!A1", "Results") -> Results
D5: Location and climate
A7: INPUTS | D7: Location information is used to reference some region and climate-specific emission factors
A8: =HYPERLINK("#'Input - Enterprise'!A1", "Enterprise") -> Enterprise | D8: Tip: Use the web-based GAF Location Helper tool to easily get region and climate information. You will need an internet connection to use the GAF Location Helper.
A9: =HYPERLINK("#'Input - Site'!A1", "Site") -> Site
A10: =HYPERLINK("#'Input - Pasture Beef'!A1", "Pasture Beef") -> Pasture Beef | D10: State | E10: Western Australia | F10: ← Please select
A11: =HYPERLINK("#'Input - Pasture Beef (Enteric)'!A1", "Pasture Beef (Enteric)") -> Pasture Beef (Enteric) | D11: Region (ABS Statistical area level 4) if state is WA | E11: Western Australia - Outback (South) | F11: ← Please select
A12: =HYPERLINK("#'Input - Pasture'!A1", "Pasture") -> Pasture | D12: Leaching zone | E12: NO - Not in leaching zone | F12: ← Please select
A13: =HYPERLINK("#'Input - Fertiliser'!A1", "Fertiliser") -> Fertiliser | D13: Elevation | E13: 307.7 | F13: Meters
A14: =HYPERLINK("#'Input - Fuel'!A1", "Fuel") -> Fuel | D14: Average temperature for reporting period | E14: 18 | F14: Degrees celsius
A15: =HYPERLINK("#'Input - Electricity'!A1", "Electricity") -> Electricity | D15: Total rainfall for reporting period | E15: 601 | F15: Millimetres
D16: Potential evapotranspiration for reporting period | E16: 1326 | F16: Millimetres
D17: Number of frost days for reporting period | E17: 7 | F17: Days
A18: CALCULATIONS | D18: MAP:PET ratio | E18: =E15/E16 -> 0.45324284
A19: =HYPERLINK("#'3.2.1.1-2 Enteric Methane'!A1", "3.2.1.1-2 Enteric methane") -> 3.2.1.1-2 Enteric methane | D19: Rainfall zone | E19: =Common_InputFunctions.Utility_LookupItemFromMinMax(E15,Table_SourceData_RainfallZones[Min rainfall],Table_SourceData_RainfallZones[Max rainfall],Table_SourceData_RainfallZones[Rainfall Zone]) -> High rainfall
A20: =HYPERLINK("#'4.2.1.1-2 Methane'!A1", "4.2.1.1-2 Manure methane") -> 4.2.1.1-2 Manure methane | D20: Climate zone | E20: =Common_InputFunctions.Utility_GetClimateZone(E14,E15,E17,E13,E18,Table_SourceData_ClimateZones[Min temp],Table_SourceData_ClimateZones[Max temp],Table_SourceData_ClimateZones[Min rainfall],Table_SourceData_ClimateZones[Max rainfall],Table_SourceData_ClimateZones[Min frost days],Table_SourceData_ClimateZones[Max frost days],Table_SourceData_ClimateZones[Min elevation],Table_SourceData_ClimateZones[Max elevation],Table_SourceData_ClimateZones[Min MAP:PET],Table_SourceData_ClimateZones[Max MAP:PET],Table_SourceData_ClimateZones[Climate zone]) -> Warm temperate dry
A21: =HYPERLINK("#'4.2.1.3-4 Soil direct N20'!A1", "4.2.1.3-4 Soil direct N2O") -> 4.2.1.3-4 Soil direct N2O | D21: Wet or dry climate zone | E21: =Common_InputFunctions.Utility_LookupValueInTable($E$20,Table_SourceData_WetDryZones[Climate zone],Table_SourceData_WetDryZones[Wet or Dry Zone]) -> Dry climate zone
A22: =HYPERLINK("#'4.2.1.5-6 Soil Atmos Dep'!A1", "4.2.1.5-6 Soil atm. deposition") -> 4.2.1.5-6 Soil atm. deposition | D22: Temperature zone | E22: =Common_InputFunctions.Utility_LookupItemFromMinMax(E14,Table_SourceData_TemperatureZones[Min MAT],Table_SourceData_TemperatureZones[Max MAT],Table_SourceData_TemperatureZones[Temperature Zone]) -> Temperate
A23: =HYPERLINK("#'4.2.1.7-8 Soil leach runoff'!A1", "4.2.1.7-8 Soil leach & runoff") -> 4.2.1.7-8 Soil leach & runoff
A24: =HYPERLINK("#'5.1.1.1-2 Inorganic fert N2O'!A1", "5.1.1.1-2 Inorganic fert N2O") -> 5.1.1.1-2 Inorganic fert N2O
A25: =HYPERLINK("#'5.1.1.3-4 Inorganic fert CO2'!A1", "5.1.1.3-4 Inorganic fert CO2") -> 5.1.1.3-4 Inorganic fert CO2
A26: =HYPERLINK("#'5.2.1.1-2 Organic Fert N2O'!A1", "5.2.1.1-2 Organic fert N2O") -> 5.2.1.1-2 Organic fert N2O
A27: =HYPERLINK("#'5.3.1.1-2 Lime CO2'!A1", "5.3.1.1-2 Lime CO2") -> 5.3.1.1-2 Lime CO2
A28: =HYPERLINK("#'5.4.1.1-4 Atmos deposition'!A1", "5.4.1.1-4 Atmos. deposition") -> 5.4.1.1-4 Atmos. deposition
A29: =HYPERLINK("#'5.5.1.1-2 Leaching and runoff'!A1", "5.5.1.1-2 Leaching & runoff") -> 5.5.1.1-2 Leaching & runoff
A30: =HYPERLINK("#'6.2.1.1-2 Pasture residue N2O'!A1", "6.2.1.1-2 Pasture residue N2O") -> 6.2.1.1-2 Pasture residue N2O
A31: =HYPERLINK("#'6.3.1.1-2 Leach runoff pasture'!A1", "6.3.1.1-2 Leach & runoff (pasture)") -> 6.3.1.1-2 Leach & runoff (pasture)
A32: =HYPERLINK("#'8.1.1.1-2 Transport fuel'!A1", "8.1.1.1-2 Transport fuel") -> 8.1.1.1-2 Transport fuel
A33: =HYPERLINK("#'8.2.1.1-2 Stationary fuel'!A1", "8.2.1.1-2 Stationary fuel") -> 8.2.1.1-2 Stationary fuel
A34: =HYPERLINK("#'14.1.1-2 Purchased electricity'!A1", "14.1.1-2 Purchased electricity") -> 14.1.1-2 Purchased electricity
A37: APPENDICES
A38: =HYPERLINK("#'Constants - Pasture Beef'!A1", "Constants - Pasture Beef") -> Constants - Pasture Beef
A39: =HYPERLINK("#'Constants - Ag Residue'!A1", "Constants - Ag residue") -> Constants - Ag residue
A40: =HYPERLINK("#'Constants - Common Livestock'!A1", "Constants - Common Livestock") -> Constants - Common Livestock
A41: =HYPERLINK("#'Constants - Electricity'!A1", "Constants - Electricity") -> Constants - Electricity
A42: =HYPERLINK("#'Constants - Fertiliser'!A1", "Constants - Fertiliser") -> Constants - Fertiliser
A43: =HYPERLINK("#'Constants - Fuel'!A1", "Constants - Fuel") -> Constants - Fuel
A44: =HYPERLINK("#'Constants - Common'!A1", "Constants - Common") -> Constants - Common
...

Sheet Input - Pasture Beef
A1: #VALUE! | C1: Input -Pasture Beef
A3: =HYPERLINK("#'Home'!A1", "Home") -> Home
A4: =HYPERLINK("#'Results'!A1", "Results") -> Results
D5: Herd movement
A7: INPUTS | D7: State | E7: =X_Cell_Site_State -> Western Australia
A8: =HYPERLINK("#'Input - Enterprise'!A1", "Enterprise") -> Enterprise | D8: Livestock production region | E8: South West | F8: ← Please select
A9: =HYPERLINK("#'Input - Site'!A1", "Site") -> Site | D9: Cattle breed | E9: Hereford or Shorthorn breeds | F9: ← Please select
A10: =HYPERLINK("#'Input - Pasture Beef'!A1", "Pasture Beef") -> Pasture Beef
A11: =HYPERLINK("#'Input - Pasture Beef (Enteric)'!A1", "Pasture Beef (Enteric)") -> Pasture Beef (Enteric)
A12: =HYPERLINK("#'Input - Pasture'!A1", "Pasture") -> Pasture
A13: =HYPERLINK("#'Input - Fertiliser'!A1", "Fertiliser") -> Fertiliser | D13: NOTE: VEERG states that under method 2, time periods may be seasons, months or a custom time period. In this example, method 2 time periods are months.
A14: =HYPERLINK("#'Input - Fuel'!A1", "Fuel") -> Fuel
A15: =HYPERLINK("#'Input - Electricity'!A1", "Electricity") -> Electricity | D15: Duration on farm
D16: Method 1 default values (do not edit) | E16: Bulls < 1 year | F16: Bulls > 1 year | G16: Cows < 1 year | H16: Cows 1-2 years | I16: Cows 2-3 years | J16: Cows > 3 years | K16: Steers < 1 year | L16: Steers 1-2 years | M16: Steers 2-3 years | N16: Steers >3 years
D17: Spring | E17: 91.25 | F17: 91.25 | G17: 91.25 | H17: 91.25 | I17: 91.25 | J17: 91.25 | K17: 91.25 | L17: 91.25 | M17: 91.25 | N17: 91.25 | O17: Days
A18: CALCULATIONS | D18: Summer | E18: 91.25 | F18: 91.25 | G18: 91.25 | H18: 91.25 | I18: 91.25 | J18: 91.25 | K18: 91.25 | L18: 91.25 | M18: 91.25 | N18: 91.25 | O18: Days
A19: =HYPERLINK("#'3.2.1.1-2 Enteric Methane'!A1", "3.2.1.1-2 Enteric methane") -> 3.2.1.1-2 Enteric methane | D19: Autumn | E19: 91.25 | F19: 91.25 | G19: 91.25 | H19: 91.25 | I19: 91.25 | J19: 91.25 | K19: 91.25 | L19: 91.25 | M19: 91.25 | N19: 91.25 | O19: Days
A20: =HYPERLINK("#'4.2.1.1-2 Methane'!A1", "4.2.1.1-2 Manure methane") -> 4.2.1.1-2 Manure methane | D20: Winter | E20: 91.25 | F20: 91.25 | G20: 91.25 | H20: 91.25 | I20: 91.25 | J20: 91.25 | K20: 91.25 | L20: 91.25 | M20: 91.25 | N20: 91.25 | O20: Days
A21: =HYPERLINK("#'4.2.1.3-4 Soil direct N20'!A1", "4.2.1.3-4 Soil direct N2O") -> 4.2.1.3-4 Soil direct N2O
A22: =HYPERLINK("#'4.2.1.5-6 Soil Atmos Dep'!A1", "4.2.1.5-6 Soil atm. deposition") -> 4.2.1.5-6 Soil atm. deposition | D22: Method 2 custom values (edit if known) | E22: Bulls < 1 year | F22: Bulls > 1 year | G22: Cows < 1 year | H22: Cows 1-2 years | I22: Cows 2-3 years | J22: Cows > 3 years | K22: Steers < 1 year | L22: Steers 1-2 years | M22: Steers 2-3 years | N22: Steers >3 years
A23: =HYPERLINK("#'4.2.1.7-8 Soil leach runoff'!A1", "4.2.1.7-8 Soil leach & runoff") -> 4.2.1.7-8 Soil leach & runoff | D23: =TEXT(X_Cell_Site_StartDate, "mmmm yyyy") -> January 2025 | E23: 31 | F23: 31 | G23: 31 | H23: 31 | I23: 31 | J23: 31 | K23: 31 | L23: 31 | M23: 31 | N23: 31 | O23: Days
A24: =HYPERLINK("#'5.1.1.1-2 Inorganic fert N2O'!A1", "5.1.1.1-2 Inorganic fert N2O") -> 5.1.1.1-2 Inorganic fert N2O | D24: =TEXT(EDATE(X_Cell_Site_StartDate,1), "mmmm yyyy") -> February 2025 | E24: 29 | F24: 29 | G24: 29 | H24: 29 | I24: 29 | J24: 29 | K24: 29 | L24: 29 | M24: 29 | N24: 29 | O24: Days
A25: =HYPERLINK("#'5.1.1.3-4 Inorganic fert CO2'!A1", "5.1.1.3-4 Inorganic fert CO2") -> 5.1.1.3-4 Inorganic fert CO2 | D25: =TEXT(EDATE(X_Cell_Site_StartDate,2), "mmmm yyyy") -> March 2025 | E25: 31 | F25: 31 | G25: 31 | H25: 31 | I25: 31 | J25: 31 | K25: 31 | L25: 31 | M25: 31 | N25: 31 | O25: Days
A26: =HYPERLINK("#'5.2.1.1-2 Organic Fert N2O'!A1", "5.2.1.1-2 Organic fert N2O") -> 5.2.1.1-2 Organic fert N2O | D26: =TEXT(EDATE(X_Cell_Site_StartDate,3), "mmmm yyyy") -> April 2025 | E26: 30 | F26: 30 | G26: 30 | H26: 30 | I26: 30 | J26: 30 | K26: 30 | L26: 30 | M26: 30 | N26: 30 | O26: Days
A27: =HYPERLINK("#'5.3.1.1-2 Lime CO2'!A1", "5.3.1.1-2 Lime CO2") -> 5.3.1.1-2 Lime CO2 | D27: =TEXT(EDATE(X_Cell_Site_StartDate,4), "mmmm yyyy") -> May 2025 | E27: 31 | F27: 31 | G27: 31 | H27: 31 | I27: 31 | J27: 31 | K27: 31 | L27: 31 | M27: 31 | N27: 31 | O27: Days
A28: =HYPERLINK("#'5.4.1.1-4 Atmos deposition'!A1", "5.4.1.1-4 Atmos. deposition") -> 5.4.1.1-4 Atmos. deposition | D28: =TEXT(EDATE(X_Cell_Site_StartDate,5), "mmmm yyyy") -> June 2025 | E28: 30 | F28: 30 | G28: 30 | H28: 30 | I28: 30 | J28: 30 | K28: 30 | L28: 30 | M28: 30 | N28: 30 | O28: Days
A29: =HYPERLINK("#'5.5.1.1-2 Leaching and runoff'!A1", "5.5.1.1-2 Leaching & runoff") -> 5.5.1.1-2 Leaching & runoff | D29: =TEXT(EDATE(X_Cell_Site_StartDate,6), "mmmm yyyy") -> July 2025 | E29: 31 | F29: 31 | G29: 31 | H29: 31 | I29: 31 | J29: 31 | K29: 31 | L29: 31 | M29: 31 | N29: 31 | O29: Days
A30: =HYPERLINK("#'6.2.1.1-2 Pasture residue N2O'!A1", "6.2.1.1-2 Pasture residue N2O") -> 6.2.1.1-2 Pasture residue N2O | D30: =TEXT(EDATE(X_Cell_Site_StartDate,7), "mmmm yyyy") -> August 2025 | E30: 31 | F30: 31 | G30: 31 | H30: 31 | I30: 31 | J30: 31 | K30: 31 | L30: 31 | M30: 31 | N30: 31 | O30: Days
A31: =HYPERLINK("#'6.3.1.1-2 Leach runoff pasture'!A1", "6.3.1.1-2 Leach & runoff (pasture)") -> 6.3.1.1-2 Leach & runoff (pasture) | D31: =TEXT(EDATE(X_Cell_Site_StartDate,8), "mmmm yyyy") -> September 2025 | E31: 30 | F31: 30 | G31: 30 | H31: 30 | I31: 30 | J31: 30 | K31: 30 | L31: 30 | M31: 30 | N31: 30 | O31: Days
A32: =HYPERLINK("#'8.1.1.1-2 Transport fuel'!A1", "8.1.1.1-2 Transport fuel") -> 8.1.1.1-2 Transport fuel | D32: =TEXT(EDATE(X_Cell_Site_StartDate,9), "mmmm yyyy") -> October 2025 | E32: 31 | F32: 31 | G32: 31 | H32: 31 | I32: 31 | J32: 31 | K32: 31 | L32: 31 | M32: 31 | N32: 31 | O32: Days
A33: =HYPERLINK("#'8.2.1.1-2 Stationary fuel'!A1", "8.2.1.1-2 Stationary fuel") -> 8.2.1.1-2 Stationary fuel | D33: =TEXT(EDATE(X_Cell_Site_StartDate,10), "mmmm yyyy") -> November 2025 | E33: 30 | F33: 30 | G33: 30 | H33: 30 | I33: 30 | J33: 30 | K33: 30 | L33: 30 | M33: 30 | N33: 30 | O33: Days
A34: =HYPERLINK("#'14.1.1-2 Purchased electricity'!A1", "14.1.1-2 Purchased electricity") -> 14.1.1-2 Purchased electricity | D34: =TEXT(EDATE(X_Cell_Site_StartDate,11), "mmmm yyyy") -> December 2025 | E34: 31 | F34: 31 | G34: 31 | H34: 31 | I34: 31 | J34: 31 | K34: 31 | L34: 31 | M34: 31 | N34: 31 | O34: Days
A37: APPENDICES | D37: Head
A38: =HYPERLINK("#'Constants - Pasture Beef'!A1", "Constants - Pasture Beef") -> Constants - Pasture Beef | D38: Method 1 values | E38: Bulls < 1 year | F38: Bulls > 1 year | G38: Cows < 1 year | H38: Cows 1-2 years | I38: Cows 2-3 years | J38: Cows > 3 years | K38: Steers < 1 year | L38: Steers 1-2 years | M38: Steers 2-3 years | N38: Steers >3 years
A39: =HYPERLINK("#'Constants - Ag Residue'!A1", "Constants - Ag residue") -> Constants - Ag residue | D39: Spring | E39: 100 | F39: 100 | G39: 100 | H39: 100 | I39: 100 | J39: 100 | K39: 100 | L39: 100 | M39: 100 | N39: 100 | O39: Head
A40: =HYPERLINK("#'Constants - Common Livestock'!A1", "Constants - Common Livestock") -> Constants - Common Livestock | D40: Summer | E40: 100 | F40: 100 | G40: 100 | H40: 100 | I40: 100 | J40: 100 | K40: 100 | L40: 100 | M40: 100 | N40: 100 | O40: Head
A41: =HYPERLINK("#'Constants - Electricity'!A1", "Constants - Electricity") -> Constants - Electricity | D41: Autumn | E41: 100 | F41: 100 | G41: 100 | H41: 100 | I41: 100 | J41: 100 | K41: 100 | L41: 100 | M41: 100 | N41: 100 | O41: Head
A42: =HYPERLINK("#'Constants - Fertiliser'!A1", "Constants - Fertiliser") -> Constants - Fertiliser | D42: Winter | E42: 100 | F42: 100 | G42: 100 | H42: 100 | I42: 100 | J42: 100 | K42: 100 | L42: 100 | M42: 100 | N42: 100 | O42: Head
A43: =HYPERLINK("#'Constants - Fuel'!A1", "Constants - Fuel") -> Constants - Fuel
A44: =HYPERLINK("#'Constants - Common'!A1", "Constants - Common") -> Constants - Common | D44: Method 2 values | E44: Bulls < 1 year | F44: Bulls > 1 year | G44: Cows < 1 year | H44: Cows 1-2 years | I44: Cows 2-3 years | J44: Cows > 3 years | K44: Steers < 1 year | L44: Steers 1-2 years | M44: Steers 2-3 years | N44: Steers >3 years
...

Sheet Input - Pasture Beef (Enteric)
A1: #VALUE! | C1: Input -Pasture Beef
A3: =HYPERLINK("#'Home'!A1", "Home") -> Home
A4: =HYPERLINK("#'Results'!A1", "Results") -> Results
D5: Herd movement
A7: INPUTS | D7: State | E7: =X_Cell_Site_State -> Western Australia
A8: =HYPERLINK("#'Input - Enterprise'!A1", "Enterprise") -> Enterprise | D8: Livestock production region | E8: South West | F8: ← Please select
A9: =HYPERLINK("#'Input - Site'!A1", "Site") -> Site | D9: Cattle breed | E9: Hereford or Shorthorn breeds | F9: ← Please select
A10: =HYPERLINK("#'Input - Pasture Beef'!A1", "Pasture Beef") -> Pasture Beef
A11: =HYPERLINK("#'Input - Pasture Beef (Enteric)'!A1", "Pasture Beef (Enteric)") -> Pasture Beef (Enteric)
A12: =HYPERLINK("#'Input - Pasture'!A1", "Pasture") -> Pasture
A13: =HYPERLINK("#'Input - Fertiliser'!A1", "Fertiliser") -> Fertiliser | D13: NOTE: VEERG states that under method 2, time periods may be seasons, months or a custom time period. In this example, method 2 time periods are months.
A14: =HYPERLINK("#'Input - Fuel'!A1", "Fuel") -> Fuel
A15: =HYPERLINK("#'Input - Electricity'!A1", "Electricity") -> Electricity | D15: Duration on farm
D16: Method 1 default values (do not edit) | E16: Bulls < 1 year | F16: Bulls > 1 year | G16: Cows < 1 year | H16: Cows 1-2 years | I16: Cows 2-3 years | J16: Cows > 3 years | K16: Steers < 1 year | L16: Steers 1-2 years | M16: Steers 2-3 years | N16: Steers >3 years
D17: Spring | E17: 91.25 | F17: 91.25 | G17: 91.25 | H17: 91.25 | I17: 91.25 | J17: 91.25 | K17: 91.25 | L17: 91.25 | M17: 91.25 | N17: 91.25 | O17: Days
A18: CALCULATIONS | D18: Summer | E18: 91.25 | F18: 91.25 | G18: 91.25 | H18: 91.25 | I18: 91.25 | J18: 91.25 | K18: 91.25 | L18: 91.25 | M18: 91.25 | N18: 91.25 | O18: Days
A19: =HYPERLINK("#'3.2.1.1-2 Enteric Methane'!A1", "3.2.1.1-2 Enteric methane") -> 3.2.1.1-2 Enteric methane | D19: Autumn | E19: 91.25 | F19: 91.25 | G19: 91.25 | H19: 91.25 | I19: 91.25 | J19: 91.25 | K19: 91.25 | L19: 91.25 | M19: 91.25 | N19: 91.25 | O19: Days
A20: =HYPERLINK("#'4.2.1.1-2 Methane'!A1", "4.2.1.1-2 Manure methane") -> 4.2.1.1-2 Manure methane | D20: Winter | E20: 91.25 | F20: 91.25 | G20: 91.25 | H20: 91.25 | I20: 91.25 | J20: 91.25 | K20: 91.25 | L20: 91.25 | M20: 91.25 | N20: 91.25 | O20: Days
A21: =HYPERLINK("#'4.2.1.3-4 Soil direct N20'!A1", "4.2.1.3-4 Soil direct N2O") -> 4.2.1.3-4 Soil direct N2O
A22: =HYPERLINK("#'4.2.1.5-6 Soil Atmos Dep'!A1", "4.2.1.5-6 Soil atm. deposition") -> 4.2.1.5-6 Soil atm. deposition | D22: Method 2 custom values (edit if known) | E22: Bulls < 1 year | F22: Bulls > 1 year | G22: Cows < 1 year | H22: Cows 1-2 years | I22: Cows 2-3 years | J22: Cows > 3 years | K22: Steers < 1 year | L22: Steers 1-2 years | M22: Steers 2-3 years | N22: Steers >3 years
A23: =HYPERLINK("#'4.2.1.7-8 Soil leach runoff'!A1", "4.2.1.7-8 Soil leach & runoff") -> 4.2.1.7-8 Soil leach & runoff | D23: =TEXT(X_Cell_Site_StartDate, "mmmm yyyy") -> January 2025 | E23: =DAY(EOMONTH($D23,0)) -> 31 | F23: =DAY(EOMONTH($D23,0)) -> 31 | G23: =DAY(EOMONTH($D23,0)) -> 31 | H23: =DAY(EOMONTH($D23,0)) -> 31 | I23: =DAY(EOMONTH($D23,0)) -> 31 | J23: =DAY(EOMONTH($D23,0)) -> 31 | K23: =DAY(EOMONTH($D23,0)) -> 31 | L23: =DAY(EOMONTH($D23,0)) -> 31 | ... N23: =DAY(EOMONTH($D23,0)) -> 31 | O23: Days
A24: =HYPERLINK("#'5.1.1.1-2 Inorganic fert N2O'!A1", "5.1.1.1-2 Inorganic fert N2O") -> 5.1.1.1-2 Inorganic fert N2O | D24: =TEXT(EDATE(X_Cell_Site_StartDate,1), "mmmm yyyy") -> February 2025 | E24: =DAY(EOMONTH($D24,0)) -> 28 | F24: =DAY(EOMONTH($D24,0)) -> 28 | G24: =DAY(EOMONTH($D24,0)) -> 28 | H24: =DAY(EOMONTH($D24,0)) -> 28 | I24: =DAY(EOMONTH($D24,0)) -> 28 | J24: =DAY(EOMONTH($D24,0)) -> 28 | K24: =DAY(EOMONTH($D24,0)) -> 28 | L24: =DAY(EOMONTH($D24,0)) -> 28 | ... N24: =DAY(EOMONTH($D24,0)) -> 28 | O24: Days
A25: =HYPERLINK("#'5.1.1.3-4 Inorganic fert CO2'!A1", "5.1.1.3-4 Inorganic fert CO2") -> 5.1.1.3-4 Inorganic fert CO2 | D25: =TEXT(EDATE(X_Cell_Site_StartDate,2), "mmmm yyyy") -> March 2025 | E25: =DAY(EOMONTH($D25,0)) -> 31 | F25: =DAY(EOMONTH($D25,0)) -> 31 | G25: =DAY(EOMONTH($D25,0)) -> 31 | H25: =DAY(EOMONTH($D25,0)) -> 31 | I25: =DAY(EOMONTH($D25,0)) -> 31 | J25: =DAY(EOMONTH($D25,0)) -> 31 | K25: =DAY(EOMONTH($D25,0)) -> 31 | L25: =DAY(EOMONTH($D25,0)) -> 31 | ... N25: =DAY(EOMONTH($D25,0)) -> 31 | O25: Days
A26: =HYPERLINK("#'5.2.1.1-2 Organic Fert N2O'!A1", "5.2.1.1-2 Organic fert N2O") -> 5.2.1.1-2 Organic fert N2O | D26: =TEXT(EDATE(X_Cell_Site_StartDate,3), "mmmm yyyy") -> April 2025 | E26: =DAY(EOMONTH($D26,0)) -> 30 | F26: =DAY(EOMONTH($D26,0)) -> 30 | G26: =DAY(EOMONTH($D26,0)) -> 30 | H26: =DAY(EOMONTH($D26,0)) -> 30 | I26: =DAY(EOMONTH($D26,0)) -> 30 | J26: =DAY(EOMONTH($D26,0)) -> 30 | K26: =DAY(EOMONTH($D26,0)) -> 30 | L26: =DAY(EOMONTH($D26,0)) -> 30 | ... N26: =DAY(EOMONTH($D26,0)) -> 30 | O26: Days
A27: =HYPERLINK("#'5.3.1.1-2 Lime CO2'!A1", "5.3.1.1-2 Lime CO2") -> 5.3.1.1-2 Lime CO2 | D27: =TEXT(EDATE(X_Cell_Site_StartDate,4), "mmmm yyyy") -> May 2025 | E27: =DAY(EOMONTH($D27,0)) -> 31 | F27: =DAY(EOMONTH($D27,0)) -> 31 | G27: =DAY(EOMONTH($D27,0)) -> 31 | H27: =DAY(EOMONTH($D27,0)) -> 31 | I27: =DAY(EOMONTH($D27,0)) -> 31 | J27: =DAY(EOMONTH($D27,0)) -> 31 | K27: =DAY(EOMONTH($D27,0)) -> 31 | L27: =DAY(EOMONTH($D27,0)) -> 31 | ... N27: =DAY(EOMONTH($D27,0)) -> 31 | O27: Days
A28: =HYPERLINK("#'5.4.1.1-4 Atmos deposition'!A1", "5.4.1.1-4 Atmos. deposition") -> 5.4.1.1-4 Atmos. deposition | D28: =TEXT(EDATE(X_Cell_Site_StartDate,5), "mmmm yyyy") -> June 2025 | E28: =DAY(EOMONTH($D28,0)) -> 30 | F28: =DAY(EOMONTH($D28,0)) -> 30 | G28: =DAY(EOMONTH($D28,0)) -> 30 | H28: =DAY(EOMONTH($D28,0)) -> 30 | I28: =DAY(EOMONTH($D28,0)) -> 30 | J28: =DAY(EOMONTH($D28,0)) -> 30 | K28: =DAY(EOMONTH($D28,0)) -> 30 | L28: =DAY(EOMONTH($D28,0)) -> 30 | ... N28: =DAY(EOMONTH($D28,0)) -> 30 | O28: Days
A29: =HYPERLINK("#'5.5.1.1-2 Leaching and runoff'!A1", "5.5.1.1-2 Leaching & runoff") -> 5.5.1.1-2 Leaching & runoff | D29: =TEXT(EDATE(X_Cell_Site_StartDate,6), "mmmm yyyy") -> July 2025 | E29: =DAY(EOMONTH($D29,0)) -> 31 | F29: =DAY(EOMONTH($D29,0)) -> 31 | G29: =DAY(EOMONTH($D29,0)) -> 31 | H29: =DAY(EOMONTH($D29,0)) -> 31 | I29: =DAY(EOMONTH($D29,0)) -> 31 | J29: =DAY(EOMONTH($D29,0)) -> 31 | K29: =DAY(EOMONTH($D29,0)) -> 31 | L29: =DAY(EOMONTH($D29,0)) -> 31 | ... N29: =DAY(EOMONTH($D29,0)) -> 31 | O29: Days
A30: =HYPERLINK("#'6.2.1.1-2 Pasture residue N2O'!A1", "6.2.1.1-2 Pasture residue N2O") -> 6.2.1.1-2 Pasture residue N2O | D30: =TEXT(EDATE(X_Cell_Site_StartDate,7), "mmmm yyyy") -> August 2025 | E30: =DAY(EOMONTH($D30,0)) -> 31 | F30: =DAY(EOMONTH($D30,0)) -> 31 | G30: =DAY(EOMONTH($D30,0)) -> 31 | H30: =DAY(EOMONTH($D30,0)) -> 31 | I30: =DAY(EOMONTH($D30,0)) -> 31 | J30: =DAY(EOMONTH($D30,0)) -> 31 | K30: =DAY(EOMONTH($D30,0)) -> 31 | L30: =DAY(EOMONTH($D30,0)) -> 31 | ... N30: =DAY(EOMONTH($D30,0)) -> 31 | O30: Days
A31: =HYPERLINK("#'6.3.1.1-2 Leach runoff pasture'!A1", "6.3.1.1-2 Leach & runoff (pasture)") -> 6.3.1.1-2 Leach & runoff (pasture) | D31: =TEXT(EDATE(X_Cell_Site_StartDate,8), "mmmm yyyy") -> September 2025 | E31: =DAY(EOMONTH($D31,0)) -> 30 | F31: =DAY(EOMONTH($D31,0)) -> 30 | G31: =DAY(EOMONTH($D31,0)) -> 30 | H31: =DAY(EOMONTH($D31,0)) -> 30 | I31: =DAY(EOMONTH($D31,0)) -> 30 | J31: =DAY(EOMONTH($D31,0)) -> 30 | K31: =DAY(EOMONTH($D31,0)) -> 30 | L31: =DAY(EOMONTH($D31,0)) -> 30 | ... N31: =DAY(EOMONTH($D31,0)) -> 30 | O31: Days
A32: =HYPERLINK("#'8.1.1.1-2 Transport fuel'!A1", "8.1.1.1-2 Transport fuel") -> 8.1.1.1-2 Transport fuel | D32: =TEXT(EDATE(X_Cell_Site_StartDate,9), "mmmm yyyy") -> October 2025 | E32: =DAY(EOMONTH($D32,0)) -> 31 | F32: =DAY(EOMONTH($D32,0)) -> 31 | G32: =DAY(EOMONTH($D32,0)) -> 31 | H32: =DAY(EOMONTH($D32,0)) -> 31 | I32: =DAY(EOMONTH($D32,0)) -> 31 | J32: =DAY(EOMONTH($D32,0)) -> 31 | K32: =DAY(EOMONTH($D32,0)) -> 31 | L32: =DAY(EOMONTH($D32,0)) -> 31 | ... N32: =DAY(EOMONTH($D32,0)) -> 31 | O32: Days
A33: =HYPERLINK("#'8.2.1.1-2 Stationary fuel'!A1", "8.2.1.1-2 Stationary fuel") -> 8.2.1.1-2 Stationary fuel | D33: =TEXT(EDATE(X_Cell_Site_StartDate,10), "mmmm yyyy") -> November 2025 | E33: =DAY(EOMONTH($D33,0)) -> 30 | F33: =DAY(EOMONTH($D33,0)) -> 30 | G33: =DAY(EOMONTH($D33,0)) -> 30 | H33: =DAY(EOMONTH($D33,0)) -> 30 | I33: =DAY(EOMONTH($D33,0)) -> 30 | J33: =DAY(EOMONTH($D33,0)) -> 30 | K33: =DAY(EOMONTH($D33,0)) -> 30 | L33: =DAY(EOMONTH($D33,0)) -> 30 | ... N33: =DAY(EOMONTH($D33,0)) -> 30 | O33: Days
A34: =HYPERLINK("#'14.1.1-2 Purchased electricity'!A1", "14.1.1-2 Purchased electricity") -> 14.1.1-2 Purchased electricity | D34: =TEXT(EDATE(X_Cell_Site_StartDate,11), "mmmm yyyy") -> December 2025 | E34: =DAY(EOMONTH($D34,0)) -> 31 | F34: =DAY(EOMONTH($D34,0)) -> 31 | G34: =DAY(EOMONTH($D34,0)) -> 31 | H34: =DAY(EOMONTH($D34,0)) -> 31 | I34: =DAY(EOMONTH($D34,0)) -> 31 | J34: =DAY(EOMONTH($D34,0)) -> 31 | K34: =DAY(EOMONTH($D34,0)) -> 31 | L34: =DAY(EOMONTH($D34,0)) -> 31 | ... N34: =DAY(EOMONTH($D34,0)) -> 31 | O34: Days
A37: APPENDICES | D37: Head
A38: =HYPERLINK("#'Constants - Pasture Beef'!A1", "Constants - Pasture Beef") -> Constants - Pasture Beef | D38: Method 1 values | E38: Bulls < 1 year | F38: Bulls > 1 year | G38: Cows < 1 year | H38: Cows 1-2 years | I38: Cows 2-3 years | J38: Cows > 3 years | K38: Steers < 1 year | L38: Steers 1-2 years | M38: Steers 2-3 years | N38: Steers >3 years
A39: =HYPERLINK("#'Constants - Ag Residue'!A1", "Constants - Ag residue") -> Constants - Ag residue | D39: Spring | E39: 100 | F39: 100 | G39: 100 | H39: 100 | I39: 100 | J39: 100 | K39: 100 | L39: 100 | M39: 100 | N39: 100 | O39: Head
A40: =HYPERLINK("#'Constants - Common Livestock'!A1", "Constants - Common Livestock") -> Constants - Common Livestock | D40: Summer | E40: 100 | F40: 100 | G40: 100 | H40: 100 | I40: 100 | J40: 100 | K40: 100 | L40: 100 | M40: 100 | N40: 100 | O40: Head
A41: =HYPERLINK("#'Constants - Electricity'!A1", "Constants - Electricity") -> Constants - Electricity | D41: Autumn | E41: 100 | F41: 100 | G41: 100 | H41: 100 | I41: 100 | J41: 100 | K41: 100 | L41: 100 | M41: 100 | N41: 100 | O41: Head
A42: =HYPERLINK("#'Constants - Fertiliser'!A1", "Constants - Fertiliser") -> Constants - Fertiliser | D42: Winter | E42: 100 | F42: 100 | G42: 100 | H42: 100 | I42: 100 | J42: 100 | K42: 100 | L42: 100 | M42: 100 | N42: 100 | O42: Head
A43: =HYPERLINK("#'Constants - Fuel'!A1", "Constants - Fuel") -> Constants - Fuel
A44: =HYPERLINK("#'Constants - Common'!A1", "Constants - Common") -> Constants - Common | D44: Method 2 values | E44: Bulls < 1 year | F44: Bulls > 1 year | G44: Cows < 1 year | H44: Cows 1-2 years | I44: Cows 2-3 years | J44: Cows > 3 years | K44: Steers < 1 year | L44: Steers 1-2 years | M44: Steers 2-3 years | N44: Steers >3 years
...

Sheet Input - Pasture
A1: #VALUE! | C1: Input - Pasture
A3: =HYPERLINK("#'Home'!A1", "Home") -> Home
A4: =HYPERLINK("#'Results'!A1", "Results") -> Results
D5: Area
A7: INPUTS | D7: If multiple paddocks were managed in the same way at the same time, you can enter information for them all together.
A8: =HYPERLINK("#'Input - Enterprise'!A1", "Enterprise") -> Enterprise
A9: =HYPERLINK("#'Input - Site'!A1", "Site") -> Site | D9: Pasture type | E9: Grass clover mixture | F9: ← Please select
A10: =HYPERLINK("#'Input - Pasture Beef'!A1", "Pasture Beef") -> Pasture Beef | D10: Irrigation method | E10: Surface irrigation | F10: ← Please select
A11: =HYPERLINK("#'Input - Pasture Beef (Enteric)'!A1", "Pasture Beef (Enteric)") -> Pasture Beef (Enteric)
A12: =HYPERLINK("#'Input - Pasture'!A1", "Pasture") -> Pasture | D12: Area under pasture | E12: 1000 | F12: Hectares
A13: =HYPERLINK("#'Input - Fertiliser'!A1", "Fertiliser") -> Fertiliser
A14: =HYPERLINK("#'Input - Fuel'!A1", "Fuel") -> Fuel | D14: Yield
A15: =HYPERLINK("#'Input - Electricity'!A1", "Electricity") -> Electricity
D16: 💡 'Pasture yield' is the average amount of dry matter that is grazed.
D17: A default value is provided based on pasture type. You can edit this if known.
A18: CALCULATIONS
A19: =HYPERLINK("#'3.2.1.1-2 Enteric Methane'!A1", "3.2.1.1-2 Enteric methane") -> 3.2.1.1-2 Enteric methane | D19: Pasture yield | E19: 8.34 | F19: Tonnes dry matter / hectare
A20: =HYPERLINK("#'4.2.1.1-2 Methane'!A1", "4.2.1.1-2 Manure methane") -> 4.2.1.1-2 Manure methane | D20: Total pasture yield | E20: =E12*E19 -> 8340 | F20: Tonnes
A21: =HYPERLINK("#'4.2.1.3-4 Soil direct N20'!A1", "4.2.1.3-4 Soil direct N2O") -> 4.2.1.3-4 Soil direct N2O
A22: =HYPERLINK("#'4.2.1.5-6 Soil Atmos Dep'!A1", "4.2.1.5-6 Soil atm. deposition") -> 4.2.1.5-6 Soil atm. deposition
