Workbook
Name _Toc225350871: '5.4.1.1-4 Atmos deposition'!$C$1
Name _Toc225350871: '5.5.1.1-2 Leaching and runoff'!$C$1
Name Common_Equations.Common_ConvertCH4ToCO2e: _xlfn.LAMBDA(_xlpm.E_CH4,_xlpm.GWP_CH4, _xlpm.E_CH4 * _xlpm.GWP_CH4)
Name Common_Equations.Common_ConvertCH4ToCO2e_Arguments: _xlfn.LAMBDA(_xlfn.MAKEARRAY(2, 2, _xlfn.LAMBDA(_xlpm.r,_xlpm.c, INDEX({"ECH4","Methane emissions (t CH4)";"GWPCH4","Global warming potential for methane (t CO2-e / t CH4)"}, _xlpm.r, _xlpm.c))))
Name Common_Equations.Common_ConvertCH4ToCO2e_LatexEquation: _xlfn.LAMBDA("CO2_e = E_{CH4} \times GWP_{CH4}")
Name Common_Equations.Common_ConvertCH4ToCO2e_NIRReference: _xlfn.LAMBDA("")
Name Common_Equations.Common_ConvertCH4ToCO2e_Title: _xlfn.LAMBDA("Convert methane emissions to carbon dioxide equivalent emissions")
Name Common_Equations.Common_ConvertCH4ToCO2e_Unit: _xlfn.LAMBDA("t CO2e")
Name Common_Equations.Common_ConvertCH4ToCO2e_Variable: _xlfn.LAMBDA("ECH4 CO2e")
Name Common_Equations.Common_ConvertN2OToCO2e: _xlfn.LAMBDA(_xlpm.E_N2O,_xlpm.GWP_N2O, _xlpm.E_N2O * _xlpm.GWP_N2O)
Name Common_Equations.Common_ConvertN2OToCO2e_LatexEquation: _xlfn.LAMBDA("CO2_e = E_{N2O} \times GWP_{N2O}")
Name Common_Equations.Common_ConvertN2OToCO2e_NIRReference: _xlfn.LAMBDA("")
Name Common_Equations.Common_ConvertN2OToCO2e_Title: _xlfn.LAMBDA("Convert nitrous oxide emissions to carbon dioxide equivalent emissions")
Name Common_Equations.Common_ConvertN2OToCO2e_Unit: _xlfn.LAMBDA("t CO2e")
Name Common_Equations.Common_ConvertN2OToCO2e_Variable: _xlfn.LAMBDA("EN2O CO2e")
Name Common_InputFunctions.Utility_ConvertStateCommonNameToAbbreviation: _xlfn.LAMBDA(_xlpm.StateCommonName,_xlpm.StateCommonNameArray,_xlpm.StateAbbreviationArray, _xlfn.XLOOKUP(_xlpm.StateCommonName, _xlpm.StateCommonNameArray, _xlpm.StateAbbreviationArray, ""))
Name Common_InputFunctions.Utility_DisplayArguments_1_2: _xlfn.LAMBDA(_xlpm.ArgumentsArray, _xlfn.CHOOSECOLS(_xlpm.ArgumentsArray, 1, 2))
Name Common_InputFunctions.Utility_DisplayArguments_3_4: _xlfn.LAMBDA(_xlpm.ArgumentsArray, _xlfn.CHOOSECOLS(_xlpm.ArgumentsArray, 3, 4))
Name Common_InputFunctions.Utility_DisplayFunctionName: _xlfn.LAMBDA(_xlpm.Function, _xlfn.TEXTBEFORE(_xlfn.FORMULATEXT(_xlpm.Function), "("))
Name Common_InputFunctions.Utility_GetArrayTableColumnStartNumber: _xlfn.LAMBDA(_xlpm.TableHeaderCell, COLUMN(_xlpm.TableHeaderCell))
Name Common_InputFunctions.Utility_GetArrayTableRowStartNumber: _xlfn.LAMBDA(_xlpm.TableheaderCell,_xlpm.RowsBetweenHeaderandArray, ROW(_xlpm.TableheaderCell) + _xlpm.RowsBetweenHeaderandArray - 1)
Name Common_InputFunctions.Utility_LookupValueInTable: _xlfn.LAMBDA(_xlpm.LookupValue,_xlpm.LookupArray,_xlpm.ReturnArray, _xlfn.XLOOKUP(_xlpm.LookupValue, _xlpm.LookupArray, _xlpm.ReturnArray, ""))
Name Common_InputFunctions.Utility_ResultsItemFromEquationTitleAndSource: _xlfn.LAMBDA(_xlpm.TitleCell,_xlpm.SourceCell, SUBSTITUTE(LEFT(_xlpm.SourceCell, FIND(",", _xlpm.SourceCell) - 1), "VEERG 2026: ", "") & " " & _xlpm.TitleCell)
Name Common_InputFunctions.Utility_SourceHyperlink: _xlfn.LAMBDA(_xlpm.TargetCell, _xlfn.LET(_xlpm.sh, _xlfn.TEXTAFTER(CELL("filename", _xlpm.TargetCell), "]"), _xlpm.addr, CELL("address", _xlpm.TargetCell), "#'" & _xlpm.sh & "'!" & _xlpm.addr))
Name Common_InputFunctions.Utility_SourceHyperlinkDifferentSheet: _xlfn.LAMBDA(_xlpm.TargetCell, _xlfn.LET(_xlpm.sh, _xlfn.TEXTAFTER(CELL("filename", _xlpm.TargetCell), "]"), _xlpm.addr, CELL("address", _xlpm.TargetCell), "#" & _xlpm.addr))
Name Common_SourceData.Common_SourceData_AustralianStatesTerritories_Source: _xlfn.LAMBDA("")
Name Common_SourceData.Common_SourceData_AustralianStatesTerritories_Title: _xlfn.LAMBDA("Australian states and territories")
Name Common_SourceData.Common_SourceData_AustralianStatesTerritories_Unit: _xlfn.LAMBDA("")
Name Common_SourceData.Common_SourceData_AustralianStatesTerritories_Variable: _xlfn.LAMBDA("")
Name Common_SourceData.Common_SourceData_ClimateZones_Source: _xlfn.LAMBDA("VEERG 2026: Table 1.3: Climate and Rainfall zone classifications and definitions")
Name Common_SourceData.Common_SourceData_ClimateZones_Title: _xlfn.LAMBDA("VEERG Australian climate zones")
Name Common_SourceData.Common_SourceData_ClimateZones_Unit: _xlfn.LAMBDA("")
Name Common_SourceData.Common_SourceData_ClimateZones_Variable: _xlfn.LAMBDA("")
Name Common_SourceData.Common_SourceData_ConvertGasElementalToMolecular_Source: _xlfn.LAMBDA("XXXXXXX")
Name Common_SourceData.Common_SourceData_ConvertGasElementalToMolecular_Title: _xlfn.LAMBDA("Factor to convert elemental mass of gas to molecular mass")
Name Common_SourceData.Common_SourceData_ConvertGasElementalToMolecular_Unit: _xlfn.LAMBDA("factor")
Name Common_SourceData.Common_SourceData_ConvertGasElementalToMolecular_Variable: _xlfn.LAMBDA("Cg")
Name Common_SourceData.Common_SourceData_ConvertN2oElementalToMolecularCg_Data: _xlfn.LAMBDA(44 / 28)
Name Common_SourceData.Common_SourceData_ConvertN2oElementalToMolecularCg_Source: _xlfn.LAMBDA("National Inventory Report 2023 Volume 1")
Name Common_SourceData.Common_SourceData_ConvertN2oElementalToMolecularCg_Title: _xlfn.LAMBDA("Factor to convert elemental mass of N2O to molecular mass")
Name Common_SourceData.Common_SourceData_ConvertN2oElementalToMolecularCg_Unit: _xlfn.LAMBDA("factor")
Name Common_SourceData.Common_SourceData_ConvertN2oElementalToMolecularCg_Variable: _xlfn.LAMBDA("CgN2O")
Name Common_SourceData.Common_SourceData_DataScores_Scope3_Source: _xlfn.LAMBDA("VEERG 2026: XXXXXXXX")
Name Common_SourceData.Common_SourceData_DataScores_Scope3_Title: _xlfn.LAMBDA("Australian data scores for scope 3")
Name Common_SourceData.Common_SourceData_DataScores_Scope3_Unit: _xlfn.LAMBDA("")
Name Common_SourceData.Common_SourceData_DataScores_Scope3_Variable: _xlfn.LAMBDA("")
Name Common_SourceData.Common_SourceData_DataScores_Scope3_Variation: _xlfn.LAMBDA("")
Name Common_SourceData.Common_SourceData_DensityOfMethane_Data: _xlfn.LAMBDA(0.6784)
Name Common_SourceData.Common_SourceData_DensityOfMethane_Source: _xlfn.LAMBDA("National Inventory Report 2023 Volume 1: Equations 3.B.1a_2, 3.B.1c_2, 3.B.3_1, 3.B.4g_2")
Name Common_SourceData.Common_SourceData_DensityOfMethane_Title: _xlfn.LAMBDA("p = density of methane")
Name Common_SourceData.Common_SourceData_DensityOfMethane_Unit: _xlfn.LAMBDA("kg/m3")
Name Common_SourceData.Common_SourceData_EFleach_Data: _xlfn.LAMBDA(_xlfn.MAKEARRAY(1, 2, _xlfn.LAMBDA(_xlpm.r,_xlpm.c, INDEX({"EFleach",0.011}, _xlpm.r, _xlpm.c))))
Name Common_SourceData.Common_SourceData_EFleach_NIRReference: _xlfn.LAMBDA("National Inventory Report Volume 1: Equation 3.D.B_10")
Name Common_SourceData.Common_SourceData_EFleach_Source: _xlfn.LAMBDA("VEERG 2026:5.5.2.3 Constant Parameters")
Name Common_SourceData.Common_SourceData_EFleach_Title: _xlfn.LAMBDA("Emission factor for nitrogen leaching and runoff")
Name Common_SourceData.Common_SourceData_EFleach_Unit: _xlfn.LAMBDA("(kg N2O-N / kg N")
Name Common_SourceData.Common_SourceData_EFleach_Variation: _xlfn.LAMBDA((""))
Name Common_SourceData.Common_SourceData_EFN2O_NIRReference: _xlfn.LAMBDA("")
Name Common_SourceData.Common_SourceData_EFN2O_Source: _xlfn.LAMBDA("VEERG 2026: Table A.2.2.1")
Name Common_SourceData.Common_SourceData_EFN2O_Title: _xlfn.LAMBDA("Nitrous oxide emission factors for inorganic fertiliser application")

Sheet Home
A1: #VALUE!
A3: =HYPERLINK("#'Home'!A1", "Home") -> Home
A6: INPUTS
A7: =HYPERLINK("#'Input - Planting'!A1", "Planting") -> Planting
A8: =HYPERLINK("#'Input - Fertiliser'!A1", "Fertiliser") -> Fertiliser
A9: =HYPERLINK("#'Input - Fuel'!A1", "Fuel") -> Fuel
A10: =HYPERLINK("#'Input - Site'!A1", "Site") -> Site
A13: CALCULATIONS
A14: =HYPERLINK("#'5.1.1.1-2 Inorganic fert N2O'!A1", "5.1.1.1-2 Inorganic fert N2O") -> 5.1.1.1-2 Inorganic fert N2O
A15: =HYPERLINK("#'5.1.1.3-4 Inorganic fert CO2'!A1", "5.1.1.3-4 Inorganic fert CO2") -> 5.1.1.3-4 Inorganic fert CO2
A16: =HYPERLINK("#'5.2.1.1-2 Organic Fert N2O'!A1", "5.2.1.1-2 Organic fert N2O") -> 5.2.1.1-2 Organic fert N2O
A17: =HYPERLINK("#'5.3.1.1-2 Lime CO2'!A1", "5.3.1.1-2 Lime CO2") -> 5.3.1.1-2 Lime CO2
A18: =HYPERLINK("#'5.4.1.1-4 Atmos deposition'!A1", "5.4.1.1-4 Atmos. deposition") -> 5.4.1.1-4 Atmos. deposition
A19: =HYPERLINK("#'5.5.1.1-2 Leaching and runoff'!A1", "5.5.1.1-2 Leaching & runoff") -> 5.5.1.1-2 Leaching & runoff
A20: =HYPERLINK("#'8.1.1.1-2 Transport fuel'!A1", "8.1.1.1-2 Transport fuel") -> 8.1.1.1-2 Transport fuel
A21: =HYPERLINK("#'8.2.1.1-2 Stationary fuel'!A1", "8.2.1.1-2 Stationary fuel") -> 8.2.1.1-2 Stationary fuel
A24: APPENDICES
A25: =HYPERLINK("#'Constants - Fertiliser'!A1", "Constants - Fertiliser") -> Constants - Fertiliser
A26: =HYPERLINK("#'Constants - Fuel'!A1", "Constants - Fuel") -> Constants - Fuel
A27: =HYPERLINK("#'Constants - Common'!A1", "Constants - Common") -> Constants - Common
A28: =HYPERLINK("#'Overview'!A1", "Overview") -> Overview

Sheet Input - Planting
A1: #VALUE!
A3: =HYPERLINK("#'Home'!A1", "Home") -> Home | B3: Latitude | C3: -33.8688
B4: Longitude | C4: 151.2093
B5: Date planted | C5: 43831
A6: INPUTS | B6: Planting name | C6: My cool thing
A7: =HYPERLINK("#'Input - Planting'!A1", "Planting") -> Planting
A8: =HYPERLINK("#'Input - Fertiliser'!A1", "Fertiliser") -> Fertiliser | B8: Planting area in hectares | C8: 100
A9: =HYPERLINK("#'Input - Fuel'!A1", "Fuel") -> Fuel
A10: =HYPERLINK("#'Input - Site'!A1", "Site") -> Site
B11: Emissions calculation period start date | C11: 45658
B12: Emissions calculation period end date | C12: =DATE(YEAR(C11)+1,MONTH(C11),DAY(C11))-1 -> 46022
A13: CALCULATIONS
A14: =HYPERLINK("#'5.1.1.1-2 Inorganic fert N2O'!A1", "5.1.1.1-2 Inorganic fert N2O") -> 5.1.1.1-2 Inorganic fert N2O | B14: FullCAM simulation results
A15: =HYPERLINK("#'5.1.1.3-4 Inorganic fert CO2'!A1", "5.1.1.3-4 Inorganic fert CO2") -> 5.1.1.3-4 Inorganic fert CO2 | B15: Carbon captured per hectare | C15: 123 | D15: tonnes CO2/hectare
A16: =HYPERLINK("#'5.2.1.1-2 Organic Fert N2O'!A1", "5.2.1.1-2 Organic fert N2O") -> 5.2.1.1-2 Organic fert N2O | B16: Total carbon captured | C16: =C8*X_Result_Planting_CarbonCapturedPerHectare -> 12300 | D16: tonnes CO2
A17: =HYPERLINK("#'5.3.1.1-2 Lime CO2'!A1", "5.3.1.1-2 Lime CO2") -> 5.3.1.1-2 Lime CO2
A18: =HYPERLINK("#'5.4.1.1-4 Atmos deposition'!A1", "5.4.1.1-4 Atmos. deposition") -> 5.4.1.1-4 Atmos. deposition
A19: =HYPERLINK("#'5.5.1.1-2 Leaching and runoff'!A1", "5.5.1.1-2 Leaching & runoff") -> 5.5.1.1-2 Leaching & runoff
A20: =HYPERLINK("#'8.1.1.1-2 Transport fuel'!A1", "8.1.1.1-2 Transport fuel") -> 8.1.1.1-2 Transport fuel
A21: =HYPERLINK("#'8.2.1.1-2 Stationary fuel'!A1", "8.2.1.1-2 Stationary fuel") -> 8.2.1.1-2 Stationary fuel
A24: APPENDICES
A25: =HYPERLINK("#'Constants - Fertiliser'!A1", "Constants - Fertiliser") -> Constants - Fertiliser
A26: =HYPERLINK("#'Constants - Fuel'!A1", "Constants - Fuel") -> Constants - Fuel
A27: =HYPERLINK("#'Constants - Common'!A1", "Constants - Common") -> Constants - Common
A28: =HYPERLINK("#'Overview'!A1", "Overview") -> Overview

Sheet Input - Fertiliser
A1: #VALUE! | C1: Input - Fertiliser
A3: =HYPERLINK("#'Home'!A1", "Home") -> Home
A6: INPUTS | D6: Production system | E6: Crop | F6: ← Please select
A7: =HYPERLINK("#'Input - Planting'!A1", "Planting") -> Planting | D7: Crop type | E7: Grains | F7: ← Please select
A8: =HYPERLINK("#'Input - Fertiliser'!A1", "Fertiliser") -> Fertiliser | D8: Irrigation method | E8: Sprinkler Irrigation | F8: ← Please select
A9: =HYPERLINK("#'Input - Fuel'!A1", "Fuel") -> Fuel | D9: Area under cropping | E9: 100 | F9: hectares
A10: =HYPERLINK("#'Input - Site'!A1", "Site") -> Site
D11: Inorganic fertiliser applied
A13: CALCULATIONS | D13: 💡You can add more rows to tables by right-clicking on the table and selecting "Insert > Table rows above/below".
A14: =HYPERLINK("#'5.1.1.1-2 Inorganic fert N2O'!A1", "5.1.1.1-2 Inorganic fert N2O") -> 5.1.1.1-2 Inorganic fert N2O | D14: 💡The application area is the same as the area under pasture / cropping by default. You can edit it if the application area is different.
A15: =HYPERLINK("#'5.1.1.3-4 Inorganic fert CO2'!A1", "5.1.1.3-4 Inorganic fert CO2") -> 5.1.1.3-4 Inorganic fert CO2
A16: =HYPERLINK("#'5.2.1.1-2 Organic Fert N2O'!A1", "5.2.1.1-2 Organic fert N2O") -> 5.2.1.1-2 Organic fert N2O | D16: Branded fertiliser products
A17: =HYPERLINK("#'5.3.1.1-2 Lime CO2'!A1", "5.3.1.1-2 Lime CO2") -> 5.3.1.1-2 Lime CO2 | D17: Product (select) | E17: Amount applied per hectare | F17: Application unit | G17: Density | H17: Application area (ha) | I17: Total applied (kg) | J17: Ingredient 1 | K17: Ingredient 1 percent | L17: Ingredient 2 | M17: Ingredient 2 percent | N17: Ingredient 3 | O17: Ingredient 3 percent | P17: Ingredient 4 | Q17: Ingredient 4 percent | R17: Ingredient 5 | S17: Ingredient 5 percent | T17: Ingredient 6 | U17: Ingredient 6 percent | V17: N application rate (kg/ha) | W17: Urea source | X17: Ammonia source
A18: =HYPERLINK("#'5.4.1.1-4 Atmos deposition'!A1", "5.4.1.1-4 Atmos. deposition") -> 5.4.1.1-4 Atmos. deposition | D18: Aqua Finish | E18: 100 | F18: L | G18: 1.26 | H18: 100 | I18: 12600 | J18: Potassium - Generic | K18: 0.225 | L18: Phosphorus - Generic | M18: 0.04 | N18: Nitrogen - Generic | O18: 0.026 | V18: 3.276
A19: =HYPERLINK("#'5.5.1.1-2 Leaching and runoff'!A1", "5.5.1.1-2 Leaching & runoff") -> 5.5.1.1-2 Leaching & runoff | D19: CalPhos | E19: 100 | F19: L | G19: 1.285 | H19: 100 | I19: 12850 | J19: Phosphorus - Generic | K19: 0.135 | L19: Calcium - Generic | M19: 0.04 | V19: 0
A20: =HYPERLINK("#'8.1.1.1-2 Transport fuel'!A1", "8.1.1.1-2 Transport fuel") -> 8.1.1.1-2 Transport fuel | D20: CalPhos | E20: 100 | F20: L | G20: 1.285 | H20: 100 | I20: 12850 | J20: Phosphorus - Generic | K20: 0.135 | L20: Calcium - Generic | M20: 0.04 | V20: 0
A21: =HYPERLINK("#'8.2.1.1-2 Stationary fuel'!A1", "8.2.1.1-2 Stationary fuel") -> 8.2.1.1-2 Stationary fuel | D21: Aqua Grow | E21: 100 | F21: L | G21: 1.26 | H21: 100 | I21: 12600 | J21: Potassium - Generic | K21: 0.105 | L21: Nitrogen - Generic | M21: 0.096 | N21: Phosphorus - Generic | O21: 0.05 | V21: 12.096
D22: Aqua NitroCal | E22: 100 | F22: L | G22: 1.5 | H22: 100 | I22: 15000 | J22: Calcium - Generic | K22: 0.162 | L22: Nitrogen - Nitrate | M22: 0.132 | V22: 19.8
A24: APPENDICES | D24: Custom fertiliser blends
A25: =HYPERLINK("#'Constants - Fertiliser'!A1", "Constants - Fertiliser") -> Constants - Fertiliser | D25: Custom blend name | E25: Amount applied (kg / ha) | F25: Application area (ha) | G25: Total applied (kg) | H25: Ingredient 1 (select) | I25: Ingredient 1 percent | J25: Ingredient 2 | K25: Ingredient 2 percent | L25: Ingredient 3 | M25: Ingredient 3 percent | N25: Ingredient 4 | O25: Ingredient 4 percent | P25: N application rate (kg/ha) | Q25: Urea source (Select) | R25: Ammonia source (select)
A26: =HYPERLINK("#'Constants - Fuel'!A1", "Constants - Fuel") -> Constants - Fuel | D26: My first custom blend | E26: 100 | F26: 100 | G26: 10000 | H26: Calcium nitrate | I26: 0.5 | J26: Zinc - Generic | K26: 0.2 | L26: Potassium - Generic | M26: 0.2 | N26: Sulfur - Generic | O26: 0.1 | P26: 7.75
A27: =HYPERLINK("#'Constants - Common'!A1", "Constants - Common") -> Constants - Common | D27: My second custom blend | E27: 100 | F27: 100 | G27: 10000 | H27: Urea | I27: 1 | P27: 46
A28: =HYPERLINK("#'Overview'!A1", "Overview") -> Overview | D28: My third custom blend | E28: 100 | F28: 100 | G28: 10000 | H28: Ammonia | I28: 0.5 | P28: 41.175
D30: Soil ameliorants (lime)
D32: 💡 You can add more rows to the table by right-clicking on the table and selecting "Insert > Table rows above/below".
D33: 💡 'Lime' refers to calcium carbonate - CaCO3. 'Dolomite' refers to calcium magnesium carbonate - CaMg(CO3)2
D34: 💡The application area is the same as the area under pasture / cropping by default. You can edit it if the application area is different.
D35: =IF(MAX(Table_Input_Lime[Total]) > 1, "There can not be more than 100% ingredients in a product. Check the table below.", "")
D36: Product | E36: Amount applied (t/hectare) | F36: Application area (ha) | G36: Total amount applied (t) | H36: Percent Lime CaCO3 | I36: Percent Dolomite CaMg(CO3)2 | J36: Percent Gypsum | K36: Total
D37: Lime product 1 | E37: 1 | F37: 100 | G37: 100 | H37: 0.8 | I37: 0.1 | J37: 0.1 | K37: =SUM(Table_Input_Lime[[#This Row],[Percent Lime CaCO3]:[Percent Gypsum]]) -> 1
D38: Lime product 2 | E38: 1 | F38: 100 | G38: 100 | H38: 1 | K38: =SUM(Table_Input_Lime[[#This Row],[Percent Lime CaCO3]:[Percent Gypsum]]) -> 1
D39: Lime product 3 | E39: 1 | F39: 100 | G39: 100 | H39: 0 | J39: 1 | K39: =SUM(Table_Input_Lime[[#This Row],[Percent Lime CaCO3]:[Percent Gypsum]]) -> 1
D42: Organic fertiliser applied
D44: 💡 You can add more rows to the table by right-clicking on the table and selecting "Insert > Table rows above/below".
D45: 💡The application area is the same as the area under pasture / cropping by default. You can edit it if the application area is different.
D47: Organic fertiliser type (select) | E47: Percentage of N in fertiliser | F47: Amount applied (kg/hectare) | G47: Amount N applied (kg/hectare) | H47: Application area (ha) | I47: Total organic fertliser applied | J47: Total nitrogen applied (kg)
D48: Manure - Other | E48: 0.3 | F48: 10 | G48: 3 | H48: 100 | I48: 1000 | J48: 300
D49: Manure - Poultry | E49: 0.25 | F49: 10 | G49: 2.5 | H49: 100 | I49: 1000 | J49: 250
D50: Other organic fertiliser | E50: 0.16 | F50: 10 | G50: 1.6 | H50: 100 | I50: 1000 | J50: 160

Sheet Input - Fuel
A1: #VALUE! | C1: Input - Fuel
A3: =HYPERLINK("#'Home'!A1", "Home") -> Home
D5: Fuel purchases and consumption
A6: INPUTS
A7: =HYPERLINK("#'Input - Planting'!A1", "Planting") -> Planting | D7: A 'Metropolitan' location is:
A8: =HYPERLINK("#'Input - Fertiliser'!A1", "Fertiliser") -> Fertiliser | D8: ● On or east of the dividing range in NSW (including Canberra and Queanbeyan)
A9: =HYPERLINK("#'Input - Fuel'!A1", "Fuel") -> Fuel | D9: ● In Melbourne, Brisbane, Adelaide or Perth
A10: =HYPERLINK("#'Input - Site'!A1", "Site") -> Site
D11: Is the property in a Metropolitan location? | E11: Metro | F11: ← Please select
A13: CALCULATIONS | D13: 💡 You can add more rows to the table by right-clicking on the table and selecting "Insert > Table rows above/below"
A14: =HYPERLINK("#'5.1.1.1-2 Inorganic fert N2O'!A1", "5.1.1.1-2 Inorganic fert N2O") -> 5.1.1.1-2 Inorganic fert N2O | D14: 💡 'Percent consumed" is 100% by default. If you purchased more fuel than was consumed you can edit this field.
A15: =HYPERLINK("#'5.1.1.3-4 Inorganic fert CO2'!A1", "5.1.1.3-4 Inorganic fert CO2") -> 5.1.1.3-4 Inorganic fert CO2
A16: =HYPERLINK("#'5.2.1.1-2 Organic Fert N2O'!A1", "5.2.1.1-2 Organic fert N2O") -> 5.2.1.1-2 Organic fert N2O | D16: Fuel use (select) | E16: Fuel type (select) | F16: Amount purchased | G16: Amount unit | H16: Percent consumed | I16: Amount consumed | J16: Amount consumed unit
A17: =HYPERLINK("#'5.3.1.1-2 Lime CO2'!A1", "5.3.1.1-2 Lime CO2") -> 5.3.1.1-2 Lime CO2 | D17: Power standalone machinery or heating | E17: Town gas in GJ | F17: 100 | G17: GJ | H17: 1 | I17: =Table_Input_Fuel[[#This Row],[Amount purchased]]*Table_Input_Fuel[[#This Row],[Percent consumed]]*IF(Table_Input_Fuel[[#This Row],[Amount unit]]="L", 10^-3, 1) -> 100 | J17: {=Common_InputFunctions.Utility_LookupValueInTable(Table_Input_Fuel[[#This Row],[Fuel type (select)]],Table_FuelTypes_Units[Fuel type], Table_FuelTypes_Units[Unit])} -> GJ
A18: =HYPERLINK("#'5.4.1.1-4 Atmos deposition'!A1", "5.4.1.1-4 Atmos. deposition") -> 5.4.1.1-4 Atmos. deposition | D18: Power standalone machinery or heating | E18: Petrol | F18: 10000 | G18: L | H18: 1 | I18: =Table_Input_Fuel[[#This Row],[Amount purchased]]*Table_Input_Fuel[[#This Row],[Percent consumed]]*IF(Table_Input_Fuel[[#This Row],[Amount unit]]="L", 10^-3, 1) -> 10 | J18: {=Common_InputFunctions.Utility_LookupValueInTable(Table_Input_Fuel[[#This Row],[Fuel type (select)]],Table_FuelTypes_Units[Fuel type], Table_FuelTypes_Units[Unit])} -> kL
A19: =HYPERLINK("#'5.5.1.1-2 Leaching and runoff'!A1", "5.5.1.1-2 Leaching & runoff") -> 5.5.1.1-2 Leaching & runoff | D19: Cars and light commercial vehicles | E19: Diesel | F19: 10000 | G19: L | H19: 1 | I19: =Table_Input_Fuel[[#This Row],[Amount purchased]]*Table_Input_Fuel[[#This Row],[Percent consumed]]*IF(Table_Input_Fuel[[#This Row],[Amount unit]]="L", 10^-3, 1) -> 10 | J19: {=Common_InputFunctions.Utility_LookupValueInTable(Table_Input_Fuel[[#This Row],[Fuel type (select)]],Table_FuelTypes_Units[Fuel type], Table_FuelTypes_Units[Unit])} -> kL
A20: =HYPERLINK("#'8.1.1.1-2 Transport fuel'!A1", "8.1.1.1-2 Transport fuel") -> 8.1.1.1-2 Transport fuel | D20: Off-road Agriculture and forestry equipment | E20: Diesel | F20: 10000 | G20: L | H20: 1 | I20: =Table_Input_Fuel[[#This Row],[Amount purchased]]*Table_Input_Fuel[[#This Row],[Percent consumed]]*IF(Table_Input_Fuel[[#This Row],[Amount unit]]="L", 10^-3, 1) -> 10 | J20: {=Common_InputFunctions.Utility_LookupValueInTable(Table_Input_Fuel[[#This Row],[Fuel type (select)]],Table_FuelTypes_Units[Fuel type], Table_FuelTypes_Units[Unit])} -> kL
A21: =HYPERLINK("#'8.2.1.1-2 Stationary fuel'!A1", "8.2.1.1-2 Stationary fuel") -> 8.2.1.1-2 Stationary fuel | D21: Vessels | E21: Fuel oil | F21: 10000 | G21: L | H21: 1 | I21: =Table_Input_Fuel[[#This Row],[Amount purchased]]*Table_Input_Fuel[[#This Row],[Percent consumed]]*IF(Table_Input_Fuel[[#This Row],[Amount unit]]="L", 10^-3, 1) -> 10 | J21: {=Common_InputFunctions.Utility_LookupValueInTable(Table_Input_Fuel[[#This Row],[Fuel type (select)]],Table_FuelTypes_Units[Fuel type], Table_FuelTypes_Units[Unit])} -> kL
A24: APPENDICES
A25: =HYPERLINK("#'Constants - Fertiliser'!A1", "Constants - Fertiliser") -> Constants - Fertiliser
A26: =HYPERLINK("#'Constants - Fuel'!A1", "Constants - Fuel") -> Constants - Fuel
A27: =HYPERLINK("#'Constants - Common'!A1", "Constants - Common") -> Constants - Common
A28: =HYPERLINK("#'Overview'!A1", "Overview") -> Overview

Sheet 5.1.1.1-2 Inorganic fert N2O
A1: #VALUE! | C1: 5.1.1.1-2 Inorganic fertiliser application N2O emissions
A3: =HYPERLINK("#'Home'!A1", "Home") -> Home | D3: Method 1 | M3: Method 2
D5: {=Fertiliser_Equations_InorganicN2O.VEERG_5_1_1_1__2_MassOfNitrogenInInorganicFertiliser_Title()} -> Mass of nitrogen in inorganic fertiliser applied to production system | M5: {=Fertiliser_Equations_InorganicN2O.VEERG_5_1_1_2__1_EmissionFactorIrrigatedMaize_Title()} -> Emission factor for nitrous oxide for irrigated maize
A6: INPUTS | D6: {=Fertiliser_Equations_InorganicN2O.VEERG_5_1_1_1__2_MassOfNitrogenInInorganicFertiliser_Source()} -> VEERG 2026: 5.1.1.1, Equation (2) | M6: {=Fertiliser_Equations_InorganicN2O.VEERG_5_1_1_2__1_EmissionFactorIrrigatedMaize_Source()} -> VEERG 2026: 5.1.1.2, Equation (1)
A7: =HYPERLINK("#'Input - Planting'!A1", "Planting") -> Planting | D7: Function name | E7: {=Common_InputFunctions.Utility_DisplayFunctionName(G19)} -> =Fertiliser_Equations_InorganicN2O.VEERG_5_1_1_1__2_MassOfNitrogenInInorganicFertiliser
A8: =HYPERLINK("#'Input - Fertiliser'!A1", "Fertiliser") -> Fertiliser
A9: =HYPERLINK("#'Input - Fuel'!A1", "Fuel") -> Fuel | M9: Variable | N9: {=Fertiliser_Equations_InorganicN2O.VEERG_5_1_1_2__1_EmissionFactorIrrigatedMaize_Variable()} -> EF_fjIrrigatedMaizeN2O
A10: =HYPERLINK("#'Input - Site'!A1", "Site") -> Site | D10: Variable | E10: {=Fertiliser_Equations_InorganicN2O.VEERG_5_1_1_1__2_MassOfNitrogenInInorganicFertiliser_Variable()} -> MN_jf | M10: Unit | N10: {=Fertiliser_Equations_InorganicN2O.VEERG_5_1_1_2__1_EmissionFactorIrrigatedMaize_Unit()} -> kg N2O-N/kg N applied
D11: Unit | E11: {=Fertiliser_Equations_InorganicN2O.VEERG_5_1_1_1__2_MassOfNitrogenInInorganicFertiliser_Unit()} -> kg N
M12: {=_xlfn.CHOOSECOLS(Fertiliser_Equations_InorganicN2O.VEERG_5_1_1_2__1_EmissionFactorIrrigatedMaize_Arguments(), 1, 2)} -> N_fjIrrigatedMaize | N12: application rate of inorganic fertiliser type f in the irrigated maize crop | P12: {=_xlfn.CHOOSECOLS(Fertiliser_Equations_InorganicN2O.VEERG_5_1_1_2__1_EmissionFactorIrrigatedMaize_Arguments(), 3,4)} -> kg N/ha | Q12: Input | R12: {=HYPERLINK(Common_InputFunctions.Utility_SourceHyperlink($M$41), $M$41)} -> M2_Table_FertApplications
A13: CALCULATIONS | D13: {=_xlfn.CHOOSECOLS(Fertiliser_Equations_InorganicN2O.VEERG_5_1_1_1__2_MassOfNitrogenInInorganicFertiliser_Arguments(), 1,2)} -> TM_jf | E13: total mass of inorganic fertiliser type f applied to production system j | G13: {=_xlfn.CHOOSECOLS(Fertiliser_Equations_InorganicN2O.VEERG_5_1_1_1__2_MassOfNitrogenInInorganicFertiliser_Arguments(), 3,4)} -> kg | H13: Input | I13: {=HYPERLINK(Common_InputFunctions.Utility_SourceHyperlink($D$16), $D$16)} -> Table_MN_j_f | M13: f | N13: Inorganic fertiliser type | Q13: Constant | R13: Not used - application rate calculated per product blend application
A14: =HYPERLINK("#'5.1.1.1-2 Inorganic fert N2O'!A1", "5.1.1.1-2 Inorganic fert N2O") -> 5.1.1.1-2 Inorganic fert N2O | D14: FN_inorganicf | E14: fraction of nitrogen in inorganic fertiliser type f | G14: kg N/kg | H14: Constant | I14: {=HYPERLINK(Common_InputFunctions.Utility_SourceHyperlink($D$16), $D$16)} -> Table_MN_j_f
A15: =HYPERLINK("#'5.1.1.3-4 Inorganic fert CO2'!A1", "5.1.1.3-4 Inorganic fert CO2") -> 5.1.1.3-4 Inorganic fert CO2
A16: =HYPERLINK("#'5.2.1.1-2 Organic Fert N2O'!A1", "5.2.1.1-2 Organic fert N2O") -> 5.2.1.1-2 Organic fert N2O | D16: Table_MN_j_f | M16: {=Fertiliser_Equations_InorganicN2O.VEERG_5_1_1_2__2_EmissionFactorNonIrrigatedGrainsHighRainfall_Title()} -> Emission factor for nitrous oxide for non-irrigated grains in high rainfall zone
A17: =HYPERLINK("#'5.3.1.1-2 Lime CO2'!A1", "5.3.1.1-2 Lime CO2") -> 5.3.1.1-2 Lime CO2 | D17: Mass of nitrogen applied | M17: {=Fertiliser_Equations_InorganicN2O.VEERG_5_1_1_2__2_EmissionFactorNonIrrigatedGrainsHighRainfall_Source()} -> VEERG 2026: 5.1.1.2, Equation (2)
A18: =HYPERLINK("#'5.4.1.1-4 Atmos deposition'!A1", "5.4.1.1-4 Atmos. deposition") -> 5.4.1.1-4 Atmos. deposition | D18: Fertiliser type f | E18: TMjf | F18: FNinorganic,f | G18: MNjf
A19: =HYPERLINK("#'5.5.1.1-2 Leaching and runoff'!A1", "5.5.1.1-2 Leaching & runoff") -> 5.5.1.1-2 Leaching & runoff | D19: {=Table_Fertiliser_ChemicalCompounds[Fertiliser type f]} -> Monoammonium phosphate (MAP) | E19: {=Fertiliser_InputFunctions.Fertiliser_TotalChemicalCompoundAppliedAllIngredients($D19,Table_Input_InorganicFertiliser_Brands[Total applied (kg)],Table_Input_InorganicFertiliser_Brands[Ingredient 1],Table_Input_InorganicFertiliser_Brands[Ingredient 1 percent],Table_Input_InorganicFertiliser_Brands[Ingredient 2],Table_Input_InorganicFertiliser_Brands[Ingredient 2 percent],Table_Input_InorganicFertiliser_Brands[Ingredient 3],Table_Input_InorganicFertiliser_Brands[Ingredient 3 percent],Table_Input_InorganicFertiliser_Brands[Ingredient 4],Table_Input_InorganicFertiliser_Brands[Ingredient 4 percent],Table_Input_InorganicFertiliser_Brands[Ingredient 5],Table_Input_InorganicFertiliser_Brands[Ingredient 5 percent],Table_Input_InorganicFertiliser_Brands[Ingredient 6],Table_Input_InorganicFertiliser_Brands[Ingredient 6 percent])+ Fertiliser_InputFunctions.Fertiliser_TotalChemicalCompoundAppliedAllIngredients($D19,Table_Input_InorganicFertiliser_Custom[Total applied (kg)],Table_Input_InorganicFertiliser_Custom[Ingredient 1 (select)],Table_Input_InorganicFertiliser_Custom[Ingredient 1 percent],Table_Input_InorganicFertiliser_Custom[Ingredient 2],Table_Input_InorganicFertiliser_Custom[Ingredient 2 percent],Table_Input_InorganicFertiliser_Custom[Ingredient 3],Table_Input_InorganicFertiliser_Custom[Ingredient 3 percent],Table_Input_InorganicFertiliser_Custom[Ingredient 4],Table_Input_InorganicFertiliser_Custom[Ingredient 4 percent])} -> 0 | F19: {=Common_InputFunctions.Utility_LookupValueInTableNumber(D19,Table_Fertiliser_ChemicalCompounds[Fertiliser type f],Table_Fertiliser_ChemicalCompounds[FNinorganic f])} -> 0.1 | G19: {=Fertiliser_Equations_InorganicN2O.VEERG_5_1_1_1__2_MassOfNitrogenInInorganicFertiliser(E19,F19)} -> 0
A20: =HYPERLINK("#'8.1.1.1-2 Transport fuel'!A1", "8.1.1.1-2 Transport fuel") -> 8.1.1.1-2 Transport fuel | D20: Diammonium phosphate (DAP) | E20: {=Fertiliser_InputFunctions.Fertiliser_TotalChemicalCompoundAppliedAllIngredients($D20,Table_Input_InorganicFertiliser_Brands[Total applied (kg)],Table_Input_InorganicFertiliser_Brands[Ingredient 1],Table_Input_InorganicFertiliser_Brands[Ingredient 1 percent],Table_Input_InorganicFertiliser_Brands[Ingredient 2],Table_Input_InorganicFertiliser_Brands[Ingredient 2 percent],Table_Input_InorganicFertiliser_Brands[Ingredient 3],Table_Input_InorganicFertiliser_Brands[Ingredient 3 percent],Table_Input_InorganicFertiliser_Brands[Ingredient 4],Table_Input_InorganicFertiliser_Brands[Ingredient 4 percent],Table_Input_InorganicFertiliser_Brands[Ingredient 5],Table_Input_InorganicFertiliser_Brands[Ingredient 5 percent],Table_Input_InorganicFertiliser_Brands[Ingredient 6],Table_Input_InorganicFertiliser_Brands[Ingredient 6 percent])+ Fertiliser_InputFunctions.Fertiliser_TotalChemicalCompoundAppliedAllIngredients($D20,Table_Input_InorganicFertiliser_Custom[Total applied (kg)],Table_Input_InorganicFertiliser_Custom[Ingredient 1 (select)],Table_Input_InorganicFertiliser_Custom[Ingredient 1 percent],Table_Input_InorganicFertiliser_Custom[Ingredient 2],Table_Input_InorganicFertiliser_Custom[Ingredient 2 percent],Table_Input_InorganicFertiliser_Custom[Ingredient 3],Table_Input_InorganicFertiliser_Custom[Ingredient 3 percent],Table_Input_InorganicFertiliser_Custom[Ingredient 4],Table_Input_InorganicFertiliser_Custom[Ingredient 4 percent])} -> 0 | F20: {=Common_InputFunctions.Utility_LookupValueInTableNumber(D20,Table_Fertiliser_ChemicalCompounds[Fertiliser type f],Table_Fertiliser_ChemicalCompounds[FNinorganic f])} -> 0.18 | G20: {=Fertiliser_Equations_InorganicN2O.VEERG_5_1_1_1__2_MassOfNitrogenInInorganicFertiliser(E20,F20)} -> 0 | M20: Variable | N20: {=Fertiliser_Equations_InorganicN2O.VEERG_5_1_1_2__2_EmissionFactorNonIrrigatedGrainsHighRainfall_Variable()} -> EF_fjNonIrrigatedGrainsN2O
A21: =HYPERLINK("#'8.2.1.1-2 Stationary fuel'!A1", "8.2.1.1-2 Stationary fuel") -> 8.2.1.1-2 Stationary fuel | D21: Urea | E21: {=Fertiliser_InputFunctions.Fertiliser_TotalChemicalCompoundAppliedAllIngredients($D21,Table_Input_InorganicFertiliser_Brands[Total applied (kg)],Table_Input_InorganicFertiliser_Brands[Ingredient 1],Table_Input_InorganicFertiliser_Brands[Ingredient 1 percent],Table_Input_InorganicFertiliser_Brands[Ingredient 2],Table_Input_InorganicFertiliser_Brands[Ingredient 2 percent],Table_Input_InorganicFertiliser_Brands[Ingredient 3],Table_Input_InorganicFertiliser_Brands[Ingredient 3 percent],Table_Input_InorganicFertiliser_Brands[Ingredient 4],Table_Input_InorganicFertiliser_Brands[Ingredient 4 percent],Table_Input_InorganicFertiliser_Brands[Ingredient 5],Table_Input_InorganicFertiliser_Brands[Ingredient 5 percent],Table_Input_InorganicFertiliser_Brands[Ingredient 6],Table_Input_InorganicFertiliser_Brands[Ingredient 6 percent])+ Fertiliser_InputFunctions.Fertiliser_TotalChemicalCompoundAppliedAllIngredients($D21,Table_Input_InorganicFertiliser_Custom[Total applied (kg)],Table_Input_InorganicFertiliser_Custom[Ingredient 1 (select)],Table_Input_InorganicFertiliser_Custom[Ingredient 1 percent],Table_Input_InorganicFertiliser_Custom[Ingredient 2],Table_Input_InorganicFertiliser_Custom[Ingredient 2 percent],Table_Input_InorganicFertiliser_Custom[Ingredient 3],Table_Input_InorganicFertiliser_Custom[Ingredient 3 percent],Table_Input_InorganicFertiliser_Custom[Ingredient 4],Table_Input_InorganicFertiliser_Custom[Ingredient 4 percent])} -> 10000 | F21: {=Common_InputFunctions.Utility_LookupValueInTableNumber(D21,Table_Fertiliser_ChemicalCompounds[Fertiliser type f],Table_Fertiliser_ChemicalCompounds[FNinorganic f])} -> 0.46 | G21: {=Fertiliser_Equations_InorganicN2O.VEERG_5_1_1_1__2_MassOfNitrogenInInorganicFertiliser(E21,F21)} -> 4600 | M21: Unit | N21: {=Fertiliser_Equations_InorganicN2O.VEERG_5_1_1_2__2_EmissionFactorNonIrrigatedGrainsHighRainfall_Unit()} -> kg N2O-N/kg N applied
D22: Sulphate of ammonia (SOA) | E22: {=Fertiliser_InputFunctions.Fertiliser_TotalChemicalCompoundAppliedAllIngredients($D22,Table_Input_InorganicFertiliser_Brands[Total applied (kg)],Table_Input_InorganicFertiliser_Brands[Ingredient 1],Table_Input_InorganicFertiliser_Brands[Ingredient 1 percent],Table_Input_InorganicFertiliser_Brands[Ingredient 2],Table_Input_InorganicFertiliser_Brands[Ingredient 2 percent],Table_Input_InorganicFertiliser_Brands[Ingredient 3],Table_Input_InorganicFertiliser_Brands[Ingredient 3 percent],Table_Input_InorganicFertiliser_Brands[Ingredient 4],Table_Input_InorganicFertiliser_Brands[Ingredient 4 percent],Table_Input_InorganicFertiliser_Brands[Ingredient 5],Table_Input_InorganicFertiliser_Brands[Ingredient 5 percent],Table_Input_InorganicFertiliser_Brands[Ingredient 6],Table_Input_InorganicFertiliser_Brands[Ingredient 6 percent])+ Fertiliser_InputFunctions.Fertiliser_TotalChemicalCompoundAppliedAllIngredients($D22,Table_Input_InorganicFertiliser_Custom[Total applied (kg)],Table_Input_InorganicFertiliser_Custom[Ingredient 1 (select)],Table_Input_InorganicFertiliser_Custom[Ingredient 1 percent],Table_Input_InorganicFertiliser_Custom[Ingredient 2],Table_Input_InorganicFertiliser_Custom[Ingredient 2 percent],Table_Input_InorganicFertiliser_Custom[Ingredient 3],Table_Input_InorganicFertiliser_Custom[Ingredient 3 percent],Table_Input_InorganicFertiliser_Custom[Ingredient 4],Table_Input_InorganicFertiliser_Custom[Ingredient 4 percent])} -> 0 | F22: {=Common_InputFunctions.Utility_LookupValueInTableNumber(D22,Table_Fertiliser_ChemicalCompounds[Fertiliser type f],Table_Fertiliser_ChemicalCompounds[FNinorganic f])} -> 0.21 | G22: {=Fertiliser_Equations_InorganicN2O.VEERG_5_1_1_1__2_MassOfNitrogenInInorganicFertiliser(E22,F22)} -> 0
D23: Urea-ammonium nitrate (UAN) | E23: {=Fertiliser_InputFunctions.Fertiliser_TotalChemicalCompoundAppliedAllIngredients($D23,Table_Input_InorganicFertiliser_Brands[Total applied (kg)],Table_Input_InorganicFertiliser_Brands[Ingredient 1],Table_Input_InorganicFertiliser_Brands[Ingredient 1 percent],Table_Input_InorganicFertiliser_Brands[Ingredient 2],Table_Input_InorganicFertiliser_Brands[Ingredient 2 percent],Table_Input_InorganicFertiliser_Brands[Ingredient 3],Table_Input_InorganicFertiliser_Brands[Ingredient 3 percent],Table_Input_InorganicFertiliser_Brands[Ingredient 4],Table_Input_InorganicFertiliser_Brands[Ingredient 4 percent],Table_Input_InorganicFertiliser_Brands[Ingredient 5],Table_Input_InorganicFertiliser_Brands[Ingredient 5 percent],Table_Input_InorganicFertiliser_Brands[Ingredient 6],Table_Input_InorganicFertiliser_Brands[Ingredient 6 percent])+ Fertiliser_InputFunctions.Fertiliser_TotalChemicalCompoundAppliedAllIngredients($D23,Table_Input_InorganicFertiliser_Custom[Total applied (kg)],Table_Input_InorganicFertiliser_Custom[Ingredient 1 (select)],Table_Input_InorganicFertiliser_Custom[Ingredient 1 percent],Table_Input_InorganicFertiliser_Custom[Ingredient 2],Table_Input_InorganicFertiliser_Custom[Ingredient 2 percent],Table_Input_InorganicFertiliser_Custom[Ingredient 3],Table_Input_InorganicFertiliser_Custom[Ingredient 3 percent],Table_Input_InorganicFertiliser_Custom[Ingredient 4],Table_Input_InorganicFertiliser_Custom[Ingredient 4 percent])} -> 0 | F23: {=Common_InputFunctions.Utility_LookupValueInTableNumber(D23,Table_Fertiliser_ChemicalCompounds[Fertiliser type f],Table_Fertiliser_ChemicalCompounds[FNinorganic f])} -> 0.32 | G23: {=Fertiliser_Equations_InorganicN2O.VEERG_5_1_1_1__2_MassOfNitrogenInInorganicFertiliser(E23,F23)} -> 0 | M23: {=_xlfn.CHOOSECOLS(Fertiliser_Equations_InorganicN2O.VEERG_5_1_1_2__2_EmissionFactorNonIrrigatedGrainsHighRainfall_Arguments(), 1, 2)} -> N_fjNonIrrigatedGrains | N23: application rate of inorganic fertiliser type f in the grains crop | P23: {=_xlfn.CHOOSECOLS(Fertiliser_Equations_InorganicN2O.VEERG_5_1_1_2__2_EmissionFactorNonIrrigatedGrainsHighRainfall_Arguments(), 3,4)} -> kg N/ha | Q23: Input | R23: {=HYPERLINK(Common_InputFunctions.Utility_SourceHyperlink($M$41), $M$41)} -> M2_Table_FertApplications
A24: APPENDICES | D24: Ammonium nitrate (AN) | E24: {=Fertiliser_InputFunctions.Fertiliser_TotalChemicalCompoundAppliedAllIngredients($D24,Table_Input_InorganicFertiliser_Brands[Total applied (kg)],Table_Input_InorganicFertiliser_Brands[Ingredient 1],Table_Input_InorganicFertiliser_Brands[Ingredient 1 percent],Table_Input_InorganicFertiliser_Brands[Ingredient 2],Table_Input_InorganicFertiliser_Brands[Ingredient 2 percent],Table_Input_InorganicFertiliser_Brands[Ingredient 3],Table_Input_InorganicFertiliser_Brands[Ingredient 3 percent],Table_Input_InorganicFertiliser_Brands[Ingredient 4],Table_Input_InorganicFertiliser_Brands[Ingredient 4 percent],Table_Input_InorganicFertiliser_Brands[Ingredient 5],Table_Input_InorganicFertiliser_Brands[Ingredient 5 percent],Table_Input_InorganicFertiliser_Brands[Ingredient 6],Table_Input_InorganicFertiliser_Brands[Ingredient 6 percent])+ Fertiliser_InputFunctions.Fertiliser_TotalChemicalCompoundAppliedAllIngredients($D24,Table_Input_InorganicFertiliser_Custom[Total applied (kg)],Table_Input_InorganicFertiliser_Custom[Ingredient 1 (select)],Table_Input_InorganicFertiliser_Custom[Ingredient 1 percent],Table_Input_InorganicFertiliser_Custom[Ingredient 2],Table_Input_InorganicFertiliser_Custom[Ingredient 2 percent],Table_Input_InorganicFertiliser_Custom[Ingredient 3],Table_Input_InorganicFertiliser_Custom[Ingredient 3 percent],Table_Input_InorganicFertiliser_Custom[Ingredient 4],Table_Input_InorganicFertiliser_Custom[Ingredient 4 percent])} -> 0 | F24: {=Common_InputFunctions.Utility_LookupValueInTableNumber(D24,Table_Fertiliser_ChemicalCompounds[Fertiliser type f],Table_Fertiliser_ChemicalCompounds[FNinorganic f])} -> 0.337 | G24: {=Fertiliser_Equations_InorganicN2O.VEERG_5_1_1_1__2_MassOfNitrogenInInorganicFertiliser(E24,F24)} -> 0 | M24: f | N24: Inorganic fertiliser type | Q24: Constant | R24: Not used - application rate calculated per product blend application
A25: =HYPERLINK("#'Constants - Fertiliser'!A1", "Constants - Fertiliser") -> Constants - Fertiliser | D25: Calcium ammonium nitrate (CAN) | E25: {=Fertiliser_InputFunctions.Fertiliser_TotalChemicalCompoundAppliedAllIngredients($D25,Table_Input_InorganicFertiliser_Brands[Total applied (kg)],Table_Input_InorganicFertiliser_Brands[Ingredient 1],Table_Input_InorganicFertiliser_Brands[Ingredient 1 percent],Table_Input_InorganicFertiliser_Brands[Ingredient 2],Table_Input_InorganicFertiliser_Brands[Ingredient 2 percent],Table_Input_InorganicFertiliser_Brands[Ingredient 3],Table_Input_InorganicFertiliser_Brands[Ingredient 3 percent],Table_Input_InorganicFertiliser_Brands[Ingredient 4],Table_Input_InorganicFertiliser_Brands[Ingredient 4 percent],Table_Input_InorganicFertiliser_Brands[Ingredient 5],Table_Input_InorganicFertiliser_Brands[Ingredient 5 percent],Table_Input_InorganicFertiliser_Brands[Ingredient 6],Table_Input_InorganicFertiliser_Brands[Ingredient 6 percent])+ Fertiliser_InputFunctions.Fertiliser_TotalChemicalCompoundAppliedAllIngredients($D25,Table_Input_InorganicFertiliser_Custom[Total applied (kg)],Table_Input_InorganicFertiliser_Custom[Ingredient 1 (select)],Table_Input_InorganicFertiliser_Custom[Ingredient 1 percent],Table_Input_InorganicFertiliser_Custom[Ingredient 2],Table_Input_InorganicFertiliser_Custom[Ingredient 2 percent],Table_Input_InorganicFertiliser_Custom[Ingredient 3],Table_Input_InorganicFertiliser_Custom[Ingredient 3 percent],Table_Input_InorganicFertiliser_Custom[Ingredient 4],Table_Input_InorganicFertiliser_Custom[Ingredient 4 percent])} -> 0 | F25: {=Common_InputFunctions.Utility_LookupValueInTableNumber(D25,Table_Fertiliser_ChemicalCompounds[Fertiliser type f],Table_Fertiliser_ChemicalCompounds[FNinorganic f])} -> 0.27 | G25: {=Fertiliser_Equations_InorganicN2O.VEERG_5_1_1_1__2_MassOfNitrogenInInorganicFertiliser(E25,F25)} -> 0
A26: =HYPERLINK("#'Constants - Fuel'!A1", "Constants - Fuel") -> Constants - Fuel | D26: Nitrogen - Ammoniacal | E26: {=Fertiliser_InputFunctions.Fertiliser_TotalChemicalCompoundAppliedAllIngredients($D26,Table_Input_InorganicFertiliser_Brands[Total applied (kg)],Table_Input_InorganicFertiliser_Brands[Ingredient 1],Table_Input_InorganicFertiliser_Brands[Ingredient 1 percent],Table_Input_InorganicFertiliser_Brands[Ingredient 2],Table_Input_InorganicFertiliser_Brands[Ingredient 2 percent],Table_Input_InorganicFertiliser_Brands[Ingredient 3],Table_Input_InorganicFertiliser_Brands[Ingredient 3 percent],Table_Input_InorganicFertiliser_Brands[Ingredient 4],Table_Input_InorganicFertiliser_Brands[Ingredient 4 percent],Table_Input_InorganicFertiliser_Brands[Ingredient 5],Table_Input_InorganicFertiliser_Brands[Ingredient 5 percent],Table_Input_InorganicFertiliser_Brands[Ingredient 6],Table_Input_InorganicFertiliser_Brands[Ingredient 6 percent])+ Fertiliser_InputFunctions.Fertiliser_TotalChemicalCompoundAppliedAllIngredients($D26,Table_Input_InorganicFertiliser_Custom[Total applied (kg)],Table_Input_InorganicFertiliser_Custom[Ingredient 1 (select)],Table_Input_InorganicFertiliser_Custom[Ingredient 1 percent],Table_Input_InorganicFertiliser_Custom[Ingredient 2],Table_Input_InorganicFertiliser_Custom[Ingredient 2 percent],Table_Input_InorganicFertiliser_Custom[Ingredient 3],Table_Input_InorganicFertiliser_Custom[Ingredient 3 percent],Table_Input_InorganicFertiliser_Custom[Ingredient 4],Table_Input_InorganicFertiliser_Custom[Ingredient 4 percent])} -> 0 | F26: {=Common_InputFunctions.Utility_LookupValueInTableNumber(D26,Table_Fertiliser_ChemicalCompounds[Fertiliser type f],Table_Fertiliser_ChemicalCompounds[FNinorganic f])} -> 1 | G26: {=Fertiliser_Equations_InorganicN2O.VEERG_5_1_1_1__2_MassOfNitrogenInInorganicFertiliser(E26,F26)} -> 0
A27: =HYPERLINK("#'Constants - Common'!A1", "Constants - Common") -> Constants - Common | D27: Nitrogen - Nitrate | E27: {=Fertiliser_InputFunctions.Fertiliser_TotalChemicalCompoundAppliedAllIngredients($D27,Table_Input_InorganicFertiliser_Brands[Total applied (kg)],Table_Input_InorganicFertiliser_Brands[Ingredient 1],Table_Input_InorganicFertiliser_Brands[Ingredient 1 percent],Table_Input_InorganicFertiliser_Brands[Ingredient 2],Table_Input_InorganicFertiliser_Brands[Ingredient 2 percent],Table_Input_InorganicFertiliser_Brands[Ingredient 3],Table_Input_InorganicFertiliser_Brands[Ingredient 3 percent],Table_Input_InorganicFertiliser_Brands[Ingredient 4],Table_Input_InorganicFertiliser_Brands[Ingredient 4 percent],Table_Input_InorganicFertiliser_Brands[Ingredient 5],Table_Input_InorganicFertiliser_Brands[Ingredient 5 percent],Table_Input_InorganicFertiliser_Brands[Ingredient 6],Table_Input_InorganicFertiliser_Brands[Ingredient 6 percent])+ Fertiliser_InputFunctions.Fertiliser_TotalChemicalCompoundAppliedAllIngredients($D27,Table_Input_InorganicFertiliser_Custom[Total applied (kg)],Table_Input_InorganicFertiliser_Custom[Ingredient 1 (select)],Table_Input_InorganicFertiliser_Custom[Ingredient 1 percent],Table_Input_InorganicFertiliser_Custom[Ingredient 2],Table_Input_InorganicFertiliser_Custom[Ingredient 2 percent],Table_Input_InorganicFertiliser_Custom[Ingredient 3],Table_Input_InorganicFertiliser_Custom[Ingredient 3 percent],Table_Input_InorganicFertiliser_Custom[Ingredient 4],Table_Input_InorganicFertiliser_Custom[Ingredient 4 percent])} -> 1980 | F27: {=Common_InputFunctions.Utility_LookupValueInTableNumber(D27,Table_Fertiliser_ChemicalCompounds[Fertiliser type f],Table_Fertiliser_ChemicalCompounds[FNinorganic f])} -> 1 | G27: {=Fertiliser_Equations_InorganicN2O.VEERG_5_1_1_1__2_MassOfNitrogenInInorganicFertiliser(E27,F27)} -> 1980 | M27: {=Fertiliser_Equations_InorganicN2O.VEERG_5_1_1_2__3_EmissionFactorCotton_Title()} -> Emission factor for nitrous oxide for cotton
A28: =HYPERLINK("#'Overview'!A1", "Overview") -> Overview | D28: Nitrogen - Generic | E28: {=Fertiliser_InputFunctions.Fertiliser_TotalChemicalCompoundAppliedAllIngredients($D28,Table_Input_InorganicFertiliser_Brands[Total applied (kg)],Table_Input_InorganicFertiliser_Brands[Ingredient 1],Table_Input_InorganicFertiliser_Brands[Ingredient 1 percent],Table_Input_InorganicFertiliser_Brands[Ingredient 2],Table_Input_InorganicFertiliser_Brands[Ingredient 2 percent],Table_Input_InorganicFertiliser_Brands[Ingredient 3],Table_Input_InorganicFertiliser_Brands[Ingredient 3 percent],Table_Input_InorganicFertiliser_Brands[Ingredient 4],Table_Input_InorganicFertiliser_Brands[Ingredient 4 percent],Table_Input_InorganicFertiliser_Brands[Ingredient 5],Table_Input_InorganicFertiliser_Brands[Ingredient 5 percent],Table_Input_InorganicFertiliser_Brands[Ingredient 6],Table_Input_InorganicFertiliser_Brands[Ingredient 6 percent])+ Fertiliser_InputFunctions.Fertiliser_TotalChemicalCompoundAppliedAllIngredients($D28,Table_Input_InorganicFertiliser_Custom[Total applied (kg)],Table_Input_InorganicFertiliser_Custom[Ingredient 1 (select)],Table_Input_InorganicFertiliser_Custom[Ingredient 1 percent],Table_Input_InorganicFertiliser_Custom[Ingredient 2],Table_Input_InorganicFertiliser_Custom[Ingredient 2 percent],Table_Input_InorganicFertiliser_Custom[Ingredient 3],Table_Input_InorganicFertiliser_Custom[Ingredient 3 percent],Table_Input_InorganicFertiliser_Custom[Ingredient 4],Table_Input_InorganicFertiliser_Custom[Ingredient 4 percent])} -> 1537.2 | F28: {=Common_InputFunctions.Utility_LookupValueInTableNumber(D28,Table_Fertiliser_ChemicalCompounds[Fertiliser type f],Table_Fertiliser_ChemicalCompounds[FNinorganic f])} -> 1 | G28: {=Fertiliser_Equations_InorganicN2O.VEERG_5_1_1_1__2_MassOfNitrogenInInorganicFertiliser(E28,F28)} -> 1537.2 | M28: {=Fertiliser_Equations_InorganicN2O.VEERG_5_1_1_2__3_EmissionFactorCotton_Source()} -> VEERG 2026: 5.1.1.2, Equation (3)
D29: Phosphorus - Generic | E29: {=Fertiliser_InputFunctions.Fertiliser_TotalChemicalCompoundAppliedAllIngredients($D29,Table_Input_InorganicFertiliser_Brands[Total applied (kg)],Table_Input_InorganicFertiliser_Brands[Ingredient 1],Table_Input_InorganicFertiliser_Brands[Ingredient 1 percent],Table_Input_InorganicFertiliser_Brands[Ingredient 2],Table_Input_InorganicFertiliser_Brands[Ingredient 2 percent],Table_Input_InorganicFertiliser_Brands[Ingredient 3],Table_Input_InorganicFertiliser_Brands[Ingredient 3 percent],Table_Input_InorganicFertiliser_Brands[Ingredient 4],Table_Input_InorganicFertiliser_Brands[Ingredient 4 percent],Table_Input_InorganicFertiliser_Brands[Ingredient 5],Table_Input_InorganicFertiliser_Brands[Ingredient 5 percent],Table_Input_InorganicFertiliser_Brands[Ingredient 6],Table_Input_InorganicFertiliser_Brands[Ingredient 6 percent])+ Fertiliser_InputFunctions.Fertiliser_TotalChemicalCompoundAppliedAllIngredients($D29,Table_Input_InorganicFertiliser_Custom[Total applied (kg)],Table_Input_InorganicFertiliser_Custom[Ingredient 1 (select)],Table_Input_InorganicFertiliser_Custom[Ingredient 1 percent],Table_Input_InorganicFertiliser_Custom[Ingredient 2],Table_Input_InorganicFertiliser_Custom[Ingredient 2 percent],Table_Input_InorganicFertiliser_Custom[Ingredient 3],Table_Input_InorganicFertiliser_Custom[Ingredient 3 percent],Table_Input_InorganicFertiliser_Custom[Ingredient 4],Table_Input_InorganicFertiliser_Custom[Ingredient 4 percent])} -> 4603.5 | F29: {=Common_InputFunctions.Utility_LookupValueInTableNumber(D29,Table_Fertiliser_ChemicalCompounds[Fertiliser type f],Table_Fertiliser_ChemicalCompounds[FNinorganic f])} -> 0 | G29: {=Fertiliser_Equations_InorganicN2O.VEERG_5_1_1_1__2_MassOfNitrogenInInorganicFertiliser(E29,F29)} -> 0
D30: Potassium - Generic | E30: {=Fertiliser_InputFunctions.Fertiliser_TotalChemicalCompoundAppliedAllIngredients($D30,Table_Input_InorganicFertiliser_Brands[Total applied (kg)],Table_Input_InorganicFertiliser_Brands[Ingredient 1],Table_Input_InorganicFertiliser_Brands[Ingredient 1 percent],Table_Input_InorganicFertiliser_Brands[Ingredient 2],Table_Input_InorganicFertiliser_Brands[Ingredient 2 percent],Table_Input_InorganicFertiliser_Brands[Ingredient 3],Table_Input_InorganicFertiliser_Brands[Ingredient 3 percent],Table_Input_InorganicFertiliser_Brands[Ingredient 4],Table_Input_InorganicFertiliser_Brands[Ingredient 4 percent],Table_Input_InorganicFertiliser_Brands[Ingredient 5],Table_Input_InorganicFertiliser_Brands[Ingredient 5 percent],Table_Input_InorganicFertiliser_Brands[Ingredient 6],Table_Input_InorganicFertiliser_Brands[Ingredient 6 percent])+ Fertiliser_InputFunctions.Fertiliser_TotalChemicalCompoundAppliedAllIngredients($D30,Table_Input_InorganicFertiliser_Custom[Total applied (kg)],Table_Input_InorganicFertiliser_Custom[Ingredient 1 (select)],Table_Input_InorganicFertiliser_Custom[Ingredient 1 percent],Table_Input_InorganicFertiliser_Custom[Ingredient 2],Table_Input_InorganicFertiliser_Custom[Ingredient 2 percent],Table_Input_InorganicFertiliser_Custom[Ingredient 3],Table_Input_InorganicFertiliser_Custom[Ingredient 3 percent],Table_Input_InorganicFertiliser_Custom[Ingredient 4],Table_Input_InorganicFertiliser_Custom[Ingredient 4 percent])} -> 6158 | F30: {=Common_InputFunctions.Utility_LookupValueInTableNumber(D30,Table_Fertiliser_ChemicalCompounds[Fertiliser type f],Table_Fertiliser_ChemicalCompounds[FNinorganic f])} -> 0 | G30: {=Fertiliser_Equations_InorganicN2O.VEERG_5_1_1_1__2_MassOfNitrogenInInorganicFertiliser(E30,F30)} -> 0
D31: Sulfur - Generic | E31: {=Fertiliser_InputFunctions.Fertiliser_TotalChemicalCompoundAppliedAllIngredients($D31,Table_Input_InorganicFertiliser_Brands[Total applied (kg)],Table_Input_InorganicFertiliser_Brands[Ingredient 1],Table_Input_InorganicFertiliser_Brands[Ingredient 1 percent],Table_Input_InorganicFertiliser_Brands[Ingredient 2],Table_Input_InorganicFertiliser_Brands[Ingredient 2 percent],Table_Input_InorganicFertiliser_Brands[Ingredient 3],Table_Input_InorganicFertiliser_Brands[Ingredient 3 percent],Table_Input_InorganicFertiliser_Brands[Ingredient 4],Table_Input_InorganicFertiliser_Brands[Ingredient 4 percent],Table_Input_InorganicFertiliser_Brands[Ingredient 5],Table_Input_InorganicFertiliser_Brands[Ingredient 5 percent],Table_Input_InorganicFertiliser_Brands[Ingredient 6],Table_Input_InorganicFertiliser_Brands[Ingredient 6 percent])+ Fertiliser_InputFunctions.Fertiliser_TotalChemicalCompoundAppliedAllIngredients($D31,Table_Input_InorganicFertiliser_Custom[Total applied (kg)],Table_Input_InorganicFertiliser_Custom[Ingredient 1 (select)],Table_Input_InorganicFertiliser_Custom[Ingredient 1 percent],Table_Input_InorganicFertiliser_Custom[Ingredient 2],Table_Input_InorganicFertiliser_Custom[Ingredient 2 percent],Table_Input_InorganicFertiliser_Custom[Ingredient 3],Table_Input_InorganicFertiliser_Custom[Ingredient 3 percent],Table_Input_InorganicFertiliser_Custom[Ingredient 4],Table_Input_InorganicFertiliser_Custom[Ingredient 4 percent])} -> 1000 | F31: {=Common_InputFunctions.Utility_LookupValueInTableNumber(D31,Table_Fertiliser_ChemicalCompounds[Fertiliser type f],Table_Fertiliser_ChemicalCompounds[FNinorganic f])} -> 0 | G31: {=Fertiliser_Equations_InorganicN2O.VEERG_5_1_1_1__2_MassOfNitrogenInInorganicFertiliser(E31,F31)} -> 0
D32: Zinc - Generic | E32: {=Fertiliser_InputFunctions.Fertiliser_TotalChemicalCompoundAppliedAllIngredients($D32,Table_Input_InorganicFertiliser_Brands[Total applied (kg)],Table_Input_InorganicFertiliser_Brands[Ingredient 1],Table_Input_InorganicFertiliser_Brands[Ingredient 1 percent],Table_Input_InorganicFertiliser_Brands[Ingredient 2],Table_Input_InorganicFertiliser_Brands[Ingredient 2 percent],Table_Input_InorganicFertiliser_Brands[Ingredient 3],Table_Input_InorganicFertiliser_Brands[Ingredient 3 percent],Table_Input_InorganicFertiliser_Brands[Ingredient 4],Table_Input_InorganicFertiliser_Brands[Ingredient 4 percent],Table_Input_InorganicFertiliser_Brands[Ingredient 5],Table_Input_InorganicFertiliser_Brands[Ingredient 5 percent],Table_Input_InorganicFertiliser_Brands[Ingredient 6],Table_Input_InorganicFertiliser_Brands[Ingredient 6 percent])+ Fertiliser_InputFunctions.Fertiliser_TotalChemicalCompoundAppliedAllIngredients($D32,Table_Input_InorganicFertiliser_Custom[Total applied (kg)],Table_Input_InorganicFertiliser_Custom[Ingredient 1 (select)],Table_Input_InorganicFertiliser_Custom[Ingredient 1 percent],Table_Input_InorganicFertiliser_Custom[Ingredient 2],Table_Input_InorganicFertiliser_Custom[Ingredient 2 percent],Table_Input_InorganicFertiliser_Custom[Ingredient 3],Table_Input_InorganicFertiliser_Custom[Ingredient 3 percent],Table_Input_InorganicFertiliser_Custom[Ingredient 4],Table_Input_InorganicFertiliser_Custom[Ingredient 4 percent])} -> 2000 | F32: {=Common_InputFunctions.Utility_LookupValueInTableNumber(D32,Table_Fertiliser_ChemicalCompounds[Fertiliser type f],Table_Fertiliser_ChemicalCompounds[FNinorganic f])} -> 0 | G32: {=Fertiliser_Equations_InorganicN2O.VEERG_5_1_1_1__2_MassOfNitrogenInInorganicFertiliser(E32,F32)} -> 0 | M32: Variable | N32: {=Fertiliser_Equations_InorganicN2O.VEERG_5_1_1_2__3_EmissionFactorCotton_Variable()} -> EF_fjCottonN2O
D33: Muriate of potash (MOP) | E33: {=Fertiliser_InputFunctions.Fertiliser_TotalChemicalCompoundAppliedAllIngredients($D33,Table_Input_InorganicFertiliser_Brands[Total applied (kg)],Table_Input_InorganicFertiliser_Brands[Ingredient 1],Table_Input_InorganicFertiliser_Brands[Ingredient 1 percent],Table_Input_InorganicFertiliser_Brands[Ingredient 2],Table_Input_InorganicFertiliser_Brands[Ingredient 2 percent],Table_Input_InorganicFertiliser_Brands[Ingredient 3],Table_Input_InorganicFertiliser_Brands[Ingredient 3 percent],Table_Input_InorganicFertiliser_Brands[Ingredient 4],Table_Input_InorganicFertiliser_Brands[Ingredient 4 percent],Table_Input_InorganicFertiliser_Brands[Ingredient 5],Table_Input_InorganicFertiliser_Brands[Ingredient 5 percent],Table_Input_InorganicFertiliser_Brands[Ingredient 6],Table_Input_InorganicFertiliser_Brands[Ingredient 6 percent])+ Fertiliser_InputFunctions.Fertiliser_TotalChemicalCompoundAppliedAllIngredients($D33,Table_Input_InorganicFertiliser_Custom[Total applied (kg)],Table_Input_InorganicFertiliser_Custom[Ingredient 1 (select)],Table_Input_InorganicFertiliser_Custom[Ingredient 1 percent],Table_Input_InorganicFertiliser_Custom[Ingredient 2],Table_Input_InorganicFertiliser_Custom[Ingredient 2 percent],Table_Input_InorganicFertiliser_Custom[Ingredient 3],Table_Input_InorganicFertiliser_Custom[Ingredient 3 percent],Table_Input_InorganicFertiliser_Custom[Ingredient 4],Table_Input_InorganicFertiliser_Custom[Ingredient 4 percent])} -> 0 | F33: {=Common_InputFunctions.Utility_LookupValueInTableNumber(D33,Table_Fertiliser_ChemicalCompounds[Fertiliser type f],Table_Fertiliser_ChemicalCompounds[FNinorganic f])} -> 0 | G33: {=Fertiliser_Equations_InorganicN2O.VEERG_5_1_1_1__2_MassOfNitrogenInInorganicFertiliser(E33,F33)} -> 0 | M33: Unit | N33: {=Fertiliser_Equations_InorganicN2O.VEERG_5_1_1_2__3_EmissionFactorCotton_Unit()} -> kg N2O-N/kg N applied
D34: Double superphosphate | E34: {=Fertiliser_InputFunctions.Fertiliser_TotalChemicalCompoundAppliedAllIngredients($D34,Table_Input_InorganicFertiliser_Brands[Total applied (kg)],Table_Input_InorganicFertiliser_Brands[Ingredient 1],Table_Input_InorganicFertiliser_Brands[Ingredient 1 percent],Table_Input_InorganicFertiliser_Brands[Ingredient 2],Table_Input_InorganicFertiliser_Brands[Ingredient 2 percent],Table_Input_InorganicFertiliser_Brands[Ingredient 3],Table_Input_InorganicFertiliser_Brands[Ingredient 3 percent],Table_Input_InorganicFertiliser_Brands[Ingredient 4],Table_Input_InorganicFertiliser_Brands[Ingredient 4 percent],Table_Input_InorganicFertiliser_Brands[Ingredient 5],Table_Input_InorganicFertiliser_Brands[Ingredient 5 percent],Table_Input_InorganicFertiliser_Brands[Ingredient 6],Table_Input_InorganicFertiliser_Brands[Ingredient 6 percent])+ Fertiliser_InputFunctions.Fertiliser_TotalChemicalCompoundAppliedAllIngredients($D34,Table_Input_InorganicFertiliser_Custom[Total applied (kg)],Table_Input_InorganicFertiliser_Custom[Ingredient 1 (select)],Table_Input_InorganicFertiliser_Custom[Ingredient 1 percent],Table_Input_InorganicFertiliser_Custom[Ingredient 2],Table_Input_InorganicFertiliser_Custom[Ingredient 2 percent],Table_Input_InorganicFertiliser_Custom[Ingredient 3],Table_Input_InorganicFertiliser_Custom[Ingredient 3 percent],Table_Input_InorganicFertiliser_Custom[Ingredient 4],Table_Input_InorganicFertiliser_Custom[Ingredient 4 percent])} -> 0 | F34: {=Common_InputFunctions.Utility_LookupValueInTableNumber(D34,Table_Fertiliser_ChemicalCompounds[Fertiliser type f],Table_Fertiliser_ChemicalCompounds[FNinorganic f])} -> 0 | G34: {=Fertiliser_Equations_InorganicN2O.VEERG_5_1_1_1__2_MassOfNitrogenInInorganicFertiliser(E34,F34)} -> 0
D35: Single superphosphate (SSP) | E35: {=Fertiliser_InputFunctions.Fertiliser_TotalChemicalCompoundAppliedAllIngredients($D35,Table_Input_InorganicFertiliser_Brands[Total applied (kg)],Table_Input_InorganicFertiliser_Brands[Ingredient 1],Table_Input_InorganicFertiliser_Brands[Ingredient 1 percent],Table_Input_InorganicFertiliser_Brands[Ingredient 2],Table_Input_InorganicFertiliser_Brands[Ingredient 2 percent],Table_Input_InorganicFertiliser_Brands[Ingredient 3],Table_Input_InorganicFertiliser_Brands[Ingredient 3 percent],Table_Input_InorganicFertiliser_Brands[Ingredient 4],Table_Input_InorganicFertiliser_Brands[Ingredient 4 percent],Table_Input_InorganicFertiliser_Brands[Ingredient 5],Table_Input_InorganicFertiliser_Brands[Ingredient 5 percent],Table_Input_InorganicFertiliser_Brands[Ingredient 6],Table_Input_InorganicFertiliser_Brands[Ingredient 6 percent])+ Fertiliser_InputFunctions.Fertiliser_TotalChemicalCompoundAppliedAllIngredients($D35,Table_Input_InorganicFertiliser_Custom[Total applied (kg)],Table_Input_InorganicFertiliser_Custom[Ingredient 1 (select)],Table_Input_InorganicFertiliser_Custom[Ingredient 1 percent],Table_Input_InorganicFertiliser_Custom[Ingredient 2],Table_Input_InorganicFertiliser_Custom[Ingredient 2 percent],Table_Input_InorganicFertiliser_Custom[Ingredient 3],Table_Input_InorganicFertiliser_Custom[Ingredient 3 percent],Table_Input_InorganicFertiliser_Custom[Ingredient 4],Table_Input_InorganicFertiliser_Custom[Ingredient 4 percent])} -> 0 | F35: {=Common_InputFunctions.Utility_LookupValueInTableNumber(D35,Table_Fertiliser_ChemicalCompounds[Fertiliser type f],Table_Fertiliser_ChemicalCompounds[FNinorganic f])} -> 0 | G35: {=Fertiliser_Equations_InorganicN2O.VEERG_5_1_1_1__2_MassOfNitrogenInInorganicFertiliser(E35,F35)} -> 0 | M35: {=_xlfn.CHOOSECOLS(Fertiliser_Equations_InorganicN2O.VEERG_5_1_1_2__3_EmissionFactorCotton_Arguments(), 1, 2)} -> N_fjCotton | N35: application rate of inorganic fertiliser type f in the cotton crop | P35: {=_xlfn.CHOOSECOLS(Fertiliser_Equations_InorganicN2O.VEERG_5_1_1_2__3_EmissionFactorCotton_Arguments(), 3,4)} -> kg N/ha | Q35: Input | R35: {=HYPERLINK(Common_InputFunctions.Utility_SourceHyperlink($M$41), $M$41)} -> M2_Table_FertApplications
